Workbook

Sheet cover
B6: JRC-IDEES-2023 - Integrated Database of the European Energy System
C15: International maritime bunkers
L28: Prepared by JRC C.6
L30: 45967.481
L31: v2023-1.00
B33: Legal Notice
B35: The information made available is property of the Joint Research Centre of the European Commission.
B36: Neither the European Commission nor any person acting on behalf of the Commission is responsible for the use which might be made of this information.
B38: Use conditions
B39: This work is licensed under
B40: CC BY 4.0

Sheet EEA
A1: EEA - European Economic Area (EU27+IS+NO) | B1: 1990 | C1: 1991 | D1: 1992 | E1: 1993 | F1: 1994 | G1: 1995 | H1: 1996 | I1: 1997 | J1: 1998 | K1: 1999 | L1: 2000 | M1: 2001 | N1: 2002 | O1: 2003 | P1: 2004 | Q1: 2005 | R1: 2006 | S1: 2007 | T1: 2008 | U1: 2009 | V1: 2010 | W1: 2011 | X1: 2012 | Y1: 2013 | Z1: 2014 | AA1: 2015 | AB1: 2016 | AC1: 2017 | AD1: 2018 | AE1: 2019 | AF1: 2020 | AG1: 2021 | AH1: 2022 | AI1: 2023
A3: Transport activity (Mtkm) | B3: =SUM(B4:B5) -> 5421990.5 | C3: =SUM(C4:C5) -> 5192550.7 | D3: =SUM(D4:D5) -> 5129778.7 | E3: =SUM(E4:E5) -> 5114655.3 | F3: =SUM(F4:F5) -> 5018576.3 | G3: =SUM(G4:G5) -> 5041273.4 | H3: =SUM(H4:H5) -> 5110446.4 | I3: =SUM(I4:I5) -> 5388897.6 | ... AI3: =SUM(AI4:AI5) -> 8185303.5
A4: Intra-EEA | B4: =AT!B4+BE!B4+BG!B4+CY!B4+CZ!B4+DE!B4+DK!B4+EE!B4+EL!B4+ES!B4+FI!B4+FR!B4+HR!B4+HU!B4+IE!B4+IT!B4+LT!B4+LU!B4+LV!B4+MT!B4+NL!B4+PL!B4+PT!B4+RO!B4+SE!B4+SI!B4+SK!B4+IS!B4+NO!B4 -> 773600.04 | C4: =AT!C4+BE!C4+BG!C4+CY!C4+CZ!C4+DE!C4+DK!C4+EE!C4+EL!C4+ES!C4+FI!C4+FR!C4+HR!C4+HU!C4+IE!C4+IT!C4+LT!C4+LU!C4+LV!C4+MT!C4+NL!C4+PL!C4+PT!C4+RO!C4+SE!C4+SI!C4+SK!C4+IS!C4+NO!C4 -> 720270.44 | D4: =AT!D4+BE!D4+BG!D4+CY!D4+CZ!D4+DE!D4+DK!D4+EE!D4+EL!D4+ES!D4+FI!D4+FR!D4+HR!D4+HU!D4+IE!D4+IT!D4+LT!D4+LU!D4+LV!D4+MT!D4+NL!D4+PL!D4+PT!D4+RO!D4+SE!D4+SI!D4+SK!D4+IS!D4+NO!D4 -> 732989.03 | E4: =AT!E4+BE!E4+BG!E4+CY!E4+CZ!E4+DE!E4+DK!E4+EE!E4+EL!E4+ES!E4+FI!E4+FR!E4+HR!E4+HU!E4+IE!E4+IT!E4+LT!E4+LU!E4+LV!E4+MT!E4+NL!E4+PL!E4+PT!E4+RO!E4+SE!E4+SI!E4+SK!E4+IS!E4+NO!E4 -> 726980.15 | F4: =AT!F4+BE!F4+BG!F4+CY!F4+CZ!F4+DE!F4+DK!F4+EE!F4+EL!F4+ES!F4+FI!F4+FR!F4+HR!F4+HU!F4+IE!F4+IT!F4+LT!F4+LU!F4+LV!F4+MT!F4+NL!F4+PL!F4+PT!F4+RO!F4+SE!F4+SI!F4+SK!F4+IS!F4+NO!F4 -> 722250.78 | G4: =AT!G4+BE!G4+BG!G4+CY!G4+CZ!G4+DE!G4+DK!G4+EE!G4+EL!G4+ES!G4+FI!G4+FR!G4+HR!G4+HU!G4+IE!G4+IT!G4+LT!G4+LU!G4+LV!G4+MT!G4+NL!G4+PL!G4+PT!G4+RO!G4+SE!G4+SI!G4+SK!G4+IS!G4+NO!G4 -> 714127.38 | H4: =AT!H4+BE!H4+BG!H4+CY!H4+CZ!H4+DE!H4+DK!H4+EE!H4+EL!H4+ES!H4+FI!H4+FR!H4+HR!H4+HU!H4+IE!H4+IT!H4+LT!H4+LU!H4+LV!H4+MT!H4+NL!H4+PL!H4+PT!H4+RO!H4+SE!H4+SI!H4+SK!H4+IS!H4+NO!H4 -> 736831.6 | I4: =AT!I4+BE!I4+BG!I4+CY!I4+CZ!I4+DE!I4+DK!I4+EE!I4+EL!I4+ES!I4+FI!I4+FR!I4+HR!I4+HU!I4+IE!I4+IT!I4+LT!I4+LU!I4+LV!I4+MT!I4+NL!I4+PL!I4+PT!I4+RO!I4+SE!I4+SI!I4+SK!I4+IS!I4+NO!I4 -> 761213.79 | ... AI4: =AT!AI4+BE!AI4+BG!AI4+CY!AI4+CZ!AI4+DE!AI4+DK!AI4+EE!AI4+EL!AI4+ES!AI4+FI!AI4+FR!AI4+HR!AI4+HU!AI4+IE!AI4+IT!AI4+LT!AI4+LU!AI4+LV!AI4+MT!AI4+NL!AI4+PL!AI4+PT!AI4+RO!AI4+SE!AI4+SI!AI4+SK!AI4+IS!AI4+NO!AI4 -> 1106111.8
A5: Extra-EEA | B5: =AT!B5+BE!B5+BG!B5+CY!B5+CZ!B5+DE!B5+DK!B5+EE!B5+EL!B5+ES!B5+FI!B5+FR!B5+HR!B5+HU!B5+IE!B5+IT!B5+LT!B5+LU!B5+LV!B5+MT!B5+NL!B5+PL!B5+PT!B5+RO!B5+SE!B5+SI!B5+SK!B5+IS!B5+NO!B5 -> 4648390.5 | C5: =AT!C5+BE!C5+BG!C5+CY!C5+CZ!C5+DE!C5+DK!C5+EE!C5+EL!C5+ES!C5+FI!C5+FR!C5+HR!C5+HU!C5+IE!C5+IT!C5+LT!C5+LU!C5+LV!C5+MT!C5+NL!C5+PL!C5+PT!C5+RO!C5+SE!C5+SI!C5+SK!C5+IS!C5+NO!C5 -> 4472280.3 | D5: =AT!D5+BE!D5+BG!D5+CY!D5+CZ!D5+DE!D5+DK!D5+EE!D5+EL!D5+ES!D5+FI!D5+FR!D5+HR!D5+HU!D5+IE!D5+IT!D5+LT!D5+LU!D5+LV!D5+MT!D5+NL!D5+PL!D5+PT!D5+RO!D5+SE!D5+SI!D5+SK!D5+IS!D5+NO!D5 -> 4396789.7 | E5: =AT!E5+BE!E5+BG!E5+CY!E5+CZ!E5+DE!E5+DK!E5+EE!E5+EL!E5+ES!E5+FI!E5+FR!E5+HR!E5+HU!E5+IE!E5+IT!E5+LT!E5+LU!E5+LV!E5+MT!E5+NL!E5+PL!E5+PT!E5+RO!E5+SE!E5+SI!E5+SK!E5+IS!E5+NO!E5 -> 4387675.1 | F5: =AT!F5+BE!F5+BG!F5+CY!F5+CZ!F5+DE!F5+DK!F5+EE!F5+EL!F5+ES!F5+FI!F5+FR!F5+HR!F5+HU!F5+IE!F5+IT!F5+LT!F5+LU!F5+LV!F5+MT!F5+NL!F5+PL!F5+PT!F5+RO!F5+SE!F5+SI!F5+SK!F5+IS!F5+NO!F5 -> 4296325.5 | G5: =AT!G5+BE!G5+BG!G5+CY!G5+CZ!G5+DE!G5+DK!G5+EE!G5+EL!G5+ES!G5+FI!G5+FR!G5+HR!G5+HU!G5+IE!G5+IT!G5+LT!G5+LU!G5+LV!G5+MT!G5+NL!G5+PL!G5+PT!G5+RO!G5+SE!G5+SI!G5+SK!G5+IS!G5+NO!G5 -> 4327146 | H5: =AT!H5+BE!H5+BG!H5+CY!H5+CZ!H5+DE!H5+DK!H5+EE!H5+EL!H5+ES!H5+FI!H5+FR!H5+HR!H5+HU!H5+IE!H5+IT!H5+LT!H5+LU!H5+LV!H5+MT!H5+NL!H5+PL!H5+PT!H5+RO!H5+SE!H5+SI!H5+SK!H5+IS!H5+NO!H5 -> 4373614.8 | I5: =AT!I5+BE!I5+BG!I5+CY!I5+CZ!I5+DE!I5+DK!I5+EE!I5+EL!I5+ES!I5+FI!I5+FR!I5+HR!I5+HU!I5+IE!I5+IT!I5+LT!I5+LU!I5+LV!I5+MT!I5+NL!I5+PL!I5+PT!I5+RO!I5+SE!I5+SI!I5+SK!I5+IS!I5+NO!I5 -> 4627683.8 | ... AI5: =AT!AI5+BE!AI5+BG!AI5+CY!AI5+CZ!AI5+DE!AI5+DK!AI5+EE!AI5+EL!AI5+ES!AI5+FI!AI5+FR!AI5+HR!AI5+HU!AI5+IE!AI5+IT!AI5+LT!AI5+LU!AI5+LV!AI5+MT!AI5+NL!AI5+PL!AI5+PT!AI5+RO!AI5+SE!AI5+SI!AI5+SK!AI5+IS!AI5+NO!AI5 -> 7079191.7
A6: * Considering both inwards and outwards flows of goods transported with half of the distance of the voyages (thus the total distance for Intra-EEA in the EEA aggregation)
A8: Market shares of activity (% of tkm) | B8: =IF(B3=0,0,B3/B$3) -> 1 | C8: =IF(C3=0,0,C3/C$3) -> 1 | D8: =IF(D3=0,0,D3/D$3) -> 1 | E8: =IF(E3=0,0,E3/E$3) -> 1 | F8: =IF(F3=0,0,F3/F$3) -> 1 | G8: =IF(G3=0,0,G3/G$3) -> 1 | H8: =IF(H3=0,0,H3/H$3) -> 1 | I8: =IF(I3=0,0,I3/I$3) -> 1 | ... AI8: =IF(AI3=0,0,AI3/AI$3) -> 1
A9: Intra-EEA | B9: =IF(B4=0,0,B4/B$3) -> 0.14267823 | C9: =IF(C4=0,0,C4/C$3) -> 0.13871226 | D9: =IF(D4=0,0,D4/D$3) -> 0.14288902 | E9: =IF(E4=0,0,E4/E$3) -> 0.14213669 | F9: =IF(F4=0,0,F4/F$3) -> 0.14391547 | G9: =IF(G4=0,0,G4/G$3) -> 0.14165615 | H9: =IF(H4=0,0,H4/H$3) -> 0.14418146 | I9: =IF(I4=0,0,I4/I$3) -> 0.14125594 | ... AI9: =IF(AI4=0,0,AI4/AI$3) -> 0.13513387
A10: Extra-EEA | B10: =IF(B5=0,0,B5/B$3) -> 0.85732177 | C10: =IF(C5=0,0,C5/C$3) -> 0.86128774 | D10: =IF(D5=0,0,D5/D$3) -> 0.85711098 | E10: =IF(E5=0,0,E5/E$3) -> 0.85786331 | F10: =IF(F5=0,0,F5/F$3) -> 0.85608453 | G10: =IF(G5=0,0,G5/G$3) -> 0.85834385 | H10: =IF(H5=0,0,H5/H$3) -> 0.85581854 | I10: =IF(I5=0,0,I5/I$3) -> 0.85874406 | ... AI10: =IF(AI5=0,0,AI5/AI$3) -> 0.86486613
A12: Vehicle-km (Mvkm) | B12: =SUM(B13:B14) -> 358.54904 | C12: =SUM(C13:C14) -> 330.60565 | D12: =SUM(D13:D14) -> 331.43499 | E12: =SUM(E13:E14) -> 333.09692 | F12: =SUM(F13:F14) -> 333.53067 | G12: =SUM(G13:G14) -> 333.90186 | H12: =SUM(H13:H14) -> 337.17897 | I12: =SUM(I13:I14) -> 349.3633 | ... AI12: =SUM(AI13:AI14) -> 352.33876
A13: Intra-EEA | B13: =AT!B13+BE!B13+BG!B13+CY!B13+CZ!B13+DE!B13+DK!B13+EE!B13+EL!B13+ES!B13+FI!B13+FR!B13+HR!B13+HU!B13+IE!B13+IT!B13+LT!B13+LU!B13+LV!B13+MT!B13+NL!B13+PL!B13+PT!B13+RO!B13+SE!B13+SI!B13+SK!B13+IS!B13+NO!B13 -> 150.91776 | C13: =AT!C13+BE!C13+BG!C13+CY!C13+CZ!C13+DE!C13+DK!C13+EE!C13+EL!C13+ES!C13+FI!C13+FR!C13+HR!C13+HU!C13+IE!C13+IT!C13+LT!C13+LU!C13+LV!C13+MT!C13+NL!C13+PL!C13+PT!C13+RO!C13+SE!C13+SI!C13+SK!C13+IS!C13+NO!C13 -> 136.74817 | D13: =AT!D13+BE!D13+BG!D13+CY!D13+CZ!D13+DE!D13+DK!D13+EE!D13+EL!D13+ES!D13+FI!D13+FR!D13+HR!D13+HU!D13+IE!D13+IT!D13+LT!D13+LU!D13+LV!D13+MT!D13+NL!D13+PL!D13+PT!D13+RO!D13+SE!D13+SI!D13+SK!D13+IS!D13+NO!D13 -> 139.56603 | E13: =AT!E13+BE!E13+BG!E13+CY!E13+CZ!E13+DE!E13+DK!E13+EE!E13+EL!E13+ES!E13+FI!E13+FR!E13+HR!E13+HU!E13+IE!E13+IT!E13+LT!E13+LU!E13+LV!E13+MT!E13+NL!E13+PL!E13+PT!E13+RO!E13+SE!E13+SI!E13+SK!E13+IS!E13+NO!E13 -> 140.05713 | F13: =AT!F13+BE!F13+BG!F13+CY!F13+CZ!F13+DE!F13+DK!F13+EE!F13+EL!F13+ES!F13+FI!F13+FR!F13+HR!F13+HU!F13+IE!F13+IT!F13+LT!F13+LU!F13+LV!F13+MT!F13+NL!F13+PL!F13+PT!F13+RO!F13+SE!F13+SI!F13+SK!F13+IS!F13+NO!F13 -> 141.56611 | G13: =AT!G13+BE!G13+BG!G13+CY!G13+CZ!G13+DE!G13+DK!G13+EE!G13+EL!G13+ES!G13+FI!G13+FR!G13+HR!G13+HU!G13+IE!G13+IT!G13+LT!G13+LU!G13+LV!G13+MT!G13+NL!G13+PL!G13+PT!G13+RO!G13+SE!G13+SI!G13+SK!G13+IS!G13+NO!G13 -> 140.86666 | H13: =AT!H13+BE!H13+BG!H13+CY!H13+CZ!H13+DE!H13+DK!H13+EE!H13+EL!H13+ES!H13+FI!H13+FR!H13+HR!H13+HU!H13+IE!H13+IT!H13+LT!H13+LU!H13+LV!H13+MT!H13+NL!H13+PL!H13+PT!H13+RO!H13+SE!H13+SI!H13+SK!H13+IS!H13+NO!H13 -> 143.69124 | I13: =AT!I13+BE!I13+BG!I13+CY!I13+CZ!I13+DE!I13+DK!I13+EE!I13+EL!I13+ES!I13+FI!I13+FR!I13+HR!I13+HU!I13+IE!I13+IT!I13+LT!I13+LU!I13+LV!I13+MT!I13+NL!I13+PL!I13+PT!I13+RO!I13+SE!I13+SI!I13+SK!I13+IS!I13+NO!I13 -> 147.33089 | ... AI13: =AT!AI13+BE!AI13+BG!AI13+CY!AI13+CZ!AI13+DE!AI13+DK!AI13+EE!AI13+EL!AI13+ES!AI13+FI!AI13+FR!AI13+HR!AI13+HU!AI13+IE!AI13+IT!AI13+LT!AI13+LU!AI13+LV!AI13+MT!AI13+NL!AI13+PL!AI13+PT!AI13+RO!AI13+SE!AI13+SI!AI13+SK!AI13+IS!AI13+NO!AI13 -> 155.36371
A14: Extra-EEA | B14: =AT!B14+BE!B14+BG!B14+CY!B14+CZ!B14+DE!B14+DK!B14+EE!B14+EL!B14+ES!B14+FI!B14+FR!B14+HR!B14+HU!B14+IE!B14+IT!B14+LT!B14+LU!B14+LV!B14+MT!B14+NL!B14+PL!B14+PT!B14+RO!B14+SE!B14+SI!B14+SK!B14+IS!B14+NO!B14 -> 207.63127 | C14: =AT!C14+BE!C14+BG!C14+CY!C14+CZ!C14+DE!C14+DK!C14+EE!C14+EL!C14+ES!C14+FI!C14+FR!C14+HR!C14+HU!C14+IE!C14+IT!C14+LT!C14+LU!C14+LV!C14+MT!C14+NL!C14+PL!C14+PT!C14+RO!C14+SE!C14+SI!C14+SK!C14+IS!C14+NO!C14 -> 193.85747 | D14: =AT!D14+BE!D14+BG!D14+CY!D14+CZ!D14+DE!D14+DK!D14+EE!D14+EL!D14+ES!D14+FI!D14+FR!D14+HR!D14+HU!D14+IE!D14+IT!D14+LT!D14+LU!D14+LV!D14+MT!D14+NL!D14+PL!D14+PT!D14+RO!D14+SE!D14+SI!D14+SK!D14+IS!D14+NO!D14 -> 191.86896 | E14: =AT!E14+BE!E14+BG!E14+CY!E14+CZ!E14+DE!E14+DK!E14+EE!E14+EL!E14+ES!E14+FI!E14+FR!E14+HR!E14+HU!E14+IE!E14+IT!E14+LT!E14+LU!E14+LV!E14+MT!E14+NL!E14+PL!E14+PT!E14+RO!E14+SE!E14+SI!E14+SK!E14+IS!E14+NO!E14 -> 193.03979 | F14: =AT!F14+BE!F14+BG!F14+CY!F14+CZ!F14+DE!F14+DK!F14+EE!F14+EL!F14+ES!F14+FI!F14+FR!F14+HR!F14+HU!F14+IE!F14+IT!F14+LT!F14+LU!F14+LV!F14+MT!F14+NL!F14+PL!F14+PT!F14+RO!F14+SE!F14+SI!F14+SK!F14+IS!F14+NO!F14 -> 191.96455 | G14: =AT!G14+BE!G14+BG!G14+CY!G14+CZ!G14+DE!G14+DK!G14+EE!G14+EL!G14+ES!G14+FI!G14+FR!G14+HR!G14+HU!G14+IE!G14+IT!G14+LT!G14+LU!G14+LV!G14+MT!G14+NL!G14+PL!G14+PT!G14+RO!G14+SE!G14+SI!G14+SK!G14+IS!G14+NO!G14 -> 193.03519 | H14: =AT!H14+BE!H14+BG!H14+CY!H14+CZ!H14+DE!H14+DK!H14+EE!H14+EL!H14+ES!H14+FI!H14+FR!H14+HR!H14+HU!H14+IE!H14+IT!H14+LT!H14+LU!H14+LV!H14+MT!H14+NL!H14+PL!H14+PT!H14+RO!H14+SE!H14+SI!H14+SK!H14+IS!H14+NO!H14 -> 193.48774 | I14: =AT!I14+BE!I14+BG!I14+CY!I14+CZ!I14+DE!I14+DK!I14+EE!I14+EL!I14+ES!I14+FI!I14+FR!I14+HR!I14+HU!I14+IE!I14+IT!I14+LT!I14+LU!I14+LV!I14+MT!I14+NL!I14+PL!I14+PT!I14+RO!I14+SE!I14+SI!I14+SK!I14+IS!I14+NO!I14 -> 202.03242 | ... AI14: =AT!AI14+BE!AI14+BG!AI14+CY!AI14+CZ!AI14+DE!AI14+DK!AI14+EE!AI14+EL!AI14+ES!AI14+FI!AI14+FR!AI14+HR!AI14+HU!AI14+IE!AI14+IT!AI14+LT!AI14+LU!AI14+LV!AI14+MT!AI14+NL!AI14+PL!AI14+PT!AI14+RO!AI14+SE!AI14+SI!AI14+SK!AI14+IS!AI14+NO!AI14 -> 196.97505
A15: * Considering half of the distance of the voyages (thus the total distance for Intra-EEA in the EEA aggregation)
A17: Market shares of vehicle km (% of km) | B17: =IF(B12=0,0,B12/B$12) -> 1 | C17: =IF(C12=0,0,C12/C$12) -> 1 | D17: =IF(D12=0,0,D12/D$12) -> 1 | E17: =IF(E12=0,0,E12/E$12) -> 1 | F17: =IF(F12=0,0,F12/F$12) -> 1 | G17: =IF(G12=0,0,G12/G$12) -> 1 | H17: =IF(H12=0,0,H12/H$12) -> 1 | I17: =IF(I12=0,0,I12/I$12) -> 1 | ... AI17: =IF(AI12=0,0,AI12/AI$12) -> 1
A18: Intra-EEA | B18: =IF(B13=0,0,B13/B$12) -> 0.42091248 | C18: =IF(C13=0,0,C13/C$12) -> 0.41362927 | D18: =IF(D13=0,0,D13/D$12) -> 0.42109623 | E18: =IF(E13=0,0,E13/E$12) -> 0.4204696 | F18: =IF(F13=0,0,F13/F$12) -> 0.42444707 | G18: =IF(G13=0,0,G13/G$12) -> 0.42188044 | H18: =IF(H13=0,0,H13/H$12) -> 0.42615717 | I18: =IF(I13=0,0,I13/I$12) -> 0.42171254 | ... AI18: =IF(AI13=0,0,AI13/AI$12) -> 0.44094982
A19: Extra-EEA | B19: =IF(B14=0,0,B14/B$12) -> 0.57908752 | C19: =IF(C14=0,0,C14/C$12) -> 0.58637073 | D19: =IF(D14=0,0,D14/D$12) -> 0.57890377 | E19: =IF(E14=0,0,E14/E$12) -> 0.5795304 | F19: =IF(F14=0,0,F14/F$12) -> 0.57555293 | G19: =IF(G14=0,0,G14/G$12) -> 0.57811956 | H19: =IF(H14=0,0,H14/H$12) -> 0.57384283 | I19: =IF(I14=0,0,I14/I$12) -> 0.57828746 | ... AI19: =IF(AI14=0,0,AI14/AI$12) -> 0.55905018
A21: Load factor of vessels (t/movement) | B21: =IF(B3=0,0,B3/B12) -> 15122.034 | C21: =IF(C3=0,0,C3/C12) -> 15706.177 | D21: =IF(D3=0,0,D3/D12) -> 15477.481 | E21: =IF(E3=0,0,E3/E12) -> 15354.856 | F21: =IF(F3=0,0,F3/F12) -> 15046.821 | G21: =IF(G3=0,0,G3/G12) -> 15098.069 | H21: =IF(H3=0,0,H3/H12) -> 15156.48 | I21: =IF(I3=0,0,I3/I12) -> 15424.91 | ... AI21: =IF(AI3=0,0,AI3/AI12) -> 23231.345
A22: Intra-EEA | B22: =IF(B4=0,0,B4/B13) -> 5125.9707 | C22: =IF(C4=0,0,C4/C13) -> 5267.1302 | D22: =IF(D4=0,0,D4/D13) -> 5251.9159 | E22: =IF(E4=0,0,E4/E13) -> 5190.5972 | F22: =IF(F4=0,0,F4/F13) -> 5101.862 | G22: =IF(G4=0,0,G4/G13) -> 5069.5272 | H22: =IF(H4=0,0,H4/H13) -> 5127.8813 | I22: =IF(I4=0,0,I4/I13) -> 5166.6953 | ... AI22: =IF(AI4=0,0,AI4/AI13) -> 7119.4987
A23: Extra-EEA | B23: =IF(B5=0,0,B5/B14) -> 22387.719 | C23: =IF(C5=0,0,C5/C14) -> 23069.94 | D23: =IF(D5=0,0,D5/D14) -> 22915.586 | E23: =IF(E5=0,0,E5/E14) -> 22729.382 | F23: =IF(F5=0,0,F5/F14) -> 22380.827 | G23: =IF(G5=0,0,G5/G14) -> 22416.358 | H23: =IF(H5=0,0,H5/H14) -> 22604.093 | I23: =IF(I5=0,0,I5/I14) -> 22905.65 | ... AI23: =IF(AI5=0,0,AI5/AI14) -> 35939.535
A25: Total energy consumption (ktoe) | B25: =SUM(B26,B32) -> 33617.575 | C25: =SUM(C26,C32) -> 33286.787 | D25: =SUM(D26,D32) -> 33686.069 | E25: =SUM(E26,E32) -> 33615.51 | F25: =SUM(F26,F32) -> 33187.762 | G25: =SUM(G26,G32) -> 33532.668 | H25: =SUM(H26,H32) -> 35282.809 | I25: =SUM(I26,I32) -> 38005.547 | ... AI25: =SUM(AI26,AI32) -> 39656.607
A26: Intra-EEA | B26: =SUM(B27:B31) -> 11663.979 | C26: =SUM(C27:C31) -> 11405.357 | D26: =SUM(D27:D31) -> 11749.275 | E26: =SUM(E27:E31) -> 11890.478 | F26: =SUM(F27:F31) -> 11844.19 | G26: =SUM(G27:G31) -> 12038.117 | H26: =SUM(H27:H31) -> 12704.051 | I26: =SUM(I27:I31) -> 13646.949 | ... AI26: =SUM(AI27:AI31) -> 14238.07
A27: Gas oil and diesel oil (excluding biofuel portion) | B27: =AT!B27+BE!B27+BG!B27+CY!B27+CZ!B27+DE!B27+DK!B27+EE!B27+EL!B27+ES!B27+FI!B27+FR!B27+HR!B27+HU!B27+IE!B27+IT!B27+LT!B27+LU!B27+LV!B27+MT!B27+NL!B27+PL!B27+PT!B27+RO!B27+SE!B27+SI!B27+SK!B27+IS!B27+NO!B27 -> 5408.1702 | C27: =AT!C27+BE!C27+BG!C27+CY!C27+CZ!C27+DE!C27+DK!C27+EE!C27+EL!C27+ES!C27+FI!C27+FR!C27+HR!C27+HU!C27+IE!C27+IT!C27+LT!C27+LU!C27+LV!C27+MT!C27+NL!C27+PL!C27+PT!C27+RO!C27+SE!C27+SI!C27+SK!C27+IS!C27+NO!C27 -> 5346.6099 | D27: =AT!D27+BE!D27+BG!D27+CY!D27+CZ!D27+DE!D27+DK!D27+EE!D27+EL!D27+ES!D27+FI!D27+FR!D27+HR!D27+HU!D27+IE!D27+IT!D27+LT!D27+LU!D27+LV!D27+MT!D27+NL!D27+PL!D27+PT!D27+RO!D27+SE!D27+SI!D27+SK!D27+IS!D27+NO!D27 -> 5716.24 | E27: =AT!E27+BE!E27+BG!E27+CY!E27+CZ!E27+DE!E27+DK!E27+EE!E27+EL!E27+ES!E27+FI!E27+FR!E27+HR!E27+HU!E27+IE!E27+IT!E27+LT!E27+LU!E27+LV!E27+MT!E27+NL!E27+PL!E27+PT!E27+RO!E27+SE!E27+SI!E27+SK!E27+IS!E27+NO!E27 -> 5260.7716 | F27: =AT!F27+BE!F27+BG!F27+CY!F27+CZ!F27+DE!F27+DK!F27+EE!F27+EL!F27+ES!F27+FI!F27+FR!F27+HR!F27+HU!F27+IE!F27+IT!F27+LT!F27+LU!F27+LV!F27+MT!F27+NL!F27+PL!F27+PT!F27+RO!F27+SE!F27+SI!F27+SK!F27+IS!F27+NO!F27 -> 5086.6035 | G27: =AT!G27+BE!G27+BG!G27+CY!G27+CZ!G27+DE!G27+DK!G27+EE!G27+EL!G27+ES!G27+FI!G27+FR!G27+HR!G27+HU!G27+IE!G27+IT!G27+LT!G27+LU!G27+LV!G27+MT!G27+NL!G27+PL!G27+PT!G27+RO!G27+SE!G27+SI!G27+SK!G27+IS!G27+NO!G27 -> 5636.3245 | H27: =AT!H27+BE!H27+BG!H27+CY!H27+CZ!H27+DE!H27+DK!H27+EE!H27+EL!H27+ES!H27+FI!H27+FR!H27+HR!H27+HU!H27+IE!H27+IT!H27+LT!H27+LU!H27+LV!H27+MT!H27+NL!H27+PL!H27+PT!H27+RO!H27+SE!H27+SI!H27+SK!H27+IS!H27+NO!H27 -> 5998.2169 | I27: =AT!I27+BE!I27+BG!I27+CY!I27+CZ!I27+DE!I27+DK!I27+EE!I27+EL!I27+ES!I27+FI!I27+FR!I27+HR!I27+HU!I27+IE!I27+IT!I27+LT!I27+LU!I27+LV!I27+MT!I27+NL!I27+PL!I27+PT!I27+RO!I27+SE!I27+SI!I27+SK!I27+IS!I27+NO!I27 -> 6425.3039 | ... AI27: =AT!AI27+BE!AI27+BG!AI27+CY!AI27+CZ!AI27+DE!AI27+DK!AI27+EE!AI27+EL!AI27+ES!AI27+FI!AI27+FR!AI27+HR!AI27+HU!AI27+IE!AI27+IT!AI27+LT!AI27+LU!AI27+LV!AI27+MT!AI27+NL!AI27+PL!AI27+PT!AI27+RO!AI27+SE!AI27+SI!AI27+SK!AI27+IS!AI27+NO!AI27 -> 6739.9575
A28: Fuel oil and Other oil products | B28: =AT!B28+BE!B28+BG!B28+CY!B28+CZ!B28+DE!B28+DK!B28+EE!B28+EL!B28+ES!B28+FI!B28+FR!B28+HR!B28+HU!B28+IE!B28+IT!B28+LT!B28+LU!B28+LV!B28+MT!B28+NL!B28+PL!B28+PT!B28+RO!B28+SE!B28+SI!B28+SK!B28+IS!B28+NO!B28 -> 6255.8083 | C28: =AT!C28+BE!C28+BG!C28+CY!C28+CZ!C28+DE!C28+DK!C28+EE!C28+EL!C28+ES!C28+FI!C28+FR!C28+HR!C28+HU!C28+IE!C28+IT!C28+LT!C28+LU!C28+LV!C28+MT!C28+NL!C28+PL!C28+PT!C28+RO!C28+SE!C28+SI!C28+SK!C28+IS!C28+NO!C28 -> 6058.7475 | D28: =AT!D28+BE!D28+BG!D28+CY!D28+CZ!D28+DE!D28+DK!D28+EE!D28+EL!D28+ES!D28+FI!D28+FR!D28+HR!D28+HU!D28+IE!D28+IT!D28+LT!D28+LU!D28+LV!D28+MT!D28+NL!D28+PL!D28+PT!D28+RO!D28+SE!D28+SI!D28+SK!D28+IS!D28+NO!D28 -> 6033.035 | E28: =AT!E28+BE!E28+BG!E28+CY!E28+CZ!E28+DE!E28+DK!E28+EE!E28+EL!E28+ES!E28+FI!E28+FR!E28+HR!E28+HU!E28+IE!E28+IT!E28+LT!E28+LU!E28+LV!E28+MT!E28+NL!E28+PL!E28+PT!E28+RO!E28+SE!E28+SI!E28+SK!E28+IS!E28+NO!E28 -> 6629.7066 | F28: =AT!F28+BE!F28+BG!F28+CY!F28+CZ!F28+DE!F28+DK!F28+EE!F28+EL!F28+ES!F28+FI!F28+FR!F28+HR!F28+HU!F28+IE!F28+IT!F28+LT!F28+LU!F28+LV!F28+MT!F28+NL!F28+PL!F28+PT!F28+RO!F28+SE!F28+SI!F28+SK!F28+IS!F28+NO!F28 -> 6757.5865 | G28: =AT!G28+BE!G28+BG!G28+CY!G28+CZ!G28+DE!G28+DK!G28+EE!G28+EL!G28+ES!G28+FI!G28+FR!G28+HR!G28+HU!G28+IE!G28+IT!G28+LT!G28+LU!G28+LV!G28+MT!G28+NL!G28+PL!G28+PT!G28+RO!G28+SE!G28+SI!G28+SK!G28+IS!G28+NO!G28 -> 6401.7929 | H28: =AT!H28+BE!H28+BG!H28+CY!H28+CZ!H28+DE!H28+DK!H28+EE!H28+EL!H28+ES!H28+FI!H28+FR!H28+HR!H28+HU!H28+IE!H28+IT!H28+LT!H28+LU!H28+LV!H28+MT!H28+NL!H28+PL!H28+PT!H28+RO!H28+SE!H28+SI!H28+SK!H28+IS!H28+NO!H28 -> 6705.8343 | I28: =AT!I28+BE!I28+BG!I28+CY!I28+CZ!I28+DE!I28+DK!I28+EE!I28+EL!I28+ES!I28+FI!I28+FR!I28+HR!I28+HU!I28+IE!I28+IT!I28+LT!I28+LU!I28+LV!I28+MT!I28+NL!I28+PL!I28+PT!I28+RO!I28+SE!I28+SI!I28+SK!I28+IS!I28+NO!I28 -> 7221.6453 | ... AI28: =AT!AI28+BE!AI28+BG!AI28+CY!AI28+CZ!AI28+DE!AI28+DK!AI28+EE!AI28+EL!AI28+ES!AI28+FI!AI28+FR!AI28+HR!AI28+HU!AI28+IE!AI28+IT!AI28+LT!AI28+LU!AI28+LV!AI28+MT!AI28+NL!AI28+PL!AI28+PT!AI28+RO!AI28+SE!AI28+SI!AI28+SK!AI28+IS!AI28+NO!AI28 -> 7249.5616
A29: Blended biofuels | B29: =AT!B29+BE!B29+BG!B29+CY!B29+CZ!B29+DE!B29+DK!B29+EE!B29+EL!B29+ES!B29+FI!B29+FR!B29+HR!B29+HU!B29+IE!B29+IT!B29+LT!B29+LU!B29+LV!B29+MT!B29+NL!B29+PL!B29+PT!B29+RO!B29+SE!B29+SI!B29+SK!B29+IS!B29+NO!B29 -> 0 | C29: =AT!C29+BE!C29+BG!C29+CY!C29+CZ!C29+DE!C29+DK!C29+EE!C29+EL!C29+ES!C29+FI!C29+FR!C29+HR!C29+HU!C29+IE!C29+IT!C29+LT!C29+LU!C29+LV!C29+MT!C29+NL!C29+PL!C29+PT!C29+RO!C29+SE!C29+SI!C29+SK!C29+IS!C29+NO!C29 -> 0 | D29: =AT!D29+BE!D29+BG!D29+CY!D29+CZ!D29+DE!D29+DK!D29+EE!D29+EL!D29+ES!D29+FI!D29+FR!D29+HR!D29+HU!D29+IE!D29+IT!D29+LT!D29+LU!D29+LV!D29+MT!D29+NL!D29+PL!D29+PT!D29+RO!D29+SE!D29+SI!D29+SK!D29+IS!D29+NO!D29 -> 0 | E29: =AT!E29+BE!E29+BG!E29+CY!E29+CZ!E29+DE!E29+DK!E29+EE!E29+EL!E29+ES!E29+FI!E29+FR!E29+HR!E29+HU!E29+IE!E29+IT!E29+LT!E29+LU!E29+LV!E29+MT!E29+NL!E29+PL!E29+PT!E29+RO!E29+SE!E29+SI!E29+SK!E29+IS!E29+NO!E29 -> 0 | F29: =AT!F29+BE!F29+BG!F29+CY!F29+CZ!F29+DE!F29+DK!F29+EE!F29+EL!F29+ES!F29+FI!F29+FR!F29+HR!F29+HU!F29+IE!F29+IT!F29+LT!F29+LU!F29+LV!F29+MT!F29+NL!F29+PL!F29+PT!F29+RO!F29+SE!F29+SI!F29+SK!F29+IS!F29+NO!F29 -> 0 | G29: =AT!G29+BE!G29+BG!G29+CY!G29+CZ!G29+DE!G29+DK!G29+EE!G29+EL!G29+ES!G29+FI!G29+FR!G29+HR!G29+HU!G29+IE!G29+IT!G29+LT!G29+LU!G29+LV!G29+MT!G29+NL!G29+PL!G29+PT!G29+RO!G29+SE!G29+SI!G29+SK!G29+IS!G29+NO!G29 -> 0 | H29: =AT!H29+BE!H29+BG!H29+CY!H29+CZ!H29+DE!H29+DK!H29+EE!H29+EL!H29+ES!H29+FI!H29+FR!H29+HR!H29+HU!H29+IE!H29+IT!H29+LT!H29+LU!H29+LV!H29+MT!H29+NL!H29+PL!H29+PT!H29+RO!H29+SE!H29+SI!H29+SK!H29+IS!H29+NO!H29 -> 0 | I29: =AT!I29+BE!I29+BG!I29+CY!I29+CZ!I29+DE!I29+DK!I29+EE!I29+EL!I29+ES!I29+FI!I29+FR!I29+HR!I29+HU!I29+IE!I29+IT!I29+LT!I29+LU!I29+LV!I29+MT!I29+NL!I29+PL!I29+PT!I29+RO!I29+SE!I29+SI!I29+SK!I29+IS!I29+NO!I29 -> 0 | ... AI29: =AT!AI29+BE!AI29+BG!AI29+CY!AI29+CZ!AI29+DE!AI29+DK!AI29+EE!AI29+EL!AI29+ES!AI29+FI!AI29+FR!AI29+HR!AI29+HU!AI29+IE!AI29+IT!AI29+LT!AI29+LU!AI29+LV!AI29+MT!AI29+NL!AI29+PL!AI29+PT!AI29+RO!AI29+SE!AI29+SI!AI29+SK!AI29+IS!AI29+NO!AI29 -> 74.519223
A30: Natural gas | B30: =AT!B30+BE!B30+BG!B30+CY!B30+CZ!B30+DE!B30+DK!B30+EE!B30+EL!B30+ES!B30+FI!B30+FR!B30+HR!B30+HU!B30+IE!B30+IT!B30+LT!B30+LU!B30+LV!B30+MT!B30+NL!B30+PL!B30+PT!B30+RO!B30+SE!B30+SI!B30+SK!B30+IS!B30+NO!B30 -> 0 | C30: =AT!C30+BE!C30+BG!C30+CY!C30+CZ!C30+DE!C30+DK!C30+EE!C30+EL!C30+ES!C30+FI!C30+FR!C30+HR!C30+HU!C30+IE!C30+IT!C30+LT!C30+LU!C30+LV!C30+MT!C30+NL!C30+PL!C30+PT!C30+RO!C30+SE!C30+SI!C30+SK!C30+IS!C30+NO!C30 -> 0 | D30: =AT!D30+BE!D30+BG!D30+CY!D30+CZ!D30+DE!D30+DK!D30+EE!D30+EL!D30+ES!D30+FI!D30+FR!D30+HR!D30+HU!D30+IE!D30+IT!D30+LT!D30+LU!D30+LV!D30+MT!D30+NL!D30+PL!D30+PT!D30+RO!D30+SE!D30+SI!D30+SK!D30+IS!D30+NO!D30 -> 0 | E30: =AT!E30+BE!E30+BG!E30+CY!E30+CZ!E30+DE!E30+DK!E30+EE!E30+EL!E30+ES!E30+FI!E30+FR!E30+HR!E30+HU!E30+IE!E30+IT!E30+LT!E30+LU!E30+LV!E30+MT!E30+NL!E30+PL!E30+PT!E30+RO!E30+SE!E30+SI!E30+SK!E30+IS!E30+NO!E30 -> 0 | F30: =AT!F30+BE!F30+BG!F30+CY!F30+CZ!F30+DE!F30+DK!F30+EE!F30+EL!F30+ES!F30+FI!F30+FR!F30+HR!F30+HU!F30+IE!F30+IT!F30+LT!F30+LU!F30+LV!F30+MT!F30+NL!F30+PL!F30+PT!F30+RO!F30+SE!F30+SI!F30+SK!F30+IS!F30+NO!F30 -> 0 | G30: =AT!G30+BE!G30+BG!G30+CY!G30+CZ!G30+DE!G30+DK!G30+EE!G30+EL!G30+ES!G30+FI!G30+FR!G30+HR!G30+HU!G30+IE!G30+IT!G30+LT!G30+LU!G30+LV!G30+MT!G30+NL!G30+PL!G30+PT!G30+RO!G30+SE!G30+SI!G30+SK!G30+IS!G30+NO!G30 -> 0 | H30: =AT!H30+BE!H30+BG!H30+CY!H30+CZ!H30+DE!H30+DK!H30+EE!H30+EL!H30+ES!H30+FI!H30+FR!H30+HR!H30+HU!H30+IE!H30+IT!H30+LT!H30+LU!H30+LV!H30+MT!H30+NL!H30+PL!H30+PT!H30+RO!H30+SE!H30+SI!H30+SK!H30+IS!H30+NO!H30 -> 0 | I30: =AT!I30+BE!I30+BG!I30+CY!I30+CZ!I30+DE!I30+DK!I30+EE!I30+EL!I30+ES!I30+FI!I30+FR!I30+HR!I30+HU!I30+IE!I30+IT!I30+LT!I30+LU!I30+LV!I30+MT!I30+NL!I30+PL!I30+PT!I30+RO!I30+SE!I30+SI!I30+SK!I30+IS!I30+NO!I30 -> 0 | ... AI30: =AT!AI30+BE!AI30+BG!AI30+CY!AI30+CZ!AI30+DE!AI30+DK!AI30+EE!AI30+EL!AI30+ES!AI30+FI!AI30+FR!AI30+HR!AI30+HU!AI30+IE!AI30+IT!AI30+LT!AI30+LU!AI30+LV!AI30+MT!AI30+NL!AI30+PL!AI30+PT!AI30+RO!AI30+SE!AI30+SI!AI30+SK!AI30+IS!AI30+NO!AI30 -> 171.54457
A31: Biogases | B31: =AT!B31+BE!B31+BG!B31+CY!B31+CZ!B31+DE!B31+DK!B31+EE!B31+EL!B31+ES!B31+FI!B31+FR!B31+HR!B31+HU!B31+IE!B31+IT!B31+LT!B31+LU!B31+LV!B31+MT!B31+NL!B31+PL!B31+PT!B31+RO!B31+SE!B31+SI!B31+SK!B31+IS!B31+NO!B31 -> 0 | C31: =AT!C31+BE!C31+BG!C31+CY!C31+CZ!C31+DE!C31+DK!C31+EE!C31+EL!C31+ES!C31+FI!C31+FR!C31+HR!C31+HU!C31+IE!C31+IT!C31+LT!C31+LU!C31+LV!C31+MT!C31+NL!C31+PL!C31+PT!C31+RO!C31+SE!C31+SI!C31+SK!C31+IS!C31+NO!C31 -> 0 | D31: =AT!D31+BE!D31+BG!D31+CY!D31+CZ!D31+DE!D31+DK!D31+EE!D31+EL!D31+ES!D31+FI!D31+FR!D31+HR!D31+HU!D31+IE!D31+IT!D31+LT!D31+LU!D31+LV!D31+MT!D31+NL!D31+PL!D31+PT!D31+RO!D31+SE!D31+SI!D31+SK!D31+IS!D31+NO!D31 -> 0 | E31: =AT!E31+BE!E31+BG!E31+CY!E31+CZ!E31+DE!E31+DK!E31+EE!E31+EL!E31+ES!E31+FI!E31+FR!E31+HR!E31+HU!E31+IE!E31+IT!E31+LT!E31+LU!E31+LV!E31+MT!E31+NL!E31+PL!E31+PT!E31+RO!E31+SE!E31+SI!E31+SK!E31+IS!E31+NO!E31 -> 0 | F31: =AT!F31+BE!F31+BG!F31+CY!F31+CZ!F31+DE!F31+DK!F31+EE!F31+EL!F31+ES!F31+FI!F31+FR!F31+HR!F31+HU!F31+IE!F31+IT!F31+LT!F31+LU!F31+LV!F31+MT!F31+NL!F31+PL!F31+PT!F31+RO!F31+SE!F31+SI!F31+SK!F31+IS!F31+NO!F31 -> 0 | G31: =AT!G31+BE!G31+BG!G31+CY!G31+CZ!G31+DE!G31+DK!G31+EE!G31+EL!G31+ES!G31+FI!G31+FR!G31+HR!G31+HU!G31+IE!G31+IT!G31+LT!G31+LU!G31+LV!G31+MT!G31+NL!G31+PL!G31+PT!G31+RO!G31+SE!G31+SI!G31+SK!G31+IS!G31+NO!G31 -> 0 | H31: =AT!H31+BE!H31+BG!H31+CY!H31+CZ!H31+DE!H31+DK!H31+EE!H31+EL!H31+ES!H31+FI!H31+FR!H31+HR!H31+HU!H31+IE!H31+IT!H31+LT!H31+LU!H31+LV!H31+MT!H31+NL!H31+PL!H31+PT!H31+RO!H31+SE!H31+SI!H31+SK!H31+IS!H31+NO!H31 -> 0 | I31: =AT!I31+BE!I31+BG!I31+CY!I31+CZ!I31+DE!I31+DK!I31+EE!I31+EL!I31+ES!I31+FI!I31+FR!I31+HR!I31+HU!I31+IE!I31+IT!I31+LT!I31+LU!I31+LV!I31+MT!I31+NL!I31+PL!I31+PT!I31+RO!I31+SE!I31+SI!I31+SK!I31+IS!I31+NO!I31 -> 0 | ... AI31: =AT!AI31+BE!AI31+BG!AI31+CY!AI31+CZ!AI31+DE!AI31+DK!AI31+EE!AI31+EL!AI31+ES!AI31+FI!AI31+FR!AI31+HR!AI31+HU!AI31+IE!AI31+IT!AI31+LT!AI31+LU!AI31+LV!AI31+MT!AI31+NL!AI31+PL!AI31+PT!AI31+RO!AI31+SE!AI31+SI!AI31+SK!AI31+IS!AI31+NO!AI31 -> 2.4874549
A32: Extra-EEA | B32: =SUM(B33:B37) -> 21953.596 | C32: =SUM(C33:C37) -> 21881.43 | D32: =SUM(D33:D37) -> 21936.794 | E32: =SUM(E33:E37) -> 21725.032 | F32: =SUM(F33:F37) -> 21343.572 | G32: =SUM(G33:G37) -> 21494.551 | H32: =SUM(H33:H37) -> 22578.757 | I32: =SUM(I33:I37) -> 24358.598 | ... AI32: =SUM(AI33:AI37) -> 25418.537
A33: Gas oil and diesel oil (excluding biofuel portion) | B33: =AT!B33+BE!B33+BG!B33+CY!B33+CZ!B33+DE!B33+DK!B33+EE!B33+EL!B33+ES!B33+FI!B33+FR!B33+HR!B33+HU!B33+IE!B33+IT!B33+LT!B33+LU!B33+LV!B33+MT!B33+NL!B33+PL!B33+PT!B33+RO!B33+SE!B33+SI!B33+SK!B33+IS!B33+NO!B33 -> 2020.5428 | C33: =AT!C33+BE!C33+BG!C33+CY!C33+CZ!C33+DE!C33+DK!C33+EE!C33+EL!C33+ES!C33+FI!C33+FR!C33+HR!C33+HU!C33+IE!C33+IT!C33+LT!C33+LU!C33+LV!C33+MT!C33+NL!C33+PL!C33+PT!C33+RO!C33+SE!C33+SI!C33+SK!C33+IS!C33+NO!C33 -> 2029.4738 | D33: =AT!D33+BE!D33+BG!D33+CY!D33+CZ!D33+DE!D33+DK!D33+EE!D33+EL!D33+ES!D33+FI!D33+FR!D33+HR!D33+HU!D33+IE!D33+IT!D33+LT!D33+LU!D33+LV!D33+MT!D33+NL!D33+PL!D33+PT!D33+RO!D33+SE!D33+SI!D33+SK!D33+IS!D33+NO!D33 -> 2096.8914 | E33: =AT!E33+BE!E33+BG!E33+CY!E33+CZ!E33+DE!E33+DK!E33+EE!E33+EL!E33+ES!E33+FI!E33+FR!E33+HR!E33+HU!E33+IE!E33+IT!E33+LT!E33+LU!E33+LV!E33+MT!E33+NL!E33+PL!E33+PT!E33+RO!E33+SE!E33+SI!E33+SK!E33+IS!E33+NO!E33 -> 1879.5252 | F33: =AT!F33+BE!F33+BG!F33+CY!F33+CZ!F33+DE!F33+DK!F33+EE!F33+EL!F33+ES!F33+FI!F33+FR!F33+HR!F33+HU!F33+IE!F33+IT!F33+LT!F33+LU!F33+LV!F33+MT!F33+NL!F33+PL!F33+PT!F33+RO!F33+SE!F33+SI!F33+SK!F33+IS!F33+NO!F33 -> 1719.2613 | G33: =AT!G33+BE!G33+BG!G33+CY!G33+CZ!G33+DE!G33+DK!G33+EE!G33+EL!G33+ES!G33+FI!G33+FR!G33+HR!G33+HU!G33+IE!G33+IT!G33+LT!G33+LU!G33+LV!G33+MT!G33+NL!G33+PL!G33+PT!G33+RO!G33+SE!G33+SI!G33+SK!G33+IS!G33+NO!G33 -> 1882.835 | H33: =AT!H33+BE!H33+BG!H33+CY!H33+CZ!H33+DE!H33+DK!H33+EE!H33+EL!H33+ES!H33+FI!H33+FR!H33+HR!H33+HU!H33+IE!H33+IT!H33+LT!H33+LU!H33+LV!H33+MT!H33+NL!H33+PL!H33+PT!H33+RO!H33+SE!H33+SI!H33+SK!H33+IS!H33+NO!H33 -> 1972.2254 | I33: =AT!I33+BE!I33+BG!I33+CY!I33+CZ!I33+DE!I33+DK!I33+EE!I33+EL!I33+ES!I33+FI!I33+FR!I33+HR!I33+HU!I33+IE!I33+IT!I33+LT!I33+LU!I33+LV!I33+MT!I33+NL!I33+PL!I33+PT!I33+RO!I33+SE!I33+SI!I33+SK!I33+IS!I33+NO!I33 -> 2098.7775 | ... AI33: =AT!AI33+BE!AI33+BG!AI33+CY!AI33+CZ!AI33+DE!AI33+DK!AI33+EE!AI33+EL!AI33+ES!AI33+FI!AI33+FR!AI33+HR!AI33+HU!AI33+IE!AI33+IT!AI33+LT!AI33+LU!AI33+LV!AI33+MT!AI33+NL!AI33+PL!AI33+PT!AI33+RO!AI33+SE!AI33+SI!AI33+SK!AI33+IS!AI33+NO!AI33 -> 2565.9136
A34: Fuel oil and Other oil products | B34: =AT!B34+BE!B34+BG!B34+CY!B34+CZ!B34+DE!B34+DK!B34+EE!B34+EL!B34+ES!B34+FI!B34+FR!B34+HR!B34+HU!B34+IE!B34+IT!B34+LT!B34+LU!B34+LV!B34+MT!B34+NL!B34+PL!B34+PT!B34+RO!B34+SE!B34+SI!B34+SK!B34+IS!B34+NO!B34 -> 19933.054 | C34: =AT!C34+BE!C34+BG!C34+CY!C34+CZ!C34+DE!C34+DK!C34+EE!C34+EL!C34+ES!C34+FI!C34+FR!C34+HR!C34+HU!C34+IE!C34+IT!C34+LT!C34+LU!C34+LV!C34+MT!C34+NL!C34+PL!C34+PT!C34+RO!C34+SE!C34+SI!C34+SK!C34+IS!C34+NO!C34 -> 19851.956 | D34: =AT!D34+BE!D34+BG!D34+CY!D34+CZ!D34+DE!D34+DK!D34+EE!D34+EL!D34+ES!D34+FI!D34+FR!D34+HR!D34+HU!D34+IE!D34+IT!D34+LT!D34+LU!D34+LV!D34+MT!D34+NL!D34+PL!D34+PT!D34+RO!D34+SE!D34+SI!D34+SK!D34+IS!D34+NO!D34 -> 19839.902 | E34: =AT!E34+BE!E34+BG!E34+CY!E34+CZ!E34+DE!E34+DK!E34+EE!E34+EL!E34+ES!E34+FI!E34+FR!E34+HR!E34+HU!E34+IE!E34+IT!E34+LT!E34+LU!E34+LV!E34+MT!E34+NL!E34+PL!E34+PT!E34+RO!E34+SE!E34+SI!E34+SK!E34+IS!E34+NO!E34 -> 19845.507 | F34: =AT!F34+BE!F34+BG!F34+CY!F34+CZ!F34+DE!F34+DK!F34+EE!F34+EL!F34+ES!F34+FI!F34+FR!F34+HR!F34+HU!F34+IE!F34+IT!F34+LT!F34+LU!F34+LV!F34+MT!F34+NL!F34+PL!F34+PT!F34+RO!F34+SE!F34+SI!F34+SK!F34+IS!F34+NO!F34 -> 19624.311 | G34: =AT!G34+BE!G34+BG!G34+CY!G34+CZ!G34+DE!G34+DK!G34+EE!G34+EL!G34+ES!G34+FI!G34+FR!G34+HR!G34+HU!G34+IE!G34+IT!G34+LT!G34+LU!G34+LV!G34+MT!G34+NL!G34+PL!G34+PT!G34+RO!G34+SE!G34+SI!G34+SK!G34+IS!G34+NO!G34 -> 19611.716 | H34: =AT!H34+BE!H34+BG!H34+CY!H34+CZ!H34+DE!H34+DK!H34+EE!H34+EL!H34+ES!H34+FI!H34+FR!H34+HR!H34+HU!H34+IE!H34+IT!H34+LT!H34+LU!H34+LV!H34+MT!H34+NL!H34+PL!H34+PT!H34+RO!H34+SE!H34+SI!H34+SK!H34+IS!H34+NO!H34 -> 20606.532 | I34: =AT!I34+BE!I34+BG!I34+CY!I34+CZ!I34+DE!I34+DK!I34+EE!I34+EL!I34+ES!I34+FI!I34+FR!I34+HR!I34+HU!I34+IE!I34+IT!I34+LT!I34+LU!I34+LV!I34+MT!I34+NL!I34+PL!I34+PT!I34+RO!I34+SE!I34+SI!I34+SK!I34+IS!I34+NO!I34 -> 22259.82 | ... AI34: =AT!AI34+BE!AI34+BG!AI34+CY!AI34+CZ!AI34+DE!AI34+DK!AI34+EE!AI34+EL!AI34+ES!AI34+FI!AI34+FR!AI34+HR!AI34+HU!AI34+IE!AI34+IT!AI34+LT!AI34+LU!AI34+LV!AI34+MT!AI34+NL!AI34+PL!AI34+PT!AI34+RO!AI34+SE!AI34+SI!AI34+SK!AI34+IS!AI34+NO!AI34 -> 22292.831
A35: Blended biofuels | B35: =AT!B35+BE!B35+BG!B35+CY!B35+CZ!B35+DE!B35+DK!B35+EE!B35+EL!B35+ES!B35+FI!B35+FR!B35+HR!B35+HU!B35+IE!B35+IT!B35+LT!B35+LU!B35+LV!B35+MT!B35+NL!B35+PL!B35+PT!B35+RO!B35+SE!B35+SI!B35+SK!B35+IS!B35+NO!B35 -> 0 | C35: =AT!C35+BE!C35+BG!C35+CY!C35+CZ!C35+DE!C35+DK!C35+EE!C35+EL!C35+ES!C35+FI!C35+FR!C35+HR!C35+HU!C35+IE!C35+IT!C35+LT!C35+LU!C35+LV!C35+MT!C35+NL!C35+PL!C35+PT!C35+RO!C35+SE!C35+SI!C35+SK!C35+IS!C35+NO!C35 -> 0 | D35: =AT!D35+BE!D35+BG!D35+CY!D35+CZ!D35+DE!D35+DK!D35+EE!D35+EL!D35+ES!D35+FI!D35+FR!D35+HR!D35+HU!D35+IE!D35+IT!D35+LT!D35+LU!D35+LV!D35+MT!D35+NL!D35+PL!D35+PT!D35+RO!D35+SE!D35+SI!D35+SK!D35+IS!D35+NO!D35 -> 0 | E35: =AT!E35+BE!E35+BG!E35+CY!E35+CZ!E35+DE!E35+DK!E35+EE!E35+EL!E35+ES!E35+FI!E35+FR!E35+HR!E35+HU!E35+IE!E35+IT!E35+LT!E35+LU!E35+LV!E35+MT!E35+NL!E35+PL!E35+PT!E35+RO!E35+SE!E35+SI!E35+SK!E35+IS!E35+NO!E35 -> 0 | F35: =AT!F35+BE!F35+BG!F35+CY!F35+CZ!F35+DE!F35+DK!F35+EE!F35+EL!F35+ES!F35+FI!F35+FR!F35+HR!F35+HU!F35+IE!F35+IT!F35+LT!F35+LU!F35+LV!F35+MT!F35+NL!F35+PL!F35+PT!F35+RO!F35+SE!F35+SI!F35+SK!F35+IS!F35+NO!F35 -> 0 | G35: =AT!G35+BE!G35+BG!G35+CY!G35+CZ!G35+DE!G35+DK!G35+EE!G35+EL!G35+ES!G35+FI!G35+FR!G35+HR!G35+HU!G35+IE!G35+IT!G35+LT!G35+LU!G35+LV!G35+MT!G35+NL!G35+PL!G35+PT!G35+RO!G35+SE!G35+SI!G35+SK!G35+IS!G35+NO!G35 -> 0 | H35: =AT!H35+BE!H35+BG!H35+CY!H35+CZ!H35+DE!H35+DK!H35+EE!H35+EL!H35+ES!H35+FI!H35+FR!H35+HR!H35+HU!H35+IE!H35+IT!H35+LT!H35+LU!H35+LV!H35+MT!H35+NL!H35+PL!H35+PT!H35+RO!H35+SE!H35+SI!H35+SK!H35+IS!H35+NO!H35 -> 0 | I35: =AT!I35+BE!I35+BG!I35+CY!I35+CZ!I35+DE!I35+DK!I35+EE!I35+EL!I35+ES!I35+FI!I35+FR!I35+HR!I35+HU!I35+IE!I35+IT!I35+LT!I35+LU!I35+LV!I35+MT!I35+NL!I35+PL!I35+PT!I35+RO!I35+SE!I35+SI!I35+SK!I35+IS!I35+NO!I35 -> 0 | ... AI35: =AT!AI35+BE!AI35+BG!AI35+CY!AI35+CZ!AI35+DE!AI35+DK!AI35+EE!AI35+EL!AI35+ES!AI35+FI!AI35+FR!AI35+HR!AI35+HU!AI35+IE!AI35+IT!AI35+LT!AI35+LU!AI35+LV!AI35+MT!AI35+NL!AI35+PL!AI35+PT!AI35+RO!AI35+SE!AI35+SI!AI35+SK!AI35+IS!AI35+NO!AI35 -> 255.62858
A36: Natural gas | B36: =AT!B36+BE!B36+BG!B36+CY!B36+CZ!B36+DE!B36+DK!B36+EE!B36+EL!B36+ES!B36+FI!B36+FR!B36+HR!B36+HU!B36+IE!B36+IT!B36+LT!B36+LU!B36+LV!B36+MT!B36+NL!B36+PL!B36+PT!B36+RO!B36+SE!B36+SI!B36+SK!B36+IS!B36+NO!B36 -> 0 | C36: =AT!C36+BE!C36+BG!C36+CY!C36+CZ!C36+DE!C36+DK!C36+EE!C36+EL!C36+ES!C36+FI!C36+FR!C36+HR!C36+HU!C36+IE!C36+IT!C36+LT!C36+LU!C36+LV!C36+MT!C36+NL!C36+PL!C36+PT!C36+RO!C36+SE!C36+SI!C36+SK!C36+IS!C36+NO!C36 -> 0 | D36: =AT!D36+BE!D36+BG!D36+CY!D36+CZ!D36+DE!D36+DK!D36+EE!D36+EL!D36+ES!D36+FI!D36+FR!D36+HR!D36+HU!D36+IE!D36+IT!D36+LT!D36+LU!D36+LV!D36+MT!D36+NL!D36+PL!D36+PT!D36+RO!D36+SE!D36+SI!D36+SK!D36+IS!D36+NO!D36 -> 0 | E36: =AT!E36+BE!E36+BG!E36+CY!E36+CZ!E36+DE!E36+DK!E36+EE!E36+EL!E36+ES!E36+FI!E36+FR!E36+HR!E36+HU!E36+IE!E36+IT!E36+LT!E36+LU!E36+LV!E36+MT!E36+NL!E36+PL!E36+PT!E36+RO!E36+SE!E36+SI!E36+SK!E36+IS!E36+NO!E36 -> 0 | F36: =AT!F36+BE!F36+BG!F36+CY!F36+CZ!F36+DE!F36+DK!F36+EE!F36+EL!F36+ES!F36+FI!F36+FR!F36+HR!F36+HU!F36+IE!F36+IT!F36+LT!F36+LU!F36+LV!F36+MT!F36+NL!F36+PL!F36+PT!F36+RO!F36+SE!F36+SI!F36+SK!F36+IS!F36+NO!F36 -> 0 | G36: =AT!G36+BE!G36+BG!G36+CY!G36+CZ!G36+DE!G36+DK!G36+EE!G36+EL!G36+ES!G36+FI!G36+FR!G36+HR!G36+HU!G36+IE!G36+IT!G36+LT!G36+LU!G36+LV!G36+MT!G36+NL!G36+PL!G36+PT!G36+RO!G36+SE!G36+SI!G36+SK!G36+IS!G36+NO!G36 -> 0 | H36: =AT!H36+BE!H36+BG!H36+CY!H36+CZ!H36+DE!H36+DK!H36+EE!H36+EL!H36+ES!H36+FI!H36+FR!H36+HR!H36+HU!H36+IE!H36+IT!H36+LT!H36+LU!H36+LV!H36+MT!H36+NL!H36+PL!H36+PT!H36+RO!H36+SE!H36+SI!H36+SK!H36+IS!H36+NO!H36 -> 0 | I36: =AT!I36+BE!I36+BG!I36+CY!I36+CZ!I36+DE!I36+DK!I36+EE!I36+EL!I36+ES!I36+FI!I36+FR!I36+HR!I36+HU!I36+IE!I36+IT!I36+LT!I36+LU!I36+LV!I36+MT!I36+NL!I36+PL!I36+PT!I36+RO!I36+SE!I36+SI!I36+SK!I36+IS!I36+NO!I36 -> 0 | ... AI36: =AT!AI36+BE!AI36+BG!AI36+CY!AI36+CZ!AI36+DE!AI36+DK!AI36+EE!AI36+EL!AI36+ES!AI36+FI!AI36+FR!AI36+HR!AI36+HU!AI36+IE!AI36+IT!AI36+LT!AI36+LU!AI36+LV!AI36+MT!AI36+NL!AI36+PL!AI36+PT!AI36+RO!AI36+SE!AI36+SI!AI36+SK!AI36+IS!AI36+NO!AI36 -> 301.18726
A37: Biogases | B37: =AT!B37+BE!B37+BG!B37+CY!B37+CZ!B37+DE!B37+DK!B37+EE!B37+EL!B37+ES!B37+FI!B37+FR!B37+HR!B37+HU!B37+IE!B37+IT!B37+LT!B37+LU!B37+LV!B37+MT!B37+NL!B37+PL!B37+PT!B37+RO!B37+SE!B37+SI!B37+SK!B37+IS!B37+NO!B37 -> 0 | C37: =AT!C37+BE!C37+BG!C37+CY!C37+CZ!C37+DE!C37+DK!C37+EE!C37+EL!C37+ES!C37+FI!C37+FR!C37+HR!C37+HU!C37+IE!C37+IT!C37+LT!C37+LU!C37+LV!C37+MT!C37+NL!C37+PL!C37+PT!C37+RO!C37+SE!C37+SI!C37+SK!C37+IS!C37+NO!C37 -> 0 | D37: =AT!D37+BE!D37+BG!D37+CY!D37+CZ!D37+DE!D37+DK!D37+EE!D37+EL!D37+ES!D37+FI!D37+FR!D37+HR!D37+HU!D37+IE!D37+IT!D37+LT!D37+LU!D37+LV!D37+MT!D37+NL!D37+PL!D37+PT!D37+RO!D37+SE!D37+SI!D37+SK!D37+IS!D37+NO!D37 -> 0 | E37: =AT!E37+BE!E37+BG!E37+CY!E37+CZ!E37+DE!E37+DK!E37+EE!E37+EL!E37+ES!E37+FI!E37+FR!E37+HR!E37+HU!E37+IE!E37+IT!E37+LT!E37+LU!E37+LV!E37+MT!E37+NL!E37+PL!E37+PT!E37+RO!E37+SE!E37+SI!E37+SK!E37+IS!E37+NO!E37 -> 0 | F37: =AT!F37+BE!F37+BG!F37+CY!F37+CZ!F37+DE!F37+DK!F37+EE!F37+EL!F37+ES!F37+FI!F37+FR!F37+HR!F37+HU!F37+IE!F37+IT!F37+LT!F37+LU!F37+LV!F37+MT!F37+NL!F37+PL!F37+PT!F37+RO!F37+SE!F37+SI!F37+SK!F37+IS!F37+NO!F37 -> 0 | G37: =AT!G37+BE!G37+BG!G37+CY!G37+CZ!G37+DE!G37+DK!G37+EE!G37+EL!G37+ES!G37+FI!G37+FR!G37+HR!G37+HU!G37+IE!G37+IT!G37+LT!G37+LU!G37+LV!G37+MT!G37+NL!G37+PL!G37+PT!G37+RO!G37+SE!G37+SI!G37+SK!G37+IS!G37+NO!G37 -> 0 | H37: =AT!H37+BE!H37+BG!H37+CY!H37+CZ!H37+DE!H37+DK!H37+EE!H37+EL!H37+ES!H37+FI!H37+FR!H37+HR!H37+HU!H37+IE!H37+IT!H37+LT!H37+LU!H37+LV!H37+MT!H37+NL!H37+PL!H37+PT!H37+RO!H37+SE!H37+SI!H37+SK!H37+IS!H37+NO!H37 -> 0 | I37: =AT!I37+BE!I37+BG!I37+CY!I37+CZ!I37+DE!I37+DK!I37+EE!I37+EL!I37+ES!I37+FI!I37+FR!I37+HR!I37+HU!I37+IE!I37+IT!I37+LT!I37+LU!I37+LV!I37+MT!I37+NL!I37+PL!I37+PT!I37+RO!I37+SE!I37+SI!I37+SK!I37+IS!I37+NO!I37 -> 0 | ... AI37: =AT!AI37+BE!AI37+BG!AI37+CY!AI37+CZ!AI37+DE!AI37+DK!AI37+EE!AI37+EL!AI37+ES!AI37+FI!AI37+FR!AI37+HR!AI37+HU!AI37+IE!AI37+IT!AI37+LT!AI37+LU!AI37+LV!AI37+MT!AI37+NL!AI37+PL!AI37+PT!AI37+RO!AI37+SE!AI37+SI!AI37+SK!AI37+IS!AI37+NO!AI37 -> 2.9762353
A38: * As reported in the Eurostat energy balances
A40: Energy intensity over activity (kgoe / 000 tkm) | B40: =IF(B25=0,0,B25/(B3/1000)) -> 6.2002275 | C40: =IF(C25=0,0,C25/(C3/1000)) -> 6.4104886 | D40: =IF(D25=0,0,D25/(D3/1000)) -> 6.5667684 | E40: =IF(E25=0,0,E25/(E3/1000)) -> 6.5723903 | F40: =IF(F25=0,0,F25/(F3/1000)) -> 6.6129834 | G40: =IF(G25=0,0,G25/(G3/1000)) -> 6.6516266 | H40: =IF(H25=0,0,H25/(H3/1000)) -> 6.9040561 | I40: =IF(I25=0,0,I25/(I3/1000)) -> 7.0525642 | ... AI40: =IF(AI25=0,0,AI25/(AI3/1000)) -> 4.8448549
A41: Intra-EEA | B41: =IF(B26=0,0,B26/(B4/1000)) -> 15.077531 | C41: =IF(C26=0,0,C26/(C4/1000)) -> 15.834826 | D41: =IF(D26=0,0,D26/(D4/1000)) -> 16.029264 | E41: =IF(E26=0,0,E26/(E4/1000)) -> 16.355987 | F41: =IF(F26=0,0,F26/(F4/1000)) -> 16.398999 | G41: =IF(G26=0,0,G26/(G4/1000)) -> 16.857101 | H41: =IF(H26=0,0,H26/(H4/1000)) -> 17.241458 | I41: =IF(I26=0,0,I26/(I4/1000)) -> 17.92788 | ... AI41: =IF(AI26=0,0,AI26/(AI4/1000)) -> 12.872181
A42: Extra-EEA | B42: =IF(B32=0,0,B32/(B5/1000)) -> 4.7228382 | C42: =IF(C32=0,0,C32/(C5/1000)) -> 4.8926786 | D42: =IF(D32=0,0,D32/(D5/1000)) -> 4.9892752 | E42: =IF(E32=0,0,E32/(E5/1000)) -> 4.9513767 | F42: =IF(F32=0,0,F32/(F5/1000)) -> 4.9678665 | G42: =IF(G32=0,0,G32/(G5/1000)) -> 4.9673736 | H42: =IF(H32=0,0,H32/(H5/1000)) -> 5.1624934 | I42: =IF(I32=0,0,I32/(I5/1000)) -> 5.2636693 | ... AI42: =IF(AI32=0,0,AI32/(AI5/1000)) -> 3.5905988
A44: Shares of total energy consumption (%) | B44: =IF(B25=0,0,B25/B$25) -> 1 | C44: =IF(C25=0,0,C25/C$25) -> 1 | D44: =IF(D25=0,0,D25/D$25) -> 1 | E44: =IF(E25=0,0,E25/E$25) -> 1 | F44: =IF(F25=0,0,F25/F$25) -> 1 | G44: =IF(G25=0,0,G25/G$25) -> 1 | H44: =IF(H25=0,0,H25/H$25) -> 1 | I44: =IF(I25=0,0,I25/I$25) -> 1 | ... AI44: =IF(AI25=0,0,AI25/AI$25) -> 1
A45: Intra-EEA | B45: =IF(B26=0,0,B26/B$25) -> 0.34696074 | C45: =IF(C26=0,0,C26/C$25) -> 0.34263918 | D45: =IF(D26=0,0,D26/D$25) -> 0.34878736 | E45: =IF(E26=0,0,E26/E$25) -> 0.35372 | F45: =IF(F26=0,0,F26/F$25) -> 0.35688427 | G45: =IF(G26=0,0,G26/G$25) -> 0.3589967 | H45: =IF(H26=0,0,H26/H$25) -> 0.36006349 | I45: =IF(I26=0,0,I26/I$25) -> 0.35907783 | ... AI45: =IF(AI26=0,0,AI26/AI$25) -> 0.359034
A46: Extra-EEA | B46: =IF(B32=0,0,B32/B$25) -> 0.65303926 | C46: =IF(C32=0,0,C32/C$25) -> 0.65736082 | D46: =IF(D32=0,0,D32/D$25) -> 0.65121264 | E46: =IF(E32=0,0,E32/E$25) -> 0.64628 | F46: =IF(F32=0,0,F32/F$25) -> 0.64311573 | G46: =IF(G32=0,0,G32/G$25) -> 0.6410033 | H46: =IF(H32=0,0,H32/H$25) -> 0.63993651 | I46: =IF(I32=0,0,I32/I$25) -> 0.64092217 | ... AI46: =IF(AI32=0,0,AI32/AI$25) -> 0.640966
A48: Vehicle-efficiency - effective (kgoe/100 km) | B48: =IF(B25=0,0,100*B25/B12) -> 9376.0048 | C48: =IF(C25=0,0,100*C25/C12) -> 10068.427 | D48: =IF(D25=0,0,100*D25/D12) -> 10163.703 | E48: =IF(E25=0,0,100*E25/E12) -> 10091.811 | F48: =IF(F25=0,0,100*F25/F12) -> 9950.4379 | G48: =IF(G25=0,0,100*G25/G12) -> 10042.672 | H48: =IF(H25=0,0,100*H25/H12) -> 10464.119 | I48: =IF(I25=0,0,100*I25/I12) -> 10878.517 | ... AI48: =IF(AI25=0,0,100*AI25/AI12) -> 11255.25
A49: Intra-EEA | B49: =IF(B26=0,0,100*B26/B13) -> 7728.6983 | C49: =IF(C26=0,0,100*C26/C13) -> 8340.4092 | D49: =IF(D26=0,0,100*D26/D13) -> 8418.4349 | E49: =IF(E26=0,0,100*E26/E13) -> 8489.7344 | F49: =IF(F26=0,0,100*F26/F13) -> 8366.5431 | G49: =IF(G26=0,0,100*G26/G13) -> 8545.7533 | H49: =IF(H26=0,0,100*H26/H13) -> 8841.2151 | I49: =IF(I26=0,0,100*I26/I13) -> 9262.7891 | ... AI49: =IF(AI26=0,0,100*AI26/AI13) -> 9164.3472
...

Sheet EU27
A1: EU27 - European Union - 27 countries (from 2020) | B1: 1990 | C1: 1991 | D1: 1992 | E1: 1993 | F1: 1994 | G1: 1995 | H1: 1996 | I1: 1997 | J1: 1998 | K1: 1999 | L1: 2000 | M1: 2001 | N1: 2002 | O1: 2003 | P1: 2004 | Q1: 2005 | R1: 2006 | S1: 2007 | T1: 2008 | U1: 2009 | V1: 2010 | W1: 2011 | X1: 2012 | Y1: 2013 | Z1: 2014 | AA1: 2015 | AB1: 2016 | AC1: 2017 | AD1: 2018 | AE1: 2019 | AF1: 2020 | AG1: 2021 | AH1: 2022 | AI1: 2023
A3: Transport activity (Mtkm) | B3: =SUM(B4:B5) -> 5260244.1 | C3: =SUM(C4:C5) -> 5056483.1 | D3: =SUM(D4:D5) -> 4958716.1 | E3: =SUM(E4:E5) -> 4927827.7 | F3: =SUM(F4:F5) -> 4816013.9 | G3: =SUM(G4:G5) -> 4787796.6 | H3: =SUM(H4:H5) -> 4835398.5 | I3: =SUM(I4:I5) -> 5047205 | ... AI3: =SUM(AI4:AI5) -> 7841448.3
A4: Intra-EEA | B4: =AT!B4+BE!B4+BG!B4+CY!B4+CZ!B4+DE!B4+DK!B4+EE!B4+EL!B4+ES!B4+FI!B4+FR!B4+HR!B4+HU!B4+IE!B4+IT!B4+LT!B4+LU!B4+LV!B4+MT!B4+NL!B4+PL!B4+PT!B4+RO!B4+SE!B4+SI!B4+SK!B4 -> 733107.97 | C4: =AT!C4+BE!C4+BG!C4+CY!C4+CZ!C4+DE!C4+DK!C4+EE!C4+EL!C4+ES!C4+FI!C4+FR!C4+HR!C4+HU!C4+IE!C4+IT!C4+LT!C4+LU!C4+LV!C4+MT!C4+NL!C4+PL!C4+PT!C4+RO!C4+SE!C4+SI!C4+SK!C4 -> 685506.99 | D4: =AT!D4+BE!D4+BG!D4+CY!D4+CZ!D4+DE!D4+DK!D4+EE!D4+EL!D4+ES!D4+FI!D4+FR!D4+HR!D4+HU!D4+IE!D4+IT!D4+LT!D4+LU!D4+LV!D4+MT!D4+NL!D4+PL!D4+PT!D4+RO!D4+SE!D4+SI!D4+SK!D4 -> 689476.39 | E4: =AT!E4+BE!E4+BG!E4+CY!E4+CZ!E4+DE!E4+DK!E4+EE!E4+EL!E4+ES!E4+FI!E4+FR!E4+HR!E4+HU!E4+IE!E4+IT!E4+LT!E4+LU!E4+LV!E4+MT!E4+NL!E4+PL!E4+PT!E4+RO!E4+SE!E4+SI!E4+SK!E4 -> 679967.22 | F4: =AT!F4+BE!F4+BG!F4+CY!F4+CZ!F4+DE!F4+DK!F4+EE!F4+EL!F4+ES!F4+FI!F4+FR!F4+HR!F4+HU!F4+IE!F4+IT!F4+LT!F4+LU!F4+LV!F4+MT!F4+NL!F4+PL!F4+PT!F4+RO!F4+SE!F4+SI!F4+SK!F4 -> 671046.38 | G4: =AT!G4+BE!G4+BG!G4+CY!G4+CZ!G4+DE!G4+DK!G4+EE!G4+EL!G4+ES!G4+FI!G4+FR!G4+HR!G4+HU!G4+IE!G4+IT!G4+LT!G4+LU!G4+LV!G4+MT!G4+NL!G4+PL!G4+PT!G4+RO!G4+SE!G4+SI!G4+SK!G4 -> 650481.21 | H4: =AT!H4+BE!H4+BG!H4+CY!H4+CZ!H4+DE!H4+DK!H4+EE!H4+EL!H4+ES!H4+FI!H4+FR!H4+HR!H4+HU!H4+IE!H4+IT!H4+LT!H4+LU!H4+LV!H4+MT!H4+NL!H4+PL!H4+PT!H4+RO!H4+SE!H4+SI!H4+SK!H4 -> 665205.69 | I4: =AT!I4+BE!I4+BG!I4+CY!I4+CZ!I4+DE!I4+DK!I4+EE!I4+EL!I4+ES!I4+FI!I4+FR!I4+HR!I4+HU!I4+IE!I4+IT!I4+LT!I4+LU!I4+LV!I4+MT!I4+NL!I4+PL!I4+PT!I4+RO!I4+SE!I4+SI!I4+SK!I4 -> 672111.47 | ... AI4: =AT!AI4+BE!AI4+BG!AI4+CY!AI4+CZ!AI4+DE!AI4+DK!AI4+EE!AI4+EL!AI4+ES!AI4+FI!AI4+FR!AI4+HR!AI4+HU!AI4+IE!AI4+IT!AI4+LT!AI4+LU!AI4+LV!AI4+MT!AI4+NL!AI4+PL!AI4+PT!AI4+RO!AI4+SE!AI4+SI!AI4+SK!AI4 -> 1009046.4
A5: Extra-EEA | B5: =AT!B5+BE!B5+BG!B5+CY!B5+CZ!B5+DE!B5+DK!B5+EE!B5+EL!B5+ES!B5+FI!B5+FR!B5+HR!B5+HU!B5+IE!B5+IT!B5+LT!B5+LU!B5+LV!B5+MT!B5+NL!B5+PL!B5+PT!B5+RO!B5+SE!B5+SI!B5+SK!B5 -> 4527136.2 | C5: =AT!C5+BE!C5+BG!C5+CY!C5+CZ!C5+DE!C5+DK!C5+EE!C5+EL!C5+ES!C5+FI!C5+FR!C5+HR!C5+HU!C5+IE!C5+IT!C5+LT!C5+LU!C5+LV!C5+MT!C5+NL!C5+PL!C5+PT!C5+RO!C5+SE!C5+SI!C5+SK!C5 -> 4370976.1 | D5: =AT!D5+BE!D5+BG!D5+CY!D5+CZ!D5+DE!D5+DK!D5+EE!D5+EL!D5+ES!D5+FI!D5+FR!D5+HR!D5+HU!D5+IE!D5+IT!D5+LT!D5+LU!D5+LV!D5+MT!D5+NL!D5+PL!D5+PT!D5+RO!D5+SE!D5+SI!D5+SK!D5 -> 4269239.7 | E5: =AT!E5+BE!E5+BG!E5+CY!E5+CZ!E5+DE!E5+DK!E5+EE!E5+EL!E5+ES!E5+FI!E5+FR!E5+HR!E5+HU!E5+IE!E5+IT!E5+LT!E5+LU!E5+LV!E5+MT!E5+NL!E5+PL!E5+PT!E5+RO!E5+SE!E5+SI!E5+SK!E5 -> 4247860.5 | F5: =AT!F5+BE!F5+BG!F5+CY!F5+CZ!F5+DE!F5+DK!F5+EE!F5+EL!F5+ES!F5+FI!F5+FR!F5+HR!F5+HU!F5+IE!F5+IT!F5+LT!F5+LU!F5+LV!F5+MT!F5+NL!F5+PL!F5+PT!F5+RO!F5+SE!F5+SI!F5+SK!F5 -> 4144967.5 | G5: =AT!G5+BE!G5+BG!G5+CY!G5+CZ!G5+DE!G5+DK!G5+EE!G5+EL!G5+ES!G5+FI!G5+FR!G5+HR!G5+HU!G5+IE!G5+IT!G5+LT!G5+LU!G5+LV!G5+MT!G5+NL!G5+PL!G5+PT!G5+RO!G5+SE!G5+SI!G5+SK!G5 -> 4137315.4 | H5: =AT!H5+BE!H5+BG!H5+CY!H5+CZ!H5+DE!H5+DK!H5+EE!H5+EL!H5+ES!H5+FI!H5+FR!H5+HR!H5+HU!H5+IE!H5+IT!H5+LT!H5+LU!H5+LV!H5+MT!H5+NL!H5+PL!H5+PT!H5+RO!H5+SE!H5+SI!H5+SK!H5 -> 4170192.8 | I5: =AT!I5+BE!I5+BG!I5+CY!I5+CZ!I5+DE!I5+DK!I5+EE!I5+EL!I5+ES!I5+FI!I5+FR!I5+HR!I5+HU!I5+IE!I5+IT!I5+LT!I5+LU!I5+LV!I5+MT!I5+NL!I5+PL!I5+PT!I5+RO!I5+SE!I5+SI!I5+SK!I5 -> 4375093.5 | ... AI5: =AT!AI5+BE!AI5+BG!AI5+CY!AI5+CZ!AI5+DE!AI5+DK!AI5+EE!AI5+EL!AI5+ES!AI5+FI!AI5+FR!AI5+HR!AI5+HU!AI5+IE!AI5+IT!AI5+LT!AI5+LU!AI5+LV!AI5+MT!AI5+NL!AI5+PL!AI5+PT!AI5+RO!AI5+SE!AI5+SI!AI5+SK!AI5 -> 6832401.8
A6: * Considering both inwards and outwards flows of goods transported with half of the distance of the voyages (thus the total distance for Intra-EU in the EU aggregation)
A8: Market shares of activity (% of tkm) | B8: =IF(B3=0,0,B3/B$3) -> 1 | C8: =IF(C3=0,0,C3/C$3) -> 1 | D8: =IF(D3=0,0,D3/D$3) -> 1 | E8: =IF(E3=0,0,E3/E$3) -> 1 | F8: =IF(F3=0,0,F3/F$3) -> 1 | G8: =IF(G3=0,0,G3/G$3) -> 1 | H8: =IF(H3=0,0,H3/H$3) -> 1 | I8: =IF(I3=0,0,I3/I$3) -> 1 | ... AI8: =IF(AI3=0,0,AI3/AI$3) -> 1
A9: Intra-EEA | B9: =IF(B4=0,0,B4/B$3) -> 0.13936767 | C9: =IF(C4=0,0,C4/C$3) -> 0.13556992 | D9: =IF(D4=0,0,D4/D$3) -> 0.13904333 | E9: =IF(E4=0,0,E4/E$3) -> 0.13798518 | F9: =IF(F4=0,0,F4/F$3) -> 0.13933647 | G9: =IF(G4=0,0,G4/G$3) -> 0.13586233 | H9: =IF(H4=0,0,H4/H$3) -> 0.13756998 | I9: =IF(I4=0,0,I4/I$3) -> 0.13316508 | ... AI9: =IF(AI4=0,0,AI4/AI$3) -> 0.12868113
A10: Extra-EEA | B10: =IF(B5=0,0,B5/B$3) -> 0.86063233 | C10: =IF(C5=0,0,C5/C$3) -> 0.86443008 | D10: =IF(D5=0,0,D5/D$3) -> 0.86095667 | E10: =IF(E5=0,0,E5/E$3) -> 0.86201482 | F10: =IF(F5=0,0,F5/F$3) -> 0.86066353 | G10: =IF(G5=0,0,G5/G$3) -> 0.86413767 | H10: =IF(H5=0,0,H5/H$3) -> 0.86243002 | I10: =IF(I5=0,0,I5/I$3) -> 0.86683492 | ... AI10: =IF(AI5=0,0,AI5/AI$3) -> 0.87131887
A12: Vehicle-km (Mvkm) | B12: =SUM(B13:B14) -> 342.67916 | C12: =SUM(C13:C14) -> 316.94217 | D12: =SUM(D13:D14) -> 314.34312 | E12: =SUM(E13:E14) -> 314.65794 | F12: =SUM(F13:F14) -> 313.43495 | G12: =SUM(G13:G14) -> 308.94677 | H12: =SUM(H13:H14) -> 309.58308 | I12: =SUM(I13:I14) -> 315.09587 | ... AI12: =SUM(AI13:AI14) -> 327.50104
A13: Intra-EEA | B13: =AT!B13+BE!B13+BG!B13+CY!B13+CZ!B13+DE!B13+DK!B13+EE!B13+EL!B13+ES!B13+FI!B13+FR!B13+HR!B13+HU!B13+IE!B13+IT!B13+LT!B13+LU!B13+LV!B13+MT!B13+NL!B13+PL!B13+PT!B13+RO!B13+SE!B13+SI!B13+SK!B13 -> 142.34759 | C13: =AT!C13+BE!C13+BG!C13+CY!C13+CZ!C13+DE!C13+DK!C13+EE!C13+EL!C13+ES!C13+FI!C13+FR!C13+HR!C13+HU!C13+IE!C13+IT!C13+LT!C13+LU!C13+LV!C13+MT!C13+NL!C13+PL!C13+PT!C13+RO!C13+SE!C13+SI!C13+SK!C13 -> 129.29935 | D13: =AT!D13+BE!D13+BG!D13+CY!D13+CZ!D13+DE!D13+DK!D13+EE!D13+EL!D13+ES!D13+FI!D13+FR!D13+HR!D13+HU!D13+IE!D13+IT!D13+LT!D13+LU!D13+LV!D13+MT!D13+NL!D13+PL!D13+PT!D13+RO!D13+SE!D13+SI!D13+SK!D13 -> 130.26693 | E13: =AT!E13+BE!E13+BG!E13+CY!E13+CZ!E13+DE!E13+DK!E13+EE!E13+EL!E13+ES!E13+FI!E13+FR!E13+HR!E13+HU!E13+IE!E13+IT!E13+LT!E13+LU!E13+LV!E13+MT!E13+NL!E13+PL!E13+PT!E13+RO!E13+SE!E13+SI!E13+SK!E13 -> 130.0753 | F13: =AT!F13+BE!F13+BG!F13+CY!F13+CZ!F13+DE!F13+DK!F13+EE!F13+EL!F13+ES!F13+FI!F13+FR!F13+HR!F13+HU!F13+IE!F13+IT!F13+LT!F13+LU!F13+LV!F13+MT!F13+NL!F13+PL!F13+PT!F13+RO!F13+SE!F13+SI!F13+SK!F13 -> 130.66431 | G13: =AT!G13+BE!G13+BG!G13+CY!G13+CZ!G13+DE!G13+DK!G13+EE!G13+EL!G13+ES!G13+FI!G13+FR!G13+HR!G13+HU!G13+IE!G13+IT!G13+LT!G13+LU!G13+LV!G13+MT!G13+NL!G13+PL!G13+PT!G13+RO!G13+SE!G13+SI!G13+SK!G13 -> 127.37116 | H13: =AT!H13+BE!H13+BG!H13+CY!H13+CZ!H13+DE!H13+DK!H13+EE!H13+EL!H13+ES!H13+FI!H13+FR!H13+HR!H13+HU!H13+IE!H13+IT!H13+LT!H13+LU!H13+LV!H13+MT!H13+NL!H13+PL!H13+PT!H13+RO!H13+SE!H13+SI!H13+SK!H13 -> 128.43417 | I13: =AT!I13+BE!I13+BG!I13+CY!I13+CZ!I13+DE!I13+DK!I13+EE!I13+EL!I13+ES!I13+FI!I13+FR!I13+HR!I13+HU!I13+IE!I13+IT!I13+LT!I13+LU!I13+LV!I13+MT!I13+NL!I13+PL!I13+PT!I13+RO!I13+SE!I13+SI!I13+SK!I13 -> 128.34228 | ... AI13: =AT!AI13+BE!AI13+BG!AI13+CY!AI13+CZ!AI13+DE!AI13+DK!AI13+EE!AI13+EL!AI13+ES!AI13+FI!AI13+FR!AI13+HR!AI13+HU!AI13+IE!AI13+IT!AI13+LT!AI13+LU!AI13+LV!AI13+MT!AI13+NL!AI13+PL!AI13+PT!AI13+RO!AI13+SE!AI13+SI!AI13+SK!AI13 -> 139.49633
A14: Extra-EEA | B14: =AT!B14+BE!B14+BG!B14+CY!B14+CZ!B14+DE!B14+DK!B14+EE!B14+EL!B14+ES!B14+FI!B14+FR!B14+HR!B14+HU!B14+IE!B14+IT!B14+LT!B14+LU!B14+LV!B14+MT!B14+NL!B14+PL!B14+PT!B14+RO!B14+SE!B14+SI!B14+SK!B14 -> 200.33158 | C14: =AT!C14+BE!C14+BG!C14+CY!C14+CZ!C14+DE!C14+DK!C14+EE!C14+EL!C14+ES!C14+FI!C14+FR!C14+HR!C14+HU!C14+IE!C14+IT!C14+LT!C14+LU!C14+LV!C14+MT!C14+NL!C14+PL!C14+PT!C14+RO!C14+SE!C14+SI!C14+SK!C14 -> 187.64282 | D14: =AT!D14+BE!D14+BG!D14+CY!D14+CZ!D14+DE!D14+DK!D14+EE!D14+EL!D14+ES!D14+FI!D14+FR!D14+HR!D14+HU!D14+IE!D14+IT!D14+LT!D14+LU!D14+LV!D14+MT!D14+NL!D14+PL!D14+PT!D14+RO!D14+SE!D14+SI!D14+SK!D14 -> 184.07619 | E14: =AT!E14+BE!E14+BG!E14+CY!E14+CZ!E14+DE!E14+DK!E14+EE!E14+EL!E14+ES!E14+FI!E14+FR!E14+HR!E14+HU!E14+IE!E14+IT!E14+LT!E14+LU!E14+LV!E14+MT!E14+NL!E14+PL!E14+PT!E14+RO!E14+SE!E14+SI!E14+SK!E14 -> 184.58264 | F14: =AT!F14+BE!F14+BG!F14+CY!F14+CZ!F14+DE!F14+DK!F14+EE!F14+EL!F14+ES!F14+FI!F14+FR!F14+HR!F14+HU!F14+IE!F14+IT!F14+LT!F14+LU!F14+LV!F14+MT!F14+NL!F14+PL!F14+PT!F14+RO!F14+SE!F14+SI!F14+SK!F14 -> 182.77064 | G14: =AT!G14+BE!G14+BG!G14+CY!G14+CZ!G14+DE!G14+DK!G14+EE!G14+EL!G14+ES!G14+FI!G14+FR!G14+HR!G14+HU!G14+IE!G14+IT!G14+LT!G14+LU!G14+LV!G14+MT!G14+NL!G14+PL!G14+PT!G14+RO!G14+SE!G14+SI!G14+SK!G14 -> 181.57561 | H14: =AT!H14+BE!H14+BG!H14+CY!H14+CZ!H14+DE!H14+DK!H14+EE!H14+EL!H14+ES!H14+FI!H14+FR!H14+HR!H14+HU!H14+IE!H14+IT!H14+LT!H14+LU!H14+LV!H14+MT!H14+NL!H14+PL!H14+PT!H14+RO!H14+SE!H14+SI!H14+SK!H14 -> 181.14891 | I14: =AT!I14+BE!I14+BG!I14+CY!I14+CZ!I14+DE!I14+DK!I14+EE!I14+EL!I14+ES!I14+FI!I14+FR!I14+HR!I14+HU!I14+IE!I14+IT!I14+LT!I14+LU!I14+LV!I14+MT!I14+NL!I14+PL!I14+PT!I14+RO!I14+SE!I14+SI!I14+SK!I14 -> 186.75359 | ... AI14: =AT!AI14+BE!AI14+BG!AI14+CY!AI14+CZ!AI14+DE!AI14+DK!AI14+EE!AI14+EL!AI14+ES!AI14+FI!AI14+FR!AI14+HR!AI14+HU!AI14+IE!AI14+IT!AI14+LT!AI14+LU!AI14+LV!AI14+MT!AI14+NL!AI14+PL!AI14+PT!AI14+RO!AI14+SE!AI14+SI!AI14+SK!AI14 -> 188.0047
A15: * Considering half of the distance of the voyages (thus the total distance for Intra-EU in the EU aggregation)
A17: Market shares of vehicle km (% of km) | B17: =IF(B12=0,0,B12/B$12) -> 1 | C17: =IF(C12=0,0,C12/C$12) -> 1 | D17: =IF(D12=0,0,D12/D$12) -> 1 | E17: =IF(E12=0,0,E12/E$12) -> 1 | F17: =IF(F12=0,0,F12/F$12) -> 1 | G17: =IF(G12=0,0,G12/G$12) -> 1 | H17: =IF(H12=0,0,H12/H$12) -> 1 | I17: =IF(I12=0,0,I12/I$12) -> 1 | ... AI17: =IF(AI12=0,0,AI12/AI$12) -> 1
A18: Intra-EEA | B18: =IF(B13=0,0,B13/B$12) -> 0.4153961 | C18: =IF(C13=0,0,C13/C$12) -> 0.40795882 | D18: =IF(D13=0,0,D13/D$12) -> 0.41441001 | E18: =IF(E13=0,0,E13/E$12) -> 0.41338637 | F18: =IF(F13=0,0,F13/F$12) -> 0.41687855 | G18: =IF(G13=0,0,G13/G$12) -> 0.41227543 | H18: =IF(H13=0,0,H13/H$12) -> 0.41486172 | I18: =IF(I13=0,0,I13/I$12) -> 0.40731184 | ... AI18: =IF(AI13=0,0,AI13/AI$12) -> 0.42594165
A19: Extra-EEA | B19: =IF(B14=0,0,B14/B$12) -> 0.5846039 | C19: =IF(C14=0,0,C14/C$12) -> 0.59204118 | D19: =IF(D14=0,0,D14/D$12) -> 0.58558999 | E19: =IF(E14=0,0,E14/E$12) -> 0.58661363 | F19: =IF(F14=0,0,F14/F$12) -> 0.58312145 | G19: =IF(G14=0,0,G14/G$12) -> 0.58772457 | H19: =IF(H14=0,0,H14/H$12) -> 0.58513828 | I19: =IF(I14=0,0,I14/I$12) -> 0.59268816 | ... AI19: =IF(AI14=0,0,AI14/AI$12) -> 0.57405835
A21: Load factor of vessels (t/movement) | B21: =IF(B3=0,0,B3/B12) -> 15350.347 | C21: =IF(C3=0,0,C3/C12) -> 15953.961 | D21: =IF(D3=0,0,D3/D12) -> 15774.852 | E21: =IF(E3=0,0,E3/E12) -> 15660.904 | F21: =IF(F3=0,0,F3/F12) -> 15365.274 | G21: =IF(G3=0,0,G3/G12) -> 15497.157 | H21: =IF(H3=0,0,H3/H12) -> 15619.066 | I21: =IF(I3=0,0,I3/I12) -> 16017.998 | ... AI21: =IF(AI3=0,0,AI3/AI12) -> 23943.278
A22: Intra-EEA | B22: =IF(B4=0,0,B4/B13) -> 5150.1257 | C22: =IF(C4=0,0,C4/C13) -> 5301.7047 | D22: =IF(D4=0,0,D4/D13) -> 5292.7967 | E22: =IF(E4=0,0,E4/E13) -> 5227.489 | F22: =IF(F4=0,0,F4/F13) -> 5135.6517 | G22: =IF(G4=0,0,G4/G13) -> 5106.974 | H22: =IF(H4=0,0,H4/H13) -> 5179.3514 | I22: =IF(I4=0,0,I4/I13) -> 5236.8673 | ... AI22: =IF(AI4=0,0,AI4/AI13) -> 7233.4979
A23: Extra-EEA | B23: =IF(B5=0,0,B5/B14) -> 22598.216 | C23: =IF(C5=0,0,C5/C14) -> 23294.13 | D23: =IF(D5=0,0,D5/D14) -> 23192.787 | E23: =IF(E5=0,0,E5/E14) -> 23013.326 | F23: =IF(F5=0,0,F5/F14) -> 22678.519 | G23: =IF(G5=0,0,G5/G14) -> 22785.635 | H23: =IF(H5=0,0,H5/H14) -> 23020.8 | I23: =IF(I5=0,0,I5/I14) -> 23427.092 | ... AI23: =IF(AI5=0,0,AI5/AI14) -> 36341.654
A25: Total energy consumption (ktoe) | B25: =SUM(B26,B32) -> 33136.348 | C25: =SUM(C26,C32) -> 32882.736 | D25: =SUM(D26,D32) -> 33177.888 | E25: =SUM(E26,E32) -> 33059.931 | F25: =SUM(F26,F32) -> 32585.648 | G25: =SUM(G26,G32) -> 32778.737 | H25: =SUM(H26,H32) -> 34472.748 | I25: =SUM(I26,I32) -> 36998.102 | ... AI25: =SUM(AI26,AI32) -> 39293.935
A26: Intra-EEA | B26: =SUM(B27:B31) -> 11422.605 | C26: =SUM(C27:C31) -> 11199.642 | D26: =SUM(D27:D31) -> 11491.38 | E26: =SUM(E27:E31) -> 11610.756 | F26: =SUM(F27:F31) -> 11540.026 | G26: =SUM(G27:G31) -> 11659.132 | H26: =SUM(H27:H31) -> 12288.464 | I26: =SUM(I27:I31) -> 13128.574 | ... AI26: =SUM(AI27:AI31) -> 14068.829
A27: Gas oil and diesel oil (excluding biofuel portion) | B27: =AT!B27+BE!B27+BG!B27+CY!B27+CZ!B27+DE!B27+DK!B27+EE!B27+EL!B27+ES!B27+FI!B27+FR!B27+HR!B27+HU!B27+IE!B27+IT!B27+LT!B27+LU!B27+LV!B27+MT!B27+NL!B27+PL!B27+PT!B27+RO!B27+SE!B27+SI!B27+SK!B27 -> 5209.4667 | C27: =AT!C27+BE!C27+BG!C27+CY!C27+CZ!C27+DE!C27+DK!C27+EE!C27+EL!C27+ES!C27+FI!C27+FR!C27+HR!C27+HU!C27+IE!C27+IT!C27+LT!C27+LU!C27+LV!C27+MT!C27+NL!C27+PL!C27+PT!C27+RO!C27+SE!C27+SI!C27+SK!C27 -> 5188.5184 | D27: =AT!D27+BE!D27+BG!D27+CY!D27+CZ!D27+DE!D27+DK!D27+EE!D27+EL!D27+ES!D27+FI!D27+FR!D27+HR!D27+HU!D27+IE!D27+IT!D27+LT!D27+LU!D27+LV!D27+MT!D27+NL!D27+PL!D27+PT!D27+RO!D27+SE!D27+SI!D27+SK!D27 -> 5527.3687 | E27: =AT!E27+BE!E27+BG!E27+CY!E27+CZ!E27+DE!E27+DK!E27+EE!E27+EL!E27+ES!E27+FI!E27+FR!E27+HR!E27+HU!E27+IE!E27+IT!E27+LT!E27+LU!E27+LV!E27+MT!E27+NL!E27+PL!E27+PT!E27+RO!E27+SE!E27+SI!E27+SK!E27 -> 5051.6813 | F27: =AT!F27+BE!F27+BG!F27+CY!F27+CZ!F27+DE!F27+DK!F27+EE!F27+EL!F27+ES!F27+FI!F27+FR!F27+HR!F27+HU!F27+IE!F27+IT!F27+LT!F27+LU!F27+LV!F27+MT!F27+NL!F27+PL!F27+PT!F27+RO!F27+SE!F27+SI!F27+SK!F27 -> 4861.6807 | G27: =AT!G27+BE!G27+BG!G27+CY!G27+CZ!G27+DE!G27+DK!G27+EE!G27+EL!G27+ES!G27+FI!G27+FR!G27+HR!G27+HU!G27+IE!G27+IT!G27+LT!G27+LU!G27+LV!G27+MT!G27+NL!G27+PL!G27+PT!G27+RO!G27+SE!G27+SI!G27+SK!G27 -> 5339.6796 | H27: =AT!H27+BE!H27+BG!H27+CY!H27+CZ!H27+DE!H27+DK!H27+EE!H27+EL!H27+ES!H27+FI!H27+FR!H27+HR!H27+HU!H27+IE!H27+IT!H27+LT!H27+LU!H27+LV!H27+MT!H27+NL!H27+PL!H27+PT!H27+RO!H27+SE!H27+SI!H27+SK!H27 -> 5684.6865 | I27: =AT!I27+BE!I27+BG!I27+CY!I27+CZ!I27+DE!I27+DK!I27+EE!I27+EL!I27+ES!I27+FI!I27+FR!I27+HR!I27+HU!I27+IE!I27+IT!I27+LT!I27+LU!I27+LV!I27+MT!I27+NL!I27+PL!I27+PT!I27+RO!I27+SE!I27+SI!I27+SK!I27 -> 6006.9822 | ... AI27: =AT!AI27+BE!AI27+BG!AI27+CY!AI27+CZ!AI27+DE!AI27+DK!AI27+EE!AI27+EL!AI27+ES!AI27+FI!AI27+FR!AI27+HR!AI27+HU!AI27+IE!AI27+IT!AI27+LT!AI27+LU!AI27+LV!AI27+MT!AI27+NL!AI27+PL!AI27+PT!AI27+RO!AI27+SE!AI27+SI!AI27+SK!AI27 -> 6596.3587
A28: Fuel oil and Other oil products | B28: =AT!B28+BE!B28+BG!B28+CY!B28+CZ!B28+DE!B28+DK!B28+EE!B28+EL!B28+ES!B28+FI!B28+FR!B28+HR!B28+HU!B28+IE!B28+IT!B28+LT!B28+LU!B28+LV!B28+MT!B28+NL!B28+PL!B28+PT!B28+RO!B28+SE!B28+SI!B28+SK!B28 -> 6213.1385 | C28: =AT!C28+BE!C28+BG!C28+CY!C28+CZ!C28+DE!C28+DK!C28+EE!C28+EL!C28+ES!C28+FI!C28+FR!C28+HR!C28+HU!C28+IE!C28+IT!C28+LT!C28+LU!C28+LV!C28+MT!C28+NL!C28+PL!C28+PT!C28+RO!C28+SE!C28+SI!C28+SK!C28 -> 6011.1231 | D28: =AT!D28+BE!D28+BG!D28+CY!D28+CZ!D28+DE!D28+DK!D28+EE!D28+EL!D28+ES!D28+FI!D28+FR!D28+HR!D28+HU!D28+IE!D28+IT!D28+LT!D28+LU!D28+LV!D28+MT!D28+NL!D28+PL!D28+PT!D28+RO!D28+SE!D28+SI!D28+SK!D28 -> 5964.0117 | E28: =AT!E28+BE!E28+BG!E28+CY!E28+CZ!E28+DE!E28+DK!E28+EE!E28+EL!E28+ES!E28+FI!E28+FR!E28+HR!E28+HU!E28+IE!E28+IT!E28+LT!E28+LU!E28+LV!E28+MT!E28+NL!E28+PL!E28+PT!E28+RO!E28+SE!E28+SI!E28+SK!E28 -> 6559.0744 | F28: =AT!F28+BE!F28+BG!F28+CY!F28+CZ!F28+DE!F28+DK!F28+EE!F28+EL!F28+ES!F28+FI!F28+FR!F28+HR!F28+HU!F28+IE!F28+IT!F28+LT!F28+LU!F28+LV!F28+MT!F28+NL!F28+PL!F28+PT!F28+RO!F28+SE!F28+SI!F28+SK!F28 -> 6678.3456 | G28: =AT!G28+BE!G28+BG!G28+CY!G28+CZ!G28+DE!G28+DK!G28+EE!G28+EL!G28+ES!G28+FI!G28+FR!G28+HR!G28+HU!G28+IE!G28+IT!G28+LT!G28+LU!G28+LV!G28+MT!G28+NL!G28+PL!G28+PT!G28+RO!G28+SE!G28+SI!G28+SK!G28 -> 6319.4526 | H28: =AT!H28+BE!H28+BG!H28+CY!H28+CZ!H28+DE!H28+DK!H28+EE!H28+EL!H28+ES!H28+FI!H28+FR!H28+HR!H28+HU!H28+IE!H28+IT!H28+LT!H28+LU!H28+LV!H28+MT!H28+NL!H28+PL!H28+PT!H28+RO!H28+SE!H28+SI!H28+SK!H28 -> 6603.7771 | I28: =AT!I28+BE!I28+BG!I28+CY!I28+CZ!I28+DE!I28+DK!I28+EE!I28+EL!I28+ES!I28+FI!I28+FR!I28+HR!I28+HU!I28+IE!I28+IT!I28+LT!I28+LU!I28+LV!I28+MT!I28+NL!I28+PL!I28+PT!I28+RO!I28+SE!I28+SI!I28+SK!I28 -> 7121.5916 | ... AI28: =AT!AI28+BE!AI28+BG!AI28+CY!AI28+CZ!AI28+DE!AI28+DK!AI28+EE!AI28+EL!AI28+ES!AI28+FI!AI28+FR!AI28+HR!AI28+HU!AI28+IE!AI28+IT!AI28+LT!AI28+LU!AI28+LV!AI28+MT!AI28+NL!AI28+PL!AI28+PT!AI28+RO!AI28+SE!AI28+SI!AI28+SK!AI28 -> 7249.5616
A29: Blended biofuels | B29: =AT!B29+BE!B29+BG!B29+CY!B29+CZ!B29+DE!B29+DK!B29+EE!B29+EL!B29+ES!B29+FI!B29+FR!B29+HR!B29+HU!B29+IE!B29+IT!B29+LT!B29+LU!B29+LV!B29+MT!B29+NL!B29+PL!B29+PT!B29+RO!B29+SE!B29+SI!B29+SK!B29 -> 0 | C29: =AT!C29+BE!C29+BG!C29+CY!C29+CZ!C29+DE!C29+DK!C29+EE!C29+EL!C29+ES!C29+FI!C29+FR!C29+HR!C29+HU!C29+IE!C29+IT!C29+LT!C29+LU!C29+LV!C29+MT!C29+NL!C29+PL!C29+PT!C29+RO!C29+SE!C29+SI!C29+SK!C29 -> 0 | D29: =AT!D29+BE!D29+BG!D29+CY!D29+CZ!D29+DE!D29+DK!D29+EE!D29+EL!D29+ES!D29+FI!D29+FR!D29+HR!D29+HU!D29+IE!D29+IT!D29+LT!D29+LU!D29+LV!D29+MT!D29+NL!D29+PL!D29+PT!D29+RO!D29+SE!D29+SI!D29+SK!D29 -> 0 | E29: =AT!E29+BE!E29+BG!E29+CY!E29+CZ!E29+DE!E29+DK!E29+EE!E29+EL!E29+ES!E29+FI!E29+FR!E29+HR!E29+HU!E29+IE!E29+IT!E29+LT!E29+LU!E29+LV!E29+MT!E29+NL!E29+PL!E29+PT!E29+RO!E29+SE!E29+SI!E29+SK!E29 -> 0 | F29: =AT!F29+BE!F29+BG!F29+CY!F29+CZ!F29+DE!F29+DK!F29+EE!F29+EL!F29+ES!F29+FI!F29+FR!F29+HR!F29+HU!F29+IE!F29+IT!F29+LT!F29+LU!F29+LV!F29+MT!F29+NL!F29+PL!F29+PT!F29+RO!F29+SE!F29+SI!F29+SK!F29 -> 0 | G29: =AT!G29+BE!G29+BG!G29+CY!G29+CZ!G29+DE!G29+DK!G29+EE!G29+EL!G29+ES!G29+FI!G29+FR!G29+HR!G29+HU!G29+IE!G29+IT!G29+LT!G29+LU!G29+LV!G29+MT!G29+NL!G29+PL!G29+PT!G29+RO!G29+SE!G29+SI!G29+SK!G29 -> 0 | H29: =AT!H29+BE!H29+BG!H29+CY!H29+CZ!H29+DE!H29+DK!H29+EE!H29+EL!H29+ES!H29+FI!H29+FR!H29+HR!H29+HU!H29+IE!H29+IT!H29+LT!H29+LU!H29+LV!H29+MT!H29+NL!H29+PL!H29+PT!H29+RO!H29+SE!H29+SI!H29+SK!H29 -> 0 | I29: =AT!I29+BE!I29+BG!I29+CY!I29+CZ!I29+DE!I29+DK!I29+EE!I29+EL!I29+ES!I29+FI!I29+FR!I29+HR!I29+HU!I29+IE!I29+IT!I29+LT!I29+LU!I29+LV!I29+MT!I29+NL!I29+PL!I29+PT!I29+RO!I29+SE!I29+SI!I29+SK!I29 -> 0 | ... AI29: =AT!AI29+BE!AI29+BG!AI29+CY!AI29+CZ!AI29+DE!AI29+DK!AI29+EE!AI29+EL!AI29+ES!AI29+FI!AI29+FR!AI29+HR!AI29+HU!AI29+IE!AI29+IT!AI29+LT!AI29+LU!AI29+LV!AI29+MT!AI29+NL!AI29+PL!AI29+PT!AI29+RO!AI29+SE!AI29+SI!AI29+SK!AI29 -> 74.519223
A30: Natural gas | B30: =AT!B30+BE!B30+BG!B30+CY!B30+CZ!B30+DE!B30+DK!B30+EE!B30+EL!B30+ES!B30+FI!B30+FR!B30+HR!B30+HU!B30+IE!B30+IT!B30+LT!B30+LU!B30+LV!B30+MT!B30+NL!B30+PL!B30+PT!B30+RO!B30+SE!B30+SI!B30+SK!B30 -> 0 | C30: =AT!C30+BE!C30+BG!C30+CY!C30+CZ!C30+DE!C30+DK!C30+EE!C30+EL!C30+ES!C30+FI!C30+FR!C30+HR!C30+HU!C30+IE!C30+IT!C30+LT!C30+LU!C30+LV!C30+MT!C30+NL!C30+PL!C30+PT!C30+RO!C30+SE!C30+SI!C30+SK!C30 -> 0 | D30: =AT!D30+BE!D30+BG!D30+CY!D30+CZ!D30+DE!D30+DK!D30+EE!D30+EL!D30+ES!D30+FI!D30+FR!D30+HR!D30+HU!D30+IE!D30+IT!D30+LT!D30+LU!D30+LV!D30+MT!D30+NL!D30+PL!D30+PT!D30+RO!D30+SE!D30+SI!D30+SK!D30 -> 0 | E30: =AT!E30+BE!E30+BG!E30+CY!E30+CZ!E30+DE!E30+DK!E30+EE!E30+EL!E30+ES!E30+FI!E30+FR!E30+HR!E30+HU!E30+IE!E30+IT!E30+LT!E30+LU!E30+LV!E30+MT!E30+NL!E30+PL!E30+PT!E30+RO!E30+SE!E30+SI!E30+SK!E30 -> 0 | F30: =AT!F30+BE!F30+BG!F30+CY!F30+CZ!F30+DE!F30+DK!F30+EE!F30+EL!F30+ES!F30+FI!F30+FR!F30+HR!F30+HU!F30+IE!F30+IT!F30+LT!F30+LU!F30+LV!F30+MT!F30+NL!F30+PL!F30+PT!F30+RO!F30+SE!F30+SI!F30+SK!F30 -> 0 | G30: =AT!G30+BE!G30+BG!G30+CY!G30+CZ!G30+DE!G30+DK!G30+EE!G30+EL!G30+ES!G30+FI!G30+FR!G30+HR!G30+HU!G30+IE!G30+IT!G30+LT!G30+LU!G30+LV!G30+MT!G30+NL!G30+PL!G30+PT!G30+RO!G30+SE!G30+SI!G30+SK!G30 -> 0 | H30: =AT!H30+BE!H30+BG!H30+CY!H30+CZ!H30+DE!H30+DK!H30+EE!H30+EL!H30+ES!H30+FI!H30+FR!H30+HR!H30+HU!H30+IE!H30+IT!H30+LT!H30+LU!H30+LV!H30+MT!H30+NL!H30+PL!H30+PT!H30+RO!H30+SE!H30+SI!H30+SK!H30 -> 0 | I30: =AT!I30+BE!I30+BG!I30+CY!I30+CZ!I30+DE!I30+DK!I30+EE!I30+EL!I30+ES!I30+FI!I30+FR!I30+HR!I30+HU!I30+IE!I30+IT!I30+LT!I30+LU!I30+LV!I30+MT!I30+NL!I30+PL!I30+PT!I30+RO!I30+SE!I30+SI!I30+SK!I30 -> 0 | ... AI30: =AT!AI30+BE!AI30+BG!AI30+CY!AI30+CZ!AI30+DE!AI30+DK!AI30+EE!AI30+EL!AI30+ES!AI30+FI!AI30+FR!AI30+HR!AI30+HU!AI30+IE!AI30+IT!AI30+LT!AI30+LU!AI30+LV!AI30+MT!AI30+NL!AI30+PL!AI30+PT!AI30+RO!AI30+SE!AI30+SI!AI30+SK!AI30 -> 146.00529
