Workbook

Sheet cover
B6: JRC-IDEES-2023 - Integrated Database of the European Energy System
C15: CO2 Emissions - comparison to UNFCC submissions
L28: Prepared by JRC C.6
L30: 45967.481
L31: v2023-1.00
B33: Legal Notice
B35: The information made available is property of the Joint Research Centre of the European Commission.
B36: Neither the European Commission nor any person acting on behalf of the Commission is responsible for the use which might be made of this information.
B38: Use conditions
B39: This work is licensed under
B40: CC BY 4.0

Sheet summary
B1: 2000 | C1: 2001 | D1: 2002 | E1: 2003 | F1: 2004 | G1: 2005 | H1: 2006 | I1: 2007 | J1: 2008 | K1: 2009 | L1: 2010 | M1: 2011 | N1: 2012 | O1: 2013 | P1: 2014 | Q1: 2015 | R1: 2016 | S1: 2017 | T1: 2018 | U1: 2019 | V1: 2020 | W1: 2021 | X1: 2022 | Y1: 2023
A3: Total UNFCCC CO2 emissions without LULUCF, with international transport (kt CO2)
A4: EU27 | B4: ='EU27'!B$3 -> 3816857.2 | C4: ='EU27'!C$3 -> 3877827.2 | D4: ='EU27'!D$3 -> 3882075.7 | E4: ='EU27'!E$3 -> 3967540.4 | F4: ='EU27'!F$3 -> 3989630.7 | G4: ='EU27'!G$3 -> 3990103.5 | H4: ='EU27'!H$3 -> 4023087.2 | I4: ='EU27'!I$3 -> 3985401.9 | ... Y4: ='EU27'!Y$3 -> 2731933.9
A5: AT | B5: =AT!B$3 -> 67966.753 | C5: =AT!C$3 -> 71912.975 | D5: =AT!D$3 -> 73609.058 | E5: =AT!E$3 -> 78928.551 | F5: =AT!F$3 -> 79516.845 | G5: =AT!G$3 -> 81129.859 | H5: =AT!H$3 -> 78910.32 | I5: =AT!I$3 -> 76337.934 | ... Y5: =AT!Y$3 -> 59572.658
A6: BE | B6: =BE!B$3 -> 147666.86 | C6: =BE!C$3 -> 146640.36 | D6: =BE!D$3 -> 153290.57 | E6: =BE!E$3 -> 155349.71 | F6: =BE!F$3 -> 157063.03 | G6: =BE!G$3 -> 154446.16 | H6: =BE!H$3 -> 155186.82 | I6: =BE!I$3 -> 155257.04 | ... Y6: =BE!Y$3 -> 112210.43
A7: BG | B7: =BG!B$3 -> 45939.728 | C7: =BG!C$3 -> 49631.03 | D7: =BG!D$3 -> 46842.171 | E7: =BG!E$3 -> 51397.173 | F7: =BG!F$3 -> 50357.125 | G7: =BG!G$3 -> 51463.91 | H7: =BG!H$3 -> 52743.276 | I7: =BG!I$3 -> 56454.475 | ... Y7: =BG!Y$3 -> 35366.803
A8: CY | B8: =CY!B$3 -> 8540.6694 | C8: =CY!C$3 -> 8553.5069 | D8: =CY!D$3 -> 8540.3364 | E8: =CY!E$3 -> 8952.0102 | F8: =CY!F$3 -> 8873.4147 | G8: =CY!G$3 -> 9699.0076 | H8: =CY!H$3 -> 9951.2201 | I8: =CY!I$3 -> 10164.661 | ... Y8: =CY!Y$3 -> 8881.1781
A9: CZ | B9: =CZ!B$3 -> 127727.84 | C9: =CZ!C$3 -> 127662.91 | D9: =CZ!D$3 -> 124501.57 | E9: =CZ!E$3 -> 128212.22 | F9: =CZ!F$3 -> 129201.96 | G9: =CZ!G$3 -> 126683.65 | H9: =CZ!H$3 -> 127556.31 | I9: =CZ!I$3 -> 129415.74 | ... Y9: =CZ!Y$3 -> 84271.743
A10: DE | B10: =DE!B$3 -> 924570.93 | C10: =DE!C$3 -> 940432.13 | D10: =DE!D$3 -> 924402.45 | E10: =DE!E$3 -> 921051.5 | F10: =DE!F$3 -> 905374.76 | G10: =DE!G$3 -> 898223.65 | H10: =DE!H$3 -> 918280.62 | I10: =DE!I$3 -> 880413.56 | ... Y10: =DE!Y$3 -> 625595.29
A11: DK | B11: =DK!B$3 -> 60563.014 | C11: =DK!C$3 -> 61479.014 | D11: =DK!D$3 -> 60205.948 | E11: =DK!E$3 -> 65542.383 | F11: =DK!F$3 -> 59751.942 | G11: =DK!G$3 -> 56361.291 | H11: =DK!H$3 -> 65129.153 | I11: =DK!I$3 -> 60558.293 | ... Y11: =DK!Y$3 -> 29882.751
A12: EE | B12: =EE!B$3 -> 15866.504 | C12: =EE!C$3 -> 16237.632 | D12: =EE!D$3 -> 15784.213 | E12: =EE!E$3 -> 17666.799 | F12: =EE!F$3 -> 17888.875 | G12: =EE!G$3 -> 17604.651 | H12: =EE!H$3 -> 17254.922 | I12: =EE!I$3 -> 20887.203 | ... Y12: =EE!Y$3 -> 9611.0954
A13: EL | B13: =EL!B$3 -> 116991.24 | C13: =EL!C$3 -> 118875.11 | D13: =EL!D$3 -> 117342.27 | E13: =EL!E$3 -> 122370.75 | F13: =EL!F$3 -> 122959.04 | G13: =EL!G$3 -> 125703.9 | H13: =EL!H$3 -> 125146.9 | I13: =EL!I$3 -> 127649.25 | ... Y13: =EL!Y$3 -> 62698.78
A14: ES | B14: =ES!B$3 -> 338149.62 | C14: =ES!C$3 -> 342351.81 | D14: =ES!D$3 -> 362625.9 | E14: =ES!E$3 -> 368153.29 | F14: =ES!F$3 -> 386523.11 | G14: =ES!G$3 -> 404873.84 | H14: =ES!H$3 -> 397955.6 | I14: =ES!I$3 -> 407065.36 | ... Y14: =ES!Y$3 -> 259696.26
A15: FI | B15: =FI!B$3 -> 60127.152 | C15: =FI!C$3 -> 65443.549 | D15: =FI!D$3 -> 68195.254 | E15: =FI!E$3 -> 75826.178 | F15: =FI!F$3 -> 71876.486 | G15: =FI!G$3 -> 59968.067 | H15: =FI!H$3 -> 71596.163 | I15: =FI!I$3 -> 69877.923 | ... Y15: =FI!Y$3 -> 34605.824
A16: FR | B16: =FR!B$3 -> 436604.38 | C16: =FR!C$3 -> 439865.49 | D16: =FR!D$3 -> 435364.08 | E16: =FR!E$3 -> 442371.58 | F16: =FR!F$3 -> 446462.23 | G16: =FR!G$3 -> 448654.04 | H16: =FR!H$3 -> 440233.57 | I16: =FR!I$3 -> 431296.32 | ... Y16: =FR!Y$3 -> 298761.25
A17: HR | B17: =HR!B$3 -> 19911.464 | C17: =HR!C$3 -> 21067.404 | D17: =HR!D$3 -> 22178.116 | E17: =HR!E$3 -> 23477.885 | F17: =HR!F$3 -> 23137.115 | G17: =HR!G$3 -> 23633.105 | H17: =HR!H$3 -> 23821.849 | I17: =HR!I$3 -> 25154.806 | ... Y17: =HR!Y$3 -> 19137.202
A18: HU | B18: =HU!B$3 -> 58962.63 | C18: =HU!C$3 -> 60501.949 | D18: =HU!D$3 -> 59478.349 | E18: =HU!E$3 -> 62234.984 | F18: =HU!F$3 -> 60703.166 | G18: =HU!G$3 -> 60964.599 | H18: =HU!H$3 -> 60360.569 | I18: =HU!I$3 -> 59312.125 | ... Y18: =HU!Y$3 -> 41254.505
A19: IE | B19: =IE!B$3 -> 47542.33 | C19: =IE!C$3 -> 50310.845 | D19: =IE!D$3 -> 48868.555 | E19: =IE!E$3 -> 48500.902 | F19: =IE!F$3 -> 48798.205 | G19: =IE!G$3 -> 50970.326 | H19: =IE!H$3 -> 50868.383 | I19: =IE!I$3 -> 51054.4 | ... Y19: =IE!Y$3 -> 37393.938
A20: IT | B20: =IT!B$3 -> 481406.18 | C20: =IT!C$3 -> 482059.25 | D20: =IT!D$3 -> 489178.07 | E20: =IT!E$3 -> 509159.74 | F20: =IT!F$3 -> 515193.1 | G20: =IT!G$3 -> 516502.16 | H20: =IT!H$3 -> 512460.17 | I20: =IT!I$3 -> 507102.1 | ... Y20: =IT!Y$3 -> 328422.8
A21: LT | B21: =LT!B$3 -> 12205.868 | C21: =LT!C$3 -> 13002.168 | D21: =LT!D$3 -> 13098.396 | E21: =LT!E$3 -> 13101.079 | F21: =LT!F$3 -> 13718.584 | G21: =LT!G$3 -> 14458.237 | H21: =LT!H$3 -> 14791.243 | I21: =LT!I$3 -> 16052.334 | ... Y21: =LT!Y$3 -> 13207.724
A22: LU | B22: =LU!B$3 -> 9662.9586 | C22: =LU!C$3 -> 10244.368 | D22: =LU!D$3 -> 11104.191 | E22: =LU!E$3 -> 11623.64 | F22: =LU!F$3 -> 13091.985 | G22: =LU!G$3 -> 13372.402 | H22: =LU!H$3 -> 13118.961 | I22: =LU!I$3 -> 12606.382 | ... Y22: =LU!Y$3 -> 8630.181
A23: LV | B23: =LV!B$3 -> 7188.0213 | C23: =LV!C$3 -> 8199.9184 | D23: =LV!D$3 -> 8261.0067 | E23: =LV!E$3 -> 8447.0655 | F23: =LV!F$3 -> 8525.984 | G23: =LV!G$3 -> 8822.9519 | H23: =LV!H$3 -> 9142.3604 | I23: =LV!I$3 -> 9453.7475 | ... Y23: =LV!Y$3 -> 7113.0911
A24: MT | B24: =MT!B$3 -> 5035.6493 | C24: =MT!C$3 -> 5333.5355 | D24: =MT!D$3 -> 5774.0955 | E24: =MT!E$3 -> 6164.2004 | F24: =MT!F$3 -> 6263.3456 | G24: =MT!G$3 -> 5028.8994 | H24: =MT!H$3 -> 5327.081 | I24: =MT!I$3 -> 5706.355 | ... Y24: =MT!Y$3 -> 9462.3825
A25: NL | B25: =NL!B$3 -> 224367.09 | C25: =NL!C$3 -> 233397.17 | D25: =NL!D$3 -> 232708.24 | E25: =NL!E$3 -> 233170.34 | F25: =NL!F$3 -> 239678.82 | G25: =NL!G$3 -> 239379.17 | H25: =NL!H$3 -> 238040.99 | I25: =NL!I$3 -> 239149.11 | ... Y25: =NL!Y$3 -> 160158.95
A26: PL | B26: =PL!B$3 -> 319016.25 | C26: =PL!C$3 -> 314885.74 | D26: =PL!D$3 -> 307485.58 | E26: =PL!E$3 -> 320475.42 | F26: =PL!F$3 -> 325248.13 | G26: =PL!G$3 -> 324524.13 | H26: =PL!H$3 -> 338562.81 | I26: =PL!I$3 -> 337817.96 | ... Y26: =PL!Y$3 -> 287589.95
A27: PT | B27: =PT!B$3 -> 69172.948 | C27: =PT!C$3 -> 68299.636 | D27: =PT!D$3 -> 72666.817 | E27: =PT!E$3 -> 68038.343 | F27: =PT!F$3 -> 71270.337 | G27: =PT!G$3 -> 73472.503 | H27: =PT!H$3 -> 68962.256 | I27: =PT!I$3 -> 66707.194 | ... Y27: =PT!Y$3 -> 44199.324
A28: RO | B28: =RO!B$3 -> 93635.052 | C28: =RO!C$3 -> 99311.294 | D28: =RO!D$3 -> 99396.263 | E28: =RO!E$3 -> 104104.39 | F28: =RO!F$3 -> 103695.75 | G28: =RO!G$3 -> 101714.66 | H28: =RO!H$3 -> 104755.82 | I28: =RO!I$3 -> 108974.76 | ... Y28: =RO!Y$3 -> 68218.611
A29: SE | B29: =SE!B$3 -> 61673.206 | C29: =SE!C$3 -> 62397.894 | D29: =SE!D$3 -> 62414.61 | E29: =SE!E$3 -> 64424.144 | F29: =SE!F$3 -> 64742.285 | G29: =SE!G$3 -> 62380.026 | H29: =SE!H$3 -> 62746.777 | I29: =SE!I$3 -> 62096.611 | ... Y29: =SE!Y$3 -> 42989.174
A30: SI | B30: =SI!B$3 -> 15128.522 | C30: =SI!C$3 -> 16387.047 | D30: =SI!D$3 -> 16651.184 | E30: =SI!E$3 -> 16354.61 | F30: =SI!F$3 -> 16767.955 | G30: =SI!G$3 -> 17070.976 | H30: =SI!H$3 -> 17347.977 | I30: =SI!I$3 -> 17599.043 | ... Y30: =SI!Y$3 -> 12066.073
A31: SK | B31: =SK!B$3 -> 41234.38 | C31: =SK!C$3 -> 43343.453 | D31: =SK!D$3 -> 42108.408 | E31: =SK!E$3 -> 42441.54 | F31: =SK!F$3 -> 42947.119 | G31: =SK!G$3 -> 42997.371 | H31: =SK!H$3 -> 42835.12 | I31: =SK!I$3 -> 41237.209 | ... Y31: =SK!Y$3 -> 30935.905
A33: JRC-IDEES CO2 emissions (kt CO2)
A34: EU27 | B34: ='EU27'!B$49 -> 3807100.8 | C34: ='EU27'!C$49 -> 3854406.7 | D34: ='EU27'!D$49 -> 3859798.6 | E34: ='EU27'!E$49 -> 3956300.3 | F34: ='EU27'!F$49 -> 3984196 | G34: ='EU27'!G$49 -> 3970901.2 | H34: ='EU27'!H$49 -> 4001693.9 | I34: ='EU27'!I$49 -> 3966645.1 | ... Y34: ='EU27'!Y$49 -> 2748921.4
A35: AT | B35: =AT!B$49 -> 70406.026 | C35: =AT!C$49 -> 74513.792 | D35: =AT!D$49 -> 76716.24 | E35: =AT!E$49 -> 81799.36 | F35: =AT!F$49 -> 83545.969 | G35: =AT!G$49 -> 84270.69 | H35: =AT!H$49 -> 82284.618 | I35: =AT!I$49 -> 79765.83 | ... Y35: =AT!Y$49 -> 62500.037
A36: BE | B36: =BE!B$49 -> 146993.7 | C36: =BE!C$49 -> 145182.47 | D36: =BE!D$49 -> 147078.06 | E36: =BE!E$49 -> 154725.64 | F36: =BE!F$49 -> 154320.62 | G36: =BE!G$49 -> 151208.93 | H36: =BE!H$49 -> 150635.25 | I36: =BE!I$49 -> 149333.32 | ... Y36: =BE!Y$49 -> 115150.48
A37: BG | B37: =BG!B$49 -> 49706.346 | C37: =BG!C$49 -> 52868.942 | D37: =BG!D$49 -> 49728.564 | E37: =BG!E$49 -> 54654.947 | F37: =BG!F$49 -> 53888.509 | G37: =BG!G$49 -> 54854.444 | H37: =BG!H$49 -> 55646.968 | I37: =BG!I$49 -> 59320.212 | ... Y37: =BG!Y$49 -> 36451.429
A38: CY | B38: =CY!B$49 -> 8655.6821 | C38: =CY!C$49 -> 8663.2158 | D38: =CY!D$49 -> 8643.6273 | E38: =CY!E$49 -> 9350.9441 | F38: =CY!F$49 -> 8994.78 | G38: =CY!G$49 -> 9842.5725 | H38: =CY!H$49 -> 9988.3522 | I38: =CY!I$49 -> 10189.463 | ... Y38: =CY!Y$49 -> 8726.6688
A39: CZ | B39: =CZ!B$49 -> 129460.79 | C39: =CZ!C$49 -> 129625.5 | D39: =CZ!D$49 -> 126458.37 | E39: =CZ!E$49 -> 130136.1 | F39: =CZ!F$49 -> 131502.58 | G39: =CZ!G$49 -> 129206.55 | H39: =CZ!H$49 -> 130963.74 | I39: =CZ!I$49 -> 131858.87 | ... Y39: =CZ!Y$49 -> 86974.399
A40: DE | B40: =DE!B$49 -> 921573.17 | C40: =DE!C$49 -> 934353.48 | D40: =DE!D$49 -> 919994.26 | E40: =DE!E$49 -> 921591.52 | F40: =DE!F$49 -> 908892.9 | G40: =DE!G$49 -> 888217.83 | H40: =DE!H$49 -> 902995.56 | I40: =DE!I$49 -> 874688.47 | ... Y40: =DE!Y$49 -> 626558.22
A41: DK | B41: =DK!B$49 -> 61420.464 | C41: =DK!C$49 -> 62165.072 | D41: =DK!D$49 -> 60644.407 | E41: =DK!E$49 -> 65232.743 | F41: =DK!F$49 -> 59573.728 | G41: =DK!G$49 -> 56243.766 | H41: =DK!H$49 -> 64871.981 | I41: =DK!I$49 -> 60362.844 | ... Y41: =DK!Y$49 -> 29379.499
A42: EE | B42: =EE!B$49 -> 15248.993 | C42: =EE!C$49 -> 15515.359 | D42: =EE!D$49 -> 14980.346 | E42: =EE!E$49 -> 16811.83 | F42: =EE!F$49 -> 17089.08 | G42: =EE!G$49 -> 16973.406 | H42: =EE!H$49 -> 16566.078 | I42: =EE!I$49 -> 20114.993 | ... Y42: =EE!Y$49 -> 7284.2094
...

Sheet EU27
A1: EU27 - European Union - 27 countries (from 2020) | B1: 2000 | C1: 2001 | D1: 2002 | E1: 2003 | F1: 2004 | G1: 2005 | H1: 2006 | I1: 2007 | J1: 2008 | K1: 2009 | L1: 2010 | M1: 2011 | N1: 2012 | O1: 2013 | P1: 2014 | Q1: 2015 | R1: 2016 | S1: 2017 | T1: 2018 | U1: 2019 | V1: 2020 | W1: 2021 | X1: 2022 | Y1: 2023
A3: Total UNFCCC CO2 emissions without LULUCF, with international transport (kt CO2) | B3: =SUM(AT!B3,BE!B3,BG!B3,CY!B3,CZ!B3,DE!B3,DK!B3,EE!B3,EL!B3,ES!B3,FI!B3,FR!B3,HR!B3,HU!B3,IE!B3,IT!B3,LT!B3,LU!B3,LV!B3,MT!B3,NL!B3,PL!B3,PT!B3,RO!B3,SE!B3,SI!B3,SK!B3) -> 3816857.2 | C3: =SUM(AT!C3,BE!C3,BG!C3,CY!C3,CZ!C3,DE!C3,DK!C3,EE!C3,EL!C3,ES!C3,FI!C3,FR!C3,HR!C3,HU!C3,IE!C3,IT!C3,LT!C3,LU!C3,LV!C3,MT!C3,NL!C3,PL!C3,PT!C3,RO!C3,SE!C3,SI!C3,SK!C3) -> 3877827.2 | D3: =SUM(AT!D3,BE!D3,BG!D3,CY!D3,CZ!D3,DE!D3,DK!D3,EE!D3,EL!D3,ES!D3,FI!D3,FR!D3,HR!D3,HU!D3,IE!D3,IT!D3,LT!D3,LU!D3,LV!D3,MT!D3,NL!D3,PL!D3,PT!D3,RO!D3,SE!D3,SI!D3,SK!D3) -> 3882075.7 | E3: =SUM(AT!E3,BE!E3,BG!E3,CY!E3,CZ!E3,DE!E3,DK!E3,EE!E3,EL!E3,ES!E3,FI!E3,FR!E3,HR!E3,HU!E3,IE!E3,IT!E3,LT!E3,LU!E3,LV!E3,MT!E3,NL!E3,PL!E3,PT!E3,RO!E3,SE!E3,SI!E3,SK!E3) -> 3967540.4 | F3: =SUM(AT!F3,BE!F3,BG!F3,CY!F3,CZ!F3,DE!F3,DK!F3,EE!F3,EL!F3,ES!F3,FI!F3,FR!F3,HR!F3,HU!F3,IE!F3,IT!F3,LT!F3,LU!F3,LV!F3,MT!F3,NL!F3,PL!F3,PT!F3,RO!F3,SE!F3,SI!F3,SK!F3) -> 3989630.7 | G3: =SUM(AT!G3,BE!G3,BG!G3,CY!G3,CZ!G3,DE!G3,DK!G3,EE!G3,EL!G3,ES!G3,FI!G3,FR!G3,HR!G3,HU!G3,IE!G3,IT!G3,LT!G3,LU!G3,LV!G3,MT!G3,NL!G3,PL!G3,PT!G3,RO!G3,SE!G3,SI!G3,SK!G3) -> 3990103.5 | H3: =SUM(AT!H3,BE!H3,BG!H3,CY!H3,CZ!H3,DE!H3,DK!H3,EE!H3,EL!H3,ES!H3,FI!H3,FR!H3,HR!H3,HU!H3,IE!H3,IT!H3,LT!H3,LU!H3,LV!H3,MT!H3,NL!H3,PL!H3,PT!H3,RO!H3,SE!H3,SI!H3,SK!H3) -> 4023087.2 | I3: =SUM(AT!I3,BE!I3,BG!I3,CY!I3,CZ!I3,DE!I3,DK!I3,EE!I3,EL!I3,ES!I3,FI!I3,FR!I3,HR!I3,HU!I3,IE!I3,IT!I3,LT!I3,LU!I3,LV!I3,MT!I3,NL!I3,PL!I3,PT!I3,RO!I3,SE!I3,SI!I3,SK!I3) -> 3985401.9 | ... Y3: =SUM(AT!Y3,BE!Y3,BG!Y3,CY!Y3,CZ!Y3,DE!Y3,DK!Y3,EE!Y3,EL!Y3,ES!Y3,FI!Y3,FR!Y3,HR!Y3,HU!Y3,IE!Y3,IT!Y3,LT!Y3,LU!Y3,LV!Y3,MT!Y3,NL!Y3,PL!Y3,PT!Y3,RO!Y3,SE!Y3,SI!Y3,SK!Y3) -> 2731933.9
A4: 1 - Energy | B4: =SUM(B5,B31,B32) -> 3300932.6 | C4: =SUM(C5,C31,C32) -> 3368627.6 | D4: =SUM(D5,D31,D32) -> 3368045.4 | E4: =SUM(E5,E31,E32) -> 3439965.7 | F4: =SUM(F5,F31,F32) -> 3436135.3 | G4: =SUM(G5,G31,G32) -> 3430894.8 | H4: =SUM(H5,H31,H32) -> 3441430.5 | I4: =SUM(I5,I31,I32) -> 3384778.7 | ... Y4: =SUM(Y5,Y31,Y32) -> 2281878.1
A5: 1.A - Fuel combustion activities (sectoral approach) | B5: =SUM(B6,B10,B18,B24,B28) -> 3279958.3 | C5: =SUM(C6,C10,C18,C24,C28) -> 3348848.4 | D5: =SUM(D6,D10,D18,D24,D28) -> 3347631.9 | E5: =SUM(E6,E10,E18,E24,E28) -> 3418496.1 | F5: =SUM(F6,F10,F18,F24,F28) -> 3415948.1 | G5: =SUM(G6,G10,G18,G24,G28) -> 3409873.3 | H5: =SUM(H6,H10,H18,H24,H28) -> 3418456.4 | I5: =SUM(I6,I10,I18,I24,I28) -> 3362019.1 | ... Y5: =SUM(Y6,Y10,Y18,Y24,Y28) -> 2264959.3
A6: 1.A.1 - Energy Industries | B6: =SUM(B7:B9) -> 1296255.2 | C6: =SUM(C7:C9) -> 1321173.7 | D6: =SUM(D7:D9) -> 1343439.7 | E6: =SUM(E7:E9) -> 1394438.4 | F6: =SUM(F7:F9) -> 1387131.3 | G6: =SUM(G7:G9) -> 1376478.8 | H6: =SUM(H7:H9) -> 1383777.3 | I6: =SUM(I7:I9) -> 1394464.4 | ... Y6: =SUM(Y7:Y9) -> 691629.76
A7: 1.A.1.a - Public Electricity and Heat Production | B7: =SUM(AT!B7,BE!B7,BG!B7,CY!B7,CZ!B7,DE!B7,DK!B7,EE!B7,EL!B7,ES!B7,FI!B7,FR!B7,HR!B7,HU!B7,IE!B7,IT!B7,LT!B7,LU!B7,LV!B7,MT!B7,NL!B7,PL!B7,PT!B7,RO!B7,SE!B7,SI!B7,SK!B7) -> 1118514.2 | C7: =SUM(AT!C7,BE!C7,BG!C7,CY!C7,CZ!C7,DE!C7,DK!C7,EE!C7,EL!C7,ES!C7,FI!C7,FR!C7,HR!C7,HU!C7,IE!C7,IT!C7,LT!C7,LU!C7,LV!C7,MT!C7,NL!C7,PL!C7,PT!C7,RO!C7,SE!C7,SI!C7,SK!C7) -> 1145565.1 | D7: =SUM(AT!D7,BE!D7,BG!D7,CY!D7,CZ!D7,DE!D7,DK!D7,EE!D7,EL!D7,ES!D7,FI!D7,FR!D7,HR!D7,HU!D7,IE!D7,IT!D7,LT!D7,LU!D7,LV!D7,MT!D7,NL!D7,PL!D7,PT!D7,RO!D7,SE!D7,SI!D7,SK!D7) -> 1167201.1 | E7: =SUM(AT!E7,BE!E7,BG!E7,CY!E7,CZ!E7,DE!E7,DK!E7,EE!E7,EL!E7,ES!E7,FI!E7,FR!E7,HR!E7,HU!E7,IE!E7,IT!E7,LT!E7,LU!E7,LV!E7,MT!E7,NL!E7,PL!E7,PT!E7,RO!E7,SE!E7,SI!E7,SK!E7) -> 1214569.2 | F7: =SUM(AT!F7,BE!F7,BG!F7,CY!F7,CZ!F7,DE!F7,DK!F7,EE!F7,EL!F7,ES!F7,FI!F7,FR!F7,HR!F7,HU!F7,IE!F7,IT!F7,LT!F7,LU!F7,LV!F7,MT!F7,NL!F7,PL!F7,PT!F7,RO!F7,SE!F7,SI!F7,SK!F7) -> 1201002.1 | G7: =SUM(AT!G7,BE!G7,BG!G7,CY!G7,CZ!G7,DE!G7,DK!G7,EE!G7,EL!G7,ES!G7,FI!G7,FR!G7,HR!G7,HU!G7,IE!G7,IT!G7,LT!G7,LU!G7,LV!G7,MT!G7,NL!G7,PL!G7,PT!G7,RO!G7,SE!G7,SI!G7,SK!G7) -> 1188566.6 | H7: =SUM(AT!H7,BE!H7,BG!H7,CY!H7,CZ!H7,DE!H7,DK!H7,EE!H7,EL!H7,ES!H7,FI!H7,FR!H7,HR!H7,HU!H7,IE!H7,IT!H7,LT!H7,LU!H7,LV!H7,MT!H7,NL!H7,PL!H7,PT!H7,RO!H7,SE!H7,SI!H7,SK!H7) -> 1194253.3 | I7: =SUM(AT!I7,BE!I7,BG!I7,CY!I7,CZ!I7,DE!I7,DK!I7,EE!I7,EL!I7,ES!I7,FI!I7,FR!I7,HR!I7,HU!I7,IE!I7,IT!I7,LT!I7,LU!I7,LV!I7,MT!I7,NL!I7,PL!I7,PT!I7,RO!I7,SE!I7,SI!I7,SK!I7) -> 1206791.6 | ... Y7: =SUM(AT!Y7,BE!Y7,BG!Y7,CY!Y7,CZ!Y7,DE!Y7,DK!Y7,EE!Y7,EL!Y7,ES!Y7,FI!Y7,FR!Y7,HR!Y7,HU!Y7,IE!Y7,IT!Y7,LT!Y7,LU!Y7,LV!Y7,MT!Y7,NL!Y7,PL!Y7,PT!Y7,RO!Y7,SE!Y7,SI!Y7,SK!Y7) -> 568562.92
A8: 1.A.1.b - Petroleum Refining | B8: =SUM(AT!B8,BE!B8,BG!B8,CY!B8,CZ!B8,DE!B8,DK!B8,EE!B8,EL!B8,ES!B8,FI!B8,FR!B8,HR!B8,HU!B8,IE!B8,IT!B8,LT!B8,LU!B8,LV!B8,MT!B8,NL!B8,PL!B8,PT!B8,RO!B8,SE!B8,SI!B8,SK!B8) -> 116460.24 | C8: =SUM(AT!C8,BE!C8,BG!C8,CY!C8,CZ!C8,DE!C8,DK!C8,EE!C8,EL!C8,ES!C8,FI!C8,FR!C8,HR!C8,HU!C8,IE!C8,IT!C8,LT!C8,LU!C8,LV!C8,MT!C8,NL!C8,PL!C8,PT!C8,RO!C8,SE!C8,SI!C8,SK!C8) -> 117057.4 | D8: =SUM(AT!D8,BE!D8,BG!D8,CY!D8,CZ!D8,DE!D8,DK!D8,EE!D8,EL!D8,ES!D8,FI!D8,FR!D8,HR!D8,HU!D8,IE!D8,IT!D8,LT!D8,LU!D8,LV!D8,MT!D8,NL!D8,PL!D8,PT!D8,RO!D8,SE!D8,SI!D8,SK!D8) -> 117296.98 | E8: =SUM(AT!E8,BE!E8,BG!E8,CY!E8,CZ!E8,DE!E8,DK!E8,EE!E8,EL!E8,ES!E8,FI!E8,FR!E8,HR!E8,HU!E8,IE!E8,IT!E8,LT!E8,LU!E8,LV!E8,MT!E8,NL!E8,PL!E8,PT!E8,RO!E8,SE!E8,SI!E8,SK!E8) -> 118238.75 | F8: =SUM(AT!F8,BE!F8,BG!F8,CY!F8,CZ!F8,DE!F8,DK!F8,EE!F8,EL!F8,ES!F8,FI!F8,FR!F8,HR!F8,HU!F8,IE!F8,IT!F8,LT!F8,LU!F8,LV!F8,MT!F8,NL!F8,PL!F8,PT!F8,RO!F8,SE!F8,SI!F8,SK!F8) -> 123135.58 | G8: =SUM(AT!G8,BE!G8,BG!G8,CY!G8,CZ!G8,DE!G8,DK!G8,EE!G8,EL!G8,ES!G8,FI!G8,FR!G8,HR!G8,HU!G8,IE!G8,IT!G8,LT!G8,LU!G8,LV!G8,MT!G8,NL!G8,PL!G8,PT!G8,RO!G8,SE!G8,SI!G8,SK!G8) -> 125328.48 | H8: =SUM(AT!H8,BE!H8,BG!H8,CY!H8,CZ!H8,DE!H8,DK!H8,EE!H8,EL!H8,ES!H8,FI!H8,FR!H8,HR!H8,HU!H8,IE!H8,IT!H8,LT!H8,LU!H8,LV!H8,MT!H8,NL!H8,PL!H8,PT!H8,RO!H8,SE!H8,SI!H8,SK!H8) -> 125210.15 | I8: =SUM(AT!I8,BE!I8,BG!I8,CY!I8,CZ!I8,DE!I8,DK!I8,EE!I8,EL!I8,ES!I8,FI!I8,FR!I8,HR!I8,HU!I8,IE!I8,IT!I8,LT!I8,LU!I8,LV!I8,MT!I8,NL!I8,PL!I8,PT!I8,RO!I8,SE!I8,SI!I8,SK!I8) -> 125764.88 | ... Y8: =SUM(AT!Y8,BE!Y8,BG!Y8,CY!Y8,CZ!Y8,DE!Y8,DK!Y8,EE!Y8,EL!Y8,ES!Y8,FI!Y8,FR!Y8,HR!Y8,HU!Y8,IE!Y8,IT!Y8,LT!Y8,LU!Y8,LV!Y8,MT!Y8,NL!Y8,PL!Y8,PT!Y8,RO!Y8,SE!Y8,SI!Y8,SK!Y8) -> 95413.811
A9: 1.A.1.c - Manufacture of Solid Fuels and Other Energy Industries | B9: =SUM(AT!B9,BE!B9,BG!B9,CY!B9,CZ!B9,DE!B9,DK!B9,EE!B9,EL!B9,ES!B9,FI!B9,FR!B9,HR!B9,HU!B9,IE!B9,IT!B9,LT!B9,LU!B9,LV!B9,MT!B9,NL!B9,PL!B9,PT!B9,RO!B9,SE!B9,SI!B9,SK!B9) -> 61280.799 | C9: =SUM(AT!C9,BE!C9,BG!C9,CY!C9,CZ!C9,DE!C9,DK!C9,EE!C9,EL!C9,ES!C9,FI!C9,FR!C9,HR!C9,HU!C9,IE!C9,IT!C9,LT!C9,LU!C9,LV!C9,MT!C9,NL!C9,PL!C9,PT!C9,RO!C9,SE!C9,SI!C9,SK!C9) -> 58551.113 | D9: =SUM(AT!D9,BE!D9,BG!D9,CY!D9,CZ!D9,DE!D9,DK!D9,EE!D9,EL!D9,ES!D9,FI!D9,FR!D9,HR!D9,HU!D9,IE!D9,IT!D9,LT!D9,LU!D9,LV!D9,MT!D9,NL!D9,PL!D9,PT!D9,RO!D9,SE!D9,SI!D9,SK!D9) -> 58941.582 | E9: =SUM(AT!E9,BE!E9,BG!E9,CY!E9,CZ!E9,DE!E9,DK!E9,EE!E9,EL!E9,ES!E9,FI!E9,FR!E9,HR!E9,HU!E9,IE!E9,IT!E9,LT!E9,LU!E9,LV!E9,MT!E9,NL!E9,PL!E9,PT!E9,RO!E9,SE!E9,SI!E9,SK!E9) -> 61630.498 | F9: =SUM(AT!F9,BE!F9,BG!F9,CY!F9,CZ!F9,DE!F9,DK!F9,EE!F9,EL!F9,ES!F9,FI!F9,FR!F9,HR!F9,HU!F9,IE!F9,IT!F9,LT!F9,LU!F9,LV!F9,MT!F9,NL!F9,PL!F9,PT!F9,RO!F9,SE!F9,SI!F9,SK!F9) -> 62993.595 | G9: =SUM(AT!G9,BE!G9,BG!G9,CY!G9,CZ!G9,DE!G9,DK!G9,EE!G9,EL!G9,ES!G9,FI!G9,FR!G9,HR!G9,HU!G9,IE!G9,IT!G9,LT!G9,LU!G9,LV!G9,MT!G9,NL!G9,PL!G9,PT!G9,RO!G9,SE!G9,SI!G9,SK!G9) -> 62583.657 | H9: =SUM(AT!H9,BE!H9,BG!H9,CY!H9,CZ!H9,DE!H9,DK!H9,EE!H9,EL!H9,ES!H9,FI!H9,FR!H9,HR!H9,HU!H9,IE!H9,IT!H9,LT!H9,LU!H9,LV!H9,MT!H9,NL!H9,PL!H9,PT!H9,RO!H9,SE!H9,SI!H9,SK!H9) -> 64313.849 | I9: =SUM(AT!I9,BE!I9,BG!I9,CY!I9,CZ!I9,DE!I9,DK!I9,EE!I9,EL!I9,ES!I9,FI!I9,FR!I9,HR!I9,HU!I9,IE!I9,IT!I9,LT!I9,LU!I9,LV!I9,MT!I9,NL!I9,PL!I9,PT!I9,RO!I9,SE!I9,SI!I9,SK!I9) -> 61907.905 | ... Y9: =SUM(AT!Y9,BE!Y9,BG!Y9,CY!Y9,CZ!Y9,DE!Y9,DK!Y9,EE!Y9,EL!Y9,ES!Y9,FI!Y9,FR!Y9,HR!Y9,HU!Y9,IE!Y9,IT!Y9,LT!Y9,LU!Y9,LV!Y9,MT!Y9,NL!Y9,PL!Y9,PT!Y9,RO!Y9,SE!Y9,SI!Y9,SK!Y9) -> 27653.03
A10: 1.A.2 - Manufacturing Industries and Construction | B10: =SUM(B11:B17) -> 573089.16 | C10: =SUM(C11:C17) -> 561584.11 | D10: =SUM(D11:D17) -> 551189.81 | E10: =SUM(E11:E17) -> 555961.89 | F10: =SUM(F11:F17) -> 548237.76 | G10: =SUM(G11:G17) -> 543108.81 | H10: =SUM(H11:H17) -> 532154.51 | I10: =SUM(I11:I17) -> 541781.19 | ... Y10: =SUM(Y11:Y17) -> 358305.05
A11: 1.A.2.a - Iron and Steel | B11: =SUM(AT!B11,BE!B11,BG!B11,CY!B11,CZ!B11,DE!B11,DK!B11,EE!B11,EL!B11,ES!B11,FI!B11,FR!B11,HR!B11,HU!B11,IE!B11,IT!B11,LT!B11,LU!B11,LV!B11,MT!B11,NL!B11,PL!B11,PT!B11,RO!B11,SE!B11,SI!B11,SK!B11) -> 116583.13 | C11: =SUM(AT!C11,BE!C11,BG!C11,CY!C11,CZ!C11,DE!C11,DK!C11,EE!C11,EL!C11,ES!C11,FI!C11,FR!C11,HR!C11,HU!C11,IE!C11,IT!C11,LT!C11,LU!C11,LV!C11,MT!C11,NL!C11,PL!C11,PT!C11,RO!C11,SE!C11,SI!C11,SK!C11) -> 108674.04 | D11: =SUM(AT!D11,BE!D11,BG!D11,CY!D11,CZ!D11,DE!D11,DK!D11,EE!D11,EL!D11,ES!D11,FI!D11,FR!D11,HR!D11,HU!D11,IE!D11,IT!D11,LT!D11,LU!D11,LV!D11,MT!D11,NL!D11,PL!D11,PT!D11,RO!D11,SE!D11,SI!D11,SK!D11) -> 105092.76 | E11: =SUM(AT!E11,BE!E11,BG!E11,CY!E11,CZ!E11,DE!E11,DK!E11,EE!E11,EL!E11,ES!E11,FI!E11,FR!E11,HR!E11,HU!E11,IE!E11,IT!E11,LT!E11,LU!E11,LV!E11,MT!E11,NL!E11,PL!E11,PT!E11,RO!E11,SE!E11,SI!E11,SK!E11) -> 105487.02 | F11: =SUM(AT!F11,BE!F11,BG!F11,CY!F11,CZ!F11,DE!F11,DK!F11,EE!F11,EL!F11,ES!F11,FI!F11,FR!F11,HR!F11,HU!F11,IE!F11,IT!F11,LT!F11,LU!F11,LV!F11,MT!F11,NL!F11,PL!F11,PT!F11,RO!F11,SE!F11,SI!F11,SK!F11) -> 107335.31 | G11: =SUM(AT!G11,BE!G11,BG!G11,CY!G11,CZ!G11,DE!G11,DK!G11,EE!G11,EL!G11,ES!G11,FI!G11,FR!G11,HR!G11,HU!G11,IE!G11,IT!G11,LT!G11,LU!G11,LV!G11,MT!G11,NL!G11,PL!G11,PT!G11,RO!G11,SE!G11,SI!G11,SK!G11) -> 105692.61 | H11: =SUM(AT!H11,BE!H11,BG!H11,CY!H11,CZ!H11,DE!H11,DK!H11,EE!H11,EL!H11,ES!H11,FI!H11,FR!H11,HR!H11,HU!H11,IE!H11,IT!H11,LT!H11,LU!H11,LV!H11,MT!H11,NL!H11,PL!H11,PT!H11,RO!H11,SE!H11,SI!H11,SK!H11) -> 106759.65 | I11: =SUM(AT!I11,BE!I11,BG!I11,CY!I11,CZ!I11,DE!I11,DK!I11,EE!I11,EL!I11,ES!I11,FI!I11,FR!I11,HR!I11,HU!I11,IE!I11,IT!I11,LT!I11,LU!I11,LV!I11,MT!I11,NL!I11,PL!I11,PT!I11,RO!I11,SE!I11,SI!I11,SK!I11) -> 111722.38 | ... Y11: =SUM(AT!Y11,BE!Y11,BG!Y11,CY!Y11,CZ!Y11,DE!Y11,DK!Y11,EE!Y11,EL!Y11,ES!Y11,FI!Y11,FR!Y11,HR!Y11,HU!Y11,IE!Y11,IT!Y11,LT!Y11,LU!Y11,LV!Y11,MT!Y11,NL!Y11,PL!Y11,PT!Y11,RO!Y11,SE!Y11,SI!Y11,SK!Y11) -> 67597.947
A12: 1.A.2.b - Non-Ferrous Metals | B12: =SUM(AT!B12,BE!B12,BG!B12,CY!B12,CZ!B12,DE!B12,DK!B12,EE!B12,EL!B12,ES!B12,FI!B12,FR!B12,HR!B12,HU!B12,IE!B12,IT!B12,LT!B12,LU!B12,LV!B12,MT!B12,NL!B12,PL!B12,PT!B12,RO!B12,SE!B12,SI!B12,SK!B12) -> 12474.859 | C12: =SUM(AT!C12,BE!C12,BG!C12,CY!C12,CZ!C12,DE!C12,DK!C12,EE!C12,EL!C12,ES!C12,FI!C12,FR!C12,HR!C12,HU!C12,IE!C12,IT!C12,LT!C12,LU!C12,LV!C12,MT!C12,NL!C12,PL!C12,PT!C12,RO!C12,SE!C12,SI!C12,SK!C12) -> 13025.941 | D12: =SUM(AT!D12,BE!D12,BG!D12,CY!D12,CZ!D12,DE!D12,DK!D12,EE!D12,EL!D12,ES!D12,FI!D12,FR!D12,HR!D12,HU!D12,IE!D12,IT!D12,LT!D12,LU!D12,LV!D12,MT!D12,NL!D12,PL!D12,PT!D12,RO!D12,SE!D12,SI!D12,SK!D12) -> 12723.763 | E12: =SUM(AT!E12,BE!E12,BG!E12,CY!E12,CZ!E12,DE!E12,DK!E12,EE!E12,EL!E12,ES!E12,FI!E12,FR!E12,HR!E12,HU!E12,IE!E12,IT!E12,LT!E12,LU!E12,LV!E12,MT!E12,NL!E12,PL!E12,PT!E12,RO!E12,SE!E12,SI!E12,SK!E12) -> 12257.426 | F12: =SUM(AT!F12,BE!F12,BG!F12,CY!F12,CZ!F12,DE!F12,DK!F12,EE!F12,EL!F12,ES!F12,FI!F12,FR!F12,HR!F12,HU!F12,IE!F12,IT!F12,LT!F12,LU!F12,LV!F12,MT!F12,NL!F12,PL!F12,PT!F12,RO!F12,SE!F12,SI!F12,SK!F12) -> 12275.874 | G12: =SUM(AT!G12,BE!G12,BG!G12,CY!G12,CZ!G12,DE!G12,DK!G12,EE!G12,EL!G12,ES!G12,FI!G12,FR!G12,HR!G12,HU!G12,IE!G12,IT!G12,LT!G12,LU!G12,LV!G12,MT!G12,NL!G12,PL!G12,PT!G12,RO!G12,SE!G12,SI!G12,SK!G12) -> 11245.428 | H12: =SUM(AT!H12,BE!H12,BG!H12,CY!H12,CZ!H12,DE!H12,DK!H12,EE!H12,EL!H12,ES!H12,FI!H12,FR!H12,HR!H12,HU!H12,IE!H12,IT!H12,LT!H12,LU!H12,LV!H12,MT!H12,NL!H12,PL!H12,PT!H12,RO!H12,SE!H12,SI!H12,SK!H12) -> 11000.935 | I12: =SUM(AT!I12,BE!I12,BG!I12,CY!I12,CZ!I12,DE!I12,DK!I12,EE!I12,EL!I12,ES!I12,FI!I12,FR!I12,HR!I12,HU!I12,IE!I12,IT!I12,LT!I12,LU!I12,LV!I12,MT!I12,NL!I12,PL!I12,PT!I12,RO!I12,SE!I12,SI!I12,SK!I12) -> 11125.543 | ... Y12: =SUM(AT!Y12,BE!Y12,BG!Y12,CY!Y12,CZ!Y12,DE!Y12,DK!Y12,EE!Y12,EL!Y12,ES!Y12,FI!Y12,FR!Y12,HR!Y12,HU!Y12,IE!Y12,IT!Y12,LT!Y12,LU!Y12,LV!Y12,MT!Y12,NL!Y12,PL!Y12,PT!Y12,RO!Y12,SE!Y12,SI!Y12,SK!Y12) -> 7721.1459
A13: 1.A.2.c - Chemicals | B13: =SUM(AT!B13,BE!B13,BG!B13,CY!B13,CZ!B13,DE!B13,DK!B13,EE!B13,EL!B13,ES!B13,FI!B13,FR!B13,HR!B13,HU!B13,IE!B13,IT!B13,LT!B13,LU!B13,LV!B13,MT!B13,NL!B13,PL!B13,PT!B13,RO!B13,SE!B13,SI!B13,SK!B13) -> 79557.653 | C13: =SUM(AT!C13,BE!C13,BG!C13,CY!C13,CZ!C13,DE!C13,DK!C13,EE!C13,EL!C13,ES!C13,FI!C13,FR!C13,HR!C13,HU!C13,IE!C13,IT!C13,LT!C13,LU!C13,LV!C13,MT!C13,NL!C13,PL!C13,PT!C13,RO!C13,SE!C13,SI!C13,SK!C13) -> 77835.973 | D13: =SUM(AT!D13,BE!D13,BG!D13,CY!D13,CZ!D13,DE!D13,DK!D13,EE!D13,EL!D13,ES!D13,FI!D13,FR!D13,HR!D13,HU!D13,IE!D13,IT!D13,LT!D13,LU!D13,LV!D13,MT!D13,NL!D13,PL!D13,PT!D13,RO!D13,SE!D13,SI!D13,SK!D13) -> 74023.972 | E13: =SUM(AT!E13,BE!E13,BG!E13,CY!E13,CZ!E13,DE!E13,DK!E13,EE!E13,EL!E13,ES!E13,FI!E13,FR!E13,HR!E13,HU!E13,IE!E13,IT!E13,LT!E13,LU!E13,LV!E13,MT!E13,NL!E13,PL!E13,PT!E13,RO!E13,SE!E13,SI!E13,SK!E13) -> 75599.345 | F13: =SUM(AT!F13,BE!F13,BG!F13,CY!F13,CZ!F13,DE!F13,DK!F13,EE!F13,EL!F13,ES!F13,FI!F13,FR!F13,HR!F13,HU!F13,IE!F13,IT!F13,LT!F13,LU!F13,LV!F13,MT!F13,NL!F13,PL!F13,PT!F13,RO!F13,SE!F13,SI!F13,SK!F13) -> 76888.281 | G13: =SUM(AT!G13,BE!G13,BG!G13,CY!G13,CZ!G13,DE!G13,DK!G13,EE!G13,EL!G13,ES!G13,FI!G13,FR!G13,HR!G13,HU!G13,IE!G13,IT!G13,LT!G13,LU!G13,LV!G13,MT!G13,NL!G13,PL!G13,PT!G13,RO!G13,SE!G13,SI!G13,SK!G13) -> 76675.948 | H13: =SUM(AT!H13,BE!H13,BG!H13,CY!H13,CZ!H13,DE!H13,DK!H13,EE!H13,EL!H13,ES!H13,FI!H13,FR!H13,HR!H13,HU!H13,IE!H13,IT!H13,LT!H13,LU!H13,LV!H13,MT!H13,NL!H13,PL!H13,PT!H13,RO!H13,SE!H13,SI!H13,SK!H13) -> 74433.669 | I13: =SUM(AT!I13,BE!I13,BG!I13,CY!I13,CZ!I13,DE!I13,DK!I13,EE!I13,EL!I13,ES!I13,FI!I13,FR!I13,HR!I13,HU!I13,IE!I13,IT!I13,LT!I13,LU!I13,LV!I13,MT!I13,NL!I13,PL!I13,PT!I13,RO!I13,SE!I13,SI!I13,SK!I13) -> 75085.878 | ... Y13: =SUM(AT!Y13,BE!Y13,BG!Y13,CY!Y13,CZ!Y13,DE!Y13,DK!Y13,EE!Y13,EL!Y13,ES!Y13,FI!Y13,FR!Y13,HR!Y13,HU!Y13,IE!Y13,IT!Y13,LT!Y13,LU!Y13,LV!Y13,MT!Y13,NL!Y13,PL!Y13,PT!Y13,RO!Y13,SE!Y13,SI!Y13,SK!Y13) -> 47250.885
A14: 1.A.2.d - Pulp, Paper and Print | B14: =SUM(AT!B14,BE!B14,BG!B14,CY!B14,CZ!B14,DE!B14,DK!B14,EE!B14,EL!B14,ES!B14,FI!B14,FR!B14,HR!B14,HU!B14,IE!B14,IT!B14,LT!B14,LU!B14,LV!B14,MT!B14,NL!B14,PL!B14,PT!B14,RO!B14,SE!B14,SI!B14,SK!B14) -> 31842.903 | C14: =SUM(AT!C14,BE!C14,BG!C14,CY!C14,CZ!C14,DE!C14,DK!C14,EE!C14,EL!C14,ES!C14,FI!C14,FR!C14,HR!C14,HU!C14,IE!C14,IT!C14,LT!C14,LU!C14,LV!C14,MT!C14,NL!C14,PL!C14,PT!C14,RO!C14,SE!C14,SI!C14,SK!C14) -> 30592.102 | D14: =SUM(AT!D14,BE!D14,BG!D14,CY!D14,CZ!D14,DE!D14,DK!D14,EE!D14,EL!D14,ES!D14,FI!D14,FR!D14,HR!D14,HU!D14,IE!D14,IT!D14,LT!D14,LU!D14,LV!D14,MT!D14,NL!D14,PL!D14,PT!D14,RO!D14,SE!D14,SI!D14,SK!D14) -> 30909.5 | E14: =SUM(AT!E14,BE!E14,BG!E14,CY!E14,CZ!E14,DE!E14,DK!E14,EE!E14,EL!E14,ES!E14,FI!E14,FR!E14,HR!E14,HU!E14,IE!E14,IT!E14,LT!E14,LU!E14,LV!E14,MT!E14,NL!E14,PL!E14,PT!E14,RO!E14,SE!E14,SI!E14,SK!E14) -> 31115.422 | F14: =SUM(AT!F14,BE!F14,BG!F14,CY!F14,CZ!F14,DE!F14,DK!F14,EE!F14,EL!F14,ES!F14,FI!F14,FR!F14,HR!F14,HU!F14,IE!F14,IT!F14,LT!F14,LU!F14,LV!F14,MT!F14,NL!F14,PL!F14,PT!F14,RO!F14,SE!F14,SI!F14,SK!F14) -> 30176.119 | G14: =SUM(AT!G14,BE!G14,BG!G14,CY!G14,CZ!G14,DE!G14,DK!G14,EE!G14,EL!G14,ES!G14,FI!G14,FR!G14,HR!G14,HU!G14,IE!G14,IT!G14,LT!G14,LU!G14,LV!G14,MT!G14,NL!G14,PL!G14,PT!G14,RO!G14,SE!G14,SI!G14,SK!G14) -> 30244.921 | H14: =SUM(AT!H14,BE!H14,BG!H14,CY!H14,CZ!H14,DE!H14,DK!H14,EE!H14,EL!H14,ES!H14,FI!H14,FR!H14,HR!H14,HU!H14,IE!H14,IT!H14,LT!H14,LU!H14,LV!H14,MT!H14,NL!H14,PL!H14,PT!H14,RO!H14,SE!H14,SI!H14,SK!H14) -> 29851.05 | I14: =SUM(AT!I14,BE!I14,BG!I14,CY!I14,CZ!I14,DE!I14,DK!I14,EE!I14,EL!I14,ES!I14,FI!I14,FR!I14,HR!I14,HU!I14,IE!I14,IT!I14,LT!I14,LU!I14,LV!I14,MT!I14,NL!I14,PL!I14,PT!I14,RO!I14,SE!I14,SI!I14,SK!I14) -> 28953.354 | ... Y14: =SUM(AT!Y14,BE!Y14,BG!Y14,CY!Y14,CZ!Y14,DE!Y14,DK!Y14,EE!Y14,EL!Y14,ES!Y14,FI!Y14,FR!Y14,HR!Y14,HU!Y14,IE!Y14,IT!Y14,LT!Y14,LU!Y14,LV!Y14,MT!Y14,NL!Y14,PL!Y14,PT!Y14,RO!Y14,SE!Y14,SI!Y14,SK!Y14) -> 16884.639
A15: 1.A.2.e - Food Processing, Beverages and Tobacco | B15: =SUM(AT!B15,BE!B15,BG!B15,CY!B15,CZ!B15,DE!B15,DK!B15,EE!B15,EL!B15,ES!B15,FI!B15,FR!B15,HR!B15,HU!B15,IE!B15,IT!B15,LT!B15,LU!B15,LV!B15,MT!B15,NL!B15,PL!B15,PT!B15,RO!B15,SE!B15,SI!B15,SK!B15) -> 49056.561 | C15: =SUM(AT!C15,BE!C15,BG!C15,CY!C15,CZ!C15,DE!C15,DK!C15,EE!C15,EL!C15,ES!C15,FI!C15,FR!C15,HR!C15,HU!C15,IE!C15,IT!C15,LT!C15,LU!C15,LV!C15,MT!C15,NL!C15,PL!C15,PT!C15,RO!C15,SE!C15,SI!C15,SK!C15) -> 49689.866 | D15: =SUM(AT!D15,BE!D15,BG!D15,CY!D15,CZ!D15,DE!D15,DK!D15,EE!D15,EL!D15,ES!D15,FI!D15,FR!D15,HR!D15,HU!D15,IE!D15,IT!D15,LT!D15,LU!D15,LV!D15,MT!D15,NL!D15,PL!D15,PT!D15,RO!D15,SE!D15,SI!D15,SK!D15) -> 49986.696 | E15: =SUM(AT!E15,BE!E15,BG!E15,CY!E15,CZ!E15,DE!E15,DK!E15,EE!E15,EL!E15,ES!E15,FI!E15,FR!E15,HR!E15,HU!E15,IE!E15,IT!E15,LT!E15,LU!E15,LV!E15,MT!E15,NL!E15,PL!E15,PT!E15,RO!E15,SE!E15,SI!E15,SK!E15) -> 48999.92 | F15: =SUM(AT!F15,BE!F15,BG!F15,CY!F15,CZ!F15,DE!F15,DK!F15,EE!F15,EL!F15,ES!F15,FI!F15,FR!F15,HR!F15,HU!F15,IE!F15,IT!F15,LT!F15,LU!F15,LV!F15,MT!F15,NL!F15,PL!F15,PT!F15,RO!F15,SE!F15,SI!F15,SK!F15) -> 46212.983 | G15: =SUM(AT!G15,BE!G15,BG!G15,CY!G15,CZ!G15,DE!G15,DK!G15,EE!G15,EL!G15,ES!G15,FI!G15,FR!G15,HR!G15,HU!G15,IE!G15,IT!G15,LT!G15,LU!G15,LV!G15,MT!G15,NL!G15,PL!G15,PT!G15,RO!G15,SE!G15,SI!G15,SK!G15) -> 45183.808 | H15: =SUM(AT!H15,BE!H15,BG!H15,CY!H15,CZ!H15,DE!H15,DK!H15,EE!H15,EL!H15,ES!H15,FI!H15,FR!H15,HR!H15,HU!H15,IE!H15,IT!H15,LT!H15,LU!H15,LV!H15,MT!H15,NL!H15,PL!H15,PT!H15,RO!H15,SE!H15,SI!H15,SK!H15) -> 41120.568 | I15: =SUM(AT!I15,BE!I15,BG!I15,CY!I15,CZ!I15,DE!I15,DK!I15,EE!I15,EL!I15,ES!I15,FI!I15,FR!I15,HR!I15,HU!I15,IE!I15,IT!I15,LT!I15,LU!I15,LV!I15,MT!I15,NL!I15,PL!I15,PT!I15,RO!I15,SE!I15,SI!I15,SK!I15) -> 40433.703 | ... Y15: =SUM(AT!Y15,BE!Y15,BG!Y15,CY!Y15,CZ!Y15,DE!Y15,DK!Y15,EE!Y15,EL!Y15,ES!Y15,FI!Y15,FR!Y15,HR!Y15,HU!Y15,IE!Y15,IT!Y15,LT!Y15,LU!Y15,LV!Y15,MT!Y15,NL!Y15,PL!Y15,PT!Y15,RO!Y15,SE!Y15,SI!Y15,SK!Y15) -> 31924.39
A16: 1.A.2.f - Non-metallic minerals | B16: =SUM(AT!B16,BE!B16,BG!B16,CY!B16,CZ!B16,DE!B16,DK!B16,EE!B16,EL!B16,ES!B16,FI!B16,FR!B16,HR!B16,HU!B16,IE!B16,IT!B16,LT!B16,LU!B16,LV!B16,MT!B16,NL!B16,PL!B16,PT!B16,RO!B16,SE!B16,SI!B16,SK!B16) -> 119639.62 | C16: =SUM(AT!C16,BE!C16,BG!C16,CY!C16,CZ!C16,DE!C16,DK!C16,EE!C16,EL!C16,ES!C16,FI!C16,FR!C16,HR!C16,HU!C16,IE!C16,IT!C16,LT!C16,LU!C16,LV!C16,MT!C16,NL!C16,PL!C16,PT!C16,RO!C16,SE!C16,SI!C16,SK!C16) -> 119269.82 | D16: =SUM(AT!D16,BE!D16,BG!D16,CY!D16,CZ!D16,DE!D16,DK!D16,EE!D16,EL!D16,ES!D16,FI!D16,FR!D16,HR!D16,HU!D16,IE!D16,IT!D16,LT!D16,LU!D16,LV!D16,MT!D16,NL!D16,PL!D16,PT!D16,RO!D16,SE!D16,SI!D16,SK!D16) -> 116728.89 | E16: =SUM(AT!E16,BE!E16,BG!E16,CY!E16,CZ!E16,DE!E16,DK!E16,EE!E16,EL!E16,ES!E16,FI!E16,FR!E16,HR!E16,HU!E16,IE!E16,IT!E16,LT!E16,LU!E16,LV!E16,MT!E16,NL!E16,PL!E16,PT!E16,RO!E16,SE!E16,SI!E16,SK!E16) -> 119832.98 | F16: =SUM(AT!F16,BE!F16,BG!F16,CY!F16,CZ!F16,DE!F16,DK!F16,EE!F16,EL!F16,ES!F16,FI!F16,FR!F16,HR!F16,HU!F16,IE!F16,IT!F16,LT!F16,LU!F16,LV!F16,MT!F16,NL!F16,PL!F16,PT!F16,RO!F16,SE!F16,SI!F16,SK!F16) -> 119471.93 | G16: =SUM(AT!G16,BE!G16,BG!G16,CY!G16,CZ!G16,DE!G16,DK!G16,EE!G16,EL!G16,ES!G16,FI!G16,FR!G16,HR!G16,HU!G16,IE!G16,IT!G16,LT!G16,LU!G16,LV!G16,MT!G16,NL!G16,PL!G16,PT!G16,RO!G16,SE!G16,SI!G16,SK!G16) -> 123383.49 | H16: =SUM(AT!H16,BE!H16,BG!H16,CY!H16,CZ!H16,DE!H16,DK!H16,EE!H16,EL!H16,ES!H16,FI!H16,FR!H16,HR!H16,HU!H16,IE!H16,IT!H16,LT!H16,LU!H16,LV!H16,MT!H16,NL!H16,PL!H16,PT!H16,RO!H16,SE!H16,SI!H16,SK!H16) -> 122018.61 | I16: =SUM(AT!I16,BE!I16,BG!I16,CY!I16,CZ!I16,DE!I16,DK!I16,EE!I16,EL!I16,ES!I16,FI!I16,FR!I16,HR!I16,HU!I16,IE!I16,IT!I16,LT!I16,LU!I16,LV!I16,MT!I16,NL!I16,PL!I16,PT!I16,RO!I16,SE!I16,SI!I16,SK!I16) -> 125022.16 | ... Y16: =SUM(AT!Y16,BE!Y16,BG!Y16,CY!Y16,CZ!Y16,DE!Y16,DK!Y16,EE!Y16,EL!Y16,ES!Y16,FI!Y16,FR!Y16,HR!Y16,HU!Y16,IE!Y16,IT!Y16,LT!Y16,LU!Y16,LV!Y16,MT!Y16,NL!Y16,PL!Y16,PT!Y16,RO!Y16,SE!Y16,SI!Y16,SK!Y16) -> 70930.553
A17: 1.A.2.g - Other Manufacturing Industries and Constructions | B17: =SUM(AT!B17,BE!B17,BG!B17,CY!B17,CZ!B17,DE!B17,DK!B17,EE!B17,EL!B17,ES!B17,FI!B17,FR!B17,HR!B17,HU!B17,IE!B17,IT!B17,LT!B17,LU!B17,LV!B17,MT!B17,NL!B17,PL!B17,PT!B17,RO!B17,SE!B17,SI!B17,SK!B17) -> 163934.42 | C17: =SUM(AT!C17,BE!C17,BG!C17,CY!C17,CZ!C17,DE!C17,DK!C17,EE!C17,EL!C17,ES!C17,FI!C17,FR!C17,HR!C17,HU!C17,IE!C17,IT!C17,LT!C17,LU!C17,LV!C17,MT!C17,NL!C17,PL!C17,PT!C17,RO!C17,SE!C17,SI!C17,SK!C17) -> 162496.37 | D17: =SUM(AT!D17,BE!D17,BG!D17,CY!D17,CZ!D17,DE!D17,DK!D17,EE!D17,EL!D17,ES!D17,FI!D17,FR!D17,HR!D17,HU!D17,IE!D17,IT!D17,LT!D17,LU!D17,LV!D17,MT!D17,NL!D17,PL!D17,PT!D17,RO!D17,SE!D17,SI!D17,SK!D17) -> 161724.22 | E17: =SUM(AT!E17,BE!E17,BG!E17,CY!E17,CZ!E17,DE!E17,DK!E17,EE!E17,EL!E17,ES!E17,FI!E17,FR!E17,HR!E17,HU!E17,IE!E17,IT!E17,LT!E17,LU!E17,LV!E17,MT!E17,NL!E17,PL!E17,PT!E17,RO!E17,SE!E17,SI!E17,SK!E17) -> 162669.78 | F17: =SUM(AT!F17,BE!F17,BG!F17,CY!F17,CZ!F17,DE!F17,DK!F17,EE!F17,EL!F17,ES!F17,FI!F17,FR!F17,HR!F17,HU!F17,IE!F17,IT!F17,LT!F17,LU!F17,LV!F17,MT!F17,NL!F17,PL!F17,PT!F17,RO!F17,SE!F17,SI!F17,SK!F17) -> 155877.26 | G17: =SUM(AT!G17,BE!G17,BG!G17,CY!G17,CZ!G17,DE!G17,DK!G17,EE!G17,EL!G17,ES!G17,FI!G17,FR!G17,HR!G17,HU!G17,IE!G17,IT!G17,LT!G17,LU!G17,LV!G17,MT!G17,NL!G17,PL!G17,PT!G17,RO!G17,SE!G17,SI!G17,SK!G17) -> 150682.6 | H17: =SUM(AT!H17,BE!H17,BG!H17,CY!H17,CZ!H17,DE!H17,DK!H17,EE!H17,EL!H17,ES!H17,FI!H17,FR!H17,HR!H17,HU!H17,IE!H17,IT!H17,LT!H17,LU!H17,LV!H17,MT!H17,NL!H17,PL!H17,PT!H17,RO!H17,SE!H17,SI!H17,SK!H17) -> 146970.03 | I17: =SUM(AT!I17,BE!I17,BG!I17,CY!I17,CZ!I17,DE!I17,DK!I17,EE!I17,EL!I17,ES!I17,FI!I17,FR!I17,HR!I17,HU!I17,IE!I17,IT!I17,LT!I17,LU!I17,LV!I17,MT!I17,NL!I17,PL!I17,PT!I17,RO!I17,SE!I17,SI!I17,SK!I17) -> 149438.18 | ... Y17: =SUM(AT!Y17,BE!Y17,BG!Y17,CY!Y17,CZ!Y17,DE!Y17,DK!Y17,EE!Y17,EL!Y17,ES!Y17,FI!Y17,FR!Y17,HR!Y17,HU!Y17,IE!Y17,IT!Y17,LT!Y17,LU!Y17,LV!Y17,MT!Y17,NL!Y17,PL!Y17,PT!Y17,RO!Y17,SE!Y17,SI!Y17,SK!Y17) -> 115995.49
A18: 1.A.3 - Transport | B18: =SUM(B19:B23) -> 787290.73 | C18: =SUM(C19:C23) -> 801576.75 | D18: =SUM(D19:D23) -> 811215.98 | E18: =SUM(E19:E23) -> 818726.91 | F18: =SUM(F19:F23) -> 831837.95 | G18: =SUM(G19:G23) -> 834747.58 | H18: =SUM(H19:H23) -> 851649.77 | I18: =SUM(I19:I23) -> 855110.99 | ... Y18: =SUM(Y19:Y23) -> 785742.9
A19: 1.A.3.a - Domestic Aviation | B19: =SUM(AT!B19,BE!B19,BG!B19,CY!B19,CZ!B19,DE!B19,DK!B19,EE!B19,EL!B19,ES!B19,FI!B19,FR!B19,HR!B19,HU!B19,IE!B19,IT!B19,LT!B19,LU!B19,LV!B19,MT!B19,NL!B19,PL!B19,PT!B19,RO!B19,SE!B19,SI!B19,SK!B19) -> 16737.265 | C19: =SUM(AT!C19,BE!C19,BG!C19,CY!C19,CZ!C19,DE!C19,DK!C19,EE!C19,EL!C19,ES!C19,FI!C19,FR!C19,HR!C19,HU!C19,IE!C19,IT!C19,LT!C19,LU!C19,LV!C19,MT!C19,NL!C19,PL!C19,PT!C19,RO!C19,SE!C19,SI!C19,SK!C19) -> 16250.596 | D19: =SUM(AT!D19,BE!D19,BG!D19,CY!D19,CZ!D19,DE!D19,DK!D19,EE!D19,EL!D19,ES!D19,FI!D19,FR!D19,HR!D19,HU!D19,IE!D19,IT!D19,LT!D19,LU!D19,LV!D19,MT!D19,NL!D19,PL!D19,PT!D19,RO!D19,SE!D19,SI!D19,SK!D19) -> 15936.04 | E19: =SUM(AT!E19,BE!E19,BG!E19,CY!E19,CZ!E19,DE!E19,DK!E19,EE!E19,EL!E19,ES!E19,FI!E19,FR!E19,HR!E19,HU!E19,IE!E19,IT!E19,LT!E19,LU!E19,LV!E19,MT!E19,NL!E19,PL!E19,PT!E19,RO!E19,SE!E19,SI!E19,SK!E19) -> 15862.214 | F19: =SUM(AT!F19,BE!F19,BG!F19,CY!F19,CZ!F19,DE!F19,DK!F19,EE!F19,EL!F19,ES!F19,FI!F19,FR!F19,HR!F19,HU!F19,IE!F19,IT!F19,LT!F19,LU!F19,LV!F19,MT!F19,NL!F19,PL!F19,PT!F19,RO!F19,SE!F19,SI!F19,SK!F19) -> 16359.168 | G19: =SUM(AT!G19,BE!G19,BG!G19,CY!G19,CZ!G19,DE!G19,DK!G19,EE!G19,EL!G19,ES!G19,FI!G19,FR!G19,HR!G19,HU!G19,IE!G19,IT!G19,LT!G19,LU!G19,LV!G19,MT!G19,NL!G19,PL!G19,PT!G19,RO!G19,SE!G19,SI!G19,SK!G19) -> 16351.22 | H19: =SUM(AT!H19,BE!H19,BG!H19,CY!H19,CZ!H19,DE!H19,DK!H19,EE!H19,EL!H19,ES!H19,FI!H19,FR!H19,HR!H19,HU!H19,IE!H19,IT!H19,LT!H19,LU!H19,LV!H19,MT!H19,NL!H19,PL!H19,PT!H19,RO!H19,SE!H19,SI!H19,SK!H19) -> 16343.722 | I19: =SUM(AT!I19,BE!I19,BG!I19,CY!I19,CZ!I19,DE!I19,DK!I19,EE!I19,EL!I19,ES!I19,FI!I19,FR!I19,HR!I19,HU!I19,IE!I19,IT!I19,LT!I19,LU!I19,LV!I19,MT!I19,NL!I19,PL!I19,PT!I19,RO!I19,SE!I19,SI!I19,SK!I19) -> 16779.959 | ... Y19: =SUM(AT!Y19,BE!Y19,BG!Y19,CY!Y19,CZ!Y19,DE!Y19,DK!Y19,EE!Y19,EL!Y19,ES!Y19,FI!Y19,FR!Y19,HR!Y19,HU!Y19,IE!Y19,IT!Y19,LT!Y19,LU!Y19,LV!Y19,MT!Y19,NL!Y19,PL!Y19,PT!Y19,RO!Y19,SE!Y19,SI!Y19,SK!Y19) -> 13053.984
A20: 1.A.3.b - Road Transportation | B20: =SUM(AT!B20,BE!B20,BG!B20,CY!B20,CZ!B20,DE!B20,DK!B20,EE!B20,EL!B20,ES!B20,FI!B20,FR!B20,HR!B20,HU!B20,IE!B20,IT!B20,LT!B20,LU!B20,LV!B20,MT!B20,NL!B20,PL!B20,PT!B20,RO!B20,SE!B20,SI!B20,SK!B20) -> 735885.78 | C20: =SUM(AT!C20,BE!C20,BG!C20,CY!C20,CZ!C20,DE!C20,DK!C20,EE!C20,EL!C20,ES!C20,FI!C20,FR!C20,HR!C20,HU!C20,IE!C20,IT!C20,LT!C20,LU!C20,LV!C20,MT!C20,NL!C20,PL!C20,PT!C20,RO!C20,SE!C20,SI!C20,SK!C20) -> 751432.1 | D20: =SUM(AT!D20,BE!D20,BG!D20,CY!D20,CZ!D20,DE!D20,DK!D20,EE!D20,EL!D20,ES!D20,FI!D20,FR!D20,HR!D20,HU!D20,IE!D20,IT!D20,LT!D20,LU!D20,LV!D20,MT!D20,NL!D20,PL!D20,PT!D20,RO!D20,SE!D20,SI!D20,SK!D20) -> 761791.82 | E20: =SUM(AT!E20,BE!E20,BG!E20,CY!E20,CZ!E20,DE!E20,DK!E20,EE!E20,EL!E20,ES!E20,FI!E20,FR!E20,HR!E20,HU!E20,IE!E20,IT!E20,LT!E20,LU!E20,LV!E20,MT!E20,NL!E20,PL!E20,PT!E20,RO!E20,SE!E20,SI!E20,SK!E20) -> 768815.2 | F20: =SUM(AT!F20,BE!F20,BG!F20,CY!F20,CZ!F20,DE!F20,DK!F20,EE!F20,EL!F20,ES!F20,FI!F20,FR!F20,HR!F20,HU!F20,IE!F20,IT!F20,LT!F20,LU!F20,LV!F20,MT!F20,NL!F20,PL!F20,PT!F20,RO!F20,SE!F20,SI!F20,SK!F20) -> 780512.61 | G20: =SUM(AT!G20,BE!G20,BG!G20,CY!G20,CZ!G20,DE!G20,DK!G20,EE!G20,EL!G20,ES!G20,FI!G20,FR!G20,HR!G20,HU!G20,IE!G20,IT!G20,LT!G20,LU!G20,LV!G20,MT!G20,NL!G20,PL!G20,PT!G20,RO!G20,SE!G20,SI!G20,SK!G20) -> 783828.2 | H20: =SUM(AT!H20,BE!H20,BG!H20,CY!H20,CZ!H20,DE!H20,DK!H20,EE!H20,EL!H20,ES!H20,FI!H20,FR!H20,HR!H20,HU!H20,IE!H20,IT!H20,LT!H20,LU!H20,LV!H20,MT!H20,NL!H20,PL!H20,PT!H20,RO!H20,SE!H20,SI!H20,SK!H20) -> 800506.59 | I20: =SUM(AT!I20,BE!I20,BG!I20,CY!I20,CZ!I20,DE!I20,DK!I20,EE!I20,EL!I20,ES!I20,FI!I20,FR!I20,HR!I20,HU!I20,IE!I20,IT!I20,LT!I20,LU!I20,LV!I20,MT!I20,NL!I20,PL!I20,PT!I20,RO!I20,SE!I20,SI!I20,SK!I20) -> 805238.33 | ... Y20: =SUM(AT!Y20,BE!Y20,BG!Y20,CY!Y20,CZ!Y20,DE!Y20,DK!Y20,EE!Y20,EL!Y20,ES!Y20,FI!Y20,FR!Y20,HR!Y20,HU!Y20,IE!Y20,IT!Y20,LT!Y20,LU!Y20,LV!Y20,MT!Y20,NL!Y20,PL!Y20,PT!Y20,RO!Y20,SE!Y20,SI!Y20,SK!Y20) -> 749089.78
A21: 1.A.3.c - Railways | B21: =SUM(AT!B21,BE!B21,BG!B21,CY!B21,CZ!B21,DE!B21,DK!B21,EE!B21,EL!B21,ES!B21,FI!B21,FR!B21,HR!B21,HU!B21,IE!B21,IT!B21,LT!B21,LU!B21,LV!B21,MT!B21,NL!B21,PL!B21,PT!B21,RO!B21,SE!B21,SI!B21,SK!B21) -> 7727.9221 | C21: =SUM(AT!C21,BE!C21,BG!C21,CY!C21,CZ!C21,DE!C21,DK!C21,EE!C21,EL!C21,ES!C21,FI!C21,FR!C21,HR!C21,HU!C21,IE!C21,IT!C21,LT!C21,LU!C21,LV!C21,MT!C21,NL!C21,PL!C21,PT!C21,RO!C21,SE!C21,SI!C21,SK!C21) -> 6836.6504 | D21: =SUM(AT!D21,BE!D21,BG!D21,CY!D21,CZ!D21,DE!D21,DK!D21,EE!D21,EL!D21,ES!D21,FI!D21,FR!D21,HR!D21,HU!D21,IE!D21,IT!D21,LT!D21,LU!D21,LV!D21,MT!D21,NL!D21,PL!D21,PT!D21,RO!D21,SE!D21,SI!D21,SK!D21) -> 6826.9167 | E21: =SUM(AT!E21,BE!E21,BG!E21,CY!E21,CZ!E21,DE!E21,DK!E21,EE!E21,EL!E21,ES!E21,FI!E21,FR!E21,HR!E21,HU!E21,IE!E21,IT!E21,LT!E21,LU!E21,LV!E21,MT!E21,NL!E21,PL!E21,PT!E21,RO!E21,SE!E21,SI!E21,SK!E21) -> 6738.6734 | F21: =SUM(AT!F21,BE!F21,BG!F21,CY!F21,CZ!F21,DE!F21,DK!F21,EE!F21,EL!F21,ES!F21,FI!F21,FR!F21,HR!F21,HU!F21,IE!F21,IT!F21,LT!F21,LU!F21,LV!F21,MT!F21,NL!F21,PL!F21,PT!F21,RO!F21,SE!F21,SI!F21,SK!F21) -> 6627.6417 | G21: =SUM(AT!G21,BE!G21,BG!G21,CY!G21,CZ!G21,DE!G21,DK!G21,EE!G21,EL!G21,ES!G21,FI!G21,FR!G21,HR!G21,HU!G21,IE!G21,IT!G21,LT!G21,LU!G21,LV!G21,MT!G21,NL!G21,PL!G21,PT!G21,RO!G21,SE!G21,SI!G21,SK!G21) -> 6016.386 | H21: =SUM(AT!H21,BE!H21,BG!H21,CY!H21,CZ!H21,DE!H21,DK!H21,EE!H21,EL!H21,ES!H21,FI!H21,FR!H21,HR!H21,HU!H21,IE!H21,IT!H21,LT!H21,LU!H21,LV!H21,MT!H21,NL!H21,PL!H21,PT!H21,RO!H21,SE!H21,SI!H21,SK!H21) -> 5850.8651 | I21: =SUM(AT!I21,BE!I21,BG!I21,CY!I21,CZ!I21,DE!I21,DK!I21,EE!I21,EL!I21,ES!I21,FI!I21,FR!I21,HR!I21,HU!I21,IE!I21,IT!I21,LT!I21,LU!I21,LV!I21,MT!I21,NL!I21,PL!I21,PT!I21,RO!I21,SE!I21,SI!I21,SK!I21) -> 6048.5826 | ... Y21: =SUM(AT!Y21,BE!Y21,BG!Y21,CY!Y21,CZ!Y21,DE!Y21,DK!Y21,EE!Y21,EL!Y21,ES!Y21,FI!Y21,FR!Y21,HR!Y21,HU!Y21,IE!Y21,IT!Y21,LT!Y21,LU!Y21,LV!Y21,MT!Y21,NL!Y21,PL!Y21,PT!Y21,RO!Y21,SE!Y21,SI!Y21,SK!Y21) -> 3226.423
A22: 1.A.3.d - Domestic Navigation | B22: =SUM(AT!B22,BE!B22,BG!B22,CY!B22,CZ!B22,DE!B22,DK!B22,EE!B22,EL!B22,ES!B22,FI!B22,FR!B22,HR!B22,HU!B22,IE!B22,IT!B22,LT!B22,LU!B22,LV!B22,MT!B22,NL!B22,PL!B22,PT!B22,RO!B22,SE!B22,SI!B22,SK!B22) -> 20102.23 | C22: =SUM(AT!C22,BE!C22,BG!C22,CY!C22,CZ!C22,DE!C22,DK!C22,EE!C22,EL!C22,ES!C22,FI!C22,FR!C22,HR!C22,HU!C22,IE!C22,IT!C22,LT!C22,LU!C22,LV!C22,MT!C22,NL!C22,PL!C22,PT!C22,RO!C22,SE!C22,SI!C22,SK!C22) -> 20381.892 | D22: =SUM(AT!D22,BE!D22,BG!D22,CY!D22,CZ!D22,DE!D22,DK!D22,EE!D22,EL!D22,ES!D22,FI!D22,FR!D22,HR!D22,HU!D22,IE!D22,IT!D22,LT!D22,LU!D22,LV!D22,MT!D22,NL!D22,PL!D22,PT!D22,RO!D22,SE!D22,SI!D22,SK!D22) -> 19997.68 | E22: =SUM(AT!E22,BE!E22,BG!E22,CY!E22,CZ!E22,DE!E22,DK!E22,EE!E22,EL!E22,ES!E22,FI!E22,FR!E22,HR!E22,HU!E22,IE!E22,IT!E22,LT!E22,LU!E22,LV!E22,MT!E22,NL!E22,PL!E22,PT!E22,RO!E22,SE!E22,SI!E22,SK!E22) -> 20736.249 | F22: =SUM(AT!F22,BE!F22,BG!F22,CY!F22,CZ!F22,DE!F22,DK!F22,EE!F22,EL!F22,ES!F22,FI!F22,FR!F22,HR!F22,HU!F22,IE!F22,IT!F22,LT!F22,LU!F22,LV!F22,MT!F22,NL!F22,PL!F22,PT!F22,RO!F22,SE!F22,SI!F22,SK!F22) -> 20680.128 | G22: =SUM(AT!G22,BE!G22,BG!G22,CY!G22,CZ!G22,DE!G22,DK!G22,EE!G22,EL!G22,ES!G22,FI!G22,FR!G22,HR!G22,HU!G22,IE!G22,IT!G22,LT!G22,LU!G22,LV!G22,MT!G22,NL!G22,PL!G22,PT!G22,RO!G22,SE!G22,SI!G22,SK!G22) -> 20414.872 | H22: =SUM(AT!H22,BE!H22,BG!H22,CY!H22,CZ!H22,DE!H22,DK!H22,EE!H22,EL!H22,ES!H22,FI!H22,FR!H22,HR!H22,HU!H22,IE!H22,IT!H22,LT!H22,LU!H22,LV!H22,MT!H22,NL!H22,PL!H22,PT!H22,RO!H22,SE!H22,SI!H22,SK!H22) -> 20827.08 | I22: =SUM(AT!I22,BE!I22,BG!I22,CY!I22,CZ!I22,DE!I22,DK!I22,EE!I22,EL!I22,ES!I22,FI!I22,FR!I22,HR!I22,HU!I22,IE!I22,IT!I22,LT!I22,LU!I22,LV!I22,MT!I22,NL!I22,PL!I22,PT!I22,RO!I22,SE!I22,SI!I22,SK!I22) -> 19568.921 | ... Y22: =SUM(AT!Y22,BE!Y22,BG!Y22,CY!Y22,CZ!Y22,DE!Y22,DK!Y22,EE!Y22,EL!Y22,ES!Y22,FI!Y22,FR!Y22,HR!Y22,HU!Y22,IE!Y22,IT!Y22,LT!Y22,LU!Y22,LV!Y22,MT!Y22,NL!Y22,PL!Y22,PT!Y22,RO!Y22,SE!Y22,SI!Y22,SK!Y22) -> 16232.343
A23: 1.A.3.e - Other Transportation | B23: =SUM(AT!B23,BE!B23,BG!B23,CY!B23,CZ!B23,DE!B23,DK!B23,EE!B23,EL!B23,ES!B23,FI!B23,FR!B23,HR!B23,HU!B23,IE!B23,IT!B23,LT!B23,LU!B23,LV!B23,MT!B23,NL!B23,PL!B23,PT!B23,RO!B23,SE!B23,SI!B23,SK!B23) -> 6837.5314 | C23: =SUM(AT!C23,BE!C23,BG!C23,CY!C23,CZ!C23,DE!C23,DK!C23,EE!C23,EL!C23,ES!C23,FI!C23,FR!C23,HR!C23,HU!C23,IE!C23,IT!C23,LT!C23,LU!C23,LV!C23,MT!C23,NL!C23,PL!C23,PT!C23,RO!C23,SE!C23,SI!C23,SK!C23) -> 6675.5114 | D23: =SUM(AT!D23,BE!D23,BG!D23,CY!D23,CZ!D23,DE!D23,DK!D23,EE!D23,EL!D23,ES!D23,FI!D23,FR!D23,HR!D23,HU!D23,IE!D23,IT!D23,LT!D23,LU!D23,LV!D23,MT!D23,NL!D23,PL!D23,PT!D23,RO!D23,SE!D23,SI!D23,SK!D23) -> 6663.5169 | E23: =SUM(AT!E23,BE!E23,BG!E23,CY!E23,CZ!E23,DE!E23,DK!E23,EE!E23,EL!E23,ES!E23,FI!E23,FR!E23,HR!E23,HU!E23,IE!E23,IT!E23,LT!E23,LU!E23,LV!E23,MT!E23,NL!E23,PL!E23,PT!E23,RO!E23,SE!E23,SI!E23,SK!E23) -> 6574.5685 | F23: =SUM(AT!F23,BE!F23,BG!F23,CY!F23,CZ!F23,DE!F23,DK!F23,EE!F23,EL!F23,ES!F23,FI!F23,FR!F23,HR!F23,HU!F23,IE!F23,IT!F23,LT!F23,LU!F23,LV!F23,MT!F23,NL!F23,PL!F23,PT!F23,RO!F23,SE!F23,SI!F23,SK!F23) -> 7658.4028 | G23: =SUM(AT!G23,BE!G23,BG!G23,CY!G23,CZ!G23,DE!G23,DK!G23,EE!G23,EL!G23,ES!G23,FI!G23,FR!G23,HR!G23,HU!G23,IE!G23,IT!G23,LT!G23,LU!G23,LV!G23,MT!G23,NL!G23,PL!G23,PT!G23,RO!G23,SE!G23,SI!G23,SK!G23) -> 8136.9045 | H23: =SUM(AT!H23,BE!H23,BG!H23,CY!H23,CZ!H23,DE!H23,DK!H23,EE!H23,EL!H23,ES!H23,FI!H23,FR!H23,HR!H23,HU!H23,IE!H23,IT!H23,LT!H23,LU!H23,LV!H23,MT!H23,NL!H23,PL!H23,PT!H23,RO!H23,SE!H23,SI!H23,SK!H23) -> 8121.5121 | I23: =SUM(AT!I23,BE!I23,BG!I23,CY!I23,CZ!I23,DE!I23,DK!I23,EE!I23,EL!I23,ES!I23,FI!I23,FR!I23,HR!I23,HU!I23,IE!I23,IT!I23,LT!I23,LU!I23,LV!I23,MT!I23,NL!I23,PL!I23,PT!I23,RO!I23,SE!I23,SI!I23,SK!I23) -> 7475.1952 | ... Y23: =SUM(AT!Y23,BE!Y23,BG!Y23,CY!Y23,CZ!Y23,DE!Y23,DK!Y23,EE!Y23,EL!Y23,ES!Y23,FI!Y23,FR!Y23,HR!Y23,HU!Y23,IE!Y23,IT!Y23,LT!Y23,LU!Y23,LV!Y23,MT!Y23,NL!Y23,PL!Y23,PT!Y23,RO!Y23,SE!Y23,SI!Y23,SK!Y23) -> 4140.3709
A24: 1.A.4 - Other Sectors | B24: =SUM(B25:B27) -> 614868.52 | C24: =SUM(C25:C27) -> 656549.23 | D24: =SUM(D25:D27) -> 633473.89 | E24: =SUM(E25:E27) -> 640281.25 | F24: =SUM(F25:F27) -> 638559.07 | G24: =SUM(G25:G27) -> 644918.42 | H24: =SUM(H25:H27) -> 641336.23 | I24: =SUM(I25:I27) -> 561203.62 | ... Y24: =SUM(Y25:Y27) -> 422016.14
A25: 1.A.4.a - Commercial/Institutional | B25: =SUM(AT!B25,BE!B25,BG!B25,CY!B25,CZ!B25,DE!B25,DK!B25,EE!B25,EL!B25,ES!B25,FI!B25,FR!B25,HR!B25,HU!B25,IE!B25,IT!B25,LT!B25,LU!B25,LV!B25,MT!B25,NL!B25,PL!B25,PT!B25,RO!B25,SE!B25,SI!B25,SK!B25) -> 142951.82 | C25: =SUM(AT!C25,BE!C25,BG!C25,CY!C25,CZ!C25,DE!C25,DK!C25,EE!C25,EL!C25,ES!C25,FI!C25,FR!C25,HR!C25,HU!C25,IE!C25,IT!C25,LT!C25,LU!C25,LV!C25,MT!C25,NL!C25,PL!C25,PT!C25,RO!C25,SE!C25,SI!C25,SK!C25) -> 156107.24 | D25: =SUM(AT!D25,BE!D25,BG!D25,CY!D25,CZ!D25,DE!D25,DK!D25,EE!D25,EL!D25,ES!D25,FI!D25,FR!D25,HR!D25,HU!D25,IE!D25,IT!D25,LT!D25,LU!D25,LV!D25,MT!D25,NL!D25,PL!D25,PT!D25,RO!D25,SE!D25,SI!D25,SK!D25) -> 149890.39 | E25: =SUM(AT!E25,BE!E25,BG!E25,CY!E25,CZ!E25,DE!E25,DK!E25,EE!E25,EL!E25,ES!E25,FI!E25,FR!E25,HR!E25,HU!E25,IE!E25,IT!E25,LT!E25,LU!E25,LV!E25,MT!E25,NL!E25,PL!E25,PT!E25,RO!E25,SE!E25,SI!E25,SK!E25) -> 145694.1 | F25: =SUM(AT!F25,BE!F25,BG!F25,CY!F25,CZ!F25,DE!F25,DK!F25,EE!F25,EL!F25,ES!F25,FI!F25,FR!F25,HR!F25,HU!F25,IE!F25,IT!F25,LT!F25,LU!F25,LV!F25,MT!F25,NL!F25,PL!F25,PT!F25,RO!F25,SE!F25,SI!F25,SK!F25) -> 149653.77 | G25: =SUM(AT!G25,BE!G25,BG!G25,CY!G25,CZ!G25,DE!G25,DK!G25,EE!G25,EL!G25,ES!G25,FI!G25,FR!G25,HR!G25,HU!G25,IE!G25,IT!G25,LT!G25,LU!G25,LV!G25,MT!G25,NL!G25,PL!G25,PT!G25,RO!G25,SE!G25,SI!G25,SK!G25) -> 156877.01 | H25: =SUM(AT!H25,BE!H25,BG!H25,CY!H25,CZ!H25,DE!H25,DK!H25,EE!H25,EL!H25,ES!H25,FI!H25,FR!H25,HR!H25,HU!H25,IE!H25,IT!H25,LT!H25,LU!H25,LV!H25,MT!H25,NL!H25,PL!H25,PT!H25,RO!H25,SE!H25,SI!H25,SK!H25) -> 163015.46 | I25: =SUM(AT!I25,BE!I25,BG!I25,CY!I25,CZ!I25,DE!I25,DK!I25,EE!I25,EL!I25,ES!I25,FI!I25,FR!I25,HR!I25,HU!I25,IE!I25,IT!I25,LT!I25,LU!I25,LV!I25,MT!I25,NL!I25,PL!I25,PT!I25,RO!I25,SE!I25,SI!I25,SK!I25) -> 139678.01 | ... Y25: =SUM(AT!Y25,BE!Y25,BG!Y25,CY!Y25,CZ!Y25,DE!Y25,DK!Y25,EE!Y25,EL!Y25,ES!Y25,FI!Y25,FR!Y25,HR!Y25,HU!Y25,IE!Y25,IT!Y25,LT!Y25,LU!Y25,LV!Y25,MT!Y25,NL!Y25,PL!Y25,PT!Y25,RO!Y25,SE!Y25,SI!Y25,SK!Y25) -> 100643.64
A26: 1.A.4.b - Residential | B26: =SUM(AT!B26,BE!B26,BG!B26,CY!B26,CZ!B26,DE!B26,DK!B26,EE!B26,EL!B26,ES!B26,FI!B26,FR!B26,HR!B26,HU!B26,IE!B26,IT!B26,LT!B26,LU!B26,LV!B26,MT!B26,NL!B26,PL!B26,PT!B26,RO!B26,SE!B26,SI!B26,SK!B26) -> 389475 | C26: =SUM(AT!C26,BE!C26,BG!C26,CY!C26,CZ!C26,DE!C26,DK!C26,EE!C26,EL!C26,ES!C26,FI!C26,FR!C26,HR!C26,HU!C26,IE!C26,IT!C26,LT!C26,LU!C26,LV!C26,MT!C26,NL!C26,PL!C26,PT!C26,RO!C26,SE!C26,SI!C26,SK!C26) -> 418061.97 | D26: =SUM(AT!D26,BE!D26,BG!D26,CY!D26,CZ!D26,DE!D26,DK!D26,EE!D26,EL!D26,ES!D26,FI!D26,FR!D26,HR!D26,HU!D26,IE!D26,IT!D26,LT!D26,LU!D26,LV!D26,MT!D26,NL!D26,PL!D26,PT!D26,RO!D26,SE!D26,SI!D26,SK!D26) -> 403307.11 | E26: =SUM(AT!E26,BE!E26,BG!E26,CY!E26,CZ!E26,DE!E26,DK!E26,EE!E26,EL!E26,ES!E26,FI!E26,FR!E26,HR!E26,HU!E26,IE!E26,IT!E26,LT!E26,LU!E26,LV!E26,MT!E26,NL!E26,PL!E26,PT!E26,RO!E26,SE!E26,SI!E26,SK!E26) -> 413736.66 | F26: =SUM(AT!F26,BE!F26,BG!F26,CY!F26,CZ!F26,DE!F26,DK!F26,EE!F26,EL!F26,ES!F26,FI!F26,FR!F26,HR!F26,HU!F26,IE!F26,IT!F26,LT!F26,LU!F26,LV!F26,MT!F26,NL!F26,PL!F26,PT!F26,RO!F26,SE!F26,SI!F26,SK!F26) -> 407632.63 | G26: =SUM(AT!G26,BE!G26,BG!G26,CY!G26,CZ!G26,DE!G26,DK!G26,EE!G26,EL!G26,ES!G26,FI!G26,FR!G26,HR!G26,HU!G26,IE!G26,IT!G26,LT!G26,LU!G26,LV!G26,MT!G26,NL!G26,PL!G26,PT!G26,RO!G26,SE!G26,SI!G26,SK!G26) -> 406952.62 | H26: =SUM(AT!H26,BE!H26,BG!H26,CY!H26,CZ!H26,DE!H26,DK!H26,EE!H26,EL!H26,ES!H26,FI!H26,FR!H26,HR!H26,HU!H26,IE!H26,IT!H26,LT!H26,LU!H26,LV!H26,MT!H26,NL!H26,PL!H26,PT!H26,RO!H26,SE!H26,SI!H26,SK!H26) -> 400103.88 | I26: =SUM(AT!I26,BE!I26,BG!I26,CY!I26,CZ!I26,DE!I26,DK!I26,EE!I26,EL!I26,ES!I26,FI!I26,FR!I26,HR!I26,HU!I26,IE!I26,IT!I26,LT!I26,LU!I26,LV!I26,MT!I26,NL!I26,PL!I26,PT!I26,RO!I26,SE!I26,SI!I26,SK!I26) -> 346476.03 | ... Y26: =SUM(AT!Y26,BE!Y26,BG!Y26,CY!Y26,CZ!Y26,DE!Y26,DK!Y26,EE!Y26,EL!Y26,ES!Y26,FI!Y26,FR!Y26,HR!Y26,HU!Y26,IE!Y26,IT!Y26,LT!Y26,LU!Y26,LV!Y26,MT!Y26,NL!Y26,PL!Y26,PT!Y26,RO!Y26,SE!Y26,SI!Y26,SK!Y26) -> 251588
A27: 1.A.4.c - Agriculture/Forestry/Fishing | B27: =SUM(AT!B27,BE!B27,BG!B27,CY!B27,CZ!B27,DE!B27,DK!B27,EE!B27,EL!B27,ES!B27,FI!B27,FR!B27,HR!B27,HU!B27,IE!B27,IT!B27,LT!B27,LU!B27,LV!B27,MT!B27,NL!B27,PL!B27,PT!B27,RO!B27,SE!B27,SI!B27,SK!B27) -> 82441.701 | C27: =SUM(AT!C27,BE!C27,BG!C27,CY!C27,CZ!C27,DE!C27,DK!C27,EE!C27,EL!C27,ES!C27,FI!C27,FR!C27,HR!C27,HU!C27,IE!C27,IT!C27,LT!C27,LU!C27,LV!C27,MT!C27,NL!C27,PL!C27,PT!C27,RO!C27,SE!C27,SI!C27,SK!C27) -> 82380.026 | D27: =SUM(AT!D27,BE!D27,BG!D27,CY!D27,CZ!D27,DE!D27,DK!D27,EE!D27,EL!D27,ES!D27,FI!D27,FR!D27,HR!D27,HU!D27,IE!D27,IT!D27,LT!D27,LU!D27,LV!D27,MT!D27,NL!D27,PL!D27,PT!D27,RO!D27,SE!D27,SI!D27,SK!D27) -> 80276.388 | E27: =SUM(AT!E27,BE!E27,BG!E27,CY!E27,CZ!E27,DE!E27,DK!E27,EE!E27,EL!E27,ES!E27,FI!E27,FR!E27,HR!E27,HU!E27,IE!E27,IT!E27,LT!E27,LU!E27,LV!E27,MT!E27,NL!E27,PL!E27,PT!E27,RO!E27,SE!E27,SI!E27,SK!E27) -> 80850.485 | F27: =SUM(AT!F27,BE!F27,BG!F27,CY!F27,CZ!F27,DE!F27,DK!F27,EE!F27,EL!F27,ES!F27,FI!F27,FR!F27,HR!F27,HU!F27,IE!F27,IT!F27,LT!F27,LU!F27,LV!F27,MT!F27,NL!F27,PL!F27,PT!F27,RO!F27,SE!F27,SI!F27,SK!F27) -> 81272.674 | G27: =SUM(AT!G27,BE!G27,BG!G27,CY!G27,CZ!G27,DE!G27,DK!G27,EE!G27,EL!G27,ES!G27,FI!G27,FR!G27,HR!G27,HU!G27,IE!G27,IT!G27,LT!G27,LU!G27,LV!G27,MT!G27,NL!G27,PL!G27,PT!G27,RO!G27,SE!G27,SI!G27,SK!G27) -> 81088.796 | H27: =SUM(AT!H27,BE!H27,BG!H27,CY!H27,CZ!H27,DE!H27,DK!H27,EE!H27,EL!H27,ES!H27,FI!H27,FR!H27,HR!H27,HU!H27,IE!H27,IT!H27,LT!H27,LU!H27,LV!H27,MT!H27,NL!H27,PL!H27,PT!H27,RO!H27,SE!H27,SI!H27,SK!H27) -> 78216.888 | I27: =SUM(AT!I27,BE!I27,BG!I27,CY!I27,CZ!I27,DE!I27,DK!I27,EE!I27,EL!I27,ES!I27,FI!I27,FR!I27,HR!I27,HU!I27,IE!I27,IT!I27,LT!I27,LU!I27,LV!I27,MT!I27,NL!I27,PL!I27,PT!I27,RO!I27,SE!I27,SI!I27,SK!I27) -> 75049.569 | ... Y27: =SUM(AT!Y27,BE!Y27,BG!Y27,CY!Y27,CZ!Y27,DE!Y27,DK!Y27,EE!Y27,EL!Y27,ES!Y27,FI!Y27,FR!Y27,HR!Y27,HU!Y27,IE!Y27,IT!Y27,LT!Y27,LU!Y27,LV!Y27,MT!Y27,NL!Y27,PL!Y27,PT!Y27,RO!Y27,SE!Y27,SI!Y27,SK!Y27) -> 69784.494
A28: 1.A.5 - Other Other Sectors | B28: =SUM(B29:B30) -> 8454.673 | C28: =SUM(C29:C30) -> 7964.6191 | D28: =SUM(D29:D30) -> 8312.5079 | E28: =SUM(E29:E30) -> 9087.6868 | F28: =SUM(F29:F30) -> 10182.041 | G28: =SUM(G29:G30) -> 10619.762 | H28: =SUM(H29:H30) -> 9538.6185 | I28: =SUM(I29:I30) -> 9458.926 | ... Y28: =SUM(Y29:Y30) -> 7265.4656
A29: 1.A.5.a - Stationary | B29: =SUM(AT!B29,BE!B29,BG!B29,CY!B29,CZ!B29,DE!B29,DK!B29,EE!B29,EL!B29,ES!B29,FI!B29,FR!B29,HR!B29,HU!B29,IE!B29,IT!B29,LT!B29,LU!B29,LV!B29,MT!B29,NL!B29,PL!B29,PT!B29,RO!B29,SE!B29,SI!B29,SK!B29) -> 4731.8725 | C29: =SUM(AT!C29,BE!C29,BG!C29,CY!C29,CZ!C29,DE!C29,DK!C29,EE!C29,EL!C29,ES!C29,FI!C29,FR!C29,HR!C29,HU!C29,IE!C29,IT!C29,LT!C29,LU!C29,LV!C29,MT!C29,NL!C29,PL!C29,PT!C29,RO!C29,SE!C29,SI!C29,SK!C29) -> 5099.9376 | D29: =SUM(AT!D29,BE!D29,BG!D29,CY!D29,CZ!D29,DE!D29,DK!D29,EE!D29,EL!D29,ES!D29,FI!D29,FR!D29,HR!D29,HU!D29,IE!D29,IT!D29,LT!D29,LU!D29,LV!D29,MT!D29,NL!D29,PL!D29,PT!D29,RO!D29,SE!D29,SI!D29,SK!D29) -> 5403.1741 | E29: =SUM(AT!E29,BE!E29,BG!E29,CY!E29,CZ!E29,DE!E29,DK!E29,EE!E29,EL!E29,ES!E29,FI!E29,FR!E29,HR!E29,HU!E29,IE!E29,IT!E29,LT!E29,LU!E29,LV!E29,MT!E29,NL!E29,PL!E29,PT!E29,RO!E29,SE!E29,SI!E29,SK!E29) -> 5795.8783 | F29: =SUM(AT!F29,BE!F29,BG!F29,CY!F29,CZ!F29,DE!F29,DK!F29,EE!F29,EL!F29,ES!F29,FI!F29,FR!F29,HR!F29,HU!F29,IE!F29,IT!F29,LT!F29,LU!F29,LV!F29,MT!F29,NL!F29,PL!F29,PT!F29,RO!F29,SE!F29,SI!F29,SK!F29) -> 6500.6478 | G29: =SUM(AT!G29,BE!G29,BG!G29,CY!G29,CZ!G29,DE!G29,DK!G29,EE!G29,EL!G29,ES!G29,FI!G29,FR!G29,HR!G29,HU!G29,IE!G29,IT!G29,LT!G29,LU!G29,LV!G29,MT!G29,NL!G29,PL!G29,PT!G29,RO!G29,SE!G29,SI!G29,SK!G29) -> 6215.2456 | H29: =SUM(AT!H29,BE!H29,BG!H29,CY!H29,CZ!H29,DE!H29,DK!H29,EE!H29,EL!H29,ES!H29,FI!H29,FR!H29,HR!H29,HU!H29,IE!H29,IT!H29,LT!H29,LU!H29,LV!H29,MT!H29,NL!H29,PL!H29,PT!H29,RO!H29,SE!H29,SI!H29,SK!H29) -> 5511.1179 | I29: =SUM(AT!I29,BE!I29,BG!I29,CY!I29,CZ!I29,DE!I29,DK!I29,EE!I29,EL!I29,ES!I29,FI!I29,FR!I29,HR!I29,HU!I29,IE!I29,IT!I29,LT!I29,LU!I29,LV!I29,MT!I29,NL!I29,PL!I29,PT!I29,RO!I29,SE!I29,SI!I29,SK!I29) -> 5559.6262 | ... Y29: =SUM(AT!Y29,BE!Y29,BG!Y29,CY!Y29,CZ!Y29,DE!Y29,DK!Y29,EE!Y29,EL!Y29,ES!Y29,FI!Y29,FR!Y29,HR!Y29,HU!Y29,IE!Y29,IT!Y29,LT!Y29,LU!Y29,LV!Y29,MT!Y29,NL!Y29,PL!Y29,PT!Y29,RO!Y29,SE!Y29,SI!Y29,SK!Y29) -> 4543.2988
A30: 1.A.5.b - Mobile | B30: =SUM(AT!B30,BE!B30,BG!B30,CY!B30,CZ!B30,DE!B30,DK!B30,EE!B30,EL!B30,ES!B30,FI!B30,FR!B30,HR!B30,HU!B30,IE!B30,IT!B30,LT!B30,LU!B30,LV!B30,MT!B30,NL!B30,PL!B30,PT!B30,RO!B30,SE!B30,SI!B30,SK!B30) -> 3722.8006 | C30: =SUM(AT!C30,BE!C30,BG!C30,CY!C30,CZ!C30,DE!C30,DK!C30,EE!C30,EL!C30,ES!C30,FI!C30,FR!C30,HR!C30,HU!C30,IE!C30,IT!C30,LT!C30,LU!C30,LV!C30,MT!C30,NL!C30,PL!C30,PT!C30,RO!C30,SE!C30,SI!C30,SK!C30) -> 2864.6816 | D30: =SUM(AT!D30,BE!D30,BG!D30,CY!D30,CZ!D30,DE!D30,DK!D30,EE!D30,EL!D30,ES!D30,FI!D30,FR!D30,HR!D30,HU!D30,IE!D30,IT!D30,LT!D30,LU!D30,LV!D30,MT!D30,NL!D30,PL!D30,PT!D30,RO!D30,SE!D30,SI!D30,SK!D30) -> 2909.3338 | E30: =SUM(AT!E30,BE!E30,BG!E30,CY!E30,CZ!E30,DE!E30,DK!E30,EE!E30,EL!E30,ES!E30,FI!E30,FR!E30,HR!E30,HU!E30,IE!E30,IT!E30,LT!E30,LU!E30,LV!E30,MT!E30,NL!E30,PL!E30,PT!E30,RO!E30,SE!E30,SI!E30,SK!E30) -> 3291.8085 | F30: =SUM(AT!F30,BE!F30,BG!F30,CY!F30,CZ!F30,DE!F30,DK!F30,EE!F30,EL!F30,ES!F30,FI!F30,FR!F30,HR!F30,HU!F30,IE!F30,IT!F30,LT!F30,LU!F30,LV!F30,MT!F30,NL!F30,PL!F30,PT!F30,RO!F30,SE!F30,SI!F30,SK!F30) -> 3681.3935 | G30: =SUM(AT!G30,BE!G30,BG!G30,CY!G30,CZ!G30,DE!G30,DK!G30,EE!G30,EL!G30,ES!G30,FI!G30,FR!G30,HR!G30,HU!G30,IE!G30,IT!G30,LT!G30,LU!G30,LV!G30,MT!G30,NL!G30,PL!G30,PT!G30,RO!G30,SE!G30,SI!G30,SK!G30) -> 4404.5165 | H30: =SUM(AT!H30,BE!H30,BG!H30,CY!H30,CZ!H30,DE!H30,DK!H30,EE!H30,EL!H30,ES!H30,FI!H30,FR!H30,HR!H30,HU!H30,IE!H30,IT!H30,LT!H30,LU!H30,LV!H30,MT!H30,NL!H30,PL!H30,PT!H30,RO!H30,SE!H30,SI!H30,SK!H30) -> 4027.5007 | I30: =SUM(AT!I30,BE!I30,BG!I30,CY!I30,CZ!I30,DE!I30,DK!I30,EE!I30,EL!I30,ES!I30,FI!I30,FR!I30,HR!I30,HU!I30,IE!I30,IT!I30,LT!I30,LU!I30,LV!I30,MT!I30,NL!I30,PL!I30,PT!I30,RO!I30,SE!I30,SI!I30,SK!I30) -> 3899.2998 | ... Y30: =SUM(AT!Y30,BE!Y30,BG!Y30,CY!Y30,CZ!Y30,DE!Y30,DK!Y30,EE!Y30,EL!Y30,ES!Y30,FI!Y30,FR!Y30,HR!Y30,HU!Y30,IE!Y30,IT!Y30,LT!Y30,LU!Y30,LV!Y30,MT!Y30,NL!Y30,PL!Y30,PT!Y30,RO!Y30,SE!Y30,SI!Y30,SK!Y30) -> 2722.1668
A31: 1.B - Fugitive Emissions from Fuels | B31: =SUM(AT!B31,BE!B31,BG!B31,CY!B31,CZ!B31,DE!B31,DK!B31,EE!B31,EL!B31,ES!B31,FI!B31,FR!B31,HR!B31,HU!B31,IE!B31,IT!B31,LT!B31,LU!B31,LV!B31,MT!B31,NL!B31,PL!B31,PT!B31,RO!B31,SE!B31,SI!B31,SK!B31) -> 20974.364 | C31: =SUM(AT!C31,BE!C31,BG!C31,CY!C31,CZ!C31,DE!C31,DK!C31,EE!C31,EL!C31,ES!C31,FI!C31,FR!C31,HR!C31,HU!C31,IE!C31,IT!C31,LT!C31,LU!C31,LV!C31,MT!C31,NL!C31,PL!C31,PT!C31,RO!C31,SE!C31,SI!C31,SK!C31) -> 19779.237 | D31: =SUM(AT!D31,BE!D31,BG!D31,CY!D31,CZ!D31,DE!D31,DK!D31,EE!D31,EL!D31,ES!D31,FI!D31,FR!D31,HR!D31,HU!D31,IE!D31,IT!D31,LT!D31,LU!D31,LV!D31,MT!D31,NL!D31,PL!D31,PT!D31,RO!D31,SE!D31,SI!D31,SK!D31) -> 20413.534 | E31: =SUM(AT!E31,BE!E31,BG!E31,CY!E31,CZ!E31,DE!E31,DK!E31,EE!E31,EL!E31,ES!E31,FI!E31,FR!E31,HR!E31,HU!E31,IE!E31,IT!E31,LT!E31,LU!E31,LV!E31,MT!E31,NL!E31,PL!E31,PT!E31,RO!E31,SE!E31,SI!E31,SK!E31) -> 21469.564 | F31: =SUM(AT!F31,BE!F31,BG!F31,CY!F31,CZ!F31,DE!F31,DK!F31,EE!F31,EL!F31,ES!F31,FI!F31,FR!F31,HR!F31,HU!F31,IE!F31,IT!F31,LT!F31,LU!F31,LV!F31,MT!F31,NL!F31,PL!F31,PT!F31,RO!F31,SE!F31,SI!F31,SK!F31) -> 20187.203 | G31: =SUM(AT!G31,BE!G31,BG!G31,CY!G31,CZ!G31,DE!G31,DK!G31,EE!G31,EL!G31,ES!G31,FI!G31,FR!G31,HR!G31,HU!G31,IE!G31,IT!G31,LT!G31,LU!G31,LV!G31,MT!G31,NL!G31,PL!G31,PT!G31,RO!G31,SE!G31,SI!G31,SK!G31) -> 21021.444 | H31: =SUM(AT!H31,BE!H31,BG!H31,CY!H31,CZ!H31,DE!H31,DK!H31,EE!H31,EL!H31,ES!H31,FI!H31,FR!H31,HR!H31,HU!H31,IE!H31,IT!H31,LT!H31,LU!H31,LV!H31,MT!H31,NL!H31,PL!H31,PT!H31,RO!H31,SE!H31,SI!H31,SK!H31) -> 22974.045 | I31: =SUM(AT!I31,BE!I31,BG!I31,CY!I31,CZ!I31,DE!I31,DK!I31,EE!I31,EL!I31,ES!I31,FI!I31,FR!I31,HR!I31,HU!I31,IE!I31,IT!I31,LT!I31,LU!I31,LV!I31,MT!I31,NL!I31,PL!I31,PT!I31,RO!I31,SE!I31,SI!I31,SK!I31) -> 22759.594 | ... Y31: =SUM(AT!Y31,BE!Y31,BG!Y31,CY!Y31,CZ!Y31,DE!Y31,DK!Y31,EE!Y31,EL!Y31,ES!Y31,FI!Y31,FR!Y31,HR!Y31,HU!Y31,IE!Y31,IT!Y31,LT!Y31,LU!Y31,LV!Y31,MT!Y31,NL!Y31,PL!Y31,PT!Y31,RO!Y31,SE!Y31,SI!Y31,SK!Y31) -> 16918.829
A32: 1.C - CO2 Transport and Storage | B32: =SUM(AT!B32,BE!B32,BG!B32,CY!B32,CZ!B32,DE!B32,DK!B32,EE!B32,EL!B32,ES!B32,FI!B32,FR!B32,HR!B32,HU!B32,IE!B32,IT!B32,LT!B32,LU!B32,LV!B32,MT!B32,NL!B32,PL!B32,PT!B32,RO!B32,SE!B32,SI!B32,SK!B32) -> 0 | C32: =SUM(AT!C32,BE!C32,BG!C32,CY!C32,CZ!C32,DE!C32,DK!C32,EE!C32,EL!C32,ES!C32,FI!C32,FR!C32,HR!C32,HU!C32,IE!C32,IT!C32,LT!C32,LU!C32,LV!C32,MT!C32,NL!C32,PL!C32,PT!C32,RO!C32,SE!C32,SI!C32,SK!C32) -> 0 | D32: =SUM(AT!D32,BE!D32,BG!D32,CY!D32,CZ!D32,DE!D32,DK!D32,EE!D32,EL!D32,ES!D32,FI!D32,FR!D32,HR!D32,HU!D32,IE!D32,IT!D32,LT!D32,LU!D32,LV!D32,MT!D32,NL!D32,PL!D32,PT!D32,RO!D32,SE!D32,SI!D32,SK!D32) -> 0 | E32: =SUM(AT!E32,BE!E32,BG!E32,CY!E32,CZ!E32,DE!E32,DK!E32,EE!E32,EL!E32,ES!E32,FI!E32,FR!E32,HR!E32,HU!E32,IE!E32,IT!E32,LT!E32,LU!E32,LV!E32,MT!E32,NL!E32,PL!E32,PT!E32,RO!E32,SE!E32,SI!E32,SK!E32) -> 0 | F32: =SUM(AT!F32,BE!F32,BG!F32,CY!F32,CZ!F32,DE!F32,DK!F32,EE!F32,EL!F32,ES!F32,FI!F32,FR!F32,HR!F32,HU!F32,IE!F32,IT!F32,LT!F32,LU!F32,LV!F32,MT!F32,NL!F32,PL!F32,PT!F32,RO!F32,SE!F32,SI!F32,SK!F32) -> 0 | G32: =SUM(AT!G32,BE!G32,BG!G32,CY!G32,CZ!G32,DE!G32,DK!G32,EE!G32,EL!G32,ES!G32,FI!G32,FR!G32,HR!G32,HU!G32,IE!G32,IT!G32,LT!G32,LU!G32,LV!G32,MT!G32,NL!G32,PL!G32,PT!G32,RO!G32,SE!G32,SI!G32,SK!G32) -> 0 | H32: =SUM(AT!H32,BE!H32,BG!H32,CY!H32,CZ!H32,DE!H32,DK!H32,EE!H32,EL!H32,ES!H32,FI!H32,FR!H32,HR!H32,HU!H32,IE!H32,IT!H32,LT!H32,LU!H32,LV!H32,MT!H32,NL!H32,PL!H32,PT!H32,RO!H32,SE!H32,SI!H32,SK!H32) -> 0 | I32: =SUM(AT!I32,BE!I32,BG!I32,CY!I32,CZ!I32,DE!I32,DK!I32,EE!I32,EL!I32,ES!I32,FI!I32,FR!I32,HR!I32,HU!I32,IE!I32,IT!I32,LT!I32,LU!I32,LV!I32,MT!I32,NL!I32,PL!I32,PT!I32,RO!I32,SE!I32,SI!I32,SK!I32) -> 0 | ... Y32: =SUM(AT!Y32,BE!Y32,BG!Y32,CY!Y32,CZ!Y32,DE!Y32,DK!Y32,EE!Y32,EL!Y32,ES!Y32,FI!Y32,FR!Y32,HR!Y32,HU!Y32,IE!Y32,IT!Y32,LT!Y32,LU!Y32,LV!Y32,MT!Y32,NL!Y32,PL!Y32,PT!Y32,RO!Y32,SE!Y32,SI!Y32,SK!Y32) -> 0
A33: 2 - Industrial Processes and Product Use | B33: =SUM(B34:B41) -> 292931.99 | C33: =SUM(C34:C41) -> 282528.04 | D33: =SUM(D34:D41) -> 283658.62 | E33: =SUM(E34:E41) -> 290816.51 | F33: =SUM(F34:F41) -> 302572.28 | G33: =SUM(G34:G41) -> 299750.44 | H33: =SUM(H34:H41) -> 306642.26 | I33: =SUM(I34:I41) -> 313584.1 | ... Y33: =SUM(Y34:Y41) -> 196294.29
