Workbook

Sheet cover
B6: JRC-IDEES-2023 - Integrated Database of the European Energy System
C10: European Union (27 countries from 2020)
C15: Energy balances
L28: Prepared by JRC C.6
L30: 45967.481
L31: v2023-1.00
B33: Legal Notice
B35: The information made available is property of the Joint Research Centre of the European Commission.
B36: Neither the European Commission nor any person acting on behalf of the Commission is responsible for the use which might be made of this information.
B38: Use conditions
B39: This work is licensed under
B40: CC BY 4.0

Sheet index
A1: European Union (27 countries from 2020) | B1: EU27 | C1: 2000 | D1: 2001 | E1: 2002 | F1: 2003 | G1: 2004 | H1: 2005 | I1: 2006 | J1: 2007 | K1: 2008 | L1: 2009 | M1: 2010 | N1: 2011 | O1: 2012 | P1: 2013 | Q1: 2014 | R1: 2015 | S1: 2016 | T1: 2017 | U1: 2018 | V1: 2019 | W1: 2020 | X1: 2021 | Y1: 2022 | Z1: 2023
B2: Click on the link to jump to the sheet
A3: Total | B3: kt CO2
A4: Gross available energy | B4: =HYPERLINK("#"&CELL("address",GAE!$Z$2),"GAE") -> GAE | C4: =GAE!C$2 -> 3498242.5 | D4: =GAE!D$2 -> 3556692.7 | E4: =GAE!E$2 -> 3562766.6 | F4: =GAE!F$2 -> 3649251.9 | G4: =GAE!G$2 -> 3667632.4 | H4: =GAE!H$2 -> 3654689.4 | I4: =GAE!I$2 -> 3680644.1 | J4: =GAE!J$2 -> 3638457.5 | ... Z4: =GAE!Z$2 -> 2532690.8
A5: International maritime bunkers | B5: =HYPERLINK("#"&CELL("address",INTMARB!$Z$2),"INTMARB") -> INTMARB | C5: =INTMARB!C$2 -> 129755.56 | D5: =INTMARB!D$2 -> 133806.23 | E5: =INTMARB!E$2 -> 137724.48 | F5: =INTMARB!F$2 -> 141828.47 | G5: =INTMARB!G$2 -> 149118.53 | H5: =INTMARB!H$2 -> 152050.66 | I5: =INTMARB!I$2 -> 162126.1 | J5: =INTMARB!J$2 -> 169125.02 | ... Z5: =INTMARB!Z$2 -> 124591.13
A6: International Intra-EEA maritime bunkers | B6: =HYPERLINK("#"&CELL("address",index!$Z$2),"index") -> index | C6: =index!C$2 -> 0 | D6: =index!D$2 -> 0 | E6: =index!E$2 -> 0 | F6: =index!F$2 -> 0 | G6: =index!G$2 -> 0 | H6: =index!H$2 -> 0 | I6: =index!I$2 -> 0 | J6: =index!J$2 -> 0 | ... Z6: =index!Z$2 -> 0
A7: International Extra-EEA maritime bunkers | B7: =HYPERLINK("#"&CELL("address",INTMARB_EX!$Z$2),"INTMARB_EX") -> INTMARB_EX | C7: =INTMARB_EX!C$2 -> 83174.473 | D7: =INTMARB_EX!D$2 -> 87375.792 | E7: =INTMARB_EX!E$2 -> 91266.991 | F7: =INTMARB_EX!F$2 -> 93612.98 | G7: =INTMARB_EX!G$2 -> 99787.809 | H7: =INTMARB_EX!H$2 -> 104345.29 | I7: =INTMARB_EX!I$2 -> 113164.79 | J7: =INTMARB_EX!J$2 -> 119087.51 | ... Z7: =INTMARB_EX!Z$2 -> 80296.513
A8: Gross inland consumption | B8: =HYPERLINK("#"&CELL("address",GIC!$Z$2),"GIC") -> GIC | C8: =GIC!C$2 -> 3368486.9 | D8: =GIC!D$2 -> 3422886.4 | E8: =GIC!E$2 -> 3425042.1 | F8: =GIC!F$2 -> 3507423.5 | G8: =GIC!G$2 -> 3518513.9 | H8: =GIC!H$2 -> 3502638.7 | I8: =GIC!I$2 -> 3518518 | J8: =GIC!J$2 -> 3469332.5 | ... Z8: =GIC!Z$2 -> 2408099.7
A9: International aviation | B9: =HYPERLINK("#"&CELL("address",INTAVI!$Z$2),"INTAVI") -> INTAVI | C9: =INTAVI!C$2 -> 86018.368 | D9: =INTAVI!D$2 -> 84030.351 | E9: =INTAVI!E$2 -> 82576.137 | F9: =INTAVI!F$2 -> 84156.863 | G9: =INTAVI!G$2 -> 90121.752 | H9: =INTAVI!H$2 -> 93765.213 | I9: =INTAVI!I$2 -> 98548.682 | J9: =INTAVI!J$2 -> 102820.45 | ... Z9: =INTAVI!Z$2 -> 115178.69
A10: International Intra-EEAwUK passenger aviation | B10: =HYPERLINK("#"&CELL("address",INTAVI_PA_IN!$Z$2),"INTAVI_PA_IN") -> INTAVI_PA_IN | C10: =INTAVI_PA_IN!C$2 -> 34769.311 | D10: =INTAVI_PA_IN!D$2 -> 34754.964 | E10: =INTAVI_PA_IN!E$2 -> 32737.549 | F10: =INTAVI_PA_IN!F$2 -> 34971.181 | G10: =INTAVI_PA_IN!G$2 -> 36326.911 | H10: =INTAVI_PA_IN!H$2 -> 37762.713 | I10: =INTAVI_PA_IN!I$2 -> 40221.77 | J10: =INTAVI_PA_IN!J$2 -> 42692.7 | ... Z10: =INTAVI_PA_IN!Z$2 -> 50836.243
A11: International Extra-EEAwUK passenger aviation | B11: =HYPERLINK("#"&CELL("address",INTAVI_PA_EX!$Z$2),"INTAVI_PA_EX") -> INTAVI_PA_EX | C11: =INTAVI_PA_EX!C$2 -> 43454.575 | D11: =INTAVI_PA_EX!D$2 -> 42095.647 | E11: =INTAVI_PA_EX!E$2 -> 42067.591 | F11: =INTAVI_PA_EX!F$2 -> 40849.288 | G11: =INTAVI_PA_EX!G$2 -> 44793.917 | H11: =INTAVI_PA_EX!H$2 -> 46174.39 | I11: =INTAVI_PA_EX!I$2 -> 47473.989 | J11: =INTAVI_PA_EX!J$2 -> 48787.344 | ... Z11: =INTAVI_PA_EX!Z$2 -> 51821.241
A12: International Intra-EEAwUK freight aviation | B12: =HYPERLINK("#"&CELL("address",INTAVI_FR_IN!$Z$2),"INTAVI_FR_IN") -> INTAVI_FR_IN | C12: =INTAVI_FR_IN!C$2 -> 885.03687 | D12: =INTAVI_FR_IN!D$2 -> 795.87915 | E12: =INTAVI_FR_IN!E$2 -> 844.33354 | F12: =INTAVI_FR_IN!F$2 -> 838.10987 | G12: =INTAVI_FR_IN!G$2 -> 929.59018 | H12: =INTAVI_FR_IN!H$2 -> 995.73104 | I12: =INTAVI_FR_IN!I$2 -> 1257.4879 | J12: =INTAVI_FR_IN!J$2 -> 1346.9569 | ... Z12: =INTAVI_FR_IN!Z$2 -> 1465.7926
A13: International Extra-EEAwUK freight aviation | B13: =HYPERLINK("#"&CELL("address",INTAVI_FR_EX!$Z$2),"INTAVI_FR_EX") -> INTAVI_FR_EX | C13: =INTAVI_FR_EX!C$2 -> 6909.4444 | D13: =INTAVI_FR_EX!D$2 -> 6383.861 | E13: =INTAVI_FR_EX!E$2 -> 6926.6635 | F13: =INTAVI_FR_EX!F$2 -> 7498.2841 | G13: =INTAVI_FR_EX!G$2 -> 8071.3341 | H13: =INTAVI_FR_EX!H$2 -> 8832.3792 | I13: =INTAVI_FR_EX!I$2 -> 9595.4351 | J13: =INTAVI_FR_EX!J$2 -> 9993.4475 | ... Z13: =INTAVI_FR_EX!Z$2 -> 11055.409
A14: Total energy supply | B14: =HYPERLINK("#"&CELL("address",NRGSUP!$Z$2),"NRGSUP") -> NRGSUP | C14: =NRGSUP!C$2 -> 3282468.5 | D14: =NRGSUP!D$2 -> 3338856.1 | E14: =NRGSUP!E$2 -> 3342465.9 | F14: =NRGSUP!F$2 -> 3423266.6 | G14: =NRGSUP!G$2 -> 3428392.1 | H14: =NRGSUP!H$2 -> 3408873.5 | I14: =NRGSUP!I$2 -> 3419969.3 | J14: =NRGSUP!J$2 -> 3366512 | ... Z14: =NRGSUP!Z$2 -> 2292921
A15: Electricity & heat generation | B15: =HYPERLINK("#"&CELL("address",TI_EHG_E!$Z$2),"TI_EHG_E") -> TI_EHG_E | C15: =TI_EHG_E!C$2 -> 1238715.6 | D15: =TI_EHG_E!D$2 -> 1262140 | E15: =TI_EHG_E!E$2 -> 1287832.2 | F15: =TI_EHG_E!F$2 -> 1332859.7 | G15: =TI_EHG_E!G$2 -> 1333122.7 | H15: =TI_EHG_E!H$2 -> 1322101.5 | I15: =TI_EHG_E!I$2 -> 1340447 | J15: =TI_EHG_E!J$2 -> 1354675.5 | ... Z15: =TI_EHG_E!Z$2 -> 658426.23
A16: Electricity only | B16: =HYPERLINK("#"&CELL("address",TI_EHG_E_E!$Z$2),"TI_EHG_E_E") -> TI_EHG_E_E | C16: =TI_EHG_E_E!C$2 -> 770427.39 | D16: =TI_EHG_E_E!D$2 -> 782995.1 | E16: =TI_EHG_E_E!E$2 -> 805203.23 | F16: =TI_EHG_E_E!F$2 -> 788512.33 | G16: =TI_EHG_E_E!G$2 -> 804279.61 | H16: =TI_EHG_E_E!H$2 -> 797138.6 | I16: =TI_EHG_E_E!I$2 -> 800530.69 | J16: =TI_EHG_E_E!J$2 -> 826673.03 | ... Z16: =TI_EHG_E_E!Z$2 -> 334100.78
A17: CHP | B17: =HYPERLINK("#"&CELL("address",TI_EHG_CHP_E!$Z$2),"TI_EHG_CHP_E") -> TI_EHG_CHP_E | C17: =TI_EHG_CHP_E!C$2 -> 416123.38 | D17: =TI_EHG_CHP_E!D$2 -> 425399.05 | E17: =TI_EHG_CHP_E!E$2 -> 430780.08 | F17: =TI_EHG_CHP_E!F$2 -> 489498.25 | G17: =TI_EHG_CHP_E!G$2 -> 480187.79 | H17: =TI_EHG_CHP_E!H$2 -> 480938.91 | I17: =TI_EHG_CHP_E!I$2 -> 498830.09 | J17: =TI_EHG_CHP_E!J$2 -> 486767.58 | ... Z17: =TI_EHG_CHP_E!Z$2 -> 294648.19
A18: Heat only | B18: =HYPERLINK("#"&CELL("address",TI_EHG_H_E!$Z$2),"TI_EHG_H_E") -> TI_EHG_H_E | C18: =TI_EHG_H_E!C$2 -> 52164.782 | D18: =TI_EHG_H_E!D$2 -> 53745.866 | E18: =TI_EHG_H_E!E$2 -> 51848.919 | F18: =TI_EHG_H_E!F$2 -> 54849.082 | G18: =TI_EHG_H_E!G$2 -> 48655.303 | H18: =TI_EHG_H_E!H$2 -> 44023.998 | I18: =TI_EHG_H_E!I$2 -> 41086.253 | J18: =TI_EHG_H_E!J$2 -> 41234.881 | ... Z18: =TI_EHG_H_E!Z$2 -> 29677.262
A19: Energy sector | B19: =HYPERLINK("#"&CELL("address",NRG_E!$Z$2),"NRG_E") -> NRG_E | C19: =NRG_E!C$2 -> 154789.43 | D19: =NRG_E!D$2 -> 150763.54 | E19: =NRG_E!E$2 -> 151719.48 | F19: =NRG_E!F$2 -> 148186.54 | G19: =NRG_E!G$2 -> 151751.45 | H19: =NRG_E!H$2 -> 151893.39 | I19: =NRG_E!I$2 -> 153129.44 | J19: =NRG_E!J$2 -> 155518.19 | ... Z19: =NRG_E!Z$2 -> 125369.48
A20: Coal mines | B20: =HYPERLINK("#"&CELL("address",NRG_CM_E!$Z$2),"NRG_CM_E") -> NRG_CM_E | C20: =NRG_CM_E!C$2 -> 3859.673 | D20: =NRG_CM_E!D$2 -> 3472.1711 | E20: =NRG_CM_E!E$2 -> 2015.8642 | F20: =NRG_CM_E!F$2 -> 2195.4098 | G20: =NRG_CM_E!G$2 -> 2014.3829 | H20: =NRG_CM_E!H$2 -> 1284.3301 | I20: =NRG_CM_E!I$2 -> 1284.9316 | J20: =NRG_CM_E!J$2 -> 2034.5231 | ... Z20: =NRG_CM_E!Z$2 -> 790.37496
A21: Oil & natural gas extraction plants | B21: =HYPERLINK("#"&CELL("address",NRG_OIL_NG_E!$Z$2),"NRG_OIL_NG_E") -> NRG_OIL_NG_E | C21: =NRG_OIL_NG_E!C$2 -> 9499.8683 | D21: =NRG_OIL_NG_E!D$2 -> 8794.0383 | E21: =NRG_OIL_NG_E!E$2 -> 8872.7942 | F21: =NRG_OIL_NG_E!F$2 -> 7739.6032 | G21: =NRG_OIL_NG_E!G$2 -> 8443.8365 | H21: =NRG_OIL_NG_E!H$2 -> 8561.242 | I21: =NRG_OIL_NG_E!I$2 -> 7132.846 | J21: =NRG_OIL_NG_E!J$2 -> 6075.9852 | ... Z21: =NRG_OIL_NG_E!Z$2 -> 4619.7078
A22: Patent fuel plants | B22: =HYPERLINK("#"&CELL("address",NRG_PF_E!$Z$2),"NRG_PF_E") -> NRG_PF_E | C22: =NRG_PF_E!C$2 -> 0 | D22: =NRG_PF_E!D$2 -> 0 | E22: =NRG_PF_E!E$2 -> 3.9929366 | F22: =NRG_PF_E!F$2 -> 0 | G22: =NRG_PF_E!G$2 -> 0 | H22: =NRG_PF_E!H$2 -> 0 | I22: =NRG_PF_E!I$2 -> 0 | J22: =NRG_PF_E!J$2 -> 0 | ... Z22: =NRG_PF_E!Z$2 -> 0
A23: Coke ovens | B23: =HYPERLINK("#"&CELL("address",NRG_CO_E!$Z$2),"NRG_CO_E") -> NRG_CO_E | C23: =NRG_CO_E!C$2 -> 19867.369 | D23: =NRG_CO_E!D$2 -> 18756.735 | E23: =NRG_CO_E!E$2 -> 19405.777 | F23: =NRG_CO_E!F$2 -> 17422.607 | G23: =NRG_CO_E!G$2 -> 17828.242 | H23: =NRG_CO_E!H$2 -> 18623.603 | I23: =NRG_CO_E!I$2 -> 17718.409 | J23: =NRG_CO_E!J$2 -> 18019.722 | ... Z23: =NRG_CO_E!Z$2 -> 13155.299
A24: BKB & PB plants | B24: =HYPERLINK("#"&CELL("address",NRG_BKBPB_E!$Z$2),"NRG_BKBPB_E") -> NRG_BKBPB_E | C24: =NRG_BKBPB_E!C$2 -> 847.45643 | D24: =NRG_BKBPB_E!D$2 -> 859.47534 | E24: =NRG_BKBPB_E!E$2 -> 1157.632 | F24: =NRG_BKBPB_E!F$2 -> 1302.6426 | G24: =NRG_BKBPB_E!G$2 -> 1352.7665 | H24: =NRG_BKBPB_E!H$2 -> 1180.9797 | I24: =NRG_BKBPB_E!I$2 -> 1224.874 | J24: =NRG_BKBPB_E!J$2 -> 1341.8623 | ... Z24: =NRG_BKBPB_E!Z$2 -> 612.96595
A25: Gas works | B25: =HYPERLINK("#"&CELL("address",NRG_GW_E!$Z$2),"NRG_GW_E") -> NRG_GW_E | C25: =NRG_GW_E!C$2 -> 12.29742 | D25: =NRG_GW_E!D$2 -> 8.84277 | E25: =NRG_GW_E!E$2 -> 33.860871 | F25: =NRG_GW_E!F$2 -> 38.216977 | G25: =NRG_GW_E!G$2 -> 42.254691 | H25: =NRG_GW_E!H$2 -> 34.294007 | I25: =NRG_GW_E!I$2 -> 33.919862 | J25: =NRG_GW_E!J$2 -> 12.473719 | ... Z25: =NRG_GW_E!Z$2 -> 0.06383196
A26: Blast furnaces | B26: =HYPERLINK("#"&CELL("address",NRG_BF_E!$Z$2),"NRG_BF_E") -> NRG_BF_E | C26: =NRG_BF_E!C$2 -> 18270.401 | D26: =NRG_BF_E!D$2 -> 16769.596 | E26: =NRG_BF_E!E$2 -> 18465.343 | F26: =NRG_BF_E!F$2 -> 20731.811 | G26: =NRG_BF_E!G$2 -> 20848.666 | H26: =NRG_BF_E!H$2 -> 20320.228 | I26: =NRG_BF_E!I$2 -> 20242.53 | J26: =NRG_BF_E!J$2 -> 20198.626 | ... Z26: =NRG_BF_E!Z$2 -> 20621.096
A27: Petroleum refineries (oil refineries) | B27: =HYPERLINK("#"&CELL("address",NRG_PR_E!$Z$2),"NRG_PR_E") -> NRG_PR_E | C27: =NRG_PR_E!C$2 -> 102432.36 | D27: =NRG_PR_E!D$2 -> 102102.68 | E27: =NRG_PR_E!E$2 -> 101764.22 | F27: =NRG_PR_E!F$2 -> 98756.248 | G27: =NRG_PR_E!G$2 -> 101192.65 | H27: =NRG_PR_E!H$2 -> 101824.86 | I27: =NRG_PR_E!I$2 -> 105408.1 | J27: =NRG_PR_E!J$2 -> 107655.15 | ... Z27: =NRG_PR_E!Z$2 -> 84867.958
A28: Nuclear industry | B28: =HYPERLINK("#"&CELL("address",NRG_NI_E!$Z$2),"NRG_NI_E") -> NRG_NI_E | C28: =NRG_NI_E!C$2 -> 0 | D28: =NRG_NI_E!D$2 -> 0 | E28: =NRG_NI_E!E$2 -> 0 | F28: =NRG_NI_E!F$2 -> 0 | G28: =NRG_NI_E!G$2 -> 0 | H28: =NRG_NI_E!H$2 -> 0 | I28: =NRG_NI_E!I$2 -> 0 | J28: =NRG_NI_E!J$2 -> 0 | ... Z28: =NRG_NI_E!Z$2 -> 0
A29: Coal liquefaction plants | B29: =HYPERLINK("#"&CELL("address",NRG_CL_E!$Z$2),"NRG_CL_E") -> NRG_CL_E | C29: =NRG_CL_E!C$2 -> 0 | D29: =NRG_CL_E!D$2 -> 0 | E29: =NRG_CL_E!E$2 -> 0 | F29: =NRG_CL_E!F$2 -> 0 | G29: =NRG_CL_E!G$2 -> 0 | H29: =NRG_CL_E!H$2 -> 0 | I29: =NRG_CL_E!I$2 -> 0 | J29: =NRG_CL_E!J$2 -> 0 | ... Z29: =NRG_CL_E!Z$2 -> 0
A30: Liquefaction & regasification plants (LNG) | B30: =HYPERLINK("#"&CELL("address",NRG_LNG_E!$Z$2),"NRG_LNG_E") -> NRG_LNG_E | C30: =NRG_LNG_E!C$2 -> 0 | D30: =NRG_LNG_E!D$2 -> 0 | E30: =NRG_LNG_E!E$2 -> 0 | F30: =NRG_LNG_E!F$2 -> 0 | G30: =NRG_LNG_E!G$2 -> 28.647218 | H30: =NRG_LNG_E!H$2 -> 32.406098 | I30: =NRG_LNG_E!I$2 -> 42.360504 | J30: =NRG_LNG_E!J$2 -> 142.10188 | ... Z30: =NRG_LNG_E!Z$2 -> 702.01579
A31: Gasification plants for biogas | B31: =HYPERLINK("#"&CELL("address",NRG_BIOG_E!$Z$2),"NRG_BIOG_E") -> NRG_BIOG_E | C31: =NRG_BIOG_E!C$2 -> 0 | D31: =NRG_BIOG_E!D$2 -> 0 | E31: =NRG_BIOG_E!E$2 -> 0 | F31: =NRG_BIOG_E!F$2 -> 0 | G31: =NRG_BIOG_E!G$2 -> 0 | H31: =NRG_BIOG_E!H$2 -> 0 | I31: =NRG_BIOG_E!I$2 -> 0 | J31: =NRG_BIOG_E!J$2 -> 0 | ... Z31: =NRG_BIOG_E!Z$2 -> 0
A32: Gas-to-liquids (GTL) plants | B32: =HYPERLINK("#"&CELL("address",NRG_GTL_E!$Z$2),"NRG_GTL_E") -> NRG_GTL_E | C32: =NRG_GTL_E!C$2 -> 0 | D32: =NRG_GTL_E!D$2 -> 0 | E32: =NRG_GTL_E!E$2 -> 0 | F32: =NRG_GTL_E!F$2 -> 0 | G32: =NRG_GTL_E!G$2 -> 0 | H32: =NRG_GTL_E!H$2 -> 0 | I32: =NRG_GTL_E!I$2 -> 0 | J32: =NRG_GTL_E!J$2 -> 0 | ... Z32: =NRG_GTL_E!Z$2 -> 0
A33: Charcoal production plants | B33: =HYPERLINK("#"&CELL("address",NRG_CPP_E!$Z$2),"NRG_CPP_E") -> NRG_CPP_E | C33: =NRG_CPP_E!C$2 -> 0 | D33: =NRG_CPP_E!D$2 -> 0 | E33: =NRG_CPP_E!E$2 -> 0 | F33: =NRG_CPP_E!F$2 -> 0 | G33: =NRG_CPP_E!G$2 -> 0 | H33: =NRG_CPP_E!H$2 -> 0 | I33: =NRG_CPP_E!I$2 -> 0 | J33: =NRG_CPP_E!J$2 -> 0 | ... Z33: =NRG_CPP_E!Z$2 -> 0
A34: Not elsewhere specified (energy) | B34: =HYPERLINK("#"&CELL("address",NRG_NSP_E!$Z$2),"NRG_NSP_E") -> NRG_NSP_E | C34: =NRG_NSP_E!C$2 -> 0 | D34: =NRG_NSP_E!D$2 -> 0 | E34: =NRG_NSP_E!E$2 -> 0 | F34: =NRG_NSP_E!F$2 -> 0 | G34: =NRG_NSP_E!G$2 -> 0 | H34: =NRG_NSP_E!H$2 -> 31.446267 | I34: =NRG_NSP_E!I$2 -> 41.472548 | J34: =NRG_NSP_E!J$2 -> 37.743791 | ... Z34: =NRG_NSP_E!Z$2 -> 0
A35: Final energy consumption | B35: =HYPERLINK("#"&CELL("address",FC_E!$Z$2),"FC_E") -> FC_E | C35: =FC_E!C$2 -> 1888963.6 | D35: =FC_E!D$2 -> 1925952.5 | E35: =FC_E!E$2 -> 1902914.2 | F35: =FC_E!F$2 -> 1942220.4 | G35: =FC_E!G$2 -> 1943518 | H35: =FC_E!H$2 -> 1934878.6 | I35: =FC_E!I$2 -> 1926392.8 | J35: =FC_E!J$2 -> 1856318.3 | ... Z35: =FC_E!Z$2 -> 1509125.3
A36: Industry sector | B36: =HYPERLINK("#"&CELL("address",FC_IND_E!$Z$2),"FC_IND_E") -> FC_IND_E | C36: =FC_IND_E!C$2 -> 501771.2 | D36: =FC_IND_E!D$2 -> 489860.34 | E36: =FC_IND_E!E$2 -> 482917.85 | F36: =FC_IND_E!F$2 -> 491010.1 | G36: =FC_IND_E!G$2 -> 475003.57 | H36: =FC_IND_E!H$2 -> 468505.53 | I36: =FC_IND_E!I$2 -> 453207.15 | J36: =FC_IND_E!J$2 -> 454615.84 | ... Z36: =FC_IND_E!Z$2 -> 322489.45
A37: Iron & steel | B37: =HYPERLINK("#"&CELL("address",FC_IND_IS_E!$Z$2),"FC_IND_IS_E") -> FC_IND_IS_E | C37: =FC_IND_IS_E!C$2 -> 107772.55 | D37: =FC_IND_IS_E!D$2 -> 99393.101 | E37: =FC_IND_IS_E!E$2 -> 98407.599 | F37: =FC_IND_IS_E!F$2 -> 102545.45 | G37: =FC_IND_IS_E!G$2 -> 101963.63 | H37: =FC_IND_IS_E!H$2 -> 96204.301 | I37: =FC_IND_IS_E!I$2 -> 98279.624 | J37: =FC_IND_IS_E!J$2 -> 92023.387 | ... Z37: =FC_IND_IS_E!Z$2 -> 54422.883
A38: Iron & steel - Integrated steelworks | B38: =HYPERLINK("#"&CELL("address",FC_IND_IS_BF_E!$Z$2),"FC_IND_IS_BF_E") -> FC_IND_IS_BF_E | C38: =FC_IND_IS_BF_E!C$2 -> 95379.415 | D38: =FC_IND_IS_BF_E!D$2 -> 87330.501 | E38: =FC_IND_IS_BF_E!E$2 -> 86909.623 | F38: =FC_IND_IS_BF_E!F$2 -> 90745.279 | G38: =FC_IND_IS_BF_E!G$2 -> 89907.845 | H38: =FC_IND_IS_BF_E!H$2 -> 84763.705 | I38: =FC_IND_IS_BF_E!I$2 -> 86146.679 | J38: =FC_IND_IS_BF_E!J$2 -> 80356.587 | ... Z38: =FC_IND_IS_BF_E!Z$2 -> 46887.164
A39: Iron & steel - Electric arc | B39: =HYPERLINK("#"&CELL("address",FC_IND_IS_EA_E!$Z$2),"FC_IND_IS_EA_E") -> FC_IND_IS_EA_E | C39: =FC_IND_IS_EA_E!C$2 -> 12393.14 | D39: =FC_IND_IS_EA_E!D$2 -> 12062.6 | E39: =FC_IND_IS_EA_E!E$2 -> 11497.975 | F39: =FC_IND_IS_EA_E!F$2 -> 11800.173 | G39: =FC_IND_IS_EA_E!G$2 -> 12055.783 | H39: =FC_IND_IS_EA_E!H$2 -> 11440.596 | I39: =FC_IND_IS_EA_E!I$2 -> 12132.945 | J39: =FC_IND_IS_EA_E!J$2 -> 11666.8 | ... Z39: =FC_IND_IS_EA_E!Z$2 -> 7535.7188
A40: Non-ferrous metals | B40: =HYPERLINK("#"&CELL("address",FC_IND_NFM_E!$Z$2),"FC_IND_NFM_E") -> FC_IND_NFM_E | C40: =FC_IND_NFM_E!C$2 -> 13911.801 | D40: =FC_IND_NFM_E!D$2 -> 13273.95 | E40: =FC_IND_NFM_E!E$2 -> 13638.814 | F40: =FC_IND_NFM_E!F$2 -> 12964.912 | G40: =FC_IND_NFM_E!G$2 -> 13039.901 | H40: =FC_IND_NFM_E!H$2 -> 12645.534 | I40: =FC_IND_NFM_E!I$2 -> 12134.689 | J40: =FC_IND_NFM_E!J$2 -> 11706.033 | ... Z40: =FC_IND_NFM_E!Z$2 -> 8445.8535
...

Sheet ef
A1: CO2 emission factors (t CO2 / toe) | B1: ef | C1: 2000 | D1: 2001 | E1: 2002 | F1: 2003 | G1: 2004 | H1: 2005 | I1: 2006 | J1: 2007 | K1: 2008 | L1: 2009 | M1: 2010 | N1: 2011 | O1: 2012 | P1: 2013 | Q1: 2014 | R1: 2015 | S1: 2016 | T1: 2017 | U1: 2018 | V1: 2019 | W1: 2020 | X1: 2021 | Y1: 2022 | Z1: 2023
A2: Total | B2: TOTAL
A3: Solid fossil fuels | B3: C0000X0350-0370
A4: Hard coal | B4: C0100
A5: Anthracite | B5: C0110 | C5: 4.1227813 | D5: 4.1148197 | E5: 4.1136434 | F5: 3.991908 | G5: 4.1069596 | H5: 4.1106688 | I5: 4.1188254 | J5: 4.0986137 | K5: 4.1542439 | L5: 4.1219116 | M5: 4.1241861 | N5: 4.104472 | O5: 4.0766349 | P5: 4.0841122 | Q5: 4.0911505 | R5: 4.0878834 | S5: 4.1065321 | T5: 4.1208936 | U5: 4.11445 | V5: 4.1532709 | W5: 4.1622583 | X5: 4.1402545 | Y5: 4.1247806 | Z5: 4.1332556
A6: Coking coal | B6: C0121 | C6: 3.994418 | D6: 3.966068 | E6: 3.9910516 | F6: 3.9738991 | G6: 4.0082218 | H6: 4.0026016 | I6: 4.0106429 | J6: 4.0108228 | K6: 4.0375818 | L6: 4.0205713 | M6: 4.0474047 | N6: 4.0465334 | O6: 4.0277796 | P6: 4.0595863 | Q6: 4.0475587 | R6: 4.0228831 | S6: 4.0550939 | T6: 4.0757462 | U6: 4.0671462 | V6: 3.9553368 | W6: 3.9557516 | X6: 3.9554612 | Y6: 4.077315 | Z6: 4.1118253
A7: Other bituminous coal | B7: C0129 | C7: 3.9778491 | D7: 3.9741633 | E7: 3.9806025 | F7: 3.9747291 | G7: 3.9828575 | H7: 3.9825206 | I7: 3.9783462 | J7: 3.9801483 | K7: 3.9800028 | L7: 3.9757761 | M7: 3.9788903 | N7: 3.9828206 | O7: 3.9772055 | P7: 3.9880559 | Q7: 3.9883969 | R7: 3.9917511 | S7: 3.9863309 | T7: 3.9803701 | U7: 3.9942492 | V7: 4.0096235 | W7: 4.0010576 | X7: 3.9863169 | Y7: 3.997876 | Z7: 3.9923853
A8: Brown coal | B8: C0200
A9: Sub-bituminous coal | B9: C0210 | C9: 4.0811556 | D9: 4.0711834 | E9: 4.0815353 | F9: 4.0893121 | G9: 4.0477967 | H9: 4.0439127 | I9: 4.0506737 | J9: 3.9907685 | K9: 3.9615805 | L9: 4.0079387 | M9: 3.9907092 | N9: 4.0098143 | O9: 4.0287212 | P9: 4.0418804 | Q9: 4.0258705 | R9: 3.9960759 | S9: 3.9261654 | T9: 3.9808014 | U9: 3.9730199 | V9: 4.0068483 | W9: 3.9930383 | X9: 3.9550053 | Y9: 3.9396168 | Z9: 3.9589557
A10: Lignite | B10: C0220 | C10: 4.5095154 | D10: 4.5145639 | E10: 4.5226417 | F10: 4.5093144 | G10: 4.5184629 | H10: 4.5210061 | I10: 4.5095894 | J10: 4.530142 | K10: 4.5219559 | L10: 4.5224107 | M10: 4.5184206 | N10: 4.5154136 | O10: 4.5486173 | P10: 4.5354845 | Q10: 4.5520551 | R10: 4.534616 | S10: 4.5307269 | T10: 4.5326321 | U10: 4.5107725 | V10: 4.4912861 | W10: 4.4948129 | X10: 4.4913463 | Y10: 4.4916135 | Z10: 4.461148
A11: Coal products | B11: C0300
A12: Patent fuel | B12: C0320 | C12: 4.2975558 | D12: 4.296055 | E12: 4.28885 | F12: 4.2714741 | G12: 4.2969541 | H12: 4.3306899 | I12: 4.3347739 | J12: 4.3310834 | K12: 4.3253149 | L12: 4.2998201 | M12: 4.1803846 | N12: 4.1535154 | O12: 4.2374149 | P12: 4.1938385 | Q12: 4.1798355 | R12: 4.1702534 | S12: 4.1758359 | T12: 4.1768161 | U12: 4.0998335 | V12: 4.1428601 | W12: 4.1522742 | X12: 4.1721061 | Y12: 4.1207842 | Z12: 4.1497228
A13: Coke oven coke | B13: C0311 | C13: 4.4798451 | D13: 4.4863089 | E13: 4.4830964 | F13: 4.473412 | G13: 4.4716026 | H13: 4.5153958 | I13: 4.5126799 | J13: 4.5259727 | K13: 4.4941313 | L13: 4.5283534 | M13: 4.5243747 | N13: 4.4790854 | O13: 4.5010794 | P13: 4.4465419 | Q13: 4.4993934 | R13: 4.5009504 | S13: 4.4868588 | T13: 4.4535701 | U13: 4.4532636 | V13: 4.4446134 | W13: 4.4393147 | X13: 4.4001815 | Y13: 4.4007001 | Z13: 4.4529361
A14: Gas coke | B14: C0312 | C14: 0 | D14: 0 | E14: 0 | F14: 0 | G14: 0 | H14: 0 | I14: 0 | J14: 0 | K14: 0 | L14: 0 | M14: 0 | N14: 0 | O14: 0 | P14: 0 | Q14: 0 | R14: 0 | S14: 0 | T14: 0 | U14: 0 | V14: 0 | W14: 0 | X14: 0 | Y14: 0 | Z14: 0
A15: Coal tar | B15: C0340 | C15: 3.3787476 | D15: 3.3592367 | E15: 3.3703841 | F15: 3.3769721 | G15: 3.3689863 | H15: 3.364134 | I15: 3.3708517 | J15: 3.3611187 | K15: 3.3571358 | L15: 3.3674 | M15: 3.3527017 | N15: 3.3537357 | O15: 3.3517412 | P15: 3.3467454 | Q15: 3.3470486 | R15: 3.3773246 | S15: 3.3766164 | T15: 3.3763589 | U15: 3.3767533 | V15: 3.371789 | W15: 3.3619051 | X15: 3.3746849 | Y15: 3.37428 | Z15: 3.3621981
A16: Brown coal briquettes | B16: C0330 | C16: 4.0843771 | D16: 4.0829358 | E16: 4.0964983 | F16: 4.0828653 | G16: 4.0654543 | H16: 4.0909389 | I16: 4.1008206 | J16: 4.1283876 | K16: 4.1441861 | L16: 4.1288903 | M16: 4.1000498 | N16: 4.1154941 | O16: 4.1287343 | P16: 4.1196029 | Q16: 4.1339332 | R16: 4.1236582 | S16: 4.1268055 | T16: 4.1237635 | U16: 4.1162886 | V16: 4.1181687 | W16: 4.1242218 | X16: 4.1203018 | Y16: 4.0873375 | Z16: 4.1192306
A17: Manufactured gases | B17: C0350-0370
A18: Gas works gas | B18: C0360 | C18: 1.8589392 | D18: 1.8589392 | E18: 1.8589392 | F18: 1.8589392 | G18: 1.8589392 | H18: 1.8589392 | I18: 1.8589392 | J18: 1.8589392 | K18: 1.8589392 | L18: 1.8589392 | M18: 1.8589392 | N18: 1.8589392 | O18: 1.8589392 | P18: 1.8589392 | Q18: 1.8589392 | R18: 1.8589392 | S18: 1.8589392 | T18: 1.8589392 | U18: 1.8589392 | V18: 1.8589392 | W18: 1.8589392 | X18: 1.8589392 | Y18: 1.8589392 | Z18: 1.8589392
A19: Coke oven gas | B19: C0350 | C19: 1.8589392 | D19: 1.8589392 | E19: 1.8589392 | F19: 1.8589392 | G19: 1.8589392 | H19: 1.8589392 | I19: 1.8589392 | J19: 1.8589392 | K19: 1.8589392 | L19: 1.8589392 | M19: 1.8589392 | N19: 1.8589392 | O19: 1.8589392 | P19: 1.8589392 | Q19: 1.8589392 | R19: 1.8589392 | S19: 1.8589392 | T19: 1.8589392 | U19: 1.8589392 | V19: 1.8589392 | W19: 1.8589392 | X19: 1.8589392 | Y19: 1.8589392 | Z19: 1.8589392
A20: Blast furnace gas | B20: C0371 | C20: 10.88568 | D20: 10.88568 | E20: 10.88568 | F20: 10.88568 | G20: 10.88568 | H20: 10.88568 | I20: 10.88568 | J20: 10.88568 | K20: 10.88568 | L20: 10.88568 | M20: 10.88568 | N20: 10.88568 | O20: 10.88568 | P20: 10.88568 | Q20: 10.88568 | R20: 10.88568 | S20: 10.88568 | T20: 10.88568 | U20: 10.88568 | V20: 10.88568 | W20: 10.88568 | X20: 10.88568 | Y20: 10.88568 | Z20: 10.88568
A21: Other recovered gases | B21: C0379 | C21: 7.619976 | D21: 7.619976 | E21: 7.619976 | F21: 7.619976 | G21: 7.619976 | H21: 7.619976 | I21: 7.619976 | J21: 7.619976 | K21: 7.619976 | L21: 7.619976 | M21: 7.619976 | N21: 7.619976 | O21: 7.619976 | P21: 7.619976 | Q21: 7.619976 | R21: 7.619976 | S21: 7.619976 | T21: 7.619976 | U21: 7.619976 | V21: 7.619976 | W21: 7.619976 | X21: 7.619976 | Y21: 7.619976 | Z21: 7.619976
A22: Peat and peat products | B22: P1000
A23: Peat | B23: P1100 | C23: 4.4138047 | D23: 4.4102396 | E23: 4.4093041 | F23: 4.4081251 | G23: 4.4686388 | H23: 4.478775 | I23: 4.4460466 | J23: 4.4307489 | K23: 4.4689193 | L23: 4.4883962 | M23: 4.4505419 | N23: 4.4881683 | O23: 4.5402339 | P23: 4.5579979 | Q23: 4.5430649 | R23: 4.5186313 | S23: 4.5482661 | T23: 4.5497815 | U23: 4.4827365 | V23: 4.4688184 | W23: 4.4694447 | X23: 4.4605168 | Y23: 4.4734969 | Z23: 4.4549357
A24: Peat products | B24: P1200 | C24: 4.4853698 | D24: 4.4959373 | E24: 4.4959897 | F24: 4.4982031 | G24: 4.8244253 | H24: 4.7178276 | I24: 4.6532445 | J24: 4.6008458 | K24: 4.6480937 | L24: 4.6888968 | M24: 4.6320738 | N24: 4.6107496 | O24: 4.6611372 | P24: 4.7263927 | Q24: 4.7020551 | R24: 4.6504864 | S24: 4.6992324 | T24: 4.696702 | U24: 4.5779354 | V24: 4.5844374 | W24: 4.6401857 | X24: 4.6197903 | Y24: 4.6672363 | Z24: 4.5492024
A25: Oil shale and oil sands | B25: S2000 | C25: 4.2754206 | D25: 4.2754206 | E25: 4.2754206 | F25: 4.2754206 | G25: 4.2471284 | H25: 4.2643029 | I25: 4.2529743 | J25: 4.2298973 | K25: 4.2214619 | L25: 4.226115 | M25: 4.232043 | N25: 4.2301305 | O25: 4.2380708 | P25: 4.2990537 | Q25: 4.4007581 | R25: 4.3408402 | S25: 4.3785295 | T25: 4.3851238 | U25: 4.4536429 | V25: 4.3972273 | W25: 4.2733179 | X25: 4.1860683 | Y25: 4.1355612 | Z25: 3.975295
A26: Oil and petroleum products | B26: O4000XBIO
A27: Crude oil, NGL, refinery feedstocks, additives and oxygenates and other hydrocarbons (excluding biofuel portion) | B27: O4100_TOT_4200-4500XBIO
A28: Crude oil | B28: O4100_TOT | C28: 3.0689244 | D28: 3.0689244 | E28: 3.0689244 | F28: 3.0689244 | G28: 3.0689244 | H28: 3.0689244 | I28: 3.0689244 | J28: 3.0689244 | K28: 3.0689244 | L28: 3.0689244 | M28: 3.0689244 | N28: 3.0689244 | O28: 3.0689244 | P28: 3.0689244 | Q28: 3.0689244 | R28: 3.0689244 | S28: 3.0689244 | T28: 3.0689244 | U28: 3.0689244 | V28: 3.0689244 | W28: 3.0689244 | X28: 3.0689244 | Y28: 3.0689244 | Z28: 3.0689244
A29: Natural gas liquids | B29: O4200 | C29: 2.6879256 | D29: 2.6879256 | E29: 2.6879256 | F29: 2.6879256 | G29: 2.6879256 | H29: 2.6879256 | I29: 2.6879256 | J29: 2.6879256 | K29: 2.6879256 | L29: 2.6879256 | M29: 2.6879256 | N29: 2.6879256 | O29: 2.6879256 | P29: 2.6879256 | Q29: 2.6879256 | R29: 2.6879256 | S29: 2.6879256 | T29: 2.6879256 | U29: 2.6879256 | V29: 2.6879256 | W29: 2.6879256 | X29: 2.6879256 | Y29: 2.6879256 | Z29: 2.6879256
A30: Refinery feedstocks | B30: O4300 | C30: 0 | D30: 0 | E30: 0 | F30: 0 | G30: 0 | H30: 0 | I30: 0 | J30: 0 | K30: 0 | L30: 0 | M30: 0 | N30: 0 | O30: 0 | P30: 0 | Q30: 0 | R30: 0 | S30: 0 | T30: 0 | U30: 0 | V30: 0 | W30: 0 | X30: 0 | Y30: 0 | Z30: 0
A31: Additives and oxygenates (excluding biofuel portion) | B31: O4400X4410 | C31: 0 | D31: 0 | E31: 0 | F31: 0 | G31: 0 | H31: 0 | I31: 0 | J31: 0 | K31: 0 | L31: 0 | M31: 0 | N31: 0 | O31: 0 | P31: 0 | Q31: 0 | R31: 0 | S31: 0 | T31: 0 | U31: 0 | V31: 0 | W31: 0 | X31: 0 | Y31: 0 | Z31: 0
A32: Other hydrocarbons | B32: O4500 | C32: 0 | D32: 0 | E32: 0 | F32: 0 | G32: 0 | H32: 0 | I32: 0 | J32: 0 | K32: 0 | L32: 0 | M32: 0 | N32: 0 | O32: 0 | P32: 0 | Q32: 0 | R32: 0 | S32: 0 | T32: 0 | U32: 0 | V32: 0 | W32: 0 | X32: 0 | Y32: 0 | Z32: 0
A33: Oil products (excluding biofuel portion) | B33: O4600XBIO
A34: Refinery gas | B34: O4610 | C34: 2.4115968 | D34: 2.4115968 | E34: 2.4115968 | F34: 2.4115968 | G34: 2.4115968 | H34: 2.4115968 | I34: 2.4115968 | J34: 2.4115968 | K34: 2.4115968 | L34: 2.4115968 | M34: 2.4115968 | N34: 2.4115968 | O34: 2.4115968 | P34: 2.4115968 | Q34: 2.4115968 | R34: 2.4115968 | S34: 2.4115968 | T34: 2.4115968 | U34: 2.4115968 | V34: 2.4115968 | W34: 2.4115968 | X34: 2.4115968 | Y34: 2.4115968 | Z34: 2.4115968
A35: Ethane | B35: O4620 | C35: 2.5790688 | D35: 2.5790688 | E35: 2.5790688 | F35: 2.5790688 | G35: 2.5790688 | H35: 2.5790688 | I35: 2.5790688 | J35: 2.5790688 | K35: 2.5790688 | L35: 2.5790688 | M35: 2.5790688 | N35: 2.5790688 | O35: 2.5790688 | P35: 2.5790688 | Q35: 2.5790688 | R35: 2.5790688 | S35: 2.5790688 | T35: 2.5790688 | U35: 2.5790688 | V35: 2.5790688 | W35: 2.5790688 | X35: 2.5790688 | Y35: 2.5790688 | Z35: 2.5790688
A36: Liquefied petroleum gases | B36: O4630 | C36: 2.6418708 | D36: 2.6418708 | E36: 2.6418708 | F36: 2.6418708 | G36: 2.6418708 | H36: 2.6418708 | I36: 2.6418708 | J36: 2.6418708 | K36: 2.6418708 | L36: 2.6418708 | M36: 2.6418708 | N36: 2.6418708 | O36: 2.6418708 | P36: 2.6418708 | Q36: 2.6418708 | R36: 2.6418708 | S36: 2.6418708 | T36: 2.6418708 | U36: 2.6418708 | V36: 2.6418708 | W36: 2.6418708 | X36: 2.6418708 | Y36: 2.6418708 | Z36: 2.6418708
A37: Motor gasoline (excluding biofuel portion) | B37: O4652XR5210B | C37: 2.9014524 | D37: 2.9014524 | E37: 2.9014524 | F37: 2.9014524 | G37: 2.9014524 | H37: 2.9014524 | I37: 2.9014524 | J37: 2.9014524 | K37: 2.9014524 | L37: 2.9014524 | M37: 2.9014524 | N37: 2.9014524 | O37: 2.9014524 | P37: 2.9014524 | Q37: 2.9014524 | R37: 2.9014524 | S37: 2.9014524 | T37: 2.9014524 | U37: 2.9014524 | V37: 2.9014524 | W37: 2.9014524 | X37: 2.9014524 | Y37: 2.9014524 | Z37: 2.9014524
A38: Aviation gasoline | B38: O4651 | C38: 2.93076 | D38: 2.93076 | E38: 2.93076 | F38: 2.93076 | G38: 2.93076 | H38: 2.93076 | I38: 2.93076 | J38: 2.93076 | K38: 2.93076 | L38: 2.93076 | M38: 2.93076 | N38: 2.93076 | O38: 2.93076 | P38: 2.93076 | Q38: 2.93076 | R38: 2.93076 | S38: 2.93076 | T38: 2.93076 | U38: 2.93076 | V38: 2.93076 | W38: 2.93076 | X38: 2.93076 | Y38: 2.93076 | Z38: 2.93076
A39: Gasoline-type jet fuel | B39: O4653 | C39: 3.0103092 | D39: 3.0103092 | E39: 3.0103092 | F39: 3.0103092 | G39: 3.0103092 | H39: 3.0103092 | I39: 3.0103092 | J39: 3.0103092 | K39: 3.0103092 | L39: 0 | M39: 0 | N39: 0 | O39: 0 | P39: 0 | Q39: 0 | R39: 0 | S39: 0 | T39: 0 | U39: 0 | V39: 0 | W39: 0 | X39: 0 | Y39: 0 | Z39: 0
A40: Kerosene-type jet fuel (excluding biofuel portion) | B40: O4661XR5230B | C40: 3.0103092 | D40: 3.0103092 | E40: 3.0103092 | F40: 3.0103092 | G40: 3.0103092 | H40: 3.0103092 | I40: 3.0103092 | J40: 3.0103092 | K40: 3.0103092 | L40: 3.0103092 | M40: 3.0103092 | N40: 3.0103092 | O40: 3.0103092 | P40: 3.0103092 | Q40: 3.0103092 | R40: 3.0103092 | S40: 3.0103092 | T40: 3.0103092 | U40: 3.0103092 | V40: 3.0103092 | W40: 3.0103092 | X40: 3.0103092 | Y40: 3.0103092 | Z40: 3.0103092
...

Sheet GAE
A1: Gross available energy | B1: GAE | C1: 2000 | D1: 2001 | E1: 2002 | F1: 2003 | G1: 2004 | H1: 2005 | I1: 2006 | J1: 2007 | K1: 2008 | L1: 2009 | M1: 2010 | N1: 2011 | O1: 2012 | P1: 2013 | Q1: 2014 | R1: 2015 | S1: 2016 | T1: 2017 | U1: 2018 | V1: 2019 | W1: 2020 | X1: 2021 | Y1: 2022 | Z1: 2023
A2: Total | B2: TOTAL | C2: =SUM(C3,C17,C22,C25,C26,C51,C52) -> 3498242.5 | D2: =SUM(D3,D17,D22,D25,D26,D51,D52) -> 3556692.7 | E2: =SUM(E3,E17,E22,E25,E26,E51,E52) -> 3562766.6 | F2: =SUM(F3,F17,F22,F25,F26,F51,F52) -> 3649251.9 | G2: =SUM(G3,G17,G22,G25,G26,G51,G52) -> 3667632.4 | H2: =SUM(H3,H17,H22,H25,H26,H51,H52) -> 3654689.4 | I2: =SUM(I3,I17,I22,I25,I26,I51,I52) -> 3680644.1 | J2: =SUM(J3,J17,J22,J25,J26,J51,J52) -> 3638457.5 | ... Z2: =SUM(Z3,Z17,Z22,Z25,Z26,Z51,Z52) -> 2532690.8
A3: Solid fossil fuels | B3: C0000X0350-0370 | C3: =SUM(C4,C8,C11) -> 964289.03 | D3: =SUM(D4,D8,D11) -> 962445.4 | E3: =SUM(E4,E8,E11) -> 970416.24 | F3: =SUM(F4,F8,F11) -> 1006302.2 | G3: =SUM(G4,G8,G11) -> 991149.19 | H3: =SUM(H4,H8,H11) -> 959765.59 | I3: =SUM(I4,I8,I11) -> 975017.29 | J3: =SUM(J4,J8,J11) -> 982600.21 | ... Z3: =SUM(Z4,Z8,Z11) -> 393682.93
A4: Hard coal | B4: C0100 | C4: =SUM(C5:C7) -> 521809.87 | D4: =SUM(D5:D7) -> 515576.76 | E4: =SUM(E5:E7) -> 524177.3 | F4: =SUM(F5:F7) -> 554548.53 | G4: =SUM(G5:G7) -> 549431.13 | H4: =SUM(H5:H7) -> 527992.06 | I4: =SUM(I5:I7) -> 543349.96 | J4: =SUM(J5:J7) -> 550354.37 | ... Z4: =SUM(Z5:Z7) -> 182273.63
A5: Anthracite | B5: C0110 | C5: =INTMARB!C5+GIC!C5 -> 403.18249 | D5: =INTMARB!D5+GIC!D5 -> 395.51307 | E5: =INTMARB!E5+GIC!E5 -> 1478.7554 | F5: =INTMARB!F5+GIC!F5 -> 10947.103 | G5: =INTMARB!G5+GIC!G5 -> 20522.115 | H5: =INTMARB!H5+GIC!H5 -> 21169.218 | I5: =INTMARB!I5+GIC!I5 -> 19226.707 | J5: =INTMARB!J5+GIC!J5 -> 22286.223 | ... Z5: =INTMARB!Z5+GIC!Z5 -> 2787.544
A6: Coking coal | B6: C0121 | C6: =INTMARB!C6+GIC!C6 -> 36650.466 | D6: =INTMARB!D6+GIC!D6 -> 34124.055 | E6: =INTMARB!E6+GIC!E6 -> 36510.995 | F6: =INTMARB!F6+GIC!F6 -> 38024.306 | G6: =INTMARB!G6+GIC!G6 -> 38824.655 | H6: =INTMARB!H6+GIC!H6 -> 35784.495 | I6: =INTMARB!I6+GIC!I6 -> 32523.689 | J6: =INTMARB!J6+GIC!J6 -> 35888.898 | ... Z6: =INTMARB!Z6+GIC!Z6 -> 4977.1775
A7: Other bituminous coal | B7: C0129 | C7: =INTMARB!C7+GIC!C7 -> 484756.22 | D7: =INTMARB!D7+GIC!D7 -> 481057.2 | E7: =INTMARB!E7+GIC!E7 -> 486187.55 | F7: =INTMARB!F7+GIC!F7 -> 505577.12 | G7: =INTMARB!G7+GIC!G7 -> 490084.36 | H7: =INTMARB!H7+GIC!H7 -> 471038.35 | I7: =INTMARB!I7+GIC!I7 -> 491599.56 | J7: =INTMARB!J7+GIC!J7 -> 492179.25 | ... Z7: =INTMARB!Z7+GIC!Z7 -> 174508.91
A8: Brown coal | B8: C0200 | C8: =SUM(C9:C10) -> 395758.61 | D8: =SUM(D9:D10) -> 404606.12 | E8: =SUM(E9:E10) -> 405092.2 | F8: =SUM(F9:F10) -> 408138.74 | G8: =SUM(G9:G10) -> 405721.84 | H8: =SUM(H9:H10) -> 397190.87 | I8: =SUM(I9:I10) -> 394923.8 | J8: =SUM(J9:J10) -> 397898.65 | ... Z8: =SUM(Z9:Z10) -> 194685.55
A9: Sub-bituminous coal | B9: C0210 | C9: =INTMARB!C9+GIC!C9 -> 8118.1877 | D9: =INTMARB!D9+GIC!D9 -> 6258.0054 | E9: =INTMARB!E9+GIC!E9 -> 7666.3969 | F9: =INTMARB!F9+GIC!F9 -> 6630.9863 | G9: =INTMARB!G9+GIC!G9 -> 7878.6876 | H9: =INTMARB!H9+GIC!H9 -> 8834.7483 | I9: =INTMARB!I9+GIC!I9 -> 9078.5848 | J9: =INTMARB!J9+GIC!J9 -> 9310.5901 | ... Z9: =INTMARB!Z9+GIC!Z9 -> 1280.4012
A10: Lignite | B10: C0220 | C10: =INTMARB!C10+GIC!C10 -> 387640.42 | D10: =INTMARB!D10+GIC!D10 -> 398348.12 | E10: =INTMARB!E10+GIC!E10 -> 397425.8 | F10: =INTMARB!F10+GIC!F10 -> 401507.76 | G10: =INTMARB!G10+GIC!G10 -> 397843.15 | H10: =INTMARB!H10+GIC!H10 -> 388356.12 | I10: =INTMARB!I10+GIC!I10 -> 385845.22 | J10: =INTMARB!J10+GIC!J10 -> 388588.06 | ... Z10: =INTMARB!Z10+GIC!Z10 -> 193405.15
A11: Coal products | B11: C0300 | C11: =SUM(C12:C16) -> 46720.549 | D11: =SUM(D12:D16) -> 42262.512 | E11: =SUM(E12:E16) -> 41146.745 | F11: =SUM(F12:F16) -> 43614.913 | G11: =SUM(G12:G16) -> 35996.218 | H11: =SUM(H12:H16) -> 34582.666 | I11: =SUM(I12:I16) -> 36743.53 | J11: =SUM(J12:J16) -> 34347.188 | ... Z11: =SUM(Z12:Z16) -> 16723.75
A12: Patent fuel | B12: C0320 | C12: =INTMARB!C12+GIC!C12 -> 1204.8369 | D12: =INTMARB!D12+GIC!D12 -> 904.19804 | E12: =INTMARB!E12+GIC!E12 -> 938.3163 | F12: =INTMARB!F12+GIC!F12 -> 791.41489 | G12: =INTMARB!G12+GIC!G12 -> 673.89726 | H12: =INTMARB!H12+GIC!H12 -> 771.89092 | I12: =INTMARB!I12+GIC!I12 -> 747.36199 | J12: =INTMARB!J12+GIC!J12 -> 700.17382 | ... Z12: =INTMARB!Z12+GIC!Z12 -> 200.65926
A13: Coke oven coke | B13: C0311 | C13: =INTMARB!C13+GIC!C13 -> 32724.06 | D13: =INTMARB!D13+GIC!D13 -> 29149.165 | E13: =INTMARB!E13+GIC!E13 -> 27962.23 | F13: =INTMARB!F13+GIC!F13 -> 29446.84 | G13: =INTMARB!G13+GIC!G13 -> 22336.103 | H13: =INTMARB!H13+GIC!H13 -> 20405.887 | I13: =INTMARB!I13+GIC!I13 -> 22782.073 | J13: =INTMARB!J13+GIC!J13 -> 20086.438 | ... Z13: =INTMARB!Z13+GIC!Z13 -> 8135.5383
A14: Gas coke | B14: C0312 | C14: =INTMARB!C14+GIC!C14 -> 0 | D14: =INTMARB!D14+GIC!D14 -> 0 | E14: =INTMARB!E14+GIC!E14 -> 0 | F14: =INTMARB!F14+GIC!F14 -> 0 | G14: =INTMARB!G14+GIC!G14 -> 0 | H14: =INTMARB!H14+GIC!H14 -> 0 | I14: =INTMARB!I14+GIC!I14 -> 0 | J14: =INTMARB!J14+GIC!J14 -> 0 | ... Z14: =INTMARB!Z14+GIC!Z14 -> 0
A15: Coal tar | B15: C0340 | C15: =INTMARB!C15+GIC!C15 -> 121.95042 | D15: =INTMARB!D15+GIC!D15 -> 153.94778 | E15: =INTMARB!E15+GIC!E15 -> 624.57159 | F15: =INTMARB!F15+GIC!F15 -> 566.89228 | G15: =INTMARB!G15+GIC!G15 -> 637.77807 | H15: =INTMARB!H15+GIC!H15 -> 669.44588 | I15: =INTMARB!I15+GIC!I15 -> 343.70282 | J15: =INTMARB!J15+GIC!J15 -> 400.54333 | ... Z15: =INTMARB!Z15+GIC!Z15 -> 143.41003
A16: Brown coal briquettes | B16: C0330 | C16: =INTMARB!C16+GIC!C16 -> 12669.701 | D16: =INTMARB!D16+GIC!D16 -> 12055.201 | E16: =INTMARB!E16+GIC!E16 -> 11621.627 | F16: =INTMARB!F16+GIC!F16 -> 12809.766 | G16: =INTMARB!G16+GIC!G16 -> 12348.439 | H16: =INTMARB!H16+GIC!H16 -> 12735.442 | I16: =INTMARB!I16+GIC!I16 -> 12870.392 | J16: =INTMARB!J16+GIC!J16 -> 13160.034 | ... Z16: =INTMARB!Z16+GIC!Z16 -> 8244.142
A17: Manufactured gases | B17: C0350-0370 | C17: =SUM(C18:C21) -> 156228.88 | D17: =SUM(D18:D21) -> 149492.33 | E17: =SUM(E18:E21) -> 151767.87 | F17: =SUM(F18:F21) -> 150164.94 | G17: =SUM(G18:G21) -> 155681.92 | H17: =SUM(H18:H21) -> 152725.72 | I17: =SUM(I18:I21) -> 155428.83 | J17: =SUM(J18:J21) -> 159058.72 | ... Z17: =SUM(Z18:Z21) -> 111093.93
A18: Gas works gas | B18: C0360 | C18: =INTMARB!C18+GIC!C18 -> 965.18968 | D18: =INTMARB!D18+GIC!D18 -> 837.3984 | E18: =INTMARB!E18+GIC!E18 -> 845.92619 | F18: =INTMARB!F18+GIC!F18 -> 870.92836 | G18: =INTMARB!G18+GIC!G18 -> 855.63471 | H18: =INTMARB!H18+GIC!H18 -> 901.01105 | I18: =INTMARB!I18+GIC!I18 -> 930.71204 | J18: =INTMARB!J18+GIC!J18 -> 890.15951 | ... Z18: =INTMARB!Z18+GIC!Z18 -> 103.10495
A19: Coke oven gas | B19: C0350 | C19: =INTMARB!C19+GIC!C19 -> 15304.114 | D19: =INTMARB!D19+GIC!D19 -> 13883.623 | E19: =INTMARB!E19+GIC!E19 -> 13501.705 | F19: =INTMARB!F19+GIC!F19 -> 13319.112 | G19: =INTMARB!G19+GIC!G19 -> 13583.546 | H19: =INTMARB!H19+GIC!H19 -> 13141.793 | I19: =INTMARB!I19+GIC!I19 -> 13642.476 | J19: =INTMARB!J19+GIC!J19 -> 14216.464 | ... Z19: =INTMARB!Z19+GIC!Z19 -> 9654.4074
A20: Blast furnace gas | B20: C0371 | C20: =INTMARB!C20+GIC!C20 -> 135123.3 | D20: =INTMARB!D20+GIC!D20 -> 129916.28 | E20: =INTMARB!E20+GIC!E20 -> 132320.24 | F20: =INTMARB!F20+GIC!F20 -> 129746.5 | G20: =INTMARB!G20+GIC!G20 -> 134596.28 | H20: =INTMARB!H20+GIC!H20 -> 131974.06 | I20: =INTMARB!I20+GIC!I20 -> 134485.4 | J20: =INTMARB!J20+GIC!J20 -> 137326.46 | ... Z20: =INTMARB!Z20+GIC!Z20 -> 94767.966
A21: Other recovered gases | B21: C0379 | C21: =INTMARB!C21+GIC!C21 -> 4836.2854 | D21: =INTMARB!D21+GIC!D21 -> 4855.0307 | E21: =INTMARB!E21+GIC!E21 -> 5100.0034 | F21: =INTMARB!F21+GIC!F21 -> 6228.4039 | G21: =INTMARB!G21+GIC!G21 -> 6646.4589 | H21: =INTMARB!H21+GIC!H21 -> 6708.8542 | I21: =INTMARB!I21+GIC!I21 -> 6370.2456 | J21: =INTMARB!J21+GIC!J21 -> 6625.6347 | ... Z21: =INTMARB!Z21+GIC!Z21 -> 6568.4475
A22: Peat and peat products | B22: P1000 | C22: =SUM(C23:C24) -> 11745.939 | D22: =SUM(D23:D24) -> 14668.922 | E22: =SUM(E23:E24) -> 15647.04 | F22: =SUM(F23:F24) -> 16346.631 | G22: =SUM(G23:G24) -> 14770.748 | H22: =SUM(H23:H24) -> 12885.91 | I22: =SUM(I23:I24) -> 15135.244 | J22: =SUM(J23:J24) -> 16086.077 | ... Z22: =SUM(Z23:Z24) -> 3822.5388
A23: Peat | B23: P1100 | C23: =INTMARB!C23+GIC!C23 -> 11122.298 | D23: =INTMARB!D23+GIC!D23 -> 14117.313 | E23: =INTMARB!E23+GIC!E23 -> 15080.562 | F23: =INTMARB!F23+GIC!F23 -> 15862.085 | G23: =INTMARB!G23+GIC!G23 -> 14281.963 | H23: =INTMARB!H23+GIC!H23 -> 12404.037 | I23: =INTMARB!I23+GIC!I23 -> 14659.843 | J23: =INTMARB!J23+GIC!J23 -> 15618.12 | ... Z23: =INTMARB!Z23+GIC!Z23 -> 3708.8968
A24: Peat products | B24: P1200 | C24: =INTMARB!C24+GIC!C24 -> 623.64111 | D24: =INTMARB!D24+GIC!D24 -> 551.60898 | E24: =INTMARB!E24+GIC!E24 -> 566.47731 | F24: =INTMARB!F24+GIC!F24 -> 484.54621 | G24: =INTMARB!G24+GIC!G24 -> 488.78481 | H24: =INTMARB!H24+GIC!H24 -> 481.87234 | I24: =INTMARB!I24+GIC!I24 -> 475.40074 | J24: =INTMARB!J24+GIC!J24 -> 467.95665 | ... Z24: =INTMARB!Z24+GIC!Z24 -> 113.64205
A25: Oil shale and oil sands | B25: S2000 | C25: =INTMARB!C25+GIC!C25 -> 9707.0447 | D25: =INTMARB!D25+GIC!D25 -> 9333.6626 | E25: =INTMARB!E25+GIC!E25 -> 9056.6106 | F25: =INTMARB!F25+GIC!F25 -> 10861.617 | G25: =INTMARB!G25+GIC!G25 -> 10720.924 | H25: =INTMARB!H25+GIC!H25 -> 10579.734 | I25: =INTMARB!I25+GIC!I25 -> 9743.0462 | J25: =INTMARB!J25+GIC!J25 -> 12667.722 | ... Z25: =INTMARB!Z25+GIC!Z25 -> 2079.672
A26: Oil and petroleum products | B26: O4000XBIO | C26: =SUM(C27,C33) -> 1651646.1 | D26: =SUM(D27,D33) -> 1687435.9 | E26: =SUM(E27,E33) -> 1675026.4 | F26: =SUM(F27,F33) -> 1689680.6 | G26: =SUM(G27,G33) -> 1698837.7 | H26: =SUM(H27,H33) -> 1694081.9 | I26: =SUM(I27,I33) -> 1696295.9 | J26: =SUM(J27,J33) -> 1652563.7 | ... Z26: =SUM(Z27,Z33) -> 1340624.6
A27: Crude oil, NGL, refinery feedstocks, additives and oxygenates and other hydrocarbons (excluding biofuel portion) | B27: O4100_TOT_4200-4500XBIO | C27: =SUM(C28:C32) -> 435.30568 | D27: =SUM(D28:D32) -> 276.49452 | E27: =SUM(E28:E32) -> 266.42992 | F27: =SUM(F28:F32) -> 276.30282 | G27: =SUM(G28:G32) -> 499.48715 | H27: =SUM(H28:H32) -> 170.42927 | I27: =SUM(I28:I32) -> 82.890249 | J27: =SUM(J28:J32) -> 171.57729 | ... Z27: =SUM(Z28:Z32) -> 100.80657
A28: Crude oil | B28: O4100_TOT | C28: =INTMARB!C28+GIC!C28 -> 435.30568 | D28: =INTMARB!D28+GIC!D28 -> 276.49452 | E28: =INTMARB!E28+GIC!E28 -> 135.08835 | F28: =INTMARB!F28+GIC!F28 -> 173.80271 | G28: =INTMARB!G28+GIC!G28 -> 468.273 | H28: =INTMARB!H28+GIC!H28 -> 170.42927 | I28: =INTMARB!I28+GIC!I28 -> 82.890249 | J28: =INTMARB!J28+GIC!J28 -> 43.362081 | ... Z28: =INTMARB!Z28+GIC!Z28 -> 36.437342
A29: Natural gas liquids | B29: O4200 | C29: =INTMARB!C29+GIC!C29 -> 0 | D29: =INTMARB!D29+GIC!D29 -> 0 | E29: =INTMARB!E29+GIC!E29 -> 131.34157 | F29: =INTMARB!F29+GIC!F29 -> 102.5001 | G29: =INTMARB!G29+GIC!G29 -> 31.214143 | H29: =INTMARB!H29+GIC!H29 -> 0 | I29: =INTMARB!I29+GIC!I29 -> 0 | J29: =INTMARB!J29+GIC!J29 -> 128.21521 | ... Z29: =INTMARB!Z29+GIC!Z29 -> 64.369231
A30: Refinery feedstocks | B30: O4300 | C30: =INTMARB!C30+GIC!C30 -> 0 | D30: =INTMARB!D30+GIC!D30 -> 0 | E30: =INTMARB!E30+GIC!E30 -> 0 | F30: =INTMARB!F30+GIC!F30 -> 0 | G30: =INTMARB!G30+GIC!G30 -> 0 | H30: =INTMARB!H30+GIC!H30 -> 0 | I30: =INTMARB!I30+GIC!I30 -> 0 | J30: =INTMARB!J30+GIC!J30 -> 0 | ... Z30: =INTMARB!Z30+GIC!Z30 -> 0
A31: Additives and oxygenates (excluding biofuel portion) | B31: O4400X4410 | C31: =INTMARB!C31+GIC!C31 -> 0 | D31: =INTMARB!D31+GIC!D31 -> 0 | E31: =INTMARB!E31+GIC!E31 -> 0 | F31: =INTMARB!F31+GIC!F31 -> 0 | G31: =INTMARB!G31+GIC!G31 -> 0 | H31: =INTMARB!H31+GIC!H31 -> 0 | I31: =INTMARB!I31+GIC!I31 -> 0 | J31: =INTMARB!J31+GIC!J31 -> 0 | ... Z31: =INTMARB!Z31+GIC!Z31 -> 0
A32: Other hydrocarbons | B32: O4500 | C32: =INTMARB!C32+GIC!C32 -> 0 | D32: =INTMARB!D32+GIC!D32 -> 0 | E32: =INTMARB!E32+GIC!E32 -> 0 | F32: =INTMARB!F32+GIC!F32 -> 0 | G32: =INTMARB!G32+GIC!G32 -> 0 | H32: =INTMARB!H32+GIC!H32 -> 0 | I32: =INTMARB!I32+GIC!I32 -> 0 | J32: =INTMARB!J32+GIC!J32 -> 0 | ... Z32: =INTMARB!Z32+GIC!Z32 -> 0
A33: Oil products (excluding biofuel portion) | B33: O4600XBIO | C33: =SUM(C34:C50) -> 1651210.8 | D33: =SUM(D34:D50) -> 1687159.4 | E33: =SUM(E34:E50) -> 1674759.9 | F33: =SUM(F34:F50) -> 1689404.3 | G33: =SUM(G34:G50) -> 1698338.2 | H33: =SUM(H34:H50) -> 1693911.4 | I33: =SUM(I34:I50) -> 1696213.1 | J33: =SUM(J34:J50) -> 1652392.1 | ... Z33: =SUM(Z34:Z50) -> 1340523.8
A34: Refinery gas | B34: O4610 | C34: =INTMARB!C34+GIC!C34 -> 53560.028 | D34: =INTMARB!D34+GIC!D34 -> 53212.676 | E34: =INTMARB!E34+GIC!E34 -> 54531.128 | F34: =INTMARB!F34+GIC!F34 -> 59096.205 | G34: =INTMARB!G34+GIC!G34 -> 61616.98 | H34: =INTMARB!H34+GIC!H34 -> 62078.787 | I34: =INTMARB!I34+GIC!I34 -> 61792.963 | J34: =INTMARB!J34+GIC!J34 -> 64488.891 | ... Z34: =INTMARB!Z34+GIC!Z34 -> 59314.865
A35: Ethane | B35: O4620 | C35: =INTMARB!C35+GIC!C35 -> 28.582425 | D35: =INTMARB!D35+GIC!D35 -> 22.865895 | E35: =INTMARB!E35+GIC!E35 -> 25.72416 | F35: =INTMARB!F35+GIC!F35 -> 27.443465 | G35: =INTMARB!G35+GIC!G35 -> 58.502062 | H35: =INTMARB!H35+GIC!H35 -> 67.458727 | I35: =INTMARB!I35+GIC!I35 -> 38.876524 | J35: =INTMARB!J35+GIC!J35 -> 38.734597 | ... Z35: =INTMARB!Z35+GIC!Z35 -> 0.65729664
A36: Liquefied petroleum gases | B36: O4630 | C36: =INTMARB!C36+GIC!C36 -> 52714.078 | D36: =INTMARB!D36+GIC!D36 -> 52387.672 | E36: =INTMARB!E36+GIC!E36 -> 52060.552 | F36: =INTMARB!F36+GIC!F36 -> 51928.973 | G36: =INTMARB!G36+GIC!G36 -> 52141.672 | H36: =INTMARB!H36+GIC!H36 -> 53172.897 | I36: =INTMARB!I36+GIC!I36 -> 51710.124 | J36: =INTMARB!J36+GIC!J36 -> 50686.157 | ... Z36: =INTMARB!Z36+GIC!Z36 -> 44451.494
A37: Motor gasoline (excluding biofuel portion) | B37: O4652XR5210B | C37: =INTMARB!C37+GIC!C37 -> 320345.03 | D37: =INTMARB!D37+GIC!D37 -> 315577.95 | E37: =INTMARB!E37+GIC!E37 -> 310556.94 | F37: =INTMARB!F37+GIC!F37 -> 300286.55 | G37: =INTMARB!G37+GIC!G37 -> 290894.46 | H37: =INTMARB!H37+GIC!H37 -> 277883.22 | I37: =INTMARB!I37+GIC!I37 -> 268152.1 | J37: =INTMARB!J37+GIC!J37 -> 259318.04 | ... Z37: =INTMARB!Z37+GIC!Z37 -> 204059.51
A38: Aviation gasoline | B38: O4651 | C38: =INTMARB!C38+GIC!C38 -> 351.04154 | D38: =INTMARB!D38+GIC!D38 -> 335.36311 | E38: =INTMARB!E38+GIC!E38 -> 341.32342 | F38: =INTMARB!F38+GIC!F38 -> 317.68229 | G38: =INTMARB!G38+GIC!G38 -> 319.84319 | H38: =INTMARB!H38+GIC!H38 -> 377.528 | I38: =INTMARB!I38+GIC!I38 -> 309.51421 | J38: =INTMARB!J38+GIC!J38 -> 284.45206 | ... Z38: =INTMARB!Z38+GIC!Z38 -> 148.22564
A39: Gasoline-type jet fuel | B39: O4653 | C39: =INTMARB!C39+GIC!C39 -> 372.66489 | D39: =INTMARB!D39+GIC!D39 -> 317.50505 | E39: =INTMARB!E39+GIC!E39 -> 104.42046 | F39: =INTMARB!F39+GIC!F39 -> 95.094969 | G39: =INTMARB!G39+GIC!G39 -> 142.27425 | H39: =INTMARB!H39+GIC!H39 -> 44.592438 | I39: =INTMARB!I39+GIC!I39 -> 47.777464 | J39: =INTMARB!J39+GIC!J39 -> 9.5555963 | ... Z39: =INTMARB!Z39+GIC!Z39 -> 0
A40: Kerosene-type jet fuel (excluding biofuel portion) | B40: O4661XR5230B | C40: =INTMARB!C40+GIC!C40 -> 105625.38 | D40: =INTMARB!D40+GIC!D40 -> 102751.43 | E40: =INTMARB!E40+GIC!E40 -> 100325.33 | F40: =INTMARB!F40+GIC!F40 -> 102324.53 | G40: =INTMARB!G40+GIC!G40 -> 108819.9 | H40: =INTMARB!H40+GIC!H40 -> 113768.73 | I40: =INTMARB!I40+GIC!I40 -> 118794.09 | J40: =INTMARB!J40+GIC!J40 -> 123867.98 | ... Z40: =INTMARB!Z40+GIC!Z40 -> 136897.36
...

Sheet INTMARB
A1: International maritime bunkers | B1: INTMARB | C1: 2000 | D1: 2001 | E1: 2002 | F1: 2003 | G1: 2004 | H1: 2005 | I1: 2006 | J1: 2007 | K1: 2008 | L1: 2009 | M1: 2010 | N1: 2011 | O1: 2012 | P1: 2013 | Q1: 2014 | R1: 2015 | S1: 2016 | T1: 2017 | U1: 2018 | V1: 2019 | W1: 2020 | X1: 2021 | Y1: 2022 | Z1: 2023
A2: Total | B2: TOTAL | C2: =SUM(C3,C17,C22,C25,C26,C51,C52) -> 129755.56 | D2: =SUM(D3,D17,D22,D25,D26,D51,D52) -> 133806.23 | E2: =SUM(E3,E17,E22,E25,E26,E51,E52) -> 137724.48 | F2: =SUM(F3,F17,F22,F25,F26,F51,F52) -> 141828.47 | G2: =SUM(G3,G17,G22,G25,G26,G51,G52) -> 149118.53 | H2: =SUM(H3,H17,H22,H25,H26,H51,H52) -> 152050.66 | I2: =SUM(I3,I17,I22,I25,I26,I51,I52) -> 162126.1 | J2: =SUM(J3,J17,J22,J25,J26,J51,J52) -> 169125.02 | ... Z2: =SUM(Z3,Z17,Z22,Z25,Z26,Z51,Z52) -> 124591.13
A3: Solid fossil fuels | B3: C0000X0350-0370 | C3: =SUM(C4,C8,C11) -> 0 | D3: =SUM(D4,D8,D11) -> 0 | E3: =SUM(E4,E8,E11) -> 0 | F3: =SUM(F4,F8,F11) -> 0 | G3: =SUM(G4,G8,G11) -> 0 | H3: =SUM(H4,H8,H11) -> 0 | I3: =SUM(I4,I8,I11) -> 0 | J3: =SUM(J4,J8,J11) -> 0 | ... Z3: =SUM(Z4,Z8,Z11) -> 0
A4: Hard coal | B4: C0100 | C4: =SUM(C5:C7) -> 0 | D4: =SUM(D5:D7) -> 0 | E4: =SUM(E5:E7) -> 0 | F4: =SUM(F5:F7) -> 0 | G4: =SUM(G5:G7) -> 0 | H4: =SUM(H5:H7) -> 0 | I4: =SUM(I5:I7) -> 0 | J4: =SUM(J5:J7) -> 0 | ... Z4: =SUM(Z5:Z7) -> 0
A5: Anthracite | B5: C0110 | C5: =INTMARB_IN!C5+INTMARB_EX!C5 -> 0 | D5: =INTMARB_IN!D5+INTMARB_EX!D5 -> 0 | E5: =INTMARB_IN!E5+INTMARB_EX!E5 -> 0 | F5: =INTMARB_IN!F5+INTMARB_EX!F5 -> 0 | G5: =INTMARB_IN!G5+INTMARB_EX!G5 -> 0 | H5: =INTMARB_IN!H5+INTMARB_EX!H5 -> 0 | I5: =INTMARB_IN!I5+INTMARB_EX!I5 -> 0 | J5: =INTMARB_IN!J5+INTMARB_EX!J5 -> 0 | ... Z5: =INTMARB_IN!Z5+INTMARB_EX!Z5 -> 0
A6: Coking coal | B6: C0121 | C6: =INTMARB_IN!C6+INTMARB_EX!C6 -> 0 | D6: =INTMARB_IN!D6+INTMARB_EX!D6 -> 0 | E6: =INTMARB_IN!E6+INTMARB_EX!E6 -> 0 | F6: =INTMARB_IN!F6+INTMARB_EX!F6 -> 0 | G6: =INTMARB_IN!G6+INTMARB_EX!G6 -> 0 | H6: =INTMARB_IN!H6+INTMARB_EX!H6 -> 0 | I6: =INTMARB_IN!I6+INTMARB_EX!I6 -> 0 | J6: =INTMARB_IN!J6+INTMARB_EX!J6 -> 0 | ... Z6: =INTMARB_IN!Z6+INTMARB_EX!Z6 -> 0
A7: Other bituminous coal | B7: C0129 | C7: =INTMARB_IN!C7+INTMARB_EX!C7 -> 0 | D7: =INTMARB_IN!D7+INTMARB_EX!D7 -> 0 | E7: =INTMARB_IN!E7+INTMARB_EX!E7 -> 0 | F7: =INTMARB_IN!F7+INTMARB_EX!F7 -> 0 | G7: =INTMARB_IN!G7+INTMARB_EX!G7 -> 0 | H7: =INTMARB_IN!H7+INTMARB_EX!H7 -> 0 | I7: =INTMARB_IN!I7+INTMARB_EX!I7 -> 0 | J7: =INTMARB_IN!J7+INTMARB_EX!J7 -> 0 | ... Z7: =INTMARB_IN!Z7+INTMARB_EX!Z7 -> 0
A8: Brown coal | B8: C0200 | C8: =SUM(C9:C10) -> 0 | D8: =SUM(D9:D10) -> 0 | E8: =SUM(E9:E10) -> 0 | F8: =SUM(F9:F10) -> 0 | G8: =SUM(G9:G10) -> 0 | H8: =SUM(H9:H10) -> 0 | I8: =SUM(I9:I10) -> 0 | J8: =SUM(J9:J10) -> 0 | ... Z8: =SUM(Z9:Z10) -> 0
A9: Sub-bituminous coal | B9: C0210 | C9: =INTMARB_IN!C9+INTMARB_EX!C9 -> 0 | D9: =INTMARB_IN!D9+INTMARB_EX!D9 -> 0 | E9: =INTMARB_IN!E9+INTMARB_EX!E9 -> 0 | F9: =INTMARB_IN!F9+INTMARB_EX!F9 -> 0 | G9: =INTMARB_IN!G9+INTMARB_EX!G9 -> 0 | H9: =INTMARB_IN!H9+INTMARB_EX!H9 -> 0 | I9: =INTMARB_IN!I9+INTMARB_EX!I9 -> 0 | J9: =INTMARB_IN!J9+INTMARB_EX!J9 -> 0 | ... Z9: =INTMARB_IN!Z9+INTMARB_EX!Z9 -> 0
A10: Lignite | B10: C0220 | C10: =INTMARB_IN!C10+INTMARB_EX!C10 -> 0 | D10: =INTMARB_IN!D10+INTMARB_EX!D10 -> 0 | E10: =INTMARB_IN!E10+INTMARB_EX!E10 -> 0 | F10: =INTMARB_IN!F10+INTMARB_EX!F10 -> 0 | G10: =INTMARB_IN!G10+INTMARB_EX!G10 -> 0 | H10: =INTMARB_IN!H10+INTMARB_EX!H10 -> 0 | I10: =INTMARB_IN!I10+INTMARB_EX!I10 -> 0 | J10: =INTMARB_IN!J10+INTMARB_EX!J10 -> 0 | ... Z10: =INTMARB_IN!Z10+INTMARB_EX!Z10 -> 0
A11: Coal products | B11: C0300 | C11: =SUM(C12:C16) -> 0 | D11: =SUM(D12:D16) -> 0 | E11: =SUM(E12:E16) -> 0 | F11: =SUM(F12:F16) -> 0 | G11: =SUM(G12:G16) -> 0 | H11: =SUM(H12:H16) -> 0 | I11: =SUM(I12:I16) -> 0 | J11: =SUM(J12:J16) -> 0 | ... Z11: =SUM(Z12:Z16) -> 0
A12: Patent fuel | B12: C0320 | C12: =INTMARB_IN!C12+INTMARB_EX!C12 -> 0 | D12: =INTMARB_IN!D12+INTMARB_EX!D12 -> 0 | E12: =INTMARB_IN!E12+INTMARB_EX!E12 -> 0 | F12: =INTMARB_IN!F12+INTMARB_EX!F12 -> 0 | G12: =INTMARB_IN!G12+INTMARB_EX!G12 -> 0 | H12: =INTMARB_IN!H12+INTMARB_EX!H12 -> 0 | I12: =INTMARB_IN!I12+INTMARB_EX!I12 -> 0 | J12: =INTMARB_IN!J12+INTMARB_EX!J12 -> 0 | ... Z12: =INTMARB_IN!Z12+INTMARB_EX!Z12 -> 0
A13: Coke oven coke | B13: C0311 | C13: =INTMARB_IN!C13+INTMARB_EX!C13 -> 0 | D13: =INTMARB_IN!D13+INTMARB_EX!D13 -> 0 | E13: =INTMARB_IN!E13+INTMARB_EX!E13 -> 0 | F13: =INTMARB_IN!F13+INTMARB_EX!F13 -> 0 | G13: =INTMARB_IN!G13+INTMARB_EX!G13 -> 0 | H13: =INTMARB_IN!H13+INTMARB_EX!H13 -> 0 | I13: =INTMARB_IN!I13+INTMARB_EX!I13 -> 0 | J13: =INTMARB_IN!J13+INTMARB_EX!J13 -> 0 | ... Z13: =INTMARB_IN!Z13+INTMARB_EX!Z13 -> 0
A14: Gas coke | B14: C0312 | C14: =INTMARB_IN!C14+INTMARB_EX!C14 -> 0 | D14: =INTMARB_IN!D14+INTMARB_EX!D14 -> 0 | E14: =INTMARB_IN!E14+INTMARB_EX!E14 -> 0 | F14: =INTMARB_IN!F14+INTMARB_EX!F14 -> 0 | G14: =INTMARB_IN!G14+INTMARB_EX!G14 -> 0 | H14: =INTMARB_IN!H14+INTMARB_EX!H14 -> 0 | I14: =INTMARB_IN!I14+INTMARB_EX!I14 -> 0 | J14: =INTMARB_IN!J14+INTMARB_EX!J14 -> 0 | ... Z14: =INTMARB_IN!Z14+INTMARB_EX!Z14 -> 0
A15: Coal tar | B15: C0340 | C15: =INTMARB_IN!C15+INTMARB_EX!C15 -> 0 | D15: =INTMARB_IN!D15+INTMARB_EX!D15 -> 0 | E15: =INTMARB_IN!E15+INTMARB_EX!E15 -> 0 | F15: =INTMARB_IN!F15+INTMARB_EX!F15 -> 0 | G15: =INTMARB_IN!G15+INTMARB_EX!G15 -> 0 | H15: =INTMARB_IN!H15+INTMARB_EX!H15 -> 0 | I15: =INTMARB_IN!I15+INTMARB_EX!I15 -> 0 | J15: =INTMARB_IN!J15+INTMARB_EX!J15 -> 0 | ... Z15: =INTMARB_IN!Z15+INTMARB_EX!Z15 -> 0
A16: Brown coal briquettes | B16: C0330 | C16: =INTMARB_IN!C16+INTMARB_EX!C16 -> 0 | D16: =INTMARB_IN!D16+INTMARB_EX!D16 -> 0 | E16: =INTMARB_IN!E16+INTMARB_EX!E16 -> 0 | F16: =INTMARB_IN!F16+INTMARB_EX!F16 -> 0 | G16: =INTMARB_IN!G16+INTMARB_EX!G16 -> 0 | H16: =INTMARB_IN!H16+INTMARB_EX!H16 -> 0 | I16: =INTMARB_IN!I16+INTMARB_EX!I16 -> 0 | J16: =INTMARB_IN!J16+INTMARB_EX!J16 -> 0 | ... Z16: =INTMARB_IN!Z16+INTMARB_EX!Z16 -> 0
A17: Manufactured gases | B17: C0350-0370 | C17: =SUM(C18:C21) -> 0 | D17: =SUM(D18:D21) -> 0 | E17: =SUM(E18:E21) -> 0 | F17: =SUM(F18:F21) -> 0 | G17: =SUM(G18:G21) -> 0 | H17: =SUM(H18:H21) -> 0 | I17: =SUM(I18:I21) -> 0 | J17: =SUM(J18:J21) -> 0 | ... Z17: =SUM(Z18:Z21) -> 0
A18: Gas works gas | B18: C0360 | C18: =INTMARB_IN!C18+INTMARB_EX!C18 -> 0 | D18: =INTMARB_IN!D18+INTMARB_EX!D18 -> 0 | E18: =INTMARB_IN!E18+INTMARB_EX!E18 -> 0 | F18: =INTMARB_IN!F18+INTMARB_EX!F18 -> 0 | G18: =INTMARB_IN!G18+INTMARB_EX!G18 -> 0 | H18: =INTMARB_IN!H18+INTMARB_EX!H18 -> 0 | I18: =INTMARB_IN!I18+INTMARB_EX!I18 -> 0 | J18: =INTMARB_IN!J18+INTMARB_EX!J18 -> 0 | ... Z18: =INTMARB_IN!Z18+INTMARB_EX!Z18 -> 0
A19: Coke oven gas | B19: C0350 | C19: =INTMARB_IN!C19+INTMARB_EX!C19 -> 0 | D19: =INTMARB_IN!D19+INTMARB_EX!D19 -> 0 | E19: =INTMARB_IN!E19+INTMARB_EX!E19 -> 0 | F19: =INTMARB_IN!F19+INTMARB_EX!F19 -> 0 | G19: =INTMARB_IN!G19+INTMARB_EX!G19 -> 0 | H19: =INTMARB_IN!H19+INTMARB_EX!H19 -> 0 | I19: =INTMARB_IN!I19+INTMARB_EX!I19 -> 0 | J19: =INTMARB_IN!J19+INTMARB_EX!J19 -> 0 | ... Z19: =INTMARB_IN!Z19+INTMARB_EX!Z19 -> 0
A20: Blast furnace gas | B20: C0371 | C20: =INTMARB_IN!C20+INTMARB_EX!C20 -> 0 | D20: =INTMARB_IN!D20+INTMARB_EX!D20 -> 0 | E20: =INTMARB_IN!E20+INTMARB_EX!E20 -> 0 | F20: =INTMARB_IN!F20+INTMARB_EX!F20 -> 0 | G20: =INTMARB_IN!G20+INTMARB_EX!G20 -> 0 | H20: =INTMARB_IN!H20+INTMARB_EX!H20 -> 0 | I20: =INTMARB_IN!I20+INTMARB_EX!I20 -> 0 | J20: =INTMARB_IN!J20+INTMARB_EX!J20 -> 0 | ... Z20: =INTMARB_IN!Z20+INTMARB_EX!Z20 -> 0
A21: Other recovered gases | B21: C0379 | C21: =INTMARB_IN!C21+INTMARB_EX!C21 -> 0 | D21: =INTMARB_IN!D21+INTMARB_EX!D21 -> 0 | E21: =INTMARB_IN!E21+INTMARB_EX!E21 -> 0 | F21: =INTMARB_IN!F21+INTMARB_EX!F21 -> 0 | G21: =INTMARB_IN!G21+INTMARB_EX!G21 -> 0 | H21: =INTMARB_IN!H21+INTMARB_EX!H21 -> 0 | I21: =INTMARB_IN!I21+INTMARB_EX!I21 -> 0 | J21: =INTMARB_IN!J21+INTMARB_EX!J21 -> 0 | ... Z21: =INTMARB_IN!Z21+INTMARB_EX!Z21 -> 0
A22: Peat and peat products | B22: P1000 | C22: =SUM(C23:C24) -> 0 | D22: =SUM(D23:D24) -> 0 | E22: =SUM(E23:E24) -> 0 | F22: =SUM(F23:F24) -> 0 | G22: =SUM(G23:G24) -> 0 | H22: =SUM(H23:H24) -> 0 | I22: =SUM(I23:I24) -> 0 | J22: =SUM(J23:J24) -> 0 | ... Z22: =SUM(Z23:Z24) -> 0
A23: Peat | B23: P1100 | C23: =INTMARB_IN!C23+INTMARB_EX!C23 -> 0 | D23: =INTMARB_IN!D23+INTMARB_EX!D23 -> 0 | E23: =INTMARB_IN!E23+INTMARB_EX!E23 -> 0 | F23: =INTMARB_IN!F23+INTMARB_EX!F23 -> 0 | G23: =INTMARB_IN!G23+INTMARB_EX!G23 -> 0 | H23: =INTMARB_IN!H23+INTMARB_EX!H23 -> 0 | I23: =INTMARB_IN!I23+INTMARB_EX!I23 -> 0 | J23: =INTMARB_IN!J23+INTMARB_EX!J23 -> 0 | ... Z23: =INTMARB_IN!Z23+INTMARB_EX!Z23 -> 0
A24: Peat products | B24: P1200 | C24: =INTMARB_IN!C24+INTMARB_EX!C24 -> 0 | D24: =INTMARB_IN!D24+INTMARB_EX!D24 -> 0 | E24: =INTMARB_IN!E24+INTMARB_EX!E24 -> 0 | F24: =INTMARB_IN!F24+INTMARB_EX!F24 -> 0 | G24: =INTMARB_IN!G24+INTMARB_EX!G24 -> 0 | H24: =INTMARB_IN!H24+INTMARB_EX!H24 -> 0 | I24: =INTMARB_IN!I24+INTMARB_EX!I24 -> 0 | J24: =INTMARB_IN!J24+INTMARB_EX!J24 -> 0 | ... Z24: =INTMARB_IN!Z24+INTMARB_EX!Z24 -> 0
A25: Oil shale and oil sands | B25: S2000 | C25: =INTMARB_IN!C25+INTMARB_EX!C25 -> 0 | D25: =INTMARB_IN!D25+INTMARB_EX!D25 -> 0 | E25: =INTMARB_IN!E25+INTMARB_EX!E25 -> 0 | F25: =INTMARB_IN!F25+INTMARB_EX!F25 -> 0 | G25: =INTMARB_IN!G25+INTMARB_EX!G25 -> 0 | H25: =INTMARB_IN!H25+INTMARB_EX!H25 -> 0 | I25: =INTMARB_IN!I25+INTMARB_EX!I25 -> 0 | J25: =INTMARB_IN!J25+INTMARB_EX!J25 -> 0 | ... Z25: =INTMARB_IN!Z25+INTMARB_EX!Z25 -> 0
A26: Oil and petroleum products | B26: O4000XBIO | C26: =SUM(C27,C33) -> 129755.56 | D26: =SUM(D27,D33) -> 133806.23 | E26: =SUM(E27,E33) -> 137724.48 | F26: =SUM(F27,F33) -> 141828.47 | G26: =SUM(G27,G33) -> 149118.53 | H26: =SUM(H27,H33) -> 152050.66 | I26: =SUM(I27,I33) -> 162126.1 | J26: =SUM(J27,J33) -> 169125.02 | ... Z26: =SUM(Z27,Z33) -> 123582.49
A27: Crude oil, NGL, refinery feedstocks, additives and oxygenates and other hydrocarbons (excluding biofuel portion) | B27: O4100_TOT_4200-4500XBIO | C27: =SUM(C28:C32) -> 0 | D27: =SUM(D28:D32) -> 0 | E27: =SUM(E28:E32) -> 0 | F27: =SUM(F28:F32) -> 0 | G27: =SUM(G28:G32) -> 0 | H27: =SUM(H28:H32) -> 0 | I27: =SUM(I28:I32) -> 0 | J27: =SUM(J28:J32) -> 0 | ... Z27: =SUM(Z28:Z32) -> 0
A28: Crude oil | B28: O4100_TOT | C28: =INTMARB_IN!C28+INTMARB_EX!C28 -> 0 | D28: =INTMARB_IN!D28+INTMARB_EX!D28 -> 0 | E28: =INTMARB_IN!E28+INTMARB_EX!E28 -> 0 | F28: =INTMARB_IN!F28+INTMARB_EX!F28 -> 0 | G28: =INTMARB_IN!G28+INTMARB_EX!G28 -> 0 | H28: =INTMARB_IN!H28+INTMARB_EX!H28 -> 0 | I28: =INTMARB_IN!I28+INTMARB_EX!I28 -> 0 | J28: =INTMARB_IN!J28+INTMARB_EX!J28 -> 0 | ... Z28: =INTMARB_IN!Z28+INTMARB_EX!Z28 -> 0
A29: Natural gas liquids | B29: O4200 | C29: =INTMARB_IN!C29+INTMARB_EX!C29 -> 0 | D29: =INTMARB_IN!D29+INTMARB_EX!D29 -> 0 | E29: =INTMARB_IN!E29+INTMARB_EX!E29 -> 0 | F29: =INTMARB_IN!F29+INTMARB_EX!F29 -> 0 | G29: =INTMARB_IN!G29+INTMARB_EX!G29 -> 0 | H29: =INTMARB_IN!H29+INTMARB_EX!H29 -> 0 | I29: =INTMARB_IN!I29+INTMARB_EX!I29 -> 0 | J29: =INTMARB_IN!J29+INTMARB_EX!J29 -> 0 | ... Z29: =INTMARB_IN!Z29+INTMARB_EX!Z29 -> 0
A30: Refinery feedstocks | B30: O4300 | C30: =INTMARB_IN!C30+INTMARB_EX!C30 -> 0 | D30: =INTMARB_IN!D30+INTMARB_EX!D30 -> 0 | E30: =INTMARB_IN!E30+INTMARB_EX!E30 -> 0 | F30: =INTMARB_IN!F30+INTMARB_EX!F30 -> 0 | G30: =INTMARB_IN!G30+INTMARB_EX!G30 -> 0 | H30: =INTMARB_IN!H30+INTMARB_EX!H30 -> 0 | I30: =INTMARB_IN!I30+INTMARB_EX!I30 -> 0 | J30: =INTMARB_IN!J30+INTMARB_EX!J30 -> 0 | ... Z30: =INTMARB_IN!Z30+INTMARB_EX!Z30 -> 0
A31: Additives and oxygenates (excluding biofuel portion) | B31: O4400X4410 | C31: =INTMARB_IN!C31+INTMARB_EX!C31 -> 0 | D31: =INTMARB_IN!D31+INTMARB_EX!D31 -> 0 | E31: =INTMARB_IN!E31+INTMARB_EX!E31 -> 0 | F31: =INTMARB_IN!F31+INTMARB_EX!F31 -> 0 | G31: =INTMARB_IN!G31+INTMARB_EX!G31 -> 0 | H31: =INTMARB_IN!H31+INTMARB_EX!H31 -> 0 | I31: =INTMARB_IN!I31+INTMARB_EX!I31 -> 0 | J31: =INTMARB_IN!J31+INTMARB_EX!J31 -> 0 | ... Z31: =INTMARB_IN!Z31+INTMARB_EX!Z31 -> 0
A32: Other hydrocarbons | B32: O4500 | C32: =INTMARB_IN!C32+INTMARB_EX!C32 -> 0 | D32: =INTMARB_IN!D32+INTMARB_EX!D32 -> 0 | E32: =INTMARB_IN!E32+INTMARB_EX!E32 -> 0 | F32: =INTMARB_IN!F32+INTMARB_EX!F32 -> 0 | G32: =INTMARB_IN!G32+INTMARB_EX!G32 -> 0 | H32: =INTMARB_IN!H32+INTMARB_EX!H32 -> 0 | I32: =INTMARB_IN!I32+INTMARB_EX!I32 -> 0 | J32: =INTMARB_IN!J32+INTMARB_EX!J32 -> 0 | ... Z32: =INTMARB_IN!Z32+INTMARB_EX!Z32 -> 0
A33: Oil products (excluding biofuel portion) | B33: O4600XBIO | C33: =SUM(C34:C50) -> 129755.56 | D33: =SUM(D34:D50) -> 133806.23 | E33: =SUM(E34:E50) -> 137724.48 | F33: =SUM(F34:F50) -> 141828.47 | G33: =SUM(G34:G50) -> 149118.53 | H33: =SUM(H34:H50) -> 152050.66 | I33: =SUM(I34:I50) -> 162126.1 | J33: =SUM(J34:J50) -> 169125.02 | ... Z33: =SUM(Z34:Z50) -> 123582.49
A34: Refinery gas | B34: O4610 | C34: =INTMARB_IN!C34+INTMARB_EX!C34 -> 0 | D34: =INTMARB_IN!D34+INTMARB_EX!D34 -> 0 | E34: =INTMARB_IN!E34+INTMARB_EX!E34 -> 0 | F34: =INTMARB_IN!F34+INTMARB_EX!F34 -> 0 | G34: =INTMARB_IN!G34+INTMARB_EX!G34 -> 0 | H34: =INTMARB_IN!H34+INTMARB_EX!H34 -> 0 | I34: =INTMARB_IN!I34+INTMARB_EX!I34 -> 0 | J34: =INTMARB_IN!J34+INTMARB_EX!J34 -> 0 | ... Z34: =INTMARB_IN!Z34+INTMARB_EX!Z34 -> 0
A35: Ethane | B35: O4620 | C35: =INTMARB_IN!C35+INTMARB_EX!C35 -> 0 | D35: =INTMARB_IN!D35+INTMARB_EX!D35 -> 0 | E35: =INTMARB_IN!E35+INTMARB_EX!E35 -> 0 | F35: =INTMARB_IN!F35+INTMARB_EX!F35 -> 0 | G35: =INTMARB_IN!G35+INTMARB_EX!G35 -> 0 | H35: =INTMARB_IN!H35+INTMARB_EX!H35 -> 0 | I35: =INTMARB_IN!I35+INTMARB_EX!I35 -> 0 | J35: =INTMARB_IN!J35+INTMARB_EX!J35 -> 0 | ... Z35: =INTMARB_IN!Z35+INTMARB_EX!Z35 -> 0
A36: Liquefied petroleum gases | B36: O4630 | C36: =INTMARB_IN!C36+INTMARB_EX!C36 -> 0 | D36: =INTMARB_IN!D36+INTMARB_EX!D36 -> 0 | E36: =INTMARB_IN!E36+INTMARB_EX!E36 -> 0 | F36: =INTMARB_IN!F36+INTMARB_EX!F36 -> 0 | G36: =INTMARB_IN!G36+INTMARB_EX!G36 -> 0 | H36: =INTMARB_IN!H36+INTMARB_EX!H36 -> 0 | I36: =INTMARB_IN!I36+INTMARB_EX!I36 -> 0 | J36: =INTMARB_IN!J36+INTMARB_EX!J36 -> 0 | ... Z36: =INTMARB_IN!Z36+INTMARB_EX!Z36 -> 0
A37: Motor gasoline (excluding biofuel portion) | B37: O4652XR5210B | C37: =INTMARB_IN!C37+INTMARB_EX!C37 -> 0 | D37: =INTMARB_IN!D37+INTMARB_EX!D37 -> 0 | E37: =INTMARB_IN!E37+INTMARB_EX!E37 -> 0 | F37: =INTMARB_IN!F37+INTMARB_EX!F37 -> 0 | G37: =INTMARB_IN!G37+INTMARB_EX!G37 -> 0 | H37: =INTMARB_IN!H37+INTMARB_EX!H37 -> 0 | I37: =INTMARB_IN!I37+INTMARB_EX!I37 -> 0 | J37: =INTMARB_IN!J37+INTMARB_EX!J37 -> 0 | ... Z37: =INTMARB_IN!Z37+INTMARB_EX!Z37 -> 14.130797
A38: Aviation gasoline | B38: O4651 | C38: =INTMARB_IN!C38+INTMARB_EX!C38 -> 0 | D38: =INTMARB_IN!D38+INTMARB_EX!D38 -> 0 | E38: =INTMARB_IN!E38+INTMARB_EX!E38 -> 0 | F38: =INTMARB_IN!F38+INTMARB_EX!F38 -> 0 | G38: =INTMARB_IN!G38+INTMARB_EX!G38 -> 0 | H38: =INTMARB_IN!H38+INTMARB_EX!H38 -> 0 | I38: =INTMARB_IN!I38+INTMARB_EX!I38 -> 0 | J38: =INTMARB_IN!J38+INTMARB_EX!J38 -> 0 | ... Z38: =INTMARB_IN!Z38+INTMARB_EX!Z38 -> 0
A39: Gasoline-type jet fuel | B39: O4653 | C39: =INTMARB_IN!C39+INTMARB_EX!C39 -> 0 | D39: =INTMARB_IN!D39+INTMARB_EX!D39 -> 0 | E39: =INTMARB_IN!E39+INTMARB_EX!E39 -> 0 | F39: =INTMARB_IN!F39+INTMARB_EX!F39 -> 0 | G39: =INTMARB_IN!G39+INTMARB_EX!G39 -> 0 | H39: =INTMARB_IN!H39+INTMARB_EX!H39 -> 0 | I39: =INTMARB_IN!I39+INTMARB_EX!I39 -> 0 | J39: =INTMARB_IN!J39+INTMARB_EX!J39 -> 0 | ... Z39: =INTMARB_IN!Z39+INTMARB_EX!Z39 -> 0
