Workbook

Sheet cover
B6: JRC-IDEES-2023 - Integrated Database of the European Energy System
C15: Aviation - EU split
L28: Prepared by JRC C.6
L30: 45967.481
L31: v2023-1.00
B33: Legal Notice
B35: The information made available is property of the Joint Research Centre of the European Commission.
B36: Neither the European Commission nor any person acting on behalf of the Commission is responsible for the use which might be made of this information.
B38: Use conditions
B39: This work is licensed under
B40: CC BY 4.0

Sheet EU27
A1: EU27 - European Union - 27 countries (from 2020) | B1: 1990 | C1: 1991 | D1: 1992 | E1: 1993 | F1: 1994 | G1: 1995 | H1: 1996 | I1: 1997 | J1: 1998 | K1: 1999 | L1: 2000 | M1: 2001 | N1: 2002 | O1: 2003 | P1: 2004 | Q1: 2005 | R1: 2006 | S1: 2007 | T1: 2008 | U1: 2009 | V1: 2010 | W1: 2011 | X1: 2012 | Y1: 2013 | Z1: 2014 | AA1: 2015 | AB1: 2016 | AC1: 2017 | AD1: 2018 | AE1: 2019 | AF1: 2020 | AG1: 2021 | AH1: 2022 | AI1: 2023
A3: Transport activity
A4: Passenger transport (mio pkm) | B4: =SUM(B5:B7) -> 412211.97 | C4: =SUM(C5:C7) -> 416852.95 | D4: =SUM(D5:D7) -> 449647.09 | E4: =SUM(E5:E7) -> 469623.28 | F4: =SUM(F5:F7) -> 500981.22 | G4: =SUM(G5:G7) -> 538635.46 | H4: =SUM(H5:H7) -> 572555.33 | I4: =SUM(I5:I7) -> 607981.47 | ... AI4: =SUM(AI5:AI7) -> 1402030.1
A5: Domestic | B5: =AT!B5+BE!B5+BG!B5+CY!B5+CZ!B5+DE!B5+DK!B5+EE!B5+EL!B5+ES!B5+FI!B5+FR!B5+HR!B5+HU!B5+IE!B5+IT!B5+LT!B5+LU!B5+LV!B5+MT!B5+NL!B5+PL!B5+PT!B5+RO!B5+SE!B5+SI!B5+SK!B5 -> 56675.975 | C5: =AT!C5+BE!C5+BG!C5+CY!C5+CZ!C5+DE!C5+DK!C5+EE!C5+EL!C5+ES!C5+FI!C5+FR!C5+HR!C5+HU!C5+IE!C5+IT!C5+LT!C5+LU!C5+LV!C5+MT!C5+NL!C5+PL!C5+PT!C5+RO!C5+SE!C5+SI!C5+SK!C5 -> 57158.692 | D5: =AT!D5+BE!D5+BG!D5+CY!D5+CZ!D5+DE!D5+DK!D5+EE!D5+EL!D5+ES!D5+FI!D5+FR!D5+HR!D5+HU!D5+IE!D5+IT!D5+LT!D5+LU!D5+LV!D5+MT!D5+NL!D5+PL!D5+PT!D5+RO!D5+SE!D5+SI!D5+SK!D5 -> 57375.405 | E5: =AT!E5+BE!E5+BG!E5+CY!E5+CZ!E5+DE!E5+DK!E5+EE!E5+EL!E5+ES!E5+FI!E5+FR!E5+HR!E5+HU!E5+IE!E5+IT!E5+LT!E5+LU!E5+LV!E5+MT!E5+NL!E5+PL!E5+PT!E5+RO!E5+SE!E5+SI!E5+SK!E5 -> 57259.071 | F5: =AT!F5+BE!F5+BG!F5+CY!F5+CZ!F5+DE!F5+DK!F5+EE!F5+EL!F5+ES!F5+FI!F5+FR!F5+HR!F5+HU!F5+IE!F5+IT!F5+LT!F5+LU!F5+LV!F5+MT!F5+NL!F5+PL!F5+PT!F5+RO!F5+SE!F5+SI!F5+SK!F5 -> 54902.733 | G5: =AT!G5+BE!G5+BG!G5+CY!G5+CZ!G5+DE!G5+DK!G5+EE!G5+EL!G5+ES!G5+FI!G5+FR!G5+HR!G5+HU!G5+IE!G5+IT!G5+LT!G5+LU!G5+LV!G5+MT!G5+NL!G5+PL!G5+PT!G5+RO!G5+SE!G5+SI!G5+SK!G5 -> 57599.512 | H5: =AT!H5+BE!H5+BG!H5+CY!H5+CZ!H5+DE!H5+DK!H5+EE!H5+EL!H5+ES!H5+FI!H5+FR!H5+HR!H5+HU!H5+IE!H5+IT!H5+LT!H5+LU!H5+LV!H5+MT!H5+NL!H5+PL!H5+PT!H5+RO!H5+SE!H5+SI!H5+SK!H5 -> 62081.333 | I5: =AT!I5+BE!I5+BG!I5+CY!I5+CZ!I5+DE!I5+DK!I5+EE!I5+EL!I5+ES!I5+FI!I5+FR!I5+HR!I5+HU!I5+IE!I5+IT!I5+LT!I5+LU!I5+LV!I5+MT!I5+NL!I5+PL!I5+PT!I5+RO!I5+SE!I5+SI!I5+SK!I5 -> 65324.417 | ... AI5: =AT!AI5+BE!AI5+BG!AI5+CY!AI5+CZ!AI5+DE!AI5+DK!AI5+EE!AI5+EL!AI5+ES!AI5+FI!AI5+FR!AI5+HR!AI5+HU!AI5+IE!AI5+IT!AI5+LT!AI5+LU!AI5+LV!AI5+MT!AI5+NL!AI5+PL!AI5+PT!AI5+RO!AI5+SE!AI5+SI!AI5+SK!AI5 -> 114163.84
A6: International - Intra-EU27 | B6: =AT!B6+BE!B6+BG!B6+CY!B6+CZ!B6+DE!B6+DK!B6+EE!B6+EL!B6+ES!B6+FI!B6+FR!B6+HR!B6+HU!B6+IE!B6+IT!B6+LT!B6+LU!B6+LV!B6+MT!B6+NL!B6+PL!B6+PT!B6+RO!B6+SE!B6+SI!B6+SK!B6 -> 131107.36 | C6: =AT!C6+BE!C6+BG!C6+CY!C6+CZ!C6+DE!C6+DK!C6+EE!C6+EL!C6+ES!C6+FI!C6+FR!C6+HR!C6+HU!C6+IE!C6+IT!C6+LT!C6+LU!C6+LV!C6+MT!C6+NL!C6+PL!C6+PT!C6+RO!C6+SE!C6+SI!C6+SK!C6 -> 132881.09 | D6: =AT!D6+BE!D6+BG!D6+CY!D6+CZ!D6+DE!D6+DK!D6+EE!D6+EL!D6+ES!D6+FI!D6+FR!D6+HR!D6+HU!D6+IE!D6+IT!D6+LT!D6+LU!D6+LV!D6+MT!D6+NL!D6+PL!D6+PT!D6+RO!D6+SE!D6+SI!D6+SK!D6 -> 144328.97 | E6: =AT!E6+BE!E6+BG!E6+CY!E6+CZ!E6+DE!E6+DK!E6+EE!E6+EL!E6+ES!E6+FI!E6+FR!E6+HR!E6+HU!E6+IE!E6+IT!E6+LT!E6+LU!E6+LV!E6+MT!E6+NL!E6+PL!E6+PT!E6+RO!E6+SE!E6+SI!E6+SK!E6 -> 152776.64 | F6: =AT!F6+BE!F6+BG!F6+CY!F6+CZ!F6+DE!F6+DK!F6+EE!F6+EL!F6+ES!F6+FI!F6+FR!F6+HR!F6+HU!F6+IE!F6+IT!F6+LT!F6+LU!F6+LV!F6+MT!F6+NL!F6+PL!F6+PT!F6+RO!F6+SE!F6+SI!F6+SK!F6 -> 168673.32 | G6: =AT!G6+BE!G6+BG!G6+CY!G6+CZ!G6+DE!G6+DK!G6+EE!G6+EL!G6+ES!G6+FI!G6+FR!G6+HR!G6+HU!G6+IE!G6+IT!G6+LT!G6+LU!G6+LV!G6+MT!G6+NL!G6+PL!G6+PT!G6+RO!G6+SE!G6+SI!G6+SK!G6 -> 179633.09 | H6: =AT!H6+BE!H6+BG!H6+CY!H6+CZ!H6+DE!H6+DK!H6+EE!H6+EL!H6+ES!H6+FI!H6+FR!H6+HR!H6+HU!H6+IE!H6+IT!H6+LT!H6+LU!H6+LV!H6+MT!H6+NL!H6+PL!H6+PT!H6+RO!H6+SE!H6+SI!H6+SK!H6 -> 188864.14 | I6: =AT!I6+BE!I6+BG!I6+CY!I6+CZ!I6+DE!I6+DK!I6+EE!I6+EL!I6+ES!I6+FI!I6+FR!I6+HR!I6+HU!I6+IE!I6+IT!I6+LT!I6+LU!I6+LV!I6+MT!I6+NL!I6+PL!I6+PT!I6+RO!I6+SE!I6+SI!I6+SK!I6 -> 202076.5 | ... AI6: =AT!AI6+BE!AI6+BG!AI6+CY!AI6+CZ!AI6+DE!AI6+DK!AI6+EE!AI6+EL!AI6+ES!AI6+FI!AI6+FR!AI6+HR!AI6+HU!AI6+IE!AI6+IT!AI6+LT!AI6+LU!AI6+LV!AI6+MT!AI6+NL!AI6+PL!AI6+PT!AI6+RO!AI6+SE!AI6+SI!AI6+SK!AI6 -> 467852.04
A7: International - Extra-EU27 | B7: =AT!B7+BE!B7+BG!B7+CY!B7+CZ!B7+DE!B7+DK!B7+EE!B7+EL!B7+ES!B7+FI!B7+FR!B7+HR!B7+HU!B7+IE!B7+IT!B7+LT!B7+LU!B7+LV!B7+MT!B7+NL!B7+PL!B7+PT!B7+RO!B7+SE!B7+SI!B7+SK!B7 -> 224428.64 | C7: =AT!C7+BE!C7+BG!C7+CY!C7+CZ!C7+DE!C7+DK!C7+EE!C7+EL!C7+ES!C7+FI!C7+FR!C7+HR!C7+HU!C7+IE!C7+IT!C7+LT!C7+LU!C7+LV!C7+MT!C7+NL!C7+PL!C7+PT!C7+RO!C7+SE!C7+SI!C7+SK!C7 -> 226813.17 | D7: =AT!D7+BE!D7+BG!D7+CY!D7+CZ!D7+DE!D7+DK!D7+EE!D7+EL!D7+ES!D7+FI!D7+FR!D7+HR!D7+HU!D7+IE!D7+IT!D7+LT!D7+LU!D7+LV!D7+MT!D7+NL!D7+PL!D7+PT!D7+RO!D7+SE!D7+SI!D7+SK!D7 -> 247942.72 | E7: =AT!E7+BE!E7+BG!E7+CY!E7+CZ!E7+DE!E7+DK!E7+EE!E7+EL!E7+ES!E7+FI!E7+FR!E7+HR!E7+HU!E7+IE!E7+IT!E7+LT!E7+LU!E7+LV!E7+MT!E7+NL!E7+PL!E7+PT!E7+RO!E7+SE!E7+SI!E7+SK!E7 -> 259587.57 | F7: =AT!F7+BE!F7+BG!F7+CY!F7+CZ!F7+DE!F7+DK!F7+EE!F7+EL!F7+ES!F7+FI!F7+FR!F7+HR!F7+HU!F7+IE!F7+IT!F7+LT!F7+LU!F7+LV!F7+MT!F7+NL!F7+PL!F7+PT!F7+RO!F7+SE!F7+SI!F7+SK!F7 -> 277405.17 | G7: =AT!G7+BE!G7+BG!G7+CY!G7+CZ!G7+DE!G7+DK!G7+EE!G7+EL!G7+ES!G7+FI!G7+FR!G7+HR!G7+HU!G7+IE!G7+IT!G7+LT!G7+LU!G7+LV!G7+MT!G7+NL!G7+PL!G7+PT!G7+RO!G7+SE!G7+SI!G7+SK!G7 -> 301402.85 | H7: =AT!H7+BE!H7+BG!H7+CY!H7+CZ!H7+DE!H7+DK!H7+EE!H7+EL!H7+ES!H7+FI!H7+FR!H7+HR!H7+HU!H7+IE!H7+IT!H7+LT!H7+LU!H7+LV!H7+MT!H7+NL!H7+PL!H7+PT!H7+RO!H7+SE!H7+SI!H7+SK!H7 -> 321609.86 | I7: =AT!I7+BE!I7+BG!I7+CY!I7+CZ!I7+DE!I7+DK!I7+EE!I7+EL!I7+ES!I7+FI!I7+FR!I7+HR!I7+HU!I7+IE!I7+IT!I7+LT!I7+LU!I7+LV!I7+MT!I7+NL!I7+PL!I7+PT!I7+RO!I7+SE!I7+SI!I7+SK!I7 -> 340580.56 | ... AI7: =AT!AI7+BE!AI7+BG!AI7+CY!AI7+CZ!AI7+DE!AI7+DK!AI7+EE!AI7+EL!AI7+ES!AI7+FI!AI7+FR!AI7+HR!AI7+HU!AI7+IE!AI7+IT!AI7+LT!AI7+LU!AI7+LV!AI7+MT!AI7+NL!AI7+PL!AI7+PT!AI7+RO!AI7+SE!AI7+SI!AI7+SK!AI7 -> 820014.18
A8: Freight transport (mio tkm) | B8: =SUM(B9:B11) -> 13732.097 | C8: =SUM(C9:C11) -> 13594.5 | D8: =SUM(D9:D11) -> 14782.206 | E8: =SUM(E9:E11) -> 15400.717 | F8: =SUM(F9:F11) -> 16943.6 | G8: =SUM(G9:G11) -> 18376.414 | H8: =SUM(H9:H11) -> 18988.637 | I8: =SUM(I9:I11) -> 20450.214 | ... AI8: =SUM(AI9:AI11) -> 42655.471
A9: Domestic | B9: =AT!B9+BE!B9+BG!B9+CY!B9+CZ!B9+DE!B9+DK!B9+EE!B9+EL!B9+ES!B9+FI!B9+FR!B9+HR!B9+HU!B9+IE!B9+IT!B9+LT!B9+LU!B9+LV!B9+MT!B9+NL!B9+PL!B9+PT!B9+RO!B9+SE!B9+SI!B9+SK!B9 -> 352.7666 | C9: =AT!C9+BE!C9+BG!C9+CY!C9+CZ!C9+DE!C9+DK!C9+EE!C9+EL!C9+ES!C9+FI!C9+FR!C9+HR!C9+HU!C9+IE!C9+IT!C9+LT!C9+LU!C9+LV!C9+MT!C9+NL!C9+PL!C9+PT!C9+RO!C9+SE!C9+SI!C9+SK!C9 -> 362.91185 | D9: =AT!D9+BE!D9+BG!D9+CY!D9+CZ!D9+DE!D9+DK!D9+EE!D9+EL!D9+ES!D9+FI!D9+FR!D9+HR!D9+HU!D9+IE!D9+IT!D9+LT!D9+LU!D9+LV!D9+MT!D9+NL!D9+PL!D9+PT!D9+RO!D9+SE!D9+SI!D9+SK!D9 -> 354.9414 | E9: =AT!E9+BE!E9+BG!E9+CY!E9+CZ!E9+DE!E9+DK!E9+EE!E9+EL!E9+ES!E9+FI!E9+FR!E9+HR!E9+HU!E9+IE!E9+IT!E9+LT!E9+LU!E9+LV!E9+MT!E9+NL!E9+PL!E9+PT!E9+RO!E9+SE!E9+SI!E9+SK!E9 -> 359.08441 | F9: =AT!F9+BE!F9+BG!F9+CY!F9+CZ!F9+DE!F9+DK!F9+EE!F9+EL!F9+ES!F9+FI!F9+FR!F9+HR!F9+HU!F9+IE!F9+IT!F9+LT!F9+LU!F9+LV!F9+MT!F9+NL!F9+PL!F9+PT!F9+RO!F9+SE!F9+SI!F9+SK!F9 -> 339.67489 | G9: =AT!G9+BE!G9+BG!G9+CY!G9+CZ!G9+DE!G9+DK!G9+EE!G9+EL!G9+ES!G9+FI!G9+FR!G9+HR!G9+HU!G9+IE!G9+IT!G9+LT!G9+LU!G9+LV!G9+MT!G9+NL!G9+PL!G9+PT!G9+RO!G9+SE!G9+SI!G9+SK!G9 -> 341.8718 | H9: =AT!H9+BE!H9+BG!H9+CY!H9+CZ!H9+DE!H9+DK!H9+EE!H9+EL!H9+ES!H9+FI!H9+FR!H9+HR!H9+HU!H9+IE!H9+IT!H9+LT!H9+LU!H9+LV!H9+MT!H9+NL!H9+PL!H9+PT!H9+RO!H9+SE!H9+SI!H9+SK!H9 -> 364.5384 | I9: =AT!I9+BE!I9+BG!I9+CY!I9+CZ!I9+DE!I9+DK!I9+EE!I9+EL!I9+ES!I9+FI!I9+FR!I9+HR!I9+HU!I9+IE!I9+IT!I9+LT!I9+LU!I9+LV!I9+MT!I9+NL!I9+PL!I9+PT!I9+RO!I9+SE!I9+SI!I9+SK!I9 -> 364.15301 | ... AI9: =AT!AI9+BE!AI9+BG!AI9+CY!AI9+CZ!AI9+DE!AI9+DK!AI9+EE!AI9+EL!AI9+ES!AI9+FI!AI9+FR!AI9+HR!AI9+HU!AI9+IE!AI9+IT!AI9+LT!AI9+LU!AI9+LV!AI9+MT!AI9+NL!AI9+PL!AI9+PT!AI9+RO!AI9+SE!AI9+SI!AI9+SK!AI9 -> 208.10622
A10: International - Intra-EU27 | B10: =AT!B10+BE!B10+BG!B10+CY!B10+CZ!B10+DE!B10+DK!B10+EE!B10+EL!B10+ES!B10+FI!B10+FR!B10+HR!B10+HU!B10+IE!B10+IT!B10+LT!B10+LU!B10+LV!B10+MT!B10+NL!B10+PL!B10+PT!B10+RO!B10+SE!B10+SI!B10+SK!B10 -> 859.21746 | C10: =AT!C10+BE!C10+BG!C10+CY!C10+CZ!C10+DE!C10+DK!C10+EE!C10+EL!C10+ES!C10+FI!C10+FR!C10+HR!C10+HU!C10+IE!C10+IT!C10+LT!C10+LU!C10+LV!C10+MT!C10+NL!C10+PL!C10+PT!C10+RO!C10+SE!C10+SI!C10+SK!C10 -> 840.46493 | D10: =AT!D10+BE!D10+BG!D10+CY!D10+CZ!D10+DE!D10+DK!D10+EE!D10+EL!D10+ES!D10+FI!D10+FR!D10+HR!D10+HU!D10+IE!D10+IT!D10+LT!D10+LU!D10+LV!D10+MT!D10+NL!D10+PL!D10+PT!D10+RO!D10+SE!D10+SI!D10+SK!D10 -> 892.53065 | E10: =AT!E10+BE!E10+BG!E10+CY!E10+CZ!E10+DE!E10+DK!E10+EE!E10+EL!E10+ES!E10+FI!E10+FR!E10+HR!E10+HU!E10+IE!E10+IT!E10+LT!E10+LU!E10+LV!E10+MT!E10+NL!E10+PL!E10+PT!E10+RO!E10+SE!E10+SI!E10+SK!E10 -> 921.64651 | F10: =AT!F10+BE!F10+BG!F10+CY!F10+CZ!F10+DE!F10+DK!F10+EE!F10+EL!F10+ES!F10+FI!F10+FR!F10+HR!F10+HU!F10+IE!F10+IT!F10+LT!F10+LU!F10+LV!F10+MT!F10+NL!F10+PL!F10+PT!F10+RO!F10+SE!F10+SI!F10+SK!F10 -> 1020.7608 | G10: =AT!G10+BE!G10+BG!G10+CY!G10+CZ!G10+DE!G10+DK!G10+EE!G10+EL!G10+ES!G10+FI!G10+FR!G10+HR!G10+HU!G10+IE!G10+IT!G10+LT!G10+LU!G10+LV!G10+MT!G10+NL!G10+PL!G10+PT!G10+RO!G10+SE!G10+SI!G10+SK!G10 -> 1076.3537 | H10: =AT!H10+BE!H10+BG!H10+CY!H10+CZ!H10+DE!H10+DK!H10+EE!H10+EL!H10+ES!H10+FI!H10+FR!H10+HR!H10+HU!H10+IE!H10+IT!H10+LT!H10+LU!H10+LV!H10+MT!H10+NL!H10+PL!H10+PT!H10+RO!H10+SE!H10+SI!H10+SK!H10 -> 1096.2339 | I10: =AT!I10+BE!I10+BG!I10+CY!I10+CZ!I10+DE!I10+DK!I10+EE!I10+EL!I10+ES!I10+FI!I10+FR!I10+HR!I10+HU!I10+IE!I10+IT!I10+LT!I10+LU!I10+LV!I10+MT!I10+NL!I10+PL!I10+PT!I10+RO!I10+SE!I10+SI!I10+SK!I10 -> 1181.7128 | ... AI10: =AT!AI10+BE!AI10+BG!AI10+CY!AI10+CZ!AI10+DE!AI10+DK!AI10+EE!AI10+EL!AI10+ES!AI10+FI!AI10+FR!AI10+HR!AI10+HU!AI10+IE!AI10+IT!AI10+LT!AI10+LU!AI10+LV!AI10+MT!AI10+NL!AI10+PL!AI10+PT!AI10+RO!AI10+SE!AI10+SI!AI10+SK!AI10 -> 1977.958
A11: International - Extra-EU27 | B11: =AT!B11+BE!B11+BG!B11+CY!B11+CZ!B11+DE!B11+DK!B11+EE!B11+EL!B11+ES!B11+FI!B11+FR!B11+HR!B11+HU!B11+IE!B11+IT!B11+LT!B11+LU!B11+LV!B11+MT!B11+NL!B11+PL!B11+PT!B11+RO!B11+SE!B11+SI!B11+SK!B11 -> 12520.113 | C11: =AT!C11+BE!C11+BG!C11+CY!C11+CZ!C11+DE!C11+DK!C11+EE!C11+EL!C11+ES!C11+FI!C11+FR!C11+HR!C11+HU!C11+IE!C11+IT!C11+LT!C11+LU!C11+LV!C11+MT!C11+NL!C11+PL!C11+PT!C11+RO!C11+SE!C11+SI!C11+SK!C11 -> 12391.123 | D11: =AT!D11+BE!D11+BG!D11+CY!D11+CZ!D11+DE!D11+DK!D11+EE!D11+EL!D11+ES!D11+FI!D11+FR!D11+HR!D11+HU!D11+IE!D11+IT!D11+LT!D11+LU!D11+LV!D11+MT!D11+NL!D11+PL!D11+PT!D11+RO!D11+SE!D11+SI!D11+SK!D11 -> 13534.734 | E11: =AT!E11+BE!E11+BG!E11+CY!E11+CZ!E11+DE!E11+DK!E11+EE!E11+EL!E11+ES!E11+FI!E11+FR!E11+HR!E11+HU!E11+IE!E11+IT!E11+LT!E11+LU!E11+LV!E11+MT!E11+NL!E11+PL!E11+PT!E11+RO!E11+SE!E11+SI!E11+SK!E11 -> 14119.986 | F11: =AT!F11+BE!F11+BG!F11+CY!F11+CZ!F11+DE!F11+DK!F11+EE!F11+EL!F11+ES!F11+FI!F11+FR!F11+HR!F11+HU!F11+IE!F11+IT!F11+LT!F11+LU!F11+LV!F11+MT!F11+NL!F11+PL!F11+PT!F11+RO!F11+SE!F11+SI!F11+SK!F11 -> 15583.165 | G11: =AT!G11+BE!G11+BG!G11+CY!G11+CZ!G11+DE!G11+DK!G11+EE!G11+EL!G11+ES!G11+FI!G11+FR!G11+HR!G11+HU!G11+IE!G11+IT!G11+LT!G11+LU!G11+LV!G11+MT!G11+NL!G11+PL!G11+PT!G11+RO!G11+SE!G11+SI!G11+SK!G11 -> 16958.188 | H11: =AT!H11+BE!H11+BG!H11+CY!H11+CZ!H11+DE!H11+DK!H11+EE!H11+EL!H11+ES!H11+FI!H11+FR!H11+HR!H11+HU!H11+IE!H11+IT!H11+LT!H11+LU!H11+LV!H11+MT!H11+NL!H11+PL!H11+PT!H11+RO!H11+SE!H11+SI!H11+SK!H11 -> 17527.864 | I11: =AT!I11+BE!I11+BG!I11+CY!I11+CZ!I11+DE!I11+DK!I11+EE!I11+EL!I11+ES!I11+FI!I11+FR!I11+HR!I11+HU!I11+IE!I11+IT!I11+LT!I11+LU!I11+LV!I11+MT!I11+NL!I11+PL!I11+PT!I11+RO!I11+SE!I11+SI!I11+SK!I11 -> 18904.348 | ... AI11: =AT!AI11+BE!AI11+BG!AI11+CY!AI11+CZ!AI11+DE!AI11+DK!AI11+EE!AI11+EL!AI11+ES!AI11+FI!AI11+FR!AI11+HR!AI11+HU!AI11+IE!AI11+IT!AI11+LT!AI11+LU!AI11+LV!AI11+MT!AI11+NL!AI11+PL!AI11+PT!AI11+RO!AI11+SE!AI11+SI!AI11+SK!AI11 -> 40469.407
A13: Market shares of activity
A14: Passenger transport (% of pkm) | B14: =IF(B4=0,0,B4/B$4) -> 1 | C14: =IF(C4=0,0,C4/C$4) -> 1 | D14: =IF(D4=0,0,D4/D$4) -> 1 | E14: =IF(E4=0,0,E4/E$4) -> 1 | F14: =IF(F4=0,0,F4/F$4) -> 1 | G14: =IF(G4=0,0,G4/G$4) -> 1 | H14: =IF(H4=0,0,H4/H$4) -> 1 | I14: =IF(I4=0,0,I4/I$4) -> 1 | ... AI14: =IF(AI4=0,0,AI4/AI$4) -> 1
A15: Domestic | B15: =IF(B5=0,0,B5/B$4) -> 0.13749231 | C15: =IF(C5=0,0,C5/C$4) -> 0.13711956 | D15: =IF(D5=0,0,D5/D$4) -> 0.12760097 | E15: =IF(E5=0,0,E5/E$4) -> 0.12192554 | F15: =IF(F5=0,0,F5/F$4) -> 0.1095904 | G15: =IF(G5=0,0,G5/G$4) -> 0.10693598 | H15: =IF(H5=0,0,H5/H$4) -> 0.10842853 | I15: =IF(I5=0,0,I5/I$4) -> 0.10744475 | ... AI15: =IF(AI5=0,0,AI5/AI$4) -> 0.08142753
A16: International - Intra-EU27 | B16: =IF(B6=0,0,B6/B$4) -> 0.3180581 | C16: =IF(C6=0,0,C6/C$4) -> 0.3187721 | D16: =IF(D6=0,0,D6/D$4) -> 0.32098277 | E16: =IF(E6=0,0,E6/E$4) -> 0.32531743 | F16: =IF(F6=0,0,F6/F$4) -> 0.33668592 | G16: =IF(G6=0,0,G6/G$4) -> 0.3334966 | H16: =IF(H6=0,0,H6/H$4) -> 0.32986181 | I16: =IF(I6=0,0,I6/I$4) -> 0.33237279 | ... AI16: =IF(AI6=0,0,AI6/AI$4) -> 0.33369615
A17: International - Extra-EU27 | B17: =IF(B7=0,0,B7/B$4) -> 0.54444959 | C17: =IF(C7=0,0,C7/C$4) -> 0.54410834 | D17: =IF(D7=0,0,D7/D$4) -> 0.55141626 | E17: =IF(E7=0,0,E7/E$4) -> 0.55275703 | F17: =IF(F7=0,0,F7/F$4) -> 0.55372368 | G17: =IF(G7=0,0,G7/G$4) -> 0.55956742 | H17: =IF(H7=0,0,H7/H$4) -> 0.56170966 | I17: =IF(I7=0,0,I7/I$4) -> 0.56018247 | ... AI17: =IF(AI7=0,0,AI7/AI$4) -> 0.58487632
A18: Freight transport (% of tkm) | B18: =IF(B8=0,0,B8/B$8) -> 1 | C18: =IF(C8=0,0,C8/C$8) -> 1 | D18: =IF(D8=0,0,D8/D$8) -> 1 | E18: =IF(E8=0,0,E8/E$8) -> 1 | F18: =IF(F8=0,0,F8/F$8) -> 1 | G18: =IF(G8=0,0,G8/G$8) -> 1 | H18: =IF(H8=0,0,H8/H$8) -> 1 | I18: =IF(I8=0,0,I8/I$8) -> 1 | ... AI18: =IF(AI8=0,0,AI8/AI$8) -> 1
A19: Domestic | B19: =IF(B9=0,0,B9/B$8) -> 0.025689201 | C19: =IF(C9=0,0,C9/C$8) -> 0.02669549 | D19: =IF(D9=0,0,D9/D$8) -> 0.024011396 | E19: =IF(E9=0,0,E9/E$8) -> 0.023316084 | F19: =IF(F9=0,0,F9/F$8) -> 0.020047386 | G19: =IF(G9=0,0,G9/G$8) -> 0.018603837 | H19: =IF(H9=0,0,H9/H$8) -> 0.019197713 | I19: =IF(I9=0,0,I9/I$8) -> 0.017806807 | ... AI19: =IF(AI9=0,0,AI9/AI$8) -> 0.0048787696
A20: International - Intra-EU27 | B20: =IF(B10=0,0,B10/B$8) -> 0.062570012 | C20: =IF(C10=0,0,C10/C$8) -> 0.061823893 | D20: =IF(D10=0,0,D10/D$8) -> 0.060378718 | E20: =IF(E10=0,0,E10/E$8) -> 0.059844389 | F20: =IF(F10=0,0,F10/F$8) -> 0.060244625 | G20: =IF(G10=0,0,G10/G$8) -> 0.058572566 | H20: =IF(H10=0,0,H10/H$8) -> 0.057731047 | I20: =IF(I10=0,0,I10/I$8) -> 0.057784863 | ... AI20: =IF(AI10=0,0,AI10/AI$8) -> 0.046370558
A21: International - Extra-EU27 | B21: =IF(B11=0,0,B11/B$8) -> 0.91174079 | C21: =IF(C11=0,0,C11/C$8) -> 0.91148062 | D21: =IF(D11=0,0,D11/D$8) -> 0.91560989 | E21: =IF(E11=0,0,E11/E$8) -> 0.91683953 | F21: =IF(F11=0,0,F11/F$8) -> 0.91970799 | G21: =IF(G11=0,0,G11/G$8) -> 0.9228236 | H21: =IF(H11=0,0,H11/H$8) -> 0.92307124 | I21: =IF(I11=0,0,I11/I$8) -> 0.92440833 | ... AI21: =IF(AI11=0,0,AI11/AI$8) -> 0.94875067
A23: Vehicle-km (mio km) | B23: =SUM(B24,B28) -> 3845.5232 | C23: =SUM(C24,C28) -> 3871.2115 | D23: =SUM(D24,D28) -> 4119.5692 | E23: =SUM(E24,E28) -> 4259.9742 | F23: =SUM(F24,F28) -> 4497.7072 | G23: =SUM(G24,G28) -> 4800.9102 | H23: =SUM(H24,H28) -> 5031.4561 | I23: =SUM(I24,I28) -> 5271.0634 | ... AI23: =SUM(AI24,AI28) -> 8822.1845
A24: Passenger transport | B24: =SUM(B25:B27) -> 3618.4811 | C24: =SUM(C25:C27) -> 3644.8001 | D24: =SUM(D25:D27) -> 3878.3426 | E24: =SUM(E25:E27) -> 4014.8915 | F24: =SUM(F25:F27) -> 4233.8345 | G24: =SUM(G25:G27) -> 4516.6171 | H24: =SUM(H25:H27) -> 4732.235 | I24: =SUM(I25:I27) -> 4955.2768 | ... AI24: =SUM(AI25:AI27) -> 8190.0104
A25: Domestic | B25: =AT!B25+BE!B25+BG!B25+CY!B25+CZ!B25+DE!B25+DK!B25+EE!B25+EL!B25+ES!B25+FI!B25+FR!B25+HR!B25+HU!B25+IE!B25+IT!B25+LT!B25+LU!B25+LV!B25+MT!B25+NL!B25+PL!B25+PT!B25+RO!B25+SE!B25+SI!B25+SK!B25 -> 779.16471 | C25: =AT!C25+BE!C25+BG!C25+CY!C25+CZ!C25+DE!C25+DK!C25+EE!C25+EL!C25+ES!C25+FI!C25+FR!C25+HR!C25+HU!C25+IE!C25+IT!C25+LT!C25+LU!C25+LV!C25+MT!C25+NL!C25+PL!C25+PT!C25+RO!C25+SE!C25+SI!C25+SK!C25 -> 795.66529 | D25: =AT!D25+BE!D25+BG!D25+CY!D25+CZ!D25+DE!D25+DK!D25+EE!D25+EL!D25+ES!D25+FI!D25+FR!D25+HR!D25+HU!D25+IE!D25+IT!D25+LT!D25+LU!D25+LV!D25+MT!D25+NL!D25+PL!D25+PT!D25+RO!D25+SE!D25+SI!D25+SK!D25 -> 792.90111 | E25: =AT!E25+BE!E25+BG!E25+CY!E25+CZ!E25+DE!E25+DK!E25+EE!E25+EL!E25+ES!E25+FI!E25+FR!E25+HR!E25+HU!E25+IE!E25+IT!E25+LT!E25+LU!E25+LV!E25+MT!E25+NL!E25+PL!E25+PT!E25+RO!E25+SE!E25+SI!E25+SK!E25 -> 794.66805 | F25: =AT!F25+BE!F25+BG!F25+CY!F25+CZ!F25+DE!F25+DK!F25+EE!F25+EL!F25+ES!F25+FI!F25+FR!F25+HR!F25+HU!F25+IE!F25+IT!F25+LT!F25+LU!F25+LV!F25+MT!F25+NL!F25+PL!F25+PT!F25+RO!F25+SE!F25+SI!F25+SK!F25 -> 762.96248 | G25: =AT!G25+BE!G25+BG!G25+CY!G25+CZ!G25+DE!G25+DK!G25+EE!G25+EL!G25+ES!G25+FI!G25+FR!G25+HR!G25+HU!G25+IE!G25+IT!G25+LT!G25+LU!G25+LV!G25+MT!G25+NL!G25+PL!G25+PT!G25+RO!G25+SE!G25+SI!G25+SK!G25 -> 791.1611 | H25: =AT!H25+BE!H25+BG!H25+CY!H25+CZ!H25+DE!H25+DK!H25+EE!H25+EL!H25+ES!H25+FI!H25+FR!H25+HR!H25+HU!H25+IE!H25+IT!H25+LT!H25+LU!H25+LV!H25+MT!H25+NL!H25+PL!H25+PT!H25+RO!H25+SE!H25+SI!H25+SK!H25 -> 842.64176 | I25: =AT!I25+BE!I25+BG!I25+CY!I25+CZ!I25+DE!I25+DK!I25+EE!I25+EL!I25+ES!I25+FI!I25+FR!I25+HR!I25+HU!I25+IE!I25+IT!I25+LT!I25+LU!I25+LV!I25+MT!I25+NL!I25+PL!I25+PT!I25+RO!I25+SE!I25+SI!I25+SK!I25 -> 880.91075 | ... AI25: =AT!AI25+BE!AI25+BG!AI25+CY!AI25+CZ!AI25+DE!AI25+DK!AI25+EE!AI25+EL!AI25+ES!AI25+FI!AI25+FR!AI25+HR!AI25+HU!AI25+IE!AI25+IT!AI25+LT!AI25+LU!AI25+LV!AI25+MT!AI25+NL!AI25+PL!AI25+PT!AI25+RO!AI25+SE!AI25+SI!AI25+SK!AI25 -> 878.08462
A26: International - Intra-EU27 | B26: =AT!B26+BE!B26+BG!B26+CY!B26+CZ!B26+DE!B26+DK!B26+EE!B26+EL!B26+ES!B26+FI!B26+FR!B26+HR!B26+HU!B26+IE!B26+IT!B26+LT!B26+LU!B26+LV!B26+MT!B26+NL!B26+PL!B26+PT!B26+RO!B26+SE!B26+SI!B26+SK!B26 -> 1252.0761 | C26: =AT!C26+BE!C26+BG!C26+CY!C26+CZ!C26+DE!C26+DK!C26+EE!C26+EL!C26+ES!C26+FI!C26+FR!C26+HR!C26+HU!C26+IE!C26+IT!C26+LT!C26+LU!C26+LV!C26+MT!C26+NL!C26+PL!C26+PT!C26+RO!C26+SE!C26+SI!C26+SK!C26 -> 1258.024 | D26: =AT!D26+BE!D26+BG!D26+CY!D26+CZ!D26+DE!D26+DK!D26+EE!D26+EL!D26+ES!D26+FI!D26+FR!D26+HR!D26+HU!D26+IE!D26+IT!D26+LT!D26+LU!D26+LV!D26+MT!D26+NL!D26+PL!D26+PT!D26+RO!D26+SE!D26+SI!D26+SK!D26 -> 1349.0145 | E26: =AT!E26+BE!E26+BG!E26+CY!E26+CZ!E26+DE!E26+DK!E26+EE!E26+EL!E26+ES!E26+FI!E26+FR!E26+HR!E26+HU!E26+IE!E26+IT!E26+LT!E26+LU!E26+LV!E26+MT!E26+NL!E26+PL!E26+PT!E26+RO!E26+SE!E26+SI!E26+SK!E26 -> 1413.4321 | F26: =AT!F26+BE!F26+BG!F26+CY!F26+CZ!F26+DE!F26+DK!F26+EE!F26+EL!F26+ES!F26+FI!F26+FR!F26+HR!F26+HU!F26+IE!F26+IT!F26+LT!F26+LU!F26+LV!F26+MT!F26+NL!F26+PL!F26+PT!F26+RO!F26+SE!F26+SI!F26+SK!F26 -> 1539.2225 | G26: =AT!G26+BE!G26+BG!G26+CY!G26+CZ!G26+DE!G26+DK!G26+EE!G26+EL!G26+ES!G26+FI!G26+FR!G26+HR!G26+HU!G26+IE!G26+IT!G26+LT!G26+LU!G26+LV!G26+MT!G26+NL!G26+PL!G26+PT!G26+RO!G26+SE!G26+SI!G26+SK!G26 -> 1640.5706 | H26: =AT!H26+BE!H26+BG!H26+CY!H26+CZ!H26+DE!H26+DK!H26+EE!H26+EL!H26+ES!H26+FI!H26+FR!H26+HR!H26+HU!H26+IE!H26+IT!H26+LT!H26+LU!H26+LV!H26+MT!H26+NL!H26+PL!H26+PT!H26+RO!H26+SE!H26+SI!H26+SK!H26 -> 1687.8005 | I26: =AT!I26+BE!I26+BG!I26+CY!I26+CZ!I26+DE!I26+DK!I26+EE!I26+EL!I26+ES!I26+FI!I26+FR!I26+HR!I26+HU!I26+IE!I26+IT!I26+LT!I26+LU!I26+LV!I26+MT!I26+NL!I26+PL!I26+PT!I26+RO!I26+SE!I26+SI!I26+SK!I26 -> 1765.6105 | ... AI26: =AT!AI26+BE!AI26+BG!AI26+CY!AI26+CZ!AI26+DE!AI26+DK!AI26+EE!AI26+EL!AI26+ES!AI26+FI!AI26+FR!AI26+HR!AI26+HU!AI26+IE!AI26+IT!AI26+LT!AI26+LU!AI26+LV!AI26+MT!AI26+NL!AI26+PL!AI26+PT!AI26+RO!AI26+SE!AI26+SI!AI26+SK!AI26 -> 3245.8154
A27: International - Extra-EU27 | B27: =AT!B27+BE!B27+BG!B27+CY!B27+CZ!B27+DE!B27+DK!B27+EE!B27+EL!B27+ES!B27+FI!B27+FR!B27+HR!B27+HU!B27+IE!B27+IT!B27+LT!B27+LU!B27+LV!B27+MT!B27+NL!B27+PL!B27+PT!B27+RO!B27+SE!B27+SI!B27+SK!B27 -> 1587.2403 | C27: =AT!C27+BE!C27+BG!C27+CY!C27+CZ!C27+DE!C27+DK!C27+EE!C27+EL!C27+ES!C27+FI!C27+FR!C27+HR!C27+HU!C27+IE!C27+IT!C27+LT!C27+LU!C27+LV!C27+MT!C27+NL!C27+PL!C27+PT!C27+RO!C27+SE!C27+SI!C27+SK!C27 -> 1591.1108 | D27: =AT!D27+BE!D27+BG!D27+CY!D27+CZ!D27+DE!D27+DK!D27+EE!D27+EL!D27+ES!D27+FI!D27+FR!D27+HR!D27+HU!D27+IE!D27+IT!D27+LT!D27+LU!D27+LV!D27+MT!D27+NL!D27+PL!D27+PT!D27+RO!D27+SE!D27+SI!D27+SK!D27 -> 1736.427 | E27: =AT!E27+BE!E27+BG!E27+CY!E27+CZ!E27+DE!E27+DK!E27+EE!E27+EL!E27+ES!E27+FI!E27+FR!E27+HR!E27+HU!E27+IE!E27+IT!E27+LT!E27+LU!E27+LV!E27+MT!E27+NL!E27+PL!E27+PT!E27+RO!E27+SE!E27+SI!E27+SK!E27 -> 1806.7914 | F27: =AT!F27+BE!F27+BG!F27+CY!F27+CZ!F27+DE!F27+DK!F27+EE!F27+EL!F27+ES!F27+FI!F27+FR!F27+HR!F27+HU!F27+IE!F27+IT!F27+LT!F27+LU!F27+LV!F27+MT!F27+NL!F27+PL!F27+PT!F27+RO!F27+SE!F27+SI!F27+SK!F27 -> 1931.6496 | G27: =AT!G27+BE!G27+BG!G27+CY!G27+CZ!G27+DE!G27+DK!G27+EE!G27+EL!G27+ES!G27+FI!G27+FR!G27+HR!G27+HU!G27+IE!G27+IT!G27+LT!G27+LU!G27+LV!G27+MT!G27+NL!G27+PL!G27+PT!G27+RO!G27+SE!G27+SI!G27+SK!G27 -> 2084.8855 | H27: =AT!H27+BE!H27+BG!H27+CY!H27+CZ!H27+DE!H27+DK!H27+EE!H27+EL!H27+ES!H27+FI!H27+FR!H27+HR!H27+HU!H27+IE!H27+IT!H27+LT!H27+LU!H27+LV!H27+MT!H27+NL!H27+PL!H27+PT!H27+RO!H27+SE!H27+SI!H27+SK!H27 -> 2201.7928 | I27: =AT!I27+BE!I27+BG!I27+CY!I27+CZ!I27+DE!I27+DK!I27+EE!I27+EL!I27+ES!I27+FI!I27+FR!I27+HR!I27+HU!I27+IE!I27+IT!I27+LT!I27+LU!I27+LV!I27+MT!I27+NL!I27+PL!I27+PT!I27+RO!I27+SE!I27+SI!I27+SK!I27 -> 2308.7556 | ... AI27: =AT!AI27+BE!AI27+BG!AI27+CY!AI27+CZ!AI27+DE!AI27+DK!AI27+EE!AI27+EL!AI27+ES!AI27+FI!AI27+FR!AI27+HR!AI27+HU!AI27+IE!AI27+IT!AI27+LT!AI27+LU!AI27+LV!AI27+MT!AI27+NL!AI27+PL!AI27+PT!AI27+RO!AI27+SE!AI27+SI!AI27+SK!AI27 -> 4066.1104
A28: Freight transport | B28: =SUM(B29:B31) -> 227.04208 | C28: =SUM(C29:C31) -> 226.41141 | D28: =SUM(D29:D31) -> 241.22662 | E28: =SUM(E29:E31) -> 245.08269 | F28: =SUM(F29:F31) -> 263.87271 | G28: =SUM(G29:G31) -> 284.29302 | H28: =SUM(H29:H31) -> 299.22109 | I28: =SUM(I29:I31) -> 315.78656 | ... AI28: =SUM(AI29:AI31) -> 632.17403
A29: Domestic | B29: =AT!B29+BE!B29+BG!B29+CY!B29+CZ!B29+DE!B29+DK!B29+EE!B29+EL!B29+ES!B29+FI!B29+FR!B29+HR!B29+HU!B29+IE!B29+IT!B29+LT!B29+LU!B29+LV!B29+MT!B29+NL!B29+PL!B29+PT!B29+RO!B29+SE!B29+SI!B29+SK!B29 -> 33.376259 | C29: =AT!C29+BE!C29+BG!C29+CY!C29+CZ!C29+DE!C29+DK!C29+EE!C29+EL!C29+ES!C29+FI!C29+FR!C29+HR!C29+HU!C29+IE!C29+IT!C29+LT!C29+LU!C29+LV!C29+MT!C29+NL!C29+PL!C29+PT!C29+RO!C29+SE!C29+SI!C29+SK!C29 -> 34.765761 | D29: =AT!D29+BE!D29+BG!D29+CY!D29+CZ!D29+DE!D29+DK!D29+EE!D29+EL!D29+ES!D29+FI!D29+FR!D29+HR!D29+HU!D29+IE!D29+IT!D29+LT!D29+LU!D29+LV!D29+MT!D29+NL!D29+PL!D29+PT!D29+RO!D29+SE!D29+SI!D29+SK!D29 -> 33.260461 | E29: =AT!E29+BE!E29+BG!E29+CY!E29+CZ!E29+DE!E29+DK!E29+EE!E29+EL!E29+ES!E29+FI!E29+FR!E29+HR!E29+HU!E29+IE!E29+IT!E29+LT!E29+LU!E29+LV!E29+MT!E29+NL!E29+PL!E29+PT!E29+RO!E29+SE!E29+SI!E29+SK!E29 -> 33.358359 | F29: =AT!F29+BE!F29+BG!F29+CY!F29+CZ!F29+DE!F29+DK!F29+EE!F29+EL!F29+ES!F29+FI!F29+FR!F29+HR!F29+HU!F29+IE!F29+IT!F29+LT!F29+LU!F29+LV!F29+MT!F29+NL!F29+PL!F29+PT!F29+RO!F29+SE!F29+SI!F29+SK!F29 -> 30.824103 | G29: =AT!G29+BE!G29+BG!G29+CY!G29+CZ!G29+DE!G29+DK!G29+EE!G29+EL!G29+ES!G29+FI!G29+FR!G29+HR!G29+HU!G29+IE!G29+IT!G29+LT!G29+LU!G29+LV!G29+MT!G29+NL!G29+PL!G29+PT!G29+RO!G29+SE!G29+SI!G29+SK!G29 -> 30.661033 | H29: =AT!H29+BE!H29+BG!H29+CY!H29+CZ!H29+DE!H29+DK!H29+EE!H29+EL!H29+ES!H29+FI!H29+FR!H29+HR!H29+HU!H29+IE!H29+IT!H29+LT!H29+LU!H29+LV!H29+MT!H29+NL!H29+PL!H29+PT!H29+RO!H29+SE!H29+SI!H29+SK!H29 -> 32.691547 | I29: =AT!I29+BE!I29+BG!I29+CY!I29+CZ!I29+DE!I29+DK!I29+EE!I29+EL!I29+ES!I29+FI!I29+FR!I29+HR!I29+HU!I29+IE!I29+IT!I29+LT!I29+LU!I29+LV!I29+MT!I29+NL!I29+PL!I29+PT!I29+RO!I29+SE!I29+SI!I29+SK!I29 -> 31.972972 | ... AI29: =AT!AI29+BE!AI29+BG!AI29+CY!AI29+CZ!AI29+DE!AI29+DK!AI29+EE!AI29+EL!AI29+ES!AI29+FI!AI29+FR!AI29+HR!AI29+HU!AI29+IE!AI29+IT!AI29+LT!AI29+LU!AI29+LV!AI29+MT!AI29+NL!AI29+PL!AI29+PT!AI29+RO!AI29+SE!AI29+SI!AI29+SK!AI29 -> 13.11108
A30: International - Intra-EU27 | B30: =AT!B30+BE!B30+BG!B30+CY!B30+CZ!B30+DE!B30+DK!B30+EE!B30+EL!B30+ES!B30+FI!B30+FR!B30+HR!B30+HU!B30+IE!B30+IT!B30+LT!B30+LU!B30+LV!B30+MT!B30+NL!B30+PL!B30+PT!B30+RO!B30+SE!B30+SI!B30+SK!B30 -> 28.508969 | C30: =AT!C30+BE!C30+BG!C30+CY!C30+CZ!C30+DE!C30+DK!C30+EE!C30+EL!C30+ES!C30+FI!C30+FR!C30+HR!C30+HU!C30+IE!C30+IT!C30+LT!C30+LU!C30+LV!C30+MT!C30+NL!C30+PL!C30+PT!C30+RO!C30+SE!C30+SI!C30+SK!C30 -> 27.908984 | D30: =AT!D30+BE!D30+BG!D30+CY!D30+CZ!D30+DE!D30+DK!D30+EE!D30+EL!D30+ES!D30+FI!D30+FR!D30+HR!D30+HU!D30+IE!D30+IT!D30+LT!D30+LU!D30+LV!D30+MT!D30+NL!D30+PL!D30+PT!D30+RO!D30+SE!D30+SI!D30+SK!D30 -> 29.664238 | E30: =AT!E30+BE!E30+BG!E30+CY!E30+CZ!E30+DE!E30+DK!E30+EE!E30+EL!E30+ES!E30+FI!E30+FR!E30+HR!E30+HU!E30+IE!E30+IT!E30+LT!E30+LU!E30+LV!E30+MT!E30+NL!E30+PL!E30+PT!E30+RO!E30+SE!E30+SI!E30+SK!E30 -> 30.005413 | F30: =AT!F30+BE!F30+BG!F30+CY!F30+CZ!F30+DE!F30+DK!F30+EE!F30+EL!F30+ES!F30+FI!F30+FR!F30+HR!F30+HU!F30+IE!F30+IT!F30+LT!F30+LU!F30+LV!F30+MT!F30+NL!F30+PL!F30+PT!F30+RO!F30+SE!F30+SI!F30+SK!F30 -> 33.065229 | G30: =AT!G30+BE!G30+BG!G30+CY!G30+CZ!G30+DE!G30+DK!G30+EE!G30+EL!G30+ES!G30+FI!G30+FR!G30+HR!G30+HU!G30+IE!G30+IT!G30+LT!G30+LU!G30+LV!G30+MT!G30+NL!G30+PL!G30+PT!G30+RO!G30+SE!G30+SI!G30+SK!G30 -> 34.870933 | H30: =AT!H30+BE!H30+BG!H30+CY!H30+CZ!H30+DE!H30+DK!H30+EE!H30+EL!H30+ES!H30+FI!H30+FR!H30+HR!H30+HU!H30+IE!H30+IT!H30+LT!H30+LU!H30+LV!H30+MT!H30+NL!H30+PL!H30+PT!H30+RO!H30+SE!H30+SI!H30+SK!H30 -> 36.566987 | I30: =AT!I30+BE!I30+BG!I30+CY!I30+CZ!I30+DE!I30+DK!I30+EE!I30+EL!I30+ES!I30+FI!I30+FR!I30+HR!I30+HU!I30+IE!I30+IT!I30+LT!I30+LU!I30+LV!I30+MT!I30+NL!I30+PL!I30+PT!I30+RO!I30+SE!I30+SI!I30+SK!I30 -> 38.918247 | ... AI30: =AT!AI30+BE!AI30+BG!AI30+CY!AI30+CZ!AI30+DE!AI30+DK!AI30+EE!AI30+EL!AI30+ES!AI30+FI!AI30+FR!AI30+HR!AI30+HU!AI30+IE!AI30+IT!AI30+LT!AI30+LU!AI30+LV!AI30+MT!AI30+NL!AI30+PL!AI30+PT!AI30+RO!AI30+SE!AI30+SI!AI30+SK!AI30 -> 87.422882
A31: International - Extra-EU27 | B31: =AT!B31+BE!B31+BG!B31+CY!B31+CZ!B31+DE!B31+DK!B31+EE!B31+EL!B31+ES!B31+FI!B31+FR!B31+HR!B31+HU!B31+IE!B31+IT!B31+LT!B31+LU!B31+LV!B31+MT!B31+NL!B31+PL!B31+PT!B31+RO!B31+SE!B31+SI!B31+SK!B31 -> 165.15685 | C31: =AT!C31+BE!C31+BG!C31+CY!C31+CZ!C31+DE!C31+DK!C31+EE!C31+EL!C31+ES!C31+FI!C31+FR!C31+HR!C31+HU!C31+IE!C31+IT!C31+LT!C31+LU!C31+LV!C31+MT!C31+NL!C31+PL!C31+PT!C31+RO!C31+SE!C31+SI!C31+SK!C31 -> 163.73666 | D31: =AT!D31+BE!D31+BG!D31+CY!D31+CZ!D31+DE!D31+DK!D31+EE!D31+EL!D31+ES!D31+FI!D31+FR!D31+HR!D31+HU!D31+IE!D31+IT!D31+LT!D31+LU!D31+LV!D31+MT!D31+NL!D31+PL!D31+PT!D31+RO!D31+SE!D31+SI!D31+SK!D31 -> 178.30192 | E31: =AT!E31+BE!E31+BG!E31+CY!E31+CZ!E31+DE!E31+DK!E31+EE!E31+EL!E31+ES!E31+FI!E31+FR!E31+HR!E31+HU!E31+IE!E31+IT!E31+LT!E31+LU!E31+LV!E31+MT!E31+NL!E31+PL!E31+PT!E31+RO!E31+SE!E31+SI!E31+SK!E31 -> 181.71892 | F31: =AT!F31+BE!F31+BG!F31+CY!F31+CZ!F31+DE!F31+DK!F31+EE!F31+EL!F31+ES!F31+FI!F31+FR!F31+HR!F31+HU!F31+IE!F31+IT!F31+LT!F31+LU!F31+LV!F31+MT!F31+NL!F31+PL!F31+PT!F31+RO!F31+SE!F31+SI!F31+SK!F31 -> 199.98338 | G31: =AT!G31+BE!G31+BG!G31+CY!G31+CZ!G31+DE!G31+DK!G31+EE!G31+EL!G31+ES!G31+FI!G31+FR!G31+HR!G31+HU!G31+IE!G31+IT!G31+LT!G31+LU!G31+LV!G31+MT!G31+NL!G31+PL!G31+PT!G31+RO!G31+SE!G31+SI!G31+SK!G31 -> 218.76106 | H31: =AT!H31+BE!H31+BG!H31+CY!H31+CZ!H31+DE!H31+DK!H31+EE!H31+EL!H31+ES!H31+FI!H31+FR!H31+HR!H31+HU!H31+IE!H31+IT!H31+LT!H31+LU!H31+LV!H31+MT!H31+NL!H31+PL!H31+PT!H31+RO!H31+SE!H31+SI!H31+SK!H31 -> 229.96255 | I31: =AT!I31+BE!I31+BG!I31+CY!I31+CZ!I31+DE!I31+DK!I31+EE!I31+EL!I31+ES!I31+FI!I31+FR!I31+HR!I31+HU!I31+IE!I31+IT!I31+LT!I31+LU!I31+LV!I31+MT!I31+NL!I31+PL!I31+PT!I31+RO!I31+SE!I31+SI!I31+SK!I31 -> 244.89535 | ... AI31: =AT!AI31+BE!AI31+BG!AI31+CY!AI31+CZ!AI31+DE!AI31+DK!AI31+EE!AI31+EL!AI31+ES!AI31+FI!AI31+FR!AI31+HR!AI31+HU!AI31+IE!AI31+IT!AI31+LT!AI31+LU!AI31+LV!AI31+MT!AI31+NL!AI31+PL!AI31+PT!AI31+RO!AI31+SE!AI31+SI!AI31+SK!AI31 -> 531.64007
A33: Market shares of vehicle km (% of km)
A34: Passenger transport | B34: =IF(B24=0,0,B24/B$24) -> 1 | C34: =IF(C24=0,0,C24/C$24) -> 1 | D34: =IF(D24=0,0,D24/D$24) -> 1 | E34: =IF(E24=0,0,E24/E$24) -> 1 | F34: =IF(F24=0,0,F24/F$24) -> 1 | G34: =IF(G24=0,0,G24/G$24) -> 1 | H34: =IF(H24=0,0,H24/H$24) -> 1 | I34: =IF(I24=0,0,I24/I$24) -> 1 | ... AI34: =IF(AI24=0,0,AI24/AI$24) -> 1
A35: Domestic | B35: =IF(B25=0,0,B25/B$24) -> 0.21532922 | C35: =IF(C25=0,0,C25/C$24) -> 0.21830149 | D35: =IF(D25=0,0,D25/D$24) -> 0.20444329 | E35: =IF(E25=0,0,E25/E$24) -> 0.19793014 | F35: =IF(F25=0,0,F25/F$24) -> 0.18020602 | G35: =IF(G25=0,0,G25/G$24) -> 0.17516674 | H35: =IF(H25=0,0,H25/H$24) -> 0.17806422 | I35: =IF(I25=0,0,I25/I$24) -> 0.17777226 | ... AI35: =IF(AI25=0,0,AI25/AI$24) -> 0.1072141
A36: International - Intra-EU27 | B36: =IF(B26=0,0,B26/B$24) -> 0.34602257 | C36: =IF(C26=0,0,C26/C$24) -> 0.34515583 | D36: =IF(D26=0,0,D26/D$24) -> 0.34783274 | E36: =IF(E26=0,0,E26/E$24) -> 0.35204739 | F36: =IF(F26=0,0,F26/F$24) -> 0.36355282 | G36: =IF(G26=0,0,G26/G$24) -> 0.36322994 | H36: =IF(H26=0,0,H26/H$24) -> 0.35666032 | I36: =IF(I26=0,0,I26/I$24) -> 0.35630916 | ... AI36: =IF(AI26=0,0,AI26/AI$24) -> 0.39631395
A37: International - Extra-EU27 | B37: =IF(B27=0,0,B27/B$24) -> 0.43864821 | C37: =IF(C27=0,0,C27/C$24) -> 0.43654268 | D37: =IF(D27=0,0,D27/D$24) -> 0.44772397 | E37: =IF(E27=0,0,E27/E$24) -> 0.45002247 | F37: =IF(F27=0,0,F27/F$24) -> 0.45624116 | G37: =IF(G27=0,0,G27/G$24) -> 0.46160332 | H37: =IF(H27=0,0,H27/H$24) -> 0.46527545 | I37: =IF(I27=0,0,I27/I$24) -> 0.46591858 | ... AI37: =IF(AI27=0,0,AI27/AI$24) -> 0.49647195
A38: Freight transport | B38: =IF(B28=0,0,B28/B$28) -> 1 | C38: =IF(C28=0,0,C28/C$28) -> 1 | D38: =IF(D28=0,0,D28/D$28) -> 1 | E38: =IF(E28=0,0,E28/E$28) -> 1 | F38: =IF(F28=0,0,F28/F$28) -> 1 | G38: =IF(G28=0,0,G28/G$28) -> 1 | H38: =IF(H28=0,0,H28/H$28) -> 1 | I38: =IF(I28=0,0,I28/I$28) -> 1 | ... AI38: =IF(AI28=0,0,AI28/AI$28) -> 1
A39: Domestic | B39: =IF(B29=0,0,B29/B$28) -> 0.14700473 | C39: =IF(C29=0,0,C29/C$28) -> 0.15355128 | D39: =IF(D29=0,0,D29/D$28) -> 0.13788056 | E39: =IF(E29=0,0,E29/E$28) -> 0.13611063 | F39: =IF(F29=0,0,F29/F$28) -> 0.11681429 | G39: =IF(G29=0,0,G29/G$28) -> 0.10785011 | H39: =IF(H29=0,0,H29/H$28) -> 0.10925549 | I39: =IF(I29=0,0,I29/I$28) -> 0.10124868 | ... AI39: =IF(AI29=0,0,AI29/AI$28) -> 0.020739668
A40: International - Intra-EU27 | B40: =IF(B30=0,0,B30/B$28) -> 0.1255669 | C40: =IF(C30=0,0,C30/C$28) -> 0.12326669 | D40: =IF(D30=0,0,D30/D$28) -> 0.12297249 | E40: =IF(E30=0,0,E30/E$28) -> 0.12242975 | F40: =IF(F30=0,0,F30/F$28) -> 0.1253075 | G40: =IF(G30=0,0,G30/G$28) -> 0.12265842 | H40: =IF(H30=0,0,H30/H$28) -> 0.12220725 | I40: =IF(I30=0,0,I30/I$28) -> 0.12324225 | ... AI40: =IF(AI30=0,0,AI30/AI$28) -> 0.13828927
A41: International - Extra-EU27 | B41: =IF(B31=0,0,B31/B$28) -> 0.72742837 | C41: =IF(C31=0,0,C31/C$28) -> 0.72318204 | D41: =IF(D31=0,0,D31/D$28) -> 0.73914695 | E41: =IF(E31=0,0,E31/E$28) -> 0.74145962 | F41: =IF(F31=0,0,F31/F$28) -> 0.75787822 | G41: =IF(G31=0,0,G31/G$28) -> 0.76949147 | H41: =IF(H31=0,0,H31/H$28) -> 0.76853726 | I41: =IF(I31=0,0,I31/I$28) -> 0.77550907 | ... AI41: =IF(AI31=0,0,AI31/AI$28) -> 0.84097107
A43: Number of departing flights | B43: =SUM(B44,B48) -> 3269983 | C43: =SUM(C44,C48) -> 3284650 | D43: =SUM(D44,D48) -> 3391719 | E43: =SUM(E44,E48) -> 3493244 | F43: =SUM(F44,F48) -> 3589945 | G43: =SUM(G44,G48) -> 3803425 | H43: =SUM(H44,H48) -> 3975132 | I43: =SUM(I44,I48) -> 4160688 | ... AI43: =SUM(AI44,AI48) -> 5425889
A44: Passenger transport | B44: =SUM(B45:B47) -> 3137677 | C44: =SUM(C45:C47) -> 3152322 | D44: =SUM(D45:D47) -> 3258711 | E44: =SUM(E45:E47) -> 3358946 | F44: =SUM(F45:F47) -> 3452967 | G44: =SUM(G45:G47) -> 3660093 | H44: =SUM(H45:H47) -> 3824216 | I44: =SUM(I45:I47) -> 4005309 | ... AI44: =SUM(AI45:AI47) -> 5204436
A45: Domestic | B45: =AT!B45+BE!B45+BG!B45+CY!B45+CZ!B45+DE!B45+DK!B45+EE!B45+EL!B45+ES!B45+FI!B45+FR!B45+HR!B45+HU!B45+IE!B45+IT!B45+LT!B45+LU!B45+LV!B45+MT!B45+NL!B45+PL!B45+PT!B45+RO!B45+SE!B45+SI!B45+SK!B45 -> 1397285 | C45: =AT!C45+BE!C45+BG!C45+CY!C45+CZ!C45+DE!C45+DK!C45+EE!C45+EL!C45+ES!C45+FI!C45+FR!C45+HR!C45+HU!C45+IE!C45+IT!C45+LT!C45+LU!C45+LV!C45+MT!C45+NL!C45+PL!C45+PT!C45+RO!C45+SE!C45+SI!C45+SK!C45 -> 1413962 | D45: =AT!D45+BE!D45+BG!D45+CY!D45+CZ!D45+DE!D45+DK!D45+EE!D45+EL!D45+ES!D45+FI!D45+FR!D45+HR!D45+HU!D45+IE!D45+IT!D45+LT!D45+LU!D45+LV!D45+MT!D45+NL!D45+PL!D45+PT!D45+RO!D45+SE!D45+SI!D45+SK!D45 -> 1393673 | E45: =AT!E45+BE!E45+BG!E45+CY!E45+CZ!E45+DE!E45+DK!E45+EE!E45+EL!E45+ES!E45+FI!E45+FR!E45+HR!E45+HU!E45+IE!E45+IT!E45+LT!E45+LU!E45+LV!E45+MT!E45+NL!E45+PL!E45+PT!E45+RO!E45+SE!E45+SI!E45+SK!E45 -> 1399408 | F45: =AT!F45+BE!F45+BG!F45+CY!F45+CZ!F45+DE!F45+DK!F45+EE!F45+EL!F45+ES!F45+FI!F45+FR!F45+HR!F45+HU!F45+IE!F45+IT!F45+LT!F45+LU!F45+LV!F45+MT!F45+NL!F45+PL!F45+PT!F45+RO!F45+SE!F45+SI!F45+SK!F45 -> 1347063 | G45: =AT!G45+BE!G45+BG!G45+CY!G45+CZ!G45+DE!G45+DK!G45+EE!G45+EL!G45+ES!G45+FI!G45+FR!G45+HR!G45+HU!G45+IE!G45+IT!G45+LT!G45+LU!G45+LV!G45+MT!G45+NL!G45+PL!G45+PT!G45+RO!G45+SE!G45+SI!G45+SK!G45 -> 1401253 | H45: =AT!H45+BE!H45+BG!H45+CY!H45+CZ!H45+DE!H45+DK!H45+EE!H45+EL!H45+ES!H45+FI!H45+FR!H45+HR!H45+HU!H45+IE!H45+IT!H45+LT!H45+LU!H45+LV!H45+MT!H45+NL!H45+PL!H45+PT!H45+RO!H45+SE!H45+SI!H45+SK!H45 -> 1484360 | I45: =AT!I45+BE!I45+BG!I45+CY!I45+CZ!I45+DE!I45+DK!I45+EE!I45+EL!I45+ES!I45+FI!I45+FR!I45+HR!I45+HU!I45+IE!I45+IT!I45+LT!I45+LU!I45+LV!I45+MT!I45+NL!I45+PL!I45+PT!I45+RO!I45+SE!I45+SI!I45+SK!I45 -> 1553189 | ... AI45: =AT!AI45+BE!AI45+BG!AI45+CY!AI45+CZ!AI45+DE!AI45+DK!AI45+EE!AI45+EL!AI45+ES!AI45+FI!AI45+FR!AI45+HR!AI45+HU!AI45+IE!AI45+IT!AI45+LT!AI45+LU!AI45+LV!AI45+MT!AI45+NL!AI45+PL!AI45+PT!AI45+RO!AI45+SE!AI45+SI!AI45+SK!AI45 -> 1310191
...

Sheet AT
A1: AT - Austria | B1: 1990 | C1: 1991 | D1: 1992 | E1: 1993 | F1: 1994 | G1: 1995 | H1: 1996 | I1: 1997 | J1: 1998 | K1: 1999 | L1: 2000 | M1: 2001 | N1: 2002 | O1: 2003 | P1: 2004 | Q1: 2005 | R1: 2006 | S1: 2007 | T1: 2008 | U1: 2009 | V1: 2010 | W1: 2011 | X1: 2012 | Y1: 2013 | Z1: 2014 | AA1: 2015 | AB1: 2016 | AC1: 2017 | AD1: 2018 | AE1: 2019 | AF1: 2020 | AG1: 2021 | AH1: 2022 | AI1: 2023
A3: Transport activity
A4: Passenger transport (mio pkm) | B4: =SUM(B5:B7) -> 5731.7115 | C4: =SUM(C5:C7) -> 6491.1159 | D4: =SUM(D5:D7) -> 7080.715 | E4: =SUM(E5:E7) -> 7568.5197 | F4: =SUM(F5:F7) -> 8011.1868 | G4: =SUM(G5:G7) -> 9145.9732 | H4: =SUM(H5:H7) -> 10305.014 | I4: =SUM(I5:I7) -> 11488.297 | ... AI4: =SUM(AI5:AI7) -> 28467.541
A5: Domestic | B5: 80.050319 | C5: 88.816703 | D5: 94.403096 | E5: 112.12593 | F5: 115.86254 | G5: 111.30345 | H5: 119.09547 | I5: 123.99333 | J5: 137.53549 | K5: 145.03676 | L5: 157.73011 | M5: 161.67067 | N5: 164.77892 | O5: 169.57292 | P5: 176.92057 | Q5: 176.76307 | R5: 222.22347 | S5: 239.27198 | T5: 254.91025 | U5: 253.19716 | V5: 273.91359 | W5: 214.35635 | X5: 199.03831 | Y5: 190.16316 | Z5: 178.54922 | AA5: 162.9432 | AB5: 156.43057 | AC5: 167.9268 | AD5: 184.04799 | AE5: 174.945 | AF5: 44.975527 | AG5: 32.685958 | AH5: 72.223238 | AI5: 81.445386
A6: International - Intra-EU27 | B6: 2360.6859 | C6: 2686.4438 | D6: 2941.1143 | E6: 3141.2319 | F6: 3437.2781 | G6: 3909.3643 | H6: 4085.6112 | I6: 4345.2194 | J6: 4587.5167 | K6: 4652.9045 | L6: 4987.5895 | M6: 5022.7363 | N6: 5107.0795 | O6: 5510.9709 | P6: 6053.0276 | Q6: 6330.3745 | R6: 6547.8277 | S6: 6869.9768 | T6: 6790.9975 | U6: 6052.0117 | V6: 6534.4561 | W6: 7111.7536 | X6: 7316.9777 | Y6: 7267.2304 | Z6: 7535.478 | AA6: 7679.0592 | AB6: 7883.5557 | AC6: 8062.3631 | AD6: 8906.8925 | AE6: 10779.223 | AF6: 3067.5152 | AG6: 4054.4501 | AH6: 9000.4575 | AI6: 11098.271
A7: International - Extra-EU27 | B7: 3290.9753 | C7: 3715.8554 | D7: 4045.1976 | E7: 4315.1619 | F7: 4458.0462 | G7: 5125.3055 | H7: 6100.3071 | I7: 7019.0839 | J7: 7279.6191 | K7: 7262.8444 | L7: 8411.6776 | M7: 8380.4843 | N7: 8885.4884 | O7: 8866.4388 | P7: 10943.496 | Q7: 12203.404 | R7: 11635.387 | S7: 11706.916 | T7: 11752.805 | U7: 10393.401 | V7: 11097.258 | W7: 11335.192 | X7: 11500.058 | Y7: 11624.601 | Z7: 12726.194 | AA7: 13124.061 | AB7: 12947.661 | AC7: 13580.56 | AD7: 16255.192 | AE7: 19189.412 | AF7: 4330.4506 | AG7: 4785.3373 | AH7: 12304.093 | AI7: 17287.825
A8: Freight transport (mio tkm) | B8: =SUM(B9:B11) -> 43.912794 | C8: =SUM(C9:C11) -> 49.519309 | D8: =SUM(D9:D11) -> 53.618473 | E8: =SUM(E9:E11) -> 56.528604 | F8: =SUM(F9:F11) -> 74.382055 | G8: =SUM(G9:G11) -> 88.695864 | H8: =SUM(H9:H11) -> 88.739573 | I8: =SUM(I9:I11) -> 110.09398 | ... AI8: =SUM(AI9:AI11) -> 231.25905
A9: Domestic | B9: 0.14865409 | C9: 0.16354404 | D9: 0.17126864 | E9: 0.19906214 | F9: 0.1680924 | G9: 0.10412502 | H9: 0.12559276 | I9: 0.12784704 | J9: 0.13402257 | K9: 0.19776235 | L9: 0.28801273 | M9: 0.17715885 | N9: 0.1821774 | O9: 0.19378083 | P9: 0.23600016 | Q9: 0.24124955 | R9: 0.23872719 | S9: 0.21276302 | T9: 0.22503387 | U9: 0.21629151 | V9: 0.18957173 | W9: 0.14504914 | X9: 0.11128335 | Y9: 0.082766665 | Z9: 0.056643408 | AA9: 0.051504269 | AB9: 0.032377339 | AC9: 0.022563754 | AD9: 0.021363161 | AE9: 0.0070960203 | AF9: 0.0029143153 | AG9: 0.0028440696 | AH9: 0.0031269284 | AI9: 0.0048996119
A10: International - Intra-EU27 | B10: 16.176769 | C10: 18.208422 | D10: 19.718088 | E10: 20.846143 | F10: 26.383553 | G10: 29.235227 | H10: 28.188037 | I10: 31.71639 | J10: 29.281444 | K10: 32.4015 | L10: 30.62094 | M10: 29.267582 | N10: 36.544559 | O10: 40.752184 | P10: 55.119707 | Q10: 58.952934 | R10: 60.68571 | S10: 50.233704 | T10: 44.8159 | U10: 41.372192 | V10: 44.308283 | W10: 42.198726 | X10: 37.370304 | Y10: 40.976445 | Z10: 55.77613 | AA10: 54.585952 | AB10: 49.051057 | AC10: 53.800224 | AD10: 56.327183 | AE10: 66.699389 | AF10: 52.200025 | AG10: 56.265087 | AH10: 65.168455 | AI10: 66.548013
A11: International - Extra-EU27 | B11: 27.58737 | C11: 31.147343 | D11: 33.729116 | E11: 35.483399 | F11: 47.830409 | G11: 59.356512 | H11: 60.425944 | I11: 78.249742 | J11: 76.905496 | K11: 86.030687 | L11: 106.15102 | M11: 93.557925 | N11: 101.4122 | O11: 99.176525 | P11: 118.89472 | Q11: 154.0099 | R11: 134.82864 | S11: 118.84597 | T11: 107.98068 | U11: 92.011831 | V11: 99.212109 | W11: 143.28446 | X11: 168.4213 | Y11: 194.05359 | Z11: 247.52113 | AA11: 315.77741 | AB11: 335.11707 | AC11: 359.04465 | AD11: 437.41614 | AE11: 460.30571 | AF11: 124.64094 | AG11: 116.155 | AH11: 159.60437 | AI11: 164.70614
A13: Market shares of activity
A14: Passenger transport (% of pkm) | B14: =IF(B4=0,0,B4/B$4) -> 1 | C14: =IF(C4=0,0,C4/C$4) -> 1 | D14: =IF(D4=0,0,D4/D$4) -> 1 | E14: =IF(E4=0,0,E4/E$4) -> 1 | F14: =IF(F4=0,0,F4/F$4) -> 1 | G14: =IF(G4=0,0,G4/G$4) -> 1 | H14: =IF(H4=0,0,H4/H$4) -> 1 | I14: =IF(I4=0,0,I4/I$4) -> 1 | ... AI14: =IF(AI4=0,0,AI4/AI$4) -> 1
A15: Domestic | B15: =IF(B5=0,0,B5/B$4) -> 0.013966216 | C15: =IF(C5=0,0,C5/C$4) -> 0.01368281 | D15: =IF(D5=0,0,D5/D$4) -> 0.013332424 | E15: =IF(E5=0,0,E5/E$4) -> 0.014814777 | F15: =IF(F5=0,0,F5/F$4) -> 0.014462594 | G15: =IF(G5=0,0,G5/G$4) -> 0.012169668 | H15: =IF(H5=0,0,H5/H$4) -> 0.011557042 | I15: =IF(I5=0,0,I5/I$4) -> 0.010793013 | ... AI15: =IF(AI5=0,0,AI5/AI$4) -> 0.0028609913
A16: International - Intra-EU27 | B16: =IF(B6=0,0,B6/B$4) -> 0.41186404 | C16: =IF(C6=0,0,C6/C$4) -> 0.41386472 | D16: =IF(D6=0,0,D6/D$4) -> 0.41536968 | E16: =IF(E6=0,0,E6/E$4) -> 0.41503914 | F16: =IF(F6=0,0,F6/F$4) -> 0.42905979 | G16: =IF(G6=0,0,G6/G$4) -> 0.42744104 | H16: =IF(H6=0,0,H6/H$4) -> 0.39646829 | I16: =IF(I6=0,0,I6/I$4) -> 0.37823008 | ... AI16: =IF(AI6=0,0,AI6/AI$4) -> 0.38985702
A17: International - Extra-EU27 | B17: =IF(B7=0,0,B7/B$4) -> 0.57416974 | C17: =IF(C7=0,0,C7/C$4) -> 0.57245247 | D17: =IF(D7=0,0,D7/D$4) -> 0.57129789 | E17: =IF(E7=0,0,E7/E$4) -> 0.57014608 | F17: =IF(F7=0,0,F7/F$4) -> 0.55647762 | G17: =IF(G7=0,0,G7/G$4) -> 0.56038929 | H17: =IF(H7=0,0,H7/H$4) -> 0.59197467 | I17: =IF(I7=0,0,I7/I$4) -> 0.6109769 | ... AI17: =IF(AI7=0,0,AI7/AI$4) -> 0.60728199
A18: Freight transport (% of tkm) | B18: =IF(B8=0,0,B8/B$8) -> 1 | C18: =IF(C8=0,0,C8/C$8) -> 1 | D18: =IF(D8=0,0,D8/D$8) -> 1 | E18: =IF(E8=0,0,E8/E$8) -> 1 | F18: =IF(F8=0,0,F8/F$8) -> 1 | G18: =IF(G8=0,0,G8/G$8) -> 1 | H18: =IF(H8=0,0,H8/H$8) -> 1 | I18: =IF(I8=0,0,I8/I$8) -> 1 | ... AI18: =IF(AI8=0,0,AI8/AI$8) -> 1
A19: Domestic | B19: =IF(B9=0,0,B9/B$8) -> 0.0033852115 | C19: =IF(C9=0,0,C9/C$8) -> 0.0033026316 | D19: =IF(D9=0,0,D9/D$8) -> 0.0031942097 | E19: =IF(E9=0,0,E9/E$8) -> 0.0035214409 | F19: =IF(F9=0,0,F9/F$8) -> 0.0022598515 | G19: =IF(G9=0,0,G9/G$8) -> 0.0011739558 | H19: =IF(H9=0,0,H9/H$8) -> 0.0014152959 | I19: =IF(I9=0,0,I9/I$8) -> 0.0011612537 | ... AI19: =IF(AI9=0,0,AI9/AI$8) -> 2.1186681e-05
A20: International - Intra-EU27 | B20: =IF(B10=0,0,B10/B$8) -> 0.36838397 | C20: =IF(C10=0,0,C10/C$8) -> 0.36770347 | D20: =IF(D10=0,0,D10/D$8) -> 0.36774803 | E20: =IF(E10=0,0,E10/E$8) -> 0.36877159 | F20: =IF(F10=0,0,F10/F$8) -> 0.3547032 | G20: =IF(G10=0,0,G10/G$8) -> 0.32961207 | H20: =IF(H10=0,0,H10/H$8) -> 0.317649 | I20: =IF(I10=0,0,I10/I$8) -> 0.28808469 | ... AI20: =IF(AI10=0,0,AI10/AI$8) -> 0.28776392
A21: International - Extra-EU27 | B21: =IF(B11=0,0,B11/B$8) -> 0.62823082 | C21: =IF(C11=0,0,C11/C$8) -> 0.6289939 | D21: =IF(D11=0,0,D11/D$8) -> 0.62905776 | E21: =IF(E11=0,0,E11/E$8) -> 0.62770697 | F21: =IF(F11=0,0,F11/F$8) -> 0.64303695 | G21: =IF(G11=0,0,G11/G$8) -> 0.66921398 | H21: =IF(H11=0,0,H11/H$8) -> 0.6809357 | I21: =IF(I11=0,0,I11/I$8) -> 0.71075405 | ... AI21: =IF(AI11=0,0,AI11/AI$8) -> 0.71221489
A23: Vehicle-km (mio km) | B23: =SUM(B24,B28) -> 65.945782 | C23: =SUM(C24,C28) -> 74.129856 | D23: =SUM(D24,D28) -> 80.153905 | E23: =SUM(E24,E28) -> 85.146207 | F23: =SUM(F24,F28) -> 89.504197 | G23: =SUM(G24,G28) -> 101.06276 | H23: =SUM(H24,H28) -> 109.81471 | I23: =SUM(I24,I28) -> 114.69173 | ... AI23: =SUM(AI24,AI28) -> 176.01271
A24: Passenger transport | B24: =SUM(B25:B27) -> 64.910244 | C24: =SUM(C25:C27) -> 72.962933 | D24: =SUM(D25:D27) -> 78.890761 | E24: =SUM(E25:E27) -> 83.839059 | F24: =SUM(F25:F27) -> 87.925119 | G24: =SUM(G25:G27) -> 99.29879 | H24: =SUM(H25:H27) -> 108.04188 | I24: =SUM(I25:I27) -> 112.64763 | ... AI24: =SUM(AI25:AI27) -> 171.06284
A25: Domestic | B25: 3.6620375 | C25: 4.0172373 | D25: 4.1971297 | E25: 4.9164296 | F25: 4.9959922 | G25: 4.7087577 | H25: 4.950682 | I25: 4.9744159 | J25: 5.1874819 | K25: 4.8932351 | L25: 5.6861641 | M25: 5.096322 | N25: 5.4752558 | O25: 5.2314436 | P25: 5.1114254 | Q25: 5.1718207 | R25: 5.3994792 | S25: 5.5863667 | T25: 6.004601 | U25: 5.9842778 | V25: 5.9186437 | W25: 4.5415264 | X25: 4.3741924 | Y25: 4.1366258 | Z25: 3.8758739 | AA25: 3.5605271 | AB25: 3.2743145 | AC25: 3.2518334 | AD25: 3.197267 | AE25: 3.0205834 | AF25: 0.97697962 | AG25: 0.71541947 | AH25: 1.2051166 | AI25: 1.3318606
A26: International - Intra-EU27 | B26: 34.479544 | C26: 38.812734 | D26: 42.048678 | E26: 44.429143 | F26: 48.090291 | G26: 54.08372 | H26: 54.832687 | I26: 53.550313 | J26: 55.328899 | K26: 57.302758 | L26: 60.531939 | M26: 60.175208 | N26: 60.443179 | O26: 65.636075 | P26: 72.851013 | Q26: 74.5214 | R26: 76.007461 | S26: 83.400021 | T26: 85.957075 | U26: 75.71827 | V26: 76.583331 | W26: 76.217383 | X26: 73.61008 | Y26: 69.043135 | Z26: 71.533371 | AA26: 71.972106 | AB26: 73.341808 | AC26: 71.918724 | AD26: 77.836666 | AE26: 89.087293 | AF26: 32.254968 | AG26: 38.596726 | AH26: 71.508113 | AI26: 83.688071
A27: International - Extra-EU27 | B27: 26.768662 | C27: 30.132961 | D27: 32.644953 | E27: 34.493486 | F27: 34.838835 | G27: 40.506312 | H27: 48.258507 | I27: 54.122901 | J27: 56.863791 | K27: 56.195275 | L27: 65.189009 | M27: 64.438244 | N27: 63.407154 | O27: 65.549727 | P27: 79.719507 | Q27: 87.258737 | R27: 84.633292 | S27: 83.774241 | T27: 85.83524 | U27: 78.330095 | V27: 79.111211 | W27: 82.00975 | X27: 79.802033 | Y27: 78.465977 | Z27: 82.483416 | AA27: 84.883104 | AB27: 84.131249 | AC27: 85.669771 | AD27: 96.154561 | AE27: 108.78484 | AF27: 32.140998 | AG27: 37.19606 | AH27: 68.212686 | AI27: 86.042911
A28: Freight transport | B28: =SUM(B29:B31) -> 1.0355384 | C28: =SUM(C29:C31) -> 1.1669229 | D28: =SUM(D29:D31) -> 1.2631442 | E28: =SUM(E29:E31) -> 1.3071483 | F28: =SUM(F29:F31) -> 1.5790784 | G28: =SUM(G29:G31) -> 1.7639705 | H28: =SUM(H29:H31) -> 1.7728312 | I28: =SUM(I29:I31) -> 2.044102 | ... AI28: =SUM(AI29:AI31) -> 4.9498674
A29: Domestic | B29: 0.014390219 | C29: 0.015939934 | D29: 0.01638271 | E29: 0.018817978 | F29: 0.015497159 | G29: 0.0095196831 | H29: 0.011512175 | I29: 0.011512175 | J29: 0.012176339 | K29: 0.01748965 | L29: 0.026787945 | M29: 0.016604098 | N29: 0.016604098 | O29: 0.016604098 | P29: 0.021474634 | Q29: 0.022431579 | R29: 0.023076459 | S29: 0.020643291 | T29: 0.022694143 | U29: 0.021625709 | V29: 0.017721435 | W29: 0.013276708 | X29: 0.0096845714 | Y29: 0.0068577409 | Z29: 0.0041973938 | AA29: 0.0038537902 | AB29: 0.0021005779 | AC29: 0.0015880154 | AD29: 0.00148 | AE29: 0.000441 | AF29: 0.000196 | AG29: 0.000196 | AH29: 0.0002095 | AI29: 0.00032533333
A30: International - Intra-EU27 | B30: 0.5429474 | C30: 0.61071617 | D30: 0.66174206 | E30: 0.68566045 | F30: 0.86504835 | G30: 0.95912735 | H30: 0.95274911 | I30: 1.0595846 | J30: 1.0005859 | K30: 1.1297452 | L30: 1.112205 | M30: 1.0268961 | N30: 1.3681318 | O30: 1.4837373 | P30: 2.2116536 | Q30: 2.4072538 | R30: 2.9578835 | S30: 2.5677443 | T30: 2.364803 | U30: 2.125752 | V30: 2.2915443 | W30: 2.0754772 | X30: 1.6904417 | Y30: 1.8312639 | Z30: 2.1516061 | AA30: 2.1086288 | AB30: 1.7597948 | AC30: 2.0873445 | AD30: 2.1351473 | AE30: 2.3867101 | AF30: 2.2166564 | AG30: 2.4481867 | AH30: 2.8642478 | AI30: 2.925393
A31: International - Extra-EU27 | B31: 0.47820077 | C31: 0.54026684 | D31: 0.58501943 | E31: 0.60266983 | F31: 0.69853287 | G31: 0.7953235 | H31: 0.80856991 | I31: 0.97300525 | J31: 1.0815665 | K31: 1.2647047 | L31: 1.4058496 | M31: 1.1791472 | N31: 1.3609052 | O31: 1.4210992 | P31: 2.0500857 | Q31: 2.5623362 | R31: 2.1065093 | S31: 1.9050232 | T31: 1.7800194 | U31: 1.3618667 | V31: 1.3952937 | W31: 2.1635018 | X31: 2.3745807 | Y31: 2.641744 | Z31: 2.8504332 | AA31: 3.5185031 | AB31: 3.4108075 | AC31: 3.7177585 | AD31: 4.3001783 | AE31: 4.3351804 | AF31: 1.8095237 | AG31: 1.8681592 | AH31: 2.2330878 | AI31: 2.024149
A33: Market shares of vehicle km (% of km)
A34: Passenger transport | B34: =IF(B24=0,0,B24/B$24) -> 1 | C34: =IF(C24=0,0,C24/C$24) -> 1 | D34: =IF(D24=0,0,D24/D$24) -> 1 | E34: =IF(E24=0,0,E24/E$24) -> 1 | F34: =IF(F24=0,0,F24/F$24) -> 1 | G34: =IF(G24=0,0,G24/G$24) -> 1 | H34: =IF(H24=0,0,H24/H$24) -> 1 | I34: =IF(I24=0,0,I24/I$24) -> 1 | ... AI34: =IF(AI24=0,0,AI24/AI$24) -> 1
A35: Domestic | B35: =IF(B25=0,0,B25/B$24) -> 0.056416942 | C35: =IF(C25=0,0,C25/C$24) -> 0.055058605 | D35: =IF(D25=0,0,D25/D$24) -> 0.05320179 | E35: =IF(E25=0,0,E25/E$24) -> 0.058641279 | F35: =IF(F25=0,0,F25/F$24) -> 0.056820989 | G35: =IF(G25=0,0,G25/G$24) -> 0.047420092 | H35: =IF(H25=0,0,H25/H$24) -> 0.045821881 | I35: =IF(I25=0,0,I25/I$24) -> 0.044159082 | ... AI35: =IF(AI25=0,0,AI25/AI$24) -> 0.0077857973
A36: International - Intra-EU27 | B36: =IF(B26=0,0,B26/B$24) -> 0.53118803 | C36: =IF(C26=0,0,C26/C$24) -> 0.5319514 | D36: =IF(D26=0,0,D26/D$24) -> 0.53299877 | E36: =IF(E26=0,0,E26/E$24) -> 0.52993371 | F36: =IF(F26=0,0,F26/F$24) -> 0.54694599 | G36: =IF(G26=0,0,G26/G$24) -> 0.54465639 | H36: =IF(H26=0,0,H26/H$24) -> 0.50751328 | I36: =IF(I26=0,0,I26/I$24) -> 0.47537896 | ... AI36: =IF(AI26=0,0,AI26/AI$24) -> 0.48922413
A37: International - Extra-EU27 | B37: =IF(B27=0,0,B27/B$24) -> 0.41239503 | C37: =IF(C27=0,0,C27/C$24) -> 0.41299 | D37: =IF(D27=0,0,D27/D$24) -> 0.41379944 | E37: =IF(E27=0,0,E27/E$24) -> 0.41142501 | F37: =IF(F27=0,0,F27/F$24) -> 0.39623302 | G37: =IF(G27=0,0,G27/G$24) -> 0.40792352 | H37: =IF(H27=0,0,H27/H$24) -> 0.44666484 | I37: =IF(I27=0,0,I27/I$24) -> 0.48046196 | ... AI37: =IF(AI27=0,0,AI27/AI$24) -> 0.50299007
A38: Freight transport | B38: =IF(B28=0,0,B28/B$28) -> 1 | C38: =IF(C28=0,0,C28/C$28) -> 1 | D38: =IF(D28=0,0,D28/D$28) -> 1 | E38: =IF(E28=0,0,E28/E$28) -> 1 | F38: =IF(F28=0,0,F28/F$28) -> 1 | G38: =IF(G28=0,0,G28/G$28) -> 1 | H38: =IF(H28=0,0,H28/H$28) -> 1 | I38: =IF(I28=0,0,I28/I$28) -> 1 | ... AI38: =IF(AI28=0,0,AI28/AI$28) -> 1
A39: Domestic | B39: =IF(B29=0,0,B29/B$28) -> 0.013896364 | C39: =IF(C29=0,0,C29/C$28) -> 0.0136598 | D39: =IF(D29=0,0,D29/D$28) -> 0.012969786 | E39: =IF(E29=0,0,E29/E$28) -> 0.014396208 | F39: =IF(F29=0,0,F29/F$28) -> 0.0098140528 | G39: =IF(G29=0,0,G29/G$28) -> 0.0053967359 | H39: =IF(H29=0,0,H29/H$28) -> 0.0064936667 | I39: =IF(I29=0,0,I29/I$28) -> 0.0056318985 | ... AI39: =IF(AI29=0,0,AI29/AI$28) -> 6.5725667e-05
A40: International - Intra-EU27 | B40: =IF(B30=0,0,B30/B$28) -> 0.52431412 | C40: =IF(C30=0,0,C30/C$28) -> 0.52335604 | D40: =IF(D30=0,0,D30/D$28) -> 0.52388481 | E40: =IF(E30=0,0,E30/E$28) -> 0.52454681 | F40: =IF(F30=0,0,F30/F$28) -> 0.5478185 | G40: =IF(G30=0,0,G30/G$28) -> 0.54373207 | H40: =IF(H30=0,0,H30/H$28) -> 0.53741671 | I40: =IF(I30=0,0,I30/I$28) -> 0.51836189 | ... AI40: =IF(AI30=0,0,AI30/AI$28) -> 0.59100433
A41: International - Extra-EU27 | B41: =IF(B31=0,0,B31/B$28) -> 0.46178951 | C41: =IF(C31=0,0,C31/C$28) -> 0.46298416 | D41: =IF(D31=0,0,D31/D$28) -> 0.4631454 | E41: =IF(E31=0,0,E31/E$28) -> 0.46105698 | F41: =IF(F31=0,0,F31/F$28) -> 0.44236744 | G41: =IF(G31=0,0,G31/G$28) -> 0.45087119 | H41: =IF(H31=0,0,H31/H$28) -> 0.45608962 | I41: =IF(I31=0,0,I31/I$28) -> 0.47600621 | ... AI41: =IF(AI31=0,0,AI31/AI$28) -> 0.40892995
A43: Number of departing flights | B43: =SUM(B44,B48) -> 72131 | C43: =SUM(C44,C48) -> 80806 | D43: =SUM(D44,D48) -> 86964 | E43: =SUM(E44,E48) -> 93650 | F43: =SUM(F44,F48) -> 99324 | G43: =SUM(G44,G48) -> 107969 | H43: =SUM(H44,H48) -> 112823 | I43: =SUM(I44,I48) -> 114306 | ... AI43: =SUM(AI44,AI48) -> 129833
A44: Passenger transport | B44: =SUM(B45:B47) -> 70971 | C44: =SUM(C45:C47) -> 79501 | D44: =SUM(D45:D47) -> 85554 | E44: =SUM(E45:E47) -> 92183 | F44: =SUM(F45:F47) -> 97590 | G44: =SUM(G45:G47) -> 106084 | H44: =SUM(H45:H47) -> 110935 | I44: =SUM(I45:I47) -> 112200 | ... AI44: =SUM(AI45:AI47) -> 125420
A45: Domestic | B45: 13578 | C45: 14895 | D45: 15562 | E45: 18229 | F45: 18524 | G45: 17459 | H45: 18356 | I45: 18444 | J45: 19234 | K45: 18143 | L45: 21083 | M45: 18896 | N45: 20301 | O45: 19397 | P45: 18952 | Q45: 18970 | R45: 19618 | S45: 19837 | T45: 20580 | U45: 19975 | V45: 19873 | W45: 15427 | X45: 15550 | Y45: 14879 | Z45: 13964 | AA45: 12456 | AB45: 11028 | AC45: 10823 | AD45: 10585 | AE45: 9885 | AF45: 3253 | AG45: 2509 | AH45: 3900 | AI45: 4331
...

Sheet BE
A1: BE - Belgium | B1: 1990 | C1: 1991 | D1: 1992 | E1: 1993 | F1: 1994 | G1: 1995 | H1: 1996 | I1: 1997 | J1: 1998 | K1: 1999 | L1: 2000 | M1: 2001 | N1: 2002 | O1: 2003 | P1: 2004 | Q1: 2005 | R1: 2006 | S1: 2007 | T1: 2008 | U1: 2009 | V1: 2010 | W1: 2011 | X1: 2012 | Y1: 2013 | Z1: 2014 | AA1: 2015 | AB1: 2016 | AC1: 2017 | AD1: 2018 | AE1: 2019 | AF1: 2020 | AG1: 2021 | AH1: 2022 | AI1: 2023
A3: Transport activity
A4: Passenger transport (mio pkm) | B4: =SUM(B5:B7) -> 12474.818 | C4: =SUM(C5:C7) -> 11923.489 | D4: =SUM(D5:D7) -> 11372.059 | E4: =SUM(E5:E7) -> 10810.285 | F4: =SUM(F5:F7) -> 10248.265 | G4: =SUM(G5:G7) -> 11872.669 | H4: =SUM(H5:H7) -> 13909.89 | I4: =SUM(I5:I7) -> 15184.707 | ... AI4: =SUM(AI5:AI7) -> 32699.137
A5: Domestic | B5: 0 | C5: 0 | D5: 0 | E5: 0 | F5: 0 | G5: 0 | H5: 0 | I5: 0 | J5: 0 | K5: 0 | L5: 0 | M5: 0 | N5: 0 | O5: 0 | P5: 0 | Q5: 0 | R5: 0 | S5: 0 | T5: 0 | U5: 0 | V5: 0 | W5: 0 | X5: 0 | Y5: 0 | Z5: 0 | AA5: 0 | AB5: 0 | AC5: 0 | AD5: 0 | AE5: 0 | AF5: 0 | AG5: 0 | AH5: 0 | AI5: 0
A6: International - Intra-EU27 | B6: 5754.7715 | C6: 5512.2379 | D6: 5269.3396 | E6: 5031.5318 | F6: 4790.751 | G6: 5579.9442 | H6: 6623.5273 | I6: 7308.7586 | J6: 7995.4673 | K6: 8671.5516 | L6: 9753.7158 | M6: 9739.5324 | N6: 6984.7499 | O6: 7808.0587 | P6: 8835.513 | Q6: 8642.9128 | R6: 9038.0737 | S6: 8963.1616 | T6: 8800.6798 | U6: 8660.9357 | V6: 9438.733 | W6: 10464.646 | X6: 10650.664 | Y6: 10874.848 | Z6: 11801.394 | AA6: 12838.494 | AB6: 13190.992 | AC6: 14173.938 | AD6: 14181.27 | AE6: 14593.328 | AF6: 4408.0477 | AG6: 6701.4707 | AH6: 12424.205 | AI6: 13846.431
A7: International - Extra-EU27 | B7: 6720.0461 | C7: 6411.2508 | D7: 6102.7191 | E7: 5778.7527 | F7: 5457.514 | G7: 6292.7243 | H7: 7286.363 | I7: 7875.9486 | J7: 8950.4764 | K7: 10082.789 | L7: 10858.873 | M7: 10289.491 | N7: 6562.681 | O7: 7054.2082 | P7: 8443.4068 | Q7: 8752.4247 | R7: 9170.246 | S7: 10881.456 | T7: 13424.939 | U7: 13200.348 | V7: 14471.445 | W7: 15654.398 | X7: 15713.853 | Y7: 16234.165 | Z7: 17102.926 | AA7: 17819.115 | AB7: 15365.881 | AC7: 17731.945 | AD7: 20501.412 | AE7: 21712.953 | AF7: 6507.6134 | AG7: 9134.6035 | AH7: 17214.945 | AI7: 18852.706
A8: Freight transport (mio tkm) | B8: =SUM(B9:B11) -> 862.03715 | C8: =SUM(C9:C11) -> 822.62871 | D8: =SUM(D9:D11) -> 782.84778 | E8: =SUM(E9:E11) -> 743.76153 | F8: =SUM(F9:F11) -> 704.15454 | G8: =SUM(G9:G11) -> 814.22774 | H8: =SUM(H9:H11) -> 920.61229 | I8: =SUM(I9:I11) -> 1003.1115 | ... AI8: =SUM(AI9:AI11) -> 4671.7795
A9: Domestic | B9: 0 | C9: 0 | D9: 0 | E9: 0 | F9: 0 | G9: 0 | H9: 0 | I9: 0 | J9: 0 | K9: 0 | L9: 0 | M9: 0 | N9: 0 | O9: 0 | P9: 0 | Q9: 0 | R9: 0 | S9: 0 | T9: 0 | U9: 0 | V9: 0 | W9: 0 | X9: 0 | Y9: 0 | Z9: 0 | AA9: 0 | AB9: 0 | AC9: 0 | AD9: 0 | AE9: 0 | AF9: 0 | AG9: 0 | AH9: 0 | AI9: 0
A10: International - Intra-EU27 | B10: 148.3022 | C10: 141.47109 | D10: 134.65471 | E10: 127.9465 | F10: 121.11662 | G10: 139.63895 | H10: 156.26201 | I10: 171.02891 | J10: 191.06839 | K10: 205.50889 | L10: 227.42361 | M10: 184.74324 | N10: 142.68831 | O10: 147.57269 | P10: 153.31096 | Q10: 169.83108 | R10: 292.30072 | S10: 304.10531 | T10: 208.46436 | U10: 169.84342 | V10: 180.4506 | W10: 176.66317 | X10: 187.55389 | Y10: 190.82783 | Z10: 207.2595 | AA10: 218.86879 | AB10: 220.92532 | AC10: 209.53325 | AD10: 234.10978 | AE10: 234.3898 | AF10: 230.69876 | AG10: 247.64703 | AH10: 155.05907 | AI10: 148.4995
A11: International - Extra-EU27 | B11: 713.73495 | C11: 681.15762 | D11: 648.19307 | E11: 615.81503 | F11: 583.03792 | G11: 674.58879 | H11: 764.35028 | I11: 832.0826 | J11: 936.35511 | K11: 1025.8815 | L11: 1143.653 | M11: 1135.8758 | N11: 946.20152 | O11: 1142.0488 | P11: 1249.0709 | Q11: 1224.6548 | R11: 1797.2734 | S11: 2400.318 | T11: 2539.9034 | U11: 1972.912 | V11: 2576.4158 | W11: 2759.9461 | X11: 2354.9737 | Y11: 2144.5747 | Z11: 2343.2975 | AA11: 2953.9666 | AB11: 2839.2929 | AC11: 3261.6946 | AD11: 3882.177 | AE11: 3749.91 | AF11: 4472.9014 | AG11: 5613.0908 | AH11: 5387.4073 | AI11: 4523.28
A13: Market shares of activity
A14: Passenger transport (% of pkm) | B14: =IF(B4=0,0,B4/B$4) -> 1 | C14: =IF(C4=0,0,C4/C$4) -> 1 | D14: =IF(D4=0,0,D4/D$4) -> 1 | E14: =IF(E4=0,0,E4/E$4) -> 1 | F14: =IF(F4=0,0,F4/F$4) -> 1 | G14: =IF(G4=0,0,G4/G$4) -> 1 | H14: =IF(H4=0,0,H4/H$4) -> 1 | I14: =IF(I4=0,0,I4/I$4) -> 1 | ... AI14: =IF(AI4=0,0,AI4/AI$4) -> 1
A15: Domestic | B15: =IF(B5=0,0,B5/B$4) -> 0 | C15: =IF(C5=0,0,C5/C$4) -> 0 | D15: =IF(D5=0,0,D5/D$4) -> 0 | E15: =IF(E5=0,0,E5/E$4) -> 0 | F15: =IF(F5=0,0,F5/F$4) -> 0 | G15: =IF(G5=0,0,G5/G$4) -> 0 | H15: =IF(H5=0,0,H5/H$4) -> 0 | I15: =IF(I5=0,0,I5/I$4) -> 0 | ... AI15: =IF(AI5=0,0,AI5/AI$4) -> 0
A16: International - Intra-EU27 | B16: =IF(B6=0,0,B6/B$4) -> 0.46131107 | C16: =IF(C6=0,0,C6/C$4) -> 0.46230076 | D16: =IF(D6=0,0,D6/D$4) -> 0.46335846 | E16: =IF(E6=0,0,E6/E$4) -> 0.46543936 | F16: =IF(F6=0,0,F6/F$4) -> 0.46746947 | G16: =IF(G6=0,0,G6/G$4) -> 0.46998231 | H16: =IF(H6=0,0,H6/H$4) -> 0.47617394 | I16: =IF(I6=0,0,I6/I$4) -> 0.48132364 | ... AI16: =IF(AI6=0,0,AI6/AI$4) -> 0.42344943
A17: International - Extra-EU27 | B17: =IF(B7=0,0,B7/B$4) -> 0.53868893 | C17: =IF(C7=0,0,C7/C$4) -> 0.53769924 | D17: =IF(D7=0,0,D7/D$4) -> 0.53664154 | E17: =IF(E7=0,0,E7/E$4) -> 0.53456064 | F17: =IF(F7=0,0,F7/F$4) -> 0.53253053 | G17: =IF(G7=0,0,G7/G$4) -> 0.53001769 | H17: =IF(H7=0,0,H7/H$4) -> 0.52382606 | I17: =IF(I7=0,0,I7/I$4) -> 0.51867636 | ... AI17: =IF(AI7=0,0,AI7/AI$4) -> 0.57655057
A18: Freight transport (% of tkm) | B18: =IF(B8=0,0,B8/B$8) -> 1 | C18: =IF(C8=0,0,C8/C$8) -> 1 | D18: =IF(D8=0,0,D8/D$8) -> 1 | E18: =IF(E8=0,0,E8/E$8) -> 1 | F18: =IF(F8=0,0,F8/F$8) -> 1 | G18: =IF(G8=0,0,G8/G$8) -> 1 | H18: =IF(H8=0,0,H8/H$8) -> 1 | I18: =IF(I8=0,0,I8/I$8) -> 1 | ... AI18: =IF(AI8=0,0,AI8/AI$8) -> 1
A19: Domestic | B19: =IF(B9=0,0,B9/B$8) -> 0 | C19: =IF(C9=0,0,C9/C$8) -> 0 | D19: =IF(D9=0,0,D9/D$8) -> 0 | E19: =IF(E9=0,0,E9/E$8) -> 0 | F19: =IF(F9=0,0,F9/F$8) -> 0 | G19: =IF(G9=0,0,G9/G$8) -> 0 | H19: =IF(H9=0,0,H9/H$8) -> 0 | I19: =IF(I9=0,0,I9/I$8) -> 0 | ... AI19: =IF(AI9=0,0,AI9/AI$8) -> 0
A20: International - Intra-EU27 | B20: =IF(B10=0,0,B10/B$8) -> 0.17203691 | C20: =IF(C10=0,0,C10/C$8) -> 0.17197441 | D20: =IF(D10=0,0,D10/D$8) -> 0.17200625 | E20: =IF(E10=0,0,E10/E$8) -> 0.17202624 | F20: =IF(F10=0,0,F10/F$8) -> 0.17200289 | G20: =IF(G10=0,0,G10/G$8) -> 0.17149864 | H20: =IF(H10=0,0,H10/H$8) -> 0.16973705 | I20: =IF(I10=0,0,I10/I$8) -> 0.1704984 | ... AI20: =IF(AI10=0,0,AI10/AI$8) -> 0.031786496
A21: International - Extra-EU27 | B21: =IF(B11=0,0,B11/B$8) -> 0.82796309 | C21: =IF(C11=0,0,C11/C$8) -> 0.82802559 | D21: =IF(D11=0,0,D11/D$8) -> 0.82799375 | E21: =IF(E11=0,0,E11/E$8) -> 0.82797376 | F21: =IF(F11=0,0,F11/F$8) -> 0.82799711 | G21: =IF(G11=0,0,G11/G$8) -> 0.82850136 | H21: =IF(H11=0,0,H11/H$8) -> 0.83026295 | I21: =IF(I11=0,0,I11/I$8) -> 0.8295016 | ... AI21: =IF(AI11=0,0,AI11/AI$8) -> 0.9682135
A23: Vehicle-km (mio km) | B23: =SUM(B24,B28) -> 130.75364 | C23: =SUM(C24,C28) -> 124.74081 | D23: =SUM(D24,D28) -> 118.71921 | E23: =SUM(E24,E28) -> 112.53245 | F23: =SUM(F24,F28) -> 106.50247 | G23: =SUM(G24,G28) -> 122.83424 | H23: =SUM(H24,H28) -> 141.66339 | I23: =SUM(I24,I28) -> 153.11356 | ... AI23: =SUM(AI24,AI28) -> 267.61414
A24: Passenger transport | B24: =SUM(B25:B27) -> 115.43863 | C24: =SUM(C25:C27) -> 110.13089 | D24: =SUM(D25:D27) -> 104.81143 | E24: =SUM(E25:E27) -> 99.599448 | F24: =SUM(F25:F27) -> 94.28162 | G24: =SUM(G25:G27) -> 108.69644 | H24: =SUM(H25:H27) -> 125.35273 | I24: =SUM(I25:I27) -> 135.57194 | ... AI24: =SUM(AI25:AI27) -> 199.93578
A25: Domestic | B25: 0 | C25: 0 | D25: 0 | E25: 0 | F25: 0 | G25: 0 | H25: 0 | I25: 0 | J25: 0 | K25: 0 | L25: 0 | M25: 0 | N25: 0 | O25: 0 | P25: 0 | Q25: 0 | R25: 0 | S25: 0 | T25: 0 | U25: 0 | V25: 0 | W25: 0 | X25: 0 | Y25: 0 | Z25: 0 | AA25: 0 | AB25: 0 | AC25: 0 | AD25: 0 | AE25: 0 | AF25: 0 | AG25: 0 | AH25: 0 | AI25: 0
A26: International - Intra-EU27 | B26: 64.573776 | C26: 61.60461 | D26: 58.628736 | E26: 55.71323 | F26: 52.738474 | G26: 60.801951 | H26: 70.117487 | I26: 75.833355 | J26: 86.300337 | K26: 97.068036 | L26: 105.05885 | M26: 102.47872 | N26: 72.868661 | O26: 80.932138 | P26: 85.484264 | Q26: 82.616168 | R26: 90.024622 | S26: 95.250465 | T26: 98.607581 | U26: 94.259297 | V26: 98.150554 | W26: 102.53444 | X26: 97.55513 | Y26: 96.70635 | Z26: 104.59131 | AA26: 112.23225 | AB26: 115.17595 | AC26: 117.45801 | AD26: 117.37481 | AE26: 117.93292 | AF26: 45.395409 | AG26: 57.21957 | AH26: 97.404785 | AI26: 104.50697
A27: International - Extra-EU27 | B27: 50.864857 | C27: 48.52628 | D27: 46.182696 | E27: 43.886218 | F27: 41.543147 | G27: 47.894491 | H27: 55.235242 | I27: 59.738581 | J27: 67.985762 | K27: 76.471119 | L27: 81.636791 | M27: 76.785525 | N27: 52.463132 | O27: 53.931851 | P27: 61.490089 | Q27: 63.773822 | R27: 68.684884 | S27: 78.624083 | T27: 89.781127 | U27: 90.59687 | V27: 96.33152 | W27: 104.18272 | X27: 104.06853 | Y27: 99.536413 | Z27: 100.52198 | AA27: 103.0114 | AB27: 93.638405 | AC27: 102.293 | AD27: 117.20467 | AE27: 120.23551 | AF27: 44.655303 | AG27: 61.56158 | AH27: 92.691815 | AI27: 95.428815
