Workbook

Sheet cover
B6: JRC-IDEES-2023 - Integrated Database of the European Energy System
C10: Malta
C15: Energy balances
L28: Prepared by JRC C.6
L30: 45967.478
L31: v2023-1.00
B33: Legal Notice
B35: The information made available is property of the Joint Research Centre of the European Commission.
B36: Neither the European Commission nor any person acting on behalf of the Commission is responsible for the use which might be made of this information.
B38: Use conditions
B39: This work is licensed under
B40: CC BY 4.0

Sheet index
A1: Malta | B1: MT | C1: 2000 | D1: 2001 | E1: 2002 | F1: 2003 | G1: 2004 | H1: 2005 | I1: 2006 | J1: 2007 | K1: 2008 | L1: 2009 | M1: 2010 | N1: 2011 | O1: 2012 | P1: 2013 | Q1: 2014 | R1: 2015 | S1: 2016 | T1: 2017 | U1: 2018 | V1: 2019 | W1: 2020 | X1: 2021 | Y1: 2022 | Z1: 2023
B2: Click on the link to jump to the sheet
A3: Total | B3: ktoe
A4: Primary production | B4: =HYPERLINK("#"&CELL("address",PPRD!$Z$2),"PPRD") -> PPRD | C4: =PPRD!C$2 -> 0 | D4: =PPRD!D$2 -> 0 | E4: =PPRD!E$2 -> 0.238865 | F4: =PPRD!F$2 -> 0.31049011 | G4: =PPRD!G$2 -> 0.40601892 | H4: =PPRD!H$2 -> 0.52545142 | I4: =PPRD!I$2 -> 0.64488392 | J4: =PPRD!J$2 -> 0.78822012 | ... Z4: =PPRD!Z$2 -> 54.134738
A5: Recovered & recycled products | B5: =HYPERLINK("#"&CELL("address",RCV_RCY!$Z$2),"RCV_RCY") -> RCV_RCY | C5: =RCV_RCY!C$2 -> 0 | D5: =RCV_RCY!D$2 -> 0 | E5: =RCV_RCY!E$2 -> 0 | F5: =RCV_RCY!F$2 -> 0 | G5: =RCV_RCY!G$2 -> 0 | H5: =RCV_RCY!H$2 -> 0 | I5: =RCV_RCY!I$2 -> 0 | J5: =RCV_RCY!J$2 -> 0 | ... Z5: =RCV_RCY!Z$2 -> 0
A6: Imports | B6: =HYPERLINK("#"&CELL("address",IMP!$Z$2),"IMP") -> IMP | C6: =IMP!C$2 -> 1470.6721 | D6: =IMP!D$2 -> 1611.4335 | E6: =IMP!E$2 -> 1572.3345 | F6: =IMP!F$2 -> 1827.9212 | G6: =IMP!G$2 -> 1919.4612 | H6: =IMP!H$2 -> 1593.6132 | I6: =IMP!I$2 -> 1688.9653 | J6: =IMP!J$2 -> 1800.0575 | ... Z6: =IMP!Z$2 -> 3208.9316
A7: Exports | B7: =HYPERLINK("#"&CELL("address",EXP!$Z$2),"EXP") -> EXP | C7: =EXP!C$2 -> 0 | D7: =EXP!D$2 -> 0 | E7: =EXP!E$2 -> 0 | F7: =EXP!F$2 -> 0 | G7: =EXP!G$2 -> 0 | H7: =EXP!H$2 -> 0 | I7: =EXP!I$2 -> 0 | J7: =EXP!J$2 -> 0 | ... Z7: =EXP!Z$2 -> 92.068702
A8: Change in stock | B8: =HYPERLINK("#"&CELL("address",STK_CHG!$Z$2),"STK_CHG") -> STK_CHG | C8: =STK_CHG!C$2 -> -3.6160791 | D8: =STK_CHG!D$2 -> 2.8804815 | E8: =STK_CHG!E$2 -> 2.8804815 | F8: =STK_CHG!F$2 -> 2.8804815 | G8: =STK_CHG!G$2 -> 2.8804815 | H8: =STK_CHG!H$2 -> 0 | I8: =STK_CHG!I$2 -> 0 | J8: =STK_CHG!J$2 -> 0 | ... Z8: =STK_CHG!Z$2 -> 24.006277
A9: Gross available energy | B9: =HYPERLINK("#"&CELL("address",GAE!$Z$2),"GAE") -> GAE | C9: =GAE!C$2 -> 1467.0561 | D9: =GAE!D$2 -> 1614.314 | E9: =GAE!E$2 -> 1575.4538 | F9: =GAE!F$2 -> 1831.1121 | G9: =GAE!G$2 -> 1922.7477 | H9: =GAE!H$2 -> 1594.1387 | I9: =GAE!I$2 -> 1689.6101 | J9: =GAE!J$2 -> 1800.8457 | ... Z9: =GAE!Z$2 -> 3195.0039
A10: International maritime bunkers | B10: =HYPERLINK("#"&CELL("address",INTMARB!$Z$2),"INTMARB") -> INTMARB | C10: =INTMARB!C$2 -> 658.3166 | D10: =INTMARB!D$2 -> 724.99286 | E10: =INTMARB!E$2 -> 743.07352 | F10: =INTMARB!F$2 -> 915.98358 | G10: =INTMARB!G$2 -> 980.94007 | H10: =INTMARB!H$2 -> 658.49819 | I10: =INTMARB!I$2 -> 752.57954 | J10: =INTMARB!J$2 -> 842.17059 | ... Z10: =INTMARB!Z$2 -> 2251.8276
A11: International Intra-EEA maritime bunkers | B11: =HYPERLINK("#"&CELL("address",INTMARB_IN!$Z$2),"INTMARB_IN") -> INTMARB_IN | C11: =INTMARB_IN!C$2 -> 382.08913 | D11: =INTMARB_IN!D$2 -> 421.00678 | E11: =INTMARB_IN!E$2 -> 429.80488 | F11: =INTMARB_IN!F$2 -> 529.92831 | G11: =INTMARB_IN!G$2 -> 486.70675 | H11: =INTMARB_IN!H$2 -> 383.29419 | I11: =INTMARB_IN!I$2 -> 395.10975 | J11: =INTMARB_IN!J$2 -> 402.89749 | ... Z11: =INTMARB_IN!Z$2 -> 1402.136
A12: International Extra-EEA maritime bunkers | B12: =HYPERLINK("#"&CELL("address",INTMARB_EX!$Z$2),"INTMARB_EX") -> INTMARB_EX | C12: =INTMARB_EX!C$2 -> 276.22746 | D12: =INTMARB_EX!D$2 -> 303.98608 | E12: =INTMARB_EX!E$2 -> 313.26864 | F12: =INTMARB_EX!F$2 -> 386.05527 | G12: =INTMARB_EX!G$2 -> 494.23332 | H12: =INTMARB_EX!H$2 -> 275.20401 | I12: =INTMARB_EX!I$2 -> 357.46979 | J12: =INTMARB_EX!J$2 -> 439.2731 | ... Z12: =INTMARB_EX!Z$2 -> 849.6916
A13: Gross inland consumption | B13: =HYPERLINK("#"&CELL("address",GIC!$Z$2),"GIC") -> GIC | C13: =GIC!C$2 -> 808.73947 | D13: =GIC!D$2 -> 889.32115 | E13: =GIC!E$2 -> 832.38031 | F13: =GIC!F$2 -> 915.12855 | G13: =GIC!G$2 -> 941.80765 | H13: =GIC!H$2 -> 935.6405 | I13: =GIC!I$2 -> 937.03061 | J13: =GIC!J$2 -> 958.67515 | ... Z13: =GIC!Z$2 -> 943.17627
A14: International aviation | B14: =HYPERLINK("#"&CELL("address",INTAVI!$Z$2),"INTAVI") -> INTAVI | C14: =INTAVI!C$2 -> 126.40206 | D14: =INTAVI!D$2 -> 94.802752 | E14: =INTAVI!E$2 -> 91.638005 | F14: =INTAVI!F$2 -> 81.104901 | G14: =INTAVI!G$2 -> 104.28255 | H14: =INTAVI!H$2 -> 88.325193 | I14: =INTAVI!I$2 -> 89.352279 | J14: =INTAVI!J$2 -> 93.460361 | ... Z14: =INTAVI!Z$2 -> 150.4307
A15: International Intra-EEAwUK passenger aviation | B15: =HYPERLINK("#"&CELL("address",INTAVI_PA_IN!$Z$2),"INTAVI_PA_IN") -> INTAVI_PA_IN | C15: =INTAVI_PA_IN!C$2 -> 111.31176 | D15: =INTAVI_PA_IN!D$2 -> 83.573616 | E15: =INTAVI_PA_IN!E$2 -> 81.567116 | F15: =INTAVI_PA_IN!F$2 -> 72.28257 | G15: =INTAVI_PA_IN!G$2 -> 93.691196 | H15: =INTAVI_PA_IN!H$2 -> 79.52161 | I15: =INTAVI_PA_IN!I$2 -> 79.680989 | J15: =INTAVI_PA_IN!J$2 -> 83.659106 | ... Z15: =INTAVI_PA_IN!Z$2 -> 138.16421
A16: International Extra-EEAwUK passenger aviation | B16: =HYPERLINK("#"&CELL("address",INTAVI_PA_EX!$Z$2),"INTAVI_PA_EX") -> INTAVI_PA_EX | C16: =INTAVI_PA_EX!C$2 -> 12.317564 | D16: =INTAVI_PA_EX!D$2 -> 9.2484025 | E16: =INTAVI_PA_EX!E$2 -> 8.1155032 | F16: =INTAVI_PA_EX!F$2 -> 6.3437115 | G16: =INTAVI_PA_EX!G$2 -> 7.7493418 | H16: =INTAVI_PA_EX!H$2 -> 6.3342377 | I16: =INTAVI_PA_EX!I$2 -> 6.5708767 | J16: =INTAVI_PA_EX!J$2 -> 6.6146225 | ... Z16: =INTAVI_PA_EX!Z$2 -> 10.918093
A17: International Intra-EEAwUK freight aviation | B17: =HYPERLINK("#"&CELL("address",INTAVI_FR_IN!$Z$2),"INTAVI_FR_IN") -> INTAVI_FR_IN | C17: =INTAVI_FR_IN!C$2 -> 2.6216658 | D17: =INTAVI_FR_IN!D$2 -> 1.8635267 | E17: =INTAVI_FR_IN!E$2 -> 1.8307959 | F17: =INTAVI_FR_IN!F$2 -> 2.3553239 | G17: =INTAVI_FR_IN!G$2 -> 2.6528035 | H17: =INTAVI_FR_IN!H$2 -> 2.2201467 | I17: =INTAVI_FR_IN!I$2 -> 2.7873227 | J17: =INTAVI_FR_IN!J$2 -> 2.7583229 | ... Z17: =INTAVI_FR_IN!Z$2 -> 0.85165835
A18: International Extra-EEAwUK freight aviation | B18: =HYPERLINK("#"&CELL("address",INTAVI_FR_EX!$Z$2),"INTAVI_FR_EX") -> INTAVI_FR_EX | C18: =INTAVI_FR_EX!C$2 -> 0.15107681 | D18: =INTAVI_FR_EX!D$2 -> 0.11720616 | E18: =INTAVI_FR_EX!E$2 -> 0.12458954 | F18: =INTAVI_FR_EX!F$2 -> 0.12329558 | G18: =INTAVI_FR_EX!G$2 -> 0.18920385 | H18: =INTAVI_FR_EX!H$2 -> 0.2491987 | I18: =INTAVI_FR_EX!I$2 -> 0.31309031 | J18: =INTAVI_FR_EX!J$2 -> 0.42830986 | ... Z18: =INTAVI_FR_EX!Z$2 -> 0.49673027
A19: Total energy supply | B19: =HYPERLINK("#"&CELL("address",NRGSUP!$Z$2),"NRGSUP") -> NRGSUP | C19: =NRGSUP!C$2 -> 682.3374 | D19: =NRGSUP!D$2 -> 794.5184 | E19: =NRGSUP!E$2 -> 740.7423 | F19: =NRGSUP!F$2 -> 834.02365 | G19: =NRGSUP!G$2 -> 837.52511 | H19: =NRGSUP!H$2 -> 847.31531 | I19: =NRGSUP!I$2 -> 847.67833 | J19: =NRGSUP!J$2 -> 865.21479 | ... Z19: =NRGSUP!Z$2 -> 792.74557
A20: Gross inland consumption (Europe 2020-2030) | B20: =HYPERLINK("#"&CELL("address",'GIC2020-2030'!$Z$2),"GIC2020-2030") -> GIC2020-2030 | C20: ='GIC2020-2030'!C$2 -> 808.73947 | D20: ='GIC2020-2030'!D$2 -> 889.32115 | E20: ='GIC2020-2030'!E$2 -> 832.38031 | F20: ='GIC2020-2030'!F$2 -> 915.12855 | G20: ='GIC2020-2030'!G$2 -> 941.80765 | H20: ='GIC2020-2030'!H$2 -> 935.6405 | I20: ='GIC2020-2030'!I$2 -> 937.03061 | J20: ='GIC2020-2030'!J$2 -> 958.67515 | ... Z20: ='GIC2020-2030'!Z$2 -> 921.09905
A21: Primary energy consumption (Europe 2020-2030) | B21: =HYPERLINK("#"&CELL("address",'PEC2020-2030'!$Z$2),"PEC2020-2030") -> PEC2020-2030 | C21: ='PEC2020-2030'!C$2 -> 808.73947 | D21: ='PEC2020-2030'!D$2 -> 889.32115 | E21: ='PEC2020-2030'!E$2 -> 832.38031 | F21: ='PEC2020-2030'!F$2 -> 915.12855 | G21: ='PEC2020-2030'!G$2 -> 933.16621 | H21: ='PEC2020-2030'!H$2 -> 915.72081 | I21: ='PEC2020-2030'!I$2 -> 924.56285 | J21: ='PEC2020-2030'!J$2 -> 949.07352 | ... Z21: ='PEC2020-2030'!Z$2 -> 912.90525
A22: Final energy consumption (Europe 2020-2030) | B22: =HYPERLINK("#"&CELL("address",'FEC2020-2030'!$Z$2),"FEC2020-2030") -> FEC2020-2030 | C22: ='FEC2020-2030'!C$2 -> 445.73663 | D22: ='FEC2020-2030'!D$2 -> 403.9147 | E22: ='FEC2020-2030'!E$2 -> 366.83629 | F22: ='FEC2020-2030'!F$2 -> 397.84557 | G22: ='FEC2020-2030'!G$2 -> 446.09252 | H22: ='FEC2020-2030'!H$2 -> 464.34497 | I22: ='FEC2020-2030'!I$2 -> 466.28435 | J22: ='FEC2020-2030'!J$2 -> 480.32855 | ... Z22: ='FEC2020-2030'!Z$2 -> 721.11376
A23: Transformation input | B23: =HYPERLINK("#"&CELL("address",TI_E!$Z$2),"TI_E") -> TI_E | C23: =TI_E!C$2 -> 497.7405 | D23: =TI_E!D$2 -> 620.31617 | E23: =TI_E!E$2 -> 608.02046 | F23: =TI_E!F$2 -> 672.57094 | G23: =TI_E!G$2 -> 640.9859 | H23: =TI_E!H$2 -> 611.135 | I23: =TI_E!I$2 -> 617.60765 | J23: =TI_E!J$2 -> 627.90198 | ... Z23: =TI_E!Z$2 -> 384.09475
A24: Electricity & heat generation | B24: =HYPERLINK("#"&CELL("address",TI_EHG_E!$Z$2),"TI_EHG_E") -> TI_EHG_E | C24: =TI_EHG_E!C$2 -> 497.7405 | D24: =TI_EHG_E!D$2 -> 620.31617 | E24: =TI_EHG_E!E$2 -> 608.02046 | F24: =TI_EHG_E!F$2 -> 672.57094 | G24: =TI_EHG_E!G$2 -> 640.9859 | H24: =TI_EHG_E!H$2 -> 611.135 | I24: =TI_EHG_E!I$2 -> 617.60765 | J24: =TI_EHG_E!J$2 -> 627.90198 | ... Z24: =TI_EHG_E!Z$2 -> 370.29338
A25: Electricity only | B25: =HYPERLINK("#"&CELL("address",TI_EHG_E_E!$Z$2),"TI_EHG_E_E") -> TI_EHG_E_E | C25: =TI_EHG_E_E!C$2 -> 497.7405 | D25: =TI_EHG_E_E!D$2 -> 620.31617 | E25: =TI_EHG_E_E!E$2 -> 608.02046 | F25: =TI_EHG_E_E!F$2 -> 672.57094 | G25: =TI_EHG_E_E!G$2 -> 640.9859 | H25: =TI_EHG_E_E!H$2 -> 611.135 | I25: =TI_EHG_E_E!I$2 -> 617.60765 | J25: =TI_EHG_E_E!J$2 -> 627.90198 | ... Z25: =TI_EHG_E_E!Z$2 -> 368.76879
A26: CHP | B26: =HYPERLINK("#"&CELL("address",TI_EHG_CHP_E!$Z$2),"TI_EHG_CHP_E") -> TI_EHG_CHP_E | C26: =TI_EHG_CHP_E!C$2 -> 0 | D26: =TI_EHG_CHP_E!D$2 -> 0 | E26: =TI_EHG_CHP_E!E$2 -> 0 | F26: =TI_EHG_CHP_E!F$2 -> 0 | G26: =TI_EHG_CHP_E!G$2 -> 0 | H26: =TI_EHG_CHP_E!H$2 -> 0 | I26: =TI_EHG_CHP_E!I$2 -> 0 | J26: =TI_EHG_CHP_E!J$2 -> 0 | ... Z26: =TI_EHG_CHP_E!Z$2 -> 1.5245916
A27: Heat only | B27: =HYPERLINK("#"&CELL("address",TI_EHG_H_E!$Z$2),"TI_EHG_H_E") -> TI_EHG_H_E | C27: =TI_EHG_H_E!C$2 -> 0 | D27: =TI_EHG_H_E!D$2 -> 0 | E27: =TI_EHG_H_E!E$2 -> 0 | F27: =TI_EHG_H_E!F$2 -> 0 | G27: =TI_EHG_H_E!G$2 -> 0 | H27: =TI_EHG_H_E!H$2 -> 0 | I27: =TI_EHG_H_E!I$2 -> 0 | J27: =TI_EHG_H_E!J$2 -> 0 | ... Z27: =TI_EHG_H_E!Z$2 -> 0
A28: Electrically driven heat pumps | B28: =HYPERLINK("#"&CELL("address",TI_EHG_EDHP!$Z$2),"TI_EHG_EDHP") -> TI_EHG_EDHP | C28: =TI_EHG_EDHP!C$2 -> 0 | D28: =TI_EHG_EDHP!D$2 -> 0 | E28: =TI_EHG_EDHP!E$2 -> 0 | F28: =TI_EHG_EDHP!F$2 -> 0 | G28: =TI_EHG_EDHP!G$2 -> 0 | H28: =TI_EHG_EDHP!H$2 -> 0 | I28: =TI_EHG_EDHP!I$2 -> 0 | J28: =TI_EHG_EDHP!J$2 -> 0 | ... Z28: =TI_EHG_EDHP!Z$2 -> 0
A29: Electric boilers | B29: =HYPERLINK("#"&CELL("address",TI_EHG_EB!$Z$2),"TI_EHG_EB") -> TI_EHG_EB | C29: =TI_EHG_EB!C$2 -> 0 | D29: =TI_EHG_EB!D$2 -> 0 | E29: =TI_EHG_EB!E$2 -> 0 | F29: =TI_EHG_EB!F$2 -> 0 | G29: =TI_EHG_EB!G$2 -> 0 | H29: =TI_EHG_EB!H$2 -> 0 | I29: =TI_EHG_EB!I$2 -> 0 | J29: =TI_EHG_EB!J$2 -> 0 | ... Z29: =TI_EHG_EB!Z$2 -> 0
A30: Electricity for pumped storage | B30: =HYPERLINK("#"&CELL("address",TI_EHG_EPS!$Z$2),"TI_EHG_EPS") -> TI_EHG_EPS | C30: =TI_EHG_EPS!C$2 -> 0 | D30: =TI_EHG_EPS!D$2 -> 0 | E30: =TI_EHG_EPS!E$2 -> 0 | F30: =TI_EHG_EPS!F$2 -> 0 | G30: =TI_EHG_EPS!G$2 -> 0 | H30: =TI_EHG_EPS!H$2 -> 0 | I30: =TI_EHG_EPS!I$2 -> 0 | J30: =TI_EHG_EPS!J$2 -> 0 | ... Z30: =TI_EHG_EPS!Z$2 -> 0
A31: Derived heat for electricity production | B31: =HYPERLINK("#"&CELL("address",TI_EHG_DHEP!$Z$2),"TI_EHG_DHEP") -> TI_EHG_DHEP | C31: =TI_EHG_DHEP!C$2 -> 0 | D31: =TI_EHG_DHEP!D$2 -> 0 | E31: =TI_EHG_DHEP!E$2 -> 0 | F31: =TI_EHG_DHEP!F$2 -> 0 | G31: =TI_EHG_DHEP!G$2 -> 0 | H31: =TI_EHG_DHEP!H$2 -> 0 | I31: =TI_EHG_DHEP!I$2 -> 0 | J31: =TI_EHG_DHEP!J$2 -> 0 | ... Z31: =TI_EHG_DHEP!Z$2 -> 0
A32: Charging batteries | B32: =HYPERLINK("#"&CELL("address",TI_EHG_CB!$Z$2),"TI_EHG_CB") -> TI_EHG_CB | C32: =TI_EHG_CB!C$2 -> 0 | D32: =TI_EHG_CB!D$2 -> 0 | E32: =TI_EHG_CB!E$2 -> 0 | F32: =TI_EHG_CB!F$2 -> 0 | G32: =TI_EHG_CB!G$2 -> 0 | H32: =TI_EHG_CB!H$2 -> 0 | I32: =TI_EHG_CB!I$2 -> 0 | J32: =TI_EHG_CB!J$2 -> 0 | ... Z32: =TI_EHG_CB!Z$2 -> 0
A33: Coke ovens | B33: =HYPERLINK("#"&CELL("address",TI_CO_E!$Z$2),"TI_CO_E") -> TI_CO_E | C33: =TI_CO_E!C$2 -> 0 | D33: =TI_CO_E!D$2 -> 0 | E33: =TI_CO_E!E$2 -> 0 | F33: =TI_CO_E!F$2 -> 0 | G33: =TI_CO_E!G$2 -> 0 | H33: =TI_CO_E!H$2 -> 0 | I33: =TI_CO_E!I$2 -> 0 | J33: =TI_CO_E!J$2 -> 0 | ... Z33: =TI_CO_E!Z$2 -> 0
A34: Blast furnaces | B34: =HYPERLINK("#"&CELL("address",TI_BF_E!$Z$2),"TI_BF_E") -> TI_BF_E | C34: =TI_BF_E!C$2 -> 0 | D34: =TI_BF_E!D$2 -> 0 | E34: =TI_BF_E!E$2 -> 0 | F34: =TI_BF_E!F$2 -> 0 | G34: =TI_BF_E!G$2 -> 0 | H34: =TI_BF_E!H$2 -> 0 | I34: =TI_BF_E!I$2 -> 0 | J34: =TI_BF_E!J$2 -> 0 | ... Z34: =TI_BF_E!Z$2 -> 0
A35: Gas works | B35: =HYPERLINK("#"&CELL("address",TI_GW_E!$Z$2),"TI_GW_E") -> TI_GW_E | C35: =TI_GW_E!C$2 -> 0 | D35: =TI_GW_E!D$2 -> 0 | E35: =TI_GW_E!E$2 -> 0 | F35: =TI_GW_E!F$2 -> 0 | G35: =TI_GW_E!G$2 -> 0 | H35: =TI_GW_E!H$2 -> 0 | I35: =TI_GW_E!I$2 -> 0 | J35: =TI_GW_E!J$2 -> 0 | ... Z35: =TI_GW_E!Z$2 -> 0
A36: Refineries & petrochemical industry | B36: =HYPERLINK("#"&CELL("address",TI_RPI_E!$Z$2),"TI_RPI_E") -> TI_RPI_E | C36: =TI_RPI_E!C$2 -> 0 | D36: =TI_RPI_E!D$2 -> 0 | E36: =TI_RPI_E!E$2 -> 0 | F36: =TI_RPI_E!F$2 -> 0 | G36: =TI_RPI_E!G$2 -> 0 | H36: =TI_RPI_E!H$2 -> 0 | I36: =TI_RPI_E!I$2 -> 0 | J36: =TI_RPI_E!J$2 -> 0 | ... Z36: =TI_RPI_E!Z$2 -> 0
A37: Refinery intake | B37: =HYPERLINK("#"&CELL("address",TI_RPI_RI_E!$Z$2),"TI_RPI_RI_E") -> TI_RPI_RI_E | C37: =TI_RPI_RI_E!C$2 -> 0 | D37: =TI_RPI_RI_E!D$2 -> 0 | E37: =TI_RPI_RI_E!E$2 -> 0 | F37: =TI_RPI_RI_E!F$2 -> 0 | G37: =TI_RPI_RI_E!G$2 -> 0 | H37: =TI_RPI_RI_E!H$2 -> 0 | I37: =TI_RPI_RI_E!I$2 -> 0 | J37: =TI_RPI_RI_E!J$2 -> 0 | ... Z37: =TI_RPI_RI_E!Z$2 -> 0
A38: Backflows from petrochemical industry | B38: =HYPERLINK("#"&CELL("address",TI_RPI_BPI_E!$Z$2),"TI_RPI_BPI_E") -> TI_RPI_BPI_E | C38: =TI_RPI_BPI_E!C$2 -> 0 | D38: =TI_RPI_BPI_E!D$2 -> 0 | E38: =TI_RPI_BPI_E!E$2 -> 0 | F38: =TI_RPI_BPI_E!F$2 -> 0 | G38: =TI_RPI_BPI_E!G$2 -> 0 | H38: =TI_RPI_BPI_E!H$2 -> 0 | I38: =TI_RPI_BPI_E!I$2 -> 0 | J38: =TI_RPI_BPI_E!J$2 -> 0 | ... Z38: =TI_RPI_BPI_E!Z$2 -> 0
A39: Products transferred | B39: =HYPERLINK("#"&CELL("address",TI_RPI_PT_E!$Z$2),"TI_RPI_PT_E") -> TI_RPI_PT_E | C39: =TI_RPI_PT_E!C$2 -> 0 | D39: =TI_RPI_PT_E!D$2 -> 0 | E39: =TI_RPI_PT_E!E$2 -> 0 | F39: =TI_RPI_PT_E!F$2 -> 0 | G39: =TI_RPI_PT_E!G$2 -> 0 | H39: =TI_RPI_PT_E!H$2 -> 0 | I39: =TI_RPI_PT_E!I$2 -> 0 | J39: =TI_RPI_PT_E!J$2 -> 0 | ... Z39: =TI_RPI_PT_E!Z$2 -> 0
A40: Interproduct transfers | B40: =HYPERLINK("#"&CELL("address",TI_RPI_IT_E!$Z$2),"TI_RPI_IT_E") -> TI_RPI_IT_E | C40: =TI_RPI_IT_E!C$2 -> 0 | D40: =TI_RPI_IT_E!D$2 -> 0 | E40: =TI_RPI_IT_E!E$2 -> 0 | F40: =TI_RPI_IT_E!F$2 -> 0 | G40: =TI_RPI_IT_E!G$2 -> 0 | H40: =TI_RPI_IT_E!H$2 -> 0 | I40: =TI_RPI_IT_E!I$2 -> 0 | J40: =TI_RPI_IT_E!J$2 -> 0 | ... Z40: =TI_RPI_IT_E!Z$2 -> 0
...

Sheet PPRD
A1: Primary production | B1: PPRD | C1: 2000 | D1: 2001 | E1: 2002 | F1: 2003 | G1: 2004 | H1: 2005 | I1: 2006 | J1: 2007 | K1: 2008 | L1: 2009 | M1: 2010 | N1: 2011 | O1: 2012 | P1: 2013 | Q1: 2014 | R1: 2015 | S1: 2016 | T1: 2017 | U1: 2018 | V1: 2019 | W1: 2020 | X1: 2021 | Y1: 2022 | Z1: 2023
A2: Total | B2: TOTAL | C2: =SUM(C3,C17,C22,C25,C26,C51,C52,C71,C74,C75,C76) -> 0 | D2: =SUM(D3,D17,D22,D25,D26,D51,D52,D71,D74,D75,D76) -> 0 | E2: =SUM(E3,E17,E22,E25,E26,E51,E52,E71,E74,E75,E76) -> 0.238865 | F2: =SUM(F3,F17,F22,F25,F26,F51,F52,F71,F74,F75,F76) -> 0.31049011 | G2: =SUM(G3,G17,G22,G25,G26,G51,G52,G71,G74,G75,G76) -> 0.40601892 | H2: =SUM(H3,H17,H22,H25,H26,H51,H52,H71,H74,H75,H76) -> 0.52545142 | I2: =SUM(I3,I17,I22,I25,I26,I51,I52,I71,I74,I75,I76) -> 0.64488392 | J2: =SUM(J3,J17,J22,J25,J26,J51,J52,J71,J74,J75,J76) -> 0.78822012 | ... Z2: =SUM(Z3,Z17,Z22,Z25,Z26,Z51,Z52,Z71,Z74,Z75,Z76) -> 54.134738
A3: Solid fossil fuels | B3: C0000X0350-0370 | C3: =SUM(C4,C8,C11) -> 0 | D3: =SUM(D4,D8,D11) -> 0 | E3: =SUM(E4,E8,E11) -> 0 | F3: =SUM(F4,F8,F11) -> 0 | G3: =SUM(G4,G8,G11) -> 0 | H3: =SUM(H4,H8,H11) -> 0 | I3: =SUM(I4,I8,I11) -> 0 | J3: =SUM(J4,J8,J11) -> 0 | ... Z3: =SUM(Z4,Z8,Z11) -> 0
A4: Hard coal | B4: C0100 | C4: =SUM(C5:C7) -> 0 | D4: =SUM(D5:D7) -> 0 | E4: =SUM(E5:E7) -> 0 | F4: =SUM(F5:F7) -> 0 | G4: =SUM(G5:G7) -> 0 | H4: =SUM(H5:H7) -> 0 | I4: =SUM(I5:I7) -> 0 | J4: =SUM(J5:J7) -> 0 | ... Z4: =SUM(Z5:Z7) -> 0
A5: Anthracite | B5: C0110 | C5: 0 | D5: 0 | E5: 0 | F5: 0 | G5: 0 | H5: 0 | I5: 0 | J5: 0 | K5: 0 | L5: 0 | M5: 0 | N5: 0 | O5: 0 | P5: 0 | Q5: 0 | R5: 0 | S5: 0 | T5: 0 | U5: 0 | V5: 0 | W5: 0 | X5: 0 | Y5: 0 | Z5: 0
A6: Coking coal | B6: C0121 | C6: 0 | D6: 0 | E6: 0 | F6: 0 | G6: 0 | H6: 0 | I6: 0 | J6: 0 | K6: 0 | L6: 0 | M6: 0 | N6: 0 | O6: 0 | P6: 0 | Q6: 0 | R6: 0 | S6: 0 | T6: 0 | U6: 0 | V6: 0 | W6: 0 | X6: 0 | Y6: 0 | Z6: 0
A7: Other bituminous coal | B7: C0129 | C7: 0 | D7: 0 | E7: 0 | F7: 0 | G7: 0 | H7: 0 | I7: 0 | J7: 0 | K7: 0 | L7: 0 | M7: 0 | N7: 0 | O7: 0 | P7: 0 | Q7: 0 | R7: 0 | S7: 0 | T7: 0 | U7: 0 | V7: 0 | W7: 0 | X7: 0 | Y7: 0 | Z7: 0
A8: Brown coal | B8: C0200 | C8: =SUM(C9:C10) -> 0 | D8: =SUM(D9:D10) -> 0 | E8: =SUM(E9:E10) -> 0 | F8: =SUM(F9:F10) -> 0 | G8: =SUM(G9:G10) -> 0 | H8: =SUM(H9:H10) -> 0 | I8: =SUM(I9:I10) -> 0 | J8: =SUM(J9:J10) -> 0 | ... Z8: =SUM(Z9:Z10) -> 0
A9: Sub-bituminous coal | B9: C0210 | C9: 0 | D9: 0 | E9: 0 | F9: 0 | G9: 0 | H9: 0 | I9: 0 | J9: 0 | K9: 0 | L9: 0 | M9: 0 | N9: 0 | O9: 0 | P9: 0 | Q9: 0 | R9: 0 | S9: 0 | T9: 0 | U9: 0 | V9: 0 | W9: 0 | X9: 0 | Y9: 0 | Z9: 0
A10: Lignite | B10: C0220 | C10: 0 | D10: 0 | E10: 0 | F10: 0 | G10: 0 | H10: 0 | I10: 0 | J10: 0 | K10: 0 | L10: 0 | M10: 0 | N10: 0 | O10: 0 | P10: 0 | Q10: 0 | R10: 0 | S10: 0 | T10: 0 | U10: 0 | V10: 0 | W10: 0 | X10: 0 | Y10: 0 | Z10: 0
A11: Coal products | B11: C0300 | C11: =SUM(C12:C16) -> 0 | D11: =SUM(D12:D16) -> 0 | E11: =SUM(E12:E16) -> 0 | F11: =SUM(F12:F16) -> 0 | G11: =SUM(G12:G16) -> 0 | H11: =SUM(H12:H16) -> 0 | I11: =SUM(I12:I16) -> 0 | J11: =SUM(J12:J16) -> 0 | ... Z11: =SUM(Z12:Z16) -> 0
A12: Patent fuel | B12: C0320 | C12: 0 | D12: 0 | E12: 0 | F12: 0 | G12: 0 | H12: 0 | I12: 0 | J12: 0 | K12: 0 | L12: 0 | M12: 0 | N12: 0 | O12: 0 | P12: 0 | Q12: 0 | R12: 0 | S12: 0 | T12: 0 | U12: 0 | V12: 0 | W12: 0 | X12: 0 | Y12: 0 | Z12: 0
A13: Coke oven coke | B13: C0311 | C13: 0 | D13: 0 | E13: 0 | F13: 0 | G13: 0 | H13: 0 | I13: 0 | J13: 0 | K13: 0 | L13: 0 | M13: 0 | N13: 0 | O13: 0 | P13: 0 | Q13: 0 | R13: 0 | S13: 0 | T13: 0 | U13: 0 | V13: 0 | W13: 0 | X13: 0 | Y13: 0 | Z13: 0
A14: Gas coke | B14: C0312 | C14: 0 | D14: 0 | E14: 0 | F14: 0 | G14: 0 | H14: 0 | I14: 0 | J14: 0 | K14: 0 | L14: 0 | M14: 0 | N14: 0 | O14: 0 | P14: 0 | Q14: 0 | R14: 0 | S14: 0 | T14: 0 | U14: 0 | V14: 0 | W14: 0 | X14: 0 | Y14: 0 | Z14: 0
A15: Coal tar | B15: C0340 | C15: 0 | D15: 0 | E15: 0 | F15: 0 | G15: 0 | H15: 0 | I15: 0 | J15: 0 | K15: 0 | L15: 0 | M15: 0 | N15: 0 | O15: 0 | P15: 0 | Q15: 0 | R15: 0 | S15: 0 | T15: 0 | U15: 0 | V15: 0 | W15: 0 | X15: 0 | Y15: 0 | Z15: 0
A16: Brown coal briquettes | B16: C0330 | C16: 0 | D16: 0 | E16: 0 | F16: 0 | G16: 0 | H16: 0 | I16: 0 | J16: 0 | K16: 0 | L16: 0 | M16: 0 | N16: 0 | O16: 0 | P16: 0 | Q16: 0 | R16: 0 | S16: 0 | T16: 0 | U16: 0 | V16: 0 | W16: 0 | X16: 0 | Y16: 0 | Z16: 0
A17: Manufactured gases | B17: C0350-0370 | C17: =SUM(C18:C21) -> 0 | D17: =SUM(D18:D21) -> 0 | E17: =SUM(E18:E21) -> 0 | F17: =SUM(F18:F21) -> 0 | G17: =SUM(G18:G21) -> 0 | H17: =SUM(H18:H21) -> 0 | I17: =SUM(I18:I21) -> 0 | J17: =SUM(J18:J21) -> 0 | ... Z17: =SUM(Z18:Z21) -> 0
A18: Gas works gas | B18: C0360 | C18: 0 | D18: 0 | E18: 0 | F18: 0 | G18: 0 | H18: 0 | I18: 0 | J18: 0 | K18: 0 | L18: 0 | M18: 0 | N18: 0 | O18: 0 | P18: 0 | Q18: 0 | R18: 0 | S18: 0 | T18: 0 | U18: 0 | V18: 0 | W18: 0 | X18: 0 | Y18: 0 | Z18: 0
A19: Coke oven gas | B19: C0350 | C19: 0 | D19: 0 | E19: 0 | F19: 0 | G19: 0 | H19: 0 | I19: 0 | J19: 0 | K19: 0 | L19: 0 | M19: 0 | N19: 0 | O19: 0 | P19: 0 | Q19: 0 | R19: 0 | S19: 0 | T19: 0 | U19: 0 | V19: 0 | W19: 0 | X19: 0 | Y19: 0 | Z19: 0
A20: Blast furnace gas | B20: C0371 | C20: 0 | D20: 0 | E20: 0 | F20: 0 | G20: 0 | H20: 0 | I20: 0 | J20: 0 | K20: 0 | L20: 0 | M20: 0 | N20: 0 | O20: 0 | P20: 0 | Q20: 0 | R20: 0 | S20: 0 | T20: 0 | U20: 0 | V20: 0 | W20: 0 | X20: 0 | Y20: 0 | Z20: 0
A21: Other recovered gases | B21: C0379 | C21: 0 | D21: 0 | E21: 0 | F21: 0 | G21: 0 | H21: 0 | I21: 0 | J21: 0 | K21: 0 | L21: 0 | M21: 0 | N21: 0 | O21: 0 | P21: 0 | Q21: 0 | R21: 0 | S21: 0 | T21: 0 | U21: 0 | V21: 0 | W21: 0 | X21: 0 | Y21: 0 | Z21: 0
A22: Peat and peat products | B22: P1000 | C22: =SUM(C23:C24) -> 0 | D22: =SUM(D23:D24) -> 0 | E22: =SUM(E23:E24) -> 0 | F22: =SUM(F23:F24) -> 0 | G22: =SUM(G23:G24) -> 0 | H22: =SUM(H23:H24) -> 0 | I22: =SUM(I23:I24) -> 0 | J22: =SUM(J23:J24) -> 0 | ... Z22: =SUM(Z23:Z24) -> 0
A23: Peat | B23: P1100 | C23: 0 | D23: 0 | E23: 0 | F23: 0 | G23: 0 | H23: 0 | I23: 0 | J23: 0 | K23: 0 | L23: 0 | M23: 0 | N23: 0 | O23: 0 | P23: 0 | Q23: 0 | R23: 0 | S23: 0 | T23: 0 | U23: 0 | V23: 0 | W23: 0 | X23: 0 | Y23: 0 | Z23: 0
A24: Peat products | B24: P1200 | C24: 0 | D24: 0 | E24: 0 | F24: 0 | G24: 0 | H24: 0 | I24: 0 | J24: 0 | K24: 0 | L24: 0 | M24: 0 | N24: 0 | O24: 0 | P24: 0 | Q24: 0 | R24: 0 | S24: 0 | T24: 0 | U24: 0 | V24: 0 | W24: 0 | X24: 0 | Y24: 0 | Z24: 0
A25: Oil shale and oil sands | B25: S2000 | C25: 0 | D25: 0 | E25: 0 | F25: 0 | G25: 0 | H25: 0 | I25: 0 | J25: 0 | K25: 0 | L25: 0 | M25: 0 | N25: 0 | O25: 0 | P25: 0 | Q25: 0 | R25: 0 | S25: 0 | T25: 0 | U25: 0 | V25: 0 | W25: 0 | X25: 0 | Y25: 0 | Z25: 0
A26: Oil and petroleum products | B26: O4000XBIO | C26: =SUM(C27,C33) -> 0 | D26: =SUM(D27,D33) -> 0 | E26: =SUM(E27,E33) -> 0 | F26: =SUM(F27,F33) -> 0 | G26: =SUM(G27,G33) -> 0 | H26: =SUM(H27,H33) -> 0 | I26: =SUM(I27,I33) -> 0 | J26: =SUM(J27,J33) -> 0 | ... Z26: =SUM(Z27,Z33) -> 0
A27: Crude oil, NGL, refinery feedstocks, additives and oxygenates and other hydrocarbons (excluding biofuel portion) | B27: O4100_TOT_4200-4500XBIO | C27: =SUM(C28:C32) -> 0 | D27: =SUM(D28:D32) -> 0 | E27: =SUM(E28:E32) -> 0 | F27: =SUM(F28:F32) -> 0 | G27: =SUM(G28:G32) -> 0 | H27: =SUM(H28:H32) -> 0 | I27: =SUM(I28:I32) -> 0 | J27: =SUM(J28:J32) -> 0 | ... Z27: =SUM(Z28:Z32) -> 0
A28: Crude oil | B28: O4100_TOT | C28: 0 | D28: 0 | E28: 0 | F28: 0 | G28: 0 | H28: 0 | I28: 0 | J28: 0 | K28: 0 | L28: 0 | M28: 0 | N28: 0 | O28: 0 | P28: 0 | Q28: 0 | R28: 0 | S28: 0 | T28: 0 | U28: 0 | V28: 0 | W28: 0 | X28: 0 | Y28: 0 | Z28: 0
A29: Natural gas liquids | B29: O4200 | C29: 0 | D29: 0 | E29: 0 | F29: 0 | G29: 0 | H29: 0 | I29: 0 | J29: 0 | K29: 0 | L29: 0 | M29: 0 | N29: 0 | O29: 0 | P29: 0 | Q29: 0 | R29: 0 | S29: 0 | T29: 0 | U29: 0 | V29: 0 | W29: 0 | X29: 0 | Y29: 0 | Z29: 0
A30: Refinery feedstocks | B30: O4300 | C30: 0 | D30: 0 | E30: 0 | F30: 0 | G30: 0 | H30: 0 | I30: 0 | J30: 0 | K30: 0 | L30: 0 | M30: 0 | N30: 0 | O30: 0 | P30: 0 | Q30: 0 | R30: 0 | S30: 0 | T30: 0 | U30: 0 | V30: 0 | W30: 0 | X30: 0 | Y30: 0 | Z30: 0
A31: Additives and oxygenates (excluding biofuel portion) | B31: O4400X4410 | C31: 0 | D31: 0 | E31: 0 | F31: 0 | G31: 0 | H31: 0 | I31: 0 | J31: 0 | K31: 0 | L31: 0 | M31: 0 | N31: 0 | O31: 0 | P31: 0 | Q31: 0 | R31: 0 | S31: 0 | T31: 0 | U31: 0 | V31: 0 | W31: 0 | X31: 0 | Y31: 0 | Z31: 0
A32: Other hydrocarbons | B32: O4500 | C32: 0 | D32: 0 | E32: 0 | F32: 0 | G32: 0 | H32: 0 | I32: 0 | J32: 0 | K32: 0 | L32: 0 | M32: 0 | N32: 0 | O32: 0 | P32: 0 | Q32: 0 | R32: 0 | S32: 0 | T32: 0 | U32: 0 | V32: 0 | W32: 0 | X32: 0 | Y32: 0 | Z32: 0
A33: Oil products (excluding biofuel portion) | B33: O4600XBIO | C33: =SUM(C34:C50) -> 0 | D33: =SUM(D34:D50) -> 0 | E33: =SUM(E34:E50) -> 0 | F33: =SUM(F34:F50) -> 0 | G33: =SUM(G34:G50) -> 0 | H33: =SUM(H34:H50) -> 0 | I33: =SUM(I34:I50) -> 0 | J33: =SUM(J34:J50) -> 0 | ... Z33: =SUM(Z34:Z50) -> 0
A34: Refinery gas | B34: O4610 | C34: 0 | D34: 0 | E34: 0 | F34: 0 | G34: 0 | H34: 0 | I34: 0 | J34: 0 | K34: 0 | L34: 0 | M34: 0 | N34: 0 | O34: 0 | P34: 0 | Q34: 0 | R34: 0 | S34: 0 | T34: 0 | U34: 0 | V34: 0 | W34: 0 | X34: 0 | Y34: 0 | Z34: 0
A35: Ethane | B35: O4620 | C35: 0 | D35: 0 | E35: 0 | F35: 0 | G35: 0 | H35: 0 | I35: 0 | J35: 0 | K35: 0 | L35: 0 | M35: 0 | N35: 0 | O35: 0 | P35: 0 | Q35: 0 | R35: 0 | S35: 0 | T35: 0 | U35: 0 | V35: 0 | W35: 0 | X35: 0 | Y35: 0 | Z35: 0
A36: Liquefied petroleum gases | B36: O4630 | C36: 0 | D36: 0 | E36: 0 | F36: 0 | G36: 0 | H36: 0 | I36: 0 | J36: 0 | K36: 0 | L36: 0 | M36: 0 | N36: 0 | O36: 0 | P36: 0 | Q36: 0 | R36: 0 | S36: 0 | T36: 0 | U36: 0 | V36: 0 | W36: 0 | X36: 0 | Y36: 0 | Z36: 0
A37: Motor gasoline (excluding biofuel portion) | B37: O4652XR5210B | C37: 0 | D37: 0 | E37: 0 | F37: 0 | G37: 0 | H37: 0 | I37: 0 | J37: 0 | K37: 0 | L37: 0 | M37: 0 | N37: 0 | O37: 0 | P37: 0 | Q37: 0 | R37: 0 | S37: 0 | T37: 0 | U37: 0 | V37: 0 | W37: 0 | X37: 0 | Y37: 0 | Z37: 0
A38: Aviation gasoline | B38: O4651 | C38: 0 | D38: 0 | E38: 0 | F38: 0 | G38: 0 | H38: 0 | I38: 0 | J38: 0 | K38: 0 | L38: 0 | M38: 0 | N38: 0 | O38: 0 | P38: 0 | Q38: 0 | R38: 0 | S38: 0 | T38: 0 | U38: 0 | V38: 0 | W38: 0 | X38: 0 | Y38: 0 | Z38: 0
A39: Gasoline-type jet fuel | B39: O4653 | C39: 0 | D39: 0 | E39: 0 | F39: 0 | G39: 0 | H39: 0 | I39: 0 | J39: 0 | K39: 0 | L39: 0 | M39: 0 | N39: 0 | O39: 0 | P39: 0 | Q39: 0 | R39: 0 | S39: 0 | T39: 0 | U39: 0 | V39: 0 | W39: 0 | X39: 0 | Y39: 0 | Z39: 0
A40: Kerosene-type jet fuel (excluding biofuel portion) | B40: O4661XR5230B | C40: 0 | D40: 0 | E40: 0 | F40: 0 | G40: 0 | H40: 0 | I40: 0 | J40: 0 | K40: 0 | L40: 0 | M40: 0 | N40: 0 | O40: 0 | P40: 0 | Q40: 0 | R40: 0 | S40: 0 | T40: 0 | U40: 0 | V40: 0 | W40: 0 | X40: 0 | Y40: 0 | Z40: 0
...

Sheet RCV_RCY
A1: Recovered & recycled products | B1: RCV_RCY | C1: 2000 | D1: 2001 | E1: 2002 | F1: 2003 | G1: 2004 | H1: 2005 | I1: 2006 | J1: 2007 | K1: 2008 | L1: 2009 | M1: 2010 | N1: 2011 | O1: 2012 | P1: 2013 | Q1: 2014 | R1: 2015 | S1: 2016 | T1: 2017 | U1: 2018 | V1: 2019 | W1: 2020 | X1: 2021 | Y1: 2022 | Z1: 2023
A2: Total | B2: TOTAL | C2: =SUM(C3,C17,C22,C25,C26,C51,C52,C71,C74,C75,C76) -> 0 | D2: =SUM(D3,D17,D22,D25,D26,D51,D52,D71,D74,D75,D76) -> 0 | E2: =SUM(E3,E17,E22,E25,E26,E51,E52,E71,E74,E75,E76) -> 0 | F2: =SUM(F3,F17,F22,F25,F26,F51,F52,F71,F74,F75,F76) -> 0 | G2: =SUM(G3,G17,G22,G25,G26,G51,G52,G71,G74,G75,G76) -> 0 | H2: =SUM(H3,H17,H22,H25,H26,H51,H52,H71,H74,H75,H76) -> 0 | I2: =SUM(I3,I17,I22,I25,I26,I51,I52,I71,I74,I75,I76) -> 0 | J2: =SUM(J3,J17,J22,J25,J26,J51,J52,J71,J74,J75,J76) -> 0 | ... Z2: =SUM(Z3,Z17,Z22,Z25,Z26,Z51,Z52,Z71,Z74,Z75,Z76) -> 0
A3: Solid fossil fuels | B3: C0000X0350-0370 | C3: =SUM(C4,C8,C11) -> 0 | D3: =SUM(D4,D8,D11) -> 0 | E3: =SUM(E4,E8,E11) -> 0 | F3: =SUM(F4,F8,F11) -> 0 | G3: =SUM(G4,G8,G11) -> 0 | H3: =SUM(H4,H8,H11) -> 0 | I3: =SUM(I4,I8,I11) -> 0 | J3: =SUM(J4,J8,J11) -> 0 | ... Z3: =SUM(Z4,Z8,Z11) -> 0
A4: Hard coal | B4: C0100 | C4: =SUM(C5:C7) -> 0 | D4: =SUM(D5:D7) -> 0 | E4: =SUM(E5:E7) -> 0 | F4: =SUM(F5:F7) -> 0 | G4: =SUM(G5:G7) -> 0 | H4: =SUM(H5:H7) -> 0 | I4: =SUM(I5:I7) -> 0 | J4: =SUM(J5:J7) -> 0 | ... Z4: =SUM(Z5:Z7) -> 0
A5: Anthracite | B5: C0110 | C5: 0 | D5: 0 | E5: 0 | F5: 0 | G5: 0 | H5: 0 | I5: 0 | J5: 0 | K5: 0 | L5: 0 | M5: 0 | N5: 0 | O5: 0 | P5: 0 | Q5: 0 | R5: 0 | S5: 0 | T5: 0 | U5: 0 | V5: 0 | W5: 0 | X5: 0 | Y5: 0 | Z5: 0
A6: Coking coal | B6: C0121 | C6: 0 | D6: 0 | E6: 0 | F6: 0 | G6: 0 | H6: 0 | I6: 0 | J6: 0 | K6: 0 | L6: 0 | M6: 0 | N6: 0 | O6: 0 | P6: 0 | Q6: 0 | R6: 0 | S6: 0 | T6: 0 | U6: 0 | V6: 0 | W6: 0 | X6: 0 | Y6: 0 | Z6: 0
A7: Other bituminous coal | B7: C0129 | C7: 0 | D7: 0 | E7: 0 | F7: 0 | G7: 0 | H7: 0 | I7: 0 | J7: 0 | K7: 0 | L7: 0 | M7: 0 | N7: 0 | O7: 0 | P7: 0 | Q7: 0 | R7: 0 | S7: 0 | T7: 0 | U7: 0 | V7: 0 | W7: 0 | X7: 0 | Y7: 0 | Z7: 0
A8: Brown coal | B8: C0200 | C8: =SUM(C9:C10) -> 0 | D8: =SUM(D9:D10) -> 0 | E8: =SUM(E9:E10) -> 0 | F8: =SUM(F9:F10) -> 0 | G8: =SUM(G9:G10) -> 0 | H8: =SUM(H9:H10) -> 0 | I8: =SUM(I9:I10) -> 0 | J8: =SUM(J9:J10) -> 0 | ... Z8: =SUM(Z9:Z10) -> 0
A9: Sub-bituminous coal | B9: C0210 | C9: 0 | D9: 0 | E9: 0 | F9: 0 | G9: 0 | H9: 0 | I9: 0 | J9: 0 | K9: 0 | L9: 0 | M9: 0 | N9: 0 | O9: 0 | P9: 0 | Q9: 0 | R9: 0 | S9: 0 | T9: 0 | U9: 0 | V9: 0 | W9: 0 | X9: 0 | Y9: 0 | Z9: 0
A10: Lignite | B10: C0220 | C10: 0 | D10: 0 | E10: 0 | F10: 0 | G10: 0 | H10: 0 | I10: 0 | J10: 0 | K10: 0 | L10: 0 | M10: 0 | N10: 0 | O10: 0 | P10: 0 | Q10: 0 | R10: 0 | S10: 0 | T10: 0 | U10: 0 | V10: 0 | W10: 0 | X10: 0 | Y10: 0 | Z10: 0
A11: Coal products | B11: C0300 | C11: =SUM(C12:C16) -> 0 | D11: =SUM(D12:D16) -> 0 | E11: =SUM(E12:E16) -> 0 | F11: =SUM(F12:F16) -> 0 | G11: =SUM(G12:G16) -> 0 | H11: =SUM(H12:H16) -> 0 | I11: =SUM(I12:I16) -> 0 | J11: =SUM(J12:J16) -> 0 | ... Z11: =SUM(Z12:Z16) -> 0
A12: Patent fuel | B12: C0320 | C12: 0 | D12: 0 | E12: 0 | F12: 0 | G12: 0 | H12: 0 | I12: 0 | J12: 0 | K12: 0 | L12: 0 | M12: 0 | N12: 0 | O12: 0 | P12: 0 | Q12: 0 | R12: 0 | S12: 0 | T12: 0 | U12: 0 | V12: 0 | W12: 0 | X12: 0 | Y12: 0 | Z12: 0
A13: Coke oven coke | B13: C0311 | C13: 0 | D13: 0 | E13: 0 | F13: 0 | G13: 0 | H13: 0 | I13: 0 | J13: 0 | K13: 0 | L13: 0 | M13: 0 | N13: 0 | O13: 0 | P13: 0 | Q13: 0 | R13: 0 | S13: 0 | T13: 0 | U13: 0 | V13: 0 | W13: 0 | X13: 0 | Y13: 0 | Z13: 0
A14: Gas coke | B14: C0312 | C14: 0 | D14: 0 | E14: 0 | F14: 0 | G14: 0 | H14: 0 | I14: 0 | J14: 0 | K14: 0 | L14: 0 | M14: 0 | N14: 0 | O14: 0 | P14: 0 | Q14: 0 | R14: 0 | S14: 0 | T14: 0 | U14: 0 | V14: 0 | W14: 0 | X14: 0 | Y14: 0 | Z14: 0
A15: Coal tar | B15: C0340 | C15: 0 | D15: 0 | E15: 0 | F15: 0 | G15: 0 | H15: 0 | I15: 0 | J15: 0 | K15: 0 | L15: 0 | M15: 0 | N15: 0 | O15: 0 | P15: 0 | Q15: 0 | R15: 0 | S15: 0 | T15: 0 | U15: 0 | V15: 0 | W15: 0 | X15: 0 | Y15: 0 | Z15: 0
A16: Brown coal briquettes | B16: C0330 | C16: 0 | D16: 0 | E16: 0 | F16: 0 | G16: 0 | H16: 0 | I16: 0 | J16: 0 | K16: 0 | L16: 0 | M16: 0 | N16: 0 | O16: 0 | P16: 0 | Q16: 0 | R16: 0 | S16: 0 | T16: 0 | U16: 0 | V16: 0 | W16: 0 | X16: 0 | Y16: 0 | Z16: 0
A17: Manufactured gases | B17: C0350-0370 | C17: =SUM(C18:C21) -> 0 | D17: =SUM(D18:D21) -> 0 | E17: =SUM(E18:E21) -> 0 | F17: =SUM(F18:F21) -> 0 | G17: =SUM(G18:G21) -> 0 | H17: =SUM(H18:H21) -> 0 | I17: =SUM(I18:I21) -> 0 | J17: =SUM(J18:J21) -> 0 | ... Z17: =SUM(Z18:Z21) -> 0
A18: Gas works gas | B18: C0360 | C18: 0 | D18: 0 | E18: 0 | F18: 0 | G18: 0 | H18: 0 | I18: 0 | J18: 0 | K18: 0 | L18: 0 | M18: 0 | N18: 0 | O18: 0 | P18: 0 | Q18: 0 | R18: 0 | S18: 0 | T18: 0 | U18: 0 | V18: 0 | W18: 0 | X18: 0 | Y18: 0 | Z18: 0
A19: Coke oven gas | B19: C0350 | C19: 0 | D19: 0 | E19: 0 | F19: 0 | G19: 0 | H19: 0 | I19: 0 | J19: 0 | K19: 0 | L19: 0 | M19: 0 | N19: 0 | O19: 0 | P19: 0 | Q19: 0 | R19: 0 | S19: 0 | T19: 0 | U19: 0 | V19: 0 | W19: 0 | X19: 0 | Y19: 0 | Z19: 0
A20: Blast furnace gas | B20: C0371 | C20: 0 | D20: 0 | E20: 0 | F20: 0 | G20: 0 | H20: 0 | I20: 0 | J20: 0 | K20: 0 | L20: 0 | M20: 0 | N20: 0 | O20: 0 | P20: 0 | Q20: 0 | R20: 0 | S20: 0 | T20: 0 | U20: 0 | V20: 0 | W20: 0 | X20: 0 | Y20: 0 | Z20: 0
A21: Other recovered gases | B21: C0379 | C21: 0 | D21: 0 | E21: 0 | F21: 0 | G21: 0 | H21: 0 | I21: 0 | J21: 0 | K21: 0 | L21: 0 | M21: 0 | N21: 0 | O21: 0 | P21: 0 | Q21: 0 | R21: 0 | S21: 0 | T21: 0 | U21: 0 | V21: 0 | W21: 0 | X21: 0 | Y21: 0 | Z21: 0
A22: Peat and peat products | B22: P1000 | C22: =SUM(C23:C24) -> 0 | D22: =SUM(D23:D24) -> 0 | E22: =SUM(E23:E24) -> 0 | F22: =SUM(F23:F24) -> 0 | G22: =SUM(G23:G24) -> 0 | H22: =SUM(H23:H24) -> 0 | I22: =SUM(I23:I24) -> 0 | J22: =SUM(J23:J24) -> 0 | ... Z22: =SUM(Z23:Z24) -> 0
A23: Peat | B23: P1100 | C23: 0 | D23: 0 | E23: 0 | F23: 0 | G23: 0 | H23: 0 | I23: 0 | J23: 0 | K23: 0 | L23: 0 | M23: 0 | N23: 0 | O23: 0 | P23: 0 | Q23: 0 | R23: 0 | S23: 0 | T23: 0 | U23: 0 | V23: 0 | W23: 0 | X23: 0 | Y23: 0 | Z23: 0
A24: Peat products | B24: P1200 | C24: 0 | D24: 0 | E24: 0 | F24: 0 | G24: 0 | H24: 0 | I24: 0 | J24: 0 | K24: 0 | L24: 0 | M24: 0 | N24: 0 | O24: 0 | P24: 0 | Q24: 0 | R24: 0 | S24: 0 | T24: 0 | U24: 0 | V24: 0 | W24: 0 | X24: 0 | Y24: 0 | Z24: 0
A25: Oil shale and oil sands | B25: S2000 | C25: 0 | D25: 0 | E25: 0 | F25: 0 | G25: 0 | H25: 0 | I25: 0 | J25: 0 | K25: 0 | L25: 0 | M25: 0 | N25: 0 | O25: 0 | P25: 0 | Q25: 0 | R25: 0 | S25: 0 | T25: 0 | U25: 0 | V25: 0 | W25: 0 | X25: 0 | Y25: 0 | Z25: 0
A26: Oil and petroleum products | B26: O4000XBIO | C26: =SUM(C27,C33) -> 0 | D26: =SUM(D27,D33) -> 0 | E26: =SUM(E27,E33) -> 0 | F26: =SUM(F27,F33) -> 0 | G26: =SUM(G27,G33) -> 0 | H26: =SUM(H27,H33) -> 0 | I26: =SUM(I27,I33) -> 0 | J26: =SUM(J27,J33) -> 0 | ... Z26: =SUM(Z27,Z33) -> 0
A27: Crude oil, NGL, refinery feedstocks, additives and oxygenates and other hydrocarbons (excluding biofuel portion) | B27: O4100_TOT_4200-4500XBIO | C27: =SUM(C28:C32) -> 0 | D27: =SUM(D28:D32) -> 0 | E27: =SUM(E28:E32) -> 0 | F27: =SUM(F28:F32) -> 0 | G27: =SUM(G28:G32) -> 0 | H27: =SUM(H28:H32) -> 0 | I27: =SUM(I28:I32) -> 0 | J27: =SUM(J28:J32) -> 0 | ... Z27: =SUM(Z28:Z32) -> 0
A28: Crude oil | B28: O4100_TOT | C28: 0 | D28: 0 | E28: 0 | F28: 0 | G28: 0 | H28: 0 | I28: 0 | J28: 0 | K28: 0 | L28: 0 | M28: 0 | N28: 0 | O28: 0 | P28: 0 | Q28: 0 | R28: 0 | S28: 0 | T28: 0 | U28: 0 | V28: 0 | W28: 0 | X28: 0 | Y28: 0 | Z28: 0
A29: Natural gas liquids | B29: O4200 | C29: 0 | D29: 0 | E29: 0 | F29: 0 | G29: 0 | H29: 0 | I29: 0 | J29: 0 | K29: 0 | L29: 0 | M29: 0 | N29: 0 | O29: 0 | P29: 0 | Q29: 0 | R29: 0 | S29: 0 | T29: 0 | U29: 0 | V29: 0 | W29: 0 | X29: 0 | Y29: 0 | Z29: 0
A30: Refinery feedstocks | B30: O4300 | C30: 0 | D30: 0 | E30: 0 | F30: 0 | G30: 0 | H30: 0 | I30: 0 | J30: 0 | K30: 0 | L30: 0 | M30: 0 | N30: 0 | O30: 0 | P30: 0 | Q30: 0 | R30: 0 | S30: 0 | T30: 0 | U30: 0 | V30: 0 | W30: 0 | X30: 0 | Y30: 0 | Z30: 0
A31: Additives and oxygenates (excluding biofuel portion) | B31: O4400X4410 | C31: 0 | D31: 0 | E31: 0 | F31: 0 | G31: 0 | H31: 0 | I31: 0 | J31: 0 | K31: 0 | L31: 0 | M31: 0 | N31: 0 | O31: 0 | P31: 0 | Q31: 0 | R31: 0 | S31: 0 | T31: 0 | U31: 0 | V31: 0 | W31: 0 | X31: 0 | Y31: 0 | Z31: 0
A32: Other hydrocarbons | B32: O4500 | C32: 0 | D32: 0 | E32: 0 | F32: 0 | G32: 0 | H32: 0 | I32: 0 | J32: 0 | K32: 0 | L32: 0 | M32: 0 | N32: 0 | O32: 0 | P32: 0 | Q32: 0 | R32: 0 | S32: 0 | T32: 0 | U32: 0 | V32: 0 | W32: 0 | X32: 0 | Y32: 0 | Z32: 0
A33: Oil products (excluding biofuel portion) | B33: O4600XBIO | C33: =SUM(C34:C50) -> 0 | D33: =SUM(D34:D50) -> 0 | E33: =SUM(E34:E50) -> 0 | F33: =SUM(F34:F50) -> 0 | G33: =SUM(G34:G50) -> 0 | H33: =SUM(H34:H50) -> 0 | I33: =SUM(I34:I50) -> 0 | J33: =SUM(J34:J50) -> 0 | ... Z33: =SUM(Z34:Z50) -> 0
A34: Refinery gas | B34: O4610 | C34: 0 | D34: 0 | E34: 0 | F34: 0 | G34: 0 | H34: 0 | I34: 0 | J34: 0 | K34: 0 | L34: 0 | M34: 0 | N34: 0 | O34: 0 | P34: 0 | Q34: 0 | R34: 0 | S34: 0 | T34: 0 | U34: 0 | V34: 0 | W34: 0 | X34: 0 | Y34: 0 | Z34: 0
A35: Ethane | B35: O4620 | C35: 0 | D35: 0 | E35: 0 | F35: 0 | G35: 0 | H35: 0 | I35: 0 | J35: 0 | K35: 0 | L35: 0 | M35: 0 | N35: 0 | O35: 0 | P35: 0 | Q35: 0 | R35: 0 | S35: 0 | T35: 0 | U35: 0 | V35: 0 | W35: 0 | X35: 0 | Y35: 0 | Z35: 0
A36: Liquefied petroleum gases | B36: O4630 | C36: 0 | D36: 0 | E36: 0 | F36: 0 | G36: 0 | H36: 0 | I36: 0 | J36: 0 | K36: 0 | L36: 0 | M36: 0 | N36: 0 | O36: 0 | P36: 0 | Q36: 0 | R36: 0 | S36: 0 | T36: 0 | U36: 0 | V36: 0 | W36: 0 | X36: 0 | Y36: 0 | Z36: 0
A37: Motor gasoline (excluding biofuel portion) | B37: O4652XR5210B | C37: 0 | D37: 0 | E37: 0 | F37: 0 | G37: 0 | H37: 0 | I37: 0 | J37: 0 | K37: 0 | L37: 0 | M37: 0 | N37: 0 | O37: 0 | P37: 0 | Q37: 0 | R37: 0 | S37: 0 | T37: 0 | U37: 0 | V37: 0 | W37: 0 | X37: 0 | Y37: 0 | Z37: 0
A38: Aviation gasoline | B38: O4651 | C38: 0 | D38: 0 | E38: 0 | F38: 0 | G38: 0 | H38: 0 | I38: 0 | J38: 0 | K38: 0 | L38: 0 | M38: 0 | N38: 0 | O38: 0 | P38: 0 | Q38: 0 | R38: 0 | S38: 0 | T38: 0 | U38: 0 | V38: 0 | W38: 0 | X38: 0 | Y38: 0 | Z38: 0
A39: Gasoline-type jet fuel | B39: O4653 | C39: 0 | D39: 0 | E39: 0 | F39: 0 | G39: 0 | H39: 0 | I39: 0 | J39: 0 | K39: 0 | L39: 0 | M39: 0 | N39: 0 | O39: 0 | P39: 0 | Q39: 0 | R39: 0 | S39: 0 | T39: 0 | U39: 0 | V39: 0 | W39: 0 | X39: 0 | Y39: 0 | Z39: 0
A40: Kerosene-type jet fuel (excluding biofuel portion) | B40: O4661XR5230B | C40: 0 | D40: 0 | E40: 0 | F40: 0 | G40: 0 | H40: 0 | I40: 0 | J40: 0 | K40: 0 | L40: 0 | M40: 0 | N40: 0 | O40: 0 | P40: 0 | Q40: 0 | R40: 0 | S40: 0 | T40: 0 | U40: 0 | V40: 0 | W40: 0 | X40: 0 | Y40: 0 | Z40: 0
...

Sheet IMP
A1: Imports | B1: IMP | C1: 2000 | D1: 2001 | E1: 2002 | F1: 2003 | G1: 2004 | H1: 2005 | I1: 2006 | J1: 2007 | K1: 2008 | L1: 2009 | M1: 2010 | N1: 2011 | O1: 2012 | P1: 2013 | Q1: 2014 | R1: 2015 | S1: 2016 | T1: 2017 | U1: 2018 | V1: 2019 | W1: 2020 | X1: 2021 | Y1: 2022 | Z1: 2023
A2: Total | B2: TOTAL | C2: =SUM(C3,C17,C22,C25,C26,C51,C52,C71,C74,C75,C76) -> 1470.6721 | D2: =SUM(D3,D17,D22,D25,D26,D51,D52,D71,D74,D75,D76) -> 1611.4335 | E2: =SUM(E3,E17,E22,E25,E26,E51,E52,E71,E74,E75,E76) -> 1572.3345 | F2: =SUM(F3,F17,F22,F25,F26,F51,F52,F71,F74,F75,F76) -> 1827.9212 | G2: =SUM(G3,G17,G22,G25,G26,G51,G52,G71,G74,G75,G76) -> 1919.4612 | H2: =SUM(H3,H17,H22,H25,H26,H51,H52,H71,H74,H75,H76) -> 1593.6132 | I2: =SUM(I3,I17,I22,I25,I26,I51,I52,I71,I74,I75,I76) -> 1688.9653 | J2: =SUM(J3,J17,J22,J25,J26,J51,J52,J71,J74,J75,J76) -> 1800.0575 | ... Z2: =SUM(Z3,Z17,Z22,Z25,Z26,Z51,Z52,Z71,Z74,Z75,Z76) -> 3208.9316
A3: Solid fossil fuels | B3: C0000X0350-0370 | C3: =SUM(C4,C8,C11) -> 0 | D3: =SUM(D4,D8,D11) -> 0 | E3: =SUM(E4,E8,E11) -> 0 | F3: =SUM(F4,F8,F11) -> 0 | G3: =SUM(G4,G8,G11) -> 0 | H3: =SUM(H4,H8,H11) -> 0 | I3: =SUM(I4,I8,I11) -> 0 | J3: =SUM(J4,J8,J11) -> 0 | ... Z3: =SUM(Z4,Z8,Z11) -> 0
A4: Hard coal | B4: C0100 | C4: =SUM(C5:C7) -> 0 | D4: =SUM(D5:D7) -> 0 | E4: =SUM(E5:E7) -> 0 | F4: =SUM(F5:F7) -> 0 | G4: =SUM(G5:G7) -> 0 | H4: =SUM(H5:H7) -> 0 | I4: =SUM(I5:I7) -> 0 | J4: =SUM(J5:J7) -> 0 | ... Z4: =SUM(Z5:Z7) -> 0
A5: Anthracite | B5: C0110 | C5: 0 | D5: 0 | E5: 0 | F5: 0 | G5: 0 | H5: 0 | I5: 0 | J5: 0 | K5: 0 | L5: 0 | M5: 0 | N5: 0 | O5: 0 | P5: 0 | Q5: 0 | R5: 0 | S5: 0 | T5: 0 | U5: 0 | V5: 0 | W5: 0 | X5: 0 | Y5: 0 | Z5: 0
A6: Coking coal | B6: C0121 | C6: 0 | D6: 0 | E6: 0 | F6: 0 | G6: 0 | H6: 0 | I6: 0 | J6: 0 | K6: 0 | L6: 0 | M6: 0 | N6: 0 | O6: 0 | P6: 0 | Q6: 0 | R6: 0 | S6: 0 | T6: 0 | U6: 0 | V6: 0 | W6: 0 | X6: 0 | Y6: 0 | Z6: 0
A7: Other bituminous coal | B7: C0129 | C7: 0 | D7: 0 | E7: 0 | F7: 0 | G7: 0 | H7: 0 | I7: 0 | J7: 0 | K7: 0 | L7: 0 | M7: 0 | N7: 0 | O7: 0 | P7: 0 | Q7: 0 | R7: 0 | S7: 0 | T7: 0 | U7: 0 | V7: 0 | W7: 0 | X7: 0 | Y7: 0 | Z7: 0
A8: Brown coal | B8: C0200 | C8: =SUM(C9:C10) -> 0 | D8: =SUM(D9:D10) -> 0 | E8: =SUM(E9:E10) -> 0 | F8: =SUM(F9:F10) -> 0 | G8: =SUM(G9:G10) -> 0 | H8: =SUM(H9:H10) -> 0 | I8: =SUM(I9:I10) -> 0 | J8: =SUM(J9:J10) -> 0 | ... Z8: =SUM(Z9:Z10) -> 0
A9: Sub-bituminous coal | B9: C0210 | C9: 0 | D9: 0 | E9: 0 | F9: 0 | G9: 0 | H9: 0 | I9: 0 | J9: 0 | K9: 0 | L9: 0 | M9: 0 | N9: 0 | O9: 0 | P9: 0 | Q9: 0 | R9: 0 | S9: 0 | T9: 0 | U9: 0 | V9: 0 | W9: 0 | X9: 0 | Y9: 0 | Z9: 0
A10: Lignite | B10: C0220 | C10: 0 | D10: 0 | E10: 0 | F10: 0 | G10: 0 | H10: 0 | I10: 0 | J10: 0 | K10: 0 | L10: 0 | M10: 0 | N10: 0 | O10: 0 | P10: 0 | Q10: 0 | R10: 0 | S10: 0 | T10: 0 | U10: 0 | V10: 0 | W10: 0 | X10: 0 | Y10: 0 | Z10: 0
A11: Coal products | B11: C0300 | C11: =SUM(C12:C16) -> 0 | D11: =SUM(D12:D16) -> 0 | E11: =SUM(E12:E16) -> 0 | F11: =SUM(F12:F16) -> 0 | G11: =SUM(G12:G16) -> 0 | H11: =SUM(H12:H16) -> 0 | I11: =SUM(I12:I16) -> 0 | J11: =SUM(J12:J16) -> 0 | ... Z11: =SUM(Z12:Z16) -> 0
A12: Patent fuel | B12: C0320 | C12: 0 | D12: 0 | E12: 0 | F12: 0 | G12: 0 | H12: 0 | I12: 0 | J12: 0 | K12: 0 | L12: 0 | M12: 0 | N12: 0 | O12: 0 | P12: 0 | Q12: 0 | R12: 0 | S12: 0 | T12: 0 | U12: 0 | V12: 0 | W12: 0 | X12: 0 | Y12: 0 | Z12: 0
A13: Coke oven coke | B13: C0311 | C13: 0 | D13: 0 | E13: 0 | F13: 0 | G13: 0 | H13: 0 | I13: 0 | J13: 0 | K13: 0 | L13: 0 | M13: 0 | N13: 0 | O13: 0 | P13: 0 | Q13: 0 | R13: 0 | S13: 0 | T13: 0 | U13: 0 | V13: 0 | W13: 0 | X13: 0 | Y13: 0 | Z13: 0
A14: Gas coke | B14: C0312 | C14: 0 | D14: 0 | E14: 0 | F14: 0 | G14: 0 | H14: 0 | I14: 0 | J14: 0 | K14: 0 | L14: 0 | M14: 0 | N14: 0 | O14: 0 | P14: 0 | Q14: 0 | R14: 0 | S14: 0 | T14: 0 | U14: 0 | V14: 0 | W14: 0 | X14: 0 | Y14: 0 | Z14: 0
A15: Coal tar | B15: C0340 | C15: 0 | D15: 0 | E15: 0 | F15: 0 | G15: 0 | H15: 0 | I15: 0 | J15: 0 | K15: 0 | L15: 0 | M15: 0 | N15: 0 | O15: 0 | P15: 0 | Q15: 0 | R15: 0 | S15: 0 | T15: 0 | U15: 0 | V15: 0 | W15: 0 | X15: 0 | Y15: 0 | Z15: 0
A16: Brown coal briquettes | B16: C0330 | C16: 0 | D16: 0 | E16: 0 | F16: 0 | G16: 0 | H16: 0 | I16: 0 | J16: 0 | K16: 0 | L16: 0 | M16: 0 | N16: 0 | O16: 0 | P16: 0 | Q16: 0 | R16: 0 | S16: 0 | T16: 0 | U16: 0 | V16: 0 | W16: 0 | X16: 0 | Y16: 0 | Z16: 0
A17: Manufactured gases | B17: C0350-0370 | C17: =SUM(C18:C21) -> 0 | D17: =SUM(D18:D21) -> 0 | E17: =SUM(E18:E21) -> 0 | F17: =SUM(F18:F21) -> 0 | G17: =SUM(G18:G21) -> 0 | H17: =SUM(H18:H21) -> 0 | I17: =SUM(I18:I21) -> 0 | J17: =SUM(J18:J21) -> 0 | ... Z17: =SUM(Z18:Z21) -> 0
A18: Gas works gas | B18: C0360 | C18: 0 | D18: 0 | E18: 0 | F18: 0 | G18: 0 | H18: 0 | I18: 0 | J18: 0 | K18: 0 | L18: 0 | M18: 0 | N18: 0 | O18: 0 | P18: 0 | Q18: 0 | R18: 0 | S18: 0 | T18: 0 | U18: 0 | V18: 0 | W18: 0 | X18: 0 | Y18: 0 | Z18: 0
A19: Coke oven gas | B19: C0350 | C19: 0 | D19: 0 | E19: 0 | F19: 0 | G19: 0 | H19: 0 | I19: 0 | J19: 0 | K19: 0 | L19: 0 | M19: 0 | N19: 0 | O19: 0 | P19: 0 | Q19: 0 | R19: 0 | S19: 0 | T19: 0 | U19: 0 | V19: 0 | W19: 0 | X19: 0 | Y19: 0 | Z19: 0
A20: Blast furnace gas | B20: C0371 | C20: 0 | D20: 0 | E20: 0 | F20: 0 | G20: 0 | H20: 0 | I20: 0 | J20: 0 | K20: 0 | L20: 0 | M20: 0 | N20: 0 | O20: 0 | P20: 0 | Q20: 0 | R20: 0 | S20: 0 | T20: 0 | U20: 0 | V20: 0 | W20: 0 | X20: 0 | Y20: 0 | Z20: 0
A21: Other recovered gases | B21: C0379 | C21: 0 | D21: 0 | E21: 0 | F21: 0 | G21: 0 | H21: 0 | I21: 0 | J21: 0 | K21: 0 | L21: 0 | M21: 0 | N21: 0 | O21: 0 | P21: 0 | Q21: 0 | R21: 0 | S21: 0 | T21: 0 | U21: 0 | V21: 0 | W21: 0 | X21: 0 | Y21: 0 | Z21: 0
A22: Peat and peat products | B22: P1000 | C22: =SUM(C23:C24) -> 0 | D22: =SUM(D23:D24) -> 0 | E22: =SUM(E23:E24) -> 0 | F22: =SUM(F23:F24) -> 0 | G22: =SUM(G23:G24) -> 0 | H22: =SUM(H23:H24) -> 0 | I22: =SUM(I23:I24) -> 0 | J22: =SUM(J23:J24) -> 0 | ... Z22: =SUM(Z23:Z24) -> 0
A23: Peat | B23: P1100 | C23: 0 | D23: 0 | E23: 0 | F23: 0 | G23: 0 | H23: 0 | I23: 0 | J23: 0 | K23: 0 | L23: 0 | M23: 0 | N23: 0 | O23: 0 | P23: 0 | Q23: 0 | R23: 0 | S23: 0 | T23: 0 | U23: 0 | V23: 0 | W23: 0 | X23: 0 | Y23: 0 | Z23: 0
A24: Peat products | B24: P1200 | C24: 0 | D24: 0 | E24: 0 | F24: 0 | G24: 0 | H24: 0 | I24: 0 | J24: 0 | K24: 0 | L24: 0 | M24: 0 | N24: 0 | O24: 0 | P24: 0 | Q24: 0 | R24: 0 | S24: 0 | T24: 0 | U24: 0 | V24: 0 | W24: 0 | X24: 0 | Y24: 0 | Z24: 0
A25: Oil shale and oil sands | B25: S2000 | C25: 0 | D25: 0 | E25: 0 | F25: 0 | G25: 0 | H25: 0 | I25: 0 | J25: 0 | K25: 0 | L25: 0 | M25: 0 | N25: 0 | O25: 0 | P25: 0 | Q25: 0 | R25: 0 | S25: 0 | T25: 0 | U25: 0 | V25: 0 | W25: 0 | X25: 0 | Y25: 0 | Z25: 0
A26: Oil and petroleum products | B26: O4000XBIO | C26: =SUM(C27,C33) -> 1470.6721 | D26: =SUM(D27,D33) -> 1611.4335 | E26: =SUM(E27,E33) -> 1572.3345 | F26: =SUM(F27,F33) -> 1827.9212 | G26: =SUM(G27,G33) -> 1919.4612 | H26: =SUM(H27,H33) -> 1593.6132 | I26: =SUM(I27,I33) -> 1688.9653 | J26: =SUM(J27,J33) -> 1800.0575 | ... Z26: =SUM(Z27,Z33) -> 2825.2265
A27: Crude oil, NGL, refinery feedstocks, additives and oxygenates and other hydrocarbons (excluding biofuel portion) | B27: O4100_TOT_4200-4500XBIO | C27: =SUM(C28:C32) -> 0 | D27: =SUM(D28:D32) -> 0 | E27: =SUM(E28:E32) -> 0 | F27: =SUM(F28:F32) -> 0 | G27: =SUM(G28:G32) -> 0 | H27: =SUM(H28:H32) -> 0 | I27: =SUM(I28:I32) -> 0 | J27: =SUM(J28:J32) -> 0 | ... Z27: =SUM(Z28:Z32) -> 0
A28: Crude oil | B28: O4100_TOT | C28: 0 | D28: 0 | E28: 0 | F28: 0 | G28: 0 | H28: 0 | I28: 0 | J28: 0 | K28: 0 | L28: 0 | M28: 0 | N28: 0 | O28: 0 | P28: 0 | Q28: 0 | R28: 0 | S28: 0 | T28: 0 | U28: 0 | V28: 0 | W28: 0 | X28: 0 | Y28: 0 | Z28: 0
A29: Natural gas liquids | B29: O4200 | C29: 0 | D29: 0 | E29: 0 | F29: 0 | G29: 0 | H29: 0 | I29: 0 | J29: 0 | K29: 0 | L29: 0 | M29: 0 | N29: 0 | O29: 0 | P29: 0 | Q29: 0 | R29: 0 | S29: 0 | T29: 0 | U29: 0 | V29: 0 | W29: 0 | X29: 0 | Y29: 0 | Z29: 0
A30: Refinery feedstocks | B30: O4300 | C30: 0 | D30: 0 | E30: 0 | F30: 0 | G30: 0 | H30: 0 | I30: 0 | J30: 0 | K30: 0 | L30: 0 | M30: 0 | N30: 0 | O30: 0 | P30: 0 | Q30: 0 | R30: 0 | S30: 0 | T30: 0 | U30: 0 | V30: 0 | W30: 0 | X30: 0 | Y30: 0 | Z30: 0
A31: Additives and oxygenates (excluding biofuel portion) | B31: O4400X4410 | C31: 0 | D31: 0 | E31: 0 | F31: 0 | G31: 0 | H31: 0 | I31: 0 | J31: 0 | K31: 0 | L31: 0 | M31: 0 | N31: 0 | O31: 0 | P31: 0 | Q31: 0 | R31: 0 | S31: 0 | T31: 0 | U31: 0 | V31: 0 | W31: 0 | X31: 0 | Y31: 0 | Z31: 0
A32: Other hydrocarbons | B32: O4500 | C32: 0 | D32: 0 | E32: 0 | F32: 0 | G32: 0 | H32: 0 | I32: 0 | J32: 0 | K32: 0 | L32: 0 | M32: 0 | N32: 0 | O32: 0 | P32: 0 | Q32: 0 | R32: 0 | S32: 0 | T32: 0 | U32: 0 | V32: 0 | W32: 0 | X32: 0 | Y32: 0 | Z32: 0
A33: Oil products (excluding biofuel portion) | B33: O4600XBIO | C33: =SUM(C34:C50) -> 1470.6721 | D33: =SUM(D34:D50) -> 1611.4335 | E33: =SUM(E34:E50) -> 1572.3345 | F33: =SUM(F34:F50) -> 1827.9212 | G33: =SUM(G34:G50) -> 1919.4612 | H33: =SUM(H34:H50) -> 1593.6132 | I33: =SUM(I34:I50) -> 1688.9653 | J33: =SUM(J34:J50) -> 1800.0575 | ... Z33: =SUM(Z34:Z50) -> 2825.2265
A34: Refinery gas | B34: O4610 | C34: 0 | D34: 0 | E34: 0 | F34: 0 | G34: 0 | H34: 0 | I34: 0 | J34: 0 | K34: 0 | L34: 0 | M34: 0 | N34: 0 | O34: 0 | P34: 0 | Q34: 0 | R34: 0 | S34: 0 | T34: 0 | U34: 0 | V34: 0 | W34: 0 | X34: 0 | Y34: 0 | Z34: 0
A35: Ethane | B35: O4620 | C35: 0 | D35: 0 | E35: 0 | F35: 0 | G35: 0 | H35: 0 | I35: 0 | J35: 0 | K35: 0 | L35: 0 | M35: 0 | N35: 0 | O35: 0 | P35: 0 | Q35: 0 | R35: 0 | S35: 0 | T35: 0 | U35: 0 | V35: 0 | W35: 0 | X35: 0 | Y35: 0 | Z35: 0
A36: Liquefied petroleum gases | B36: O4630 | C36: 18.075838 | D36: 18.075838 | E36: 19.205589 | F36: 19.205589 | G36: 19.205589 | H36: 19.77644 | I36: 21.973861 | J36: 21.973861 | K36: 23.072485 | L36: 26.368616 | M36: 24.171195 | N36: 23.072485 | O36: 25.269905 | P36: 24.171195 | Q36: 24.171195 | R36: 25.269905 | S36: 18.67773 | T36: 25.707137 | U36: 29.850301 | V36: 27.760619 | W36: 27.566122 | X36: 25.752193 | Y36: 27.084953 | Z36: 27.887016
A37: Motor gasoline (excluding biofuel portion) | B37: O4652XR5210B | C37: 74.066122 | D37: 70.891831 | E37: 79.356578 | F37: 74.066122 | G37: 61.369046 | H37: 67.784437 | I37: 67.784437 | J37: 70.865606 | K37: 87.298194 | L37: 77.027773 | M37: 70.865606 | N37: 84.217025 | O37: 65.730353 | P37: 74.973689 | Q37: 80.108942 | R37: 79.081857 | S37: 71.892605 | T37: 86.564832 | U37: 81.398882 | V37: 78.475924 | W37: 76.741273 | X37: 81.465606 | Y37: 93.247807 | Z37: 79.018229
A38: Aviation gasoline | B38: O4651 | C38: 1.0581255 | D38: 1.0581255 | E38: 0 | F38: 0 | G38: 1.0581255 | H38: 0 | I38: 0 | J38: 0 | K38: 0 | L38: 0 | M38: 0 | N38: 0 | O38: 1.0581255 | P38: 0 | Q38: 0 | R38: 0 | S38: 0 | T38: 0.035769561 | U38: 0.050472915 | V38: 0.046259673 | W38: 0.03155632 | X38: 0.068271711 | Y38: 0.064144454 | Z38: 0.066208083
A39: Gasoline-type jet fuel | B39: O4653 | C39: 0 | D39: 0 | E39: 0 | F39: 0 | G39: 0 | H39: 0 | I39: 0 | J39: 0 | K39: 0 | L39: 0 | M39: 0 | N39: 0 | O39: 0 | P39: 0 | Q39: 0 | R39: 0 | S39: 0 | T39: 0 | U39: 0 | V39: 0 | W39: 0 | X39: 0 | Y39: 0 | Z39: 0
A40: Kerosene-type jet fuel (excluding biofuel portion) | B40: O4661XR5230B | C40: 120.07739 | D40: 93.744626 | E40: 91.638005 | F40: 81.104901 | G40: 103.22442 | H40: 89.352279 | I40: 90.379278 | J40: 94.487446 | K40: 97.56853 | L40: 62.649269 | M40: 96.541531 | N40: 109.89304 | O40: 102.7037 | P40: 116.0552 | Q40: 110.92003 | R40: 119.13637 | S40: 124.27154 | T40: 156.19699 | U40: 146.75649 | V40: 178.82055 | W40: 52.586328 | X40: 75.229493 | Y40: 128.2123 | Z40: 151.53422
...

Sheet EXP
A1: Exports | B1: EXP | C1: 2000 | D1: 2001 | E1: 2002 | F1: 2003 | G1: 2004 | H1: 2005 | I1: 2006 | J1: 2007 | K1: 2008 | L1: 2009 | M1: 2010 | N1: 2011 | O1: 2012 | P1: 2013 | Q1: 2014 | R1: 2015 | S1: 2016 | T1: 2017 | U1: 2018 | V1: 2019 | W1: 2020 | X1: 2021 | Y1: 2022 | Z1: 2023
A2: Total | B2: TOTAL | C2: =SUM(C3,C17,C22,C25,C26,C51,C52,C71,C74,C75,C76) -> 0 | D2: =SUM(D3,D17,D22,D25,D26,D51,D52,D71,D74,D75,D76) -> 0 | E2: =SUM(E3,E17,E22,E25,E26,E51,E52,E71,E74,E75,E76) -> 0 | F2: =SUM(F3,F17,F22,F25,F26,F51,F52,F71,F74,F75,F76) -> 0 | G2: =SUM(G3,G17,G22,G25,G26,G51,G52,G71,G74,G75,G76) -> 0 | H2: =SUM(H3,H17,H22,H25,H26,H51,H52,H71,H74,H75,H76) -> 0 | I2: =SUM(I3,I17,I22,I25,I26,I51,I52,I71,I74,I75,I76) -> 0 | J2: =SUM(J3,J17,J22,J25,J26,J51,J52,J71,J74,J75,J76) -> 0 | ... Z2: =SUM(Z3,Z17,Z22,Z25,Z26,Z51,Z52,Z71,Z74,Z75,Z76) -> 92.068702
A3: Solid fossil fuels | B3: C0000X0350-0370 | C3: =SUM(C4,C8,C11) -> 0 | D3: =SUM(D4,D8,D11) -> 0 | E3: =SUM(E4,E8,E11) -> 0 | F3: =SUM(F4,F8,F11) -> 0 | G3: =SUM(G4,G8,G11) -> 0 | H3: =SUM(H4,H8,H11) -> 0 | I3: =SUM(I4,I8,I11) -> 0 | J3: =SUM(J4,J8,J11) -> 0 | ... Z3: =SUM(Z4,Z8,Z11) -> 0
A4: Hard coal | B4: C0100 | C4: =SUM(C5:C7) -> 0 | D4: =SUM(D5:D7) -> 0 | E4: =SUM(E5:E7) -> 0 | F4: =SUM(F5:F7) -> 0 | G4: =SUM(G5:G7) -> 0 | H4: =SUM(H5:H7) -> 0 | I4: =SUM(I5:I7) -> 0 | J4: =SUM(J5:J7) -> 0 | ... Z4: =SUM(Z5:Z7) -> 0
A5: Anthracite | B5: C0110 | C5: 0 | D5: 0 | E5: 0 | F5: 0 | G5: 0 | H5: 0 | I5: 0 | J5: 0 | K5: 0 | L5: 0 | M5: 0 | N5: 0 | O5: 0 | P5: 0 | Q5: 0 | R5: 0 | S5: 0 | T5: 0 | U5: 0 | V5: 0 | W5: 0 | X5: 0 | Y5: 0 | Z5: 0
A6: Coking coal | B6: C0121 | C6: 0 | D6: 0 | E6: 0 | F6: 0 | G6: 0 | H6: 0 | I6: 0 | J6: 0 | K6: 0 | L6: 0 | M6: 0 | N6: 0 | O6: 0 | P6: 0 | Q6: 0 | R6: 0 | S6: 0 | T6: 0 | U6: 0 | V6: 0 | W6: 0 | X6: 0 | Y6: 0 | Z6: 0
A7: Other bituminous coal | B7: C0129 | C7: 0 | D7: 0 | E7: 0 | F7: 0 | G7: 0 | H7: 0 | I7: 0 | J7: 0 | K7: 0 | L7: 0 | M7: 0 | N7: 0 | O7: 0 | P7: 0 | Q7: 0 | R7: 0 | S7: 0 | T7: 0 | U7: 0 | V7: 0 | W7: 0 | X7: 0 | Y7: 0 | Z7: 0
A8: Brown coal | B8: C0200 | C8: =SUM(C9:C10) -> 0 | D8: =SUM(D9:D10) -> 0 | E8: =SUM(E9:E10) -> 0 | F8: =SUM(F9:F10) -> 0 | G8: =SUM(G9:G10) -> 0 | H8: =SUM(H9:H10) -> 0 | I8: =SUM(I9:I10) -> 0 | J8: =SUM(J9:J10) -> 0 | ... Z8: =SUM(Z9:Z10) -> 0
A9: Sub-bituminous coal | B9: C0210 | C9: 0 | D9: 0 | E9: 0 | F9: 0 | G9: 0 | H9: 0 | I9: 0 | J9: 0 | K9: 0 | L9: 0 | M9: 0 | N9: 0 | O9: 0 | P9: 0 | Q9: 0 | R9: 0 | S9: 0 | T9: 0 | U9: 0 | V9: 0 | W9: 0 | X9: 0 | Y9: 0 | Z9: 0
A10: Lignite | B10: C0220 | C10: 0 | D10: 0 | E10: 0 | F10: 0 | G10: 0 | H10: 0 | I10: 0 | J10: 0 | K10: 0 | L10: 0 | M10: 0 | N10: 0 | O10: 0 | P10: 0 | Q10: 0 | R10: 0 | S10: 0 | T10: 0 | U10: 0 | V10: 0 | W10: 0 | X10: 0 | Y10: 0 | Z10: 0
A11: Coal products | B11: C0300 | C11: =SUM(C12:C16) -> 0 | D11: =SUM(D12:D16) -> 0 | E11: =SUM(E12:E16) -> 0 | F11: =SUM(F12:F16) -> 0 | G11: =SUM(G12:G16) -> 0 | H11: =SUM(H12:H16) -> 0 | I11: =SUM(I12:I16) -> 0 | J11: =SUM(J12:J16) -> 0 | ... Z11: =SUM(Z12:Z16) -> 0
A12: Patent fuel | B12: C0320 | C12: 0 | D12: 0 | E12: 0 | F12: 0 | G12: 0 | H12: 0 | I12: 0 | J12: 0 | K12: 0 | L12: 0 | M12: 0 | N12: 0 | O12: 0 | P12: 0 | Q12: 0 | R12: 0 | S12: 0 | T12: 0 | U12: 0 | V12: 0 | W12: 0 | X12: 0 | Y12: 0 | Z12: 0
A13: Coke oven coke | B13: C0311 | C13: 0 | D13: 0 | E13: 0 | F13: 0 | G13: 0 | H13: 0 | I13: 0 | J13: 0 | K13: 0 | L13: 0 | M13: 0 | N13: 0 | O13: 0 | P13: 0 | Q13: 0 | R13: 0 | S13: 0 | T13: 0 | U13: 0 | V13: 0 | W13: 0 | X13: 0 | Y13: 0 | Z13: 0
A14: Gas coke | B14: C0312 | C14: 0 | D14: 0 | E14: 0 | F14: 0 | G14: 0 | H14: 0 | I14: 0 | J14: 0 | K14: 0 | L14: 0 | M14: 0 | N14: 0 | O14: 0 | P14: 0 | Q14: 0 | R14: 0 | S14: 0 | T14: 0 | U14: 0 | V14: 0 | W14: 0 | X14: 0 | Y14: 0 | Z14: 0
A15: Coal tar | B15: C0340 | C15: 0 | D15: 0 | E15: 0 | F15: 0 | G15: 0 | H15: 0 | I15: 0 | J15: 0 | K15: 0 | L15: 0 | M15: 0 | N15: 0 | O15: 0 | P15: 0 | Q15: 0 | R15: 0 | S15: 0 | T15: 0 | U15: 0 | V15: 0 | W15: 0 | X15: 0 | Y15: 0 | Z15: 0
A16: Brown coal briquettes | B16: C0330 | C16: 0 | D16: 0 | E16: 0 | F16: 0 | G16: 0 | H16: 0 | I16: 0 | J16: 0 | K16: 0 | L16: 0 | M16: 0 | N16: 0 | O16: 0 | P16: 0 | Q16: 0 | R16: 0 | S16: 0 | T16: 0 | U16: 0 | V16: 0 | W16: 0 | X16: 0 | Y16: 0 | Z16: 0
A17: Manufactured gases | B17: C0350-0370 | C17: =SUM(C18:C21) -> 0 | D17: =SUM(D18:D21) -> 0 | E17: =SUM(E18:E21) -> 0 | F17: =SUM(F18:F21) -> 0 | G17: =SUM(G18:G21) -> 0 | H17: =SUM(H18:H21) -> 0 | I17: =SUM(I18:I21) -> 0 | J17: =SUM(J18:J21) -> 0 | ... Z17: =SUM(Z18:Z21) -> 0
A18: Gas works gas | B18: C0360 | C18: 0 | D18: 0 | E18: 0 | F18: 0 | G18: 0 | H18: 0 | I18: 0 | J18: 0 | K18: 0 | L18: 0 | M18: 0 | N18: 0 | O18: 0 | P18: 0 | Q18: 0 | R18: 0 | S18: 0 | T18: 0 | U18: 0 | V18: 0 | W18: 0 | X18: 0 | Y18: 0 | Z18: 0
A19: Coke oven gas | B19: C0350 | C19: 0 | D19: 0 | E19: 0 | F19: 0 | G19: 0 | H19: 0 | I19: 0 | J19: 0 | K19: 0 | L19: 0 | M19: 0 | N19: 0 | O19: 0 | P19: 0 | Q19: 0 | R19: 0 | S19: 0 | T19: 0 | U19: 0 | V19: 0 | W19: 0 | X19: 0 | Y19: 0 | Z19: 0
A20: Blast furnace gas | B20: C0371 | C20: 0 | D20: 0 | E20: 0 | F20: 0 | G20: 0 | H20: 0 | I20: 0 | J20: 0 | K20: 0 | L20: 0 | M20: 0 | N20: 0 | O20: 0 | P20: 0 | Q20: 0 | R20: 0 | S20: 0 | T20: 0 | U20: 0 | V20: 0 | W20: 0 | X20: 0 | Y20: 0 | Z20: 0
A21: Other recovered gases | B21: C0379 | C21: 0 | D21: 0 | E21: 0 | F21: 0 | G21: 0 | H21: 0 | I21: 0 | J21: 0 | K21: 0 | L21: 0 | M21: 0 | N21: 0 | O21: 0 | P21: 0 | Q21: 0 | R21: 0 | S21: 0 | T21: 0 | U21: 0 | V21: 0 | W21: 0 | X21: 0 | Y21: 0 | Z21: 0
A22: Peat and peat products | B22: P1000 | C22: =SUM(C23:C24) -> 0 | D22: =SUM(D23:D24) -> 0 | E22: =SUM(E23:E24) -> 0 | F22: =SUM(F23:F24) -> 0 | G22: =SUM(G23:G24) -> 0 | H22: =SUM(H23:H24) -> 0 | I22: =SUM(I23:I24) -> 0 | J22: =SUM(J23:J24) -> 0 | ... Z22: =SUM(Z23:Z24) -> 0
A23: Peat | B23: P1100 | C23: 0 | D23: 0 | E23: 0 | F23: 0 | G23: 0 | H23: 0 | I23: 0 | J23: 0 | K23: 0 | L23: 0 | M23: 0 | N23: 0 | O23: 0 | P23: 0 | Q23: 0 | R23: 0 | S23: 0 | T23: 0 | U23: 0 | V23: 0 | W23: 0 | X23: 0 | Y23: 0 | Z23: 0
A24: Peat products | B24: P1200 | C24: 0 | D24: 0 | E24: 0 | F24: 0 | G24: 0 | H24: 0 | I24: 0 | J24: 0 | K24: 0 | L24: 0 | M24: 0 | N24: 0 | O24: 0 | P24: 0 | Q24: 0 | R24: 0 | S24: 0 | T24: 0 | U24: 0 | V24: 0 | W24: 0 | X24: 0 | Y24: 0 | Z24: 0
A25: Oil shale and oil sands | B25: S2000 | C25: 0 | D25: 0 | E25: 0 | F25: 0 | G25: 0 | H25: 0 | I25: 0 | J25: 0 | K25: 0 | L25: 0 | M25: 0 | N25: 0 | O25: 0 | P25: 0 | Q25: 0 | R25: 0 | S25: 0 | T25: 0 | U25: 0 | V25: 0 | W25: 0 | X25: 0 | Y25: 0 | Z25: 0
A26: Oil and petroleum products | B26: O4000XBIO | C26: =SUM(C27,C33) -> 0 | D26: =SUM(D27,D33) -> 0 | E26: =SUM(E27,E33) -> 0 | F26: =SUM(F27,F33) -> 0 | G26: =SUM(G27,G33) -> 0 | H26: =SUM(H27,H33) -> 0 | I26: =SUM(I27,I33) -> 0 | J26: =SUM(J27,J33) -> 0 | ... Z26: =SUM(Z27,Z33) -> 89.813672
A27: Crude oil, NGL, refinery feedstocks, additives and oxygenates and other hydrocarbons (excluding biofuel portion) | B27: O4100_TOT_4200-4500XBIO | C27: =SUM(C28:C32) -> 0 | D27: =SUM(D28:D32) -> 0 | E27: =SUM(E28:E32) -> 0 | F27: =SUM(F28:F32) -> 0 | G27: =SUM(G28:G32) -> 0 | H27: =SUM(H28:H32) -> 0 | I27: =SUM(I28:I32) -> 0 | J27: =SUM(J28:J32) -> 0 | ... Z27: =SUM(Z28:Z32) -> 0
A28: Crude oil | B28: O4100_TOT | C28: 0 | D28: 0 | E28: 0 | F28: 0 | G28: 0 | H28: 0 | I28: 0 | J28: 0 | K28: 0 | L28: 0 | M28: 0 | N28: 0 | O28: 0 | P28: 0 | Q28: 0 | R28: 0 | S28: 0 | T28: 0 | U28: 0 | V28: 0 | W28: 0 | X28: 0 | Y28: 0 | Z28: 0
A29: Natural gas liquids | B29: O4200 | C29: 0 | D29: 0 | E29: 0 | F29: 0 | G29: 0 | H29: 0 | I29: 0 | J29: 0 | K29: 0 | L29: 0 | M29: 0 | N29: 0 | O29: 0 | P29: 0 | Q29: 0 | R29: 0 | S29: 0 | T29: 0 | U29: 0 | V29: 0 | W29: 0 | X29: 0 | Y29: 0 | Z29: 0
A30: Refinery feedstocks | B30: O4300 | C30: 0 | D30: 0 | E30: 0 | F30: 0 | G30: 0 | H30: 0 | I30: 0 | J30: 0 | K30: 0 | L30: 0 | M30: 0 | N30: 0 | O30: 0 | P30: 0 | Q30: 0 | R30: 0 | S30: 0 | T30: 0 | U30: 0 | V30: 0 | W30: 0 | X30: 0 | Y30: 0 | Z30: 0
A31: Additives and oxygenates (excluding biofuel portion) | B31: O4400X4410 | C31: 0 | D31: 0 | E31: 0 | F31: 0 | G31: 0 | H31: 0 | I31: 0 | J31: 0 | K31: 0 | L31: 0 | M31: 0 | N31: 0 | O31: 0 | P31: 0 | Q31: 0 | R31: 0 | S31: 0 | T31: 0 | U31: 0 | V31: 0 | W31: 0 | X31: 0 | Y31: 0 | Z31: 0
A32: Other hydrocarbons | B32: O4500 | C32: 0 | D32: 0 | E32: 0 | F32: 0 | G32: 0 | H32: 0 | I32: 0 | J32: 0 | K32: 0 | L32: 0 | M32: 0 | N32: 0 | O32: 0 | P32: 0 | Q32: 0 | R32: 0 | S32: 0 | T32: 0 | U32: 0 | V32: 0 | W32: 0 | X32: 0 | Y32: 0 | Z32: 0
A33: Oil products (excluding biofuel portion) | B33: O4600XBIO | C33: =SUM(C34:C50) -> 0 | D33: =SUM(D34:D50) -> 0 | E33: =SUM(E34:E50) -> 0 | F33: =SUM(F34:F50) -> 0 | G33: =SUM(G34:G50) -> 0 | H33: =SUM(H34:H50) -> 0 | I33: =SUM(I34:I50) -> 0 | J33: =SUM(J34:J50) -> 0 | ... Z33: =SUM(Z34:Z50) -> 89.813672
A34: Refinery gas | B34: O4610 | C34: 0 | D34: 0 | E34: 0 | F34: 0 | G34: 0 | H34: 0 | I34: 0 | J34: 0 | K34: 0 | L34: 0 | M34: 0 | N34: 0 | O34: 0 | P34: 0 | Q34: 0 | R34: 0 | S34: 0 | T34: 0 | U34: 0 | V34: 0 | W34: 0 | X34: 0 | Y34: 0 | Z34: 0
A35: Ethane | B35: O4620 | C35: 0 | D35: 0 | E35: 0 | F35: 0 | G35: 0 | H35: 0 | I35: 0 | J35: 0 | K35: 0 | L35: 0 | M35: 0 | N35: 0 | O35: 0 | P35: 0 | Q35: 0 | R35: 0 | S35: 0 | T35: 0 | U35: 0 | V35: 0 | W35: 0 | X35: 0 | Y35: 0 | Z35: 0
A36: Liquefied petroleum gases | B36: O4630 | C36: 0 | D36: 0 | E36: 0 | F36: 0 | G36: 0 | H36: 0 | I36: 0 | J36: 0 | K36: 0 | L36: 0 | M36: 0 | N36: 0 | O36: 0 | P36: 0 | Q36: 0 | R36: 0 | S36: 0 | T36: 0 | U36: 0 | V36: 0 | W36: 0 | X36: 0 | Y36: 0 | Z36: 0
A37: Motor gasoline (excluding biofuel portion) | B37: O4652XR5210B | C37: 0 | D37: 0 | E37: 0 | F37: 0 | G37: 0 | H37: 0 | I37: 0 | J37: 0 | K37: 0 | L37: 0 | M37: 0 | N37: 0 | O37: 0 | P37: 0 | Q37: 0 | R37: 0 | S37: 0 | T37: 0 | U37: 0 | V37: 0 | W37: 0 | X37: 0 | Y37: 0 | Z37: 0
A38: Aviation gasoline | B38: O4651 | C38: 0 | D38: 0 | E38: 0 | F38: 0 | G38: 0 | H38: 0 | I38: 0 | J38: 0 | K38: 0 | L38: 0 | M38: 0 | N38: 0 | O38: 1.0581255 | P38: 0 | Q38: 0 | R38: 0 | S38: 0 | T38: 0 | U38: 0 | V38: 0 | W38: 0 | X38: 0 | Y38: 0 | Z38: 0
A39: Gasoline-type jet fuel | B39: O4653 | C39: 0 | D39: 0 | E39: 0 | F39: 0 | G39: 0 | H39: 0 | I39: 0 | J39: 0 | K39: 0 | L39: 0 | M39: 0 | N39: 0 | O39: 0 | P39: 0 | Q39: 0 | R39: 0 | S39: 0 | T39: 0 | U39: 0 | V39: 0 | W39: 0 | X39: 0 | Y39: 0 | Z39: 0
A40: Kerosene-type jet fuel (excluding biofuel portion) | B40: O4661XR5230B | C40: 0 | D40: 0 | E40: 0 | F40: 0 | G40: 0 | H40: 0 | I40: 0 | J40: 0 | K40: 0 | L40: 0 | M40: 0 | N40: 0 | O40: 0 | P40: 10.270335 | Q40: 0 | R40: 0 | S40: 0 | T40: 0 | U40: 0 | V40: 0 | W40: 0 | X40: 0 | Y40: 0 | Z40: 0
...

Sheet STK_CHG
A1: Change in stock | B1: STK_CHG | C1: 2000 | D1: 2001 | E1: 2002 | F1: 2003 | G1: 2004 | H1: 2005 | I1: 2006 | J1: 2007 | K1: 2008 | L1: 2009 | M1: 2010 | N1: 2011 | O1: 2012 | P1: 2013 | Q1: 2014 | R1: 2015 | S1: 2016 | T1: 2017 | U1: 2018 | V1: 2019 | W1: 2020 | X1: 2021 | Y1: 2022 | Z1: 2023
