Workbook

Sheet cover
B6: JRC-IDEES-2023 - Integrated Database of the European Energy System
C10: Cyprus
C15: Services and Agriculture sector
L28: Prepared by JRC C.6
L30: 45967.473
L31: v2023-1.00
B33: Legal Notice
B35: The information made available is property of the Joint Research Centre of the European Commission.
B36: Neither the European Commission nor any person acting on behalf of the Commission is responsible for the use which might be made of this information.
B38: Use conditions
B39: This work is licensed under
B40: CC BY 4.0

Sheet index
A1: CY | B1: Cyprus
B3: Click on the link to jump to the sheet
B4: =HYPERLINK("#"&CELL("address",SER_summary!$B$2),MID(CELL("filename",SER_summary!$B$2),FIND("]",CELL("filename",SER_summary!$B$2))+1,256)) -> SER_summary | D4: Services sector summary
B6: Services sector: Thermal uses
B7: =HYPERLINK("#"&CELL("address",SER_hh_num!$B$2),MID(CELL("filename",SER_hh_num!$B$2),FIND("]",CELL("filename",SER_hh_num!$B$2))+1,256)) -> SER_hh_num | D7: Number of buildings
B8: =HYPERLINK("#"&CELL("address",SER_hh_fec!$B$2),MID(CELL("filename",SER_hh_fec!$B$2),FIND("]",CELL("filename",SER_hh_fec!$B$2))+1,256)) -> SER_hh_fec | D8: Final energy consumption
B9: =HYPERLINK("#"&CELL("address",SER_hh_tes!$B$2),MID(CELL("filename",SER_hh_tes!$B$2),FIND("]",CELL("filename",SER_hh_tes!$B$2))+1,256)) -> SER_hh_tes | D9: Thermal energy service
B10: =HYPERLINK("#"&CELL("address",SER_hh_eff!$B$2),MID(CELL("filename",SER_hh_eff!$B$2),FIND("]",CELL("filename",SER_hh_eff!$B$2))+1,256)) -> SER_hh_eff | D10: System efficiency indicator of total stock
B11: =HYPERLINK("#"&CELL("address",SER_hh_emi!$B$2),MID(CELL("filename",SER_hh_emi!$B$2),FIND("]",CELL("filename",SER_hh_emi!$B$2))+1,256)) -> SER_hh_emi | D11: CO2 emissions
B12: =HYPERLINK("#"&CELL("address",SER_hh_fech!$B$2),MID(CELL("filename",SER_hh_fech!$B$2),FIND("]",CELL("filename",SER_hh_fech!$B$2))+1,256)) -> SER_hh_fech | D12: Final energy consumption per building
B13: =HYPERLINK("#"&CELL("address",SER_hh_tesh!$B$2),MID(CELL("filename",SER_hh_tesh!$B$2),FIND("]",CELL("filename",SER_hh_tesh!$B$2))+1,256)) -> SER_hh_tesh | D13: Thermal energy service per building
B14: =HYPERLINK("#"&CELL("address",SER_hh_emih!$B$2),MID(CELL("filename",SER_hh_emih!$B$2),FIND("]",CELL("filename",SER_hh_emih!$B$2))+1,256)) -> SER_hh_emih | D14: CO2 emissions per building
B15: =HYPERLINK("#"&CELL("address",SER_hh_fecs!$B$2),MID(CELL("filename",SER_hh_fecs!$B$2),FIND("]",CELL("filename",SER_hh_fecs!$B$2))+1,256)) -> SER_hh_fecs | D15: Final energy consumption per useful surface area
B16: =HYPERLINK("#"&CELL("address",SER_hh_tess!$B$2),MID(CELL("filename",SER_hh_tess!$B$2),FIND("]",CELL("filename",SER_hh_tess!$B$2))+1,256)) -> SER_hh_tess | D16: Thermal energy service per useful surface area
B17: =HYPERLINK("#"&CELL("address",SER_hh_emis!$B$2),MID(CELL("filename",SER_hh_emis!$B$2),FIND("]",CELL("filename",SER_hh_emis!$B$2))+1,256)) -> SER_hh_emis | D17: CO2 emissions per useful surface area
B19: Services sector: Thermal uses in new and renovated buildings
B20: =HYPERLINK("#"&CELL("address",SER_hh_num_in!$B$2),MID(CELL("filename",SER_hh_num_in!$B$2),FIND("]",CELL("filename",SER_hh_num_in!$B$2))+1,256)) -> SER_hh_num_in | D20: Number of new and renovated buildings
B21: =HYPERLINK("#"&CELL("address",SER_hh_fec_in!$B$2),MID(CELL("filename",SER_hh_fec_in!$B$2),FIND("]",CELL("filename",SER_hh_fec_in!$B$2))+1,256)) -> SER_hh_fec_in | D21: Final energy consumption
B22: =HYPERLINK("#"&CELL("address",SER_hh_tes_in!$B$2),MID(CELL("filename",SER_hh_tes_in!$B$2),FIND("]",CELL("filename",SER_hh_tes_in!$B$2))+1,256)) -> SER_hh_tes_in | D22: Thermal energy service
B23: =HYPERLINK("#"&CELL("address",SER_hh_eff_in!$B$2),MID(CELL("filename",SER_hh_eff_in!$B$2),FIND("]",CELL("filename",SER_hh_eff_in!$B$2))+1,256)) -> SER_hh_eff_in | D23: System efficiency indicator of total stock
B24: =HYPERLINK("#"&CELL("address",SER_hh_emi_in!$B$2),MID(CELL("filename",SER_hh_emi_in!$B$2),FIND("]",CELL("filename",SER_hh_emi_in!$B$2))+1,256)) -> SER_hh_emi_in | D24: CO2 emissions
B25: =HYPERLINK("#"&CELL("address",SER_hh_fech_in!$B$2),MID(CELL("filename",SER_hh_fech_in!$B$2),FIND("]",CELL("filename",SER_hh_fech_in!$B$2))+1,256)) -> SER_hh_fech_in | D25: Final energy consumption per building
B26: =HYPERLINK("#"&CELL("address",SER_hh_tesh_in!$B$2),MID(CELL("filename",SER_hh_tesh_in!$B$2),FIND("]",CELL("filename",SER_hh_tesh_in!$B$2))+1,256)) -> SER_hh_tesh_in | D26: Thermal energy service per building
B27: =HYPERLINK("#"&CELL("address",SER_hh_emih_in!$B$2),MID(CELL("filename",SER_hh_emih_in!$B$2),FIND("]",CELL("filename",SER_hh_emih_in!$B$2))+1,256)) -> SER_hh_emih_in | D27: CO2 emissions per building
B28: =HYPERLINK("#"&CELL("address",SER_hh_fecs_in!$B$2),MID(CELL("filename",SER_hh_fecs_in!$B$2),FIND("]",CELL("filename",SER_hh_fecs_in!$B$2))+1,256)) -> SER_hh_fecs_in | D28: Final energy consumption per useful surface area
B29: =HYPERLINK("#"&CELL("address",SER_hh_tess_in!$B$2),MID(CELL("filename",SER_hh_tess_in!$B$2),FIND("]",CELL("filename",SER_hh_tess_in!$B$2))+1,256)) -> SER_hh_tess_in | D29: Thermal energy service per useful surface area
B30: =HYPERLINK("#"&CELL("address",SER_hh_emis_in!$B$2),MID(CELL("filename",SER_hh_emis_in!$B$2),FIND("]",CELL("filename",SER_hh_emis_in!$B$2))+1,256)) -> SER_hh_emis_in | D30: CO2 emissions per useful surface area
B32: Services sector: Specific electric uses
B33: =HYPERLINK("#"&CELL("address",'SER_se-appl'!$B$2),MID(CELL("filename",'SER_se-appl'!$B$2),FIND("]",CELL("filename",'SER_se-appl'!$B$2))+1,256)) -> SER_se-appl | D33: Services / specific electric uses
B34: =HYPERLINK("#"&CELL("address",SER_VE!$B$2),MID(CELL("filename",SER_VE!$B$2),FIND("]",CELL("filename",SER_VE!$B$2))+1,256)) -> SER_VE | D34: Ventilation and others
B35: =HYPERLINK("#"&CELL("address",SER_SL!$B$2),MID(CELL("filename",SER_SL!$B$2),FIND("]",CELL("filename",SER_SL!$B$2))+1,256)) -> SER_SL | D35: Street lighting
B36: =HYPERLINK("#"&CELL("address",SER_BL!$B$2),MID(CELL("filename",SER_BL!$B$2),FIND("]",CELL("filename",SER_BL!$B$2))+1,256)) -> SER_BL | D36: Building lighting
B37: =HYPERLINK("#"&CELL("address",SER_CR!$B$2),MID(CELL("filename",SER_CR!$B$2),FIND("]",CELL("filename",SER_CR!$B$2))+1,256)) -> SER_CR | D37: Commercial refrigeration
B38: =HYPERLINK("#"&CELL("address",SER_BT!$B$2),MID(CELL("filename",SER_BT!$B$2),FIND("]",CELL("filename",SER_BT!$B$2))+1,256)) -> SER_BT | D38: Miscellaneous building technologies
B39: =HYPERLINK("#"&CELL("address",SER_IT!$B$2),MID(CELL("filename",SER_IT!$B$2),FIND("]",CELL("filename",SER_IT!$B$2))+1,256)) -> SER_IT | D39: ICT and multimedia
B41: Agriculture, forestry and fishing
B42: =HYPERLINK("#"&CELL("address",AGR!$B$2),MID(CELL("filename",AGR!$B$2),FIND("]",CELL("filename",AGR!$B$2))+1,256)) -> AGR | D42: Agriculture, forestry and fishing summary
B43: =HYPERLINK("#"&CELL("address",AGR_fec!$B$2),MID(CELL("filename",AGR_fec!$B$2),FIND("]",CELL("filename",AGR_fec!$B$2))+1,256)) -> AGR_fec | D43: detailed split of final energy consumption
B44: =HYPERLINK("#"&CELL("address",AGR_ued!$B$2),MID(CELL("filename",AGR_ued!$B$2),FIND("]",CELL("filename",AGR_ued!$B$2))+1,256)) -> AGR_ued | D44: detailed split of useful energy demand
B45: =HYPERLINK("#"&CELL("address",AGR_emi!$B$2),MID(CELL("filename",AGR_emi!$B$2),FIND("]",CELL("filename",AGR_emi!$B$2))+1,256)) -> AGR_emi | D45: detailed split of CO2 emissions

Sheet SER_summary
A1: CY - Services sector summary | B1: 2000 | C1: 2001 | D1: 2002 | E1: 2003 | F1: 2004 | G1: 2005 | H1: 2006 | I1: 2007 | J1: 2008 | K1: 2009 | L1: 2010 | M1: 2011 | N1: 2012 | O1: 2013 | P1: 2014 | Q1: 2015 | R1: 2016 | S1: 2017 | T1: 2018 | U1: 2019 | V1: 2020 | W1: 2021 | X1: 2022 | Y1: 2023 | DA1: Code
A3: Population (inhabitants) | B3: 690497 | C3: 697549 | D3: 705539 | E3: 713720 | F3: 722893 | G3: 733067 | H3: 744013 | I3: 757916 | J3: 776333 | K3: 796930 | L3: 819140 | M3: 839751 | N3: 862011 | O3: 862854 | P3: 860032 | Q3: 860846 | R3: 863764 | S3: 869878 | T3: 878601 | U3: 890194 | V3: 902429 | W3: 914476 | X3: 929764 | Y3: 949084 | DA3: Macro.number.CY.Population
A4: Gross domestic product (M€2023) | B4: 16237.914 | C4: 16879.645 | D4: 17508.242 | E4: 17967.361 | F4: 18870.599 | G4: 19786.469 | H4: 20719.131 | I4: 21775.31 | J4: 22569.536 | K4: 22114.8 | L4: 22619.416 | M4: 22713.886 | N4: 21930.883 | O4: 20485.96 | P4: 20122.224 | Q4: 20810.248 | R4: 22178.209 | S4: 23453.501 | T4: 24924.551 | U4: 26389.043 | V4: 25538.998 | W4: 28447.586 | X4: 30497.19 | Y4: 31340 | DA4: Macro.Meuro2015.CY.GDP
A5: Value added (M€2023) | B5: 11052.616 | C5: 11488.364 | D5: 11819.677 | E5: 12134.412 | F5: 12755.136 | G5: 13447.709 | H5: 14189.884 | I5: 14846.753 | J5: 15414.289 | K5: 15647.344 | L5: 16336.359 | M5: 16814.056 | N5: 16502.974 | O5: 15639.209 | P5: 15533.438 | Q5: 15998.294 | R5: 16852.007 | S5: 17793.628 | T5: 18767.688 | U5: 19729.208 | V5: 19116.273 | W5: 21739.461 | X5: 23767.6 | Y5: 24364.086 | DA5: Macro.Meuro2015.CY.VA
A6: Employment data (employees) | B6: 231510 | C6: 239300 | D6: 243380 | E6: 252680 | F6: 262480 | G6: 272400 | H6: 279590 | I6: 290670 | J6: 299640 | K6: 301620 | L6: 307180 | M6: 312300 | N6: 307320 | O6: 296500 | P6: 294520 | Q6: 299800 | R6: 313510 | S6: 329150 | T6: 349340 | U6: 363340 | V6: 358860 | W6: 369920 | X6: 386020 | Y6: 391530 | DA6: Macro.number.CY.Employees
A8: Number of representative building cells | B8: 16275.691 | C8: 16602.318 | D8: 16839.115 | E8: 17121.606 | F8: 17501.286 | G8: 17896.265 | H8: 18274.047 | I8: 18742.686 | J8: 19206.347 | K8: 19830.408 | L8: 20510.226 | M8: 20983.935 | N8: 21473.536 | O8: 21481.928 | P8: 21263.535 | Q8: 21123.162 | R8: 21299.685 | S8: 21597.6 | T8: 21894.445 | U8: 22183.991 | V8: 22434.509 | W8: 22675.701 | X8: 22907.76 | Y8: 23131.124 | DA8: NUM.number.CY.Ser.Bld
A9: Total services useful surface area (in 000 sqm) | B9: 14648.122 | C9: 14942.087 | D9: 15155.203 | E9: 15409.445 | F9: 15751.157 | G9: 16106.638 | H9: 16446.642 | I9: 16868.417 | J9: 17285.712 | K9: 17847.368 | L9: 18459.203 | M9: 18885.542 | N9: 19326.182 | O9: 19333.736 | P9: 19137.181 | Q9: 19010.846 | R9: 19169.716 | S9: 19437.84 | T9: 19705 | U9: 19965.592 | V9: 20191.058 | W9: 20408.13 | X9: 20616.984 | Y9: 20818.012 | DA9: SurfaceArea.ksqm.CY.Ser.Bld
A10: Number of new and renovated buildings | C10: 391.51955 | D10: 302.97357 | E10: 349.9532 | F10: 448.42686 | G10: 465.01113 | H10: 449.09874 | I10: 541.88388 | J10: 538.833 | K10: 701.16109 | L10: 758.84428 | M10: 555.94925 | N10: 573.76752 | O10: 94.486802 | P10: 86.094463 | Q10: 84.809471 | R10: 285.40507 | S10: 407.7076 | T10: 408.17264 | U10: 402.40368 | V10: 364.86872 | W10: 356.83343 | X10: 348.94472 | Y10: 341.44503 | DA10: NUM.number.CY.Ser.BldNew
A11: New and renovated buildings useful surface area (in 000 sqm) | C11: 352.3676 | D11: 272.67621 | E11: 314.95788 | F11: 403.58418 | G11: 418.51002 | H11: 404.18887 | I11: 487.69549 | J11: 484.9497 | K11: 631.04498 | L11: 682.95985 | M11: 500.35432 | N11: 516.39077 | O11: 85.038122 | P11: 77.485017 | Q11: 76.328524 | R11: 256.86456 | S11: 366.93684 | T11: 367.35537 | U11: 362.16331 | V11: 328.38185 | W11: 321.15008 | X11: 314.05025 | Y11: 307.30053 | DA11: SurfaceArea.ksqm.CY.Ser.BldNew
A13: Actual heating degree-days | B13: 863.34 | C13: 636.57 | D13: 714.82 | E13: 793.64 | F13: 844.33 | G13: 767.46 | H13: 852.91 | I13: 804.12 | J13: 734.66 | K13: 710.65 | L13: 498.76 | M13: 794.38 | N13: 817.04 | O13: 707.11 | P13: 523.15 | Q13: 749.52 | R13: 677.81 | S13: 720.83 | T13: 470.75 | U13: 693.06 | V13: 626.43 | W13: 609.84 | X13: 695.96 | Y13: 529.77 | DA13: HDD.Celsius.CY.Actual
A14: Mean heating degree-days over period 2000- 2020 | B14: =AVERAGE($B$13:$V$13) -> 714.34952 | C14: =AVERAGE($B$13:$V$13) -> 714.34952 | D14: =AVERAGE($B$13:$V$13) -> 714.34952 | E14: =AVERAGE($B$13:$V$13) -> 714.34952 | F14: =AVERAGE($B$13:$V$13) -> 714.34952 | G14: =AVERAGE($B$13:$V$13) -> 714.34952 | H14: =AVERAGE($B$13:$V$13) -> 714.34952 | I14: =AVERAGE($B$13:$V$13) -> 714.34952 | ... Y14: =AVERAGE($B$13:$V$13) -> 714.34952 | DA14: HDD.Celsius.CY.Mean
A15: Relative heating degree-days | B15: =B13/B14 -> 1.208568 | C15: =C13/C14 -> 0.89111839 | D15: =D13/D14 -> 1.0006586 | E15: =E13/E14 -> 1.1109968 | F15: =F13/F14 -> 1.1819564 | G15: =G13/G14 -> 1.074348 | H15: =H13/H14 -> 1.1939673 | I15: =I13/I14 -> 1.1256674 | ... Y15: =Y13/Y14 -> 0.74161175 | DA15: HDD.ratio.CY.Relative
A17: Indicators
A19: GDP per capita (€2023) | B19: =B4*1000000/B3 -> 23516.269 | C19: =C4*1000000/C3 -> 24198.508 | D19: =D4*1000000/D3 -> 24815.414 | E19: =E4*1000000/E3 -> 25174.244 | F19: =F4*1000000/F3 -> 26104.276 | G19: =G4*1000000/G3 -> 26991.352 | H19: =H4*1000000/H3 -> 27847.808 | I19: =I4*1000000/I3 -> 28730.506 | ... Y19: =Y4*1000000/Y3 -> 33021.313
A20: Value added per employee (€2023) | B20: =B5*1000000/B6 -> 47741.42 | C20: =C5*1000000/C6 -> 48008.207 | D20: =D5*1000000/D6 -> 48564.703 | E20: =E5*1000000/E6 -> 48022.845 | F20: =F5*1000000/F6 -> 48594.696 | G20: =G5*1000000/G6 -> 49367.509 | H20: =H5*1000000/H6 -> 50752.473 | I20: =I5*1000000/I6 -> 51077.693 | ... Y20: =Y5*1000000/Y6 -> 62227.889
A21: Value added per capita (€2023) | B21: =B5*1000000/B3 -> 16006.755 | C21: =C5*1000000/C3 -> 16469.616 | D21: =D5*1000000/D3 -> 16752.692 | E21: =E5*1000000/E3 -> 17001.643 | F21: =F5*1000000/F3 -> 17644.569 | G21: =G5*1000000/G3 -> 18344.448 | H21: =H5*1000000/H3 -> 19072.092 | I21: =I5*1000000/I3 -> 19588.916 | ... Y21: =Y5*1000000/Y3 -> 25671.158
A22: Value added per capita relative to EU | B22: 0.87335829 | C22: 0.87620278 | D22: 0.87363493 | E22: 0.87692855 | F22: 0.88945495 | G22: 0.90520427 | H22: 0.9131414 | I22: 0.91000385 | J22: 0.91011944 | K22: 0.92082909 | L22: 0.92144881 | M22: 0.90689293 | N22: 0.86988584 | O22: 0.8188115 | P22: 0.80267406 | Q22: 0.81241144 | R22: 0.83875669 | S22: 0.85638032 | T22: 0.87541287 | U22: 0.89138301 | V22: 0.90017979 | W22: 0.95190152 | X22: 0.99269744 | Y22: 0.99457613
A23: Representative building cell size (employees/representative building cell) | B23: =B6/B8 -> 14.224281 | C23: =C6/C8 -> 14.41365 | D23: =D6/D8 -> 14.453254 | E23: =E6/E8 -> 14.757961 | F23: =F6/F8 -> 14.997755 | G23: =G6/G8 -> 15.221053 | H23: =H6/H8 -> 15.299841 | I23: =I6/I8 -> 15.50845 | ... Y23: =Y6/Y8 -> 16.926545
A24: Services useful surface area (in sqm/capita) | B24: =B9*1000/B3 -> 21.213882 | C24: =C9*1000/C3 -> 21.420842 | D24: =D9*1000/D3 -> 21.48032 | E24: =E9*1000/E3 -> 21.590323 | F24: =F9*1000/F3 -> 21.789058 | G24: =G9*1000/G3 -> 21.971578 | H24: =H9*1000/H3 -> 22.105315 | I24: =I9*1000/I3 -> 22.256315 | ... Y24: =Y9*1000/Y3 -> 21.934846
A25: Services useful surface area (in sqm/employee) | B25: =B9*1000/B6 -> 63.272091 | C25: =C9*1000/C6 -> 62.440813 | D25: =D9*1000/D6 -> 62.269716 | E25: =E9*1000/E6 -> 60.984033 | F25: =F9*1000/F6 -> 60.008981 | G25: =G9*1000/G6 -> 59.128629 | H25: =H9*1000/H6 -> 58.824142 | I25: =I9*1000/I6 -> 58.03288 | ... Y25: =Y9*1000/Y6 -> 53.170923
A26: Services useful surface area (in sqm/representative building cell) | B26: =B9*1000/B8 -> 900 | C26: =C9*1000/C8 -> 900 | D26: =D9*1000/D8 -> 900 | E26: =E9*1000/E8 -> 900 | F26: =F9*1000/F8 -> 900 | G26: =G9*1000/G8 -> 900 | H26: =H9*1000/H8 -> 900 | I26: =I9*1000/I8 -> 900 | ... Y26: =Y9*1000/Y8 -> 900
A27: New and renovated buildings useful surface area (in sqm/representative building cell) | B27: =IF(SUM(B11)=0,"",B11*1000/B10) | C27: =IF(SUM(C11)=0,"",C11*1000/C10) -> 900 | D27: =IF(SUM(D11)=0,"",D11*1000/D10) -> 900 | E27: =IF(SUM(E11)=0,"",E11*1000/E10) -> 900 | F27: =IF(SUM(F11)=0,"",F11*1000/F10) -> 900 | G27: =IF(SUM(G11)=0,"",G11*1000/G10) -> 900 | H27: =IF(SUM(H11)=0,"",H11*1000/H10) -> 900 | I27: =IF(SUM(I11)=0,"",I11*1000/I10) -> 900 | ... Y27: =IF(SUM(Y11)=0,"",Y11*1000/Y10) -> 900
A29: Energy consumption
A31: Energy consumption by fuel - Eurostat structure (ktoe) | B31: =SUM(B32:B33,B36:B37,B44:B45) -> 153.45398 | C31: =SUM(C32:C33,C36:C37,C44:C45) -> 164.23063 | D31: =SUM(D32:D33,D36:D37,D44:D45) -> 175.05113 | E31: =SUM(E32:E33,E36:E37,E44:E45) -> 181.89014 | F31: =SUM(F32:F33,F36:F37,F44:F45) -> 185.12876 | G31: =SUM(G32:G33,G36:G37,G44:G45) -> 192.13269 | H31: =SUM(H32:H33,H36:H37,H44:H45) -> 220.09604 | I31: =SUM(I32:I33,I36:I37,I44:I45) -> 229.76563 | ... Y31: =SUM(Y32:Y33,Y36:Y37,Y44:Y45) -> 268.9644 | DA31: FEC.ktoe.CY.ES.Ser
A32: Solids | B32: 0 | C32: 0 | D32: 0 | E32: 0 | F32: 0 | G32: 0 | H32: 0 | I32: 0 | J32: 0 | K32: 0 | L32: 0 | M32: 0 | N32: 0 | O32: 0 | P32: 0 | Q32: 0 | R32: 0 | S32: 0 | T32: 0 | U32: 0 | V32: 0 | W32: 0 | X32: 0 | Y32: 0 | DA32: FEC.ktoe.CY.ES.Ser.Solids
A33: Liquids | B33: =SUM(B34:B35) -> 26.079604 | C33: =SUM(C34:C35) -> 26.35269 | D33: =SUM(D34:D35) -> 25.260345 | E33: =SUM(E34:E35) -> 25.943055 | F33: =SUM(F34:F35) -> 23.348754 | G33: =SUM(G34:G35) -> 22.402167 | H33: =SUM(H34:H35) -> 40.238435 | I33: =SUM(I34:I35) -> 41.26681 | ... Y33: =SUM(Y34:Y35) -> 45.359845
A34: Liquified petroleum gas (LPG) | B34: 0 | C34: 0 | D34: 0 | E34: 0 | F34: 0 | G34: 0 | H34: 14.686672 | I34: 14.686672 | J34: 15.816337 | K34: 14.686672 | L34: 14.686672 | M34: 15.816337 | N34: 15.816337 | O34: 14.686672 | P34: 12.427171 | Q34: 13.556922 | R34: 13.556922 | S34: 16.365434 | T34: 16.561995 | U34: 18.962769 | V34: 14.003181 | W34: 12.257696 | X34: 14.366896 | Y34: 13.419089 | DA34: FEC.ktoe.CY.ES.Ser.LPG
A35: Diesel oil and other liquids (without biofuels) | B35: 26.079604 | C35: 26.35269 | D35: 25.260345 | E35: 25.943055 | F35: 23.348754 | G35: 22.402167 | H35: 25.551763 | I35: 26.580138 | J35: 35.820292 | K35: 27.617885 | L35: 31.740499 | M35: 30.720206 | N35: 26.4454 | O35: 28.427945 | P35: 27.514187 | Q35: 23.469647 | R35: 22.363887 | S35: 25.15589 | T35: 24.804471 | U35: 31.147979 | V35: 25.239209 | W35: 28.376784 | X35: 31.393895 | Y35: 31.940757 | DA35: FEC.ktoe.CY.ES.Ser.Oil
A36: Natural gas | B36: 0 | C36: 0 | D36: 0 | E36: 0 | F36: 0 | G36: 0 | H36: 0 | I36: 0 | J36: 0 | K36: 0 | L36: 0 | M36: 0 | N36: 0 | O36: 0 | P36: 0 | Q36: 0 | R36: 0 | S36: 0 | T36: 0 | U36: 0 | V36: 0 | W36: 0 | X36: 0 | Y36: 0 | DA36: FEC.ktoe.CY.ES.Ser.NG
A37: Renewable energies and wastes | B37: =SUM(B38:B42) -> 6.9960449 | C37: =SUM(C38:C42) -> 6.8375285 | D37: =SUM(D38:D42) -> 7.6583656 | E37: =SUM(E38:E42) -> 7.7957549 | F37: =SUM(F38:F42) -> 8.7830159 | G37: =SUM(G38:G42) -> 9.7687876 | H37: =SUM(H38:H42) -> 10.007653 | I37: =SUM(I38:I42) -> 13.318057 | ... Y37: =SUM(Y38:Y42) -> 17.305503
A38: Biomass and waste | B38: 1.7614789 | C38: 1.7614789 | D38: 2.4660791 | E38: 2.4660791 | F38: 2.9425623 | G38: 3.6782459 | H38: 3.6782459 | I38: 5.4839209 | J38: 6.5348237 | K38: 6.6877042 | L38: 5.5412726 | M38: 5.9091144 | N38: 6.3271711 | O38: 6.2190886 | P38: 6.1384351 | Q38: 7.9233878 | R38: 7.1783319 | S38: 8.0896819 | T38: 6.7536543 | U38: 7.1856406 | V38: 7.005417 | W38: 7.1180567 | X38: 8.5471195 | Y38: 6.7061049 | DA38: FEC.ktoe.CY.ES.Ser.Biomass_Waste
A39: Biogas | B39: 0 | C39: 0 | D39: 0 | E39: 0 | F39: 0 | G39: 0 | H39: 0 | I39: 0 | J39: 0 | K39: 0.2627687 | L39: 0.28658641 | M39: 0.2627687 | N39: 0.2627687 | O39: 0.2627687 | P39: 0.28658641 | Q39: 0.28658641 | R39: 0.38211522 | S39: 0.40103181 | T39: 1.0655202 | U39: 1.2809974 | V39: 0.48177128 | W39: 0.56414445 | X39: 0.65468616 | Y39: 0.88564058 | DA39: FEC.ktoe.CY.ES.Ser.Biogas
A40: Liquid biofuels | B40: 0 | C40: 0 | D40: 0 | E40: 0 | F40: 0 | G40: 0 | H40: 0 | I40: 0 | J40: 0 | K40: 0 | L40: 0 | M40: 0 | N40: 0 | O40: 0 | P40: 0 | Q40: 0 | R40: 0.05038693 | S40: 1.2858126 | T40: 0 | U40: 0 | V40: 0.28185727 | W40: 0.32347377 | X40: 0.32527945 | Y40: 0.41711092 | DA40: FEC.ktoe.CY.ES.Ser.LiqBio
A41: Solar | B41: 5.2345659 | C41: 5.0760496 | D41: 5.1922864 | E41: 5.3296758 | F41: 5.8404536 | G41: 6.0905417 | H41: 6.3294067 | I41: 7.8341359 | J41: 8.4073947 | K41: 8.6939811 | L41: 9.1239037 | M41: 9.4104901 | N41: 9.6732588 | O41: 9.8643164 | P41: 10.007653 | Q41: 10.174807 | R41: 10.342046 | S41: 10.53233 | T41: 10.748237 | U41: 10.911006 | V41: 11.095357 | W41: 11.288994 | X41: 9.2009458 | Y41: 9.2966466 | DA41: FEC.ktoe.CY.ES.Ser.Solar
A42: Geothermal | B42: 0 | C42: 0 | D42: 0 | E42: 0 | F42: 0 | G42: 0 | H42: 0 | I42: 0 | J42: 0 | K42: 0 | L42: 0 | M42: 0 | N42: 0 | O42: 0 | P42: 0 | Q42: 0 | R42: 0 | S42: 0 | T42: 0 | U42: 0 | V42: 0 | W42: 0 | X42: 0 | Y42: 0 | DA42: FEC.ktoe.CY.ES.Ser.Geo
A43: Ambient heat | B43: 0.069622724 | C43: 0.30385136 | D43: 0.61759916 | E43: 1.0000362 | F43: 1.5438943 | G43: 2.2803419 | H43: 2.7946848 | I43: 3.4247976 | J43: 3.8355898 | K43: 5.0676085 | L43: 6.023606 | M43: 8.4612626 | N43: 14.022554 | O43: 27.970333 | P43: 28.852014 | Q43: 32.22002 | R43: 32.192858 | S43: 33.977241 | T43: 36.032072 | U43: 38.005417 | V43: 35.311866 | W43: 36.032072 | X43: 37.693895 | Y43: 38.109286 | DA43: FEC.ktoe.CY.ES.Ser.Ambient
A44: Distributed heat | B44: 0 | C44: 0 | D44: 0 | E44: 0 | F44: 0 | G44: 0 | H44: 0 | I44: 0 | J44: 0 | K44: 0 | L44: 0 | M44: 0 | N44: 0 | O44: 0 | P44: 0 | Q44: 0 | R44: 0 | S44: 0 | T44: 0 | U44: 0 | V44: 0 | W44: 0 | X44: 0 | Y44: 0 | DA44: FEC.ktoe.CY.ES.Ser.Steam_Distr
A45: Electricity | B45: 120.37833 | C45: 131.04041 | D45: 142.13242 | E45: 148.15133 | F45: 152.99699 | G45: 159.96174 | H45: 169.84996 | I45: 175.18076 | J45: 185.65821 | K45: 197.26615 | L45: 207.41206 | M45: 200.53824 | N45: 182.48277 | O45: 161.67358 | P45: 165.88526 | Q45: 169.66438 | R45: 185.39407 | S45: 188.0821 | T45: 195.08876 | U45: 194.41782 | V45: 161.05888 | W45: 179.65822 | X45: 200.6149 | Y45: 206.29905 | DA45: FEC.ktoe.CY.ES.Ser.Elec
A47: Energy consumption by end-uses (ktoe) | B47: =SUM(B48,B53) -> 153.45398 | C47: =SUM(C48,C53) -> 164.23063 | D47: =SUM(D48,D53) -> 175.05113 | E47: =SUM(E48,E53) -> 181.89014 | F47: =SUM(F48,F53) -> 185.12876 | G47: =SUM(G48,G53) -> 192.13269 | H47: =SUM(H48,H53) -> 220.09604 | I47: =SUM(I48,I53) -> 229.76563 | ... Y47: =SUM(Y48,Y53) -> 268.9644 | DA47: FEC.ktoe.CY.Ser
A48: Thermal uses | B48: =SUM(B49:B52) -> 97.062602 | C48: =SUM(C49:C52) -> 105.688 | D48: =SUM(D49:D52) -> 114.3036 | E48: =SUM(E49:E52) -> 119.12422 | F48: =SUM(F49:F52) -> 119.94612 | G48: =SUM(G49:G52) -> 124.87525 | H48: =SUM(H49:H52) -> 151.02902 | I48: =SUM(I49:I52) -> 158.55646 | ... Y48: =SUM(Y49:Y52) -> 194.72176 | DA48: FEC.ktoe.CY.Ser.Bld.Thermal
...

Sheet SER_hh_num
A1: CY - Number of buildings | B1: 2000 | C1: 2001 | D1: 2002 | E1: 2003 | F1: 2004 | G1: 2005 | H1: 2006 | I1: 2007 | J1: 2008 | K1: 2009 | L1: 2010 | M1: 2011 | N1: 2012 | O1: 2013 | P1: 2014 | Q1: 2015 | R1: 2016 | S1: 2017 | T1: 2018 | U1: 2019 | V1: 2020 | W1: 2021 | X1: 2022 | Y1: 2023 | DA1: Code
A3: Stock of buildings | B3: =B4 -> 16275.691 | C3: =C4 -> 16602.318 | D3: =D4 -> 16839.115 | E3: =E4 -> 17121.606 | F3: =F4 -> 17501.286 | G3: =G4 -> 17896.265 | H3: =H4 -> 18274.047 | I3: =I4 -> 18742.686 | ... Y3: =Y4 -> 23131.124 | DA3: NUM.number.CY.Ser.Bld.Thermal
A4: Space heating | B4: =SUM(B5:B14) -> 16275.691 | C4: =SUM(C5:C14) -> 16602.318 | D4: =SUM(D5:D14) -> 16839.115 | E4: =SUM(E5:E14) -> 17121.606 | F4: =SUM(F5:F14) -> 17501.286 | G4: =SUM(G5:G14) -> 17896.265 | H4: =SUM(H5:H14) -> 18274.047 | I4: =SUM(I5:I14) -> 18742.686 | ... Y4: =SUM(Y5:Y14) -> 23131.124 | DA4: NUM.number.CY.Ser.Bld.Thermal.SH
A5: Solids | B5: 0 | C5: 0 | D5: 0 | E5: 0 | F5: 0 | G5: 0 | H5: 0 | I5: 0 | J5: 0 | K5: 0 | L5: 0 | M5: 0 | N5: 0 | O5: 0 | P5: 0 | Q5: 0 | R5: 0 | S5: 0 | T5: 0 | U5: 0 | V5: 0 | W5: 0 | X5: 0 | Y5: 0 | DA5: NUM.number.CY.Ser.Bld.Thermal.SH.Solids
A6: Liquified petroleum gas (LPG) | B6: 0 | C6: 0 | D6: 0 | E6: 0 | F6: 0 | G6: 0 | H6: 0 | I6: 0 | J6: 0 | K6: 0 | L6: 0 | M6: 0 | N6: 0 | O6: 0 | P6: 0 | Q6: 0 | R6: 0 | S6: 0 | T6: 0 | U6: 0 | V6: 0 | W6: 0 | X6: 0 | Y6: 0 | DA6: NUM.number.CY.Ser.Bld.Thermal.SH.LPG
A7: Diesel oil | B7: 10346.875 | C7: 8895.2316 | D7: 7520.9566 | E7: 6572.8397 | F7: 5682.232 | G7: 4965.864 | H7: 4422.0786 | I7: 4216.5132 | J7: 4260.42 | K7: 4082.2214 | L7: 4221.905 | M7: 4372.3111 | N7: 4594.4347 | O7: 4487.7691 | P7: 4099.8954 | Q7: 3571.3187 | R7: 3209.1042 | S7: 3136.4493 | T7: 3173.3878 | U7: 3372.2796 | V7: 3500.4592 | W7: 3519.2644 | X7: 3434.8682 | Y7: 3458.8458 | DA7: NUM.number.CY.Ser.Bld.Thermal.SH.Oil
A8: Gas heat pumps | B8: 0 | C8: 0 | D8: 0 | E8: 0 | F8: 0 | G8: 0 | H8: 0 | I8: 0 | J8: 0 | K8: 0 | L8: 0 | M8: 0 | N8: 0 | O8: 0 | P8: 0 | Q8: 0 | R8: 0 | S8: 0 | T8: 0 | U8: 0 | V8: 0 | W8: 0 | X8: 0 | Y8: 0 | DA8: NUM.number.CY.Ser.Bld.Thermal.SH.GasHP
A9: Conventional gas heaters | B9: 0 | C9: 0 | D9: 0 | E9: 0 | F9: 0 | G9: 0 | H9: 0 | I9: 0 | J9: 0 | K9: 46.068695 | L9: 60.592299 | M9: 67.721977 | N9: 70.8494 | O9: 68.722767 | P9: 69.1333 | Q9: 69.759641 | R9: 89.60672 | S9: 121.86634 | T9: 160.52643 | U9: 171.98219 | V9: 176.84554 | W9: 183.97927 | X9: 182.71737 | Y9: 175.36622 | DA9: NUM.number.CY.Ser.Bld.Thermal.SH.GasTH
A10: Biomass | B10: 0 | C10: 0 | D10: 0 | E10: 0 | F10: 0 | G10: 0 | H10: 0 | I10: 96.962447 | J10: 152.67713 | K10: 152.25908 | L10: 152.45303 | M10: 158.67839 | N10: 183.8531 | O10: 215.04506 | P10: 248.22469 | Q10: 329.87785 | R10: 327.53242 | S10: 315.40489 | T10: 230.13063 | U10: 213.4997 | V10: 221.25157 | W10: 262.24793 | X10: 332.05939 | Y10: 342.73576 | DA10: NUM.number.CY.Ser.Bld.Thermal.SH.Biomass
A11: Geothermal | B11: 0 | C11: 0 | D11: 0 | E11: 0 | F11: 0 | G11: 0 | H11: 0 | I11: 0 | J11: 0 | K11: 0 | L11: 0 | M11: 0 | N11: 0 | O11: 0 | P11: 0 | Q11: 0 | R11: 0 | S11: 0 | T11: 0 | U11: 0 | V11: 0 | W11: 0 | X11: 0 | Y11: 0 | DA11: NUM.number.CY.Ser.Bld.Thermal.SH.Geo
A12: Distributed heat | B12: 0 | C12: 0 | D12: 0 | E12: 0 | F12: 0 | G12: 0 | H12: 0 | I12: 0 | J12: 0 | K12: 0 | L12: 0 | M12: 0 | N12: 0 | O12: 0 | P12: 0 | Q12: 0 | R12: 0 | S12: 0 | T12: 0 | U12: 0 | V12: 0 | W12: 0 | X12: 0 | Y12: 0 | DA12: NUM.number.CY.Ser.Bld.Thermal.SH.DistrHeat
A13: Advanced electric heating | B13: 494.90162 | C13: 801.11457 | D13: 1265.3088 | E13: 1791.4656 | F13: 2269.0659 | G13: 2661.7225 | H13: 2745.8381 | I13: 2913.7566 | J13: 3025.3838 | K13: 3442.3216 | L13: 4308.1301 | M13: 6375.1606 | N13: 9729.8966 | O13: 12925.742 | P13: 13998.055 | Q13: 14150.848 | R13: 14125.155 | S13: 14411.653 | T13: 14746.268 | U13: 14843.977 | V13: 14762.524 | W13: 14217.101 | X13: 13504.425 | Y13: 13396.618 | DA13: NUM.number.CY.Ser.Bld.Thermal.SH.AdvElc
A14: Conventional electric heating | B14: 5433.9139 | C14: 6905.9723 | D14: 8052.8495 | E14: 8757.3007 | F14: 9549.9879 | G14: 10268.678 | H14: 11106.13 | I14: 11515.454 | J14: 11767.866 | K14: 12107.538 | L14: 11767.145 | M14: 10010.063 | N14: 6894.5022 | O14: 3784.6499 | P14: 2848.2263 | Q14: 3001.3573 | R14: 3548.2863 | S14: 3612.2267 | T14: 3584.1319 | U14: 3582.2522 | V14: 3773.4291 | W14: 4493.1081 | X14: 5453.6903 | Y14: 5757.5584 | DA14: NUM.number.CY.Ser.Bld.Thermal.SH.ConvElc
A15: Circulation, other electricity | B15: =SUM(B5:B12) -> 10346.875 | C15: =SUM(C5:C12) -> 8895.2316 | D15: =SUM(D5:D12) -> 7520.9566 | E15: =SUM(E5:E12) -> 6572.8397 | F15: =SUM(F5:F12) -> 5682.232 | G15: =SUM(G5:G12) -> 4965.864 | H15: =SUM(H5:H12) -> 4422.0786 | I15: =SUM(I5:I12) -> 4313.4757 | ... Y15: =SUM(Y5:Y12) -> 3976.9478
A16: Space cooling | B16: =SUM(B17:B18) -> 4095.2961 | C16: =SUM(C17:C18) -> 5115.2157 | D16: =SUM(D17:D18) -> 6203.8365 | E16: =SUM(E17:E18) -> 7042.4612 | F16: =SUM(F17:F18) -> 8101.975 | G16: =SUM(G17:G18) -> 9077.9324 | H16: =SUM(H17:H18) -> 9819.1266 | I16: =SUM(I17:I18) -> 10551.132 | ... Y16: =SUM(Y17:Y18) -> 17838.597 | DA16: NUM.number.CY.Ser.Bld.Thermal.SC
A17: Gas heat pumps | B17: 0 | C17: 0 | D17: 0 | E17: 0 | F17: 0 | G17: 0 | H17: 0 | I17: 0 | J17: 0 | K17: 0 | L17: 0 | M17: 0 | N17: 0 | O17: 0 | P17: 0 | Q17: 0 | R17: 0 | S17: 0 | T17: 0 | U17: 0 | V17: 0 | W17: 0 | X17: 0 | Y17: 0 | DA17: NUM.number.CY.Ser.Bld.Thermal.SC.GasHP
A18: Electric space cooling | B18: 4095.2961 | C18: 5115.2157 | D18: 6203.8365 | E18: 7042.4612 | F18: 8101.975 | G18: 9077.9324 | H18: 9819.1266 | I18: 10551.132 | J18: 11305.744 | K18: 12121.081 | L18: 13082.11 | M18: 14019.827 | N18: 14533.189 | O18: 14777.881 | P18: 14786.011 | Q18: 14834.221 | R18: 15116.974 | S18: 15473.014 | T18: 16028.155 | U18: 16672.173 | V18: 17157.275 | W18: 17172.862 | X18: 17537.251 | Y18: 17838.597 | DA18: NUM.number.CY.Ser.Bld.Thermal.SC.AC
A19: Hot water | B19: =SUM(B20:B26) -> 16275.691 | C19: =SUM(C20:C26) -> 16602.318 | D19: =SUM(D20:D26) -> 16839.115 | E19: =SUM(E20:E26) -> 17121.606 | F19: =SUM(F20:F26) -> 17501.286 | G19: =SUM(G20:G26) -> 17896.265 | H19: =SUM(H20:H26) -> 18274.047 | I19: =SUM(I20:I26) -> 18742.686 | ... Y19: =SUM(Y20:Y26) -> 23131.124 | DA19: NUM.number.CY.Ser.Bld.Thermal.HW
A20: Solids | B20: 0 | C20: 0 | D20: 0 | E20: 0 | F20: 0 | G20: 0 | H20: 0 | I20: 0 | J20: 0 | K20: 0 | L20: 0 | M20: 0 | N20: 0 | O20: 0 | P20: 0 | Q20: 0 | R20: 0 | S20: 0 | T20: 0 | U20: 0 | V20: 0 | W20: 0 | X20: 0 | Y20: 0 | DA20: NUM.number.CY.Ser.Bld.Thermal.HW.Solids
A21: Liquified petroleum gas (LPG) | B21: 0 | C21: 0 | D21: 0 | E21: 0 | F21: 0 | G21: 0 | H21: 4563.5338 | I21: 6001.8645 | J21: 6792.9495 | K21: 6919.0502 | L21: 6973.3279 | M21: 6784.2266 | N21: 6415.1549 | O21: 5928.2014 | P21: 5279.3026 | Q21: 5097.7265 | R21: 5082.1879 | S21: 5140.2569 | T21: 5062.2709 | U21: 4920.3339 | V21: 4437.6077 | W21: 4258.5382 | X21: 4451.005 | Y21: 4494.8266 | DA21: NUM.number.CY.Ser.Bld.Thermal.HW.LPG
A22: Diesel oil | B22: 533.5819 | C22: 538.27551 | D22: 541.86156 | E22: 545.11263 | F22: 550.72762 | G22: 558.21431 | H22: 568.56378 | I22: 578.22101 | J22: 582.99346 | K22: 589.6969 | L22: 598.55759 | M22: 607.31142 | N22: 616.27966 | O22: 621.15895 | P22: 628.02463 | Q22: 635.91377 | R22: 650.08913 | S22: 671.5533 | T22: 696.20245 | U22: 727.10933 | V22: 735.51135 | W22: 744.94536 | X22: 766.46299 | Y22: 772.22582 | DA22: NUM.number.CY.Ser.Bld.Thermal.HW.Oil
A23: Natural gas | B23: 0 | C23: 0 | D23: 0 | E23: 0 | F23: 0 | G23: 0 | H23: 0 | I23: 0 | J23: 0 | K23: 0 | L23: 0 | M23: 0 | N23: 0 | O23: 0 | P23: 0 | Q23: 0 | R23: 0 | S23: 0 | T23: 0 | U23: 0 | V23: 0 | W23: 0 | X23: 0 | Y23: 0 | DA23: NUM.number.CY.Ser.Bld.Thermal.HW.Gas
A24: Biomass | B24: 0 | C24: 0 | D24: 0 | E24: 0 | F24: 0 | G24: 0 | H24: 0 | I24: 0 | J24: 0 | K24: 0 | L24: 0 | M24: 0 | N24: 0 | O24: 0 | P24: 0 | Q24: 0 | R24: 0 | S24: 0 | T24: 0 | U24: 0 | V24: 0 | W24: 0 | X24: 0 | Y24: 0 | DA24: NUM.number.CY.Ser.Bld.Thermal.HW.Biomass
A25: Distributed heat | B25: 0 | C25: 0 | D25: 0 | E25: 0 | F25: 0 | G25: 0 | H25: 0 | I25: 0 | J25: 0 | K25: 0 | L25: 0 | M25: 0 | N25: 0 | O25: 0 | P25: 0 | Q25: 0 | R25: 0 | S25: 0 | T25: 0 | U25: 0 | V25: 0 | W25: 0 | X25: 0 | Y25: 0 | DA25: NUM.number.CY.Ser.Bld.Thermal.HW.DistrHeat
A26: Electricity | B26: 15742.109 | C26: 16064.043 | D26: 16297.253 | E26: 16576.493 | F26: 16950.558 | G26: 17338.051 | H26: 13141.949 | I26: 12162.6 | J26: 11830.404 | K26: 12321.661 | L26: 12938.34 | M26: 13592.397 | N26: 14442.101 | O26: 14932.568 | P26: 15356.208 | Q26: 15389.522 | R26: 15567.408 | S26: 15785.79 | T26: 16135.972 | U26: 16536.547 | V26: 17261.39 | W26: 17672.217 | X26: 17690.292 | Y26: 17864.072 | DA26: NUM.number.CY.Ser.Bld.Thermal.HW.Elc
A27: Solar | B27: 6064.2376 | C27: 5851.7084 | D27: 6469.0263 | E27: 7104.0256 | F27: 7688.7725 | G27: 8531.9718 | H27: 8502.2152 | I27: 9591.8166 | J27: 10103.006 | K27: 10859.099 | L27: 11164.087 | M27: 11569.119 | N27: 11261.738 | O27: 10281.46 | P27: 10278.501 | Q27: 10578.234 | R27: 11045.715 | S27: 11929.437 | T27: 11937.473 | U27: 12067.406 | V27: 13242.578 | W27: 13099.516 | X27: 9920.7877 | Y27: 9139.6949 | DA27: NUM.number.CY.Ser.Bld.Thermal.HW.Solar
A28: Solar
A29: Catering | B29: =SUM(B30:B33) -> 16275.691 | C29: =SUM(C30:C33) -> 16602.318 | D29: =SUM(D30:D33) -> 16839.115 | E29: =SUM(E30:E33) -> 17121.606 | F29: =SUM(F30:F33) -> 17501.286 | G29: =SUM(G30:G33) -> 17896.265 | H29: =SUM(H30:H33) -> 18274.047 | I29: =SUM(I30:I33) -> 18742.686 | ... Y29: =SUM(Y30:Y33) -> 23131.124 | DA29: NUM.number.CY.Ser.Bld.Thermal.CA
A30: Liquified petroleum gas (LPG) | B30: 0 | C30: 0 | D30: 0 | E30: 0 | F30: 0 | G30: 0 | H30: 2474.5708 | I30: 3184.0095 | J30: 3587.3587 | K30: 3483.9769 | L30: 3572.3025 | M30: 3896.1784 | N30: 4075.3275 | O30: 4064.9143 | P30: 3918.4824 | Q30: 4234.4716 | R30: 4668.8662 | S30: 5621.7241 | T30: 5726.9862 | U30: 5664.1478 | V30: 5754.046 | W30: 5699.5733 | X30: 5349.9357 | Y30: 5091.312 | DA30: NUM.number.CY.Ser.Bld.Thermal.CA.LPG
A31: Natural gas | B31: 0 | C31: 0 | D31: 0 | E31: 0 | F31: 0 | G31: 0 | H31: 0 | I31: 0 | J31: 0 | K31: 0 | L31: 0 | M31: 0 | N31: 0 | O31: 0 | P31: 0 | Q31: 0 | R31: 0 | S31: 0 | T31: 0 | U31: 0 | V31: 0 | W31: 0 | X31: 0 | Y31: 0 | DA31: NUM.number.CY.Ser.Bld.Thermal.CA.Gas
A32: Biomass | B32: 1028.3862 | C32: 1134.2953 | D32: 1342.5611 | E32: 1511.706 | F32: 1728.4613 | G32: 2014.6796 | H32: 2272.3681 | I32: 2626.1623 | J32: 2774.1698 | K32: 2849.2592 | L32: 2860.9893 | M32: 2876.5044 | N32: 2891.3956 | O32: 2898.1147 | P32: 2877.835 | Q32: 2848.6394 | R32: 2839.599 | S32: 2915.8813 | T32: 3098.2654 | U32: 3100.7374 | V32: 3125.6062 | W32: 2906.8163 | X32: 2535.4529 | Y32: 2408.5747 | DA32: NUM.number.CY.Ser.Bld.Thermal.CA.Biomass
A33: Electricity | B33: 15247.305 | C33: 15468.023 | D33: 15496.554 | E33: 15609.9 | F33: 15772.825 | G33: 15881.585 | H33: 13527.108 | I33: 12932.514 | J33: 12844.818 | K33: 13497.172 | L33: 14076.934 | M33: 14211.253 | N33: 14506.813 | O33: 14518.899 | P33: 14467.217 | Q33: 14040.051 | R33: 13791.219 | S33: 13059.995 | T33: 13069.193 | U33: 13419.105 | V33: 13554.857 | W33: 14069.311 | X33: 15022.372 | Y33: 15631.237 | DA33: NUM.number.CY.Ser.Bld.Thermal.CA.Elc

Sheet SER_hh_fec
A1: CY - Final energy consumption | B1: 2000 | C1: 2001 | D1: 2002 | E1: 2003 | F1: 2004 | G1: 2005 | H1: 2006 | I1: 2007 | J1: 2008 | K1: 2009 | L1: 2010 | M1: 2011 | N1: 2012 | O1: 2013 | P1: 2014 | Q1: 2015 | R1: 2016 | S1: 2017 | T1: 2018 | U1: 2019 | V1: 2020 | W1: 2021 | X1: 2022 | Y1: 2023 | DA1: Code
A3: Final energy consumption (ktoe) | B3: =SUM(B4,B16,B19,B29) -> 97.062602 | C3: =SUM(C4,C16,C19,C29) -> 105.688 | D3: =SUM(D4,D16,D19,D29) -> 114.3036 | E3: =SUM(E4,E16,E19,E29) -> 119.12422 | F3: =SUM(F4,F16,F19,F29) -> 119.94612 | G3: =SUM(G4,G16,G19,G29) -> 124.87525 | H3: =SUM(H4,H16,H19,H29) -> 151.02902 | I3: =SUM(I4,I16,I19,I29) -> 158.55646 | ... Y3: =SUM(Y4,Y16,Y19,Y29) -> 194.72176 | DA3: FEC.ktoe.CY.Ser.Bld.Thermal
A4: Space heating | B4: =SUM(B5:B15) -> 32.254552 | C4: =SUM(C5:C15) -> 40.013564 | D4: =SUM(D5:D15) -> 46.239347 | E4: =SUM(E5:E15) -> 47.2052 | F4: =SUM(F5:F15) -> 48.984884 | G4: =SUM(G5:G15) -> 52.807986 | H4: =SUM(H5:H15) -> 74.484315 | I4: =SUM(I5:I15) -> 77.723091 | ... Y4: =SUM(Y5:Y15) -> 101.56881 | DA4: FEC.ktoe.CY.Ser.Bld.Thermal.SH
A5: Solids | B5: 0 | C5: 0 | D5: 0 | E5: 0 | F5: 0 | G5: 0 | H5: 0 | I5: 0 | J5: 0 | K5: 0 | L5: 0 | M5: 0 | N5: 0 | O5: 0 | P5: 0 | Q5: 0 | R5: 0 | S5: 0 | T5: 0 | U5: 0 | V5: 0 | W5: 0 | X5: 0 | Y5: 0 | DA5: FEC.ktoe.CY.Ser.Bld.Thermal.SH.Solids.Solids
A6: Liquified petroleum gas (LPG) | B6: 0 | C6: 0 | D6: 0 | E6: 0 | F6: 0 | G6: 0 | H6: 0 | I6: 0 | J6: 0 | K6: 0 | L6: 0 | M6: 0 | N6: 0 | O6: 0 | P6: 0 | Q6: 0 | R6: 0 | S6: 0 | T6: 0 | U6: 0 | V6: 0 | W6: 0 | X6: 0 | Y6: 0 | DA6: FEC.ktoe.CY.Ser.Bld.Thermal.SH.LPG.LPG
A7: Diesel oil | B7: 24.878464 | C7: 25.144122 | D7: 24.049493 | E7: 24.741742 | F7: 22.14215 | G7: 21.193589 | H7: 24.360985 | I7: 25.409194 | J7: 34.667208 | K7: 26.468512 | L7: 30.596729 | M7: 29.573879 | N7: 25.29509 | O7: 27.304775 | P7: 26.388347 | Q7: 22.347098 | R7: 21.28261 | S7: 25.323036 | T7: 23.678959 | U7: 30.025474 | V7: 24.494762 | W7: 27.588191 | X7: 30.464575 | Y7: 31.082419 | DA7: FEC.ktoe.CY.Ser.Bld.Thermal.SH.Oil.Oil_LiqBio
A8: Gas heat pumps | B8: 0 | C8: 0 | D8: 0 | E8: 0 | F8: 0 | G8: 0 | H8: 0 | I8: 0 | J8: 0 | K8: 0 | L8: 0 | M8: 0 | N8: 0 | O8: 0 | P8: 0 | Q8: 0 | R8: 0 | S8: 0 | T8: 0 | U8: 0 | V8: 0 | W8: 0 | X8: 0 | Y8: 0 | DA8: FEC.ktoe.CY.Ser.Bld.Thermal.SH.GasHP.NG_Biogas
A9: Conventional gas heaters | B9: 0 | C9: 0 | D9: 0 | E9: 0 | F9: 0 | G9: 0 | H9: 0 | I9: 0 | J9: 0 | K9: 0.2627687 | L9: 0.28658641 | M9: 0.2627687 | N9: 0.2627687 | O9: 0.2627687 | P9: 0.28658641 | Q9: 0.28658641 | R9: 0.38211522 | S9: 0.40103181 | T9: 1.0655202 | U9: 1.2809974 | V9: 0.48177128 | W9: 0.56414445 | X9: 0.65468616 | Y9: 0.88564058 | DA9: FEC.ktoe.CY.Ser.Bld.Thermal.SH.GasTH.NG_Biogas
A10: Biomass | B10: 0 | C10: 0 | D10: 0 | E10: 0 | F10: 0 | G10: 0 | H10: 0 | I10: 0.33439381 | J10: 1.3852966 | K10: 1.614583 | L10: 0.46815133 | M10: 0.83599312 | N10: 1.2540499 | O10: 1.1459673 | P10: 1.0653138 | Q10: 2.9912296 | R10: 2.2461737 | S10: 3.1074807 | T10: 1.7008598 | U10: 1.0268348 | V10: 0.93514787 | W10: 3.0187446 | X10: 3.972141 | Y10: 2.5419604 | DA10: FEC.ktoe.CY.Ser.Bld.Thermal.SH.Biomass.Biomass_Waste
A11: Geothermal | B11: 0 | C11: 0 | D11: 0 | E11: 0 | F11: 0 | G11: 0 | H11: 0 | I11: 0 | J11: 0 | K11: 0 | L11: 0 | M11: 0 | N11: 0 | O11: 0 | P11: 0 | Q11: 0 | R11: 0 | S11: 0 | T11: 0 | U11: 0 | V11: 0 | W11: 0 | X11: 0 | Y11: 0 | DA11: FEC.ktoe.CY.Ser.Bld.Thermal.SH.Geo.Geo
A12: Distributed heat | B12: 0 | C12: 0 | D12: 0 | E12: 0 | F12: 0 | G12: 0 | H12: 0 | I12: 0 | J12: 0 | K12: 0 | L12: 0 | M12: 0 | N12: 0 | O12: 0 | P12: 0 | Q12: 0 | R12: 0 | S12: 0 | T12: 0 | U12: 0 | V12: 0 | W12: 0 | X12: 0 | Y12: 0 | DA12: FEC.ktoe.CY.Ser.Bld.Thermal.SH.DistrHeat.Steam_Distr
A13: Advanced electric heating | B13: 0.21128932 | C13: 0.65728557 | D13: 1.0669531 | E13: 1.4957272 | F13: 2.0953407 | G13: 2.880013 | H13: 3.4237306 | I13: 4.01054 | J13: 4.3142448 | K13: 5.2383263 | L13: 5.5215497 | M13: 6.5726024 | N13: 9.4037069 | O13: 16.994 | P13: 16.840126 | Q13: 18.358156 | R13: 17.874159 | S13: 18.120565 | T13: 18.444071 | U13: 18.816473 | V13: 17.00593 | W13: 17.043059 | X13: 17.545126 | Y13: 17.119063 | DA13: FEC.ktoe.CY.Ser.Bld.Thermal.SH.AdvElc.Elec
A14: Conventional electric heating | B14: 6.9717218 | C14: 14.021075 | D14: 20.943759 | E14: 20.786903 | F14: 24.588453 | G14: 28.584819 | H14: 46.530411 | I14: 47.793578 | J14: 54.203552 | K14: 60.409016 | L14: 64.649963 | M14: 58.385305 | N14: 28.857819 | O14: 5.5604234 | P14: 12.152739 | Q14: 13.854572 | R14: 25.587063 | S14: 32.004422 | T14: 32.216251 | U14: 40.633894 | V14: 17.270493 | W14: 32.534188 | X14: 50.517789 | Y14: 49.64023 | DA14: FEC.ktoe.CY.Ser.Bld.Thermal.SH.ConvElc.Elec
A15: Electricity in circulation and other use | B15: 0.1930765 | C15: 0.19108103 | D15: 0.17914175 | E15: 0.18082789 | F15: 0.15894019 | G15: 0.14956561 | H15: 0.16918813 | I15: 0.17538493 | J15: 0.24466967 | K15: 0.19689561 | L15: 0.23063714 | M15: 0.23507914 | N15: 0.21545839 | O15: 0.24244087 | P15: 0.23280745 | Q15: 0.20491448 | R15: 0.19308841 | S15: 0.22974369 | T15: 0.21936864 | U15: 0.27449328 | V15: 0.21798421 | W15: 0.25510183 | X15: 0.29016051 | Y15: 0.29949388 | DA15: FEC.ktoe.CY.Ser.Bld.Thermal.SH.TotalCirculation.Elec
A16: Space cooling | B16: =SUM(B17:B18) -> 16.949729 | C16: =SUM(C17:C18) -> 17.202454 | D16: =SUM(D17:D18) -> 18.809043 | E16: =SUM(E17:E18) -> 21.933364 | F16: =SUM(F17:F18) -> 19.877075 | G16: =SUM(G17:G18) -> 19.489387 | H16: =SUM(H17:H18) -> 23.343422 | I16: =SUM(I17:I18) -> 26.998459 | ... Y16: =SUM(Y17:Y18) -> 31.370503 | DA16: FEC.ktoe.CY.Ser.Bld.Thermal.SC
A17: Gas heat pumps | B17: 0 | C17: 0 | D17: 0 | E17: 0 | F17: 0 | G17: 0 | H17: 0 | I17: 0 | J17: 0 | K17: 0 | L17: 0 | M17: 0 | N17: 0 | O17: 0 | P17: 0 | Q17: 0 | R17: 0 | S17: 0 | T17: 0 | U17: 0 | V17: 0 | W17: 0 | X17: 0 | Y17: 0 | DA17: FEC.ktoe.CY.Ser.Bld.Thermal.SC.GasHP.NG_Biogas
A18: Electric space cooling | B18: 16.949729 | C18: 17.202454 | D18: 18.809043 | E18: 21.933364 | F18: 19.877075 | G18: 19.489387 | H18: 23.343422 | I18: 26.998459 | J18: 28.220353 | K18: 28.598869 | L18: 31.46488 | M18: 27.988637 | N18: 34.108641 | O18: 28.351607 | P18: 24.701099 | Q18: 26.186347 | R18: 29.553906 | S18: 27.903179 | T18: 35.632972 | U18: 30.663743 | V18: 32.232167 | W18: 29.119375 | X18: 27.895686 | Y18: 31.370503 | DA18: FEC.ktoe.CY.Ser.Bld.Thermal.SC.AC.Elec
A19: Hot water | B19: =SUM(B20:B27) -> 26.753195 | C19: =SUM(C20:C27) -> 27.117535 | D19: =SUM(D20:D27) -> 27.360831 | E19: =SUM(E20:E27) -> 27.625941 | F19: =SUM(F20:F27) -> 27.755045 | G19: =SUM(G20:G27) -> 28.303419 | H19: =SUM(H20:H27) -> 27.040172 | I19: =SUM(I20:I27) -> 26.611559 | ... Y19: =SUM(Y20:Y27) -> 29.686166 | DA19: FEC.ktoe.CY.Ser.Bld.Thermal.HW
A20: Solids | B20: 0 | C20: 0 | D20: 0 | E20: 0 | F20: 0 | G20: 0 | H20: 0 | I20: 0 | J20: 0 | K20: 0 | L20: 0 | M20: 0 | N20: 0 | O20: 0 | P20: 0 | Q20: 0 | R20: 0 | S20: 0 | T20: 0 | U20: 0 | V20: 0 | W20: 0 | X20: 0 | Y20: 0 | DA20: FEC.ktoe.CY.Ser.Bld.Thermal.HW.Solids.Solids
A21: Liquified petroleum gas (LPG) | B21: 0 | C21: 0 | D21: 0 | E21: 0 | F21: 0 | G21: 0 | H21: 8.8993442 | I21: 8.9934436 | J21: 9.1230501 | K21: 9.1920626 | L21: 9.4890961 | M21: 9.0461225 | N21: 8.5453432 | O21: 7.9865387 | P21: 6.7827803 | Q21: 6.5764733 | R21: 6.6684546 | S21: 6.7611176 | T21: 6.4019527 | U21: 6.2419201 | V21: 4.8696692 | W21: 4.4135425 | X21: 5.0442263 | Y21: 5.2047441 | DA21: FEC.ktoe.CY.Ser.Bld.Thermal.HW.LPG.LPG
A22: Diesel oil | B22: 1.2011395 | C22: 1.2085676 | D22: 1.2108518 | E22: 1.2013127 | F22: 1.2066037 | G22: 1.2085778 | H22: 1.1907777 | I22: 1.1709435 | J22: 1.153084 | K22: 1.1493729 | L22: 1.1437697 | M22: 1.1463275 | N22: 1.1503095 | O22: 1.1231705 | P22: 1.12584 | Q22: 1.1225491 | R22: 1.1316636 | S22: 1.1186662 | T22: 1.1255126 | U22: 1.1225057 | V22: 1.0263045 | W22: 1.1120674 | X22: 1.2545996 | Y22: 1.2754482 | DA22: FEC.ktoe.CY.Ser.Bld.Thermal.HW.Oil.Oil_LiqBio
A23: Natural gas | B23: 0 | C23: 0 | D23: 0 | E23: 0 | F23: 0 | G23: 0 | H23: 0 | I23: 0 | J23: 0 | K23: 0 | L23: 0 | M23: 0 | N23: 0 | O23: 0 | P23: 0 | Q23: 0 | R23: 0 | S23: 0 | T23: 0 | U23: 0 | V23: 0 | W23: 0 | X23: 0 | Y23: 0 | DA23: FEC.ktoe.CY.Ser.Bld.Thermal.HW.Gas.NG_Biogas
A24: Biomass | B24: 0 | C24: 0 | D24: 0 | E24: 0 | F24: 0 | G24: 0 | H24: 0 | I24: 0 | J24: 0 | K24: 0 | L24: 0 | M24: 0 | N24: 0 | O24: 0 | P24: 0 | Q24: 0 | R24: 0 | S24: 0 | T24: 0 | U24: 0 | V24: 0 | W24: 0 | X24: 0 | Y24: 0 | DA24: FEC.ktoe.CY.Ser.Bld.Thermal.HW.Biomass.Biomass_Waste
A25: Distributed heat | B25: 0 | C25: 0 | D25: 0 | E25: 0 | F25: 0 | G25: 0 | H25: 0 | I25: 0 | J25: 0 | K25: 0 | L25: 0 | M25: 0 | N25: 0 | O25: 0 | P25: 0 | Q25: 0 | R25: 0 | S25: 0 | T25: 0 | U25: 0 | V25: 0 | W25: 0 | X25: 0 | Y25: 0 | DA25: FEC.ktoe.CY.Ser.Bld.Thermal.HW.DistrHeat.Steam_Distr
A26: Electricity | B26: 20.31749 | C26: 20.832918 | D26: 20.957693 | E26: 21.094953 | F26: 20.707987 | G26: 21.0043 | H26: 10.620643 | I26: 8.6130363 | J26: 8.7151109 | K26: 8.914376 | L26: 8.6100387 | M26: 9.2827799 | N26: 9.7709656 | O26: 9.903432 | P26: 10.35366 | Q26: 10.202641 | R26: 10.234367 | S26: 9.6463795 | T26: 9.7404283 | U26: 9.2040879 | V26: 8.6633348 | W26: 8.8992432 | X26: 12.333592 | Y26: 13.909327 | DA26: FEC.ktoe.CY.Ser.Bld.Thermal.HW.Elc.Elec
A27: Solar | B27: 5.2345659 | C27: 5.0760496 | D27: 5.1922864 | E27: 5.3296758 | F27: 5.8404536 | G27: 6.0905417 | H27: 6.3294067 | I27: 7.8341359 | J27: 8.4073947 | K27: 8.6939811 | L27: 9.1239037 | M27: 9.4104901 | N27: 9.6732588 | O27: 9.8643164 | P27: 10.007653 | Q27: 10.174807 | R27: 10.342046 | S27: 10.53233 | T27: 10.748237 | U27: 10.911006 | V27: 11.095357 | W27: 11.288994 | X27: 9.2009458 | Y27: 9.2966466 | DA27: FEC.ktoe.CY.Ser.Bld.Thermal.HW.TotalSolar.Solar
A28: Solar
A29: Catering | B29: =SUM(B30:B33) -> 21.105126 | C29: =SUM(C30:C33) -> 21.354446 | D29: =SUM(D30:D33) -> 21.89438 | E29: =SUM(E30:E33) -> 22.359711 | F29: =SUM(F30:F33) -> 23.329113 | G29: =SUM(G30:G33) -> 24.274463 | H29: =SUM(H30:H33) -> 26.161107 | I29: =SUM(I30:I33) -> 27.223351 | ... Y29: =SUM(Y30:Y33) -> 32.096285 | DA29: FEC.ktoe.CY.Ser.Bld.Thermal.CA
A30: Liquified petroleum gas (LPG) | B30: 0 | C30: 0 | D30: 0 | E30: 0 | F30: 0 | G30: 0 | H30: 5.7873282 | I30: 5.6932288 | J30: 6.693287 | K30: 5.4946098 | L30: 5.1975763 | M30: 6.7702145 | N30: 7.2709939 | O30: 6.7001337 | P30: 5.6443908 | Q30: 6.9804485 | R30: 6.8884672 | S30: 9.6043166 | T30: 10.160042 | U30: 12.720849 | V30: 9.1335123 | W30: 7.8441531 | X30: 9.3226697 | Y30: 8.2143445 | DA30: FEC.ktoe.CY.Ser.Bld.Thermal.CA.LPG
A31: Natural gas | B31: 0 | C31: 0 | D31: 0 | E31: 0 | F31: 0 | G31: 0 | H31: 0 | I31: 0 | J31: 0 | K31: 0 | L31: 0 | M31: 0 | N31: 0 | O31: 0 | P31: 0 | Q31: 0 | R31: 0 | S31: 0 | T31: 0 | U31: 0 | V31: 0 | W31: 0 | X31: 0 | Y31: 0 | DA31: FEC.ktoe.CY.Ser.Bld.Thermal.CA.Gas.NG_Biogas
A32: Biomass | B32: 1.7614789 | C32: 1.7614789 | D32: 2.4660791 | E32: 2.4660791 | F32: 2.9425623 | G32: 3.6782459 | H32: 3.6782459 | I32: 5.1495271 | J32: 5.1495271 | K32: 5.0731212 | L32: 5.0731212 | M32: 5.0731212 | N32: 5.0731212 | O32: 5.0731212 | P32: 5.0731212 | Q32: 4.9321582 | R32: 4.9321582 | S32: 4.9822012 | T32: 5.0527945 | U32: 6.1588058 | V32: 6.0702692 | W32: 4.0993121 | X32: 4.5749785 | Y32: 4.1641445 | DA32: FEC.ktoe.CY.Ser.Bld.Thermal.CA.Biomass.Biomass_Waste
A33: Electricity | B33: 19.343647 | C33: 19.592967 | D33: 19.428301 | E33: 19.893632 | F33: 20.38655 | G33: 20.596217 | H33: 16.695533 | I33: 16.380595 | J33: 16.453691 | K33: 18.036357 | L33: 18.696744 | M33: 18.009407 | N33: 18.14232 | O33: 18.088347 | P33: 18.948526 | Q33: 17.74577 | R33: 17.992725 | S33: 16.095707 | T33: 16.114729 | U33: 13.617123 | V33: 13.358419 | W33: 16.691402 | X33: 16.896408 | Y33: 19.717796 | DA33: FEC.ktoe.CY.Ser.Bld.Thermal.CA.Elc.Elec

Sheet SER_hh_tes
A1: CY - Thermal energy service | B1: 2000 | C1: 2001 | D1: 2002 | E1: 2003 | F1: 2004 | G1: 2005 | H1: 2006 | I1: 2007 | J1: 2008 | K1: 2009 | L1: 2010 | M1: 2011 | N1: 2012 | O1: 2013 | P1: 2014 | Q1: 2015 | R1: 2016 | S1: 2017 | T1: 2018 | U1: 2019 | V1: 2020 | W1: 2021 | X1: 2022 | Y1: 2023 | DA1: Code
A3: Thermal energy service (ktoe useful) | B3: =SUM(B4,B16,B19,B29) -> 75.443503 | C3: =SUM(C4,C16,C19,C29) -> 84.04969 | D3: =SUM(D4,D16,D19,D29) -> 94.878406 | E3: =SUM(E4,E16,E19,E29) -> 105.67644 | F3: =SUM(F4,F16,F19,F29) -> 107.43942 | G3: =SUM(G4,G16,G19,G29) -> 113.78476 | H3: =SUM(H4,H16,H19,H29) -> 140.31148 | I3: =SUM(I4,I16,I19,I29) -> 157.00805 | ... Y3: =SUM(Y4,Y16,Y19,Y29) -> 303.94907 | DA3: TES.ktoe.CY.Ser.Bld.Thermal
A4: Space heating | B4: =SUM(B5:B15) -> 14.117747 | C4: =SUM(C5:C15) -> 19.064543 | D4: =SUM(D5:D15) -> 23.509344 | E4: =SUM(E5:E15) -> 24.589689 | F4: =SUM(F5:F15) -> 27.065019 | G4: =SUM(G5:G15) -> 30.714158 | H4: =SUM(H5:H15) -> 44.013503 | I4: =SUM(I5:I15) -> 46.732137 | ... Y4: =SUM(Y5:Y15) -> 112.59331 | DA4: TES.ktoe.CY.Ser.Bld.Thermal.SH
A5: Solids | B5: 0 | C5: 0 | D5: 0 | E5: 0 | F5: 0 | G5: 0 | H5: 0 | I5: 0 | J5: 0 | K5: 0 | L5: 0 | M5: 0 | N5: 0 | O5: 0 | P5: 0 | Q5: 0 | R5: 0 | S5: 0 | T5: 0 | U5: 0 | V5: 0 | W5: 0 | X5: 0 | Y5: 0 | DA5: TES.ktoe.CY.Ser.Bld.Thermal.SH.Solids.Solids
A6: Liquified petroleum gas (LPG) | B6: 0 | C6: 0 | D6: 0 | E6: 0 | F6: 0 | G6: 0 | H6: 0 | I6: 0 | J6: 0 | K6: 0 | L6: 0 | M6: 0 | N6: 0 | O6: 0 | P6: 0 | Q6: 0 | R6: 0 | S6: 0 | T6: 0 | U6: 0 | V6: 0 | W6: 0 | X6: 0 | Y6: 0 | DA6: TES.ktoe.CY.Ser.Bld.Thermal.SH.LPG.LPG
A7: Diesel oil | B7: 9.653825 | C7: 9.7569108 | D7: 9.3321517 | E7: 9.6007715 | F7: 8.5920274 | G7: 8.2239482 | H7: 9.4530227 | I7: 9.8597692 | J7: 13.660385 | K7: 10.747425 | L7: 13.012583 | M7: 13.257839 | N7: 12.074028 | O7: 13.752664 | P7: 13.294885 | Q7: 11.258837 | R7: 10.72253 | S7: 12.758164 | T7: 11.95621 | U7: 15.328232 | V7: 12.624513 | W7: 14.359728 | X7: 16.069018 | Y7: 16.866079 | DA7: TES.ktoe.CY.Ser.Bld.Thermal.SH.Oil.Oil_LiqBio
A8: Gas heat pumps | B8: 0 | C8: 0 | D8: 0 | E8: 0 | F8: 0 | G8: 0 | H8: 0 | I8: 0 | J8: 0 | K8: 0 | L8: 0 | M8: 0 | N8: 0 | O8: 0 | P8: 0 | Q8: 0 | R8: 0 | S8: 0 | T8: 0 | U8: 0 | V8: 0 | W8: 0 | X8: 0 | Y8: 0 | DA8: TES.ktoe.CY.Ser.Bld.Thermal.SH.GasHP.NG_Biogas
A9: Conventional gas heaters | B9: 0 | C9: 0 | D9: 0 | E9: 0 | F9: 0 | G9: 0 | H9: 0 | I9: 0 | J9: 0 | K9: 0.19314755 | L9: 0.2111107 | M9: 0.19405114 | N9: 0.19447993 | O9: 0.19448672 | P9: 0.21225825 | Q9: 0.21281795 | R9: 0.2940707 | S9: 0.32052322 | T9: 0.87689376 | U9: 1.0655829 | V9: 0.40427339 | W9: 0.4786344 | X9: 0.5606545 | Y9: 0.76580734 | DA9: TES.ktoe.CY.Ser.Bld.Thermal.SH.GasTH.NG_Biogas
A10: Biomass | B10: 0 | C10: 0 | D10: 0 | E10: 0 | F10: 0 | G10: 0 | H10: 0 | I10: 0.15777547 | J10: 0.65806142 | K10: 0.76698482 | L10: 0.22242536 | M10: 0.39834999 | N10: 0.60403844 | O10: 0.55864594 | P10: 0.52509194 | Q10: 1.5026515 | R10: 1.131081 | S10: 1.5674881 | T10: 0.8598484 | U10: 0.51910348 | V10: 0.47501134 | W10: 1.5815538 | X10: 2.1582627 | Y10: 1.4100588 | DA10: TES.ktoe.CY.Ser.Bld.Thermal.SH.Biomass.Biomass_Waste
A11: Geothermal | B11: 0 | C11: 0 | D11: 0 | E11: 0 | F11: 0 | G11: 0 | H11: 0 | I11: 0 | J11: 0 | K11: 0 | L11: 0 | M11: 0 | N11: 0 | O11: 0 | P11: 0 | Q11: 0 | R11: 0 | S11: 0 | T11: 0 | U11: 0 | V11: 0 | W11: 0 | X11: 0 | Y11: 0 | DA11: TES.ktoe.CY.Ser.Bld.Thermal.SH.Geo.Geo
A12: Distributed heat | B12: 0 | C12: 0 | D12: 0 | E12: 0 | F12: 0 | G12: 0 | H12: 0 | I12: 0 | J12: 0 | K12: 0 | L12: 0 | M12: 0 | N12: 0 | O12: 0 | P12: 0 | Q12: 0 | R12: 0 | S12: 0 | T12: 0 | U12: 0 | V12: 0 | W12: 0 | X12: 0 | Y12: 0 | DA12: TES.ktoe.CY.Ser.Bld.Thermal.SH.DistrHeat.Steam_Distr
A13: Advanced electric heating | B13: 0.28091205 | C13: 0.96113693 | D13: 1.6845522 | E13: 2.4957634 | F13: 3.639235 | G13: 5.1603549 | H13: 6.2184154 | I13: 7.4353376 | J13: 8.1498346 | K13: 10.305935 | L13: 11.545156 | M13: 15.033865 | N13: 23.426261 | O13: 44.964333 | P13: 45.69214 | Q13: 50.578177 | R13: 50.067017 | S13: 52.097805 | T13: 54.476143 | U13: 56.82189 | V13: 52.317796 | W13: 53.075131 | X13: 55.239021 | Y13: 55.22835 | DA13: TES.ktoe.CY.Ser.Bld.Thermal.SH.AdvElc.Elec
A14: Conventional electric heating | B14: 3.9899337 | C14: 8.1554138 | D14: 12.313498 | E14: 12.312326 | F14: 14.674817 | G14: 17.180289 | H14: 28.172876 | I14: 29.10387 | J14: 33.189111 | K14: 37.221652 | L14: 40.007147 | M14: 36.253242 | N14: 17.977456 | O14: 3.4754475 | P14: 7.5958613 | Q14: 8.6863096 | R14: 16.274304 | S14: 20.746686 | T14: 21.238127 | U14: 27.250073 | V14: 11.907309 | W14: 23.442395 | X14: 37.920515 | Y14: 38.023517 | DA14: TES.ktoe.CY.Ser.Bld.Thermal.SH.ConvElc.Elec
A15: Electricity in circulation and other use | B15: 0.1930765 | C15: 0.19108103 | D15: 0.17914175 | E15: 0.18082789 | F15: 0.15894019 | G15: 0.14956561 | H15: 0.16918813 | I15: 0.17538493 | J15: 0.24466967 | K15: 0.19689561 | L15: 0.23063714 | M15: 0.23507914 | N15: 0.21545839 | O15: 0.24244087 | P15: 0.23280745 | Q15: 0.20491448 | R15: 0.19308841 | S15: 0.22974369 | T15: 0.21936864 | U15: 0.27449328 | V15: 0.21798421 | W15: 0.25510183 | X15: 0.29016051 | Y15: 0.29949388 | DA15: TES.ktoe.CY.Ser.Bld.Thermal.SH.TotalCirculation.Elec
A16: Space cooling | B16: =SUM(B17:B18) -> 29.044278 | C16: =SUM(C17:C18) -> 32.320609 | D16: =SUM(D17:D18) -> 38.192515 | E16: =SUM(E17:E18) -> 47.278681 | F16: =SUM(F17:F18) -> 45.526493 | G16: =SUM(G17:G18) -> 47.146637 | H16: =SUM(H17:H18) -> 59.344558 | I16: =SUM(I17:I18) -> 72.265248 | ... Y16: =SUM(Y17:Y18) -> 142.64729 | DA16: TES.ktoe.CY.Ser.Bld.Thermal.SC
A17: Gas heat pumps | B17: 0 | C17: 0 | D17: 0 | E17: 0 | F17: 0 | G17: 0 | H17: 0 | I17: 0 | J17: 0 | K17: 0 | L17: 0 | M17: 0 | N17: 0 | O17: 0 | P17: 0 | Q17: 0 | R17: 0 | S17: 0 | T17: 0 | U17: 0 | V17: 0 | W17: 0 | X17: 0 | Y17: 0 | DA17: TES.ktoe.CY.Ser.Bld.Thermal.SC.GasHP.NG_Biogas
A18: Electric space cooling | B18: 29.044278 | C18: 32.320609 | D18: 38.192515 | E18: 47.278681 | F18: 45.526493 | G18: 47.146637 | H18: 59.344558 | I18: 72.265248 | J18: 79.864801 | K18: 83.065982 | L18: 94.675593 | M18: 88.151454 | N18: 111.72962 | O18: 96.317747 | P18: 86.99073 | Q18: 95.59509 | R18: 112.00837 | S18: 109.72995 | T18: 145.27232 | U18: 129.05827 | V18: 139.54483 | W18: 128.85259 | X18: 125.43073 | Y18: 142.64729 | DA18: TES.ktoe.CY.Ser.Bld.Thermal.SC.AC.Elec
A19: Hot water | B19: =SUM(B20:B27) -> 16.410941 | C19: =SUM(C20:C27) -> 16.570923 | D19: =SUM(D20:D27) -> 16.777341 | E19: =SUM(E20:E27) -> 17.014797 | F19: =SUM(F20:F27) -> 17.362258 | G19: =SUM(G20:G27) -> 17.813375 | H19: =SUM(H20:H27) -> 18.29558 | I19: =SUM(I20:I27) -> 18.78241 | ... Y19: =SUM(Y20:Y27) -> 24.04613 | DA19: TES.ktoe.CY.Ser.Bld.Thermal.HW
A20: Solids | B20: 0 | C20: 0 | D20: 0 | E20: 0 | F20: 0 | G20: 0 | H20: 0 | I20: 0 | J20: 0 | K20: 0 | L20: 0 | M20: 0 | N20: 0 | O20: 0 | P20: 0 | Q20: 0 | R20: 0 | S20: 0 | T20: 0 | U20: 0 | V20: 0 | W20: 0 | X20: 0 | Y20: 0 | DA20: TES.ktoe.CY.Ser.Bld.Thermal.HW.Solids.Solids
A21: Liquified petroleum gas (LPG) | B21: 0 | C21: 0 | D21: 0 | E21: 0 | F21: 0 | G21: 0 | H21: 5.7838901 | I21: 5.8488399 | J21: 5.9373107 | K21: 5.9839125 | L21: 6.1794248 | M21: 5.8911854 | N21: 5.5653406 | O21: 5.2016192 | P21: 4.4180925 | Q21: 4.283824 | R21: 4.3479676 | S21: 4.437044 | T21: 4.2642368 | U21: 4.2707203 | V21: 3.4041558 | W21: 3.2579384 | X21: 4.0559792 | Y21: 4.2440332 | DA21: TES.ktoe.CY.Ser.Bld.Thermal.HW.LPG.LPG
A22: Diesel oil | B22: 0.5100294 | C22: 0.5149661 | D22: 0.51706834 | E22: 0.51468071 | F22: 0.51907902 | G22: 0.52240056 | H22: 0.51767684 | I22: 0.5113638 | J22: 0.50654064 | K22: 0.50916943 | L22: 0.51235874 | M22: 0.52042486 | N22: 0.53258584 | O22: 0.53302658 | P22: 0.53899744 | Q22: 0.54286682 | R22: 0.55726885 | S22: 0.56338506 | T22: 0.5851306 | U22: 0.6034109 | V22: 0.56421771 | W22: 0.62986135 | X22: 0.74510621 | Y22: 0.77464511 | DA22: TES.ktoe.CY.Ser.Bld.Thermal.HW.Oil.Oil_LiqBio
A23: Natural gas | B23: 0 | C23: 0 | D23: 0 | E23: 0 | F23: 0 | G23: 0 | H23: 0 | I23: 0 | J23: 0 | K23: 0 | L23: 0 | M23: 0 | N23: 0 | O23: 0 | P23: 0 | Q23: 0 | R23: 0 | S23: 0 | T23: 0 | U23: 0 | V23: 0 | W23: 0 | X23: 0 | Y23: 0 | DA23: TES.ktoe.CY.Ser.Bld.Thermal.HW.Gas.NG_Biogas
A24: Biomass | B24: 0 | C24: 0 | D24: 0 | E24: 0 | F24: 0 | G24: 0 | H24: 0 | I24: 0 | J24: 0 | K24: 0 | L24: 0 | M24: 0 | N24: 0 | O24: 0 | P24: 0 | Q24: 0 | R24: 0 | S24: 0 | T24: 0 | U24: 0 | V24: 0 | W24: 0 | X24: 0 | Y24: 0 | DA24: TES.ktoe.CY.Ser.Bld.Thermal.HW.Biomass.Biomass_Waste
A25: Distributed heat | B25: 0 | C25: 0 | D25: 0 | E25: 0 | F25: 0 | G25: 0 | H25: 0 | I25: 0 | J25: 0 | K25: 0 | L25: 0 | M25: 0 | N25: 0 | O25: 0 | P25: 0 | Q25: 0 | R25: 0 | S25: 0 | T25: 0 | U25: 0 | V25: 0 | W25: 0 | X25: 0 | Y25: 0 | DA25: TES.ktoe.CY.Ser.Bld.Thermal.HW.DistrHeat.Steam_Distr
A26: Electricity | B26: 10.666346 | C26: 10.979908 | D26: 11.067986 | E26: 11.17044 | F26: 11.002725 | G26: 11.200432 | H26: 5.6646068 | I26: 4.5880702 | J26: 4.6425102 | K26: 4.7777285 | L26: 4.6838934 | M26: 5.1289341 | N26: 5.5383939 | O26: 5.7715539 | P26: 6.0774192 | Q26: 6.0052451 | R26: 6.0651256 | S26: 5.7506044 | T26: 5.9248911 | U26: 5.7140701 | V26: 5.4072158 | W26: 5.6979336 | X26: 8.3987647 | Y26: 9.7308054 | DA26: TES.ktoe.CY.Ser.Bld.Thermal.HW.Elc.Elec
A27: Solar | B27: 5.2345659 | C27: 5.0760496 | D27: 5.1922864 | E27: 5.3296758 | F27: 5.8404536 | G27: 6.0905417 | H27: 6.3294067 | I27: 7.8341359 | J27: 8.4073947 | K27: 8.6939811 | L27: 9.1239037 | M27: 9.4104901 | N27: 9.6732588 | O27: 9.8643164 | P27: 10.007653 | Q27: 10.174807 | R27: 10.342046 | S27: 10.53233 | T27: 10.748237 | U27: 10.911006 | V27: 11.095357 | W27: 11.288994 | X27: 9.2009458 | Y27: 9.2966466 | DA27: TES.ktoe.CY.Ser.Bld.Thermal.HW.TotalSolar.Solar
A28: Solar
A29: Catering | B29: =SUM(B30:B33) -> 15.870537 | C29: =SUM(C30:C33) -> 16.093616 | D29: =SUM(D30:D33) -> 16.399206 | E29: =SUM(E30:E33) -> 16.793269 | F29: =SUM(F30:F33) -> 17.485653 | G29: =SUM(G30:G33) -> 18.110594 | H29: =SUM(H30:H33) -> 18.657842 | I29: =SUM(I30:I33) -> 19.228257 | ... Y29: =SUM(Y30:Y33) -> 24.662339 | DA29: TES.ktoe.CY.Ser.Bld.Thermal.CA
A30: Liquified petroleum gas (LPG) | B30: 0 | C30: 0 | D30: 0 | E30: 0 | F30: 0 | G30: 0 | H30: 3.5609775 | I30: 3.5031955 | J30: 4.1186855 | K30: 3.381086 | L30: 3.1983518 | M30: 4.1663751 | N30: 4.4748108 | O30: 4.1236627 | P30: 3.474056 | Q30: 4.2972832 | R30: 4.2426462 | S30: 5.9213905 | T30: 6.2697989 | U30: 7.8532607 | V30: 5.6412159 | W30: 4.8463959 | X30: 5.7610424 | Y30: 5.0784916 | DA30: TES.ktoe.CY.Ser.Bld.Thermal.CA.LPG
A31: Natural gas | B31: 0 | C31: 0 | D31: 0 | E31: 0 | F31: 0 | G31: 0 | H31: 0 | I31: 0 | J31: 0 | K31: 0 | L31: 0 | M31: 0 | N31: 0 | O31: 0 | P31: 0 | Q31: 0 | R31: 0 | S31: 0 | T31: 0 | U31: 0 | V31: 0 | W31: 0 | X31: 0 | Y31: 0 | DA31: TES.ktoe.CY.Ser.Bld.Thermal.CA.Gas.NG_Biogas
A32: Biomass | B32: 1.0001475 | C32: 1.0021227 | D32: 1.406183 | E32: 1.4084799 | F32: 1.6831768 | G32: 2.1069529 | H32: 2.1092985 | I32: 2.9561747 | J32: 2.9584258 | K32: 2.9166134 | L32: 2.91807 | M32: 2.9187575 | N32: 2.9196864 | O32: 2.9208724 | P32: 2.922107 | Q32: 2.8424223 | R32: 2.8452254 | S32: 2.8794177 | T32: 2.9284602 | U32: 3.5778704 | V32: 3.5346647 | W32: 2.3894371 | X32: 2.668941 | Y32: 2.4325375 | DA32: TES.ktoe.CY.Ser.Bld.Thermal.CA.Biomass.Biomass_Waste
A33: Electricity | B33: 14.870389 | C33: 15.091493 | D33: 14.993023 | E33: 15.384789 | F33: 15.802476 | G33: 16.003642 | H33: 12.987566 | I33: 12.768887 | J33: 12.871977 | K33: 14.174794 | L33: 14.742036 | M33: 14.216306 | N33: 14.349119 | O33: 14.346032 | P33: 15.075968 | Q33: 14.164837 | R33: 14.425917 | S33: 12.951817 | T33: 13.061562 | U33: 11.179256 | V33: 11.128041 | W33: 14.138531 | X33: 14.531781 | Y33: 17.15131 | DA33: TES.ktoe.CY.Ser.Bld.Thermal.CA.Elc.Elec

Sheet SER_hh_eff
A1: CY - System efficiency indicator of total stock | B1: 2000 | C1: 2001 | D1: 2002 | E1: 2003 | F1: 2004 | G1: 2005 | H1: 2006 | I1: 2007 | J1: 2008 | K1: 2009 | L1: 2010 | M1: 2011 | N1: 2012 | O1: 2013 | P1: 2014 | Q1: 2015 | R1: 2016 | S1: 2017 | T1: 2018 | U1: 2019 | V1: 2020 | W1: 2021 | X1: 2022 | Y1: 2023 | DA1: Code
A3: Ratio of energy service to energy consumption | B3: =IF(SER_hh_tes!B3=0,"",SER_hh_tes!B3/SER_hh_fec!B3) -> 0.77726644 | C3: =IF(SER_hh_tes!C3=0,"",SER_hh_tes!C3/SER_hh_fec!C3) -> 0.79526239 | D3: =IF(SER_hh_tes!D3=0,"",SER_hh_tes!D3/SER_hh_fec!D3) -> 0.83005614 | E3: =IF(SER_hh_tes!E3=0,"",SER_hh_tes!E3/SER_hh_fec!E3) -> 0.88711128 | F3: =IF(SER_hh_tes!F3=0,"",SER_hh_tes!F3/SER_hh_fec!F3) -> 0.89573073 | G3: =IF(SER_hh_tes!G3=0,"",SER_hh_tes!G3/SER_hh_fec!G3) -> 0.91118744 | H3: =IF(SER_hh_tes!H3=0,"",SER_hh_tes!H3/SER_hh_fec!H3) -> 0.9290366 | I3: =IF(SER_hh_tes!I3=0,"",SER_hh_tes!I3/SER_hh_fec!I3) -> 0.99023434 | ... Y3: =IF(SER_hh_tes!Y3=0,"",SER_hh_tes!Y3/SER_hh_fec!Y3) -> 1.5609404 | DA3: Eff.ratio.CY.Ser.Bld.Thermal
A4: Space heating | B4: =IF(SER_hh_tes!B4=0,"",SER_hh_tes!B4/SER_hh_fec!B4) -> 0.43769783 | C4: =IF(SER_hh_tes!C4=0,"",SER_hh_tes!C4/SER_hh_fec!C4) -> 0.476452 | D4: =IF(SER_hh_tes!D4=0,"",SER_hh_tes!D4/SER_hh_fec!D4) -> 0.50842725 | E4: =IF(SER_hh_tes!E4=0,"",SER_hh_tes!E4/SER_hh_fec!E4) -> 0.52091059 | F4: =IF(SER_hh_tes!F4=0,"",SER_hh_tes!F4/SER_hh_fec!F4) -> 0.55251777 | G4: =IF(SER_hh_tes!G4=0,"",SER_hh_tes!G4/SER_hh_fec!G4) -> 0.58161956 | H4: =IF(SER_hh_tes!H4=0,"",SER_hh_tes!H4/SER_hh_fec!H4) -> 0.59090968 | I4: =IF(SER_hh_tes!I4=0,"",SER_hh_tes!I4/SER_hh_fec!I4) -> 0.60126452 | ... Y4: =IF(SER_hh_tes!Y4=0,"",SER_hh_tes!Y4/SER_hh_fec!Y4) -> 1.1085422 | DA4: Eff.ratio.CY.Ser.Bld.Thermal.SH
A5: Solids | B5: =IF(SER_hh_tes!B5=0,"",SER_hh_tes!B5/SER_hh_fec!B5) | C5: =IF(SER_hh_tes!C5=0,"",SER_hh_tes!C5/SER_hh_fec!C5) | D5: =IF(SER_hh_tes!D5=0,"",SER_hh_tes!D5/SER_hh_fec!D5) | E5: =IF(SER_hh_tes!E5=0,"",SER_hh_tes!E5/SER_hh_fec!E5) | F5: =IF(SER_hh_tes!F5=0,"",SER_hh_tes!F5/SER_hh_fec!F5) | G5: =IF(SER_hh_tes!G5=0,"",SER_hh_tes!G5/SER_hh_fec!G5) | H5: =IF(SER_hh_tes!H5=0,"",SER_hh_tes!H5/SER_hh_fec!H5) | I5: =IF(SER_hh_tes!I5=0,"",SER_hh_tes!I5/SER_hh_fec!I5) | ... Y5: =IF(SER_hh_tes!Y5=0,"",SER_hh_tes!Y5/SER_hh_fec!Y5) | DA5: Eff.ratio.CY.Ser.Bld.Thermal.SH.Solids.Solids
