Workbook

Sheet cover
B6: JRC-IDEES-2023 - Integrated Database of the European Energy System
C10: Italy
C15: Industrial sectors
L28: Prepared by JRC C.6
L30: 45967.477
L31: v2023-1.00
B33: Legal Notice
B35: The information made available is property of the Joint Research Centre of the European Commission.
B36: Neither the European Commission nor any person acting on behalf of the Commission is responsible for the use which might be made of this information.
B38: Use conditions
B39: This work is licensed under
B40: CC BY 4.0

Sheet index
A1: IT | B1: Italy
B3: Click on the link to jump to the sheet
B4: =HYPERLINK("#"&CELL("address",Ind_Summary!$B$2),MID(CELL("filename",Ind_Summary!$B$2),FIND("]",CELL("filename",Ind_Summary!$B$2))+1,256)) -> Ind_Summary | D4: Industrial sectors summary
B5: =HYPERLINK("#"&CELL("address",Ind_Summary_fec!$B$2),MID(CELL("filename",Ind_Summary_fec!$B$2),FIND("]",CELL("filename",Ind_Summary_fec!$B$2))+1,256)) -> Ind_Summary_fec | D5: split of final energy consumption
B6: =HYPERLINK("#"&CELL("address",Ind_Summary_ued!$B$2),MID(CELL("filename",Ind_Summary_ued!$B$2),FIND("]",CELL("filename",Ind_Summary_ued!$B$2))+1,256)) -> Ind_Summary_ued | D6: split of useful energy demand
B8: =HYPERLINK("#"&CELL("address",ISI!$B$2),MID(CELL("filename",ISI!$B$2),FIND("]",CELL("filename",ISI!$B$2))+1,256)) -> ISI | D8: Iron and steel
B9: =HYPERLINK("#"&CELL("address",ISI_fec!$B$2),MID(CELL("filename",ISI_fec!$B$2),FIND("]",CELL("filename",ISI_fec!$B$2))+1,256)) -> ISI_fec | D9: detailed split of final energy consumption
B10: =HYPERLINK("#"&CELL("address",ISI_ued!$B$2),MID(CELL("filename",ISI_ued!$B$2),FIND("]",CELL("filename",ISI_ued!$B$2))+1,256)) -> ISI_ued | D10: detailed split of useful energy demand
B11: =HYPERLINK("#"&CELL("address",ISI_emi!$B$2),MID(CELL("filename",ISI_emi!$B$2),FIND("]",CELL("filename",ISI_emi!$B$2))+1,256)) -> ISI_emi | D11: detailed split of CO2 emissions
B13: =HYPERLINK("#"&CELL("address",NFM!$B$2),MID(CELL("filename",NFM!$B$2),FIND("]",CELL("filename",NFM!$B$2))+1,256)) -> NFM | D13: Non-ferrous metals
B14: =HYPERLINK("#"&CELL("address",NFM_fec!$B$2),MID(CELL("filename",NFM_fec!$B$2),FIND("]",CELL("filename",NFM_fec!$B$2))+1,256)) -> NFM_fec | D14: detailed split of final energy consumption
B15: =HYPERLINK("#"&CELL("address",NFM_ued!$B$2),MID(CELL("filename",NFM_ued!$B$2),FIND("]",CELL("filename",NFM_ued!$B$2))+1,256)) -> NFM_ued | D15: detailed split of useful energy demand
B16: =HYPERLINK("#"&CELL("address",NFM_emi!$B$2),MID(CELL("filename",NFM_emi!$B$2),FIND("]",CELL("filename",NFM_emi!$B$2))+1,256)) -> NFM_emi | D16: detailed split of CO2 emissions
B18: =HYPERLINK("#"&CELL("address",CHI!$B$2),MID(CELL("filename",CHI!$B$2),FIND("]",CELL("filename",CHI!$B$2))+1,256)) -> CHI | D18: Chemical industry
B19: =HYPERLINK("#"&CELL("address",CHI_fec!$B$2),MID(CELL("filename",CHI_fec!$B$2),FIND("]",CELL("filename",CHI_fec!$B$2))+1,256)) -> CHI_fec | D19: detailed split of final energy consumption
B20: =HYPERLINK("#"&CELL("address",CHI_ued!$B$2),MID(CELL("filename",CHI_ued!$B$2),FIND("]",CELL("filename",CHI_ued!$B$2))+1,256)) -> CHI_ued | D20: detailed split of useful energy demand
B21: =HYPERLINK("#"&CELL("address",CHI_emi!$B$2),MID(CELL("filename",CHI_emi!$B$2),FIND("]",CELL("filename",CHI_emi!$B$2))+1,256)) -> CHI_emi | D21: detailed split of CO2 emissions
B23: =HYPERLINK("#"&CELL("address",NMM!$B$2),MID(CELL("filename",NMM!$B$2),FIND("]",CELL("filename",NMM!$B$2))+1,256)) -> NMM | D23: Non-metallic mineral products
B24: =HYPERLINK("#"&CELL("address",NMM_fec!$B$2),MID(CELL("filename",NMM_fec!$B$2),FIND("]",CELL("filename",NMM_fec!$B$2))+1,256)) -> NMM_fec | D24: detailed split of final energy consumption
B25: =HYPERLINK("#"&CELL("address",NMM_ued!$B$2),MID(CELL("filename",NMM_ued!$B$2),FIND("]",CELL("filename",NMM_ued!$B$2))+1,256)) -> NMM_ued | D25: detailed split of useful energy demand
B26: =HYPERLINK("#"&CELL("address",NMM_emi!$B$2),MID(CELL("filename",NMM_emi!$B$2),FIND("]",CELL("filename",NMM_emi!$B$2))+1,256)) -> NMM_emi | D26: detailed split of CO2 emissions
B28: =HYPERLINK("#"&CELL("address",PPA!$B$2),MID(CELL("filename",PPA!$B$2),FIND("]",CELL("filename",PPA!$B$2))+1,256)) -> PPA | D28: Pulp, paper and printing
B29: =HYPERLINK("#"&CELL("address",PPA_fec!$B$2),MID(CELL("filename",PPA_fec!$B$2),FIND("]",CELL("filename",PPA_fec!$B$2))+1,256)) -> PPA_fec | D29: detailed split of final energy consumption
B30: =HYPERLINK("#"&CELL("address",PPA_ued!$B$2),MID(CELL("filename",PPA_ued!$B$2),FIND("]",CELL("filename",PPA_ued!$B$2))+1,256)) -> PPA_ued | D30: detailed split of useful energy demand
B31: =HYPERLINK("#"&CELL("address",PPA_emi!$B$2),MID(CELL("filename",PPA_emi!$B$2),FIND("]",CELL("filename",PPA_emi!$B$2))+1,256)) -> PPA_emi | D31: detailed split of CO2 emissions
B33: =HYPERLINK("#"&CELL("address",FBT!$B$2),MID(CELL("filename",FBT!$B$2),FIND("]",CELL("filename",FBT!$B$2))+1,256)) -> FBT | D33: Food, beverages and tobacco
B34: =HYPERLINK("#"&CELL("address",FBT_fec!$B$2),MID(CELL("filename",FBT_fec!$B$2),FIND("]",CELL("filename",FBT_fec!$B$2))+1,256)) -> FBT_fec | D34: detailed split of final energy consumption
B35: =HYPERLINK("#"&CELL("address",FBT_ued!$B$2),MID(CELL("filename",FBT_ued!$B$2),FIND("]",CELL("filename",FBT_ued!$B$2))+1,256)) -> FBT_ued | D35: detailed split of useful energy demand
B36: =HYPERLINK("#"&CELL("address",FBT_emi!$B$2),MID(CELL("filename",FBT_emi!$B$2),FIND("]",CELL("filename",FBT_emi!$B$2))+1,256)) -> FBT_emi | D36: detailed split of CO2 emissions
B38: =HYPERLINK("#"&CELL("address",TRE!$B$2),MID(CELL("filename",TRE!$B$2),FIND("]",CELL("filename",TRE!$B$2))+1,256)) -> TRE | D38: Transport equipment
B39: =HYPERLINK("#"&CELL("address",TRE_fec!$B$2),MID(CELL("filename",TRE_fec!$B$2),FIND("]",CELL("filename",TRE_fec!$B$2))+1,256)) -> TRE_fec | D39: detailed split of final energy consumption
B40: =HYPERLINK("#"&CELL("address",TRE_ued!$B$2),MID(CELL("filename",TRE_ued!$B$2),FIND("]",CELL("filename",TRE_ued!$B$2))+1,256)) -> TRE_ued | D40: detailed split of useful energy demand
B41: =HYPERLINK("#"&CELL("address",TRE_emi!$B$2),MID(CELL("filename",TRE_emi!$B$2),FIND("]",CELL("filename",TRE_emi!$B$2))+1,256)) -> TRE_emi | D41: detailed split of CO2 emissions
B43: =HYPERLINK("#"&CELL("address",MAE!$B$2),MID(CELL("filename",MAE!$B$2),FIND("]",CELL("filename",MAE!$B$2))+1,256)) -> MAE | D43: Machinery equipment
B44: =HYPERLINK("#"&CELL("address",MAE_fec!$B$2),MID(CELL("filename",MAE_fec!$B$2),FIND("]",CELL("filename",MAE_fec!$B$2))+1,256)) -> MAE_fec | D44: detailed split of final energy consumption
B45: =HYPERLINK("#"&CELL("address",MAE_ued!$B$2),MID(CELL("filename",MAE_ued!$B$2),FIND("]",CELL("filename",MAE_ued!$B$2))+1,256)) -> MAE_ued | D45: detailed split of useful energy demand
B46: =HYPERLINK("#"&CELL("address",MAE_emi!$B$2),MID(CELL("filename",MAE_emi!$B$2),FIND("]",CELL("filename",MAE_emi!$B$2))+1,256)) -> MAE_emi | D46: detailed split of CO2 emissions
B48: =HYPERLINK("#"&CELL("address",TEL!$B$2),MID(CELL("filename",TEL!$B$2),FIND("]",CELL("filename",TEL!$B$2))+1,256)) -> TEL | D48: Textiles and leather
B49: =HYPERLINK("#"&CELL("address",TEL_fec!$B$2),MID(CELL("filename",TEL_fec!$B$2),FIND("]",CELL("filename",TEL_fec!$B$2))+1,256)) -> TEL_fec | D49: detailed split of final energy consumption
B50: =HYPERLINK("#"&CELL("address",TEL_ued!$B$2),MID(CELL("filename",TEL_ued!$B$2),FIND("]",CELL("filename",TEL_ued!$B$2))+1,256)) -> TEL_ued | D50: detailed split of useful energy demand
...

Sheet Ind_Summary
A1: =index!$A$1&": Industry Summary" -> IT: Industry Summary | B1: 2000 | C1: 2001 | D1: 2002 | E1: 2003 | F1: 2004 | G1: 2005 | H1: 2006 | I1: 2007 | J1: 2008 | K1: 2009 | L1: 2010 | M1: 2011 | N1: 2012 | O1: 2013 | P1: 2014 | Q1: 2015 | R1: 2016 | S1: 2017 | T1: 2018 | U1: 2019 | V1: 2020 | W1: 2021 | X1: 2022 | Y1: 2023
A3: Value added (M€2023) | B3: =ISI!B$3+NFM!B$3+CHI!B$3+NMM!B$3+PPA!B$3+FBT!B$3+TRE!B$3+MAE!B$3+TEL!B$3+WWP!B$3+OIS!B$3 -> 415989.92 | C3: =ISI!C$3+NFM!C$3+CHI!C$3+NMM!C$3+PPA!C$3+FBT!C$3+TRE!C$3+MAE!C$3+TEL!C$3+WWP!C$3+OIS!C$3 -> 416911.81 | D3: =ISI!D$3+NFM!D$3+CHI!D$3+NMM!D$3+PPA!D$3+FBT!D$3+TRE!D$3+MAE!D$3+TEL!D$3+WWP!D$3+OIS!D$3 -> 416484.36 | E3: =ISI!E$3+NFM!E$3+CHI!E$3+NMM!E$3+PPA!E$3+FBT!E$3+TRE!E$3+MAE!E$3+TEL!E$3+WWP!E$3+OIS!E$3 -> 404241.44 | F3: =ISI!F$3+NFM!F$3+CHI!F$3+NMM!F$3+PPA!F$3+FBT!F$3+TRE!F$3+MAE!F$3+TEL!F$3+WWP!F$3+OIS!F$3 -> 409466.74 | G3: =ISI!G$3+NFM!G$3+CHI!G$3+NMM!G$3+PPA!G$3+FBT!G$3+TRE!G$3+MAE!G$3+TEL!G$3+WWP!G$3+OIS!G$3 -> 408046.53 | H3: =ISI!H$3+NFM!H$3+CHI!H$3+NMM!H$3+PPA!H$3+FBT!H$3+TRE!H$3+MAE!H$3+TEL!H$3+WWP!H$3+OIS!H$3 -> 419843.16 | I3: =ISI!I$3+NFM!I$3+CHI!I$3+NMM!I$3+PPA!I$3+FBT!I$3+TRE!I$3+MAE!I$3+TEL!I$3+WWP!I$3+OIS!I$3 -> 432503.82 | ... Y3: =ISI!Y$3+NFM!Y$3+CHI!Y$3+NMM!Y$3+PPA!Y$3+FBT!Y$3+TRE!Y$3+MAE!Y$3+TEL!Y$3+WWP!Y$3+OIS!Y$3 -> 430950.43
A4: Iron and steel | B4: =ISI!B$3 -> 9253.4118 | C4: =ISI!C$3 -> 8328.0125 | D4: =ISI!D$3 -> 7657.9868 | E4: =ISI!E$3 -> 8305.7841 | F4: =ISI!F$3 -> 8622.7112 | G4: =ISI!G$3 -> 9049.7471 | H4: =ISI!H$3 -> 9662.0193 | I4: =ISI!I$3 -> 10913.955 | ... Y4: =ISI!Y$3 -> 9646.4752
A5: Non-ferrous metals | B5: =NFM!B$3 -> 2562.5759 | C5: =NFM!C$3 -> 2306.3022 | D5: =NFM!D$3 -> 2120.7499 | E5: =NFM!E$3 -> 2300.1464 | F5: =NFM!F$3 -> 2387.914 | G5: =NFM!G$3 -> 2506.1744 | H5: =NFM!H$3 -> 2675.7328 | I5: =NFM!I$3 -> 3022.4353 | ... Y5: =NFM!Y$3 -> 3741.9292
A6: Alumina production | B6: =NFM!B$4 -> 386.91057 | C6: =NFM!C$4 -> 348.21709 | D6: =NFM!D$4 -> 320.20147 | E6: =NFM!E$4 -> 347.28765 | F6: =NFM!F$4 -> 360.53925 | G6: =NFM!G$4 -> 378.39479 | H6: =NFM!H$4 -> 403.99558 | I6: =NFM!I$4 -> 456.34245 | ... Y6: =NFM!Y$4 -> 0
A7: Aluminium production | B7: =NFM!B$5 -> 1160.7317 | C7: =NFM!C$5 -> 1044.6513 | D7: =NFM!D$5 -> 960.60441 | E7: =NFM!E$5 -> 1041.863 | F7: =NFM!F$5 -> 1081.6177 | G7: =NFM!G$5 -> 1135.1844 | H7: =NFM!H$5 -> 1211.9867 | I7: =NFM!I$5 -> 1369.0273 | ... Y7: =NFM!Y$5 -> 1142.9434
A8: Other non-ferrous metals | B8: =NFM!B$8 -> 1014.9336 | C8: =NFM!C$8 -> 913.43386 | D8: =NFM!D$8 -> 839.94404 | E8: =NFM!E$8 -> 910.9958 | F8: =NFM!F$8 -> 945.75704 | G8: =NFM!G$8 -> 992.59523 | H8: =NFM!H$8 -> 1059.7505 | I8: =NFM!I$8 -> 1197.0655 | ... Y8: =NFM!Y$8 -> 2598.9858
A9: Chemical industry | B9: =CHI!B$3 -> 27023.022 | C9: =CHI!C$3 -> 25841.545 | D9: =CHI!D$3 -> 26550.578 | E9: =CHI!E$3 -> 24887.237 | F9: =CHI!F$3 -> 24326.921 | G9: =CHI!G$3 -> 23338.06 | H9: =CHI!H$3 -> 23011.021 | I9: =CHI!I$3 -> 23153.718 | ... Y9: =CHI!Y$3 -> 25677.2
A10: Basic chemicals | B10: =CHI!B$5 -> 2571.965 | C10: =CHI!C$5 -> 2431.8211 | D10: =CHI!D$5 -> 2460.4948 | E10: =CHI!E$5 -> 2031.7187 | F10: =CHI!F$5 -> 1938.9634 | G10: =CHI!G$5 -> 2256.0056 | H10: =CHI!H$5 -> 2253.2499 | I10: =CHI!I$5 -> 2280.9788 | ... Y10: =CHI!Y$5 -> 3520.6343
A11: Other chemicals | B11: =CHI!B$6 -> 13143.819 | C11: =CHI!C$6 -> 11617.948 | D11: =CHI!D$6 -> 11922.551 | E11: =CHI!E$6 -> 10937.947 | F11: =CHI!F$6 -> 11084.289 | G11: =CHI!G$6 -> 10481.911 | H11: =CHI!H$6 -> 10453.568 | I11: =CHI!I$6 -> 10740.508 | ... Y11: =CHI!Y$6 -> 10121.866
A12: Pharmaceutical products etc. | B12: =CHI!B$7 -> 11307.238 | C12: =CHI!C$7 -> 11791.776 | D12: =CHI!D$7 -> 12167.532 | E12: =CHI!E$7 -> 11917.571 | F12: =CHI!F$7 -> 11303.668 | G12: =CHI!G$7 -> 10600.143 | H12: =CHI!H$7 -> 10304.203 | I12: =CHI!I$7 -> 10132.231 | ... Y12: =CHI!Y$7 -> 12034.7
A13: Non-metallic mineral products | B13: =NMM!B$3 -> 18318.37 | C13: =NMM!C$3 -> 18739.368 | D13: =NMM!D$3 -> 19985.855 | E13: =NMM!E$3 -> 18755.351 | F13: =NMM!F$3 -> 18648.806 | G13: =NMM!G$3 -> 18483.274 | H13: =NMM!H$3 -> 18010.853 | I13: =NMM!I$3 -> 18419.25 | ... Y13: =NMM!Y$3 -> 14245.553
A14: Cement | B14: =NMM!B$4 -> 6346.7143 | C14: =NMM!C$4 -> 6750.7435 | D14: =NMM!D$4 -> 7677.5751 | E14: =NMM!E$4 -> 6618.3752 | F14: =NMM!F$4 -> 6541.5633 | G14: =NMM!G$4 -> 6206.2176 | H14: =NMM!H$4 -> 6777.6001 | I14: =NMM!I$4 -> 6912.3595 | ... Y14: =NMM!Y$4 -> 4299.1971
A15: Ceramics & other NMM | B15: =NMM!B$5 -> 8569.4492 | C15: =NMM!C$5 -> 8389.0777 | D15: =NMM!D$5 -> 8561.008 | E15: =NMM!E$5 -> 8832.3907 | F15: =NMM!F$5 -> 8945.1734 | G15: =NMM!G$5 -> 8802.7491 | H15: =NMM!H$5 -> 8037.0768 | I15: =NMM!I$5 -> 8193.0191 | ... Y15: =NMM!Y$5 -> 6707.739
A16: Glass production | B16: =NMM!B$6 -> 3402.2062 | C16: =NMM!C$6 -> 3599.5465 | D16: =NMM!D$6 -> 3747.2717 | E16: =NMM!E$6 -> 3304.5852 | F16: =NMM!F$6 -> 3162.0689 | G16: =NMM!G$6 -> 3474.3077 | H16: =NMM!H$6 -> 3196.1758 | I16: =NMM!I$6 -> 3313.8713 | ... Y16: =NMM!Y$6 -> 3238.6173
A17: Pulp, paper and printing | B17: =PPA!B$3 -> 15898.922 | C17: =PPA!C$3 -> 15789.752 | D17: =PPA!D$3 -> 15893.328 | E17: =PPA!E$3 -> 14819.038 | F17: =PPA!F$3 -> 14779.195 | G17: =PPA!G$3 -> 14113.259 | H17: =PPA!H$3 -> 14104.578 | I17: =PPA!I$3 -> 14065.917 | ... Y17: =PPA!Y$3 -> 10859.251
A18: Pulp production | B18: =PPA!B$5 -> 34.927106 | C18: =PPA!C$5 -> 32.838482 | D18: =PPA!D$5 -> 32.104187 | E18: =PPA!E$5 -> 32.447328 | F18: =PPA!F$5 -> 33.895123 | G18: =PPA!G$5 -> 32.312425 | H18: =PPA!H$5 -> 30.427785 | I18: =PPA!I$5 -> 29.867975 | ... Y18: =PPA!Y$5 -> 9.011476
A19: Paper production | B19: =PPA!B$6 -> 7271.3191 | C19: =PPA!C$6 -> 6991.0057 | D19: =PPA!D$6 -> 6575.6876 | E19: =PPA!E$6 -> 6374.4243 | F19: =PPA!F$6 -> 6588.9841 | G19: =PPA!G$6 -> 6199.9535 | H19: =PPA!H$6 -> 6006.7332 | I19: =PPA!I$6 -> 5996.53 | ... Y19: =PPA!Y$6 -> 7058.1851
A20: Printing and media reproduction | B20: =PPA!B$7 -> 8592.6754 | C20: =PPA!C$7 -> 8765.9073 | D20: =PPA!D$7 -> 9285.5362 | E20: =PPA!E$7 -> 8412.166 | F20: =PPA!F$7 -> 8156.3163 | G20: =PPA!G$7 -> 7880.9931 | H20: =PPA!H$7 -> 8067.4173 | I20: =PPA!I$7 -> 8039.5191 | ... Y20: =PPA!Y$7 -> 3792.0544
A21: Food, beverages and tobacco | B21: =FBT!B$3 -> 32735.865 | C21: =FBT!C$3 -> 31926.429 | D21: =FBT!D$3 -> 33136.331 | E21: =FBT!E$3 -> 32084.292 | F21: =FBT!F$3 -> 32033.188 | G21: =FBT!G$3 -> 30825.411 | H21: =FBT!H$3 -> 30320.681 | I21: =FBT!I$3 -> 30857.289 | ... Y21: =FBT!Y$3 -> 36715.2
A22: Transport equipment | B22: =TRE!B$3 -> 28068.862 | C22: =TRE!C$3 -> 25689.189 | D22: =TRE!D$3 -> 24218.823 | E22: =TRE!E$3 -> 22669.549 | F22: =TRE!F$3 -> 23782.504 | G22: =TRE!G$3 -> 22636.025 | H22: =TRE!H$3 -> 24729.507 | I22: =TRE!I$3 -> 26185.98 | ... Y22: =TRE!Y$3 -> 28667.6
A23: Machinery equipment | B23: =MAE!B$3 -> 100702.21 | C23: =MAE!C$3 -> 100918.82 | D23: =MAE!D$3 -> 98785.291 | E23: =MAE!E$3 -> 97261.297 | F23: =MAE!F$3 -> 99243.51 | G23: =MAE!G$3 -> 99812.728 | H23: =MAE!H$3 -> 106471.23 | I23: =MAE!I$3 -> 112113.98 | ... Y23: =MAE!Y$3 -> 111315.7
A24: Textiles and leather | B24: =TEL!B$3 -> 43591.189 | C24: =TEL!C$3 -> 44615.992 | D24: =TEL!D$3 -> 41638.422 | E24: =TEL!E$3 -> 38324.253 | F24: =TEL!F$3 -> 35941.335 | G24: =TEL!G$3 -> 34143.576 | H24: =TEL!H$3 -> 33386.482 | I24: =TEL!I$3 -> 34076.203 | ... Y24: =TEL!Y$3 -> 27554.6
A25: Wood and wood products | B25: =WWP!B$3 -> 10278.187 | C25: =WWP!C$3 -> 11234.524 | D25: =WWP!D$3 -> 10164.194 | E25: =WWP!E$3 -> 9442.0057 | F25: =WWP!F$3 -> 9365.9354 | G25: =WWP!G$3 -> 8834.2323 | H25: =WWP!H$3 -> 8994.955 | I25: =WWP!I$3 -> 9042.1002 | ... Y25: =WWP!Y$3 -> 5767.949
A26: Other industrial sectors | B26: =OIS!B$3 -> 127557.31 | C26: =OIS!C$3 -> 131521.88 | D26: =OIS!D$3 -> 136332.8 | E26: =OIS!E$3 -> 135392.49 | F26: =OIS!F$3 -> 140334.72 | G26: =OIS!G$3 -> 144304.04 | H26: =OIS!H$3 -> 148476.09 | I26: =OIS!I$3 -> 150653 | ... Y26: =OIS!Y$3 -> 156758.98
A28: Energy consumption (ktoe)
A29: by fuel (EUROSTAT DATA) | B29: =ISI!B25+NFM!B43+CHI!B32+NMM!B31+PPA!B32+FBT!B12+TRE!B12+MAE!B12+TEL!B12+WWP!B12+OIS!B12 -> 37585.367 | C29: =ISI!C25+NFM!C43+CHI!C32+NMM!C31+PPA!C32+FBT!C12+TRE!C12+MAE!C12+TEL!C12+WWP!C12+OIS!C12 -> 36376.509 | D29: =ISI!D25+NFM!D43+CHI!D32+NMM!D31+PPA!D32+FBT!D12+TRE!D12+MAE!D12+TEL!D12+WWP!D12+OIS!D12 -> 36622.733 | E29: =ISI!E25+NFM!E43+CHI!E32+NMM!E31+PPA!E32+FBT!E12+TRE!E12+MAE!E12+TEL!E12+WWP!E12+OIS!E12 -> 38225.619 | F29: =ISI!F25+NFM!F43+CHI!F32+NMM!F31+PPA!F32+FBT!F12+TRE!F12+MAE!F12+TEL!F12+WWP!F12+OIS!F12 -> 37509.213 | G29: =ISI!G25+NFM!G43+CHI!G32+NMM!G31+PPA!G32+FBT!G12+TRE!G12+MAE!G12+TEL!G12+WWP!G12+OIS!G12 -> 37211.521 | H29: =ISI!H25+NFM!H43+CHI!H32+NMM!H31+PPA!H32+FBT!H12+TRE!H12+MAE!H12+TEL!H12+WWP!H12+OIS!H12 -> 36144.577 | I29: =ISI!I25+NFM!I43+CHI!I32+NMM!I31+PPA!I32+FBT!I12+TRE!I12+MAE!I12+TEL!I12+WWP!I12+OIS!I12 -> 35907.652 | ... Y29: =ISI!Y25+NFM!Y43+CHI!Y32+NMM!Y31+PPA!Y32+FBT!Y12+TRE!Y12+MAE!Y12+TEL!Y12+WWP!Y12+OIS!Y12 -> 23502.313
A30: Solids | B30: =B31+B32 -> 1480.9777 | C30: =C31+C32 -> 1328.4529 | D30: =D31+D32 -> 1237.5825 | E30: =E31+E32 -> 1306.4877 | F30: =F31+F32 -> 1098.1784 | G30: =G31+G32 -> 1326.112 | H30: =H31+H32 -> 1057.503 | I30: =I31+I32 -> 1487.9237 | ... Y30: =Y31+Y32 -> 296.97309
A31: Hard coal and others | B31: =ISI!B27+NFM!B44+CHI!B33+NMM!B32+PPA!B33+FBT!B13+TRE!B13+MAE!B13+TEL!B13+WWP!B13+OIS!B13 -> 563.23388 | C31: =ISI!C27+NFM!C44+CHI!C33+NMM!C32+PPA!C33+FBT!C13+TRE!C13+MAE!C13+TEL!C13+WWP!C13+OIS!C13 -> 554.91591 | D31: =ISI!D27+NFM!D44+CHI!D33+NMM!D32+PPA!D33+FBT!D13+TRE!D13+MAE!D13+TEL!D13+WWP!D13+OIS!D13 -> 479.81995 | E31: =ISI!E27+NFM!E44+CHI!E33+NMM!E32+PPA!E33+FBT!E13+TRE!E13+MAE!E13+TEL!E13+WWP!E13+OIS!E13 -> 528.63826 | F31: =ISI!F27+NFM!F44+CHI!F33+NMM!F32+PPA!F33+FBT!F13+TRE!F13+MAE!F13+TEL!F13+WWP!F13+OIS!F13 -> 285.6963 | G31: =ISI!G27+NFM!G44+CHI!G33+NMM!G32+PPA!G33+FBT!G13+TRE!G13+MAE!G13+TEL!G13+WWP!G13+OIS!G13 -> 377.1773 | H31: =ISI!H27+NFM!H44+CHI!H33+NMM!H32+PPA!H33+FBT!H13+TRE!H13+MAE!H13+TEL!H13+WWP!H13+OIS!H13 -> 139.04497 | I31: =ISI!I27+NFM!I44+CHI!I33+NMM!I32+PPA!I33+FBT!I13+TRE!I13+MAE!I13+TEL!I13+WWP!I13+OIS!I13 -> 590.24531 | ... Y31: =ISI!Y27+NFM!Y44+CHI!Y33+NMM!Y32+PPA!Y33+FBT!Y13+TRE!Y13+MAE!Y13+TEL!Y13+WWP!Y13+OIS!Y13 -> 30.111608
A32: Coke | B32: =ISI!B28 -> 917.74385 | C32: =ISI!C28 -> 773.53697 | D32: =ISI!D28 -> 757.76251 | E32: =ISI!E28 -> 777.84944 | F32: =ISI!F28 -> 812.48212 | G32: =ISI!G28 -> 948.93474 | H32: =ISI!H28 -> 918.45804 | I32: =ISI!I28 -> 897.67842 | ... Y32: =ISI!Y28 -> 266.86148
A33: Liquids | B33: =SUM(B34:B38) -> 6696.5652 | C33: =SUM(C34:C38) -> 5735.8079 | D33: =SUM(D34:D38) -> 6175.2604 | E33: =SUM(E34:E38) -> 7234.7733 | F33: =SUM(F34:F38) -> 6588.5115 | G33: =SUM(G34:G38) -> 6429.7507 | H33: =SUM(H34:H38) -> 5956.3247 | I33: =SUM(I34:I38) -> 6200.4491 | ... Y33: =SUM(Y34:Y38) -> 2871.8661
A34: Refinery gas | B34: =ISI!B30+NFM!B46+CHI!B35+NMM!B34+PPA!B35+FBT!B15+TRE!B15+MAE!B15+TEL!B15+WWP!B15+OIS!B15 -> 0 | C34: =ISI!C30+NFM!C46+CHI!C35+NMM!C34+PPA!C35+FBT!C15+TRE!C15+MAE!C15+TEL!C15+WWP!C15+OIS!C15 -> 0 | D34: =ISI!D30+NFM!D46+CHI!D35+NMM!D34+PPA!D35+FBT!D15+TRE!D15+MAE!D15+TEL!D15+WWP!D15+OIS!D15 -> 0 | E34: =ISI!E30+NFM!E46+CHI!E35+NMM!E34+PPA!E35+FBT!E15+TRE!E15+MAE!E15+TEL!E15+WWP!E15+OIS!E15 -> 133.59845 | F34: =ISI!F30+NFM!F46+CHI!F35+NMM!F34+PPA!F35+FBT!F15+TRE!F15+MAE!F15+TEL!F15+WWP!F15+OIS!F15 -> 0 | G34: =ISI!G30+NFM!G46+CHI!G35+NMM!G34+PPA!G35+FBT!G15+TRE!G15+MAE!G15+TEL!G15+WWP!G15+OIS!G15 -> 0 | H34: =ISI!H30+NFM!H46+CHI!H35+NMM!H34+PPA!H35+FBT!H15+TRE!H15+MAE!H15+TEL!H15+WWP!H15+OIS!H15 -> 0 | I34: =ISI!I30+NFM!I46+CHI!I35+NMM!I34+PPA!I35+FBT!I15+TRE!I15+MAE!I15+TEL!I15+WWP!I15+OIS!I15 -> 316.85297 | ... Y34: =ISI!Y30+NFM!Y46+CHI!Y35+NMM!Y34+PPA!Y35+FBT!Y15+TRE!Y15+MAE!Y15+TEL!Y15+WWP!Y15+OIS!Y15 -> 63.549097
A35: LPG | B35: =ISI!B31+NFM!B47+CHI!B36+NMM!B35+PPA!B36+FBT!B16+TRE!B16+MAE!B16+TEL!B16+WWP!B16+OIS!B16 -> 446.06836 | C35: =ISI!C31+NFM!C47+CHI!C36+NMM!C35+PPA!C36+FBT!C16+TRE!C16+MAE!C16+TEL!C16+WWP!C16+OIS!C16 -> 501.00318 | D35: =ISI!D31+NFM!D47+CHI!D36+NMM!D35+PPA!D36+FBT!D16+TRE!D16+MAE!D16+TEL!D16+WWP!D16+OIS!D16 -> 452.66079 | E35: =ISI!E31+NFM!E47+CHI!E36+NMM!E35+PPA!E36+FBT!E16+TRE!E16+MAE!E16+TEL!E16+WWP!E16+OIS!E16 -> 461.45021 | F35: =ISI!F31+NFM!F47+CHI!F36+NMM!F35+PPA!F36+FBT!F16+TRE!F16+MAE!F16+TEL!F16+WWP!F16+OIS!F16 -> 430.68693 | G35: =ISI!G31+NFM!G47+CHI!G36+NMM!G35+PPA!G36+FBT!G16+TRE!G16+MAE!G16+TEL!G16+WWP!G16+OIS!G16 -> 431.78555 | H35: =ISI!H31+NFM!H47+CHI!H36+NMM!H35+PPA!H36+FBT!H16+TRE!H16+MAE!H16+TEL!H16+WWP!H16+OIS!H16 -> 422.99613 | I35: =ISI!I31+NFM!I47+CHI!I36+NMM!I35+PPA!I36+FBT!I16+TRE!I16+MAE!I16+TEL!I16+WWP!I16+OIS!I16 -> 396.62743 | ... Y35: =ISI!Y31+NFM!Y47+CHI!Y36+NMM!Y35+PPA!Y36+FBT!Y16+TRE!Y16+MAE!Y16+TEL!Y16+WWP!Y16+OIS!Y16 -> 252.52313
A36: Diesel oil (without biofuels) | B36: =ISI!B32+NFM!B48+CHI!B37+NMM!B36+PPA!B37+FBT!B17+TRE!B17+MAE!B17+TEL!B17+WWP!B17+OIS!B17 -> 394.78366 | C36: =ISI!C32+NFM!C48+CHI!C37+NMM!C36+PPA!C37+FBT!C17+TRE!C17+MAE!C17+TEL!C17+WWP!C17+OIS!C17 -> 415.13336 | D36: =ISI!D32+NFM!D48+CHI!D37+NMM!D36+PPA!D37+FBT!D17+TRE!D17+MAE!D17+TEL!D17+WWP!D17+OIS!D17 -> 415.13328 | E36: =ISI!E32+NFM!E48+CHI!E37+NMM!E36+PPA!E37+FBT!E17+TRE!E17+MAE!E17+TEL!E17+WWP!E17+OIS!E17 -> 503.65426 | F36: =ISI!F32+NFM!F48+CHI!F37+NMM!F36+PPA!F37+FBT!F17+TRE!F17+MAE!F17+TEL!F17+WWP!F17+OIS!F17 -> 552.49347 | G36: =ISI!G32+NFM!G48+CHI!G37+NMM!G36+PPA!G37+FBT!G17+TRE!G17+MAE!G17+TEL!G17+WWP!G17+OIS!G17 -> 506.70688 | H36: =ISI!H32+NFM!H48+CHI!H37+NMM!H36+PPA!H37+FBT!H17+TRE!H17+MAE!H17+TEL!H17+WWP!H17+OIS!H17 -> 411.06337 | I36: =ISI!I32+NFM!I48+CHI!I37+NMM!I36+PPA!I37+FBT!I17+TRE!I17+MAE!I17+TEL!I17+WWP!I17+OIS!I17 -> 451.76285 | ... Y36: =ISI!Y32+NFM!Y48+CHI!Y37+NMM!Y36+PPA!Y37+FBT!Y17+TRE!Y17+MAE!Y17+TEL!Y17+WWP!Y17+OIS!Y17 -> 363.13981
A37: Fuel oil | B37: =ISI!B33+NFM!B49+CHI!B38+NMM!B37+PPA!B38+FBT!B18+TRE!B18+MAE!B18+TEL!B18+WWP!B18+OIS!B18 -> 3341.9318 | C37: =ISI!C33+NFM!C49+CHI!C38+NMM!C37+PPA!C38+FBT!C18+TRE!C18+MAE!C18+TEL!C18+WWP!C18+OIS!C18 -> 2938.7599 | D37: =ISI!D33+NFM!D49+CHI!D38+NMM!D37+PPA!D38+FBT!D18+TRE!D18+MAE!D18+TEL!D18+WWP!D18+OIS!D18 -> 3137.4798 | E37: =ISI!E33+NFM!E49+CHI!E38+NMM!E37+PPA!E38+FBT!E18+TRE!E18+MAE!E18+TEL!E18+WWP!E18+OIS!E18 -> 3348.6194 | F37: =ISI!F33+NFM!F49+CHI!F38+NMM!F37+PPA!F38+FBT!F18+TRE!F18+MAE!F18+TEL!F18+WWP!F18+OIS!F18 -> 2363.619 | G37: =ISI!G33+NFM!G49+CHI!G38+NMM!G37+PPA!G38+FBT!G18+TRE!G18+MAE!G18+TEL!G18+WWP!G18+OIS!G18 -> 2135.2824 | H37: =ISI!H33+NFM!H49+CHI!H38+NMM!H37+PPA!H38+FBT!H18+TRE!H18+MAE!H18+TEL!H18+WWP!H18+OIS!H18 -> 2030.19 | I37: =ISI!I33+NFM!I49+CHI!I38+NMM!I37+PPA!I38+FBT!I18+TRE!I18+MAE!I18+TEL!I18+WWP!I18+OIS!I18 -> 2067.45 | ... Y37: =ISI!Y33+NFM!Y49+CHI!Y38+NMM!Y37+PPA!Y38+FBT!Y18+TRE!Y18+MAE!Y18+TEL!Y18+WWP!Y18+OIS!Y18 -> 522.36939
A38: Other liquids | B38: =ISI!B34+NFM!B50+CHI!B39+NMM!B38+PPA!B39+FBT!B19+TRE!B19+MAE!B19+TEL!B19+WWP!B19+OIS!B19 -> 2513.7813 | C38: =ISI!C34+NFM!C50+CHI!C39+NMM!C38+PPA!C39+FBT!C19+TRE!C19+MAE!C19+TEL!C19+WWP!C19+OIS!C19 -> 1880.9114 | D38: =ISI!D34+NFM!D50+CHI!D39+NMM!D38+PPA!D39+FBT!D19+TRE!D19+MAE!D19+TEL!D19+WWP!D19+OIS!D19 -> 2169.9866 | E38: =ISI!E34+NFM!E50+CHI!E39+NMM!E38+PPA!E39+FBT!E19+TRE!E19+MAE!E19+TEL!E19+WWP!E19+OIS!E19 -> 2787.4509 | F38: =ISI!F34+NFM!F50+CHI!F39+NMM!F38+PPA!F39+FBT!F19+TRE!F19+MAE!F19+TEL!F19+WWP!F19+OIS!F19 -> 3241.7121 | G38: =ISI!G34+NFM!G50+CHI!G39+NMM!G38+PPA!G39+FBT!G19+TRE!G19+MAE!G19+TEL!G19+WWP!G19+OIS!G19 -> 3355.9759 | H38: =ISI!H34+NFM!H50+CHI!H39+NMM!H38+PPA!H39+FBT!H19+TRE!H19+MAE!H19+TEL!H19+WWP!H19+OIS!H19 -> 3092.0752 | I38: =ISI!I34+NFM!I50+CHI!I39+NMM!I38+PPA!I39+FBT!I19+TRE!I19+MAE!I19+TEL!I19+WWP!I19+OIS!I19 -> 2967.7558 | ... Y38: =ISI!Y34+NFM!Y50+CHI!Y39+NMM!Y38+PPA!Y39+FBT!Y19+TRE!Y19+MAE!Y19+TEL!Y19+WWP!Y19+OIS!Y19 -> 1670.2847
A39: Gases | B39: =B40+B41 -> 16921.472 | C39: =C40+C41 -> 16698.233 | D39: =D40+D41 -> 16612.819 | E39: =E40+E41 -> 16985.686 | F39: =F40+F41 -> 14341.019 | G39: =G40+G41 -> 13880.976 | H39: =H40+H41 -> 13298.323 | I39: =I40+I41 -> 12572.915 | ... Y39: =Y40+Y41 -> 9695.3363
A40: Natural gas | B40: =ISI!B36+NFM!B52+CHI!B41+NMM!B40+PPA!B41+FBT!B21+TRE!B21+MAE!B21+TEL!B21+WWP!B21+OIS!B21 -> 16625.15 | C40: =ISI!C36+NFM!C52+CHI!C41+NMM!C40+PPA!C41+FBT!C21+TRE!C21+MAE!C21+TEL!C21+WWP!C21+OIS!C21 -> 16652.773 | D40: =ISI!D36+NFM!D52+CHI!D41+NMM!D40+PPA!D41+FBT!D21+TRE!D21+MAE!D21+TEL!D21+WWP!D21+OIS!D21 -> 16588.951 | E40: =ISI!E36+NFM!E52+CHI!E41+NMM!E40+PPA!E41+FBT!E21+TRE!E21+MAE!E21+TEL!E21+WWP!E21+OIS!E21 -> 16963.392 | F40: =ISI!F36+NFM!F52+CHI!F41+NMM!F40+PPA!F41+FBT!F21+TRE!F21+MAE!F21+TEL!F21+WWP!F21+OIS!F21 -> 14338.607 | G40: =ISI!G36+NFM!G52+CHI!G41+NMM!G40+PPA!G41+FBT!G21+TRE!G21+MAE!G21+TEL!G21+WWP!G21+OIS!G21 -> 13861.844 | H40: =ISI!H36+NFM!H52+CHI!H41+NMM!H40+PPA!H41+FBT!H21+TRE!H21+MAE!H21+TEL!H21+WWP!H21+OIS!H21 -> 13294.024 | I40: =ISI!I36+NFM!I52+CHI!I41+NMM!I40+PPA!I41+FBT!I21+TRE!I21+MAE!I21+TEL!I21+WWP!I21+OIS!I21 -> 12572.915 | ... Y40: =ISI!Y36+NFM!Y52+CHI!Y41+NMM!Y40+PPA!Y41+FBT!Y21+TRE!Y21+MAE!Y21+TEL!Y21+WWP!Y21+OIS!Y21 -> 9634.5676
A41: Derived gases | B41: =ISI!B37+NFM!B53+CHI!B42+NMM!B41+PPA!B42+FBT!B22+TRE!B22+MAE!B22+TEL!B22+WWP!B22+OIS!B22 -> 296.32175 | C41: =ISI!C37+NFM!C53+CHI!C42+NMM!C41+PPA!C42+FBT!C22+TRE!C22+MAE!C22+TEL!C22+WWP!C22+OIS!C22 -> 45.459501 | D41: =ISI!D37+NFM!D53+CHI!D42+NMM!D41+PPA!D42+FBT!D22+TRE!D22+MAE!D22+TEL!D22+WWP!D22+OIS!D22 -> 23.867842 | E41: =ISI!E37+NFM!E53+CHI!E42+NMM!E41+PPA!E42+FBT!E22+TRE!E22+MAE!E22+TEL!E22+WWP!E22+OIS!E22 -> 22.293895 | F41: =ISI!F37+NFM!F53+CHI!F42+NMM!F41+PPA!F42+FBT!F22+TRE!F22+MAE!F22+TEL!F22+WWP!F22+OIS!F22 -> 2.4123818 | G41: =ISI!G37+NFM!G53+CHI!G42+NMM!G41+PPA!G42+FBT!G22+TRE!G22+MAE!G22+TEL!G22+WWP!G22+OIS!G22 -> 19.131556 | H41: =ISI!H37+NFM!H53+CHI!H42+NMM!H41+PPA!H42+FBT!H22+TRE!H22+MAE!H22+TEL!H22+WWP!H22+OIS!H22 -> 4.2992261 | I41: =ISI!I37+NFM!I53+CHI!I42+NMM!I41+PPA!I42+FBT!I22+TRE!I22+MAE!I22+TEL!I22+WWP!I22+OIS!I22 -> 0 | ... Y41: =ISI!Y37+NFM!Y53+CHI!Y42+NMM!Y41+PPA!Y42+FBT!Y22+TRE!Y22+MAE!Y22+TEL!Y22+WWP!Y22+OIS!Y22 -> 60.768702
A42: RES and wastes | B42: =SUM(B43:B48) -> 289.70576 | C42: =SUM(C43:C48) -> 300.60181 | D42: =SUM(D43:D48) -> 292.08461 | E42: =SUM(E43:E48) -> 285.25838 | F42: =SUM(F43:F48) -> 282.03878 | G42: =SUM(G43:G48) -> 275.05494 | H42: =SUM(H43:H48) -> 275.79063 | I42: =SUM(I43:I48) -> 244.0049 | ... Y42: =SUM(Y43:Y48) -> 898.7757
...

Sheet Ind_Summary_fec
A1: =index!$A$1&": Industry Summary / final energy consumption" -> IT: Industry Summary / final energy consumption | B1: 2000 | C1: 2001 | D1: 2002 | E1: 2003 | F1: 2004 | G1: 2005 | H1: 2006 | I1: 2007 | J1: 2008 | K1: 2009 | L1: 2010 | M1: 2011 | N1: 2012 | O1: 2013 | P1: 2014 | Q1: 2015 | R1: 2016 | S1: 2017 | T1: 2018 | U1: 2019 | V1: 2020 | W1: 2021 | X1: 2022 | Y1: 2023
A3: Detailed split of energy consumption (ktoe)
A5: All industrial sectors | B5: =SUM(B6:B10,B16,B27) -> 37585.367 | C5: =SUM(C6:C10,C16,C27) -> 36376.509 | D5: =SUM(D6:D10,D16,D27) -> 36622.733 | E5: =SUM(E6:E10,E16,E27) -> 38225.619 | F5: =SUM(F6:F10,F16,F27) -> 37509.213 | G5: =SUM(G6:G10,G16,G27) -> 37211.521 | H5: =SUM(H6:H10,H16,H27) -> 36144.577 | I5: =SUM(I6:I10,I16,I27) -> 35907.652 | ... Y5: =SUM(Y6:Y10,Y16,Y27) -> 23502.313
A6: Lighting | B6: 434.81868 | C6: 433.10836 | D6: 434.28631 | E6: 445.24665 | F6: 443.18326 | G6: 440.45875 | H6: 436.70169 | I6: 433.88089 | J6: 418.49567 | K6: 357.23449 | L6: 368.30095 | M6: 358.11331 | N6: 340.82345 | O6: 325.00302 | P6: 317.94189 | Q6: 325.81521 | R6: 324.09669 | S6: 326.95719 | T6: 326.08086 | U6: 336.20123 | V6: 330.06858 | W6: 338.29175 | X6: 324.36239 | Y6: 308.65081
A7: Air compressors | B7: 723.79945 | C7: 702.67323 | D7: 687.25029 | E7: 704.71037 | F7: 688.42317 | G7: 684.76074 | H7: 676.94487 | I7: 669.93747 | J7: 631.06814 | K7: 544.22993 | L7: 566.88173 | M7: 543.19238 | N7: 527.43025 | O7: 512.95538 | P7: 493.45657 | Q7: 507.97846 | R7: 506.82809 | S7: 512.18057 | T7: 515.50632 | U7: 509.63383 | V7: 503.77708 | W7: 533.30161 | X7: 506.61161 | Y7: 480.80696
A8: Motor drives | B8: 1242.66 | C8: 1229.1996 | D8: 1214.515 | E8: 1235.4541 | F8: 1217.1401 | G8: 1213.612 | H8: 1223.4055 | I8: 1215.0148 | J8: 1151.0488 | K8: 986.53256 | L8: 1040.7587 | M8: 1012.8352 | N8: 978.67561 | O8: 929.98874 | P8: 915.53139 | Q8: 921.23268 | R8: 928.66126 | S8: 944.00081 | T8: 940.63366 | U8: 937.15858 | V8: 919.03351 | W8: 997.21017 | X8: 932.59469 | Y8: 891.2003
A9: Fans and pumps | B9: 1149.3815 | C9: 1118.3494 | D9: 1088.8708 | E9: 1109.2855 | F9: 1079.9208 | G9: 1071.0699 | H9: 1063.7309 | I9: 1050.6658 | J9: 980.96288 | K9: 864.72612 | L9: 897.25165 | M9: 848.16418 | N9: 826.13045 | O9: 800.27305 | P9: 771.54072 | Q9: 795.3711 | R9: 792.66271 | S9: 801.24398 | T9: 804.47766 | U9: 790.88441 | V9: 792.55016 | W9: 824.91973 | X9: 780.0971 | Y9: 739.60663
A10: Low-enthalpy heat | B10: =SUM(B11:B15) -> 956.89401 | C10: =SUM(C11:C15) -> 946.28694 | D10: =SUM(D11:D15) -> 960.87636 | E10: =SUM(E11:E15) -> 991.65601 | F10: =SUM(F11:F15) -> 948.76694 | G10: =SUM(G11:G15) -> 910.72687 | H10: =SUM(H11:H15) -> 888.68524 | I10: =SUM(I11:I15) -> 855.75132 | ... Y10: =SUM(Y11:Y15) -> 546.25629
A11: Diesel oil | B11: 16.971951 | C11: 19.116236 | D11: 19.538603 | E11: 23.703843 | F11: 23.953813 | G11: 21.229127 | H11: 16.527359 | I11: 19.684248 | J11: 16.73856 | K11: 12.873071 | L11: 15.344939 | M11: 34.017524 | N11: 18.783887 | O11: 13.661175 | P11: 16.235434 | Q11: 16.278652 | R11: 14.953076 | S11: 13.046077 | T11: 16.071419 | U11: 15.121616 | V11: 14.944286 | W11: 19.239958 | X11: 14.902937 | Y11: 13.564425
A12: Natural gas | B12: 655.82639 | C12: 629.58929 | D12: 645.02876 | E12: 681.21494 | F12: 599.64287 | G12: 551.39204 | H12: 519.68261 | I12: 491.80297 | J12: 399.33497 | K12: 379.20317 | L12: 338.21164 | M12: 269.29566 | N12: 307.815 | O12: 270.07348 | P12: 277.10332 | Q12: 267.24361 | R12: 272.39797 | S12: 293.75395 | T12: 263.65706 | U12: 241.60177 | V12: 227.1251 | W12: 349.56124 | X12: 283.71707 | Y12: 281.83949
A13: Solar and geothermal | B13: 0 | C13: 0 | D13: 0 | E13: 0 | F13: 0 | G13: 0 | H13: 0 | I13: 0 | J13: 0 | K13: 0 | L13: 9.2672399 | M13: 9.57773 | N13: 9.6732588 | O13: 10.748065 | P13: 10.939123 | Q13: 11.46466 | R13: 12.348323 | S13: 12.689166 | T13: 12.015047 | U13: 12.869304 | V13: 11.584867 | W13: 11.840929 | X13: 11.788306 | Y13: 11.766294
A14: Ambient heat | B14: 0 | C14: 0 | D14: 0 | E14: 0 | F14: 0 | G14: 0 | H14: 0 | I14: 0 | J14: 0 | K14: 0 | L14: 0 | M14: 0 | N14: 0 | O14: 0 | P14: 0 | Q14: 0 | R14: 0 | S14: 0 | T14: 0 | U14: 0 | V14: 0 | W14: 4.2040413 | X14: 6.022012 | Y14: 8.2011178
A15: Electricity | B15: 284.09567 | C15: 297.58142 | D15: 296.30899 | E15: 286.73723 | F15: 325.17026 | G15: 338.1057 | H15: 352.47527 | I15: 344.2641 | J15: 367.70339 | K15: 302.87569 | L15: 327.99869 | M15: 337.23835 | N15: 305.42213 | O15: 307.26851 | P15: 296.79507 | Q15: 286.90634 | R15: 283.58785 | S15: 286.35167 | T15: 293.56177 | U15: 309.76247 | V15: 315.58685 | W15: 235.86798 | X15: 245.79823 | Y15: 230.88496
A16: Steam processes | B16: =SUM(B17:B26) -> 9701.957 | C16: =SUM(C17:C26) -> 9265.9875 | D16: =SUM(D17:D26) -> 9553.4062 | E16: =SUM(E17:E26) -> 10009.594 | F16: =SUM(F17:F26) -> 9947.7602 | G16: =SUM(G17:G26) -> 9555.61 | H16: =SUM(H17:H26) -> 9336.1705 | I16: =SUM(I17:I26) -> 9327.9096 | ... Y16: =SUM(Y17:Y26) -> 5965.7456
A17: Solids | B17: 109.74305 | C17: 98.620716 | D17: 80.847584 | E17: 25.113822 | F17: 12.372202 | G17: 14.997084 | H17: 15.985695 | I17: 20.654974 | J17: 19.306291 | K17: 6.9563844 | L17: 6.2077987 | M17: 7.7294358 | N17: 6.231534 | O17: 3.258756 | P17: 3.2740034 | Q17: 1.8670176 | R17: 11.348447 | S17: 0.98614229 | T17: 18.560149 | U17: 18.065474 | V17: 10.437441 | W17: 3.0757875 | X17: 3.2023003 | Y17: 2.7149993
A18: Refinery gas | B18: 0 | C18: 0 | D18: 0 | E18: 133.59845 | F18: 0 | G18: 0 | H18: 0 | I18: 316.85297 | J18: 228.18143 | K18: 0 | L18: 0 | M18: 21.281169 | N18: 0 | O18: 1.1822872 | P18: 0 | Q18: 0 | R18: 0 | S18: 0 | T18: 0 | U18: 0 | V18: 0 | W18: 0 | X18: 36.785727 | Y18: 63.549097
A19: LPG | B19: 151.3572 | C19: 189.68834 | D19: 168.78725 | E19: 162.08367 | F19: 132.11798 | G19: 133.85324 | H19: 131.58797 | I19: 116.75511 | J19: 91.922882 | K19: 73.606438 | L19: 71.613946 | M19: 89.39285 | N19: 74.42944 | O19: 59.260548 | P19: 44.070394 | Q19: 45.763162 | R19: 56.204339 | S19: 64.298961 | T19: 63.263158 | U19: 65.411513 | V19: 69.426468 | W19: 83.999098 | X19: 106.13552 | Y19: 122.90833
A20: Diesel oil | B20: 159.15954 | C20: 161.30273 | D20: 166.94525 | E20: 202.26371 | F20: 198.50962 | G20: 185.17437 | H20: 144.25335 | I20: 160.91111 | J20: 138.48213 | K20: 114.58389 | L20: 157.2296 | M20: 270.33416 | N20: 144.64573 | O20: 114.29467 | P20: 136.8601 | Q20: 150.26756 | R20: 127.17322 | S20: 111.11521 | T20: 136.79822 | U20: 128.6072 | V20: 146.92854 | W20: 214.53529 | X20: 152.02254 | Y20: 131.1029
A21: Fuel oil | B21: 1531.7624 | C21: 1556.9316 | D21: 1718.9175 | E21: 1852.2527 | F21: 1235.6165 | G21: 1115.8854 | H21: 1044.5376 | I21: 1018.8872 | J21: 1102.7285 | K21: 684.21629 | L21: 291.56694 | M21: 247.51083 | N21: 239.47235 | O21: 245.67483 | P21: 226.83962 | Q21: 322.35957 | R21: 405.62836 | S21: 259.0544 | T21: 233.63435 | U21: 128.70624 | V21: 109.88126 | W21: 218.79939 | X21: 218.71162 | Y21: 221.63061
A22: Other liquids | B22: 713.53309 | C22: 122.85388 | D22: 321.69666 | E22: 458.86452 | F22: 401.63337 | G22: 413.58554 | H22: 375.40449 | I22: 471.19395 | J22: 320.4846 | K22: 292.10991 | L22: 234.44021 | M22: 80.033753 | N22: 526.05085 | O22: 352.07221 | P22: 344.63154 | Q22: 42.946487 | R22: 166.43574 | S22: 149.71577 | T22: 152.39288 | U22: 143.19298 | V22: 70.534396 | W22: 715.76055 | X22: 813.45516 | Y22: 808.24449
A23: Natural gas | B23: 6765.5743 | C23: 6894.078 | D23: 6863.3014 | E23: 6948.822 | F23: 4946.0521 | G23: 4622.4366 | H23: 4522.5002 | I23: 4195.5104 | J23: 3619.5047 | K23: 3562.1246 | L23: 3675.3989 | M23: 3196.0596 | N23: 3001.2614 | O23: 2880.4301 | P23: 2808.7107 | Q23: 2765.9897 | R23: 2751.5402 | S23: 2918.8065 | T23: 2817.9498 | U23: 2778.117 | V23: 2687.0084 | W23: 4552.2344 | X23: 3896.698 | Y23: 3683.7651
A24: Derived gases | B24: 43.563125 | C24: 6.7815366 | D24: 3.6115524 | E24: 3.340785 | F24: 0.31831473 | G24: 2.5687429 | H24: 0.6698427 | I24: 0 | J24: 0 | K24: 0 | L24: 0 | M24: 0 | N24: 21.54616 | O24: 19.012764 | P24: 31.285781 | Q24: 19.7417 | R24: 19.685228 | S24: 14.950825 | T24: 16.976937 | U24: 10.638117 | V24: 9.4427308 | W24: 13.000197 | X24: 11.453786 | Y24: 7.6483377
A25: Biomass and waste | B25: 227.26431 | C25: 235.73066 | D25: 229.29901 | E25: 223.25422 | F25: 220.38543 | G25: 214.85908 | H25: 215.44732 | I25: 193.1417 | J25: 268.83663 | K25: 341.71668 | L25: 222.39819 | M25: 241.95572 | N25: 222.28968 | O25: 231.92899 | P25: 290.92172 | Q25: 329.40807 | R25: 356.40619 | S25: 342.65723 | T25: 347.01912 | U25: 383.13066 | V25: 360.83074 | W25: 356.45706 | X25: 352.23077 | Y25: 362.19328
A26: Distributed steam | B26: 0 | C26: 0 | D26: 0 | E26: 0 | F26: 2800.7547 | G26: 2852.25 | H26: 2885.784 | I26: 2834.0021 | J26: 3028.781 | K26: 2937.6612 | L26: 3129.4066 | M26: 2444.9699 | N26: 2583.0466 | O26: 2560.1892 | P26: 2629.1679 | Q26: 2695.6863 | R26: 2735.6454 | S26: 2873.934 | T26: 2601.7455 | U26: 2942.36 | V26: 2687.3108 | W26: 587.02399 | X26: 555.43646 | Y26: 561.98839
A27: Other processes | B27: =SUM(B28:B37) -> 23375.857 | C27: =SUM(C28:C37) -> 22680.904 | D27: =SUM(D28:D37) -> 22683.528 | E27: =SUM(E28:E37) -> 23729.672 | F27: =SUM(F28:F37) -> 23184.019 | G27: =SUM(G28:G37) -> 23335.283 | H27: =SUM(H28:H37) -> 22518.938 | I27: =SUM(I28:I37) -> 22354.493 | ... Y27: =SUM(Y28:Y37) -> 14570.046
A28: Solids | B28: 453.49083 | C28: 456.29519 | D28: 398.97236 | E28: 503.52444 | F28: 273.3241 | G28: 362.18022 | H28: 123.05928 | I28: 569.59034 | J28: 586.51366 | K28: 117.73029 | L28: 73.206819 | M28: 341.43703 | N28: 307.98351 | O28: 243.28484 | P28: 312.42531 | Q28: 139.82851 | R28: 270.79979 | S28: 146.77319 | T28: 194.33375 | U28: 195.1985 | V28: 158.33556 | W28: 42.062648 | X28: 34.305266 | Y28: 27.396609
A29: Coke | B29: 917.74385 | C29: 773.53697 | D29: 757.76251 | E29: 777.84944 | F29: 812.48212 | G29: 948.93474 | H29: 918.45804 | I29: 897.67842 | J29: 765.38169 | K29: 441.91264 | L29: 540.26939 | M29: 637.24084 | N29: 636.54824 | O29: 457.84368 | P29: 424.18126 | Q29: 397.7546 | R29: 405.8859 | S29: 341.51333 | T29: 410.38504 | U29: 381.79776 | V29: 240.58874 | W29: 257.13439 | X29: 268.69295 | Y29: 266.86148
A30: LPG | B30: 294.71116 | C30: 311.31484 | D30: 283.87354 | E30: 299.36655 | F30: 298.56895 | G30: 297.93231 | H30: 291.40816 | I30: 279.87232 | J30: 219.0067 | K30: 198.86906 | L30: 242.61168 | M30: 213.84602 | N30: 189.25646 | O30: 153.88563 | P30: 96.562108 | Q30: 154.19866 | R30: 164.63255 | S30: 113.689 | T30: 111.42885 | U30: 116.90414 | V30: 121.23716 | W30: 124.06109 | X30: 111.45579 | Y30: 129.6148
A31: Diesel oil | B31: 218.65217 | C31: 234.71439 | D31: 228.64942 | E31: 277.6867 | F31: 330.03003 | G31: 300.30339 | H31: 250.28266 | I31: 271.16749 | J31: 244.65033 | K31: 198.1377 | L31: 301.57275 | M31: 409.92183 | N31: 250.68621 | O31: 208.831 | P31: 239.65322 | Q31: 241.46462 | R31: 218.06296 | S31: 218.73063 | T31: 244.96638 | U31: 234.84126 | V31: 201.55504 | W31: 272.62604 | X31: 254.19301 | Y31: 222.25529
A32: Fuel oil | B32: 1810.1694 | C32: 1381.8284 | D32: 1418.5623 | E32: 1496.3667 | F32: 1128.0025 | G32: 1019.397 | H32: 985.65239 | I32: 1048.5628 | J32: 1141.4675 | K32: 832.93289 | L32: 369.55852 | M32: 333.36235 | N32: 277.39017 | O32: 292.20599 | P32: 295.75513 | Q32: 438.12581 | R32: 596.56897 | S32: 408.27131 | T32: 418.89265 | U32: 295.63976 | V32: 231.37506 | W32: 270.92546 | X32: 289.10825 | Y32: 300.73878
A33: Other liquids | B33: 1800.2483 | C33: 1758.0576 | D33: 1848.2899 | E33: 2328.5864 | F33: 2840.0788 | G33: 2942.3904 | H33: 2716.6707 | I33: 2496.5618 | J33: 2801.3267 | K33: 1918.17 | L33: 1796.6813 | M33: 1791.6343 | N33: 1547.7047 | O33: 1309.6742 | P33: 834.40733 | Q33: 1365.7188 | R33: 911.49969 | S33: 616.3924 | T33: 641.92191 | U33: 627.40263 | V33: 788.00928 | W33: 944.19182 | X33: 1127.3544 | Y33: 862.04021
A34: Natural gas | B34: 9203.7498 | C34: 9129.1057 | D34: 9080.6208 | E34: 9333.3552 | F34: 8792.912 | G34: 8688.0157 | H34: 8251.8413 | I34: 7885.6015 | J34: 7282.4286 | K34: 5955.7273 | L34: 6336.7978 | M34: 5842.4693 | N34: 5753.7353 | O34: 5600.2918 | P34: 5480.4371 | Q34: 5259.8234 | R34: 5357.7686 | S34: 5676.6135 | T34: 5586.2993 | U34: 5537.1683 | V34: 5183.5531 | W34: 6781.4975 | X34: 5999.4763 | Y34: 5730.3067
A35: Derived gases | B35: 252.75863 | C35: 38.677965 | D35: 20.256289 | E35: 18.95311 | F35: 2.094067 | G35: 16.562813 | H35: 3.6293834 | I35: 0 | J35: 0 | K35: 0 | L35: 0 | M35: 0 | N35: 184.24344 | O35: 146.18982 | P35: 249.01181 | Q35: 189.60671 | R35: 215.01907 | S35: 144.20154 | T35: 114.64465 | U35: 98.750877 | V35: 85.768963 | W35: 84.507112 | X35: 76.593935 | Y35: 53.120364
A36: Biomass and waste | B36: 62.441453 | C36: 64.87115 | D36: 62.785598 | E36: 62.004165 | F36: 61.653349 | G36: 60.195859 | H36: 60.343309 | I36: 50.863202 | J36: 73.854683 | K36: 114.02038 | L36: 208.26492 | M36: 250.23414 | N36: 299.99467 | O36: 293.00669 | P36: 277.41216 | Q36: 310.38849 | R36: 280.59579 | S36: 263.934 | T36: 280.66256 | U36: 294.81645 | V36: 358.84965 | W36: 424.70192 | X36: 403.74489 | Y36: 451.48849
A37: Electricity | B37: 8361.8913 | C37: 8532.5016 | D37: 8583.7557 | E37: 8631.9797 | F37: 8644.8727 | G37: 8699.3704 | H37: 8917.593 | I37: 8854.5946 | J37: 8630.0848 | K37: 7314.7365 | L37: 7793.4773 | M37: 7913.0104 | N37: 7367.4339 | O37: 7011.0977 | P37: 6913.9347 | Q37: 6850.1425 | R37: 6902.5125 | S37: 7069.8873 | T37: 7099.9754 | U37: 7394.5039 | V37: 7225.3591 | W37: 7177.9622 | X37: 6809.6546 | Y37: 6526.2234
A39: Market shares of energy uses (%)
A41: =$A$5 -> All industrial sectors | B41: =SUM(B42:B46,B47,B48) -> 1 | C41: =SUM(C42:C46,C47,C48) -> 1 | D41: =SUM(D42:D46,D47,D48) -> 1 | E41: =SUM(E42:E46,E47,E48) -> 1 | F41: =SUM(F42:F46,F47,F48) -> 1 | G41: =SUM(G42:G46,G47,G48) -> 1 | H41: =SUM(H42:H46,H47,H48) -> 1 | I41: =SUM(I42:I46,I47,I48) -> 1 | ... Y41: =SUM(Y42:Y46,Y47,Y48) -> 1
A42: Lighting | B42: =IF(B6=0,0,B6/B$5) -> 0.011568829 | C42: =IF(C6=0,0,C6/C$5) -> 0.011906265 | D42: =IF(D6=0,0,D6/D$5) -> 0.011858381 | E42: =IF(E6=0,0,E6/E$5) -> 0.01164786 | F42: =IF(F6=0,0,F6/F$5) -> 0.011815317 | G42: =IF(G6=0,0,G6/G$5) -> 0.011836623 | H42: =IF(H6=0,0,H6/H$5) -> 0.012082081 | I42: =IF(I6=0,0,I6/I$5) -> 0.012083243 | ... Y42: =IF(Y6=0,0,Y6/Y$5) -> 0.013132785
A43: Air compressors | B43: =IF(B7=0,0,B7/B$5) -> 0.01925748 | C43: =IF(C7=0,0,C7/C$5) -> 0.019316676 | D43: =IF(D7=0,0,D7/D$5) -> 0.018765674 | E43: =IF(E7=0,0,E7/E$5) -> 0.018435552 | F43: =IF(F7=0,0,F7/F$5) -> 0.018353442 | G43: =IF(G7=0,0,G7/G$5) -> 0.018401848 | H43: =IF(H7=0,0,H7/H$5) -> 0.018728809 | I43: =IF(I7=0,0,I7/I$5) -> 0.018657234 | ... Y43: =IF(Y7=0,0,Y7/Y$5) -> 0.020457857
A44: Motor drives | B44: =IF(B8=0,0,B8/B$5) -> 0.033062334 | C44: =IF(C8=0,0,C8/C$5) -> 0.033791026 | D44: =IF(D8=0,0,D8/D$5) -> 0.033162871 | E44: =IF(E8=0,0,E8/E$5) -> 0.032320056 | F44: =IF(F8=0,0,F8/F$5) -> 0.032449096 | G44: =IF(G8=0,0,G8/G$5) -> 0.032613877 | H44: =IF(H8=0,0,H8/H$5) -> 0.033847555 | I44: =IF(I8=0,0,I8/I$5) -> 0.033837211 | ... Y44: =IF(Y8=0,0,Y8/Y$5) -> 0.037919685
...

Sheet Ind_Summary_ued
A1: =index!$A$1&": Industry Summary / useful energy demand" -> IT: Industry Summary / useful energy demand | B1: 2000 | C1: 2001 | D1: 2002 | E1: 2003 | F1: 2004 | G1: 2005 | H1: 2006 | I1: 2007 | J1: 2008 | K1: 2009 | L1: 2010 | M1: 2011 | N1: 2012 | O1: 2013 | P1: 2014 | Q1: 2015 | R1: 2016 | S1: 2017 | T1: 2018 | U1: 2019 | V1: 2020 | W1: 2021 | X1: 2022 | Y1: 2023
A3: Detailed split of useful energy demand (ktoe)
A5: All industrial sectors | B5: =SUM(B6:B10,B16,B27) -> 19685.662 | C5: =SUM(C6:C10,C16,C27) -> 18999.973 | D5: =SUM(D6:D10,D16,D27) -> 19090.039 | E5: =SUM(E6:E10,E16,E27) -> 20023.5 | F5: =SUM(F6:F10,F16,F27) -> 20113.94 | G5: =SUM(G6:G10,G16,G27) -> 19968.779 | H5: =SUM(H6:H10,H16,H27) -> 19461.884 | I5: =SUM(I6:I10,I16,I27) -> 19485.183 | ... Y5: =SUM(Y6:Y10,Y16,Y27) -> 13100.662
A6: Lighting | B6: 204.1994 | C6: 203.11142 | D6: 203.43935 | E6: 208.99685 | F6: 208.25144 | G6: 207.07581 | H6: 205.18945 | I6: 203.79348 | J6: 196.89614 | K6: 167.21557 | L6: 172.56642 | M6: 167.84268 | N6: 159.65287 | O6: 152.58511 | P6: 149.08874 | Q6: 152.99185 | R6: 152.3644 | S6: 153.9239 | T6: 153.83362 | U6: 158.11378 | V6: 154.97676 | W6: 160.24524 | X6: 153.75371 | Y6: 146.37405
A7: Air compressors | B7: 91.424655 | C7: 88.394749 | D7: 86.272344 | E7: 89.06506 | F7: 86.995472 | G7: 86.712795 | H7: 85.658187 | I7: 85.301507 | J7: 80.105282 | K7: 68.952179 | L7: 71.833234 | M7: 68.895142 | N7: 66.835953 | O7: 65.374836 | P7: 62.64175 | Q7: 64.514578 | R7: 64.767852 | S7: 65.959594 | T7: 66.781868 | U7: 65.783398 | V7: 64.959182 | W7: 69.450908 | X7: 65.698716 | Y7: 62.330719
A8: Motor drives | B8: 826.7876 | C8: 815.94807 | D8: 804.63392 | E8: 821.36765 | F8: 810.02763 | G8: 809.15485 | H8: 817.81933 | I8: 813.66536 | J8: 770.98551 | K8: 659.68162 | L8: 697.69268 | M8: 679.7179 | N8: 655.92904 | O8: 625.77117 | P8: 614.9922 | Q8: 619.20926 | R8: 626.52377 | S8: 639.77128 | T8: 639.83015 | U8: 635.86039 | V8: 623.16914 | W8: 682.89986 | X8: 638.44715 | Y8: 611.3494
A9: Fans and pumps | B9: 560.44943 | C9: 542.39975 | D9: 526.74007 | E9: 540.98609 | F9: 526.23299 | G9: 523.09698 | H9: 519.17921 | I9: 516.76143 | J9: 479.84476 | K9: 422.91316 | L9: 438.51093 | M9: 415.22484 | N9: 403.93447 | O9: 394.03629 | P9: 377.97599 | Q9: 389.71994 | R9: 391.38986 | S9: 399.57479 | T9: 404.12562 | U9: 396.21899 | V9: 396.27518 | W9: 416.84744 | X9: 392.51453 | Y9: 372.26392
A10: Low-enthalpy heat | B10: =SUM(B11:B15) -> 665.64458 | C10: =SUM(C11:C15) -> 657.46532 | D10: =SUM(D11:D15) -> 666.24603 | E10: =SUM(E11:E15) -> 688.30755 | F10: =SUM(F11:F15) -> 667.5576 | G10: =SUM(G11:G15) -> 645.8455 | H10: =SUM(H11:H15) -> 633.78112 | I10: =SUM(I11:I15) -> 612.37613 | ... Y10: =SUM(Y11:Y15) -> 410.69758
A11: Diesel oil | B11: 10.205923 | C11: 11.528862 | D11: 11.760391 | E11: 14.279711 | F11: 14.382709 | G11: 12.747723 | H11: 9.9435787 | I11: 11.896543 | J11: 10.122595 | K11: 7.8266129 | L11: 9.3281106 | M11: 19.59858 | N11: 10.963861 | O11: 8.1262234 | P11: 9.5744782 | Q11: 9.7759393 | R11: 9.0500793 | S11: 7.9957527 | T11: 9.8905761 | U11: 9.3116404 | V11: 9.1687162 | W11: 11.976102 | X11: 9.3041169 | Y11: 8.487261
A12: Natural gas | B12: 429.3428 | C12: 410.13973 | D12: 419.92944 | E12: 445.94196 | F12: 395.30594 | G12: 364.81639 | H12: 343.43773 | I12: 325.44383 | J12: 264.64636 | K12: 249.14775 | L12: 222.20979 | M12: 177.36355 | N12: 202.45749 | O12: 179.10251 | P12: 182.7165 | Q12: 177.88863 | R12: 182.6529 | S12: 199.10789 | T12: 179.08082 | U12: 164.17396 | V12: 154.2056 | W12: 240.95689 | X12: 195.21265 | Y12: 194.3206
A13: Solar and geothermal | B13: 0 | C13: 0 | D13: 0 | E13: 0 | F13: 0 | G13: 0 | H13: 0 | I13: 0 | J13: 0 | K13: 0 | L13: 6.2489673 | M13: 6.458333 | N13: 6.5227488 | O13: 7.2474986 | P13: 7.3763302 | Q13: 7.7307039 | R13: 8.3265642 | S13: 8.5563969 | T13: 8.1018338 | U13: 8.677865 | V13: 7.8117599 | W13: 7.9844243 | X13: 7.9489406 | Y13: 7.9340977
A14: Ambient heat | B14: 0 | C14: 0 | D14: 0 | E14: 0 | F14: 0 | G14: 0 | H14: 0 | I14: 0 | J14: 0 | K14: 0 | L14: 0 | M14: 0 | N14: 0 | O14: 0 | P14: 0 | Q14: 0 | R14: 0 | S14: 0 | T14: 0 | U14: 0 | V14: 0 | W14: 4.1082063 | X14: 5.885182 | Y14: 8.0285407
A15: Electricity | B15: 226.09585 | C15: 235.79673 | D15: 234.55619 | E15: 228.08588 | F15: 257.86895 | G15: 268.28139 | H15: 280.39981 | I15: 275.03576 | J15: 292.29589 | K15: 240.86123 | L15: 260.94868 | M15: 267.76936 | N15: 242.82102 | O15: 244.50888 | P15: 236.20335 | Q15: 230.80444 | R15: 229.99322 | S15: 235.20068 | T15: 241.43805 | U15: 253.53681 | V15: 257.58967 | W15: 195.48498 | X15: 204.21269 | Y15: 191.92708
A16: Steam processes | B16: =SUM(B17:B26) -> 5284.1084 | C16: =SUM(C17:C26) -> 5006.9528 | D16: =SUM(D17:D26) -> 5105.9181 | E16: =SUM(E17:E26) -> 5400.6515 | F16: =SUM(F17:F26) -> 5605.1028 | G16: =SUM(G17:G26) -> 5403.5074 | H16: =SUM(H17:H26) -> 5274.7273 | I16: =SUM(I17:I26) -> 5385.2444 | ... Y16: =SUM(Y17:Y26) -> 3575.9084
A17: Solids | B17: 44.547591 | C17: 40.584037 | D17: 32.850553 | E17: 10.54276 | F17: 5.1814796 | G17: 6.3040478 | H17: 6.1612691 | I17: 8.779625 | J17: 8.2357664 | K17: 3.1013312 | L17: 2.8653588 | M17: 3.8138342 | N17: 3.1073798 | O17: 1.6278712 | P17: 1.6726174 | Q17: 0.92092041 | R17: 3.6195827 | S17: 0.51383556 | T17: 7.8981285 | U17: 7.5870718 | V17: 4.3600817 | W17: 1.4138118 | X17: 1.4594848 | Y17: 1.2363999
A18: Refinery gas | B18: 0 | C18: 0 | D18: 0 | E18: 86.393884 | F18: 0 | G18: 0 | H18: 0 | I18: 210.50123 | J18: 148.23924 | K18: 0 | L18: 0 | M18: 13.66105 | N18: 0 | O18: 0.77324356 | P18: 0 | Q18: 0 | R18: 0 | S18: 0 | T18: 0 | U18: 0 | V18: 0 | W18: 0 | X18: 26.03611 | Y18: 45.054309
A19: LPG | B19: 76.597206 | C19: 102.16846 | D19: 89.737825 | E19: 83.315765 | F19: 68.070218 | G19: 69.749943 | H19: 69.582084 | I19: 62.861186 | J19: 49.074419 | K19: 40.628627 | L19: 40.165877 | M19: 49.480747 | N19: 40.803025 | O19: 31.827722 | P19: 23.778747 | Q19: 25.597495 | R19: 30.986288 | S19: 35.217187 | T19: 35.085385 | U19: 36.351278 | V19: 39.874121 | W19: 50.133706 | X19: 64.187997 | Y19: 74.359433
A20: Diesel oil | B20: 76.507644 | C20: 77.908529 | D20: 80.263856 | E20: 97.335048 | F20: 104.07443 | G20: 96.112459 | H20: 74.960912 | I20: 85.527758 | J20: 73.396852 | K20: 60.265773 | L20: 82.993877 | M20: 163.33575 | N20: 85.433193 | O20: 65.402001 | P20: 78.798947 | Q20: 88.281671 | R20: 74.787947 | S20: 64.839111 | T20: 83.924376 | U20: 79.313071 | V20: 90.582979 | W20: 127.73118 | X20: 94.080258 | Y20: 81.304959
A21: Fuel oil | B21: 715.54161 | C21: 702.56031 | D21: 755.96756 | E21: 831.82502 | F21: 559.34775 | G21: 507.82419 | H21: 478.66988 | I21: 481.27941 | J21: 512.70025 | K21: 321.46676 | L21: 135.06059 | M21: 128.14785 | N21: 114.65724 | O21: 118.22928 | P21: 110.06187 | Q21: 158.86511 | R21: 194.92693 | S21: 126.13098 | T21: 115.49077 | U21: 65.856613 | V21: 57.212232 | W21: 114.94759 | X21: 119.81779 | Y21: 123.37621
A22: Other liquids | B22: 423.28655 | C22: 69.151224 | D22: 185.8979 | E22: 270.46353 | F22: 237.64238 | G22: 245.43675 | H22: 222.83269 | I22: 286.10719 | J22: 189.73807 | K22: 174.80244 | L22: 139.26788 | M22: 46.41683 | N22: 314.21719 | O22: 212.20314 | P22: 205.37557 | Q22: 24.885896 | R22: 102.36798 | S22: 93.353604 | T22: 96.457069 | U22: 91.389468 | V22: 44.119051 | W22: 467.05198 | X22: 529.84179 | Y22: 528.01602
A23: Natural gas | B23: 3846.7223 | C23: 3928.762 | D23: 3880.4046 | E23: 3942.4078 | F23: 2812.8782 | G23: 2626.7358 | H23: 2581.6302 | I23: 2422.2034 | J23: 2054.3106 | K23: 2064.7062 | L23: 2139.2399 | M23: 1810.5439 | N23: 1702.4064 | O23: 1632.072 | P23: 1593.9238 | Q23: 1594.0015 | R23: 1587.022 | S23: 1688.0592 | T23: 1633.581 | U23: 1617.6388 | V23: 1567.1837 | W23: 2774.1761 | X23: 2313.5875 | Y23: 2187.2348
A24: Derived gases | B24: 21.682508 | C24: 3.3794617 | D24: 1.8009787 | E24: 1.6678928 | F24: 0.15963945 | G24: 1.2916538 | H24: 0.33983661 | I24: 0 | J24: 0 | K24: 0 | L24: 0 | M24: 0 | N24: 10.967916 | O24: 9.6993983 | P24: 15.965742 | Q24: 10.102689 | R24: 10.158675 | S24: 7.8965363 | T24: 9.0730865 | U24: 5.6866209 | V24: 5.0619943 | W24: 7.0451722 | X24: 6.2017847 | Y24: 4.1558118
A25: Biomass and waste | B25: 79.22299 | C25: 82.438692 | D25: 78.994794 | E25: 76.699818 | F25: 75.579375 | G25: 73.528352 | H25: 73.741316 | I25: 65.709937 | J25: 94.760078 | K25: 120.13665 | L25: 97.468701 | M25: 103.15247 | N25: 93.395871 | O25: 98.807299 | P25: 117.44479 | Q25: 134.76195 | R25: 146.49326 | S25: 142.05237 | T25: 146.7488 | U25: 158.05659 | V25: 148.69937 | W25: 157.48343 | X25: 156.26002 | Y25: 161.2679
A26: Distributed steam | B26: 0 | C26: 0 | D26: 0 | E26: 0 | F26: 1742.1693 | G26: 1776.5242 | H26: 1766.8091 | I26: 1762.2746 | J26: 1805.5064 | K26: 1780.3374 | L26: 1805.3301 | M26: 1587.687 | N26: 1651.1989 | O26: 1688.121 | P26: 1675.5806 | Q26: 1747.954 | R26: 1776.1639 | S26: 1885.2744 | T26: 1715.3643 | U26: 1873.8159 | V26: 1759.3005 | W26: 396.02235 | X26: 376.61638 | Y26: 369.90258
A27: Other processes | B27: =SUM(B28:B37) -> 12053.048 | C27: =SUM(C28:C37) -> 11685.701 | D27: =SUM(D28:D37) -> 11696.79 | E27: =SUM(E28:E37) -> 12274.126 | F27: =SUM(F28:F37) -> 12209.772 | G27: =SUM(G28:G37) -> 12293.385 | H27: =SUM(H28:H37) -> 11925.53 | I27: =SUM(I28:I37) -> 11868.04 | ... Y27: =SUM(Y28:Y37) -> 7921.7375
A28: Solids | B28: 223.95056 | C28: 224.5908 | D28: 198.76092 | E28: 265.75308 | F28: 141.74139 | G28: 186.59936 | H28: 61.286273 | I28: 299.43267 | J28: 307.41152 | K28: 58.695188 | L28: 35.35194 | M28: 174.02459 | N28: 156.8674 | O28: 125.01309 | P28: 162.67934 | Q28: 70.150707 | R28: 125.69135 | S28: 77.195102 | T28: 94.863992 | U28: 95.972268 | V28: 78.434878 | W28: 19.830069 | X28: 15.765323 | Y28: 12.332778
A29: Coke | B29: 494.46449 | C29: 416.76832 | D29: 408.26931 | E29: 419.0918 | F29: 440.04345 | G29: 516.84992 | H29: 503.47249 | I29: 492.0817 | J29: 419.5604 | K29: 242.2439 | L29: 296.16026 | M29: 349.31725 | N29: 348.93758 | O29: 250.97684 | P29: 232.52406 | Q29: 218.03772 | R29: 222.49507 | S29: 187.20786 | T29: 224.96137 | U29: 209.29064 | V29: 131.88388 | W29: 140.95374 | X29: 147.28981 | Y29: 146.28585
A30: LPG | B30: 143.34772 | C30: 149.65552 | D30: 137.52978 | E30: 146.16376 | F30: 145.54894 | G30: 144.07245 | H30: 140.67905 | I30: 138.77825 | J30: 109.37878 | K30: 97.672824 | L30: 118.15442 | M30: 103.29671 | N30: 91.453706 | O30: 74.815705 | P30: 46.655959 | Q30: 75.219978 | R30: 81.450168 | S30: 53.377696 | T30: 52.806043 | U30: 55.397723 | V30: 57.369454 | W30: 60.623346 | X30: 54.926661 | Y30: 64.055015
A31: Diesel oil | B31: 75.80898 | C31: 91.224041 | D31: 88.140804 | E31: 107.03828 | F31: 127.06769 | G31: 115.09431 | H31: 96.120494 | I31: 110.55268 | J31: 97.000357 | K31: 80.063616 | L31: 118.86884 | M31: 169.05435 | N31: 104.55986 | O31: 84.540715 | P31: 98.090086 | Q31: 100.9897 | R31: 92.340804 | S31: 91.607272 | T31: 105.90123 | U31: 101.46172 | V31: 89.343124 | W31: 120.1028 | X31: 117.03006 | Y31: 102.54251
A32: Fuel oil | B32: 769.93643 | C32: 530.83571 | D32: 543.93804 | E32: 575.02112 | F32: 473.19949 | G32: 436.75346 | H32: 420.64115 | I32: 419.47122 | J32: 461.26197 | K32: 336.10282 | L32: 163.59881 | M32: 134.98023 | N32: 116.12158 | O32: 117.94779 | P32: 121.18459 | Q32: 185.23335 | R32: 256.14625 | S32: 177.05624 | T32: 179.24467 | U32: 125.31079 | V32: 97.98706 | W32: 117.65609 | X32: 131.97071 | Y32: 136.68732
A33: Other liquids | B33: 1011.4198 | C33: 986.13291 | D33: 1036.7099 | E33: 1313.8145 | F33: 1618.063 | G33: 1677.6312 | H33: 1543.3541 | I33: 1418.269 | J33: 1603.3253 | K33: 1091.4788 | L33: 1020.2074 | M33: 1019.5566 | N33: 885.03502 | O33: 750.82607 | P33: 477.64716 | Q33: 784.57647 | R33: 521.74326 | S33: 352.3301 | T33: 366.95814 | U33: 358.01588 | V33: 448.66418 | W33: 538.13417 | X33: 643.09177 | Y33: 493.55194
A34: Natural gas | B34: 4489.5122 | C34: 4441.7174 | D34: 4421.9412 | E34: 4554.9673 | F34: 4357.3947 | G34: 4274.2915 | H34: 4076.7244 | I34: 3947.3859 | J34: 3643.9123 | K34: 2934.5483 | L34: 3124.7064 | M34: 2811.4155 | N34: 2778.2785 | O34: 2710.3862 | P34: 2651.6164 | Q34: 2531.9533 | R34: 2606.7956 | S34: 2786.0666 | T34: 2756.5853 | U34: 2734.7322 | V34: 2545.9575 | W34: 3301.6213 | X34: 2920.6573 | Y34: 2794.2861
A35: Derived gases | B35: 119.40388 | C35: 18.351899 | D35: 9.5651537 | E35: 8.9648491 | F35: 0.99385567 | G35: 7.8770175 | H35: 1.7360248 | I35: 0 | J35: 0 | K35: 0 | L35: 0 | M35: 0 | N35: 88.747741 | O35: 70.23037 | P35: 119.83396 | Q35: 89.802507 | R35: 103.38375 | S35: 69.794269 | T35: 55.305694 | U35: 47.707613 | V35: 41.564376 | W35: 41.411918 | X35: 37.482133 | Y35: 25.877712
A36: Biomass and waste | B36: 36.928494 | C36: 38.241729 | D36: 36.954319 | E36: 36.820681 | F36: 37.023203 | G36: 36.20249 | H36: 36.032828 | I36: 30.370261 | J36: 44.595012 | K36: 68.093523 | L36: 123.88268 | M36: 149.46308 | N36: 180.83986 | O36: 177.47604 | P36: 167.55913 | Q36: 188.73734 | R36: 169.46089 | S36: 158.97772 | T36: 169.08475 | U36: 177.01108 | V36: 214.55187 | W36: 254.41231 | X36: 242.26147 | Y36: 272.79292
A37: Electricity | B37: 4688.275 | C37: 4788.1824 | D37: 4814.9801 | E37: 4846.4903 | F37: 4868.6968 | G37: 4898.0135 | H37: 5045.4831 | I37: 5011.6988 | J37: 4896.3528 | K37: 4109.7561 | L37: 4402.9332 | M37: 4485.6012 | N37: 4178.85 | O37: 3995.9611 | P37: 3945.1638 | Q37: 3906.0156 | R37: 3959.8062 | S37: 4095.559 | T37: 4137.9879 | U37: 4285.2619 | V37: 4159.7652 | W37: 4244.7487 | X37: 4026.078 | Y37: 3873.3253
A39: Market shares of useful energy demand (%)
A41: =$A$5 -> All industrial sectors | B41: =SUM(B42:B46,B47,B48) -> 1 | C41: =SUM(C42:C46,C47,C48) -> 1 | D41: =SUM(D42:D46,D47,D48) -> 1 | E41: =SUM(E42:E46,E47,E48) -> 1 | F41: =SUM(F42:F46,F47,F48) -> 1 | G41: =SUM(G42:G46,G47,G48) -> 1 | H41: =SUM(H42:H46,H47,H48) -> 1 | I41: =SUM(I42:I46,I47,I48) -> 1 | ... Y41: =SUM(Y42:Y46,Y47,Y48) -> 1
A42: Lighting | B42: =IF(B6=0,0,B6/B$5) -> 0.010373002 | C42: =IF(C6=0,0,C6/C$5) -> 0.01069009 | D42: =IF(D6=0,0,D6/D$5) -> 0.010656833 | E42: =IF(E6=0,0,E6/E$5) -> 0.010437578 | F42: =IF(F6=0,0,F6/F$5) -> 0.010353587 | G42: =IF(G6=0,0,G6/G$5) -> 0.010369979 | H42: =IF(H6=0,0,H6/H$5) -> 0.010543144 | I42: =IF(I6=0,0,I6/I$5) -> 0.010458895 | ... Y42: =IF(Y6=0,0,Y6/Y$5) -> 0.011173027
A43: Air compressors | B43: =IF(B7=0,0,B7/B$5) -> 0.0046442257 | C43: =IF(C7=0,0,C7/C$5) -> 0.0046523619 | D43: =IF(D7=0,0,D7/D$5) -> 0.0045192334 | E43: =IF(E7=0,0,E7/E$5) -> 0.0044480265 | F43: =IF(F7=0,0,F7/F$5) -> 0.0043251332 | G43: =IF(G7=0,0,G7/G$5) -> 0.0043424186 | H43: =IF(H7=0,0,H7/H$5) -> 0.0044013306 | I43: =IF(I7=0,0,I7/I$5) -> 0.0043777627 | ... Y43: =IF(Y7=0,0,Y7/Y$5) -> 0.0047578299
A44: Motor drives | B44: =IF(B8=0,0,B8/B$5) -> 0.041999483 | C44: =IF(C8=0,0,C8/C$5) -> 0.042944697 | D44: =IF(D8=0,0,D8/D$5) -> 0.042149412 | E44: =IF(E8=0,0,E8/E$5) -> 0.041020183 | F44: =IF(F8=0,0,F8/F$5) -> 0.040271952 | G44: =IF(G8=0,0,G8/G$5) -> 0.040520998 | H44: =IF(H8=0,0,H8/H$5) -> 0.04202159 | I44: =IF(I8=0,0,I8/I$5) -> 0.041758159 | ... Y44: =IF(Y8=0,0,Y8/Y$5) -> 0.046665537
...

Sheet Ind_Summary_emi
A1: =index!$A$1&": Industry Summary / CO2 emissions" -> IT: Industry Summary / CO2 emissions | B1: 2000 | C1: 2001 | D1: 2002 | E1: 2003 | F1: 2004 | G1: 2005 | H1: 2006 | I1: 2007 | J1: 2008 | K1: 2009 | L1: 2010 | M1: 2011 | N1: 2012 | O1: 2013 | P1: 2014 | Q1: 2015 | R1: 2016 | S1: 2017 | T1: 2018 | U1: 2019 | V1: 2020 | W1: 2021 | X1: 2022 | Y1: 2023 | DA1: Code
A3: Detailed split of CO2 emissions (kt of CO2)
A5: All industrial sectors | B5: =SUM(B6:B10,B16,B27,B38) -> 97005.136 | C5: =SUM(C6:C10,C16,C27,C38) -> 92555.41 | D5: =SUM(D6:D10,D16,D27,D38) -> 93175.371 | E5: =SUM(E6:E10,E16,E27,E38) -> 99108.546 | F5: =SUM(F6:F10,F16,F27,F38) -> 90950.824 | G5: =SUM(G6:G10,G16,G27,G38) -> 91225.651 | H5: =SUM(H6:H10,H16,H27,H38) -> 86976.96 | I5: =SUM(I6:I10,I16,I27,I38) -> 87744.287 | ... Y5: =SUM(Y6:Y10,Y16,Y27,Y38) -> 48271.504
A6: Lighting | B6: 0 | C6: 0 | D6: 0 | E6: 0 | F6: 0 | G6: 0 | H6: 0 | I6: 0 | J6: 0 | K6: 0 | L6: 0 | M6: 0 | N6: 0 | O6: 0 | P6: 0 | Q6: 0 | R6: 0 | S6: 0 | T6: 0 | U6: 0 | V6: 0 | W6: 0 | X6: 0 | Y6: 0
A7: Air compressors | B7: 0 | C7: 0 | D7: 0 | E7: 0 | F7: 0 | G7: 0 | H7: 0 | I7: 0 | J7: 0 | K7: 0 | L7: 0 | M7: 0 | N7: 0 | O7: 0 | P7: 0 | Q7: 0 | R7: 0 | S7: 0 | T7: 0 | U7: 0 | V7: 0 | W7: 0 | X7: 0 | Y7: 0
A8: Motor drives | B8: 0 | C8: 0 | D8: 0 | E8: 0 | F8: 0 | G8: 0 | H8: 0 | I8: 0 | J8: 0 | K8: 0 | L8: 0 | M8: 0 | N8: 0 | O8: 0 | P8: 0 | Q8: 0 | R8: 0 | S8: 0 | T8: 0 | U8: 0 | V8: 0 | W8: 0 | X8: 0 | Y8: 0
A9: Fans and pumps | B9: 0 | C9: 0 | D9: 0 | E9: 0 | F9: 0 | G9: 0 | H9: 0 | I9: 0 | J9: 0 | K9: 0 | L9: 0 | M9: 0 | N9: 0 | O9: 0 | P9: 0 | Q9: 0 | R9: 0 | S9: 0 | T9: 0 | U9: 0 | V9: 0 | W9: 0 | X9: 0 | Y9: 0
A10: Low-enthalpy heat | B10: =SUM(B11:B15) -> 1593.0557 | C10: =SUM(C11:C15) -> 1538.0826 | D10: =SUM(D11:D15) -> 1575.6571 | E10: =SUM(E11:E15) -> 1673.5733 | F10: =SUM(F11:F15) -> 1482.7528 | G10: =SUM(G11:G15) -> 1360.9684 | H10: =SUM(H11:H15) -> 1271.9026 | I10: =SUM(I11:I15) -> 1216.213 | ... Y10: =SUM(Y11:Y15) -> 699.82122
A11: Diesel oil | B11: 52.654099 | C11: 59.30657 | D11: 60.61693 | E11: 73.539249 | F11: 74.31476 | G11: 65.861641 | H11: 51.274788 | I11: 61.068782 | J11: 51.930022 | K11: 39.937656 | L11: 47.606429 | M11: 105.5366 | N11: 58.275483 | O11: 42.382688 | P11: 50.369115 | Q11: 50.503197 | R11: 46.390703 | S11: 40.474395 | T11: 49.860273 | U11: 46.913586 | V11: 46.363434 | W11: 59.114824 | X11: 45.990797 | Y11: 41.841741
A12: Natural gas | B12: 1540.4016 | C12: 1478.776 | D12: 1515.0402 | E12: 1600.0341 | F12: 1408.4381 | G12: 1295.1068 | H12: 1220.6278 | I12: 1155.1443 | J12: 937.95589 | K12: 890.67043 | L12: 794.38974 | M12: 632.52025 | N12: 721.43896 | O12: 632.81301 | P12: 649.3191 | Q12: 626.27066 | R12: 638.25964 | S12: 688.44322 | T12: 617.63245 | U12: 565.92859 | V12: 531.61805 | W12: 818.13193 | X12: 663.12678 | Y12: 657.97948
A13: Solar and geothermal | B13: 0 | C13: 0 | D13: 0 | E13: 0 | F13: 0 | G13: 0 | H13: 0 | I13: 0 | J13: 0 | K13: 0 | L13: 0 | M13: 0 | N13: 0 | O13: 0 | P13: 0 | Q13: 0 | R13: 0 | S13: 0 | T13: 0 | U13: 0 | V13: 0 | W13: 0 | X13: 0 | Y13: 0
A14: Ambient heat | B14: 0 | C14: 0 | D14: 0 | E14: 0 | F14: 0 | G14: 0 | H14: 0 | I14: 0 | J14: 0 | K14: 0 | L14: 0 | M14: 0 | N14: 0 | O14: 0 | P14: 0 | Q14: 0 | R14: 0 | S14: 0 | T14: 0 | U14: 0 | V14: 0 | W14: 0 | X14: 0 | Y14: 0
A15: Electricity | B15: 0 | C15: 0 | D15: 0 | E15: 0 | F15: 0 | G15: 0 | H15: 0 | I15: 0 | J15: 0 | K15: 0 | L15: 0 | M15: 0 | N15: 0 | O15: 0 | P15: 0 | Q15: 0 | R15: 0 | S15: 0 | T15: 0 | U15: 0 | V15: 0 | W15: 0 | X15: 0 | Y15: 0
A16: Steam processes | B16: =SUM(B17:B26) -> 25083.245 | C16: =SUM(C17:C26) -> 23518.746 | D16: =SUM(D17:D26) -> 24422.103 | E16: =SUM(E17:E26) -> 25669.616 | F16: =SUM(F17:F26) -> 18252.599 | G16: =SUM(G17:G26) -> 17147.296 | H16: =SUM(H17:H26) -> 16409.075 | I16: =SUM(I17:I26) -> 16622.248 | ... Y16: =SUM(Y17:Y26) -> 13285.482
