Workbook

Sheet cover
B6: JRC-IDEES-2023 - Integrated Database of the European Energy System
C10: Italy
C15: Energy related CO2 Emission balances
L28: Prepared by JRC C.6
L30: 45967.477
L31: v2023-1.00
B33: Legal Notice
B35: The information made available is property of the Joint Research Centre of the European Commission.
B36: Neither the European Commission nor any person acting on behalf of the Commission is responsible for the use which might be made of this information.
B38: Use conditions
B39: This work is licensed under
B40: CC BY 4.0

Sheet index
A1: Italy | B1: IT | C1: 2000 | D1: 2001 | E1: 2002 | F1: 2003 | G1: 2004 | H1: 2005 | I1: 2006 | J1: 2007 | K1: 2008 | L1: 2009 | M1: 2010 | N1: 2011 | O1: 2012 | P1: 2013 | Q1: 2014 | R1: 2015 | S1: 2016 | T1: 2017 | U1: 2018 | V1: 2019 | W1: 2020 | X1: 2021 | Y1: 2022 | Z1: 2023
B2: Click on the link to jump to the sheet
A3: Total | B3: kt CO2
A4: Gross available energy | B4: =HYPERLINK("#"&CELL("address",GAE!$Z$2),"GAE") -> GAE | C4: =GAE!C$2 -> 432023.33 | D4: =GAE!D$2 -> 428717.76 | E4: =GAE!E$2 -> 437805.97 | F4: =GAE!F$2 -> 456370.52 | G4: =GAE!G$2 -> 465893.95 | H4: =GAE!H$2 -> 468920.93 | I4: =GAE!I$2 -> 463897.26 | J4: =GAE!J$2 -> 457109.79 | ... Z4: =GAE!Z$2 -> 303015.24
A5: International maritime bunkers | B5: =HYPERLINK("#"&CELL("address",INTMARB!$Z$2),"INTMARB") -> INTMARB | C5: =INTMARB!C$2 -> 5302.0072 | D5: =INTMARB!D$2 -> 5663.6933 | E5: =INTMARB!E$2 -> 6167.7424 | F5: =INTMARB!F$2 -> 6728.1277 | G5: =INTMARB!G$2 -> 7059.5124 | H5: =INTMARB!H$2 -> 7235.3515 | I5: =INTMARB!I$2 -> 7523.0197 | J5: =INTMARB!J$2 -> 7766.7203 | ... Z5: =INTMARB!Z$2 -> 7279.2246
A6: International Intra-EEA maritime bunkers | B6: =HYPERLINK("#"&CELL("address",INTMARB_IN!$Z$2),"INTMARB_IN") -> INTMARB_IN | C6: =INTMARB_IN!C$2 -> 2011.6218 | D6: =INTMARB_IN!D$2 -> 2106.6567 | E6: =INTMARB_IN!E$2 -> 2379.4569 | F6: =INTMARB_IN!F$2 -> 2558.3046 | G6: =INTMARB_IN!G$2 -> 2585.5886 | H6: =INTMARB_IN!H$2 -> 2596.5087 | I6: =INTMARB_IN!I$2 -> 2682.0915 | J6: =INTMARB_IN!J$2 -> 2723.9802 | ... Z6: =INTMARB_IN!Z$2 -> 3078.3091
A7: International Extra-EEA maritime bunkers | B7: =HYPERLINK("#"&CELL("address",INTMARB_EX!$Z$2),"INTMARB_EX") -> INTMARB_EX | C7: =INTMARB_EX!C$2 -> 3290.3855 | D7: =INTMARB_EX!D$2 -> 3557.0366 | E7: =INTMARB_EX!E$2 -> 3788.2855 | F7: =INTMARB_EX!F$2 -> 4169.8231 | G7: =INTMARB_EX!G$2 -> 4473.9239 | H7: =INTMARB_EX!H$2 -> 4638.8428 | I7: =INTMARB_EX!I$2 -> 4840.9282 | J7: =INTMARB_EX!J$2 -> 5042.7401 | ... Z7: =INTMARB_EX!Z$2 -> 4200.9155
A8: Gross inland consumption | B8: =HYPERLINK("#"&CELL("address",GIC!$Z$2),"GIC") -> GIC | C8: =GIC!C$2 -> 426721.33 | D8: =GIC!D$2 -> 423054.07 | E8: =GIC!E$2 -> 431638.23 | F8: =GIC!F$2 -> 449642.39 | G8: =GIC!G$2 -> 458834.43 | H8: =GIC!H$2 -> 461685.58 | I8: =GIC!I$2 -> 456374.24 | J8: =GIC!J$2 -> 449343.07 | ... Z8: =GIC!Z$2 -> 295736.02
A9: International aviation | B9: =HYPERLINK("#"&CELL("address",INTAVI!$Z$2),"INTAVI") -> INTAVI | C9: =INTAVI!C$2 -> 8511.4502 | D9: =INTAVI!D$2 -> 7763.2587 | E9: =INTAVI!E$2 -> 7763.2587 | F9: =INTAVI!F$2 -> 8730.9608 | G9: =INTAVI!G$2 -> 8659.8517 | H9: =INTAVI!H$2 -> 9021.5806 | I9: =INTAVI!I$2 -> 9667.746 | J9: =INTAVI!J$2 -> 10270.627 | ... Z9: =INTAVI!Z$2 -> 10836.863
A10: International Intra-EEAwUK passenger aviation | B10: =HYPERLINK("#"&CELL("address",INTAVI_PA_IN!$Z$2),"INTAVI_PA_IN") -> INTAVI_PA_IN | C10: =INTAVI_PA_IN!C$2 -> 3755.8679 | D10: =INTAVI_PA_IN!D$2 -> 3558.9639 | E10: =INTAVI_PA_IN!E$2 -> 3427.2959 | F10: =INTAVI_PA_IN!F$2 -> 4002.7529 | G10: =INTAVI_PA_IN!G$2 -> 3725.9206 | H10: =INTAVI_PA_IN!H$2 -> 3913.484 | I10: =INTAVI_PA_IN!I$2 -> 4193.5825 | J10: =INTAVI_PA_IN!J$2 -> 4547.7053 | ... Z10: =INTAVI_PA_IN!Z$2 -> 4898.4986
A11: International Extra-EEAwUK passenger aviation | B11: =HYPERLINK("#"&CELL("address",INTAVI_PA_EX!$Z$2),"INTAVI_PA_EX") -> INTAVI_PA_EX | C11: =INTAVI_PA_EX!C$2 -> 4268.3548 | D11: =INTAVI_PA_EX!D$2 -> 4044.5859 | E11: =INTAVI_PA_EX!E$2 -> 3895.0087 | F11: =INTAVI_PA_EX!F$2 -> 4241.4343 | G11: =INTAVI_PA_EX!G$2 -> 4446.8667 | H11: =INTAVI_PA_EX!H$2 -> 4553.9979 | I11: =INTAVI_PA_EX!I$2 -> 4832.3833 | J11: =INTAVI_PA_EX!J$2 -> 5018.254 | ... Z11: =INTAVI_PA_EX!Z$2 -> 5276.6911
A12: International Intra-EEAwUK freight aviation | B12: =HYPERLINK("#"&CELL("address",INTAVI_FR_IN!$Z$2),"INTAVI_FR_IN") -> INTAVI_FR_IN | C12: =INTAVI_FR_IN!C$2 -> 61.330758 | D12: =INTAVI_FR_IN!D$2 -> 28.878858 | E12: =INTAVI_FR_IN!E$2 -> 107.27787 | F12: =INTAVI_FR_IN!F$2 -> 115.08348 | G12: =INTAVI_FR_IN!G$2 -> 124.1235 | H12: =INTAVI_FR_IN!H$2 -> 127.81482 | I12: =INTAVI_FR_IN!I$2 -> 140.01849 | J12: =INTAVI_FR_IN!J$2 -> 149.59702 | ... Z12: =INTAVI_FR_IN!Z$2 -> 123.28284
A13: International Extra-EEAwUK freight aviation | B13: =HYPERLINK("#"&CELL("address",INTAVI_FR_EX!$Z$2),"INTAVI_FR_EX") -> INTAVI_FR_EX | C13: =INTAVI_FR_EX!C$2 -> 425.8967 | D13: =INTAVI_FR_EX!D$2 -> 130.83006 | E13: =INTAVI_FR_EX!E$2 -> 333.67621 | F13: =INTAVI_FR_EX!F$2 -> 371.69016 | G13: =INTAVI_FR_EX!G$2 -> 362.94095 | H13: =INTAVI_FR_EX!H$2 -> 426.2839 | I13: =INTAVI_FR_EX!I$2 -> 501.76161 | J13: =INTAVI_FR_EX!J$2 -> 555.071 | ... Z13: =INTAVI_FR_EX!Z$2 -> 538.39059
A14: Total energy supply | B14: =HYPERLINK("#"&CELL("address",NRGSUP!$Z$2),"NRGSUP") -> NRGSUP | C14: =NRGSUP!C$2 -> 418209.88 | D14: =NRGSUP!D$2 -> 415290.81 | E14: =NRGSUP!E$2 -> 423874.97 | F14: =NRGSUP!F$2 -> 440911.43 | G14: =NRGSUP!G$2 -> 450174.58 | H14: =NRGSUP!H$2 -> 452664 | I14: =NRGSUP!I$2 -> 446706.5 | J14: =NRGSUP!J$2 -> 439072.44 | ... Z14: =NRGSUP!Z$2 -> 284899.16
A15: Electricity & heat generation | B15: =HYPERLINK("#"&CELL("address",TI_EHG_E!$Z$2),"TI_EHG_E") -> TI_EHG_E | C15: =TI_EHG_E!C$2 -> 136417.47 | D15: =TI_EHG_E!D$2 -> 133145.62 | E15: =TI_EHG_E!E$2 -> 141929.66 | F15: =TI_EHG_E!F$2 -> 149151.72 | G15: =TI_EHG_E!G$2 -> 163240.27 | H15: =TI_EHG_E!H$2 -> 159813.46 | I15: =TI_EHG_E!I$2 -> 165380.31 | J15: =TI_EHG_E!J$2 -> 162624.3 | ... Z15: =TI_EHG_E!Z$2 -> 73629.41
A16: Electricity only | B16: =HYPERLINK("#"&CELL("address",TI_EHG_E_E!$Z$2),"TI_EHG_E_E") -> TI_EHG_E_E | C16: =TI_EHG_E_E!C$2 -> 106948.5 | D16: =TI_EHG_E_E!D$2 -> 103262.53 | E16: =TI_EHG_E_E!E$2 -> 105471.09 | F16: =TI_EHG_E_E!F$2 -> 96523.441 | G16: =TI_EHG_E_E!G$2 -> 107114.17 | H16: =TI_EHG_E_E!H$2 -> 100820.14 | I16: =TI_EHG_E_E!I$2 -> 101415.57 | J16: =TI_EHG_E_E!J$2 -> 94978.992 | ... Z16: =TI_EHG_E_E!Z$2 -> 31674.138
A17: CHP | B17: =HYPERLINK("#"&CELL("address",TI_EHG_CHP_E!$Z$2),"TI_EHG_CHP_E") -> TI_EHG_CHP_E | C17: =TI_EHG_CHP_E!C$2 -> 29468.963 | D17: =TI_EHG_CHP_E!D$2 -> 29883.087 | E17: =TI_EHG_CHP_E!E$2 -> 36458.57 | F17: =TI_EHG_CHP_E!F$2 -> 52628.284 | G17: =TI_EHG_CHP_E!G$2 -> 56126.097 | H17: =TI_EHG_CHP_E!H$2 -> 58993.322 | I17: =TI_EHG_CHP_E!I$2 -> 63964.743 | J17: =TI_EHG_CHP_E!J$2 -> 67645.313 | ... Z17: =TI_EHG_CHP_E!Z$2 -> 41400.071
A18: Heat only | B18: =HYPERLINK("#"&CELL("address",TI_EHG_H_E!$Z$2),"TI_EHG_H_E") -> TI_EHG_H_E | C18: =TI_EHG_H_E!C$2 -> 0 | D18: =TI_EHG_H_E!D$2 -> 0 | E18: =TI_EHG_H_E!E$2 -> 0 | F18: =TI_EHG_H_E!F$2 -> 0 | G18: =TI_EHG_H_E!G$2 -> 0 | H18: =TI_EHG_H_E!H$2 -> 0 | I18: =TI_EHG_H_E!I$2 -> 0 | J18: =TI_EHG_H_E!J$2 -> 0 | ... Z18: =TI_EHG_H_E!Z$2 -> 555.20122
A19: Energy sector | B19: =HYPERLINK("#"&CELL("address",NRG_E!$Z$2),"NRG_E") -> NRG_E | C19: =NRG_E!C$2 -> 17240.168 | D19: =NRG_E!D$2 -> 16726.107 | E19: =NRG_E!E$2 -> 17555.066 | F19: =NRG_E!F$2 -> 16560.227 | G19: =NRG_E!G$2 -> 16805.485 | H19: =NRG_E!H$2 -> 19057.949 | I19: =NRG_E!I$2 -> 16292.081 | J19: =NRG_E!J$2 -> 17355.427 | ... Z19: =NRG_E!Z$2 -> 14383.507
A20: Coal mines | B20: =HYPERLINK("#"&CELL("address",NRG_CM_E!$Z$2),"NRG_CM_E") -> NRG_CM_E | C20: =NRG_CM_E!C$2 -> 0 | D20: =NRG_CM_E!D$2 -> 0 | E20: =NRG_CM_E!E$2 -> 0 | F20: =NRG_CM_E!F$2 -> 0 | G20: =NRG_CM_E!G$2 -> 0 | H20: =NRG_CM_E!H$2 -> 0 | I20: =NRG_CM_E!I$2 -> 0 | J20: =NRG_CM_E!J$2 -> 0 | ... Z20: =NRG_CM_E!Z$2 -> 0
A21: Oil & natural gas extraction plants | B21: =HYPERLINK("#"&CELL("address",NRG_OIL_NG_E!$Z$2),"NRG_OIL_NG_E") -> NRG_OIL_NG_E | C21: =NRG_OIL_NG_E!C$2 -> 915.93909 | D21: =NRG_OIL_NG_E!D$2 -> 597.39768 | E21: =NRG_OIL_NG_E!E$2 -> 793.95525 | F21: =NRG_OIL_NG_E!F$2 -> 794.2077 | G21: =NRG_OIL_NG_E!G$2 -> 697.92327 | H21: =NRG_OIL_NG_E!H$2 -> 692.26839 | I21: =NRG_OIL_NG_E!I$2 -> 731.0952 | J21: =NRG_OIL_NG_E!J$2 -> 657.3798 | ... Z21: =NRG_OIL_NG_E!Z$2 -> 596.11692
A22: Patent fuel plants | B22: =HYPERLINK("#"&CELL("address",NRG_PF_E!$Z$2),"NRG_PF_E") -> NRG_PF_E | C22: =NRG_PF_E!C$2 -> 0 | D22: =NRG_PF_E!D$2 -> 0 | E22: =NRG_PF_E!E$2 -> 0 | F22: =NRG_PF_E!F$2 -> 0 | G22: =NRG_PF_E!G$2 -> 0 | H22: =NRG_PF_E!H$2 -> 0 | I22: =NRG_PF_E!I$2 -> 0 | J22: =NRG_PF_E!J$2 -> 0 | ... Z22: =NRG_PF_E!Z$2 -> 0
A23: Coke ovens | B23: =HYPERLINK("#"&CELL("address",NRG_CO_E!$Z$2),"NRG_CO_E") -> NRG_CO_E | C23: =NRG_CO_E!C$2 -> 1031.4754 | D23: =NRG_CO_E!D$2 -> 462.80833 | E23: =NRG_CO_E!E$2 -> 490.88928 | F23: =NRG_CO_E!F$2 -> 353.35663 | G23: =NRG_CO_E!G$2 -> 217.67667 | H23: =NRG_CO_E!H$2 -> 1042.955 | I23: =NRG_CO_E!I$2 -> 226.38536 | J23: =NRG_CO_E!J$2 -> 216.2464 | ... Z23: =NRG_CO_E!Z$2 -> 168.19502
A24: BKB & PB plants | B24: =HYPERLINK("#"&CELL("address",NRG_BKBPB_E!$Z$2),"NRG_BKBPB_E") -> NRG_BKBPB_E | C24: =NRG_BKBPB_E!C$2 -> 0 | D24: =NRG_BKBPB_E!D$2 -> 0 | E24: =NRG_BKBPB_E!E$2 -> 0 | F24: =NRG_BKBPB_E!F$2 -> 0 | G24: =NRG_BKBPB_E!G$2 -> 0 | H24: =NRG_BKBPB_E!H$2 -> 0 | I24: =NRG_BKBPB_E!I$2 -> 0 | J24: =NRG_BKBPB_E!J$2 -> 0 | ... Z24: =NRG_BKBPB_E!Z$2 -> 0
A25: Gas works | B25: =HYPERLINK("#"&CELL("address",NRG_GW_E!$Z$2),"NRG_GW_E") -> NRG_GW_E | C25: =NRG_GW_E!C$2 -> 0 | D25: =NRG_GW_E!D$2 -> 0 | E25: =NRG_GW_E!E$2 -> 0 | F25: =NRG_GW_E!F$2 -> 0 | G25: =NRG_GW_E!G$2 -> 0 | H25: =NRG_GW_E!H$2 -> 0 | I25: =NRG_GW_E!I$2 -> 0 | J25: =NRG_GW_E!J$2 -> 0 | ... Z25: =NRG_GW_E!Z$2 -> 0
A26: Blast furnaces | B26: =HYPERLINK("#"&CELL("address",NRG_BF_E!$Z$2),"NRG_BF_E") -> NRG_BF_E | C26: =NRG_BF_E!C$2 -> 879.4139 | D26: =NRG_BF_E!D$2 -> 227.73802 | E26: =NRG_BF_E!E$2 -> 42.7572 | F26: =NRG_BF_E!F$2 -> 12.62736 | G26: =NRG_BF_E!G$2 -> 0 | H26: =NRG_BF_E!H$2 -> 0 | I26: =NRG_BF_E!I$2 -> 0 | J26: =NRG_BF_E!J$2 -> 0 | ... Z26: =NRG_BF_E!Z$2 -> 0
A27: Petroleum refineries (oil refineries) | B27: =HYPERLINK("#"&CELL("address",NRG_PR_E!$Z$2),"NRG_PR_E") -> NRG_PR_E | C27: =NRG_PR_E!C$2 -> 14413.34 | D27: =NRG_PR_E!D$2 -> 15438.163 | E27: =NRG_PR_E!E$2 -> 16227.464 | F27: =NRG_PR_E!F$2 -> 15400.035 | G27: =NRG_PR_E!G$2 -> 15889.885 | H27: =NRG_PR_E!H$2 -> 17322.725 | I27: =NRG_PR_E!I$2 -> 15334.6 | J27: =NRG_PR_E!J$2 -> 16366.38 | ... Z27: =NRG_PR_E!Z$2 -> 13339.822
A28: Nuclear industry | B28: =HYPERLINK("#"&CELL("address",NRG_NI_E!$Z$2),"NRG_NI_E") -> NRG_NI_E | C28: =NRG_NI_E!C$2 -> 0 | D28: =NRG_NI_E!D$2 -> 0 | E28: =NRG_NI_E!E$2 -> 0 | F28: =NRG_NI_E!F$2 -> 0 | G28: =NRG_NI_E!G$2 -> 0 | H28: =NRG_NI_E!H$2 -> 0 | I28: =NRG_NI_E!I$2 -> 0 | J28: =NRG_NI_E!J$2 -> 0 | ... Z28: =NRG_NI_E!Z$2 -> 0
A29: Coal liquefaction plants | B29: =HYPERLINK("#"&CELL("address",NRG_CL_E!$Z$2),"NRG_CL_E") -> NRG_CL_E | C29: =NRG_CL_E!C$2 -> 0 | D29: =NRG_CL_E!D$2 -> 0 | E29: =NRG_CL_E!E$2 -> 0 | F29: =NRG_CL_E!F$2 -> 0 | G29: =NRG_CL_E!G$2 -> 0 | H29: =NRG_CL_E!H$2 -> 0 | I29: =NRG_CL_E!I$2 -> 0 | J29: =NRG_CL_E!J$2 -> 0 | ... Z29: =NRG_CL_E!Z$2 -> 0
A30: Liquefaction & regasification plants (LNG) | B30: =HYPERLINK("#"&CELL("address",NRG_LNG_E!$Z$2),"NRG_LNG_E") -> NRG_LNG_E | C30: =NRG_LNG_E!C$2 -> 0 | D30: =NRG_LNG_E!D$2 -> 0 | E30: =NRG_LNG_E!E$2 -> 0 | F30: =NRG_LNG_E!F$2 -> 0 | G30: =NRG_LNG_E!G$2 -> 0 | H30: =NRG_LNG_E!H$2 -> 0 | I30: =NRG_LNG_E!I$2 -> 0 | J30: =NRG_LNG_E!J$2 -> 115.42014 | ... Z30: =NRG_LNG_E!Z$2 -> 279.37288
A31: Gasification plants for biogas | B31: =HYPERLINK("#"&CELL("address",NRG_BIOG_E!$Z$2),"NRG_BIOG_E") -> NRG_BIOG_E | C31: =NRG_BIOG_E!C$2 -> 0 | D31: =NRG_BIOG_E!D$2 -> 0 | E31: =NRG_BIOG_E!E$2 -> 0 | F31: =NRG_BIOG_E!F$2 -> 0 | G31: =NRG_BIOG_E!G$2 -> 0 | H31: =NRG_BIOG_E!H$2 -> 0 | I31: =NRG_BIOG_E!I$2 -> 0 | J31: =NRG_BIOG_E!J$2 -> 0 | ... Z31: =NRG_BIOG_E!Z$2 -> 0
A32: Gas-to-liquids (GTL) plants | B32: =HYPERLINK("#"&CELL("address",NRG_GTL_E!$Z$2),"NRG_GTL_E") -> NRG_GTL_E | C32: =NRG_GTL_E!C$2 -> 0 | D32: =NRG_GTL_E!D$2 -> 0 | E32: =NRG_GTL_E!E$2 -> 0 | F32: =NRG_GTL_E!F$2 -> 0 | G32: =NRG_GTL_E!G$2 -> 0 | H32: =NRG_GTL_E!H$2 -> 0 | I32: =NRG_GTL_E!I$2 -> 0 | J32: =NRG_GTL_E!J$2 -> 0 | ... Z32: =NRG_GTL_E!Z$2 -> 0
A33: Charcoal production plants | B33: =HYPERLINK("#"&CELL("address",NRG_CPP_E!$Z$2),"NRG_CPP_E") -> NRG_CPP_E | C33: =NRG_CPP_E!C$2 -> 0 | D33: =NRG_CPP_E!D$2 -> 0 | E33: =NRG_CPP_E!E$2 -> 0 | F33: =NRG_CPP_E!F$2 -> 0 | G33: =NRG_CPP_E!G$2 -> 0 | H33: =NRG_CPP_E!H$2 -> 0 | I33: =NRG_CPP_E!I$2 -> 0 | J33: =NRG_CPP_E!J$2 -> 0 | ... Z33: =NRG_CPP_E!Z$2 -> 0
A34: Not elsewhere specified (energy) | B34: =HYPERLINK("#"&CELL("address",NRG_NSP_E!$Z$2),"NRG_NSP_E") -> NRG_NSP_E | C34: =NRG_NSP_E!C$2 -> 0 | D34: =NRG_NSP_E!D$2 -> 0 | E34: =NRG_NSP_E!E$2 -> 0 | F34: =NRG_NSP_E!F$2 -> 0 | G34: =NRG_NSP_E!G$2 -> 0 | H34: =NRG_NSP_E!H$2 -> 0 | I34: =NRG_NSP_E!I$2 -> 0 | J34: =NRG_NSP_E!J$2 -> 0 | ... Z34: =NRG_NSP_E!Z$2 -> 0
A35: Final energy consumption | B35: =HYPERLINK("#"&CELL("address",FC_E!$Z$2),"FC_E") -> FC_E | C35: =FC_E!C$2 -> 264552.24 | D35: =FC_E!D$2 -> 265419.08 | E35: =FC_E!E$2 -> 264390.25 | F35: =FC_E!F$2 -> 275199.48 | G35: =FC_E!G$2 -> 270128.83 | H35: =FC_E!H$2 -> 273792.59 | I35: =FC_E!I$2 -> 265034.1 | J35: =FC_E!J$2 -> 259092.71 | ... Z35: =FC_E!Z$2 -> 196886.24
A36: Industry sector | B36: =HYPERLINK("#"&CELL("address",FC_IND_E!$Z$2),"FC_IND_E") -> FC_IND_E | C36: =FC_IND_E!C$2 -> 70359.932 | D36: =FC_IND_E!D$2 -> 65336.564 | E36: =FC_IND_E!E$2 -> 66057.577 | F36: =FC_IND_E!F$2 -> 70892.321 | G36: =FC_IND_E!G$2 -> 61726.62 | H36: =FC_IND_E!H$2 -> 61571.163 | I36: =FC_IND_E!I$2 -> 57311.679 | J36: =FC_IND_E!J$2 -> 57622.839 | ... Z36: =FC_IND_E!Z$2 -> 35609.081
A37: Iron & steel | B37: =HYPERLINK("#"&CELL("address",FC_IND_IS_E!$Z$2),"FC_IND_IS_E") -> FC_IND_IS_E | C37: =FC_IND_IS_E!C$2 -> 10548.563 | D37: =FC_IND_IS_E!D$2 -> 8619.665 | E37: =FC_IND_IS_E!E$2 -> 8309.9771 | F37: =FC_IND_IS_E!F$2 -> 8561.2169 | G37: =FC_IND_IS_E!G$2 -> 8444.931 | H37: =FC_IND_IS_E!H$2 -> 9490.8985 | I37: =FC_IND_IS_E!I$2 -> 9126.5748 | J37: =FC_IND_IS_E!J$2 -> 8819.8578 | ... Z37: =FC_IND_IS_E!Z$2 -> 4897.5806
A38: Iron & steel - Integrated steelworks | B38: =HYPERLINK("#"&CELL("address",FC_IND_IS_BF_E!$Z$2),"FC_IND_IS_BF_E") -> FC_IND_IS_BF_E | C38: =FC_IND_IS_BF_E!C$2 -> 8192.3943 | D38: =FC_IND_IS_BF_E!D$2 -> 6600.6069 | E38: =FC_IND_IS_BF_E!E$2 -> 6233.6177 | F38: =FC_IND_IS_BF_E!F$2 -> 6467.2211 | G38: =FC_IND_IS_BF_E!G$2 -> 6447.9016 | H38: =FC_IND_IS_BF_E!H$2 -> 7499.3893 | I38: =FC_IND_IS_BF_E!I$2 -> 7079.5542 | J38: =FC_IND_IS_BF_E!J$2 -> 6823.6432 | ... Z38: =FC_IND_IS_BF_E!Z$2 -> 2311.3749
A39: Iron & steel - Electric arc | B39: =HYPERLINK("#"&CELL("address",FC_IND_IS_EA_E!$Z$2),"FC_IND_IS_EA_E") -> FC_IND_IS_EA_E | C39: =FC_IND_IS_EA_E!C$2 -> 2356.1682 | D39: =FC_IND_IS_EA_E!D$2 -> 2019.0581 | E39: =FC_IND_IS_EA_E!E$2 -> 2076.3595 | F39: =FC_IND_IS_EA_E!F$2 -> 2093.9958 | G39: =FC_IND_IS_EA_E!G$2 -> 1997.0294 | H39: =FC_IND_IS_EA_E!H$2 -> 1991.5092 | I39: =FC_IND_IS_EA_E!I$2 -> 2047.0206 | J39: =FC_IND_IS_EA_E!J$2 -> 1996.2146 | ... Z39: =FC_IND_IS_EA_E!Z$2 -> 2586.2056
A40: Non-ferrous metals | B40: =HYPERLINK("#"&CELL("address",FC_IND_NFM_E!$Z$2),"FC_IND_NFM_E") -> FC_IND_NFM_E | C40: =FC_IND_NFM_E!C$2 -> 1258.3573 | D40: =FC_IND_NFM_E!D$2 -> 1250.328 | E40: =FC_IND_NFM_E!E$2 -> 1183.0284 | F40: =FC_IND_NFM_E!F$2 -> 1234.2989 | G40: =FC_IND_NFM_E!G$2 -> 1222.8591 | H40: =FC_IND_NFM_E!H$2 -> 1191.3817 | I40: =FC_IND_NFM_E!I$2 -> 1225.9038 | J40: =FC_IND_NFM_E!J$2 -> 1171.7967 | ... Z40: =FC_IND_NFM_E!Z$2 -> 1059.6325
...

Sheet ef
A1: CO2 emission factors (t CO2 / toe) | B1: ef | C1: 2000 | D1: 2001 | E1: 2002 | F1: 2003 | G1: 2004 | H1: 2005 | I1: 2006 | J1: 2007 | K1: 2008 | L1: 2009 | M1: 2010 | N1: 2011 | O1: 2012 | P1: 2013 | Q1: 2014 | R1: 2015 | S1: 2016 | T1: 2017 | U1: 2018 | V1: 2019 | W1: 2020 | X1: 2021 | Y1: 2022 | Z1: 2023
A2: Total | B2: TOTAL
A3: Solid fossil fuels | B3: C0000X0350-0370
A4: Hard coal | B4: C0100
A5: Anthracite | B5: C0110 | C5: 4.0319442 | D5: 4.0319442 | E5: 4.0319442 | F5: 4.0319442 | G5: 4.0319442 | H5: 3.8978082 | I5: 3.9854702 | J5: 4.0941769 | K5: 4.0715997 | L5: 4.11988 | M5: 4.0813721 | N5: 4.1672267 | O5: 4.1358605 | P5: 4.1204324 | Q5: 4.1041476 | R5: 4.247171 | S5: 4.2579038 | T5: 4.3197974 | U5: 4.2066052 | V5: 4.4038801 | W5: 4.3889466 | X5: 4.3627094 | Y5: 4.3841568 | Z5: 4.2455335
A6: Coking coal | B6: C0121 | C6: 3.9607128 | D6: 3.9607128 | E6: 3.9607128 | F6: 3.9607128 | G6: 3.9607128 | H6: 3.8739962 | I6: 3.940664 | J6: 3.9583141 | K6: 3.9746483 | L6: 3.9683352 | M6: 3.9645078 | N6: 3.9993907 | O6: 3.9960827 | P6: 3.9541933 | Q6: 3.9375401 | R6: 3.9573774 | S6: 3.9454042 | T6: 3.9384015 | U6: 3.9952527 | V6: 3.9665693 | W6: 3.9779111 | X6: 3.9699669 | Y6: 3.9569674 | Z6: 3.8342938
A7: Other bituminous coal | B7: C0129 | C7: 3.8661134 | D7: 3.9574895 | E7: 3.9423612 | F7: 3.9786421 | G7: 3.9873794 | H7: 3.9510313 | I7: 3.9274143 | J7: 3.9415367 | K7: 3.9152697 | L7: 3.9318377 | M7: 3.9255728 | N7: 3.9116544 | O7: 3.9243128 | P7: 3.9233602 | Q7: 3.9394768 | R7: 3.9642001 | S7: 3.9840173 | T7: 3.9334606 | U7: 3.9524829 | V7: 3.9917927 | W7: 3.9387994 | X7: 3.8996111 | Y7: 3.9061177 | Z7: 3.912913
A8: Brown coal | B8: C0200
A9: Sub-bituminous coal | B9: C0210 | C9: 3.9416768 | D9: 3.9416768 | E9: 3.9416768 | F9: 3.9416768 | G9: 3.9416768 | H9: 4.0221192 | I9: 4.0221192 | J9: 4.0221192 | K9: 4.0221192 | L9: 4.0221192 | M9: 4.0221192 | N9: 4.0221192 | O9: 4.0221192 | P9: 4.0221192 | Q9: 4.0221192 | R9: 4.0221192 | S9: 4.0221192 | T9: 4.0221192 | U9: 4.0221192 | V9: 4.0221192 | W9: 4.0221192 | X9: 4.0221192 | Y9: 4.0221192 | Z9: 4.0221192
A10: Lignite | B10: C0220 | C10: 4.2370416 | D10: 4.2370416 | E10: 4.2370416 | F10: 4.2370416 | G10: 4.2370416 | H10: 4.2370416 | I10: 4.2370416 | J10: 4.2370416 | K10: 4.2370416 | L10: 4.2370416 | M10: 4.2370416 | N10: 4.2370416 | O10: 4.2370416 | P10: 4.2370416 | Q10: 4.2370416 | R10: 4.2370416 | S10: 4.2370416 | T10: 4.2370416 | U10: 4.2370416 | V10: 4.2370416 | W10: 4.2370416 | X10: 4.2370416 | Y10: 4.2370416 | Z10: 4.2370416
A11: Coal products | B11: C0300
A12: Patent fuel | B12: C0320 | C12: 4.08213 | D12: 4.08213 | E12: 4.08213 | F12: 4.08213 | G12: 4.08213 | H12: 4.08213 | I12: 4.08213 | J12: 4.08213 | K12: 4.08213 | L12: 4.08213 | M12: 4.08213 | N12: 4.08213 | O12: 4.08213 | P12: 4.08213 | Q12: 4.08213 | R12: 4.08213 | S12: 4.08213 | T12: 4.08213 | U12: 4.08213 | V12: 4.08213 | W12: 4.08213 | X12: 4.08213 | Y12: 4.08213 | Z12: 4.08213
A13: Coke oven coke | B13: C0311 | C13: 4.4381476 | D13: 4.4381476 | E13: 4.4381476 | F13: 4.4381476 | G13: 4.4381476 | H13: 4.6469518 | I13: 4.6525363 | J13: 4.684604 | K13: 4.6776985 | L13: 4.6631843 | M13: 4.5700326 | N13: 4.6244425 | O13: 4.7329929 | P13: 4.6552079 | Q13: 4.5748707 | R13: 4.5971892 | S13: 4.5890322 | T13: 4.5564291 | U13: 4.5609867 | V13: 4.549499 | W13: 4.5025156 | X13: 4.544342 | Y13: 4.5338691 | Z13: 4.6635292
A14: Gas coke | B14: C0312 | C14: 4.4381476 | D14: 4.4381476 | E14: 4.4381476 | F14: 4.4381476 | G14: 4.4381476 | H14: 4.6469518 | I14: 4.6525363 | J14: 4.684604 | K14: 4.6776985 | L14: 4.6631843 | M14: 4.5700326 | N14: 4.6244425 | O14: 4.7329929 | P14: 4.6552079 | Q14: 4.5748707 | R14: 4.5971892 | S14: 4.5890322 | T14: 4.5564291 | U14: 4.5609867 | V14: 4.549499 | W14: 4.5025156 | X14: 4.544342 | Y14: 4.5338691 | Z14: 4.6635292
A15: Coal tar | B15: C0340 | C15: 3.377352 | D15: 3.377352 | E15: 3.377352 | F15: 3.377352 | G15: 3.377352 | H15: 3.377352 | I15: 3.377352 | J15: 3.377352 | K15: 3.377352 | L15: 3.377352 | M15: 3.377352 | N15: 3.377352 | O15: 3.377352 | P15: 3.377352 | Q15: 3.377352 | R15: 3.377352 | S15: 3.377352 | T15: 3.377352 | U15: 3.377352 | V15: 3.377352 | W15: 3.377352 | X15: 3.377352 | Y15: 3.377352 | Z15: 3.377352
A16: Brown coal briquettes | B16: C0330 | C16: 4.08213 | D16: 4.08213 | E16: 4.08213 | F16: 4.08213 | G16: 4.08213 | H16: 4.08213 | I16: 4.08213 | J16: 4.08213 | K16: 4.08213 | L16: 4.08213 | M16: 4.08213 | N16: 4.08213 | O16: 4.08213 | P16: 4.08213 | Q16: 4.08213 | R16: 4.08213 | S16: 4.08213 | T16: 4.08213 | U16: 4.08213 | V16: 4.08213 | W16: 4.08213 | X16: 4.08213 | Y16: 4.08213 | Z16: 4.08213
A17: Manufactured gases | B17: C0350-0370
A18: Gas works gas | B18: C0360 | C18: 1.8589392 | D18: 1.8589392 | E18: 1.8589392 | F18: 1.8589392 | G18: 1.8589392 | H18: 1.8589392 | I18: 1.8589392 | J18: 1.8589392 | K18: 1.8589392 | L18: 1.8589392 | M18: 1.8589392 | N18: 1.8589392 | O18: 1.8589392 | P18: 1.8589392 | Q18: 1.8589392 | R18: 1.8589392 | S18: 1.8589392 | T18: 1.8589392 | U18: 1.8589392 | V18: 1.8589392 | W18: 1.8589392 | X18: 1.8589392 | Y18: 1.8589392 | Z18: 1.8589392
A19: Coke oven gas | B19: C0350 | C19: 1.8589392 | D19: 1.8589392 | E19: 1.8589392 | F19: 1.8589392 | G19: 1.8589392 | H19: 1.8589392 | I19: 1.8589392 | J19: 1.8589392 | K19: 1.8589392 | L19: 1.8589392 | M19: 1.8589392 | N19: 1.8589392 | O19: 1.8589392 | P19: 1.8589392 | Q19: 1.8589392 | R19: 1.8589392 | S19: 1.8589392 | T19: 1.8589392 | U19: 1.8589392 | V19: 1.8589392 | W19: 1.8589392 | X19: 1.8589392 | Y19: 1.8589392 | Z19: 1.8589392
A20: Blast furnace gas | B20: C0371 | C20: 10.88568 | D20: 10.88568 | E20: 10.88568 | F20: 10.88568 | G20: 10.88568 | H20: 10.88568 | I20: 10.88568 | J20: 10.88568 | K20: 10.88568 | L20: 10.88568 | M20: 10.88568 | N20: 10.88568 | O20: 10.88568 | P20: 10.88568 | Q20: 10.88568 | R20: 10.88568 | S20: 10.88568 | T20: 10.88568 | U20: 10.88568 | V20: 10.88568 | W20: 10.88568 | X20: 10.88568 | Y20: 10.88568 | Z20: 10.88568
A21: Other recovered gases | B21: C0379 | C21: 7.619976 | D21: 7.619976 | E21: 7.619976 | F21: 7.619976 | G21: 7.619976 | H21: 7.619976 | I21: 7.619976 | J21: 7.619976 | K21: 7.619976 | L21: 7.619976 | M21: 7.619976 | N21: 7.619976 | O21: 7.619976 | P21: 7.619976 | Q21: 7.619976 | R21: 7.619976 | S21: 7.619976 | T21: 7.619976 | U21: 7.619976 | V21: 7.619976 | W21: 7.619976 | X21: 7.619976 | Y21: 7.619976 | Z21: 7.619976
A22: Peat and peat products | B22: P1000
A23: Peat | B23: P1100 | C23: 4.438008 | D23: 4.438008 | E23: 4.438008 | F23: 4.438008 | G23: 4.438008 | H23: 4.438008 | I23: 4.438008 | J23: 4.438008 | K23: 4.438008 | L23: 4.438008 | M23: 4.438008 | N23: 4.438008 | O23: 4.438008 | P23: 4.438008 | Q23: 4.438008 | R23: 4.438008 | S23: 4.438008 | T23: 4.438008 | U23: 4.438008 | V23: 4.438008 | W23: 4.438008 | X23: 4.438008 | Y23: 4.438008 | Z23: 4.438008
A24: Peat products | B24: P1200 | C24: 4.438008 | D24: 4.438008 | E24: 4.438008 | F24: 4.438008 | G24: 4.438008 | H24: 4.438008 | I24: 4.438008 | J24: 4.438008 | K24: 4.438008 | L24: 4.438008 | M24: 4.438008 | N24: 4.438008 | O24: 4.438008 | P24: 4.438008 | Q24: 4.438008 | R24: 4.438008 | S24: 4.438008 | T24: 4.438008 | U24: 4.438008 | V24: 4.438008 | W24: 4.438008 | X24: 4.438008 | Y24: 4.438008 | Z24: 4.438008
A25: Oil shale and oil sands | B25: S2000 | C25: 4.479876 | D25: 4.479876 | E25: 4.479876 | F25: 4.479876 | G25: 4.479876 | H25: 4.479876 | I25: 4.479876 | J25: 4.479876 | K25: 4.479876 | L25: 4.479876 | M25: 4.479876 | N25: 4.479876 | O25: 4.479876 | P25: 4.479876 | Q25: 4.479876 | R25: 4.479876 | S25: 4.479876 | T25: 4.479876 | U25: 4.479876 | V25: 4.479876 | W25: 4.479876 | X25: 4.479876 | Y25: 4.479876 | Z25: 4.479876
A26: Oil and petroleum products | B26: O4000XBIO
A27: Crude oil, NGL, refinery feedstocks, additives and oxygenates and other hydrocarbons (excluding biofuel portion) | B27: O4100_TOT_4200-4500XBIO
A28: Crude oil | B28: O4100_TOT | C28: 3.0689244 | D28: 3.0689244 | E28: 3.0689244 | F28: 3.0689244 | G28: 3.0689244 | H28: 3.0689244 | I28: 3.0689244 | J28: 3.0689244 | K28: 3.0689244 | L28: 3.0689244 | M28: 3.0689244 | N28: 3.0689244 | O28: 3.0689244 | P28: 3.0689244 | Q28: 3.0689244 | R28: 3.0689244 | S28: 3.0689244 | T28: 3.0689244 | U28: 3.0689244 | V28: 3.0689244 | W28: 3.0689244 | X28: 3.0689244 | Y28: 3.0689244 | Z28: 3.0689244
A29: Natural gas liquids | B29: O4200 | C29: 2.6879256 | D29: 2.6879256 | E29: 2.6879256 | F29: 2.6879256 | G29: 2.6879256 | H29: 2.6879256 | I29: 2.6879256 | J29: 2.6879256 | K29: 2.6879256 | L29: 2.6879256 | M29: 2.6879256 | N29: 2.6879256 | O29: 2.6879256 | P29: 2.6879256 | Q29: 2.6879256 | R29: 2.6879256 | S29: 2.6879256 | T29: 2.6879256 | U29: 2.6879256 | V29: 2.6879256 | W29: 2.6879256 | X29: 2.6879256 | Y29: 2.6879256 | Z29: 2.6879256
A30: Refinery feedstocks | B30: O4300 | C30: 3.0689244 | D30: 3.0689244 | E30: 3.0689244 | F30: 3.0689244 | G30: 3.0689244 | H30: 3.0689244 | I30: 3.0689244 | J30: 3.0689244 | K30: 3.0689244 | L30: 3.0689244 | M30: 3.0689244 | N30: 3.0689244 | O30: 3.0689244 | P30: 3.0689244 | Q30: 3.0689244 | R30: 3.0689244 | S30: 3.0689244 | T30: 3.0689244 | U30: 3.0689244 | V30: 3.0689244 | W30: 3.0689244 | X30: 3.0689244 | Y30: 3.0689244 | Z30: 3.0689244
A31: Additives and oxygenates (excluding biofuel portion) | B31: O4400X4410 | C31: 3.0689244 | D31: 3.0689244 | E31: 3.0689244 | F31: 3.0689244 | G31: 3.0689244 | H31: 3.0689244 | I31: 3.0689244 | J31: 3.0689244 | K31: 3.0689244 | L31: 3.0689244 | M31: 3.0689244 | N31: 3.0689244 | O31: 3.0689244 | P31: 3.0689244 | Q31: 3.0689244 | R31: 3.0689244 | S31: 3.0689244 | T31: 3.0689244 | U31: 3.0689244 | V31: 3.0689244 | W31: 3.0689244 | X31: 3.0689244 | Y31: 3.0689244 | Z31: 3.0689244
A32: Other hydrocarbons | B32: O4500 | C32: 3.0689244 | D32: 3.0689244 | E32: 3.0689244 | F32: 3.0689244 | G32: 3.0689244 | H32: 3.0689244 | I32: 3.0689244 | J32: 3.0689244 | K32: 3.0689244 | L32: 3.0689244 | M32: 3.0689244 | N32: 3.0689244 | O32: 3.0689244 | P32: 3.0689244 | Q32: 3.0689244 | R32: 3.0689244 | S32: 3.0689244 | T32: 3.0689244 | U32: 3.0689244 | V32: 3.0689244 | W32: 3.0689244 | X32: 3.0689244 | Y32: 3.0689244 | Z32: 3.0689244
A33: Oil products (excluding biofuel portion) | B33: O4600XBIO
A34: Refinery gas | B34: O4610 | C34: 2.4115968 | D34: 2.4115968 | E34: 2.4115968 | F34: 2.4115968 | G34: 2.4115968 | H34: 2.4115968 | I34: 2.4115968 | J34: 2.4115968 | K34: 2.4115968 | L34: 2.4115968 | M34: 2.4115968 | N34: 2.4115968 | O34: 2.4115968 | P34: 2.4115968 | Q34: 2.4115968 | R34: 2.4115968 | S34: 2.4115968 | T34: 2.4115968 | U34: 2.4115968 | V34: 2.4115968 | W34: 2.4115968 | X34: 2.4115968 | Y34: 2.4115968 | Z34: 2.4115968
A35: Ethane | B35: O4620 | C35: 2.5790688 | D35: 2.5790688 | E35: 2.5790688 | F35: 2.5790688 | G35: 2.5790688 | H35: 2.5790688 | I35: 2.5790688 | J35: 2.5790688 | K35: 2.5790688 | L35: 2.5790688 | M35: 2.5790688 | N35: 2.5790688 | O35: 2.5790688 | P35: 2.5790688 | Q35: 2.5790688 | R35: 2.5790688 | S35: 2.5790688 | T35: 2.5790688 | U35: 2.5790688 | V35: 2.5790688 | W35: 2.5790688 | X35: 2.5790688 | Y35: 2.5790688 | Z35: 2.5790688
A36: Liquefied petroleum gases | B36: O4630 | C36: 2.6418708 | D36: 2.6418708 | E36: 2.6418708 | F36: 2.6418708 | G36: 2.6418708 | H36: 2.6418708 | I36: 2.6418708 | J36: 2.6418708 | K36: 2.6418708 | L36: 2.6418708 | M36: 2.6418708 | N36: 2.6418708 | O36: 2.6418708 | P36: 2.6418708 | Q36: 2.6418708 | R36: 2.6418708 | S36: 2.6418708 | T36: 2.6418708 | U36: 2.6418708 | V36: 2.6418708 | W36: 2.6418708 | X36: 2.6418708 | Y36: 2.6418708 | Z36: 2.6418708
A37: Motor gasoline (excluding biofuel portion) | B37: O4652XR5210B | C37: 2.9014524 | D37: 2.9014524 | E37: 2.9014524 | F37: 2.9014524 | G37: 2.9014524 | H37: 2.9014524 | I37: 2.9014524 | J37: 2.9014524 | K37: 2.9014524 | L37: 2.9014524 | M37: 2.9014524 | N37: 2.9014524 | O37: 2.9014524 | P37: 2.9014524 | Q37: 2.9014524 | R37: 2.9014524 | S37: 2.9014524 | T37: 2.9014524 | U37: 2.9014524 | V37: 2.9014524 | W37: 2.9014524 | X37: 2.9014524 | Y37: 2.9014524 | Z37: 2.9014524
A38: Aviation gasoline | B38: O4651 | C38: 2.93076 | D38: 2.93076 | E38: 2.93076 | F38: 2.93076 | G38: 2.93076 | H38: 2.93076 | I38: 2.93076 | J38: 2.93076 | K38: 2.93076 | L38: 2.93076 | M38: 2.93076 | N38: 2.93076 | O38: 2.93076 | P38: 2.93076 | Q38: 2.93076 | R38: 2.93076 | S38: 2.93076 | T38: 2.93076 | U38: 2.93076 | V38: 2.93076 | W38: 2.93076 | X38: 2.93076 | Y38: 2.93076 | Z38: 2.93076
A39: Gasoline-type jet fuel | B39: O4653 | C39: 3.0103092 | D39: 3.0103092 | E39: 3.0103092 | F39: 3.0103092 | G39: 3.0103092 | H39: 3.0103092 | I39: 3.0103092 | J39: 3.0103092 | K39: 3.0103092 | L39: 3.0103092 | M39: 3.0103092 | N39: 3.0103092 | O39: 3.0103092 | P39: 3.0103092 | Q39: 3.0103092 | R39: 3.0103092 | S39: 3.0103092 | T39: 3.0103092 | U39: 3.0103092 | V39: 3.0103092 | W39: 3.0103092 | X39: 3.0103092 | Y39: 3.0103092 | Z39: 3.0103092
A40: Kerosene-type jet fuel (excluding biofuel portion) | B40: O4661XR5230B | C40: 3.0103092 | D40: 3.0103092 | E40: 3.0103092 | F40: 3.0103092 | G40: 3.0103092 | H40: 3.0103092 | I40: 3.0103092 | J40: 3.0103092 | K40: 3.0103092 | L40: 3.0103092 | M40: 3.0103092 | N40: 3.0103092 | O40: 3.0103092 | P40: 3.0103092 | Q40: 3.0103092 | R40: 3.0103092 | S40: 3.0103092 | T40: 3.0103092 | U40: 3.0103092 | V40: 3.0103092 | W40: 3.0103092 | X40: 3.0103092 | Y40: 3.0103092 | Z40: 3.0103092
...

Sheet GAE
A1: Gross available energy | B1: GAE | C1: 2000 | D1: 2001 | E1: 2002 | F1: 2003 | G1: 2004 | H1: 2005 | I1: 2006 | J1: 2007 | K1: 2008 | L1: 2009 | M1: 2010 | N1: 2011 | O1: 2012 | P1: 2013 | Q1: 2014 | R1: 2015 | S1: 2016 | T1: 2017 | U1: 2018 | V1: 2019 | W1: 2020 | X1: 2021 | Y1: 2022 | Z1: 2023
A2: Total | B2: TOTAL | C2: =SUM(C3,C17,C22,C25,C26,C51,C52) -> 432023.33 | D2: =SUM(D3,D17,D22,D25,D26,D51,D52) -> 428717.76 | E2: =SUM(E3,E17,E22,E25,E26,E51,E52) -> 437805.97 | F2: =SUM(F3,F17,F22,F25,F26,F51,F52) -> 456370.52 | G2: =SUM(G3,G17,G22,G25,G26,G51,G52) -> 465893.95 | H2: =SUM(H3,H17,H22,H25,H26,H51,H52) -> 468920.93 | I2: =SUM(I3,I17,I22,I25,I26,I51,I52) -> 463897.26 | J2: =SUM(J3,J17,J22,J25,J26,J51,J52) -> 457109.79 | ... Z2: =SUM(Z3,Z17,Z22,Z25,Z26,Z51,Z52) -> 303015.24
A3: Solid fossil fuels | B3: C0000X0350-0370 | C3: =SUM(C4,C8,C11) -> 30288.662 | D3: =SUM(D4,D8,D11) -> 34559.402 | E3: =SUM(E4,E8,E11) -> 37922.69 | F3: =SUM(F4,F8,F11) -> 41130.688 | G3: =SUM(G4,G8,G11) -> 48393.82 | H3: =SUM(H4,H8,H11) -> 48035.956 | I3: =SUM(I4,I8,I11) -> 46700.361 | J3: =SUM(J4,J8,J11) -> 47597.935 | ... Z3: =SUM(Z4,Z8,Z11) -> 14169.791
A4: Hard coal | B4: C0100 | C4: =SUM(C5:C7) -> 25056.02 | D4: =SUM(D5:D7) -> 29937.184 | E4: =SUM(E5:E7) -> 33765.143 | F4: =SUM(F5:F7) -> 37439.445 | G4: =SUM(G5:G7) -> 44664.629 | H4: =SUM(H5:H7) -> 43482.641 | I4: =SUM(I5:I7) -> 42283.378 | J4: =SUM(J5:J7) -> 43255.393 | ... Z4: =SUM(Z5:Z7) -> 12823.434
A5: Anthracite | B5: C0110 | C5: =INTMARB!C5+GIC!C5 -> 0 | D5: =INTMARB!D5+GIC!D5 -> 0 | E5: =INTMARB!E5+GIC!E5 -> 0 | F5: =INTMARB!F5+GIC!F5 -> 0 | G5: =INTMARB!G5+GIC!G5 -> 0 | H5: =INTMARB!H5+GIC!H5 -> 0 | I5: =INTMARB!I5+GIC!I5 -> 0 | J5: =INTMARB!J5+GIC!J5 -> 0 | ... Z5: =INTMARB!Z5+GIC!Z5 -> 36.441498
A6: Coking coal | B6: C0121 | C6: =INTMARB!C6+GIC!C6 -> 143.62335 | D6: =INTMARB!D6+GIC!D6 -> 196.3829 | E6: =INTMARB!E6+GIC!E6 -> 331.21265 | F6: =INTMARB!F6+GIC!F6 -> 175.86518 | G6: =INTMARB!G6+GIC!G6 -> 178.79638 | H6: =INTMARB!H6+GIC!H6 -> 1000.5526 | I6: =INTMARB!I6+GIC!I6 -> 157.47747 | J6: =INTMARB!J6+GIC!J6 -> 172.82925 | ... Z6: =INTMARB!Z6+GIC!Z6 -> 0
A7: Other bituminous coal | B7: C0129 | C7: =INTMARB!C7+GIC!C7 -> 24912.397 | D7: =INTMARB!D7+GIC!D7 -> 29740.801 | E7: =INTMARB!E7+GIC!E7 -> 33433.93 | F7: =INTMARB!F7+GIC!F7 -> 37263.58 | G7: =INTMARB!G7+GIC!G7 -> 44485.832 | H7: =INTMARB!H7+GIC!H7 -> 42482.089 | I7: =INTMARB!I7+GIC!I7 -> 42125.901 | J7: =INTMARB!J7+GIC!J7 -> 43082.564 | ... Z7: =INTMARB!Z7+GIC!Z7 -> 12786.992
A8: Brown coal | B8: C0200 | C8: =SUM(C9:C10) -> 31.771619 | D8: =SUM(D9:D10) -> 11.649861 | E8: =SUM(E9:E10) -> 10.590782 | F8: =SUM(F9:F10) -> 8.4748118 | G8: =SUM(G9:G10) -> 9.5342544 | H8: =SUM(H9:H10) -> 8.4748118 | I8: =SUM(I9:I10) -> 8.4748118 | J8: =SUM(J9:J10) -> 4.2374059 | ... Z8: =SUM(Z9:Z10) -> 0
A9: Sub-bituminous coal | B9: C0210 | C9: =INTMARB!C9+GIC!C9 -> 0 | D9: =INTMARB!D9+GIC!D9 -> 0 | E9: =INTMARB!E9+GIC!E9 -> 0 | F9: =INTMARB!F9+GIC!F9 -> 0 | G9: =INTMARB!G9+GIC!G9 -> 0 | H9: =INTMARB!H9+GIC!H9 -> 0 | I9: =INTMARB!I9+GIC!I9 -> 0 | J9: =INTMARB!J9+GIC!J9 -> 0 | ... Z9: =INTMARB!Z9+GIC!Z9 -> 0
A10: Lignite | B10: C0220 | C10: =INTMARB!C10+GIC!C10 -> 31.771619 | D10: =INTMARB!D10+GIC!D10 -> 11.649861 | E10: =INTMARB!E10+GIC!E10 -> 10.590782 | F10: =INTMARB!F10+GIC!F10 -> 8.4748118 | G10: =INTMARB!G10+GIC!G10 -> 9.5342544 | H10: =INTMARB!H10+GIC!H10 -> 8.4748118 | I10: =INTMARB!I10+GIC!I10 -> 8.4748118 | J10: =INTMARB!J10+GIC!J10 -> 4.2374059 | ... Z10: =INTMARB!Z10+GIC!Z10 -> 0
A11: Coal products | B11: C0300 | C11: =SUM(C12:C16) -> 5200.8697 | D11: =SUM(D12:D16) -> 4610.5679 | E11: =SUM(E12:E16) -> 4146.9562 | F11: =SUM(F12:F16) -> 3682.768 | G11: =SUM(G12:G16) -> 3719.6569 | H11: =SUM(H12:H16) -> 4544.8403 | I11: =SUM(I12:I16) -> 4408.5082 | J11: =SUM(J12:J16) -> 4338.3047 | ... Z11: =SUM(Z12:Z16) -> 1346.3573
A12: Patent fuel | B12: C0320 | C12: =INTMARB!C12+GIC!C12 -> 0 | D12: =INTMARB!D12+GIC!D12 -> 0 | E12: =INTMARB!E12+GIC!E12 -> 0 | F12: =INTMARB!F12+GIC!F12 -> 0 | G12: =INTMARB!G12+GIC!G12 -> 0 | H12: =INTMARB!H12+GIC!H12 -> 0 | I12: =INTMARB!I12+GIC!I12 -> 0 | J12: =INTMARB!J12+GIC!J12 -> 0 | ... Z12: =INTMARB!Z12+GIC!Z12 -> 0
A13: Coke oven coke | B13: C0311 | C13: =INTMARB!C13+GIC!C13 -> 5200.8697 | D13: =INTMARB!D13+GIC!D13 -> 4610.5679 | E13: =INTMARB!E13+GIC!E13 -> 4146.9562 | F13: =INTMARB!F13+GIC!F13 -> 3682.768 | G13: =INTMARB!G13+GIC!G13 -> 3719.6569 | H13: =INTMARB!H13+GIC!H13 -> 4544.8403 | I13: =INTMARB!I13+GIC!I13 -> 4408.5082 | J13: =INTMARB!J13+GIC!J13 -> 4338.3047 | ... Z13: =INTMARB!Z13+GIC!Z13 -> 1244.5163
A14: Gas coke | B14: C0312 | C14: =INTMARB!C14+GIC!C14 -> 0 | D14: =INTMARB!D14+GIC!D14 -> 0 | E14: =INTMARB!E14+GIC!E14 -> 0 | F14: =INTMARB!F14+GIC!F14 -> 0 | G14: =INTMARB!G14+GIC!G14 -> 0 | H14: =INTMARB!H14+GIC!H14 -> 0 | I14: =INTMARB!I14+GIC!I14 -> 0 | J14: =INTMARB!J14+GIC!J14 -> 0 | ... Z14: =INTMARB!Z14+GIC!Z14 -> 0
A15: Coal tar | B15: C0340 | C15: =INTMARB!C15+GIC!C15 -> 0 | D15: =INTMARB!D15+GIC!D15 -> 0 | E15: =INTMARB!E15+GIC!E15 -> 0 | F15: =INTMARB!F15+GIC!F15 -> 0 | G15: =INTMARB!G15+GIC!G15 -> 0 | H15: =INTMARB!H15+GIC!H15 -> 0 | I15: =INTMARB!I15+GIC!I15 -> 0 | J15: =INTMARB!J15+GIC!J15 -> 0 | ... Z15: =INTMARB!Z15+GIC!Z15 -> 101.84096
A16: Brown coal briquettes | B16: C0330 | C16: =INTMARB!C16+GIC!C16 -> 0 | D16: =INTMARB!D16+GIC!D16 -> 0 | E16: =INTMARB!E16+GIC!E16 -> 0 | F16: =INTMARB!F16+GIC!F16 -> 0 | G16: =INTMARB!G16+GIC!G16 -> 0 | H16: =INTMARB!H16+GIC!H16 -> 0 | I16: =INTMARB!I16+GIC!I16 -> 0 | J16: =INTMARB!J16+GIC!J16 -> 0 | ... Z16: =INTMARB!Z16+GIC!Z16 -> 0
A17: Manufactured gases | B17: C0350-0370 | C17: =SUM(C18:C21) -> 11323.352 | D17: =SUM(D18:D21) -> 9532.4365 | E17: =SUM(E18:E21) -> 9310.7404 | F17: =SUM(F18:F21) -> 9766.5122 | G17: =SUM(G18:G21) -> 9674.8181 | H17: =SUM(H18:H21) -> 11415.581 | I17: =SUM(I18:I21) -> 11970.026 | J17: =SUM(J18:J21) -> 11178.427 | ... Z17: =SUM(Z18:Z21) -> 2415.0151
A18: Gas works gas | B18: C0360 | C18: =INTMARB!C18+GIC!C18 -> 7.91208 | D18: =INTMARB!D18+GIC!D18 -> 0 | E18: =INTMARB!E18+GIC!E18 -> 0 | F18: =INTMARB!F18+GIC!F18 -> 0 | G18: =INTMARB!G18+GIC!G18 -> 0 | H18: =INTMARB!H18+GIC!H18 -> 0 | I18: =INTMARB!I18+GIC!I18 -> 0 | J18: =INTMARB!J18+GIC!J18 -> 0 | ... Z18: =INTMARB!Z18+GIC!Z18 -> 0
A19: Coke oven gas | B19: C0350 | C19: =INTMARB!C19+GIC!C19 -> 889.3098 | D19: =INTMARB!D19+GIC!D19 -> 584.09532 | E19: =INTMARB!E19+GIC!E19 -> 573.46596 | F19: =INTMARB!F19+GIC!F19 -> 609.90948 | G19: =INTMARB!G19+GIC!G19 -> 573.98544 | H19: =INTMARB!H19+GIC!H19 -> 565.31412 | I19: =INTMARB!I19+GIC!I19 -> 629.44992 | J19: =INTMARB!J19+GIC!J19 -> 658.5408 | ... Z19: =INTMARB!Z19+GIC!Z19 -> 361.14393
A20: Blast furnace gas | B20: C0371 | C20: =INTMARB!C20+GIC!C20 -> 9948.3799 | D20: =INTMARB!D20+GIC!D20 -> 8407.6191 | E20: =INTMARB!E20+GIC!E20 -> 8295.5602 | F20: =INTMARB!F20+GIC!F20 -> 8532.1604 | G20: =INTMARB!G20+GIC!G20 -> 8548.2802 | H20: =INTMARB!H20+GIC!H20 -> 10037.818 | I20: =INTMARB!I20+GIC!I20 -> 10654.8 | J20: =INTMARB!J20+GIC!J20 -> 10202.66 | ... Z20: =INTMARB!Z20+GIC!Z20 -> 1947.3658
A21: Other recovered gases | B21: C0379 | C21: =INTMARB!C21+GIC!C21 -> 477.75022 | D21: =INTMARB!D21+GIC!D21 -> 540.72215 | E21: =INTMARB!E21+GIC!E21 -> 441.71422 | F21: =INTMARB!F21+GIC!F21 -> 624.44229 | G21: =INTMARB!G21+GIC!G21 -> 552.55244 | H21: =INTMARB!H21+GIC!H21 -> 812.448 | I21: =INTMARB!I21+GIC!I21 -> 685.77622 | J21: =INTMARB!J21+GIC!J21 -> 317.22622 | ... Z21: =INTMARB!Z21+GIC!Z21 -> 106.50538
A22: Peat and peat products | B22: P1000 | C22: =SUM(C23:C24) -> 0 | D22: =SUM(D23:D24) -> 0 | E22: =SUM(E23:E24) -> 0 | F22: =SUM(F23:F24) -> 0 | G22: =SUM(G23:G24) -> 0 | H22: =SUM(H23:H24) -> 0 | I22: =SUM(I23:I24) -> 0 | J22: =SUM(J23:J24) -> 0 | ... Z22: =SUM(Z23:Z24) -> 0
A23: Peat | B23: P1100 | C23: =INTMARB!C23+GIC!C23 -> 0 | D23: =INTMARB!D23+GIC!D23 -> 0 | E23: =INTMARB!E23+GIC!E23 -> 0 | F23: =INTMARB!F23+GIC!F23 -> 0 | G23: =INTMARB!G23+GIC!G23 -> 0 | H23: =INTMARB!H23+GIC!H23 -> 0 | I23: =INTMARB!I23+GIC!I23 -> 0 | J23: =INTMARB!J23+GIC!J23 -> 0 | ... Z23: =INTMARB!Z23+GIC!Z23 -> 0
A24: Peat products | B24: P1200 | C24: =INTMARB!C24+GIC!C24 -> 0 | D24: =INTMARB!D24+GIC!D24 -> 0 | E24: =INTMARB!E24+GIC!E24 -> 0 | F24: =INTMARB!F24+GIC!F24 -> 0 | G24: =INTMARB!G24+GIC!G24 -> 0 | H24: =INTMARB!H24+GIC!H24 -> 0 | I24: =INTMARB!I24+GIC!I24 -> 0 | J24: =INTMARB!J24+GIC!J24 -> 0 | ... Z24: =INTMARB!Z24+GIC!Z24 -> 0
A25: Oil shale and oil sands | B25: S2000 | C25: =INTMARB!C25+GIC!C25 -> 0 | D25: =INTMARB!D25+GIC!D25 -> 0 | E25: =INTMARB!E25+GIC!E25 -> 0 | F25: =INTMARB!F25+GIC!F25 -> 0 | G25: =INTMARB!G25+GIC!G25 -> 0 | H25: =INTMARB!H25+GIC!H25 -> 0 | I25: =INTMARB!I25+GIC!I25 -> 0 | J25: =INTMARB!J25+GIC!J25 -> 0 | ... Z25: =INTMARB!Z25+GIC!Z25 -> 0
A26: Oil and petroleum products | B26: O4000XBIO | C26: =SUM(C27,C33) -> 256287.63 | D26: =SUM(D27,D33) -> 249747.22 | E26: =SUM(E27,E33) -> 256267.85 | F26: =SUM(F27,F33) -> 256456.43 | G26: =SUM(G27,G33) -> 252776.81 | H26: =SUM(H27,H33) -> 243577.45 | I26: =SUM(I27,I33) -> 242126.38 | J26: =SUM(J27,J33) -> 233939.29 | ... Z26: =SUM(Z27,Z33) -> 163675.22
A27: Crude oil, NGL, refinery feedstocks, additives and oxygenates and other hydrocarbons (excluding biofuel portion) | B27: O4100_TOT_4200-4500XBIO | C27: =SUM(C28:C32) -> 0 | D27: =SUM(D28:D32) -> 0 | E27: =SUM(E28:E32) -> 0 | F27: =SUM(F28:F32) -> 0 | G27: =SUM(G28:G32) -> 0 | H27: =SUM(H28:H32) -> 0 | I27: =SUM(I28:I32) -> 0 | J27: =SUM(J28:J32) -> 0 | ... Z27: =SUM(Z28:Z32) -> 0
A28: Crude oil | B28: O4100_TOT | C28: =INTMARB!C28+GIC!C28 -> 0 | D28: =INTMARB!D28+GIC!D28 -> 0 | E28: =INTMARB!E28+GIC!E28 -> 0 | F28: =INTMARB!F28+GIC!F28 -> 0 | G28: =INTMARB!G28+GIC!G28 -> 0 | H28: =INTMARB!H28+GIC!H28 -> 0 | I28: =INTMARB!I28+GIC!I28 -> 0 | J28: =INTMARB!J28+GIC!J28 -> 0 | ... Z28: =INTMARB!Z28+GIC!Z28 -> 0
A29: Natural gas liquids | B29: O4200 | C29: =INTMARB!C29+GIC!C29 -> 0 | D29: =INTMARB!D29+GIC!D29 -> 0 | E29: =INTMARB!E29+GIC!E29 -> 0 | F29: =INTMARB!F29+GIC!F29 -> 0 | G29: =INTMARB!G29+GIC!G29 -> 0 | H29: =INTMARB!H29+GIC!H29 -> 0 | I29: =INTMARB!I29+GIC!I29 -> 0 | J29: =INTMARB!J29+GIC!J29 -> 0 | ... Z29: =INTMARB!Z29+GIC!Z29 -> 0
A30: Refinery feedstocks | B30: O4300 | C30: =INTMARB!C30+GIC!C30 -> 0 | D30: =INTMARB!D30+GIC!D30 -> 0 | E30: =INTMARB!E30+GIC!E30 -> 0 | F30: =INTMARB!F30+GIC!F30 -> 0 | G30: =INTMARB!G30+GIC!G30 -> 0 | H30: =INTMARB!H30+GIC!H30 -> 0 | I30: =INTMARB!I30+GIC!I30 -> 0 | J30: =INTMARB!J30+GIC!J30 -> 0 | ... Z30: =INTMARB!Z30+GIC!Z30 -> 0
A31: Additives and oxygenates (excluding biofuel portion) | B31: O4400X4410 | C31: =INTMARB!C31+GIC!C31 -> 0 | D31: =INTMARB!D31+GIC!D31 -> 0 | E31: =INTMARB!E31+GIC!E31 -> 0 | F31: =INTMARB!F31+GIC!F31 -> 0 | G31: =INTMARB!G31+GIC!G31 -> 0 | H31: =INTMARB!H31+GIC!H31 -> 0 | I31: =INTMARB!I31+GIC!I31 -> 0 | J31: =INTMARB!J31+GIC!J31 -> 0 | ... Z31: =INTMARB!Z31+GIC!Z31 -> 0
A32: Other hydrocarbons | B32: O4500 | C32: =INTMARB!C32+GIC!C32 -> 0 | D32: =INTMARB!D32+GIC!D32 -> 0 | E32: =INTMARB!E32+GIC!E32 -> 0 | F32: =INTMARB!F32+GIC!F32 -> 0 | G32: =INTMARB!G32+GIC!G32 -> 0 | H32: =INTMARB!H32+GIC!H32 -> 0 | I32: =INTMARB!I32+GIC!I32 -> 0 | J32: =INTMARB!J32+GIC!J32 -> 0 | ... Z32: =INTMARB!Z32+GIC!Z32 -> 0
A33: Oil products (excluding biofuel portion) | B33: O4600XBIO | C33: =SUM(C34:C50) -> 256287.63 | D33: =SUM(D34:D50) -> 249747.22 | E33: =SUM(E34:E50) -> 256267.85 | F33: =SUM(F34:F50) -> 256456.43 | G33: =SUM(G34:G50) -> 252776.81 | H33: =SUM(H34:H50) -> 243577.45 | I33: =SUM(I34:I50) -> 242126.38 | J33: =SUM(J34:J50) -> 233939.29 | ... Z33: =SUM(Z34:Z50) -> 163675.22
A34: Refinery gas | B34: O4610 | C34: =INTMARB!C34+GIC!C34 -> 7068.1248 | D34: =INTMARB!D34+GIC!D34 -> 6372.432 | E34: =INTMARB!E34+GIC!E34 -> 6740.2368 | F34: =INTMARB!F34+GIC!F34 -> 7088.0832 | G34: =INTMARB!G34+GIC!G34 -> 7980.5088 | H34: =INTMARB!H34+GIC!H34 -> 8684.7552 | I34: =INTMARB!I34+GIC!I34 -> 8439.552 | J34: =INTMARB!J34+GIC!J34 -> 9389.0016 | ... Z34: =INTMARB!Z34+GIC!Z34 -> 7520.9725
A35: Ethane | B35: O4620 | C35: =INTMARB!C35+GIC!C35 -> 0 | D35: =INTMARB!D35+GIC!D35 -> 0 | E35: =INTMARB!E35+GIC!E35 -> 0 | F35: =INTMARB!F35+GIC!F35 -> 0 | G35: =INTMARB!G35+GIC!G35 -> 0 | H35: =INTMARB!H35+GIC!H35 -> 0 | I35: =INTMARB!I35+GIC!I35 -> 0 | J35: =INTMARB!J35+GIC!J35 -> 0 | ... Z35: =INTMARB!Z35+GIC!Z35 -> 0
A36: Liquefied petroleum gases | B36: O4630 | C36: =INTMARB!C36+GIC!C36 -> 11450.756 | D36: =INTMARB!D36+GIC!D36 -> 11360.776 | E36: =INTMARB!E36+GIC!E36 -> 10893.458 | F36: =INTMARB!F36+GIC!F36 -> 10884.75 | G36: =INTMARB!G36+GIC!G36 -> 10400.016 | H36: =INTMARB!H36+GIC!H36 -> 10391.308 | I36: =INTMARB!I36+GIC!I36 -> 9761.4441 | J36: =INTMARB!J36+GIC!J36 -> 9227.365 | ... Z36: =INTMARB!Z36+GIC!Z36 -> 9903.1108
A37: Motor gasoline (excluding biofuel portion) | B37: O4652XR5210B | C37: =INTMARB!C37+GIC!C37 -> 51238.757 | D37: =INTMARB!D37+GIC!D37 -> 50226.422 | E37: =INTMARB!E37+GIC!E37 -> 49515.958 | F37: =INTMARB!F37+GIC!F37 -> 47933.424 | G37: =INTMARB!G37+GIC!G37 -> 45216.586 | H37: =INTMARB!H37+GIC!H37 -> 42124.698 | I37: =INTMARB!I37+GIC!I37 -> 39499.337 | J37: =INTMARB!J37+GIC!J37 -> 37233.781 | ... Z37: =INTMARB!Z37+GIC!Z37 -> 24878.069
A38: Aviation gasoline | B38: O4651 | C38: =INTMARB!C38+GIC!C38 -> 18.479916 | D38: =INTMARB!D38+GIC!D38 -> 33.879888 | E38: =INTMARB!E38+GIC!E38 -> 36.960084 | F38: =INTMARB!F38+GIC!F38 -> 46.199916 | G38: =INTMARB!G38+GIC!G38 -> 43.119972 | H38: =INTMARB!H38+GIC!H38 -> 43.119972 | I38: =INTMARB!I38+GIC!I38 -> 49.280112 | J38: =INTMARB!J38+GIC!J38 -> 46.199916 | ... Z38: =INTMARB!Z38+GIC!Z38 -> 2.540916
A39: Gasoline-type jet fuel | B39: O4653 | C39: =INTMARB!C39+GIC!C39 -> 0 | D39: =INTMARB!D39+GIC!D39 -> 0 | E39: =INTMARB!E39+GIC!E39 -> 0 | F39: =INTMARB!F39+GIC!F39 -> 0 | G39: =INTMARB!G39+GIC!G39 -> 0 | H39: =INTMARB!H39+GIC!H39 -> 0 | I39: =INTMARB!I39+GIC!I39 -> 0 | J39: =INTMARB!J39+GIC!J39 -> 0 | ... Z39: =INTMARB!Z39+GIC!Z39 -> 0
A40: Kerosene-type jet fuel (excluding biofuel portion) | B40: O4661XR5230B | C40: =INTMARB!C40+GIC!C40 -> 11065.194 | D40: =INTMARB!D40+GIC!D40 -> 9874.8899 | E40: =INTMARB!E40+GIC!E40 -> 9881.0733 | F40: =INTMARB!F40+GIC!F40 -> 11201.229 | G40: =INTMARB!G40+GIC!G40 -> 11164.129 | H40: =INTMARB!H40+GIC!H40 -> 11689.718 | I40: =INTMARB!I40+GIC!I40 -> 12410.084 | J40: =INTMARB!J40+GIC!J40 -> 13080.983 | ... Z40: =INTMARB!Z40+GIC!Z40 -> 14386.048
...

Sheet INTMARB
A1: International maritime bunkers | B1: INTMARB | C1: 2000 | D1: 2001 | E1: 2002 | F1: 2003 | G1: 2004 | H1: 2005 | I1: 2006 | J1: 2007 | K1: 2008 | L1: 2009 | M1: 2010 | N1: 2011 | O1: 2012 | P1: 2013 | Q1: 2014 | R1: 2015 | S1: 2016 | T1: 2017 | U1: 2018 | V1: 2019 | W1: 2020 | X1: 2021 | Y1: 2022 | Z1: 2023
A2: Total | B2: TOTAL | C2: =SUM(C3,C17,C22,C25,C26,C51,C52) -> 5302.0072 | D2: =SUM(D3,D17,D22,D25,D26,D51,D52) -> 5663.6933 | E2: =SUM(E3,E17,E22,E25,E26,E51,E52) -> 6167.7424 | F2: =SUM(F3,F17,F22,F25,F26,F51,F52) -> 6728.1277 | G2: =SUM(G3,G17,G22,G25,G26,G51,G52) -> 7059.5124 | H2: =SUM(H3,H17,H22,H25,H26,H51,H52) -> 7235.3515 | I2: =SUM(I3,I17,I22,I25,I26,I51,I52) -> 7523.0197 | J2: =SUM(J3,J17,J22,J25,J26,J51,J52) -> 7766.7203 | ... Z2: =SUM(Z3,Z17,Z22,Z25,Z26,Z51,Z52) -> 7279.2246
A3: Solid fossil fuels | B3: C0000X0350-0370 | C3: =SUM(C4,C8,C11) -> 0 | D3: =SUM(D4,D8,D11) -> 0 | E3: =SUM(E4,E8,E11) -> 0 | F3: =SUM(F4,F8,F11) -> 0 | G3: =SUM(G4,G8,G11) -> 0 | H3: =SUM(H4,H8,H11) -> 0 | I3: =SUM(I4,I8,I11) -> 0 | J3: =SUM(J4,J8,J11) -> 0 | ... Z3: =SUM(Z4,Z8,Z11) -> 0
A4: Hard coal | B4: C0100 | C4: =SUM(C5:C7) -> 0 | D4: =SUM(D5:D7) -> 0 | E4: =SUM(E5:E7) -> 0 | F4: =SUM(F5:F7) -> 0 | G4: =SUM(G5:G7) -> 0 | H4: =SUM(H5:H7) -> 0 | I4: =SUM(I5:I7) -> 0 | J4: =SUM(J5:J7) -> 0 | ... Z4: =SUM(Z5:Z7) -> 0
A5: Anthracite | B5: C0110 | C5: =INTMARB_IN!C5+INTMARB_EX!C5 -> 0 | D5: =INTMARB_IN!D5+INTMARB_EX!D5 -> 0 | E5: =INTMARB_IN!E5+INTMARB_EX!E5 -> 0 | F5: =INTMARB_IN!F5+INTMARB_EX!F5 -> 0 | G5: =INTMARB_IN!G5+INTMARB_EX!G5 -> 0 | H5: =INTMARB_IN!H5+INTMARB_EX!H5 -> 0 | I5: =INTMARB_IN!I5+INTMARB_EX!I5 -> 0 | J5: =INTMARB_IN!J5+INTMARB_EX!J5 -> 0 | ... Z5: =INTMARB_IN!Z5+INTMARB_EX!Z5 -> 0
A6: Coking coal | B6: C0121 | C6: =INTMARB_IN!C6+INTMARB_EX!C6 -> 0 | D6: =INTMARB_IN!D6+INTMARB_EX!D6 -> 0 | E6: =INTMARB_IN!E6+INTMARB_EX!E6 -> 0 | F6: =INTMARB_IN!F6+INTMARB_EX!F6 -> 0 | G6: =INTMARB_IN!G6+INTMARB_EX!G6 -> 0 | H6: =INTMARB_IN!H6+INTMARB_EX!H6 -> 0 | I6: =INTMARB_IN!I6+INTMARB_EX!I6 -> 0 | J6: =INTMARB_IN!J6+INTMARB_EX!J6 -> 0 | ... Z6: =INTMARB_IN!Z6+INTMARB_EX!Z6 -> 0
A7: Other bituminous coal | B7: C0129 | C7: =INTMARB_IN!C7+INTMARB_EX!C7 -> 0 | D7: =INTMARB_IN!D7+INTMARB_EX!D7 -> 0 | E7: =INTMARB_IN!E7+INTMARB_EX!E7 -> 0 | F7: =INTMARB_IN!F7+INTMARB_EX!F7 -> 0 | G7: =INTMARB_IN!G7+INTMARB_EX!G7 -> 0 | H7: =INTMARB_IN!H7+INTMARB_EX!H7 -> 0 | I7: =INTMARB_IN!I7+INTMARB_EX!I7 -> 0 | J7: =INTMARB_IN!J7+INTMARB_EX!J7 -> 0 | ... Z7: =INTMARB_IN!Z7+INTMARB_EX!Z7 -> 0
A8: Brown coal | B8: C0200 | C8: =SUM(C9:C10) -> 0 | D8: =SUM(D9:D10) -> 0 | E8: =SUM(E9:E10) -> 0 | F8: =SUM(F9:F10) -> 0 | G8: =SUM(G9:G10) -> 0 | H8: =SUM(H9:H10) -> 0 | I8: =SUM(I9:I10) -> 0 | J8: =SUM(J9:J10) -> 0 | ... Z8: =SUM(Z9:Z10) -> 0
A9: Sub-bituminous coal | B9: C0210 | C9: =INTMARB_IN!C9+INTMARB_EX!C9 -> 0 | D9: =INTMARB_IN!D9+INTMARB_EX!D9 -> 0 | E9: =INTMARB_IN!E9+INTMARB_EX!E9 -> 0 | F9: =INTMARB_IN!F9+INTMARB_EX!F9 -> 0 | G9: =INTMARB_IN!G9+INTMARB_EX!G9 -> 0 | H9: =INTMARB_IN!H9+INTMARB_EX!H9 -> 0 | I9: =INTMARB_IN!I9+INTMARB_EX!I9 -> 0 | J9: =INTMARB_IN!J9+INTMARB_EX!J9 -> 0 | ... Z9: =INTMARB_IN!Z9+INTMARB_EX!Z9 -> 0
A10: Lignite | B10: C0220 | C10: =INTMARB_IN!C10+INTMARB_EX!C10 -> 0 | D10: =INTMARB_IN!D10+INTMARB_EX!D10 -> 0 | E10: =INTMARB_IN!E10+INTMARB_EX!E10 -> 0 | F10: =INTMARB_IN!F10+INTMARB_EX!F10 -> 0 | G10: =INTMARB_IN!G10+INTMARB_EX!G10 -> 0 | H10: =INTMARB_IN!H10+INTMARB_EX!H10 -> 0 | I10: =INTMARB_IN!I10+INTMARB_EX!I10 -> 0 | J10: =INTMARB_IN!J10+INTMARB_EX!J10 -> 0 | ... Z10: =INTMARB_IN!Z10+INTMARB_EX!Z10 -> 0
A11: Coal products | B11: C0300 | C11: =SUM(C12:C16) -> 0 | D11: =SUM(D12:D16) -> 0 | E11: =SUM(E12:E16) -> 0 | F11: =SUM(F12:F16) -> 0 | G11: =SUM(G12:G16) -> 0 | H11: =SUM(H12:H16) -> 0 | I11: =SUM(I12:I16) -> 0 | J11: =SUM(J12:J16) -> 0 | ... Z11: =SUM(Z12:Z16) -> 0
A12: Patent fuel | B12: C0320 | C12: =INTMARB_IN!C12+INTMARB_EX!C12 -> 0 | D12: =INTMARB_IN!D12+INTMARB_EX!D12 -> 0 | E12: =INTMARB_IN!E12+INTMARB_EX!E12 -> 0 | F12: =INTMARB_IN!F12+INTMARB_EX!F12 -> 0 | G12: =INTMARB_IN!G12+INTMARB_EX!G12 -> 0 | H12: =INTMARB_IN!H12+INTMARB_EX!H12 -> 0 | I12: =INTMARB_IN!I12+INTMARB_EX!I12 -> 0 | J12: =INTMARB_IN!J12+INTMARB_EX!J12 -> 0 | ... Z12: =INTMARB_IN!Z12+INTMARB_EX!Z12 -> 0
A13: Coke oven coke | B13: C0311 | C13: =INTMARB_IN!C13+INTMARB_EX!C13 -> 0 | D13: =INTMARB_IN!D13+INTMARB_EX!D13 -> 0 | E13: =INTMARB_IN!E13+INTMARB_EX!E13 -> 0 | F13: =INTMARB_IN!F13+INTMARB_EX!F13 -> 0 | G13: =INTMARB_IN!G13+INTMARB_EX!G13 -> 0 | H13: =INTMARB_IN!H13+INTMARB_EX!H13 -> 0 | I13: =INTMARB_IN!I13+INTMARB_EX!I13 -> 0 | J13: =INTMARB_IN!J13+INTMARB_EX!J13 -> 0 | ... Z13: =INTMARB_IN!Z13+INTMARB_EX!Z13 -> 0
A14: Gas coke | B14: C0312 | C14: =INTMARB_IN!C14+INTMARB_EX!C14 -> 0 | D14: =INTMARB_IN!D14+INTMARB_EX!D14 -> 0 | E14: =INTMARB_IN!E14+INTMARB_EX!E14 -> 0 | F14: =INTMARB_IN!F14+INTMARB_EX!F14 -> 0 | G14: =INTMARB_IN!G14+INTMARB_EX!G14 -> 0 | H14: =INTMARB_IN!H14+INTMARB_EX!H14 -> 0 | I14: =INTMARB_IN!I14+INTMARB_EX!I14 -> 0 | J14: =INTMARB_IN!J14+INTMARB_EX!J14 -> 0 | ... Z14: =INTMARB_IN!Z14+INTMARB_EX!Z14 -> 0
A15: Coal tar | B15: C0340 | C15: =INTMARB_IN!C15+INTMARB_EX!C15 -> 0 | D15: =INTMARB_IN!D15+INTMARB_EX!D15 -> 0 | E15: =INTMARB_IN!E15+INTMARB_EX!E15 -> 0 | F15: =INTMARB_IN!F15+INTMARB_EX!F15 -> 0 | G15: =INTMARB_IN!G15+INTMARB_EX!G15 -> 0 | H15: =INTMARB_IN!H15+INTMARB_EX!H15 -> 0 | I15: =INTMARB_IN!I15+INTMARB_EX!I15 -> 0 | J15: =INTMARB_IN!J15+INTMARB_EX!J15 -> 0 | ... Z15: =INTMARB_IN!Z15+INTMARB_EX!Z15 -> 0
A16: Brown coal briquettes | B16: C0330 | C16: =INTMARB_IN!C16+INTMARB_EX!C16 -> 0 | D16: =INTMARB_IN!D16+INTMARB_EX!D16 -> 0 | E16: =INTMARB_IN!E16+INTMARB_EX!E16 -> 0 | F16: =INTMARB_IN!F16+INTMARB_EX!F16 -> 0 | G16: =INTMARB_IN!G16+INTMARB_EX!G16 -> 0 | H16: =INTMARB_IN!H16+INTMARB_EX!H16 -> 0 | I16: =INTMARB_IN!I16+INTMARB_EX!I16 -> 0 | J16: =INTMARB_IN!J16+INTMARB_EX!J16 -> 0 | ... Z16: =INTMARB_IN!Z16+INTMARB_EX!Z16 -> 0
A17: Manufactured gases | B17: C0350-0370 | C17: =SUM(C18:C21) -> 0 | D17: =SUM(D18:D21) -> 0 | E17: =SUM(E18:E21) -> 0 | F17: =SUM(F18:F21) -> 0 | G17: =SUM(G18:G21) -> 0 | H17: =SUM(H18:H21) -> 0 | I17: =SUM(I18:I21) -> 0 | J17: =SUM(J18:J21) -> 0 | ... Z17: =SUM(Z18:Z21) -> 0
A18: Gas works gas | B18: C0360 | C18: =INTMARB_IN!C18+INTMARB_EX!C18 -> 0 | D18: =INTMARB_IN!D18+INTMARB_EX!D18 -> 0 | E18: =INTMARB_IN!E18+INTMARB_EX!E18 -> 0 | F18: =INTMARB_IN!F18+INTMARB_EX!F18 -> 0 | G18: =INTMARB_IN!G18+INTMARB_EX!G18 -> 0 | H18: =INTMARB_IN!H18+INTMARB_EX!H18 -> 0 | I18: =INTMARB_IN!I18+INTMARB_EX!I18 -> 0 | J18: =INTMARB_IN!J18+INTMARB_EX!J18 -> 0 | ... Z18: =INTMARB_IN!Z18+INTMARB_EX!Z18 -> 0
A19: Coke oven gas | B19: C0350 | C19: =INTMARB_IN!C19+INTMARB_EX!C19 -> 0 | D19: =INTMARB_IN!D19+INTMARB_EX!D19 -> 0 | E19: =INTMARB_IN!E19+INTMARB_EX!E19 -> 0 | F19: =INTMARB_IN!F19+INTMARB_EX!F19 -> 0 | G19: =INTMARB_IN!G19+INTMARB_EX!G19 -> 0 | H19: =INTMARB_IN!H19+INTMARB_EX!H19 -> 0 | I19: =INTMARB_IN!I19+INTMARB_EX!I19 -> 0 | J19: =INTMARB_IN!J19+INTMARB_EX!J19 -> 0 | ... Z19: =INTMARB_IN!Z19+INTMARB_EX!Z19 -> 0
A20: Blast furnace gas | B20: C0371 | C20: =INTMARB_IN!C20+INTMARB_EX!C20 -> 0 | D20: =INTMARB_IN!D20+INTMARB_EX!D20 -> 0 | E20: =INTMARB_IN!E20+INTMARB_EX!E20 -> 0 | F20: =INTMARB_IN!F20+INTMARB_EX!F20 -> 0 | G20: =INTMARB_IN!G20+INTMARB_EX!G20 -> 0 | H20: =INTMARB_IN!H20+INTMARB_EX!H20 -> 0 | I20: =INTMARB_IN!I20+INTMARB_EX!I20 -> 0 | J20: =INTMARB_IN!J20+INTMARB_EX!J20 -> 0 | ... Z20: =INTMARB_IN!Z20+INTMARB_EX!Z20 -> 0
A21: Other recovered gases | B21: C0379 | C21: =INTMARB_IN!C21+INTMARB_EX!C21 -> 0 | D21: =INTMARB_IN!D21+INTMARB_EX!D21 -> 0 | E21: =INTMARB_IN!E21+INTMARB_EX!E21 -> 0 | F21: =INTMARB_IN!F21+INTMARB_EX!F21 -> 0 | G21: =INTMARB_IN!G21+INTMARB_EX!G21 -> 0 | H21: =INTMARB_IN!H21+INTMARB_EX!H21 -> 0 | I21: =INTMARB_IN!I21+INTMARB_EX!I21 -> 0 | J21: =INTMARB_IN!J21+INTMARB_EX!J21 -> 0 | ... Z21: =INTMARB_IN!Z21+INTMARB_EX!Z21 -> 0
A22: Peat and peat products | B22: P1000 | C22: =SUM(C23:C24) -> 0 | D22: =SUM(D23:D24) -> 0 | E22: =SUM(E23:E24) -> 0 | F22: =SUM(F23:F24) -> 0 | G22: =SUM(G23:G24) -> 0 | H22: =SUM(H23:H24) -> 0 | I22: =SUM(I23:I24) -> 0 | J22: =SUM(J23:J24) -> 0 | ... Z22: =SUM(Z23:Z24) -> 0
A23: Peat | B23: P1100 | C23: =INTMARB_IN!C23+INTMARB_EX!C23 -> 0 | D23: =INTMARB_IN!D23+INTMARB_EX!D23 -> 0 | E23: =INTMARB_IN!E23+INTMARB_EX!E23 -> 0 | F23: =INTMARB_IN!F23+INTMARB_EX!F23 -> 0 | G23: =INTMARB_IN!G23+INTMARB_EX!G23 -> 0 | H23: =INTMARB_IN!H23+INTMARB_EX!H23 -> 0 | I23: =INTMARB_IN!I23+INTMARB_EX!I23 -> 0 | J23: =INTMARB_IN!J23+INTMARB_EX!J23 -> 0 | ... Z23: =INTMARB_IN!Z23+INTMARB_EX!Z23 -> 0
A24: Peat products | B24: P1200 | C24: =INTMARB_IN!C24+INTMARB_EX!C24 -> 0 | D24: =INTMARB_IN!D24+INTMARB_EX!D24 -> 0 | E24: =INTMARB_IN!E24+INTMARB_EX!E24 -> 0 | F24: =INTMARB_IN!F24+INTMARB_EX!F24 -> 0 | G24: =INTMARB_IN!G24+INTMARB_EX!G24 -> 0 | H24: =INTMARB_IN!H24+INTMARB_EX!H24 -> 0 | I24: =INTMARB_IN!I24+INTMARB_EX!I24 -> 0 | J24: =INTMARB_IN!J24+INTMARB_EX!J24 -> 0 | ... Z24: =INTMARB_IN!Z24+INTMARB_EX!Z24 -> 0
A25: Oil shale and oil sands | B25: S2000 | C25: =INTMARB_IN!C25+INTMARB_EX!C25 -> 0 | D25: =INTMARB_IN!D25+INTMARB_EX!D25 -> 0 | E25: =INTMARB_IN!E25+INTMARB_EX!E25 -> 0 | F25: =INTMARB_IN!F25+INTMARB_EX!F25 -> 0 | G25: =INTMARB_IN!G25+INTMARB_EX!G25 -> 0 | H25: =INTMARB_IN!H25+INTMARB_EX!H25 -> 0 | I25: =INTMARB_IN!I25+INTMARB_EX!I25 -> 0 | J25: =INTMARB_IN!J25+INTMARB_EX!J25 -> 0 | ... Z25: =INTMARB_IN!Z25+INTMARB_EX!Z25 -> 0
A26: Oil and petroleum products | B26: O4000XBIO | C26: =SUM(C27,C33) -> 5302.0072 | D26: =SUM(D27,D33) -> 5663.6933 | E26: =SUM(E27,E33) -> 6167.7424 | F26: =SUM(F27,F33) -> 6728.1277 | G26: =SUM(G27,G33) -> 7059.5124 | H26: =SUM(H27,H33) -> 7235.3515 | I26: =SUM(I27,I33) -> 7523.0197 | J26: =SUM(J27,J33) -> 7766.7203 | ... Z26: =SUM(Z27,Z33) -> 7279.2246
A27: Crude oil, NGL, refinery feedstocks, additives and oxygenates and other hydrocarbons (excluding biofuel portion) | B27: O4100_TOT_4200-4500XBIO | C27: =SUM(C28:C32) -> 0 | D27: =SUM(D28:D32) -> 0 | E27: =SUM(E28:E32) -> 0 | F27: =SUM(F28:F32) -> 0 | G27: =SUM(G28:G32) -> 0 | H27: =SUM(H28:H32) -> 0 | I27: =SUM(I28:I32) -> 0 | J27: =SUM(J28:J32) -> 0 | ... Z27: =SUM(Z28:Z32) -> 0
A28: Crude oil | B28: O4100_TOT | C28: =INTMARB_IN!C28+INTMARB_EX!C28 -> 0 | D28: =INTMARB_IN!D28+INTMARB_EX!D28 -> 0 | E28: =INTMARB_IN!E28+INTMARB_EX!E28 -> 0 | F28: =INTMARB_IN!F28+INTMARB_EX!F28 -> 0 | G28: =INTMARB_IN!G28+INTMARB_EX!G28 -> 0 | H28: =INTMARB_IN!H28+INTMARB_EX!H28 -> 0 | I28: =INTMARB_IN!I28+INTMARB_EX!I28 -> 0 | J28: =INTMARB_IN!J28+INTMARB_EX!J28 -> 0 | ... Z28: =INTMARB_IN!Z28+INTMARB_EX!Z28 -> 0
A29: Natural gas liquids | B29: O4200 | C29: =INTMARB_IN!C29+INTMARB_EX!C29 -> 0 | D29: =INTMARB_IN!D29+INTMARB_EX!D29 -> 0 | E29: =INTMARB_IN!E29+INTMARB_EX!E29 -> 0 | F29: =INTMARB_IN!F29+INTMARB_EX!F29 -> 0 | G29: =INTMARB_IN!G29+INTMARB_EX!G29 -> 0 | H29: =INTMARB_IN!H29+INTMARB_EX!H29 -> 0 | I29: =INTMARB_IN!I29+INTMARB_EX!I29 -> 0 | J29: =INTMARB_IN!J29+INTMARB_EX!J29 -> 0 | ... Z29: =INTMARB_IN!Z29+INTMARB_EX!Z29 -> 0
A30: Refinery feedstocks | B30: O4300 | C30: =INTMARB_IN!C30+INTMARB_EX!C30 -> 0 | D30: =INTMARB_IN!D30+INTMARB_EX!D30 -> 0 | E30: =INTMARB_IN!E30+INTMARB_EX!E30 -> 0 | F30: =INTMARB_IN!F30+INTMARB_EX!F30 -> 0 | G30: =INTMARB_IN!G30+INTMARB_EX!G30 -> 0 | H30: =INTMARB_IN!H30+INTMARB_EX!H30 -> 0 | I30: =INTMARB_IN!I30+INTMARB_EX!I30 -> 0 | J30: =INTMARB_IN!J30+INTMARB_EX!J30 -> 0 | ... Z30: =INTMARB_IN!Z30+INTMARB_EX!Z30 -> 0
A31: Additives and oxygenates (excluding biofuel portion) | B31: O4400X4410 | C31: =INTMARB_IN!C31+INTMARB_EX!C31 -> 0 | D31: =INTMARB_IN!D31+INTMARB_EX!D31 -> 0 | E31: =INTMARB_IN!E31+INTMARB_EX!E31 -> 0 | F31: =INTMARB_IN!F31+INTMARB_EX!F31 -> 0 | G31: =INTMARB_IN!G31+INTMARB_EX!G31 -> 0 | H31: =INTMARB_IN!H31+INTMARB_EX!H31 -> 0 | I31: =INTMARB_IN!I31+INTMARB_EX!I31 -> 0 | J31: =INTMARB_IN!J31+INTMARB_EX!J31 -> 0 | ... Z31: =INTMARB_IN!Z31+INTMARB_EX!Z31 -> 0
A32: Other hydrocarbons | B32: O4500 | C32: =INTMARB_IN!C32+INTMARB_EX!C32 -> 0 | D32: =INTMARB_IN!D32+INTMARB_EX!D32 -> 0 | E32: =INTMARB_IN!E32+INTMARB_EX!E32 -> 0 | F32: =INTMARB_IN!F32+INTMARB_EX!F32 -> 0 | G32: =INTMARB_IN!G32+INTMARB_EX!G32 -> 0 | H32: =INTMARB_IN!H32+INTMARB_EX!H32 -> 0 | I32: =INTMARB_IN!I32+INTMARB_EX!I32 -> 0 | J32: =INTMARB_IN!J32+INTMARB_EX!J32 -> 0 | ... Z32: =INTMARB_IN!Z32+INTMARB_EX!Z32 -> 0
A33: Oil products (excluding biofuel portion) | B33: O4600XBIO | C33: =SUM(C34:C50) -> 5302.0072 | D33: =SUM(D34:D50) -> 5663.6933 | E33: =SUM(E34:E50) -> 6167.7424 | F33: =SUM(F34:F50) -> 6728.1277 | G33: =SUM(G34:G50) -> 7059.5124 | H33: =SUM(H34:H50) -> 7235.3515 | I33: =SUM(I34:I50) -> 7523.0197 | J33: =SUM(J34:J50) -> 7766.7203 | ... Z33: =SUM(Z34:Z50) -> 7279.2246
A34: Refinery gas | B34: O4610 | C34: =INTMARB_IN!C34+INTMARB_EX!C34 -> 0 | D34: =INTMARB_IN!D34+INTMARB_EX!D34 -> 0 | E34: =INTMARB_IN!E34+INTMARB_EX!E34 -> 0 | F34: =INTMARB_IN!F34+INTMARB_EX!F34 -> 0 | G34: =INTMARB_IN!G34+INTMARB_EX!G34 -> 0 | H34: =INTMARB_IN!H34+INTMARB_EX!H34 -> 0 | I34: =INTMARB_IN!I34+INTMARB_EX!I34 -> 0 | J34: =INTMARB_IN!J34+INTMARB_EX!J34 -> 0 | ... Z34: =INTMARB_IN!Z34+INTMARB_EX!Z34 -> 0
A35: Ethane | B35: O4620 | C35: =INTMARB_IN!C35+INTMARB_EX!C35 -> 0 | D35: =INTMARB_IN!D35+INTMARB_EX!D35 -> 0 | E35: =INTMARB_IN!E35+INTMARB_EX!E35 -> 0 | F35: =INTMARB_IN!F35+INTMARB_EX!F35 -> 0 | G35: =INTMARB_IN!G35+INTMARB_EX!G35 -> 0 | H35: =INTMARB_IN!H35+INTMARB_EX!H35 -> 0 | I35: =INTMARB_IN!I35+INTMARB_EX!I35 -> 0 | J35: =INTMARB_IN!J35+INTMARB_EX!J35 -> 0 | ... Z35: =INTMARB_IN!Z35+INTMARB_EX!Z35 -> 0
A36: Liquefied petroleum gases | B36: O4630 | C36: =INTMARB_IN!C36+INTMARB_EX!C36 -> 0 | D36: =INTMARB_IN!D36+INTMARB_EX!D36 -> 0 | E36: =INTMARB_IN!E36+INTMARB_EX!E36 -> 0 | F36: =INTMARB_IN!F36+INTMARB_EX!F36 -> 0 | G36: =INTMARB_IN!G36+INTMARB_EX!G36 -> 0 | H36: =INTMARB_IN!H36+INTMARB_EX!H36 -> 0 | I36: =INTMARB_IN!I36+INTMARB_EX!I36 -> 0 | J36: =INTMARB_IN!J36+INTMARB_EX!J36 -> 0 | ... Z36: =INTMARB_IN!Z36+INTMARB_EX!Z36 -> 0
A37: Motor gasoline (excluding biofuel portion) | B37: O4652XR5210B | C37: =INTMARB_IN!C37+INTMARB_EX!C37 -> 0 | D37: =INTMARB_IN!D37+INTMARB_EX!D37 -> 0 | E37: =INTMARB_IN!E37+INTMARB_EX!E37 -> 0 | F37: =INTMARB_IN!F37+INTMARB_EX!F37 -> 0 | G37: =INTMARB_IN!G37+INTMARB_EX!G37 -> 0 | H37: =INTMARB_IN!H37+INTMARB_EX!H37 -> 0 | I37: =INTMARB_IN!I37+INTMARB_EX!I37 -> 0 | J37: =INTMARB_IN!J37+INTMARB_EX!J37 -> 0 | ... Z37: =INTMARB_IN!Z37+INTMARB_EX!Z37 -> 0
A38: Aviation gasoline | B38: O4651 | C38: =INTMARB_IN!C38+INTMARB_EX!C38 -> 0 | D38: =INTMARB_IN!D38+INTMARB_EX!D38 -> 0 | E38: =INTMARB_IN!E38+INTMARB_EX!E38 -> 0 | F38: =INTMARB_IN!F38+INTMARB_EX!F38 -> 0 | G38: =INTMARB_IN!G38+INTMARB_EX!G38 -> 0 | H38: =INTMARB_IN!H38+INTMARB_EX!H38 -> 0 | I38: =INTMARB_IN!I38+INTMARB_EX!I38 -> 0 | J38: =INTMARB_IN!J38+INTMARB_EX!J38 -> 0 | ... Z38: =INTMARB_IN!Z38+INTMARB_EX!Z38 -> 0
A39: Gasoline-type jet fuel | B39: O4653 | C39: =INTMARB_IN!C39+INTMARB_EX!C39 -> 0 | D39: =INTMARB_IN!D39+INTMARB_EX!D39 -> 0 | E39: =INTMARB_IN!E39+INTMARB_EX!E39 -> 0 | F39: =INTMARB_IN!F39+INTMARB_EX!F39 -> 0 | G39: =INTMARB_IN!G39+INTMARB_EX!G39 -> 0 | H39: =INTMARB_IN!H39+INTMARB_EX!H39 -> 0 | I39: =INTMARB_IN!I39+INTMARB_EX!I39 -> 0 | J39: =INTMARB_IN!J39+INTMARB_EX!J39 -> 0 | ... Z39: =INTMARB_IN!Z39+INTMARB_EX!Z39 -> 0
A40: Kerosene-type jet fuel (excluding biofuel portion) | B40: O4661XR5230B | C40: =INTMARB_IN!C40+INTMARB_EX!C40 -> 0 | D40: =INTMARB_IN!D40+INTMARB_EX!D40 -> 0 | E40: =INTMARB_IN!E40+INTMARB_EX!E40 -> 0 | F40: =INTMARB_IN!F40+INTMARB_EX!F40 -> 0 | G40: =INTMARB_IN!G40+INTMARB_EX!G40 -> 0 | H40: =INTMARB_IN!H40+INTMARB_EX!H40 -> 0 | I40: =INTMARB_IN!I40+INTMARB_EX!I40 -> 0 | J40: =INTMARB_IN!J40+INTMARB_EX!J40 -> 0 | ... Z40: =INTMARB_IN!Z40+INTMARB_EX!Z40 -> 0
...

Sheet INTMARB_IN
A1: International Intra-EEA maritime bunkers | B1: INTMARB_IN | C1: 2000 | D1: 2001 | E1: 2002 | F1: 2003 | G1: 2004 | H1: 2005 | I1: 2006 | J1: 2007 | K1: 2008 | L1: 2009 | M1: 2010 | N1: 2011 | O1: 2012 | P1: 2013 | Q1: 2014 | R1: 2015 | S1: 2016 | T1: 2017 | U1: 2018 | V1: 2019 | W1: 2020 | X1: 2021 | Y1: 2022 | Z1: 2023
