Workbook

Sheet cover
B6: JRC-IDEES-2023 - Integrated Database of the European Energy System
C10: Lithuania
C15: Residential sector
L28: Prepared by JRC C.6
L30: 45967.477
L31: v2023-1.00
B33: Legal Notice
B35: The information made available is property of the Joint Research Centre of the European Commission.
B36: Neither the European Commission nor any person acting on behalf of the Commission is responsible for the use which might be made of this information.
B38: Use conditions
B39: This work is licensed under
B40: CC BY 4.0

Sheet index
A1: LT | B1: Lithuania
B3: Click on the link to jump to the sheet
B4: =HYPERLINK("#"&CELL("address",RES_summary!$B$2),MID(CELL("filename",RES_summary!$B$2),FIND("]",CELL("filename",RES_summary!$B$2))+1,256)) -> RES_summary | D4: Residential sector summary
B6: Thermal uses
B7: =HYPERLINK("#"&CELL("address",RES_hh_num!$B$2),MID(CELL("filename",RES_hh_num!$B$2),FIND("]",CELL("filename",RES_hh_num!$B$2))+1,256)) -> RES_hh_num | D7: Number of households
B8: =HYPERLINK("#"&CELL("address",RES_hh_fec!$B$2),MID(CELL("filename",RES_hh_fec!$B$2),FIND("]",CELL("filename",RES_hh_fec!$B$2))+1,256)) -> RES_hh_fec | D8: Final energy consumption
B9: =HYPERLINK("#"&CELL("address",RES_hh_tes!$B$2),MID(CELL("filename",RES_hh_tes!$B$2),FIND("]",CELL("filename",RES_hh_tes!$B$2))+1,256)) -> RES_hh_tes | D9: Thermal energy service
B10: =HYPERLINK("#"&CELL("address",RES_hh_eff!$B$2),MID(CELL("filename",RES_hh_eff!$B$2),FIND("]",CELL("filename",RES_hh_eff!$B$2))+1,256)) -> RES_hh_eff | D10: System efficiency indicator of total stock
B11: =HYPERLINK("#"&CELL("address",RES_hh_emi!$B$2),MID(CELL("filename",RES_hh_emi!$B$2),FIND("]",CELL("filename",RES_hh_emi!$B$2))+1,256)) -> RES_hh_emi | D11: CO2 emissions
B12: =HYPERLINK("#"&CELL("address",RES_hh_fech!$B$2),MID(CELL("filename",RES_hh_fech!$B$2),FIND("]",CELL("filename",RES_hh_fech!$B$2))+1,256)) -> RES_hh_fech | D12: Final energy consumption per household
B13: =HYPERLINK("#"&CELL("address",RES_hh_tesh!$B$2),MID(CELL("filename",RES_hh_tesh!$B$2),FIND("]",CELL("filename",RES_hh_tesh!$B$2))+1,256)) -> RES_hh_tesh | D13: Thermal energy service per household
B14: =HYPERLINK("#"&CELL("address",RES_hh_emih!$B$2),MID(CELL("filename",RES_hh_emih!$B$2),FIND("]",CELL("filename",RES_hh_emih!$B$2))+1,256)) -> RES_hh_emih | D14: CO2 emissions per household
B15: =HYPERLINK("#"&CELL("address",RES_hh_fecs!$B$2),MID(CELL("filename",RES_hh_fecs!$B$2),FIND("]",CELL("filename",RES_hh_fecs!$B$2))+1,256)) -> RES_hh_fecs | D15: Final energy consumption per surface area
B16: =HYPERLINK("#"&CELL("address",RES_hh_tess!$B$2),MID(CELL("filename",RES_hh_tess!$B$2),FIND("]",CELL("filename",RES_hh_tess!$B$2))+1,256)) -> RES_hh_tess | D16: Thermal energy service per surface area
B17: =HYPERLINK("#"&CELL("address",RES_hh_emis!$B$2),MID(CELL("filename",RES_hh_emis!$B$2),FIND("]",CELL("filename",RES_hh_emis!$B$2))+1,256)) -> RES_hh_emis | D17: CO2 emissions per surface area
B19: Thermal uses in new and renovated households
B20: =HYPERLINK("#"&CELL("address",RES_hh_num_in!$B$2),MID(CELL("filename",RES_hh_num_in!$B$2),FIND("]",CELL("filename",RES_hh_num_in!$B$2))+1,256)) -> RES_hh_num_in | D20: Number of new and renovated households
B21: =HYPERLINK("#"&CELL("address",RES_hh_fec_in!$B$2),MID(CELL("filename",RES_hh_fec_in!$B$2),FIND("]",CELL("filename",RES_hh_fec_in!$B$2))+1,256)) -> RES_hh_fec_in | D21: Final energy consumption
B22: =HYPERLINK("#"&CELL("address",RES_hh_tes_in!$B$2),MID(CELL("filename",RES_hh_tes_in!$B$2),FIND("]",CELL("filename",RES_hh_tes_in!$B$2))+1,256)) -> RES_hh_tes_in | D22: Thermal energy service
B23: =HYPERLINK("#"&CELL("address",RES_hh_eff_in!$B$2),MID(CELL("filename",RES_hh_eff_in!$B$2),FIND("]",CELL("filename",RES_hh_eff_in!$B$2))+1,256)) -> RES_hh_eff_in | D23: System efficiency indicator of total stock
B24: =HYPERLINK("#"&CELL("address",RES_hh_emi_in!$B$2),MID(CELL("filename",RES_hh_emi_in!$B$2),FIND("]",CELL("filename",RES_hh_emi_in!$B$2))+1,256)) -> RES_hh_emi_in | D24: CO2 emissions
B25: =HYPERLINK("#"&CELL("address",RES_hh_fech_in!$B$2),MID(CELL("filename",RES_hh_fech_in!$B$2),FIND("]",CELL("filename",RES_hh_fech_in!$B$2))+1,256)) -> RES_hh_fech_in | D25: Final energy consumption per household
B26: =HYPERLINK("#"&CELL("address",RES_hh_tesh_in!$B$2),MID(CELL("filename",RES_hh_tesh_in!$B$2),FIND("]",CELL("filename",RES_hh_tesh_in!$B$2))+1,256)) -> RES_hh_tesh_in | D26: Thermal energy service per household
B27: =HYPERLINK("#"&CELL("address",RES_hh_emih_in!$B$2),MID(CELL("filename",RES_hh_emih_in!$B$2),FIND("]",CELL("filename",RES_hh_emih_in!$B$2))+1,256)) -> RES_hh_emih_in | D27: CO2 emissions per household
B28: =HYPERLINK("#"&CELL("address",RES_hh_fecs_in!$B$2),MID(CELL("filename",RES_hh_fecs_in!$B$2),FIND("]",CELL("filename",RES_hh_fecs_in!$B$2))+1,256)) -> RES_hh_fecs_in | D28: Final energy consumption per surface area
B29: =HYPERLINK("#"&CELL("address",RES_hh_tess_in!$B$2),MID(CELL("filename",RES_hh_tess_in!$B$2),FIND("]",CELL("filename",RES_hh_tess_in!$B$2))+1,256)) -> RES_hh_tess_in | D29: Thermal energy service per surface area
B30: =HYPERLINK("#"&CELL("address",RES_hh_emis_in!$B$2),MID(CELL("filename",RES_hh_emis_in!$B$2),FIND("]",CELL("filename",RES_hh_emis_in!$B$2))+1,256)) -> RES_hh_emis_in | D30: CO2 emissions per surface area
B32: Specific electric uses
B33: =HYPERLINK("#"&CELL("address",'RES_se-appl'!$B$2),MID(CELL("filename",'RES_se-appl'!$B$2),FIND("]",CELL("filename",'RES_se-appl'!$B$2))+1,256)) -> RES_se-appl | D33: Residential / specific electric uses
B34: =HYPERLINK("#"&CELL("address",RES_RF!$B$2),MID(CELL("filename",RES_RF!$B$2),FIND("]",CELL("filename",RES_RF!$B$2))+1,256)) -> RES_RF | D34: Refrigerators and freezers
B35: =HYPERLINK("#"&CELL("address",RES_WM!$B$2),MID(CELL("filename",RES_WM!$B$2),FIND("]",CELL("filename",RES_WM!$B$2))+1,256)) -> RES_WM | D35: Washing machines
B36: =HYPERLINK("#"&CELL("address",RES_DR!$B$2),MID(CELL("filename",RES_DR!$B$2),FIND("]",CELL("filename",RES_DR!$B$2))+1,256)) -> RES_DR | D36: Clothes dryers
B37: =HYPERLINK("#"&CELL("address",RES_DW!$B$2),MID(CELL("filename",RES_DW!$B$2),FIND("]",CELL("filename",RES_DW!$B$2))+1,256)) -> RES_DW | D37: Dishwashers
B38: =HYPERLINK("#"&CELL("address",RES_TV!$B$2),MID(CELL("filename",RES_TV!$B$2),FIND("]",CELL("filename",RES_TV!$B$2))+1,256)) -> RES_TV | D38: TV and multimedia
B39: =HYPERLINK("#"&CELL("address",RES_IT!$B$2),MID(CELL("filename",RES_IT!$B$2),FIND("]",CELL("filename",RES_IT!$B$2))+1,256)) -> RES_IT | D39: ICT equipment
B40: =HYPERLINK("#"&CELL("address",RES_LI!$B$2),MID(CELL("filename",RES_LI!$B$2),FIND("]",CELL("filename",RES_LI!$B$2))+1,256)) -> RES_LI | D40: Lighting
B41: =HYPERLINK("#"&CELL("address",RES_OA!$B$2),MID(CELL("filename",RES_OA!$B$2),FIND("]",CELL("filename",RES_OA!$B$2))+1,256)) -> RES_OA | D41: Other appliances (vacuum cleaners, irons etc.)
B43: Number of households - detailed structure
B44: =HYPERLINK("#"&CELL("address",RES_hhdet_num!$B$2),MID(CELL("filename",RES_hhdet_num!$B$2),FIND("]",CELL("filename",RES_hhdet_num!$B$2))+1,256)) -> RES_hhdet_num | D44: Number of households
B45: =HYPERLINK("#"&CELL("address",RES_hhdet_out!$B$2),MID(CELL("filename",RES_hhdet_out!$B$2),FIND("]",CELL("filename",RES_hhdet_out!$B$2))+1,256)) -> RES_hhdet_out | D45: Retired equipment
...

Sheet RES_summary
A1: LT - Residential sector summary | B1: 2000 | C1: 2001 | D1: 2002 | E1: 2003 | F1: 2004 | G1: 2005 | H1: 2006 | I1: 2007 | J1: 2008 | K1: 2009 | L1: 2010 | M1: 2011 | N1: 2012 | O1: 2013 | P1: 2014 | Q1: 2015 | R1: 2016 | S1: 2017 | T1: 2018 | U1: 2019 | V1: 2020 | W1: 2021 | X1: 2022 | Y1: 2023 | DA1: Code
A3: Household consumption expenditure (M€2023) | B3: 18688.775 | C3: 19469.29 | D3: 20644.071 | E3: 22988.243 | F3: 25489.213 | G3: 28458.99 | H3: 31070.659 | I3: 34959.577 | J3: 36318.928 | K3: 30005.602 | L3: 28705.116 | M3: 29833.491 | N3: 30723.726 | O3: 31842.932 | P3: 33133.691 | Q3: 34519.613 | R3: 35826.538 | S3: 36939.538 | T3: 38251.064 | U3: 39329.726 | V3: 38077.778 | W3: 41147.431 | X3: 41966.651 | Y3: 41822.7 | DA3: Macro.Meuro2015.LT.ConsumptionExpenditure
A4: Population (inhabitants) | B4: 3512074 | C4: 3486998 | D4: 3454637 | E4: 3431497 | F4: 3398929 | G4: 3355220 | H4: 3289835 | I4: 3249983 | J4: 3212605 | K4: 3183856 | L4: 3141976 | M4: 3052588 | N4: 3003641 | O4: 2974637 | P4: 2947862 | Q4: 2926644 | R4: 2895573 | S4: 2859077 | T4: 2826200 | U4: 2812200 | V4: 2809977 | W4: 2810761 | X4: 2805998 | Y4: 2857279 | DA4: Macro.number.LT.Population
A6: Number of households | B6: 1369971 | C6: 1365154 | D6: 1357439 | E6: 1353304 | F6: 1345406 | G6: 1333023 | H6: 1293683 | I6: 1274503 | J6: 1310198 | K6: 1297415 | L6: 1315735 | M6: 1302299 | N6: 1295231 | O6: 1308683 | P6: 1302059 | Q6: 1310047 | R6: 1319168 | S6: 1317547 | T6: 1301197 | U6: 1301944 | V6: 1293728 | W6: 1340372 | X6: 1371120 | Y6: 1398570 | DA6: NUM.number.LT.Res.HH
A7: Total households useful surface area (in thousand sqm) | B7: 82971.546 | C7: 82679.807 | D7: 82183.16 | E7: 82050.123 | F7: 81838.655 | G7: 81753.752 | H7: 79942.489 | I7: 79092.159 | J7: 82072.129 | K7: 81618.685 | L7: 82868.709 | M7: 82175.067 | N7: 82402.985 | O7: 84738.878 | P7: 85320.589 | Q7: 87047.042 | R7: 88881.376 | S7: 89836.36 | T7: 89652.473 | U7: 90354.914 | V7: 90172.842 | W7: 93826.04 | X7: 96252.624 | Y7: 98459.328 | DA7: SurfaceArea.ksqm.LT.Res.HH
A8: Number of new and renovated households | B8: 0 | C8: 32618 | D8: 32504 | E8: 32320 | F8: 32222 | G8: 32033 | H8: 31739 | I8: 30802 | J8: 66040 | K8: 31195 | L8: 49211 | M8: 31327 | N8: 31007 | O8: 44291 | P8: 31159 | Q8: 38989 | R8: 40313 | S8: 31409 | T8: 31370 | U8: 31728 | V8: 30999 | W8: 77447 | X8: 62662 | Y8: 60096 | DA8: NUM.number.LT.Res.HHnew
A9: New and renovated households useful surface area (in thousand sqm) | B9: 0 | C9: 1975.4914 | D9: 1939.1946 | E9: 2074.84 | F9: 2218.3779 | G9: 2605.1278 | H9: 2493.5985 | I9: 2176.8017 | J9: 4817.7987 | K9: 2210.06 | L9: 3120.9199 | M9: 2017.4049 | N9: 2533.9095 | O9: 4203.6407 | P9: 2870.018 | Q9: 3604.0112 | R9: 3723.4609 | S9: 2955.4278 | T9: 2706.2488 | U9: 2578.7877 | V9: 2192.9631 | W9: 5518.7653 | X9: 4359.438 | Y9: 4183.8912 | DA9: SurfaceArea.ksqm.LT.Res.HHnew
A11: Actual heating degree-days | B11: 3566.72 | C11: 4011.72 | D11: 3834.5 | E11: 4085.35 | F11: 4071.09 | G11: 4020.15 | H11: 3892.89 | I11: 3739.7 | J11: 3555.94 | K11: 3949.81 | L11: 4415 | M11: 3767.86 | N11: 4081.27 | O11: 3873.17 | P11: 3729.28 | Q11: 3523.32 | R11: 3829.94 | S11: 3761.5 | T11: 3687.57 | U11: 3391.36 | V11: 3304.68 | W11: 4016.22 | X11: 3772.72 | Y11: 3461.92 | DA11: HDD.Celsius.LT.Actual
A12: Mean heating degree-days over period 2000 - 2020 | B12: =AVERAGE($B11:$V11) -> 3813.9438 | C12: =AVERAGE($B11:$V11) -> 3813.9438 | D12: =AVERAGE($B11:$V11) -> 3813.9438 | E12: =AVERAGE($B11:$V11) -> 3813.9438 | F12: =AVERAGE($B11:$V11) -> 3813.9438 | G12: =AVERAGE($B11:$V11) -> 3813.9438 | H12: =AVERAGE($B11:$V11) -> 3813.9438 | I12: =AVERAGE($B11:$V11) -> 3813.9438 | ... Y12: =AVERAGE($B11:$V11) -> 3813.9438 | DA12: HDD.Celsius.LT.Mean
A13: Relative heating degree-days | B13: =B11/B12 -> 0.93517896 | C13: =C11/C12 -> 1.0518561 | D13: =D11/D12 -> 1.0053897 | E13: =E11/E12 -> 1.0711616 | F13: =F11/F12 -> 1.0674226 | G13: =G11/G12 -> 1.0540664 | H13: =H11/H12 -> 1.0206994 | I13: =I11/I12 -> 0.98053359 | ... Y13: =Y11/Y12 -> 0.90770084 | DA13: HDD.ratio.LT.Relative
A15: Indicators
A17: Households size (inhabitants/household) | B17: =B4/B6 -> 2.5636119 | C17: =C4/C6 -> 2.5542891 | D17: =D4/D6 -> 2.5449667 | E17: =E4/E6 -> 2.5356439 | F17: =F4/F6 -> 2.5263222 | G17: =G4/G6 -> 2.5170008 | H17: =H4/H6 -> 2.5429993 | I17: =I4/I6 -> 2.5500003 | ... Y17: =Y4/Y6 -> 2.0430004
A18: Households useful surface area (in sqm/capita) | B18: =B7*1000/B4 -> 23.624658 | C18: =C7*1000/C4 -> 23.710885 | D18: =D7*1000/D4 -> 23.789232 | E18: =E7*1000/E4 -> 23.910883 | F18: =F7*1000/F4 -> 24.077777 | G18: =G7*1000/G4 -> 24.366137 | H18: =H7*1000/H4 -> 24.299848 | I18: =I7*1000/I4 -> 24.336176 | ... Y18: =Y7*1000/Y4 -> 34.459123
A19: Households useful surface area (in sqm/household) | B19: =B7*1000/B6 -> 60.564454 | C19: =C7*1000/C6 -> 60.564454 | D19: =D7*1000/D6 -> 60.542802 | E19: =E7*1000/E6 -> 60.629484 | F19: =F7*1000/F6 -> 60.828222 | G19: =G7*1000/G6 -> 61.329588 | H19: =H7*1000/H6 -> 61.794496 | I19: =I7*1000/I6 -> 62.057256 | ... Y19: =Y7*1000/Y6 -> 70.4
A20: New and renovated households useful surface area (in sqm/capita) | B20: =IF(SUM(B21)=0,"",B21/B17) | C20: =IF(SUM(C21)=0,"",C21/C17) -> 23.710885 | D20: =IF(SUM(D21)=0,"",D21/D17) -> 23.442422 | E20: =IF(SUM(E21)=0,"",E21/E17) -> 25.317743 | F20: =IF(SUM(F21)=0,"",F21/F17) -> 27.251745 | G20: =IF(SUM(G21)=0,"",G21/G17) -> 32.310826 | H20: =IF(SUM(H21)=0,"",H21/H17) -> 30.894918 | I20: =IF(SUM(I21)=0,"",I21/I17) -> 27.714033 | ... Y20: =IF(SUM(Y21)=0,"",Y21/Y17) -> 34.077394
A21: New and renovated households useful surface area (in sqm/household) | B21: =IF(SUM(B9)=0,"",B9*1000/B8) | C21: =IF(SUM(C9)=0,"",C9*1000/C8) -> 60.564454 | D21: =IF(SUM(D9)=0,"",D9*1000/D8) -> 59.660182 | E21: =IF(SUM(E9)=0,"",E9*1000/E8) -> 64.196781 | F21: =IF(SUM(F9)=0,"",F9*1000/F8) -> 68.846687 | G21: =IF(SUM(G9)=0,"",G9*1000/G8) -> 81.326377 | H21: =IF(SUM(H9)=0,"",H9*1000/H8) -> 78.565756 | I21: =IF(SUM(I9)=0,"",I9*1000/I8) -> 70.670791 | ... Y21: =IF(SUM(Y9)=0,"",Y9*1000/Y8) -> 69.620127
A22: Household consumption expenditure per capita (€2023) | B22: =B3*1000000/B4 -> 5321.2932 | C22: =C3*1000000/C4 -> 5583.3957 | D22: =D3*1000000/D4 -> 5975.757 | E22: =E3*1000000/E4 -> 6699.1879 | F22: =F3*1000000/F4 -> 7499.1896 | G22: =G3*1000000/G4 -> 8482.0041 | H22: =H3*1000000/H4 -> 9444.4431 | I22: =I3*1000000/I4 -> 10756.849 | ... Y22: =Y3*1000000/Y4 -> 14637.248
A23: Household consumption expenditure per household (€2023) | B23: =B3*1000000/B6 -> 13641.731 | C23: =C3*1000000/C6 -> 14261.607 | D23: =D3*1000000/D6 -> 15208.102 | E23: =E3*1000000/E6 -> 16986.755 | F23: =F3*1000000/F6 -> 18945.369 | G23: =G3*1000000/G6 -> 21349.211 | H23: =H3*1000000/H6 -> 24017.212 | I23: =I3*1000000/I6 -> 27429.968 | ... Y23: =Y3*1000000/Y6 -> 29903.902
A24: Consumption expenditure per household relative to the EU average | B24: 0.33872091 | C24: 0.34968565 | D24: 0.37036582 | E24: 0.41097614 | F24: 0.4528549 | G24: 0.50229068 | H24: 0.55654106 | I24: 0.62680479 | J24: 0.63740582 | K24: 0.54142683 | L24: 0.50939425 | M24: 0.53440486 | N24: 0.5624855 | O24: 0.58309842 | P24: 0.60727797 | Q24: 0.61874942 | R24: 0.6272648 | S24: 0.63604304 | T24: 0.65750054 | U24: 0.66891873 | V24: 0.70348411 | W24: 0.70102349 | X24: 0.6704738 | Y24: 0.65839035
A26: Energy consumption
A28: Energy consumption by fuel - Eurostat structure (ktoe) | B28: =SUM(B29:B30,B33:B34,B41:B42) -> 1367.1114 | C28: =SUM(C29:C30,C33:C34,C41:C42) -> 1418.913 | D28: =SUM(D29:D30,D33:D34,D41:D42) -> 1441.7541 | E28: =SUM(E29:E30,E33:E34,E41:E42) -> 1466.2307 | F28: =SUM(F29:F30,F33:F34,F41:F42) -> 1478.962 | G28: =SUM(G29:G30,G33:G34,G41:G42) -> 1507.7003 | H28: =SUM(H29:H30,H33:H34,H41:H42) -> 1570.1086 | I28: =SUM(I29:I30,I33:I34,I41:I42) -> 1504.68 | ... Y28: =SUM(Y29:Y30,Y33:Y34,Y41:Y42) -> 1531.8763 | DA28: FEC.ktoe.LT.ES.Res
A29: Solids | B29: 21.982459 | C29: 21.927257 | D29: 28.563027 | E29: 33.667412 | F29: 31.250645 | G29: 35.939123 | H29: 46.637661 | I29: 49.789166 | J29: 51.762597 | K29: 48.1773 | L29: 63.84196 | M29: 66.012124 | N29: 65.25804 | O29: 67.800172 | P29: 57.449183 | Q29: 46.439295 | R29: 50.685125 | S29: 57.363543 | T29: 59.114961 | U29: 46.065778 | V29: 34.930525 | W29: 42.523216 | X29: 39.841445 | Y29: 21.417283 | DA29: FEC.ktoe.LT.ES.Res.Solids
A30: Liquids | B30: =SUM(B31:B32) -> 78.787188 | C30: =SUM(C31:C32) -> 77.677472 | D30: =SUM(D31:D32) -> 75.458126 | E30: =SUM(E31:E32) -> 73.238779 | F30: =SUM(F31:F32) -> 64.361307 | G30: =SUM(G31:G32) -> 64.273431 | H30: =SUM(H31:H32) -> 56.505675 | I30: =SUM(I31:I32) -> 39.833964 | ... Y30: =SUM(Y31:Y32) -> 82.715735
A31: Liquified petroleum gas (LPG) | B31: 78.787188 | C31: 77.677472 | D31: 75.458126 | E31: 73.238779 | F31: 64.361307 | G31: 63.251677 | H31: 55.483921 | I31: 38.805245 | J31: 36.587876 | K31: 36.587876 | L31: 39.914015 | M31: 45.45761 | N31: 46.56638 | O31: 39.914015 | P31: 36.58779 | Q31: 31.688908 | R31: 34.966982 | S31: 37.51307 | T31: 35.6227 | U31: 38.791574 | V31: 32.700946 | W31: 27.560619 | X31: 31.4227 | Y31: 53.301462 | DA31: FEC.ktoe.LT.ES.Res.LPG
A32: Diesel oil and other liquids (without biofuels) | B32: 0 | C32: 0 | D32: 0 | E32: 0 | F32: 0 | G32: 1.0217541 | H32: 1.0217541 | I32: 1.0287188 | J32: 2.0574377 | K32: 3.0861565 | L32: 7.2009458 | M32: 8.2296647 | N32: 12.34454 | O32: 10.287102 | P32: 11.315821 | Q32: 9.2132416 | R32: 14.331728 | S32: 19.040671 | T32: 22.214187 | U32: 21.292863 | V32: 22.035082 | W32: 25.51969 | X32: 30.234222 | Y32: 29.414273 | DA32: FEC.ktoe.LT.ES.Res.Oil
A33: Natural gas | B33: 104.04127 | C33: 107.48065 | D33: 110.14617 | E33: 117.49785 | F33: 127.02064 | G33: 134.4583 | H33: 140.04729 | I33: 147.2055 | J33: 145.80825 | K33: 145.09888 | L33: 158.38349 | M33: 144.77644 | N33: 135.42562 | O33: 123.17283 | P33: 119.9914 | Q33: 122.67842 | R33: 145.46432 | S33: 153.7853 | T33: 164.72373 | U33: 160.85873 | V33: 174.37463 | W33: 219.90525 | X33: 197.52966 | Y33: 180.90545 | DA33: FEC.ktoe.LT.ES.Res.NG
A34: Renewable energies and wastes | B34: =SUM(B35:B40) -> 526.6313 | C34: =SUM(C35:C40) -> 538.33474 | D34: =SUM(D35:D40) -> 528.08831 | E34: =SUM(E35:E40) -> 532.88908 | F34: =SUM(F35:F40) -> 541.79802 | G34: =SUM(G35:G40) -> 555.57945 | H34: =SUM(H35:H40) -> 574.16165 | I34: =SUM(I35:I40) -> 552.30722 | ... Y34: =SUM(Y35:Y40) -> 524.08346
A35: Biomass and waste | B35: 526.6313 | C35: 538.33474 | D35: 528.08831 | E35: 532.88908 | F35: 541.79802 | G35: 555.57945 | H35: 574.16165 | I35: 552.30722 | J35: 573.06294 | K35: 584.1454 | L35: 573.80335 | M35: 558.15899 | N35: 560.49966 | O35: 539.67231 | P35: 508.28796 | Q35: 490.66113 | R35: 483.90181 | S35: 470.192 | T35: 479.6742 | U35: 461.37859 | V35: 460.25606 | W35: 462.23844 | X35: 440.67068 | Y35: 421.0853 | DA35: FEC.ktoe.LT.ES.Res.Biomass_Waste
A36: Biogas | B36: 0 | C36: 0 | D36: 0 | E36: 0 | F36: 0 | G36: 0 | H36: 0 | I36: 0 | J36: 0 | K36: 0 | L36: 0 | M36: 0 | N36: 0 | O36: 0 | P36: 0 | Q36: 0 | R36: 0 | S36: 0 | T36: 0 | U36: 0 | V36: 0 | W36: 0 | X36: 0 | Y36: 0.86772045 | DA36: FEC.ktoe.LT.ES.Res.Biogas
A37: Liquid biofuels | B37: 0 | C37: 0 | D37: 0 | E37: 0 | F37: 0 | G37: 0 | H37: 0 | I37: 0 | J37: 0 | K37: 0 | L37: 0 | M37: 0 | N37: 0 | O37: 0 | P37: 0 | Q37: 0 | R37: 0 | S37: 0 | T37: 0 | U37: 0 | V37: 0 | W37: 0 | X37: 0 | Y37: 0 | DA37: FEC.ktoe.LT.ES.Res.LiqBio
A38: Solar | B38: 0 | C38: 0 | D38: 0 | E38: 0 | F38: 0 | G38: 0 | H38: 0 | I38: 0 | J38: 0 | K38: 0 | L38: 0 | M38: 0 | N38: 0 | O38: 0 | P38: 0 | Q38: 0 | R38: 0 | S38: 0 | T38: 0 | U38: 0 | V38: 0 | W38: 0 | X38: 0 | Y38: 0 | DA38: FEC.ktoe.LT.ES.Res.Solar
A39: Geothermal | B39: 0 | C39: 0 | D39: 0 | E39: 0 | F39: 0 | G39: 0 | H39: 0 | I39: 0 | J39: 0 | K39: 0 | L39: 0 | M39: 0 | N39: 0 | O39: 0 | P39: 0 | Q39: 0 | R39: 0 | S39: 0 | T39: 0 | U39: 0 | V39: 0 | W39: 0 | X39: 0 | Y39: 0 | DA39: FEC.ktoe.LT.ES.Res.Geo
A40: Ambient heat | B40: 0 | C40: 0 | D40: 0 | E40: 0 | F40: 0 | G40: 0 | H40: 0 | I40: 0 | J40: 0 | K40: 0 | L40: 0 | M40: 0 | N40: 0 | O40: 1.3215731 | P40: 2.2258453 | Q40: 3.9766155 | R40: 7.5104683 | S40: 15.003649 | T40: 22.284351 | U40: 23.383061 | V40: 27.80172 | W40: 58.469475 | X40: 78.580224 | Y40: 102.13044 | DA40: FEC.ktoe.LT.ES.Res.Ambient
A41: Distributed heat | B41: 483.73457 | C41: 517.173 | D41: 543.78048 | E41: 544.01926 | F41: 534.82373 | G41: 531.5515 | H41: 548.62906 | I41: 501.52863 | J41: 507.78641 | K41: 517.24471 | L41: 527.37171 | M41: 485.57369 | N41: 487.53224 | O41: 464.67472 | P41: 440.00189 | Q41: 429.73156 | R41: 466.3466 | S41: 474.80172 | T41: 472.03113 | U41: 445.6626 | V41: 420.32098 | W41: 501.12261 | X41: 457.62872 | Y41: 452.13525 | DA41: FEC.ktoe.LT.ES.Res.Steam_Distr
A42: Electricity | B42: 151.93465 | C42: 156.31986 | D42: 155.71797 | E42: 164.91831 | F42: 179.70765 | G42: 185.89854 | H42: 204.12726 | I42: 214.01548 | J42: 234.73775 | K42: 234.30782 | L42: 222.69991 | M42: 225.10748 | N42: 227.17111 | O42: 222.7859 | P42: 228.37489 | Q42: 228.71883 | R42: 238.60705 | S42: 243.98968 | T42: 256.62081 | U42: 250.44712 | V42: 261.75408 | W42: 293.21582 | X42: 282.81169 | Y42: 270.61909 | DA42: FEC.ktoe.LT.ES.Res.Elec
A44: Energy consumption by end-uses (ktoe) | B44: =SUM(B45,B50) -> 1367.1114 | C44: =SUM(C45,C50) -> 1418.913 | D44: =SUM(D45,D50) -> 1441.7541 | E44: =SUM(E45,E50) -> 1466.2307 | F44: =SUM(F45,F50) -> 1478.962 | G44: =SUM(G45,G50) -> 1507.7003 | H44: =SUM(H45,H50) -> 1570.1086 | I44: =SUM(I45,I50) -> 1504.68 | ... Y44: =SUM(Y45,Y50) -> 1429.7458 | DA44: FEC.ktoe.LT.Res.HH
A45: Thermal uses | B45: =SUM(B46:B49) -> 1230.3048 | C45: =SUM(C46:C49) -> 1279.4047 | D45: =SUM(D46:D49) -> 1299.7692 | E45: =SUM(E46:E49) -> 1319.3491 | F45: =SUM(F46:F49) -> 1328.495 | G45: =SUM(G46:G49) -> 1354.1333 | H45: =SUM(H46:H49) -> 1415.0082 | I45: =SUM(I46:I49) -> 1348.2486 | ... Y45: =SUM(Y46:Y49) -> 1237.5924 | DA45: FEC.ktoe.LT.Res.HH.Thermal
A46: Space heating (without ambient heat) | B46: 1082.1876 | C46: 1129.3752 | D46: 1158.2728 | E46: 1171.714 | F46: 1171.8469 | G46: 1195.5709 | H46: 1245.6325 | I46: 1190.6129 | J46: 1215.9401 | K46: 1233.6358 | L46: 1269.1396 | M46: 1199.4171 | N46: 1199.7868 | O46: 1145.2745 | P46: 1079.21 | Q46: 1047.8706 | R46: 1109.4144 | S46: 1129.482 | T46: 1146.9476 | U46: 1087.2581 | V46: 1073.7845 | W46: 1181.9622 | X46: 1104.6561 | Y46: 1076.5543 | DA46: FEC.ktoe.LT.Res.HH.Thermal.SH
A47: Cooling | B47: 0.001141309 | C47: 0.0013836495 | D47: 0.0018870592 | E47: 0.0031938935 | F47: 0.0057012816 | G47: 0.010309815 | H47: 0.03312332 | I47: 0.018276916 | J47: 0.018145073 | K47: 0.022971355 | L47: 0.19619309 | M47: 0.025320899 | N47: 0.076057011 | O47: 0.041686415 | P47: 0.09883377 | Q47: 0.069077735 | R47: 0.049556293 | S47: 0.0456924 | T47: 0.076889076 | U47: 0.063131721 | V47: 0.041112518 | W47: 0.14091814 | X47: 0.10243956 | Y47: 0.089710774 | DA47: FEC.ktoe.LT.Res.HH.Thermal.SC
A48: Water heating | B48: 55.489588 | C48: 58.276559 | D48: 54.275107 | E48: 58.628791 | F48: 68.134681 | G48: 70.290682 | H48: 77.139119 | I48: 71.485342 | J48: 79.295034 | K48: 80.196243 | L48: 75.586787 | M48: 78.76889 | N48: 80.399683 | O48: 75.790693 | P48: 78.597024 | Q48: 77.442024 | R48: 82.09629 | S48: 82.257343 | T48: 80.371308 | U48: 75.204059 | V48: 71.90737 | W48: 114.5122 | X48: 104.26096 | Y48: 75.425487 | DA48: FEC.ktoe.LT.Res.HH.Thermal.WH
...

Sheet RES_hh_num
A1: LT - Number of households | B1: 2000 | C1: 2001 | D1: 2002 | E1: 2003 | F1: 2004 | G1: 2005 | H1: 2006 | I1: 2007 | J1: 2008 | K1: 2009 | L1: 2010 | M1: 2011 | N1: 2012 | O1: 2013 | P1: 2014 | Q1: 2015 | R1: 2016 | S1: 2017 | T1: 2018 | U1: 2019 | V1: 2020 | W1: 2021 | X1: 2022 | Y1: 2023 | DA1: Code
A3: Stock of households | B3: =B4 -> 1369971 | C3: =C4 -> 1365154 | D3: =D4 -> 1357439 | E3: =E4 -> 1353304 | F3: =F4 -> 1345406 | G3: =G4 -> 1333023 | H3: =H4 -> 1293683 | I3: =I4 -> 1274503 | ... Y3: =Y4 -> 1398570 | DA3: NUM.number.LT.Res.HH.Thermal
A4: Space heating | B4: =SUM(B5:B13) -> 1369971 | C4: =SUM(C5:C13) -> 1365154 | D4: =SUM(D5:D13) -> 1357439 | E4: =SUM(E5:E13) -> 1353304 | F4: =SUM(F5:F13) -> 1345406 | G4: =SUM(G5:G13) -> 1333023 | H4: =SUM(H5:H13) -> 1293683 | I4: =SUM(I5:I13) -> 1274503 | ... Y4: =SUM(Y5:Y13) -> 1398570 | DA4: NUM.number.LT.Res.HH.Thermal.SH
A5: Solids | B5: 26676 | C5: 27774 | D5: 31862 | E5: 34992 | F5: 37199 | G5: 40887 | H5: 45773 | I5: 49458 | J5: 52206 | K5: 54067 | L5: 59379 | M5: 63374 | N5: 64904 | O5: 64202 | P5: 59789 | Q5: 55187 | R5: 53725 | S5: 53802 | T5: 51634 | U5: 45879 | V5: 39820 | W5: 35935 | X5: 33160 | Y5: 26150 | DA5: NUM.number.LT.Res.HH.Thermal.SH.Solids
A6: Liquified petroleum gas (LPG) | B6: 6621 | C6: 6488 | D6: 6198 | E6: 5845 | F6: 5344 | G6: 4821 | H6: 4219 | I6: 3623 | J6: 3522 | K6: 3438 | L6: 3348 | M6: 3271 | N6: 3301 | O6: 3126 | P6: 2866 | Q6: 2624 | R6: 2464 | S6: 2319 | T6: 2058 | U6: 1941 | V6: 1797 | W6: 1830 | X6: 1905 | Y6: 2488 | DA6: NUM.number.LT.Res.HH.Thermal.SH.LPG
A7: Diesel oil | B7: 0 | C7: 0 | D7: 0 | E7: 0 | F7: 0 | G7: 685 | H7: 955 | I7: 1327 | J7: 2231 | K7: 3593 | L7: 5861 | M7: 7672 | N7: 9019 | O7: 9894 | P7: 10697 | Q7: 11556 | R7: 14378 | S7: 17416 | T7: 19880 | U7: 21095 | V7: 22408 | W7: 24003 | X7: 26965 | Y7: 28511 | DA7: NUM.number.LT.Res.HH.Thermal.SH.Oil
A8: Natural gas | B8: 99648 | C8: 98914 | D8: 100801 | E8: 104452 | F8: 108745 | G8: 112377 | H8: 114004 | I8: 116735 | J8: 117744 | K8: 118183 | L8: 118844 | M8: 115392 | N8: 110905 | O8: 108525 | P8: 111948 | Q8: 120406 | R8: 132043 | S8: 141720 | T8: 151042 | U8: 161698 | V8: 174622 | W8: 185411 | X8: 189166 | Y8: 182928 | DA8: NUM.number.LT.Res.HH.Thermal.SH.Gas
A9: Biomass | B9: 476744 | C9: 466685 | D9: 456920 | E9: 455659 | F9: 459606 | G9: 463870 | H9: 466550 | I9: 468449 | J9: 490066 | K9: 493257 | L9: 507100 | M9: 506488 | N9: 514540 | O9: 520290 | P9: 517875 | Q9: 508934 | R9: 488039 | S9: 467565 | T9: 454916 | U9: 446943 | V9: 428855 | W9: 423215 | X9: 406513 | Y9: 405054 | DA9: NUM.number.LT.Res.HH.Thermal.SH.Biomass
A10: Geothermal | B10: 0 | C10: 0 | D10: 0 | E10: 0 | F10: 0 | G10: 0 | H10: 0 | I10: 0 | J10: 0 | K10: 0 | L10: 0 | M10: 0 | N10: 0 | O10: 0 | P10: 0 | Q10: 0 | R10: 0 | S10: 0 | T10: 0 | U10: 0 | V10: 0 | W10: 0 | X10: 0 | Y10: 0 | DA10: NUM.number.LT.Res.HH.Thermal.SH.Geo
A11: Distributed heat | B11: 758701 | C11: 763680 | D11: 759953 | E11: 750396 | F11: 731863 | G11: 706272 | H11: 655800 | I11: 626069 | J11: 633387 | K11: 612543 | L11: 607948 | M11: 592044 | N11: 577357 | O11: 581611 | P11: 571904 | Q11: 577135 | R11: 585192 | S11: 579269 | T11: 555219 | U11: 544427 | V11: 526254 | W11: 534178 | X11: 539483 | Y11: 549738 | DA11: NUM.number.LT.Res.HH.Thermal.SH.DistrHeat
A12: Advanced electric heating | B12: 0 | C12: 0 | D12: 0 | E12: 0 | F12: 0 | G12: 0 | H12: 0 | I12: 0 | J12: 0 | K12: 0 | L12: 0 | M12: 0 | N12: 0 | O12: 3792 | P12: 7357 | Q12: 13539 | R12: 22899 | S12: 35134 | T12: 46869 | U12: 60218 | V12: 81359 | W12: 118867 | X12: 163625 | Y12: 194829 | DA12: NUM.number.LT.Res.HH.Thermal.SH.AdvElc
A13: Conventional electric heating | B13: 1581 | C13: 1613 | D13: 1705 | E13: 1960 | F13: 2649 | G13: 4111 | H13: 6382 | I13: 8842 | J13: 11042 | K13: 12334 | L13: 13255 | M13: 14058 | N13: 15205 | O13: 17243 | P13: 19623 | Q13: 20666 | R13: 20428 | S13: 20322 | T13: 19579 | U13: 19743 | V13: 18613 | W13: 16933 | X13: 10303 | Y13: 8872 | DA13: NUM.number.LT.Res.HH.Thermal.SH.ConvElc
A14: Circulation | B14: =SUM(B5:B11) -> 1368390 | C14: =SUM(C5:C11) -> 1363541 | D14: =SUM(D5:D11) -> 1355734 | E14: =SUM(E5:E11) -> 1351344 | F14: =SUM(F5:F11) -> 1342757 | G14: =SUM(G5:G11) -> 1328912 | H14: =SUM(H5:H11) -> 1287301 | I14: =SUM(I5:I11) -> 1265661 | ... Y14: =SUM(Y5:Y11) -> 1194869
A15: Space cooling | B15: =B16 -> 205 | C15: =C16 -> 192 | D15: =D16 -> 196 | E15: =E16 -> 642 | F15: =F16 -> 1237 | G15: =G16 -> 2292 | H15: =H16 -> 3531 | I15: =I16 -> 5443 | ... Y15: =Y16 -> 26853 | DA15: NUM.number.LT.Res.HH.Thermal.SC
A16: Air conditioning | B16: 205 | C16: 192 | D16: 196 | E16: 642 | F16: 1237 | G16: 2292 | H16: 3531 | I16: 5443 | J16: 7648 | K16: 9740 | L16: 11824 | M16: 12902 | N16: 14504 | O16: 15614 | P16: 17302 | Q16: 18476 | R16: 19942 | S16: 21060 | T16: 21959 | U16: 22680 | V16: 23728 | W16: 25196 | X16: 26676 | Y16: 26853 | DA16: NUM.number.LT.Res.HH.Thermal.SC.AC
A17: Water heating | B17: =SUM(B18:B25) -> 1369971 | C17: =SUM(C18:C25) -> 1365154 | D17: =SUM(D18:D25) -> 1357439 | E17: =SUM(E18:E25) -> 1353304 | F17: =SUM(F18:F25) -> 1345406 | G17: =SUM(G18:G25) -> 1333023 | H17: =SUM(H18:H25) -> 1293683 | I17: =SUM(I18:I25) -> 1274503 | ... Y17: =SUM(Y18:Y25) -> 1398570 | DA17: NUM.number.LT.Res.HH.Thermal.WH
A18: Solids | B18: 24398 | C18: 25506 | D18: 29235 | E18: 31028 | F18: 30552 | G18: 31788 | H18: 33984 | I18: 36927 | J18: 38879 | K18: 41298 | L18: 44806 | M18: 45635 | N18: 47196 | O18: 47149 | P18: 46636 | Q18: 45440 | R18: 44343 | S18: 44778 | T18: 42720 | U18: 38377 | V18: 33188 | W18: 29436 | X18: 26612 | Y18: 21410 | DA18: NUM.number.LT.Res.HH.Thermal.WH.Solids
A19: Liquified petroleum gas (LPG) | B19: 4354 | C19: 4287 | D19: 4127 | E19: 3785 | F19: 3251 | G19: 2791 | H19: 2284 | I19: 1902 | J19: 1664 | K19: 1642 | L19: 1761 | M19: 1853 | N19: 1841 | O19: 1738 | P19: 1598 | Q19: 1490 | R19: 1567 | S19: 1698 | T19: 1840 | U19: 2053 | V19: 2482 | W19: 4055 | X19: 6238 | Y19: 10226 | DA19: NUM.number.LT.Res.HH.Thermal.WH.LPG
A20: Diesel oil | B20: 0 | C20: 0 | D20: 0 | E20: 0 | F20: 0 | G20: 663 | H20: 926 | I20: 1289 | J20: 2171 | K20: 3502 | L20: 5715 | M20: 7482 | N20: 8786 | O20: 9655 | P20: 10441 | Q20: 11285 | R20: 14044 | S20: 17002 | T20: 19396 | U20: 20557 | V20: 21803 | W20: 23322 | X20: 26160 | Y20: 27678 | DA20: NUM.number.LT.Res.HH.Thermal.WH.Oil
A21: Natural gas | B21: 96236 | C21: 95554 | D21: 97439 | E21: 101037 | F21: 105252 | G21: 108841 | H21: 110473 | I21: 113194 | J21: 114220 | K21: 114705 | L21: 115412 | M21: 112060 | N21: 107672 | O21: 105331 | P21: 108670 | Q21: 116947 | R21: 128354 | S21: 137831 | T21: 146934 | U21: 157278 | V21: 169783 | W21: 180170 | X21: 183645 | Y21: 177715 | DA21: NUM.number.LT.Res.HH.Thermal.WH.Gas
A22: Biomass | B22: 350989 | C22: 345278 | D22: 338172 | E22: 323651 | F22: 300546 | G22: 284992 | H22: 273136 | I22: 280583 | J22: 291112 | K22: 309300 | L22: 328647 | M22: 344804 | N22: 355881 | O22: 365545 | P22: 363341 | Q22: 358377 | R22: 344217 | S22: 334560 | T22: 330143 | U22: 331227 | V22: 335962 | W22: 342959 | X22: 362223 | Y22: 385769 | DA22: NUM.number.LT.Res.HH.Thermal.WH.Biomass
A23: Geothermal | B23: 0 | C23: 0 | D23: 0 | E23: 0 | F23: 0 | G23: 0 | H23: 0 | I23: 0 | J23: 0 | K23: 0 | L23: 0 | M23: 0 | N23: 0 | O23: 0 | P23: 0 | Q23: 0 | R23: 0 | S23: 0 | T23: 0 | U23: 0 | V23: 0 | W23: 0 | X23: 0 | Y23: 0 | DA23: NUM.number.LT.Res.HH.Thermal.WH.Geo
A24: Distributed heat | B24: 741606 | C24: 746695 | D24: 744882 | E24: 737513 | F24: 720757 | G24: 696453 | H24: 645993 | I24: 611294 | J24: 623656 | K24: 608165 | L24: 606820 | M24: 583121 | N24: 567517 | O24: 573047 | P24: 563068 | Q24: 568076 | R24: 576051 | S24: 570330 | T24: 546665 | U24: 536279 | V24: 513713 | W24: 526596 | X24: 531562 | Y24: 542075 | DA24: NUM.number.LT.Res.HH.Thermal.WH.DistrHeat
A25: Electricity | B25: 152388 | C25: 147834 | D25: 143584 | E25: 156290 | F25: 185048 | G25: 207495 | H25: 226887 | I25: 229314 | J25: 238496 | K25: 218803 | L25: 212574 | M25: 207344 | N25: 206338 | O25: 206218 | P25: 208305 | Q25: 208432 | R25: 210592 | S25: 211348 | T25: 213499 | U25: 216173 | V25: 216797 | W25: 233834 | X25: 234680 | Y25: 233697 | DA25: NUM.number.LT.Res.HH.Thermal.WH.Elc
A26: Solar | B26: 0 | C26: 0 | D26: 0 | E26: 0 | F26: 0 | G26: 0 | H26: 0 | I26: 0 | J26: 0 | K26: 0 | L26: 0 | M26: 0 | N26: 0 | O26: 0 | P26: 0 | Q26: 0 | R26: 0 | S26: 0 | T26: 0 | U26: 0 | V26: 0 | W26: 0 | X26: 0 | Y26: 0 | DA26: NUM.number.LT.Res.HH.Thermal.WH.Solar
A27: Cooking | B27: =SUM(B28:B32) -> 1369971 | C27: =SUM(C28:C32) -> 1365154 | D27: =SUM(D28:D32) -> 1357439 | E27: =SUM(E28:E32) -> 1353304 | F27: =SUM(F28:F32) -> 1345406 | G27: =SUM(G28:G32) -> 1333023 | H27: =SUM(H28:H32) -> 1293683 | I27: =SUM(I28:I32) -> 1274503 | ... Y27: =SUM(Y28:Y32) -> 1398570 | DA27: NUM.number.LT.Res.HH.Thermal.CO
A28: Solids | B28: 3196 | C28: 3391 | D28: 3943 | E28: 4315 | F28: 4499 | G28: 4805 | H28: 5170 | I28: 5445 | J28: 5811 | K28: 6316 | L28: 7403 | M28: 8153 | N28: 8724 | O28: 9308 | P28: 9603 | Q28: 9732 | R28: 9882 | S28: 10102 | T28: 9996 | U28: 9082 | V28: 8455 | W28: 7648 | X28: 7144 | Y28: 6511 | DA28: NUM.number.LT.Res.HH.Thermal.CO.Solids
A29: Liquified petroleum gas (LPG) | B29: 1060956 | C29: 1058506 | D29: 1028735 | E29: 976019 | F29: 888442 | G29: 793695 | H29: 639942 | I29: 526964 | J29: 463008 | K29: 464467 | L29: 513150 | M29: 544627 | N29: 553420 | O29: 563792 | P29: 559506 | Q29: 594094 | R29: 610240 | S29: 604481 | T29: 608547 | U29: 577253 | V29: 511841 | W29: 517620 | X29: 548420 | Y29: 682442 | DA29: NUM.number.LT.Res.HH.Thermal.CO.LPG
A30: Natural gas | B30: 96142 | C30: 95443 | D30: 97277 | E30: 100816 | F30: 104974 | G30: 108508 | H30: 110086 | I30: 112739 | J30: 113707 | K30: 114148 | L30: 114819 | M30: 111426 | N30: 107028 | O30: 104704 | P30: 108059 | Q30: 116358 | R30: 127778 | S30: 137290 | T30: 146426 | U30: 156845 | V30: 169475 | W30: 179981 | X30: 183609 | Y30: 177535 | DA30: NUM.number.LT.Res.HH.Thermal.CO.Gas
A31: Biomass | B31: 139980 | C31: 138873 | D31: 136785 | E31: 134617 | F31: 131681 | G31: 127380 | H31: 120895 | I31: 116683 | J31: 117031 | K31: 121052 | L31: 126947 | M31: 129962 | N31: 134569 | O31: 145071 | P31: 158387 | Q31: 176429 | R31: 180946 | S31: 178562 | T31: 161965 | U31: 150966 | V31: 147316 | W31: 148589 | X31: 153893 | Y31: 150896 | DA31: NUM.number.LT.Res.HH.Thermal.CO.Biomass
A32: Electricity | B32: 69697 | C32: 68941 | D32: 90699 | E32: 137537 | F32: 215810 | G32: 298635 | H32: 417590 | I32: 512672 | J32: 610641 | K32: 591432 | L32: 553416 | M32: 508131 | N32: 491490 | O32: 485808 | P32: 466504 | Q32: 413434 | R32: 390322 | S32: 387112 | T32: 374263 | U32: 407798 | V32: 456641 | W32: 486534 | X32: 478054 | Y32: 381186 | DA32: NUM.number.LT.Res.HH.Thermal.CO.Elc

Sheet RES_hh_fec
A1: LT - Final energy consumption | B1: 2000 | C1: 2001 | D1: 2002 | E1: 2003 | F1: 2004 | G1: 2005 | H1: 2006 | I1: 2007 | J1: 2008 | K1: 2009 | L1: 2010 | M1: 2011 | N1: 2012 | O1: 2013 | P1: 2014 | Q1: 2015 | R1: 2016 | S1: 2017 | T1: 2018 | U1: 2019 | V1: 2020 | W1: 2021 | X1: 2022 | Y1: 2023 | DA1: Code
A3: Final energy consumption (ktoe) | B3: =SUM(B4,B15,B17,B27) -> 1230.3048 | C3: =SUM(C4,C15,C17,C27) -> 1279.4047 | D3: =SUM(D4,D15,D17,D27) -> 1299.7692 | E3: =SUM(E4,E15,E17,E27) -> 1319.3491 | F3: =SUM(F4,F15,F17,F27) -> 1328.495 | G3: =SUM(G4,G15,G17,G27) -> 1354.1333 | H3: =SUM(H4,H15,H17,H27) -> 1415.0082 | I3: =SUM(I4,I15,I17,I27) -> 1348.2486 | ... Y3: =SUM(Y4,Y15,Y17,Y27) -> 1237.5924 | DA3: FEC.ktoe.LT.Res.HH.Thermal
A4: Space heating | B4: =SUM(B5:B14) -> 1082.1876 | C4: =SUM(C5:C14) -> 1129.3752 | D4: =SUM(D5:D14) -> 1158.2728 | E4: =SUM(E5:E14) -> 1171.714 | F4: =SUM(F5:F14) -> 1171.8469 | G4: =SUM(G5:G14) -> 1195.5709 | H4: =SUM(H5:H14) -> 1245.6325 | I4: =SUM(I5:I14) -> 1190.6129 | ... Y4: =SUM(Y5:Y14) -> 1076.5543 | DA4: FEC.ktoe.LT.Res.HH.Thermal.SH
A5: Solids | B5: 20.703971 | C5: 20.684542 | D5: 27.007342 | E5: 31.771646 | F5: 29.477744 | G5: 33.937293 | H5: 44.128834 | I5: 47.011317 | J5: 48.827244 | K5: 45.400794 | L5: 60.162565 | M5: 61.902074 | N5: 61.146866 | O5: 63.456583 | P5: 53.529805 | Q5: 43.160992 | R5: 47.119178 | S5: 53.322246 | T5: 55.264097 | U5: 42.962836 | V5: 32.653201 | W5: 39.132106 | X5: 36.753716 | Y5: 19.995828 | DA5: FEC.ktoe.LT.Res.HH.Thermal.SH.Solids.Solids
A6: Liquified petroleum gas (LPG) | B6: 5.8417881 | C6: 5.9682202 | D6: 6.0403898 | E6: 5.8409466 | F6: 5.1499058 | G6: 5.2039633 | H6: 4.687847 | I6: 3.3562478 | J6: 3.0300791 | K6: 3.0684654 | L6: 3.4295243 | M6: 3.5652901 | N6: 3.5764781 | O6: 3.0613981 | P6: 2.6091111 | Q6: 2.1833961 | R6: 2.3802281 | S6: 2.5154581 | T6: 1.8576526 | U6: 1.9669103 | V6: 1.8593007 | W6: 1.8592481 | X6: 1.5327601 | Y6: 2.9490924 | DA6: FEC.ktoe.LT.Res.HH.Thermal.SH.LPG.LPG
A7: Diesel oil | B7: 0 | C7: 0 | D7: 0 | E7: 0 | F7: 0 | G7: 0.96713514 | H7: 0.96424839 | I7: 0.97265316 | J7: 1.9354786 | K7: 2.9029579 | L7: 6.8062521 | M7: 7.7332676 | N7: 11.585219 | O7: 9.6636218 | P7: 10.565013 | Q7: 8.5939887 | R7: 13.370114 | S7: 17.798824 | T7: 20.833671 | U7: 19.992631 | V7: 20.740351 | W7: 23.486094 | X7: 27.961388 | Y7: 27.788935 | DA7: FEC.ktoe.LT.Res.HH.Thermal.SH.Oil.Oil_LiqBio
A8: Natural gas | B8: 92.688369 | C8: 96.043568 | D8: 99.376672 | E8: 105.57601 | F8: 113.12401 | G8: 119.81561 | H8: 124.22188 | I8: 130.71191 | J8: 128.27846 | K8: 128.25407 | L8: 142.05008 | M8: 128.15629 | N8: 119.79662 | O8: 109.54478 | P8: 106.00593 | Q8: 109.18205 | R8: 129.50833 | S8: 137.5891 | T8: 146.52348 | U8: 142.40463 | V8: 155.11397 | W8: 191.74871 | X8: 172.39058 | Y8: 160.76077 | DA8: FEC.ktoe.LT.Res.HH.Thermal.SH.Gas.NG_Biogas
A9: Biomass | B9: 497.04398 | C9: 508.92047 | D9: 500.16493 | E9: 504.1265 | F9: 512.39127 | G9: 526.02765 | H9: 544.63089 | I9: 523.14839 | J9: 542.16119 | K9: 552.28947 | L9: 542.6398 | M9: 525.31349 | N9: 527.07147 | O9: 507.02363 | P9: 475.47614 | Q9: 457.88102 | R9: 451.59879 | S9: 438.68823 | T9: 448.98251 | U9: 431.85724 | V9: 431.71398 | W9: 423.8559 | X9: 401.45218 | Y9: 388.79735 | DA9: FEC.ktoe.LT.Res.HH.Thermal.SH.Biomass.Biomass_Waste
A10: Geothermal | B10: 0 | C10: 0 | D10: 0 | E10: 0 | F10: 0 | G10: 0 | H10: 0 | I10: 0 | J10: 0 | K10: 0 | L10: 0 | M10: 0 | N10: 0 | O10: 0 | P10: 0 | Q10: 0 | R10: 0 | S10: 0 | T10: 0 | U10: 0 | V10: 0 | W10: 0 | X10: 0 | Y10: 0 | DA10: FEC.ktoe.LT.Res.HH.Thermal.SH.Geo.Geo
A11: Distributed heat | B11: 460.29247 | C11: 491.92389 | D11: 519.68737 | E11: 518.24371 | F11: 505.357 | G11: 501.9631 | H11: 516.62623 | I11: 473.28797 | J11: 476.81602 | K11: 485.76416 | L11: 497.77937 | M11: 455.68275 | N11: 456.97304 | O11: 435.9446 | P11: 410.31246 | Q11: 400.40245 | R11: 434.58109 | S11: 443.20523 | T11: 441.9312 | U11: 417.58781 | V11: 394.57906 | W11: 459.26644 | X11: 421.21642 | Y11: 425.48966 | DA11: FEC.ktoe.LT.Res.HH.Thermal.SH.DistrHeat.Steam_Distr
A12: Advanced electric heating | B12: 0 | C12: 0 | D12: 0 | E12: 0 | F12: 0 | G12: 0 | H12: 0 | I12: 0 | J12: 0 | K12: 0 | L12: 0 | M12: 0 | N12: 0 | O12: 0.76495238 | P12: 1.2240642 | Q12: 2.0637617 | R12: 3.6874067 | S12: 7.0273141 | T12: 10.101911 | U12: 10.287744 | V12: 11.812956 | W12: 23.136471 | X12: 29.599544 | Y12: 37.537675 | DA12: FEC.ktoe.LT.Res.HH.Thermal.SH.AdvElc.Elec
A13: Conventional electric heating | B13: 1.078558 | C13: 1.1632424 | D13: 1.2581003 | E13: 1.360256 | F13: 1.5107074 | G13: 2.6748529 | H13: 5.1576609 | I13: 7.0721334 | J13: 9.7046171 | K13: 10.677628 | L13: 10.730582 | M13: 11.774248 | N13: 14.289006 | O13: 10.646626 | P13: 14.651676 | Q13: 19.733036 | R13: 22.143161 | S13: 24.145812 | T13: 15.99504 | U13: 14.901073 | V13: 19.94627 | W13: 13.399809 | X13: 8.0139046 | Y13: 7.7550017 | DA13: FEC.ktoe.LT.Res.HH.Thermal.SH.ConvElc.Elec
A14: Electricity in circulation | B14: 4.538487 | C14: 4.6712991 | D14: 4.7379777 | E14: 4.7948874 | F14: 4.8362889 | G14: 4.9812527 | H14: 5.2148825 | I14: 5.052278 | J14: 5.1870211 | K14: 5.2782479 | L14: 5.5413836 | M14: 5.289666 | N14: 5.348138 | O14: 5.1683277 | P14: 4.8358189 | Q14: 4.6699289 | R14: 5.0261515 | S14: 5.1897324 | T14: 5.4580632 | U14: 5.2972224 | V14: 5.3654218 | W14: 6.077466 | X14: 5.735587 | Y14: 5.4800271 | DA14: FEC.ktoe.LT.Res.HH.Thermal.SH.TotalCirculation.Elec
A15: Space cooling | B15: =B16 -> 0.001141309 | C15: =C16 -> 0.0013836495 | D15: =D16 -> 0.0018870592 | E15: =E16 -> 0.0031938935 | F15: =F16 -> 0.0057012816 | G15: =G16 -> 0.010309815 | H15: =H16 -> 0.03312332 | I15: =I16 -> 0.018276916 | ... Y15: =Y16 -> 0.089710774 | DA15: FEC.ktoe.LT.Res.HH.Thermal.SC
A16: Air conditioning | B16: 0.001141309 | C16: 0.0013836495 | D16: 0.0018870592 | E16: 0.0031938935 | F16: 0.0057012816 | G16: 0.010309815 | H16: 0.03312332 | I16: 0.018276916 | J16: 0.018145073 | K16: 0.022971355 | L16: 0.19619309 | M16: 0.025320899 | N16: 0.076057011 | O16: 0.041686415 | P16: 0.09883377 | Q16: 0.069077735 | R16: 0.049556293 | S16: 0.0456924 | T16: 0.076889076 | U16: 0.063131721 | V16: 0.041112518 | W16: 0.14091814 | X16: 0.10243956 | Y16: 0.089710774 | DA16: FEC.ktoe.LT.Res.HH.Thermal.SC.AC.Elec
A17: Water heating | B17: =SUM(B18:B26) -> 55.489588 | C17: =SUM(C18:C26) -> 58.276559 | D17: =SUM(D18:D26) -> 54.275107 | E17: =SUM(E18:E26) -> 58.628791 | F17: =SUM(F18:F26) -> 68.134681 | G17: =SUM(G18:G26) -> 70.290682 | H17: =SUM(H18:H26) -> 77.139119 | I17: =SUM(I18:I26) -> 71.485342 | ... Y17: =SUM(Y18:Y26) -> 75.425487 | DA17: FEC.ktoe.LT.Res.HH.Thermal.WH
A18: Solids | B18: 1.060461 | C18: 1.0331273 | D18: 1.2940895 | E18: 1.5866359 | F18: 1.487128 | G18: 1.6826526 | H18: 2.1056499 | I18: 2.3592809 | J18: 2.4794576 | K18: 2.3584345 | L18: 3.1399237 | M18: 3.4969349 | N18: 3.4915912 | O18: 3.6996987 | P18: 3.331733 | Q18: 2.7866393 | R18: 3.022129 | S18: 3.4158546 | T18: 3.2013232 | U18: 2.5857934 | V18: 1.897774 | W18: 2.91349 | X18: 2.5807777 | Y18: 1.0583375 | DA18: FEC.ktoe.LT.Res.HH.Thermal.WH.Solids.Solids
A19: Liquified petroleum gas (LPG) | B19: 0.20308004 | C19: 0.20231738 | D19: 0.19870537 | E19: 0.19797083 | F19: 0.17633309 | G19: 0.17511844 | H19: 0.15181599 | I19: 0.11431722 | J19: 0.10443085 | K19: 0.10818374 | L19: 0.12148063 | M19: 0.13669657 | N19: 0.138607 | O19: 0.12114064 | P19: 0.11021673 | Q19: 0.095675835 | R19: 0.10361301 | S19: 0.10936754 | T19: 0.109272 | U19: 0.109272 | V19: 0.10936754 | W19: 0.21873507 | X19: 0.32846088 | Y19: 0.65534537 | DA19: FEC.ktoe.LT.Res.HH.Thermal.WH.LPG.LPG
A20: Diesel oil | B20: 0 | C20: 0 | D20: 0 | E20: 0 | F20: 0 | G20: 0.054618946 | H20: 0.057505692 | I20: 0.056065667 | J20: 0.12195906 | K20: 0.18319857 | L20: 0.39469368 | M20: 0.49639702 | N20: 0.75932054 | O20: 0.62348051 | P20: 0.75080773 | Q20: 0.61925287 | R20: 0.96161426 | S20: 1.2418471 | T20: 1.3805165 | U20: 1.3002321 | V20: 1.294731 | W20: 2.0335968 | X20: 2.2728342 | Y20: 1.6253383 | DA20: FEC.ktoe.LT.Res.HH.Thermal.WH.Oil.Oil_LiqBio
A21: Natural gas | B21: 4.735319 | C21: 4.9484009 | D21: 4.609536 | E21: 5.2289644 | F21: 6.5513962 | G21: 6.9906092 | H21: 7.6294301 | I21: 7.7218407 | J21: 8.2259575 | K21: 8.1844914 | L21: 8.2700411 | M21: 8.2065261 | N21: 7.788214 | O21: 6.9934331 | P21: 7.4434304 | Q21: 7.7787538 | R21: 9.2219897 | S21: 9.5455411 | T21: 9.7111809 | U21: 9.3099923 | V21: 9.7982462 | W21: 16.931221 | X21: 14.437049 | Y21: 9.7551068 | DA21: FEC.ktoe.LT.Res.HH.Thermal.WH.Gas.NG_Biogas
A22: Biomass | B22: 20.014671 | C22: 19.98345 | D22: 19.05856 | E22: 19.792 | F22: 20.322093 | G22: 20.503992 | H22: 20.430479 | I22: 20.640239 | J22: 21.643898 | K22: 22.554839 | L22: 22.264707 | M22: 23.329933 | N22: 23.660901 | O22: 23.239697 | P22: 23.265686 | Q22: 23.240987 | R22: 22.770924 | S22: 22.093245 | T22: 21.591669 | U22: 20.755708 | V22: 20.254132 | W22: 29.593007 | X22: 29.521353 | Y22: 22.5908 | DA22: FEC.ktoe.LT.Res.HH.Thermal.WH.Biomass.Biomass_Waste
A23: Geothermal | B23: 0 | C23: 0 | D23: 0 | E23: 0 | F23: 0 | G23: 0 | H23: 0 | I23: 0 | J23: 0 | K23: 0 | L23: 0 | M23: 0 | N23: 0 | O23: 0 | P23: 0 | Q23: 0 | R23: 0 | S23: 0 | T23: 0 | U23: 0 | V23: 0 | W23: 0 | X23: 0 | Y23: 0 | DA23: FEC.ktoe.LT.Res.HH.Thermal.WH.Geo.Geo
A24: Distributed heat | B24: 23.442094 | C24: 25.249108 | D24: 24.093108 | E24: 25.775551 | F24: 29.466732 | G24: 29.588409 | H24: 32.00283 | I24: 28.240661 | J24: 30.97039 | K24: 31.480547 | L24: 29.592341 | M24: 29.890941 | N24: 30.559208 | O24: 28.73012 | P24: 29.689428 | Q24: 29.329109 | R24: 31.76551 | S24: 31.596487 | T24: 30.09993 | U24: 28.074783 | V24: 25.741924 | W24: 41.856169 | X24: 36.412296 | Y24: 26.645596 | DA24: FEC.ktoe.LT.Res.HH.Thermal.WH.DistrHeat.Steam_Distr
A25: Electricity | B25: 6.0339627 | C25: 6.8601561 | D25: 5.0211077 | E25: 6.0476693 | F25: 10.130998 | G25: 11.295281 | H25: 14.761408 | I25: 12.352938 | J25: 15.748941 | K25: 15.326548 | L25: 11.8036 | M25: 13.211461 | N25: 14.001841 | O25: 12.383123 | P25: 14.005722 | Q25: 13.591606 | R25: 14.25051 | S25: 14.255 | T25: 14.277416 | U25: 13.068278 | V25: 12.811195 | W25: 20.965981 | X25: 18.708186 | Y25: 13.094963 | DA25: FEC.ktoe.LT.Res.HH.Thermal.WH.Elc.Elec
A26: Solar | B26: 0 | C26: 0 | D26: 0 | E26: 0 | F26: 0 | G26: 0 | H26: 0 | I26: 0 | J26: 0 | K26: 0 | L26: 0 | M26: 0 | N26: 0 | O26: 0 | P26: 0 | Q26: 0 | R26: 0 | S26: 0 | T26: 0 | U26: 0 | V26: 0 | W26: 0 | X26: 0 | Y26: 0 | DA26: FEC.ktoe.LT.Res.HH.Thermal.WH.TotalSolar.Solar
A27: Cooking | B27: =SUM(B28:B32) -> 92.626422 | C27: =SUM(C28:C32) -> 91.751543 | D27: =SUM(D28:D32) -> 87.21938 | E27: =SUM(E28:E32) -> 89.003205 | F27: =SUM(F28:F32) -> 88.507682 | G27: =SUM(G28:G32) -> 88.261447 | H27: =SUM(H28:H32) -> 92.20349 | I27: =SUM(I28:I32) -> 86.132126 | ... Y27: =SUM(Y28:Y32) -> 85.522839 | DA27: FEC.ktoe.LT.Res.HH.Thermal.CO
A28: Solids | B28: 0.21802761 | C28: 0.20958767 | D28: 0.26159524 | E28: 0.30913013 | F28: 0.28577321 | G28: 0.31917761 | H28: 0.40317698 | I28: 0.41856803 | J28: 0.45589472 | K28: 0.41807205 | L28: 0.53947184 | M28: 0.61311478 | N28: 0.6195824 | O28: 0.64389012 | P28: 0.58764502 | Q28: 0.49166352 | R28: 0.54381807 | S28: 0.62544186 | T28: 0.64954142 | U28: 0.51714914 | V28: 0.37955001 | W28: 0.47762014 | X28: 0.50695042 | Y28: 0.36311742 | DA28: FEC.ktoe.LT.Res.HH.Thermal.CO.Solids.Solids
A29: Liquified petroleum gas (LPG) | B29: 72.74232 | C29: 71.506934 | D29: 69.21903 | E29: 67.199862 | F29: 59.035068 | G29: 57.872595 | H29: 50.644258 | I29: 35.33468 | J29: 33.453366 | K29: 33.411227 | L29: 36.363011 | M29: 41.755623 | N29: 42.851295 | O29: 36.731477 | P29: 33.868462 | Q29: 29.409836 | R29: 32.483141 | S29: 34.888244 | T29: 33.655775 | U29: 36.715391 | V29: 30.732278 | W29: 25.482636 | X29: 29.561479 | Y29: 49.697024 | DA29: FEC.ktoe.LT.Res.HH.Thermal.CO.LPG.LPG
A30: Natural gas | B30: 6.6175848 | C30: 6.4886848 | D30: 6.159966 | E30: 6.6928739 | F30: 7.3452333 | G30: 7.6520795 | H30: 8.195981 | I30: 8.7717489 | J30: 9.3038418 | K30: 8.6603235 | L30: 8.0633675 | M30: 8.4136269 | N30: 7.8407851 | O30: 6.6346122 | P30: 6.542046 | Q30: 5.7176137 | R30: 6.7340014 | S30: 6.6506508 | T30: 8.4890722 | U30: 9.1441035 | V30: 9.4624195 | W30: 11.225313 | X30: 10.702036 | Y30: 11.257299 | DA30: FEC.ktoe.LT.Res.HH.Thermal.CO.Gas.NG_Biogas
A31: Biomass | B31: 9.5726498 | C31: 9.4308154 | D31: 8.8648173 | E31: 8.9705829 | F31: 9.0846564 | G31: 9.0478065 | H31: 9.1002862 | I31: 8.5185964 | J31: 9.2578531 | K31: 9.3010925 | L31: 8.898844 | M31: 9.5155665 | N31: 9.7672857 | O31: 9.4089852 | P31: 9.5461364 | Q31: 9.5391289 | R31: 9.5320917 | S31: 9.4105283 | T31: 9.1000287 | U31: 8.7656444 | V31: 8.2879526 | W31: 8.789529 | X31: 9.6971434 | Y31: 9.6971434 | DA31: FEC.ktoe.LT.Res.HH.Thermal.CO.Biomass.Biomass_Waste
A32: Electricity | B32: 3.4758396 | C32: 4.1155204 | D32: 2.7139715 | E32: 5.8307566 | F32: 12.756951 | G32: 13.369788 | H32: 23.859788 | I32: 33.088533 | J32: 41.733855 | K32: 38.038239 | L32: 26.240447 | M32: 27.928945 | N32: 27.670195 | O32: 24.923739 | P32: 23.736862 | Q32: 15.796016 | R32: 14.034931 | S32: 8.9357146 | T32: 18.069221 | U32: 17.355337 | V32: 17.376953 | W32: 23.7387 | X32: 21.259908 | Y32: 14.508255 | DA32: FEC.ktoe.LT.Res.HH.Thermal.CO.Elc.Elec

Sheet RES_hh_tes
A1: LT - Thermal energy service | B1: 2000 | C1: 2001 | D1: 2002 | E1: 2003 | F1: 2004 | G1: 2005 | H1: 2006 | I1: 2007 | J1: 2008 | K1: 2009 | L1: 2010 | M1: 2011 | N1: 2012 | O1: 2013 | P1: 2014 | Q1: 2015 | R1: 2016 | S1: 2017 | T1: 2018 | U1: 2019 | V1: 2020 | W1: 2021 | X1: 2022 | Y1: 2023 | DA1: Code
A3: Thermal energy service (ktoe useful) | B3: =SUM(B4,B15,B17,B27) -> 677.15542 | C3: =SUM(C4,C15,C17,C27) -> 711.98547 | D3: =SUM(D4,D15,D17,D27) -> 733.07013 | E3: =SUM(E4,E15,E17,E27) -> 750.25531 | F3: =SUM(F4,F15,F17,F27) -> 761.62497 | G3: =SUM(G4,G15,G17,G27) -> 782.83517 | H3: =SUM(H4,H15,H17,H27) -> 829.66981 | I3: =SUM(I4,I15,I17,I27) -> 798.3606 | ... Y3: =SUM(Y4,Y15,Y17,Y27) -> 1044.7851 | DA3: TES.ktoe.LT.Res.HH.Thermal
A4: Space heating | B4: =SUM(B5:B14) -> 591.47281 | C4: =SUM(C5:C14) -> 624.47121 | D4: =SUM(D5:D14) -> 650.41675 | E4: =SUM(E5:E14) -> 663.03955 | F4: =SUM(F5:F14) -> 667.05733 | G4: =SUM(G5:G14) -> 686.59593 | H4: =SUM(H5:H14) -> 724.27035 | I4: =SUM(I5:I14) -> 698.25986 | ... Y4: =SUM(Y5:Y14) -> 927.65331 | DA4: TES.ktoe.LT.Res.HH.Thermal.SH
A5: Solids | B5: 11.60976 | C5: 11.672792 | D5: 15.41492 | E5: 18.29992 | F5: 17.110032 | G5: 19.891161 | H5: 26.134905 | I5: 28.07506 | J5: 29.381335 | K5: 27.513411 | L5: 36.827823 | M5: 38.24035 | N5: 38.077419 | O5: 39.765824 | P5: 33.591217 | Q5: 27.125253 | R5: 29.721037 | S5: 34.055235 | T5: 35.699462 | U5: 27.892983 | V5: 21.311357 | W5: 25.765486 | X5: 24.616511 | Y5: 13.512442 | DA5: TES.ktoe.LT.Res.HH.Thermal.SH.Solids.Solids
A6: Liquified petroleum gas (LPG) | B6: 2.8228367 | C6: 2.9013919 | D6: 2.9492042 | E6: 2.8632782 | F6: 2.5289679 | G6: 2.5598072 | H6: 2.3104911 | I6: 1.6581849 | J6: 1.5198033 | K6: 1.5762385 | L6: 1.8099671 | M6: 1.9453086 | N6: 2.0426534 | O6: 1.8196186 | P6: 1.5550115 | Q6: 1.3047112 | R6: 1.4274938 | S6: 1.5168522 | T6: 1.1243066 | U6: 1.1924372 | V6: 1.1286426 | W6: 1.1411458 | X6: 0.96264749 | Y6: 1.9521656 | DA6: TES.ktoe.LT.Res.HH.Thermal.SH.LPG.LPG
A7: Diesel oil | B7: 0 | C7: 0 | D7: 0 | E7: 0 | F7: 0 | G7: 0.50829735 | H7: 0.50817657 | I7: 0.51497639 | J7: 1.0343291 | K7: 1.5664565 | L7: 3.7135665 | M7: 4.2607818 | N7: 6.4506086 | O7: 5.4368214 | P7: 6.0230884 | Q7: 4.9766511 | R7: 8.0249732 | S7: 10.990079 | T7: 13.108593 | U7: 12.728687 | V7: 13.368622 | W7: 15.335977 | X7: 18.521169 | Y7: 18.612998 | DA7: TES.ktoe.LT.Res.HH.Thermal.SH.Oil.Oil_LiqBio
A8: Natural gas | B8: 42.27512 | C8: 44.099858 | D8: 46.078884 | E8: 49.547279 | F8: 53.785986 | G8: 57.721756 | H8: 60.565609 | I8: 64.569563 | J8: 64.180041 | K8: 65.035704 | L8: 73.112194 | M8: 66.93447 | N8: 63.724768 | O8: 59.651509 | P8: 58.823274 | Q8: 62.592232 | R8: 77.234621 | S8: 85.234764 | T8: 94.063451 | U8: 94.621679 | V8: 106.41648 | W8: 134.95154 | X8: 123.69809 | Y8: 116.98737 | DA8: TES.ktoe.LT.Res.HH.Thermal.SH.Gas.NG_Biogas
A9: Biomass | B9: 205.4379 | C9: 212.96451 | D9: 212.2788 | E9: 218.31757 | F9: 227.43028 | G9: 239.92597 | H9: 255.48213 | I9: 252.54132 | J9: 271.86773 | K9: 286.02735 | L9: 291.6765 | M9: 292.61248 | N9: 305.98521 | O9: 305.18707 | P9: 287.90559 | Q9: 279.0762 | R9: 277.16901 | S9: 272.13228 | T9: 282.36374 | U9: 276.11505 | V9: 280.12634 | W9: 279.82207 | X9: 269.07942 | Y9: 265.50717 | DA9: TES.ktoe.LT.Res.HH.Thermal.SH.Biomass.Biomass_Waste
A10: Geothermal | B10: 0 | C10: 0 | D10: 0 | E10: 0 | F10: 0 | G10: 0 | H10: 0 | I10: 0 | J10: 0 | K10: 0 | L10: 0 | M10: 0 | N10: 0 | O10: 0 | P10: 0 | Q10: 0 | R10: 0 | S10: 0 | T10: 0 | U10: 0 | V10: 0 | W10: 0 | X10: 0 | Y10: 0 | DA10: TES.ktoe.LT.Res.HH.Thermal.SH.Geo.Geo
A11: Distributed heat | B11: 324.11126 | C11: 347.42655 | D11: 368.1558 | E11: 368.33927 | F11: 360.37287 | G11: 359.21466 | H11: 370.54705 | I11: 340.99617 | J11: 346.47174 | K11: 355.45851 | L11: 367.69388 | M11: 340.04228 | N11: 345.43465 | O11: 334.60178 | P11: 316.10805 | Q11: 310.82869 | R11: 340.85144 | S11: 351.47433 | T11: 353.18854 | U11: 336.98233 | V11: 321.07864 | W11: 378.34272 | X11: 351.25718 | Y11: 360.11017 | DA11: TES.ktoe.LT.Res.HH.Thermal.SH.DistrHeat.Steam_Distr
A12: Advanced electric heating | B12: 0 | C12: 0 | D12: 0 | E12: 0 | F12: 0 | G12: 0 | H12: 0 | I12: 0 | J12: 0 | K12: 0 | L12: 0 | M12: 0 | N12: 0 | O12: 2.0865255 | P12: 3.4499095 | Q12: 6.0403773 | R12: 11.197875 | S12: 22.030963 | T12: 32.386262 | U12: 33.670805 | V12: 39.614676 | W12: 81.605947 | X12: 108.17977 | Y12: 139.66811 | DA12: TES.ktoe.LT.Res.HH.Thermal.SH.AdvElc.Elec
A13: Conventional electric heating | B13: 0.67743854 | C13: 0.73480672 | D13: 0.80116625 | E13: 0.87734571 | F13: 0.99290192 | G13: 1.7930287 | H13: 3.5071025 | I13: 4.8522974 | J13: 6.7015174 | K13: 7.403813 | L13: 7.466275 | M13: 8.2206093 | N13: 10.019438 | O13: 7.5066855 | P13: 10.381324 | Q13: 14.033376 | R13: 15.789623 | S13: 17.313744 | T13: 11.526008 | U13: 10.89753 | V13: 14.72039 | W13: 9.9642016 | X13: 5.9988254 | Y13: 5.8228499 | DA13: TES.ktoe.LT.Res.HH.Thermal.SH.ConvElc.Elec
A14: Electricity in circulation | B14: 4.538487 | C14: 4.6712991 | D14: 4.7379777 | E14: 4.7948874 | F14: 4.8362889 | G14: 4.9812527 | H14: 5.2148825 | I14: 5.052278 | J14: 5.1870211 | K14: 5.2782479 | L14: 5.5413836 | M14: 5.289666 | N14: 5.348138 | O14: 5.1683277 | P14: 4.8358189 | Q14: 4.6699289 | R14: 5.0261515 | S14: 5.1897324 | T14: 5.4580632 | U14: 5.2972224 | V14: 5.3654218 | W14: 6.077466 | X14: 5.735587 | Y14: 5.4800271 | DA14: TES.ktoe.LT.Res.HH.Thermal.SH.TotalCirculation.Elec
A15: Space cooling | B15: =B16 -> 0.0022583566 | C15: =C16 -> 0.0028080698 | D15: =D16 -> 0.004038529 | E15: =E16 -> 0.00852387 | F15: =F16 -> 0.016343277 | G15: =G16 -> 0.031122262 | H15: =H16 -> 0.10367379 | I15: =I16 -> 0.059149598 | ... Y15: =Y16 -> 0.43493166 | DA15: TES.ktoe.LT.Res.HH.Thermal.SC
A16: Air conditioning | B16: 0.0022583566 | C16: 0.0028080698 | D16: 0.004038529 | E16: 0.00852387 | F16: 0.016343277 | G16: 0.031122262 | H16: 0.10367379 | I16: 0.059149598 | J16: 0.060405218 | K16: 0.078473513 | L16: 0.68818943 | M16: 0.090987505 | N16: 0.28291829 | O16: 0.16131099 | P16: 0.40159368 | Q16: 0.29375038 | R16: 0.21909717 | S16: 0.2077483 | T16: 0.35669394 | U16: 0.29685791 | V16: 0.19545569 | W16: 0.67545447 | X16: 0.49418443 | Y16: 0.43493166 | DA16: TES.ktoe.LT.Res.HH.Thermal.SC.AC.Elec
A17: Water heating | B17: =SUM(B18:B26) -> 32.728469 | C17: =SUM(C18:C26) -> 34.859232 | D17: =SUM(D18:D26) -> 32.702977 | E17: =SUM(E18:E26) -> 35.618157 | F17: =SUM(F18:F26) -> 41.93922 | G17: =SUM(G18:G26) -> 43.509324 | H17: =SUM(H18:H26) -> 48.376269 | I17: =SUM(I18:I26) -> 44.904942 | ... Y17: =SUM(Y18:Y26) -> 61.597817 | DA17: TES.ktoe.LT.Res.HH.Thermal.WH
A18: Solids | B18: 0.59938304 | C18: 0.58774403 | D18: 0.74445492 | E18: 0.91941139 | F18: 0.86521859 | G18: 0.98612953 | H18: 1.2450894 | I18: 1.4089395 | J18: 1.4938826 | K18: 1.4346417 | L18: 1.9306545 | M18: 2.1680617 | N18: 2.1857147 | O18: 2.3326554 | P18: 2.1089011 | Q18: 1.7719989 | R18: 1.9306451 | S18: 2.2115435 | T18: 2.095594 | U18: 1.714948 | V18: 1.2824586 | W18: 2.0044127 | X18: 1.8108105 | Y18: 0.76007099 | DA18: TES.ktoe.LT.Res.HH.Thermal.WH.Solids.Solids
A19: Liquified petroleum gas (LPG) | B19: 0.1062044 | C19: 0.10641481 | D19: 0.1051518 | E19: 0.10537828 | F19: 0.094409391 | G19: 0.09469603 | H19: 0.083359664 | I19: 0.063366718 | J19: 0.058116557 | K19: 0.061178998 | L19: 0.069864256 | M19: 0.079830609 | N19: 0.08210143 | O19: 0.072988824 | P19: 0.067583025 | Q19: 0.060333125 | R19: 0.069342764 | S19: 0.079346931 | T19: 0.08513426 | U19: 0.089393375 | V19: 0.09253222 | W19: 0.19135983 | X19: 0.29344498 | Y19: 0.59096548 | DA19: TES.ktoe.LT.Res.HH.Thermal.WH.LPG.LPG
A20: Diesel oil | B20: 0 | C20: 0 | D20: 0 | E20: 0 | F20: 0 | G20: 0.031869465 | H20: 0.033604112 | I20: 0.032851087 | J20: 0.071855899 | K20: 0.10859705 | L20: 0.23571441 | M20: 0.29860378 | N20: 0.46047106 | O20: 0.38126506 | P20: 0.46404648 | Q20: 0.38808532 | R20: 0.62403089 | S20: 0.83113694 | T20: 0.94575112 | U20: 0.9046686 | V20: 0.9167024 | W20: 1.4682107 | X20: 1.6791975 | Y20: 1.221638 | DA20: TES.ktoe.LT.Res.HH.Thermal.WH.Oil.Oil_LiqBio
A21: Natural gas | B21: 2.3110358 | C21: 2.4317664 | D21: 2.2890382 | E21: 2.63056 | F21: 3.3428044 | G21: 3.6176681 | H21: 4.0004475 | I21: 4.110746 | J21: 4.445761 | K21: 4.4954143 | L21: 4.6258034 | M21: 4.6711128 | N21: 4.5262569 | O21: 4.1610057 | P21: 4.5061271 | Q21: 4.8541775 | R21: 5.9761564 | S21: 6.4196993 | T21: 6.7666701 | U21: 6.7123384 | V21: 7.2911503 | W21: 12.922612 | X21: 11.223792 | Y21: 7.6843021 | DA21: TES.ktoe.LT.Res.HH.Thermal.WH.Gas.NG_Biogas
A22: Biomass | B22: 8.5360567 | C22: 8.6397937 | D22: 8.3622517 | E22: 8.7872585 | F22: 9.0886145 | G22: 9.3136589 | H22: 9.4858672 | I22: 10.012692 | J22: 11.102103 | K22: 12.286376 | L22: 12.855273 | M22: 14.228894 | N22: 15.195253 | O22: 15.494361 | P22: 15.581598 | Q22: 15.655562 | R22: 15.468531 | S22: 15.176638 | T22: 15.010372 | U22: 14.663823 | V22: 14.585989 | W22: 21.759346 | X22: 22.237216 | Y22: 17.448851 | DA22: TES.ktoe.LT.Res.HH.Thermal.WH.Biomass.Biomass_Waste
A23: Geothermal | B23: 0 | C23: 0 | D23: 0 | E23: 0 | F23: 0 | G23: 0 | H23: 0 | I23: 0 | J23: 0 | K23: 0 | L23: 0 | M23: 0 | N23: 0 | O23: 0 | P23: 0 | Q23: 0 | R23: 0 | S23: 0 | T23: 0 | U23: 0 | V23: 0 | W23: 0 | X23: 0 | Y23: 0 | DA23: TES.ktoe.LT.Res.HH.Thermal.WH.Geo.Geo
A24: Distributed heat | B24: 17.615882 | C24: 19.029828 | D24: 18.21372 | E24: 19.547664 | F24: 22.416922 | G24: 22.580991 | H24: 24.472355 | I24: 21.675733 | J24: 23.966601 | K24: 24.530075 | L24: 23.266818 | M24: 23.709201 | N24: 24.521679 | O24: 23.356934 | P24: 24.212501 | Q24: 24.074756 | R24: 26.309943 | S24: 26.42432 | T24: 25.347661 | U24: 23.850033 | V24: 22.019302 | W24: 36.262947 | X24: 31.911561 | Y24: 23.674483 | DA24: TES.ktoe.LT.Res.HH.Thermal.WH.DistrHeat.Steam_Distr
A25: Electricity | B25: 3.5599065 | C25: 4.0636853 | D25: 2.9883608 | E25: 3.6278846 | F25: 6.1312511 | G25: 6.8843111 | H25: 9.0555463 | I25: 7.6006139 | J25: 9.7115376 | K25: 9.4676378 | L25: 7.3189237 | M25: 8.2419084 | N25: 8.8193164 | O25: 7.8985937 | P25: 9.0710622 | Q25: 8.932105 | R25: 9.5319116 | S25: 9.704209 | T25: 9.9606936 | U25: 9.3534231 | V25: 9.3883303 | W25: 15.744312 | X25: 14.388392 | Y25: 10.217507 | DA25: TES.ktoe.LT.Res.HH.Thermal.WH.Elc.Elec
A26: Solar | B26: 0 | C26: 0 | D26: 0 | E26: 0 | F26: 0 | G26: 0 | H26: 0 | I26: 0 | J26: 0 | K26: 0 | L26: 0 | M26: 0 | N26: 0 | O26: 0 | P26: 0 | Q26: 0 | R26: 0 | S26: 0 | T26: 0 | U26: 0 | V26: 0 | W26: 0 | X26: 0 | Y26: 0 | DA26: TES.ktoe.LT.Res.HH.Thermal.WH.TotalSolar.Solar
A27: Cooking | B27: =SUM(B28:B32) -> 52.951891 | C27: =SUM(C28:C32) -> 52.652223 | D27: =SUM(D28:D32) -> 49.946362 | E27: =SUM(E28:E32) -> 51.589078 | F27: =SUM(F28:F32) -> 52.612078 | G27: =SUM(G28:G32) -> 52.69879 | H27: =SUM(H28:H32) -> 56.919508 | I27: =SUM(I28:I32) -> 55.136654 | ... Y27: =SUM(Y28:Y32) -> 55.099071 | DA27: TES.ktoe.LT.Res.HH.Thermal.CO
A28: Solids | B28: 0.12495213 | C28: 0.12037372 | D28: 0.15064077 | E28: 0.17835591 | F28: 0.16513859 | G28: 0.18474026 | H28: 0.23372513 | I28: 0.24283276 | J28: 0.26460433 | K28: 0.24278897 | L28: 0.31349914 | M28: 0.35646342 | N28: 0.36035869 | O28: 0.37462007 | P28: 0.3419785 | Q28: 0.28623395 | R28: 0.31689515 | S28: 0.36524651 | T28: 0.38042876 | U28: 0.30360681 | V28: 0.22356992 | W28: 0.28216721 | X28: 0.30057582 | Y28: 0.21595907 | DA28: TES.ktoe.LT.Res.HH.Thermal.CO.Solids.Solids
A29: Liquified petroleum gas (LPG) | B29: 41.126907 | C29: 40.496652 | D29: 39.264376 | E29: 38.182537 | F29: 33.601191 | G29: 33.011807 | H29: 28.965505 | I29: 20.240648 | J29: 19.174107 | K29: 19.18262 | L29: 20.911777 | M29: 24.04014 | N29: 24.689089 | O29: 21.173904 | P29: 19.52822 | Q29: 16.971179 | R29: 18.783735 | S29: 20.256306 | T29: 19.656467 | U29: 21.54395 | V29: 18.084347 | W29: 15.09655 | X29: 17.6382 | Y29: 29.902131 | DA29: TES.ktoe.LT.Res.HH.Thermal.CO.LPG.LPG
A30: Natural gas | B30: 3.7356135 | C30: 3.669009 | D30: 3.4905207 | E30: 3.8015228 | F30: 4.1824577 | G30: 4.3682397 | H30: 4.6910037 | I30: 5.0278323 | J30: 5.3370428 | K30: 4.9734738 | L30: 4.6364641 | M30: 4.8435063 | N30: 4.5188138 | O30: 3.8275665 | P30: 3.7770155 | Q30: 3.3056806 | R30: 3.9056257 | S30: 3.8767627 | T30: 4.981948 | U30: 5.4094295 | V30: 5.6475167 | W30: 6.7547746 | X30: 6.4833757 | Y30: 6.8587048 | DA30: TES.ktoe.LT.Res.HH.Thermal.CO.Gas.NG_Biogas
A31: Biomass | B31: 5.430645 | C31: 5.3585898 | D31: 5.0451425 | E31: 5.114233 | F31: 5.188875 | G31: 5.1781614 | H31: 5.2198006 | I31: 4.8915815 | J31: 5.3182859 | K31: 5.3462513 | L31: 5.1180395 | M31: 5.4755633 | N31: 5.6231102 | O31: 5.4190809 | P31: 5.4994388 | Q31: 5.4982328 | R31: 5.4994185 | S31: 5.4378446 | T31: 5.2658431 | U31: 5.0856441 | V31: 4.8288682 | W31: 5.1463673 | X31: 5.7030316 | Y31: 5.7217883 | DA31: TES.ktoe.LT.Res.HH.Thermal.CO.Biomass.Biomass_Waste
